[META]
version=2.0
spawnOnBlockType=2
spawnSunlight=True
spawnDarkness=True
spawnWater=False
spawnLava=False
underFill=False
randomRotation=True
dig=True
tree=True
branch=False
needsFoundation=True
rarity=5
collisionPercentage=20
spawnElevationMin=0
spawnElevationMax=200
spawnInBiome=Custom
[DATA]
3,-3,-3:17.1
3,0,-3:17.1
4,0,-3:17.1
1,1,-3:17.1
1,-3,-2:17.1
3,-3,-2:17.1
0,-2,-2:17.1
3,-1,-2:17.1
1,0,-2:17.1
3,1,-2:17.1
2,-2,-1:17.1
2,-1,-1:17.1
1,0,-1:17.1
2,0,-1:17.1
3,1,-1:17.1
2,-1,0:17.1
2,0,0:17.1
2,0,1:17.1
2,-1,2:18.1
1,0,2:18.1
2,0,2:17.1
2,2,2:18.1
2,-1,3:18.1
4,-1,3:18.1
1,0,3:18.1
2,0,3:17.1
3,0,3:18.1
4,0,3:18.1
5,0,3:18.1
2,1,3:18.1
4,1,3:18.1
5,1,3:18.1
2,2,3:18.1
1,-2,4:18.1
2,-2,4:18.1
0,-1,4:18.1
1,-1,4:18.1
2,-1,4:18.1
3,-1,4:18.1
4,-1,4:18.1
1,0,4:18.1
2,0,4:18.1
3,0,4:18.1
4,0,4:18.1
5,0,4:18.1
1,1,4:18.1
2,1,4:18.1
3,1,4:18.1
4,1,4:18.1
1,-3,5:18.1
0,-2,5:18.1
1,-2,5:18.1
2,-2,5:18.1
0,-1,5:18.1
1,-1,5:18.1
2,-1,5:18.1
3,-1,5:18.1
-1,0,5:18.1
0,0,5:18.1
1,0,5:18.1
2,0,5:18.1
3,0,5:18.1
4,0,5:18.1
0,1,5:18.1
1,1,5:18.1
2,1,5:18.1
3,1,5:18.1
0,2,5:18.1
2,2,5:18.1
5,3,5:18.1
4,5,5:18.1
0,-3,6:18.1
1,-3,6:18.1
0,-2,6:18.1
1,-2,6:18.1
2,-2,6:18.1
1,-1,6:18.1
2,-1,6:18.1
3,-1,6:18.1
4,-1,6:18.1
0,0,6:18.1
1,0,6:17.1
2,0,6:18.1
3,0,6:18.1
4,0,6:18.1
5,0,6:18.1
-5,1,6:18.1
-4,1,6:18.1
0,1,6:18.1
1,1,6:18.1
2,1,6:18.1
3,1,6:18.1
0,2,6:18.1
1,2,6:18.1
2,2,6:18.1
3,2,6:18.1
2,3,6:18.1
3,3,6:18.1
4,3,6:18.1
5,3,6:18.1
2,4,6:18.1
4,4,6:18.1
4,5,6:18.1
1,-3,7:18.1
1,-2,7:18.1
-3,-1,7:18.1
1,-1,7:18.1
3,-1,7:18.1
4,-1,7:18.1
-1,0,7:18.1
0,0,7:18.1
1,0,7:17.1
2,0,7:17.1
3,0,7:18.1
4,0,7:18.1
-4,1,7:18.1
-3,1,7:18.1
0,1,7:18.1
1,1,7:18.1
2,1,7:18.1
3,1,7:18.1
4,1,7:18.1
-4,2,7:18.1
1,2,7:18.1
2,2,7:18.1
3,2,7:18.1
2,3,7:18.1
3,3,7:18.1
4,3,7:17.1
5,3,7:18.1
4,4,7:18.1
5,-3,8:18.1
-3,-1,8:18.1
0,-1,8:18.1
1,-1,8:18.1
2,-1,8:18.1
3,-1,8:18.1
-3,0,8:18.1
-1,0,8:18.1
0,0,8:18.1
1,0,8:17.1
2,0,8:17.1
3,0,8:18.1
4,0,8:18.1
-3,1,8:17.1
-2,1,8:18.1
-1,1,8:18.1
0,1,8:18.1
2,1,8:18.1
3,1,8:18.1
-3,2,8:18.1
3,2,8:17.1
2,3,8:18.1
3,3,8:18.1
4,3,8:18.1
4,-5,9:18.1
4,-4,9:18.1
5,-3,9:18.1
0,-1,9:18.1
1,-1,9:18.1
2,-1,9:18.1
-2,0,9:18.1
-1,0,9:18.1
0,0,9:18.1
1,0,9:18.1
2,0,9:17.1
3,0,9:18.1
-3,1,9:18.1
-2,1,9:17.1
-1,1,9:18.1
0,1,9:18.1
1,1,9:18.1
2,1,9:18.1
-2,2,9:18.1
3,2,9:18.1
-1,-5,10:18.1
-1,-4,10:18.1
4,-4,10:18.1
-3,-3,10:18.1
3,-3,10:18.1
4,-3,10:18.1
5,-3,10:18.1
0,-2,10:18.1
1,-2,10:18.1
-1,-1,10:18.1
0,-1,10:18.1
1,-1,10:18.1
2,-1,10:18.1
-2,0,10:18.1
-1,0,10:17.1
0,0,10:18.1
1,0,10:18.1
2,0,10:17.1
-2,1,10:18.1
-1,1,10:18.1
0,1,10:18.1
1,1,10:18.1
2,1,10:18.1
3,1,10:18.1
3,2,10:18.1
4,2,10:18.1
5,2,10:18.1
4,3,10:18.1
-1,-4,11:18.1
4,-4,11:18.1
-3,-3,11:18.1
-2,-3,11:18.1
-1,-3,11:18.1
0,-3,11:18.1
3,-3,11:18.1
4,-3,11:17.1
0,-2,11:18.1
3,-2,11:18.1
4,-2,11:18.1
0,-1,11:18.1
1,-1,11:18.1
2,-1,11:18.1
3,-1,11:18.1
-1,0,11:18.1
0,0,11:18.1
1,0,11:18.1
2,0,11:17.1
3,0,11:18.1
1,1,11:18.1
2,1,11:18.1
3,1,11:18.1
4,1,11:18.1
2,2,11:18.1
4,2,11:18.1
4,3,11:18.1
-1,-4,12:18.1
-2,-3,12:18.1
-1,-3,12:17.1
0,-3,12:18.1
3,-3,12:18.1
4,-3,12:18.1
-1,-2,12:18.1
0,-2,12:17.1
1,-2,12:18.1
3,-2,12:17.1
4,-2,12:18.1
0,-1,12:18.1
1,-1,12:18.1
2,-1,12:18.1
3,-1,12:18.1
1,0,12:18.1
2,0,12:17.1
2,1,12:18.1
3,1,12:18.1
-1,-3,13:18.1
0,-2,13:18.1
2,-2,13:18.1
3,-2,13:18.1
1,-1,13:18.1
2,-1,13:17.1
3,-1,13:18.1
2,0,13:17.1
3,0,13:18.1
1,1,13:18.1
2,1,13:18.1
3,1,13:18.1
1,2,13:18.1
3,2,13:18.1
1,3,13:18.1
2,-1,14:18.1
2,0,14:17.1
4,0,14:18.1
2,1,14:18.1
2,-2,15:18.1
0,-1,15:18.1
2,-1,15:18.1
2,0,15:17.1
3,0,15:18.1
4,0,15:18.1
2,1,15:18.1
2,2,15:18.1
0,-1,16:18.1
2,-1,16:18.1
0,0,16:18.1
1,0,16:18.1
2,0,16:17.1
3,0,16:18.1
2,1,16:18.1
2,2,16:18.1
0,0,17:18.1
1,0,17:18.1
2,0,17:17.1
3,0,17:18.1
2,1,17:18.1
1,0,18:18.1
2,0,18:18.1
2,0,19:18.1
3,0,19:18.1
2,0,20:18.1
2,1,2:106.4
1,1,2:106.4
2,1,1:106.4
1,1,1:106.4
3,0,1:106.2
2,-1,1:106.1
2,1,0:106.4
1,1,0:106.4
3,0,0:106.2
3,-1,0:106.2
