[META]
version=2.0
spawnOnBlockType=2
spawnSunlight=True
spawnDarkness=True
spawnWater=False
spawnLava=False
underFill=False
randomRotation=True
dig=True
tree=True
branch=False
needsFoundation=True
rarity=20
collisionPercentage=20
spawnElevationMin=0
spawnElevationMax=200
spawnInBiome=Custom
[DATA]
-2,-6,-3:17.1
-1,-6,-3:17.1
-1,-5,-3:17.1
0,-5,-3:17.1
1,-5,-3:17.1
2,-5,-3:17.1
-4,-4,-3:17.1
-3,-4,-3:17.1
-1,-4,-3:17.1
0,-4,-3:17.1
1,-4,-3:17.1
2,-4,-3:17.1
3,-4,-3:17.1
-3,-3,-3:17.1
-2,-3,-3:17.1
-1,-3,-3:17.1
0,-3,-3:17.1
1,-3,-3:17.1
2,-3,-3:17.1
-2,-2,-3:17.1
-1,-2,-3:17.1
0,-2,-3:17.1
1,-2,-3:17.1
-1,-1,-3:17.1
0,-1,-3:17.1
1,-1,-3:17.1
2,-1,-3:17.1
-3,0,-3:17.1
-2,0,-3:17.1
-1,0,-3:17.1
0,0,-3:17.1
1,0,-3:17.1
2,0,-3:17.1
3,0,-3:17.1
-2,1,-3:17.1
2,1,-3:17.1
-2,-6,-2:17.1
-1,-5,-2:17.1
0,-5,-2:17.1
1,-5,-2:17.1
-4,-4,-2:17.1
-3,-4,-2:17.1
0,-4,-2:17.1
1,-4,-2:17.1
2,-4,-2:17.1
-3,-3,-2:17.1
-2,-3,-2:17.1
-1,-3,-2:17.1
0,-3,-2:17.1
1,-3,-2:17.1
2,-3,-2:17.1
-1,-2,-2:17.1
0,-2,-2:17.1
-1,-1,-2:17.1
0,-1,-2:17.1
1,-1,-2:17.1
-2,0,-2:17.1
-1,0,-2:17.1
1,0,-2:17.1
2,0,-2:17.1
-2,1,-2:17.1
-1,-6,-1:17.1
0,-5,-1:17.1
-3,-4,-1:17.1
0,-4,-1:17.1
2,-4,-1:17.1
-2,-3,-1:17.1
0,-3,-1:17.1
1,-3,-1:17.1
2,-3,-1:17.1
-1,-2,-1:17.1
0,-2,-1:17.1
-1,-1,-1:17.1
0,-1,-1:17.1
-2,0,-1:17.1
2,0,-1:17.1
-1,-6,0:17.1
0,-5,0:17.1
-3,-4,0:17.1
0,-4,0:17.1
2,-4,0:17.1
-2,-3,0:17.1
0,-3,0:17.1
1,-3,0:17.1
2,-3,0:17.1
-1,-2,0:17.1
0,-2,0:17.1
-1,-1,0:17.1
0,-1,0:17.1
1,-1,0:17.1
-2,0,0:17.1
2,0,0:17.1
0,-5,1:17.1
0,-4,1:17.1
-2,-3,1:17.1
0,-3,1:17.1
1,-3,1:17.1
2,-3,1:17.1
-1,-2,1:17.1
0,-2,1:17.1
-1,-1,1:17.1
1,-1,1:17.1
0,-4,2:17.1
0,-3,2:17.1
1,-3,2:17.1
2,-3,2:17.1
-1,-2,2:17.1
0,-2,2:17.1
1,-1,2:17.1
0,-4,3:17.1
0,-3,3:17.1
1,-3,3:17.1
-1,-2,3:17.1
0,-2,3:17.1
-4,0,3:18.1
-4,1,3:18.1
3,1,3:18.1
4,1,3:18.1
3,-8,4:18.1
-4,-7,4:18.1
3,-7,4:18.1
5,-6,4:18.1
0,-4,4:17.1
0,-3,4:17.1
1,-3,4:17.1
-1,-2,4:17.1
-5,-1,4:18.1
-3,-1,4:18.1
3,-1,4:18.1
-5,0,4:18.1
-4,0,4:18.1
-3,0,4:18.1
-2,0,4:18.1
2,0,4:18.1
3,0,4:18.1
4,0,4:18.1
5,0,4:18.1
6,0,4:18.1
-4,1,4:18.1
-3,1,4:18.1
3,1,4:18.1
4,1,4:18.1
-4,-8,5:18.1
-3,-8,5:18.1
3,-8,5:18.1
-4,-7,5:18.1
-3,-7,5:18.1
3,-7,5:18.1
2,-6,5:18.1
3,-6,5:18.1
4,-6,5:18.1
5,-6,5:18.1
3,-5,5:18.1
0,-4,5:17.1
-5,-3,5:18.1
0,-3,5:17.1
1,-3,5:17.1
-1,-2,5:17.1
2,-2,5:18.1
-4,-1,5:18.1
-3,-1,5:18.1
-2,-1,5:18.1
1,-1,5:18.1
2,-1,5:18.1
3,-1,5:18.1
4,-1,5:18.1
-4,0,5:18.1
-3,0,5:17.1
-2,0,5:18.1
1,0,5:18.1
2,0,5:18.1
3,0,5:17.1
4,0,5:18.1
5,0,5:18.1
-3,1,5:18.1
2,1,5:18.1
3,1,5:18.1
4,1,5:18.1
-4,-8,6:18.1
-3,-8,6:18.1
-2,-8,6:18.1
3,-8,6:18.1
-4,-7,6:18.1
-3,-7,6:18.1
-2,-7,6:18.1
2,-7,6:18.1
3,-7,6:18.1
4,-7,6:18.1
-3,-6,6:17.1
2,-6,6:18.1
3,-6,6:17.1
4,-6,6:18.1
-3,-5,6:18.1
1,-5,6:18.1
2,-5,6:18.1
3,-5,6:18.1
4,-5,6:18.1
0,-4,6:17.1
2,-4,6:18.1
-5,-3,6:18.1
0,-3,6:17.1
1,-3,6:17.1
-3,-2,6:18.1
-1,-2,6:17.1
1,-2,6:18.1
2,-2,6:18.1
3,-2,6:18.1
-4,-1,6:18.1
-3,-1,6:18.1
-2,-1,6:18.1
0,-1,6:18.1
1,-1,6:18.1
2,-1,6:17.1
3,-1,6:18.1
-4,0,6:18.1
-3,0,6:17.1
-2,0,6:18.1
1,0,6:18.1
2,0,6:18.1
3,0,6:18.1
4,0,6:18.1
-2,1,6:18.1
3,1,6:18.1
-3,-8,7:18.1
-4,-7,7:18.1
-3,-7,7:18.1
-2,-7,7:18.1
3,-7,7:18.1
-4,-6,7:18.1
-3,-6,7:17.1
-2,-6,7:18.1
1,-6,7:18.1
2,-6,7:18.1
3,-6,7:18.1
4,-6,7:18.1
-3,-5,7:18.1
-2,-5,7:18.1
-1,-5,7:18.1
1,-5,7:18.1
2,-5,7:17.1
3,-5,7:18.1
-2,-4,7:18.1
0,-4,7:17.1
1,-4,7:17.1
2,-4,7:18.1
3,-4,7:18.1
-5,-3,7:18.1
-4,-3,7:18.1
0,-3,7:17.1
1,-3,7:17.1
-3,-2,7:18.1
-2,-2,7:18.1
-1,-2,7:17.1
0,-2,7:18.1
1,-2,7:17.1
2,-2,7:18.1
-3,-1,7:18.1
-2,-1,7:17.1
-1,-1,7:18.1
1,-1,7:18.1
2,-1,7:17.1
3,-1,7:18.1
-3,0,7:18.1
-2,0,7:18.1
2,0,7:18.1
-3,-7,8:18.1
3,-7,8:18.1
-4,-6,8:18.1
-3,-6,8:18.1
-2,-6,8:18.1
-1,-6,8:18.1
2,-6,8:18.1
3,-6,8:18.1
4,-6,8:18.1
5,-6,8:18.1
7,-6,8:18.1
-4,-5,8:18.1
-3,-5,8:18.1
-2,-5,8:17.1
-1,-5,8:18.1
0,-5,8:18.1
1,-5,8:18.1
2,-5,8:18.1
3,-5,8:18.1
-3,-4,8:18.1
-2,-4,8:18.1
-1,-4,8:17.1
0,-4,8:17.1
2,-4,8:18.1
-5,-3,8:18.1
-4,-3,8:17.1
-3,-3,8:18.1
-2,-3,8:18.1
-1,-3,8:18.1
0,-3,8:17.1
1,-3,8:17.1
2,-3,8:18.1
-4,-2,8:18.1
-3,-2,8:18.1
-2,-2,8:18.1
-1,-2,8:17.1
0,-2,8:18.1
1,-2,8:17.1
2,-2,8:18.1
-3,-1,8:18.1
-2,-1,8:17.1
-1,-1,8:17.1
0,-1,8:18.1
1,-1,8:18.1
2,-1,8:18.1
-2,0,8:18.1
-1,0,8:18.1
3,4,8:18.1
4,4,8:18.1
6,4,8:18.1
6,5,8:18.1
-5,-8,9:18.1
3,-7,9:18.1
4,-7,9:18.1
-2,-6,9:18.1
3,-6,9:18.1
4,-6,9:17.1
5,-6,9:18.1
6,-6,9:18.1
7,-6,9:18.1
-3,-5,9:18.1
-2,-5,9:18.1
-1,-5,9:18.1
2,-5,9:18.1
3,-5,9:18.1
4,-5,9:18.1
-4,-4,9:18.1
-3,-4,9:18.1
-2,-4,9:18.1
-1,-4,9:17.1
0,-4,9:17.1
-4,-3,9:18.1
-3,-3,9:17.1
-2,-3,9:18.1
-1,-3,9:17.1
0,-3,9:17.1
1,-3,9:17.1
-4,-2,9:18.1
-3,-2,9:18.1
-2,-2,9:18.1
-1,-2,9:17.1
0,-2,9:17.1
1,-2,9:18.1
2,-2,9:18.1
-3,-1,9:18.1
-2,-1,9:18.1
-1,-1,9:18.1
1,-1,9:18.1
-2,0,9:18.1
5,3,9:18.1
3,4,9:18.1
4,4,9:18.1
5,4,9:18.1
6,4,9:18.1
5,5,9:18.1
6,5,9:18.1
-5,-8,10:18.1
3,-7,10:18.1
4,-7,10:18.1
5,-7,10:18.1
6,-7,10:18.1
3,-6,10:18.1
4,-6,10:17.1
5,-6,10:18.1
6,-6,10:18.1
7,-6,10:18.1
2,-5,10:18.1
4,-5,10:18.1
5,-5,10:18.1
-3,-4,10:18.1
-1,-4,10:18.1
0,-4,10:18.1
1,-4,10:17.1
2,-4,10:17.1
3,-4,10:18.1
-4,-3,10:18.1
-3,-3,10:17.1
-2,-3,10:18.1
-1,-3,10:18.1
0,-3,10:17.1
1,-3,10:17.1
2,-3,10:18.1
-3,-2,10:18.1
-2,-2,10:18.1
-1,-2,10:17.1
0,-2,10:17.1
-2,-1,10:18.1
4,3,10:18.1
5,3,10:18.1
6,3,10:18.1
4,4,10:18.1
5,4,10:17.1
6,4,10:18.1
4,5,10:18.1
5,5,10:18.1
6,5,10:18.1
-5,-8,11:18.1
-4,-8,11:18.1
-5,-7,11:18.1
-4,-7,11:17.1
-3,-7,11:18.1
4,-7,11:18.1
5,-7,11:18.1
3,-6,11:18.1
4,-6,11:17.1
5,-6,11:18.1
1,-5,11:18.1
2,-5,11:18.1
3,-5,11:17.1
4,-5,11:18.1
5,-5,11:18.1
1,-4,11:18.1
2,-4,11:17.1
3,-4,11:18.1
0,-3,11:17.1
1,-3,11:17.1
2,-3,11:18.1
3,-3,11:18.1
-2,-2,11:17.1
-1,-2,11:17.1
0,-2,11:17.1
-1,-1,11:18.1
0,-1,11:17.1
1,-1,11:17.1
1,0,11:18.1
2,0,11:18.1
4,2,11:18.1
5,2,11:18.1
3,3,11:18.1
4,3,11:17.1
5,3,11:17.1
4,4,11:18.1
5,4,11:18.1
6,4,11:18.1
5,5,11:18.1
-5,-8,12:18.1
-4,-8,12:18.1
-3,-8,12:18.1
-5,-7,12:18.1
-4,-7,12:17.1
-3,-7,12:18.1
4,-7,12:18.1
-4,-6,12:18.1
-3,-6,12:18.1
3,-6,12:18.1
4,-6,12:18.1
5,-6,12:18.1
2,-5,12:18.1
4,-5,12:18.1
1,-4,12:18.1
2,-4,12:18.1
3,-4,12:18.1
0,-3,12:17.1
1,-3,12:17.1
2,-3,12:18.1
-1,-2,12:17.1
0,-2,12:17.1
0,-1,12:17.1
1,-1,12:17.1
2,-1,12:18.1
0,0,12:18.1
1,0,12:17.1
2,0,12:18.1
-6,1,12:18.1
1,1,12:18.1
2,1,12:18.1
3,1,12:18.1
3,2,12:17.1
4,2,12:18.1
5,2,12:18.1
-1,3,12:18.1
3,3,12:18.1
4,3,12:17.1
5,3,12:18.1
-3,4,12:18.1
3,4,12:18.1
4,4,12:18.1
5,4,12:18.1
-2,5,12:18.1
-4,-8,13:18.1
5,-8,13:18.1
-5,-7,13:18.1
-4,-7,13:18.1
-3,-7,13:18.1
-2,-7,13:18.1
-4,-6,13:18.1
-3,-6,13:17.1
-2,-6,13:18.1
-2,-5,13:18.1
0,-3,13:17.1
1,-3,13:17.1
5,-2,13:18.1
1,-1,13:18.1
0,0,13:18.1
1,0,13:17.1
2,0,13:18.1
-6,1,13:18.1
-5,1,13:18.1
-4,1,13:18.1
1,1,13:18.1
2,1,13:17.1
3,1,13:18.1
4,1,13:18.1
-5,2,13:18.1
2,2,13:18.1
3,2,13:17.1
4,2,13:18.1
-2,3,13:18.1
-1,3,13:18.1
3,3,13:18.1
4,3,13:18.1
5,3,13:18.1
-3,4,13:18.1
-2,4,13:18.1
4,4,13:18.1
-2,5,13:18.1
5,-8,14:18.1
-3,-7,14:18.1
-2,-7,14:18.1
-3,-6,14:18.1
-2,-6,14:17.1
-1,-6,14:18.1
6,-6,14:18.1
-3,-5,14:18.1
-2,-5,14:18.1
-1,-5,14:18.1
-2,-4,14:18.1
-1,-4,14:18.1
0,-4,14:18.1
-1,-3,14:17.1
0,-3,14:17.1
1,-3,14:17.1
5,-3,14:18.1
5,-2,14:17.1
6,-2,14:18.1
-3,0,14:18.1
-5,1,14:18.1
-4,1,14:17.1
-3,1,14:18.1
1,1,14:18.1
2,1,14:18.1
3,1,14:18.1
7,1,14:18.1
8,1,14:18.1
-5,2,14:18.1
-4,2,14:18.1
2,2,14:18.1
3,2,14:18.1
4,2,14:18.1
3,3,14:18.1
-3,4,14:18.1
-2,4,14:17.1
-1,4,14:18.1
-2,5,14:18.1
4,-8,15:18.1
5,-8,15:18.1
-2,-7,15:18.1
3,-7,15:18.1
4,-7,15:17.1
5,-7,15:18.1
-3,-6,15:18.1
-2,-6,15:18.1
-1,-6,15:18.1
5,-6,15:18.1
6,-6,15:18.1
-2,-5,15:17.1
-1,-5,15:18.1
0,-5,15:18.1
-2,-4,15:18.1
-1,-4,15:17.1
0,-4,15:18.1
-2,-3,15:18.1
-1,-3,15:17.1
0,-3,15:17.1
1,-3,15:17.1
4,-3,15:18.1
4,-2,15:17.1
5,-2,15:18.1
-3,-1,15:18.1
7,-1,15:18.1
-4,0,15:18.1
-3,0,15:17.1
-2,0,15:18.1
6,0,15:18.1
7,0,15:18.1
-5,1,15:18.1
-4,1,15:18.1
-3,1,15:18.1
2,1,15:18.1
5,1,15:18.1
6,1,15:18.1
7,1,15:18.1
8,1,15:18.1
-4,2,15:18.1
-1,2,15:18.1
3,2,15:18.1
6,2,15:18.1
7,2,15:18.1
-2,3,15:18.1
-1,3,15:18.1
7,3,15:18.1
-2,4,15:17.1
-1,4,15:18.1
-1,5,15:18.1
3,-8,16:18.1
4,-8,16:18.1
3,-7,16:18.1
4,-7,16:17.1
5,-7,16:18.1
-2,-6,16:18.1
3,-6,16:18.1
4,-6,16:18.1
5,-6,16:18.1
-2,-5,16:18.1
-1,-5,16:18.1
-2,-4,16:18.1
-1,-4,16:17.1
0,-4,16:18.1
1,-4,16:17.1
-1,-3,16:18.1
0,-3,16:17.1
1,-3,16:17.1
2,-3,16:17.1
3,-3,16:17.1
4,-3,16:18.1
-2,-2,16:18.1
4,-2,16:18.1
-3,-1,16:18.1
-2,-1,16:18.1
-1,-1,16:18.1
5,-1,16:18.1
7,-1,16:18.1
-4,0,16:18.1
-3,0,16:17.1
-2,0,16:18.1
4,0,16:18.1
5,0,16:18.1
6,0,16:18.1
7,0,16:18.1
-4,1,16:18.1
-3,1,16:18.1
-2,1,16:18.1
5,1,16:18.1
6,1,16:17.1
7,1,16:18.1
-1,2,16:18.1
0,2,16:18.1
6,2,16:18.1
7,2,16:18.1
-2,3,16:18.1
-1,3,16:17.1
0,3,16:18.1
-2,4,16:18.1
-1,4,16:18.1
-1,5,16:18.1
4,-8,17:18.1
3,-7,17:18.1
4,-7,17:18.1
2,-6,17:18.1
3,-6,17:17.1
4,-6,17:18.1
1,-5,17:18.1
2,-5,17:18.1
3,-5,17:18.1
4,-5,17:18.1
-1,-4,17:18.1
2,-4,17:18.1
-1,-3,17:18.1
0,-3,17:17.1
1,-3,17:17.1
2,-3,17:18.1
3,-3,17:18.1
-2,-2,17:18.1
-1,-2,17:17.1
0,-2,17:17.1
4,-2,17:18.1
-4,-1,17:18.1
-3,-1,17:18.1
-2,-1,17:17.1
-1,-1,17:17.1
4,-1,17:18.1
5,-1,17:18.1
6,-1,17:18.1
-4,0,17:18.1
-3,0,17:18.1
-2,0,17:18.1
-1,0,17:18.1
0,0,17:18.1
4,0,17:18.1
5,0,17:17.1
6,0,17:18.1
-3,1,17:18.1
-1,1,17:18.1
0,1,17:17.1
1,1,17:18.1
4,1,17:18.1
5,1,17:18.1
6,1,17:18.1
7,1,17:18.1
-1,2,17:17.1
0,2,17:18.1
5,2,17:18.1
6,2,17:18.1
-2,3,17:18.1
-1,3,17:18.1
0,3,17:18.1
-4,-7,18:18.1
1,-6,18:18.1
2,-6,18:18.1
3,-6,18:18.1
1,-5,18:18.1
2,-5,18:17.1
3,-5,18:18.1
1,-4,18:17.1
2,-4,18:17.1
3,-4,18:18.1
0,-3,18:17.1
1,-3,18:17.1
-2,-2,18:18.1
4,-2,18:18.1
-3,-1,18:18.1
-2,-1,18:18.1
-1,-1,18:18.1
3,-1,18:18.1
4,-1,18:17.1
5,-1,18:18.1
-2,0,18:18.1
-1,0,18:18.1
0,0,18:17.1
1,0,18:18.1
4,0,18:18.1
5,0,18:18.1
6,0,18:18.1
-1,1,18:18.1
0,1,18:17.1
1,1,18:18.1
5,1,18:18.1
-5,2,18:18.1
-1,2,18:18.1
0,2,18:18.1
1,2,18:18.1
-1,3,18:18.1
4,3,18:18.1
-7,-8,19:18.1
-4,-7,19:18.1
-4,-6,19:18.1
-3,-6,19:18.1
2,-6,19:18.1
1,-5,19:18.1
2,-5,19:18.1
3,-5,19:18.1
2,-4,19:18.1
0,-3,19:17.1
1,-3,19:17.1
2,-3,19:18.1
3,-3,19:18.1
-1,-2,19:18.1
0,-2,19:17.1
2,-2,19:18.1
3,-2,19:17.1
4,-2,19:18.1
5,-2,19:18.1
-1,-1,19:18.1
0,-1,19:17.1
3,-1,19:18.1
4,-1,19:17.1
5,-1,19:18.1
0,0,19:18.1
3,0,19:18.1
4,0,19:18.1
5,0,19:18.1
-6,1,19:18.1
-4,1,19:18.1
-3,1,19:18.1
-1,1,19:18.1
0,1,19:18.1
-5,2,19:18.1
-4,2,19:18.1
0,2,19:18.1
4,2,19:18.1
4,3,19:18.1
-7,-8,20:18.1
-6,-8,20:18.1
-5,-8,20:18.1
-4,-8,20:18.1
-5,-7,20:18.1
-4,-7,20:18.1
-4,-6,20:18.1
-3,-6,20:18.1
-3,-5,20:18.1
-2,-5,20:18.1
-1,-5,20:18.1
-2,-4,20:18.1
-1,-4,20:17.1
1,-4,20:18.1
2,-4,20:18.1
3,-4,20:18.1
-1,-3,20:18.1
0,-3,20:17.1
1,-3,20:17.1
2,-3,20:17.1
3,-3,20:18.1
4,-3,20:18.1
0,-2,20:17.1
1,-2,20:18.1
2,-2,20:17.1
3,-2,20:17.1
4,-2,20:18.1
0,-1,20:18.1
2,-1,20:18.1
3,-1,20:18.1
4,-1,20:18.1
5,-1,20:18.1
-3,0,20:18.1
0,0,20:18.1
4,0,20:18.1
-6,1,20:18.1
-5,1,20:18.1
-4,1,20:17.1
-3,1,20:18.1
3,1,20:18.1
4,1,20:17.1
5,1,20:18.1
-4,2,20:18.1
-3,2,20:18.1
4,2,20:18.1
4,3,20:18.1
-6,-8,21:18.1
-5,-8,21:17.1
-4,-8,21:18.1
2,-8,21:18.1
-6,-7,21:18.1
-5,-7,21:18.1
-4,-7,21:18.1
-3,-7,21:18.1
2,-7,21:18.1
-4,-6,21:18.1
-3,-6,21:17.1
-3,-5,21:18.1
-2,-5,21:17.1
-1,-5,21:17.1
-3,-4,21:18.1
-2,-4,21:18.1
-1,-4,21:17.1
0,-4,21:17.1
2,-4,21:18.1
0,-3,21:17.1
1,-3,21:18.1
2,-3,21:18.1
3,-3,21:18.1
2,-2,21:18.1
3,-2,21:18.1
4,-2,21:18.1
3,-1,21:18.1
-4,0,21:18.1
-3,0,21:17.1
-2,0,21:18.1
3,0,21:18.1
4,0,21:18.1
5,0,21:18.1
-5,1,21:18.1
-4,1,21:18.1
-3,1,21:18.1
3,1,21:18.1
4,1,21:17.1
5,1,21:18.1
-4,2,21:18.1
4,2,21:18.1
5,2,21:18.1
-6,-8,22:18.1
-5,-8,22:17.1
-4,-8,22:18.1
-3,-8,22:18.1
2,-8,22:18.1
-5,-7,22:18.1
-4,-7,22:17.1
-3,-7,22:18.1
2,-7,22:18.1
4,-7,22:18.1
-4,-6,22:18.1
-3,-6,22:17.1
-2,-6,22:18.1
2,-6,22:18.1
3,-6,22:18.1
-3,-5,22:18.1
-2,-5,22:18.1
-1,-5,22:18.1
2,-5,22:18.1
4,-5,22:18.1
-2,-4,22:18.1
0,-3,22:17.1
3,-2,22:18.1
-3,-1,22:18.1
-2,-1,22:18.1
2,-1,22:18.1
3,-1,22:18.1
4,-1,22:18.1
-4,0,22:18.1
-3,0,22:17.1
-2,0,22:18.1
2,0,22:18.1
3,0,22:18.1
4,0,22:17.1
-4,1,22:18.1
-3,1,22:18.1
-2,1,22:18.1
3,1,22:18.1
4,1,22:18.1
5,1,22:18.1
4,2,22:18.1
-5,-8,23:18.1
-4,-8,23:18.1
2,-8,23:18.1
-4,-7,23:17.1
-3,-7,23:18.1
2,-7,23:18.1
3,-7,23:18.1
4,-7,23:18.1
-3,-6,23:18.1
-2,-6,23:18.1
1,-6,23:18.1
2,-6,23:17.1
3,-6,23:18.1
2,-5,23:18.1
3,-5,23:18.1
4,-5,23:18.1
-1,-3,23:18.1
0,-3,23:17.1
1,-3,23:17.1
-2,-2,23:18.1
-1,-2,23:18.1
0,-2,23:18.1
2,-2,23:18.1
3,-2,23:18.1
4,-2,23:18.1
-3,-1,23:18.1
-2,-1,23:17.1
-1,-1,23:18.1
2,-1,23:18.1
3,-1,23:17.1
4,-1,23:18.1
-4,0,23:18.1
-3,0,23:18.1
-2,0,23:18.1
3,0,23:18.1
4,0,23:18.1
-3,1,23:18.1
-4,-8,24:18.1
-4,-7,24:18.1
2,-7,24:18.1
3,-7,24:18.1
-3,-6,24:18.1
1,-6,24:18.1
2,-6,24:17.1
3,-6,24:18.1
2,-5,24:18.1
3,-5,24:18.1
4,-5,24:18.1
2,-4,24:18.1
-1,-3,24:18.1
0,-3,24:17.1
1,-3,24:17.1
-2,-2,24:18.1
-1,-2,24:17.1
0,-2,24:18.1
1,-2,24:18.1
2,-2,24:17.1
3,-2,24:17.1
-3,-1,24:18.1
-2,-1,24:17.1
-1,-1,24:18.1
0,-1,24:18.1
2,-1,24:18.1
3,-1,24:18.1
4,-1,24:18.1
-3,0,24:18.1
-2,0,24:18.1
2,-6,25:18.1
3,-6,25:18.1
1,-5,25:18.1
2,-5,25:17.1
3,-5,25:18.1
-1,-4,25:18.1
0,-4,25:18.1
1,-4,25:18.1
2,-4,25:18.1
3,-4,25:18.1
-2,-3,25:18.1
-1,-3,25:18.1
0,-3,25:17.1
1,-3,25:18.1
-3,-2,25:18.1
-2,-2,25:18.1
-1,-2,25:17.1
0,-2,25:18.1
1,-2,25:18.1
2,-2,25:18.1
-2,-1,25:18.1
-1,-1,25:18.1
2,-6,26:18.1
1,-5,26:18.1
2,-5,26:18.1
3,-5,26:18.1
-1,-4,26:18.1
0,-4,26:18.1
1,-4,26:17.1
2,-4,26:18.1
-2,-3,26:18.1
-1,-3,26:17.1
0,-3,26:17.1
1,-3,26:18.1
2,-3,26:18.1
-2,-2,26:18.1
-1,-2,26:18.1
0,-2,26:18.1
-2,-7,27:18.1
-3,-6,27:18.1
-2,-6,27:18.1
0,-5,27:18.1
1,-5,27:18.1
2,-5,27:18.1
-2,-4,27:18.1
-1,-4,27:18.1
0,-4,27:17.1
1,-4,27:17.1
2,-4,27:18.1
-2,-3,27:18.1
-1,-3,27:18.1
0,-3,27:17.1
1,-3,27:17.1
-1,-2,27:18.1
4,-1,27:18.1
2,0,27:18.1
-3,-6,28:18.1
-2,-6,28:18.1
-3,-5,28:18.1
-2,-5,28:18.1
-1,-5,28:18.1
-2,-4,28:17.1
-1,-4,28:18.1
0,-4,28:18.1
1,-4,28:18.1
-2,-3,28:18.1
-1,-3,28:18.1
0,-3,28:17.1
1,-3,28:18.1
3,-3,28:18.1
-1,-2,28:18.1
0,-2,28:18.1
2,-2,28:18.1
3,-2,28:18.1
4,-2,28:18.1
2,-1,28:18.1
3,-1,28:18.1
4,-1,28:18.1
5,-1,28:18.1
2,0,28:18.1
-2,-6,29:18.1
-3,-5,29:18.1
-2,-5,29:18.1
-1,-5,29:18.1
-3,-4,29:18.1
-2,-4,29:18.1
-1,-4,29:17.1
0,-4,29:17.1
1,-4,29:18.1
-2,-3,29:18.1
-1,-3,29:18.1
0,-3,29:17.1
1,-3,29:18.1
2,-3,29:18.1
3,-3,29:18.1
-2,-2,29:18.1
-1,-2,29:18.1
0,-2,29:18.1
1,-2,29:18.1
2,-2,29:18.1
3,-2,29:18.1
4,-2,29:18.1
-2,-1,29:18.1
2,-1,29:17.1
3,-1,29:18.1
4,-1,29:18.1
2,0,29:18.1
-1,-5,30:18.1
0,-5,30:18.1
-2,-4,30:18.1
-1,-4,30:18.1
0,-4,30:18.1
1,-4,30:18.1
-1,-3,30:18.1
0,-3,30:17.1
1,-3,30:17.1
2,-3,30:18.1
3,-3,30:18.1
-2,-2,30:18.1
-1,-2,30:18.1
0,-2,30:18.1
1,-2,30:17.1
2,-2,30:17.1
3,-2,30:18.1
4,-2,30:18.1
-3,-1,30:18.1
-2,-1,30:18.1
-1,-1,30:18.1
1,-1,30:18.1
2,-1,30:18.1
-2,0,30:18.1
0,-4,31:18.1
2,-4,31:18.1
-2,-3,31:18.1
-1,-3,31:18.1
0,-3,31:17.1
1,-3,31:18.1
2,-3,31:18.1
-2,-2,31:18.1
-1,-2,31:17.1
0,-2,31:18.1
1,-2,31:18.1
2,-2,31:18.1
-2,-1,31:18.1
-1,-1,31:18.1
0,-1,31:18.1
0,0,31:18.1
0,-4,32:18.1
2,-4,32:18.1
-1,-3,32:18.1
0,-3,32:17.1
1,-3,32:18.1
-2,-2,32:18.1
-1,-2,32:18.1
0,-2,32:18.1
-1,-1,32:18.1
0,-1,32:18.1
-1,-4,33:18.1
0,-4,33:18.1
-1,-3,33:18.1
0,-3,33:17.1
1,-3,33:18.1
2,-3,33:18.1
0,-2,33:18.1
1,-2,33:18.1
0,-4,34:18.1
0,-3,34:18.1
1,-3,34:18.1
-1,-2,34:18.1
0,-2,34:18.1
-2,-3,35:18.1
-1,-3,35:18.1
0,-3,35:18.1
1,-3,35:18.1
0,-2,35:18.1
-1,-3,36:18.1
-1,-3,7:106.8
-1,-4,7:106.8
-2,-2,6:106.8
-1,-3,6:106.8
-1,-4,6:106.8
-1,-1,5:106.4
-2,-2,5:106.8
-1,-3,5:106.8
-1,-4,5:106.8
-1,-1,4:106.4
-2,-2,4:106.8
-1,-3,4:106.8
-1,-4,4:106.8
0,-1,3:106.4
-1,-1,3:106.4
1,-2,3:106.2
-2,-2,3:106.8
-1,-3,3:106.8
1,-4,3:106.1
-1,-4,3:106.8
0,-5,3:106.1
1,0,2:106.4
2,-1,2:106.2
0,-1,2:106.4
-1,-1,2:106.4
1,-2,2:106.2
-2,-2,2:106.8
-1,-3,2:106.8
2,-4,2:106.1
1,-4,2:106.1
-1,-4,2:106.8
0,-5,2:106.1
1,0,1:106.4
2,-1,1:106.2
0,-1,1:106.4
1,-2,1:106.2
-2,-2,1:106.8
-1,-3,1:106.8
-3,-3,1:106.8
2,-4,1:106.1
1,-4,1:106.1
-1,-4,1:106.8
-1,-5,1:106.8
2,1,0:106.4
-2,1,0:106.4
3,0,0:106.2
1,0,0:106.4
0,0,0:106.4
-1,0,0:106.4
-3,0,0:106.8
1,-2,0:106.2
-2,-2,0:106.8
-1,-3,0:106.8
-3,-3,0:106.8
3,-4,0:106.2
1,-4,0:106.1
-1,-4,0:106.8
-4,-4,0:106.8
2,-5,0:106.1
1,-5,0:106.2
-1,-5,0:106.8
-2,-6,0:106.8
