[META]
version=2.0
spawnOnBlockType=2
spawnSunlight=True
spawnDarkness=True
spawnWater=False
spawnLava=False
underFill=False
randomRotation=True
dig=True
tree=True
branch=False
needsFoundation=True
rarity=20
collisionPercentage=20
spawnElevationMin=0
spawnElevationMax=200
spawnInBiome=Custom
[DATA]
-5,-4,-3:17.1
-1,-4,-3:17.1
-2,-3,-3:17.1
-6,-2,-3:17.1
-4,-2,-3:17.1
-2,-2,-3:17.1
-3,-1,-3:17.1
0,-1,-3:17.1
-6,0,-3:17.1
0,0,-3:17.1
1,0,-3:17.1
-5,1,-3:17.1
-3,1,-3:17.1
-1,1,-3:17.1
1,1,-3:17.1
-6,2,-3:17.1
0,2,-3:17.1
-2,3,-3:17.1
-6,4,-3:17.1
0,4,-3:17.1
-5,5,-3:17.1
-3,5,-3:17.1
-1,5,-3:17.1
-5,6,-3:17.1
-1,-4,-2:17.1
-5,-3,-2:17.1
-1,-3,-2:17.1
-6,-2,-2:17.1
-4,-2,-2:17.1
-2,-2,-2:17.1
-7,-1,-2:17.1
-3,-1,-2:17.1
-6,0,-2:17.1
-3,0,-2:17.1
-1,0,-2:17.1
0,0,-2:17.1
-5,1,-2:17.1
-3,1,-2:17.1
-2,1,-2:17.1
-1,1,-2:17.1
1,1,-2:17.1
-5,2,-2:17.1
-3,2,-2:17.1
-4,3,-2:17.1
-3,3,-2:17.1
-2,3,-2:17.1
-5,4,-2:17.1
-1,4,-2:17.1
-5,5,-2:17.1
-5,6,-2:17.1
-5,-3,-1:17.1
-1,-3,-1:17.1
-4,-2,-1:17.1
-2,-2,-1:17.1
-3,-1,-1:17.1
-6,0,-1:17.1
-3,0,-1:17.1
-1,0,-1:17.1
0,0,-1:17.1
-5,1,-1:17.1
-3,1,-1:17.1
-2,1,-1:17.1
-1,1,-1:17.1
1,1,-1:17.1
-4,2,-1:17.1
-3,2,-1:17.1
-4,3,-1:17.1
-3,3,-1:17.1
-2,3,-1:17.1
-5,4,-1:17.1
-1,4,-1:17.1
-5,5,-1:17.1
-5,-3,0:17.1
-1,-3,0:17.1
-4,-2,0:17.1
-2,-2,0:17.1
-3,-1,0:17.1
-6,0,0:17.1
-3,0,0:17.1
-1,0,0:17.1
0,0,0:17.1
-5,1,0:17.1
-3,1,0:17.1
-2,1,0:17.1
-1,1,0:17.1
1,1,0:17.1
-4,2,0:17.1
-3,2,0:17.1
-4,3,0:17.1
-3,3,0:17.1
-2,3,0:17.1
-5,4,0:17.1
-1,4,0:17.1
-5,5,0:17.1
-4,-2,1:17.1
-3,-1,1:17.1
-3,0,1:17.1
-5,1,1:17.1
-3,1,1:17.1
-2,1,1:17.1
-1,1,1:17.1
-4,2,1:17.1
-3,2,1:17.1
-4,3,1:17.1
-2,3,1:17.1
-5,4,1:17.1
-1,4,1:17.1
-3,-1,2:17.1
-3,0,2:17.1
-3,1,2:17.1
-2,1,2:17.1
-1,1,2:17.1
-4,2,2:17.1
-3,2,2:17.1
-2,3,2:17.1
1,4,2:18.1
-7,5,2:18.1
-6,-3,3:18.1
1,-2,3:18.1
-3,-1,3:17.1
-3,0,3:17.1
-3,1,3:17.1
-2,1,3:17.1
-4,2,3:17.1
-3,2,3:17.1
-6,4,3:18.1
1,4,3:18.1
-7,5,3:18.1
0,-4,4:18.1
-6,-3,4:18.1
1,-2,4:18.1
-3,0,4:17.1
-3,1,4:17.1
-2,1,4:17.1
-4,2,4:17.1
-6,3,4:18.1
-6,4,4:18.1
0,4,4:18.1
1,4,4:18.1
-7,5,4:18.1
0,-4,5:18.1
-6,-3,5:18.1
0,-3,5:18.1
-6,-2,5:18.1
-1,-2,5:18.1
0,-2,5:18.1
1,-2,5:18.1
0,-1,5:18.1
-3,0,5:17.1
-3,1,5:17.1
-2,1,5:17.1
-4,2,5:17.1
-6,3,5:18.1
-5,3,5:18.1
-1,3,5:18.1
0,3,5:18.1
-7,4,5:18.1
-6,4,5:17.1
-5,4,5:18.1
0,4,5:17.1
1,4,5:18.1
2,4,5:18.1
-7,5,5:18.1
-6,5,5:18.1
0,5,5:18.1
1,5,5:18.1
0,-4,6:18.1
3,-4,6:18.1
-6,-3,6:18.1
-1,-3,6:18.1
0,-3,6:18.1
1,-3,6:18.1
-7,-2,6:18.1
-6,-2,6:17.1
-1,-2,6:18.1
0,-2,6:17.1
1,-2,6:18.1
-6,-1,6:18.1
-2,-1,6:18.1
-1,-1,6:18.1
0,-1,6:18.1
1,-1,6:18.1
-3,0,6:17.1
-1,0,6:18.1
0,0,6:18.1
-3,1,6:17.1
-2,1,6:17.1
-4,2,6:17.1
-1,2,6:18.1
-6,3,6:18.1
-2,3,6:18.1
-1,3,6:17.1
0,3,6:18.1
1,3,6:18.1
-7,4,6:18.1
-6,4,6:17.1
-5,4,6:18.1
-1,4,6:18.1
0,4,6:18.1
1,4,6:18.1
-6,5,6:18.1
0,5,6:18.1
2,8,6:18.1
2,-5,7:18.1
3,-4,7:18.1
-6,-3,7:18.1
0,-3,7:18.1
-7,-2,7:18.1
-6,-2,7:17.1
-2,-2,7:18.1
-1,-2,7:18.1
0,-2,7:18.1
1,-2,7:18.1
-6,-1,7:18.1
-2,-1,7:18.1
-1,-1,7:17.1
0,-1,7:18.1
-6,0,7:18.1
-3,0,7:17.1
-2,0,7:17.1
-1,0,7:18.1
0,0,7:18.1
-3,1,7:17.1
-2,1,7:17.1
-1,1,7:18.1
-5,2,7:18.1
-4,2,7:17.1
-2,2,7:17.1
-1,2,7:18.1
0,2,7:18.1
-6,3,7:18.1
-5,3,7:17.1
-4,3,7:18.1
-2,3,7:18.1
-1,3,7:17.1
0,3,7:18.1
1,3,7:18.1
-5,4,7:18.1
-1,4,7:18.1
0,4,7:18.1
-7,7,7:18.1
4,7,7:18.1
2,8,7:18.1
2,-5,8:18.1
2,-4,8:17.1
3,-4,8:18.1
1,-3,8:18.1
2,-3,8:18.1
3,-3,8:18.1
-6,-2,8:18.1
-1,-2,8:18.1
2,-2,8:18.1
-6,-1,8:18.1
-5,-1,8:17.1
-2,-1,8:18.1
-1,-1,8:18.1
0,-1,8:18.1
-6,0,8:18.1
-5,0,8:18.1
-4,0,8:17.1
-3,0,8:17.1
-1,0,8:18.1
-3,1,8:17.1
-2,1,8:17.1
-6,2,8:18.1
-5,2,8:18.1
-4,2,8:17.1
-2,2,8:17.1
-1,2,8:18.1
-6,3,8:18.1
-5,3,8:17.1
-4,3,8:17.1
-2,3,8:18.1
-1,3,8:18.1
0,3,8:18.1
-6,4,8:18.1
-5,4,8:18.1
-4,4,8:18.1
-1,4,8:18.1
-7,5,8:18.1
-6,5,8:18.1
-7,6,8:18.1
-7,7,8:18.1
4,7,8:18.1
2,8,8:18.1
3,8,8:18.1
2,9,8:18.1
1,-4,9:18.1
2,-4,9:18.1
3,-4,9:18.1
-8,-3,9:18.1
1,-3,9:18.1
2,-3,9:17.1
3,-3,9:18.1
1,-2,9:18.1
2,-2,9:18.1
3,-2,9:18.1
-5,-1,9:18.1
-1,-1,9:18.1
-5,0,9:18.1
-4,0,9:17.1
-3,0,9:17.1
-4,1,9:17.1
-3,1,9:17.1
-2,1,9:17.1
-5,2,9:18.1
-4,2,9:17.1
-3,2,9:17.1
-6,3,9:18.1
-5,3,9:18.1
-4,3,9:18.1
-7,4,9:18.1
-6,4,9:18.1
-5,4,9:18.1
-7,5,9:18.1
-6,5,9:17.1
-5,5,9:18.1
-7,6,9:18.1
-6,6,9:18.1
3,7,9:18.1
4,7,9:18.1
1,8,9:18.1
2,8,9:17.1
3,8,9:18.1
2,9,9:18.1
-7,-5,10:18.1
2,-4,10:18.1
-8,-3,10:18.1
1,-3,10:18.1
2,-3,10:17.1
3,-3,10:18.1
0,-2,10:18.1
1,-2,10:17.1
2,-2,10:18.1
-1,-1,10:18.1
0,-1,10:18.1
1,-1,10:18.1
-4,0,10:18.1
-3,0,10:18.1
-2,0,10:17.1
-1,0,10:17.1
0,0,10:18.1
-4,1,10:18.1
-3,1,10:17.1
-2,1,10:17.1
-4,2,10:17.1
-3,2,10:17.1
-5,3,10:18.1
-6,4,10:18.1
-5,4,10:17.1
-4,4,10:18.1
-9,5,10:18.1
-7,5,10:18.1
-6,5,10:18.1
-5,5,10:18.1
-6,6,10:18.1
2,7,10:18.1
1,8,10:18.1
2,8,10:17.1
3,8,10:18.1
2,9,10:18.1
-7,-5,11:18.1
-7,-4,11:18.1
-8,-3,11:18.1
-7,-3,11:18.1
-6,-3,11:18.1
1,-3,11:18.1
2,-3,11:18.1
0,-2,11:18.1
1,-2,11:17.1
2,-2,11:18.1
-6,-1,11:18.1
-1,-1,11:18.1
0,-1,11:17.1
1,-1,11:18.1
2,-1,11:18.1
-3,0,11:18.1
-1,0,11:17.1
0,0,11:18.1
1,0,11:18.1
-3,1,11:17.1
-2,1,11:17.1
-4,2,11:17.1
-3,2,11:17.1
4,2,11:18.1
-5,3,11:18.1
-4,3,11:18.1
-3,3,11:17.1
-2,3,11:17.1
-6,4,11:18.1
-5,4,11:17.1
-4,4,11:18.1
-9,5,11:18.1
-6,5,11:18.1
-5,5,11:18.1
-4,5,11:18.1
1,6,11:18.1
0,7,11:18.1
1,7,11:17.1
2,7,11:17.1
1,8,11:18.1
2,8,11:18.1
-8,-4,12:18.1
-7,-4,12:18.1
-6,-4,12:18.1
-8,-3,12:18.1
-7,-3,12:17.1
-6,-3,12:18.1
-4,-3,12:18.1
1,-3,12:18.1
-7,-2,12:18.1
-6,-2,12:18.1
-5,-2,12:18.1
-1,-2,12:18.1
0,-2,12:18.1
1,-2,12:18.1
2,-2,12:18.1
-6,-1,12:18.1
-1,-1,12:18.1
0,-1,12:18.1
1,-1,12:18.1
-2,0,12:18.1
-1,0,12:18.1
0,0,12:18.1
-3,1,12:17.1
-2,1,12:17.1
-5,2,12:18.1
-4,2,12:17.1
-3,2,12:17.1
1,2,12:18.1
2,2,12:18.1
3,2,12:18.1
4,2,12:18.1
-5,3,12:18.1
-4,3,12:17.1
-3,3,12:17.1
-2,3,12:17.1
3,3,12:18.1
4,3,12:18.1
-9,4,12:18.1
-6,4,12:18.1
-5,4,12:18.1
-4,4,12:18.1
-3,4,12:18.1
-2,4,12:17.1
-1,4,12:18.1
-9,5,12:18.1
-8,5,12:18.1
-7,5,12:18.1
-5,5,12:18.1
-2,5,12:18.1
-1,5,12:18.1
0,5,12:18.1
5,5,12:18.1
-1,6,12:18.1
0,6,12:17.1
1,6,12:18.1
2,6,12:18.1
0,7,12:18.1
1,7,12:17.1
2,7,12:18.1
0,8,12:18.1
1,8,12:18.1
-5,10,12:18.1
1,-5,13:18.1
-7,-4,13:18.1
-8,-3,13:18.1
-7,-3,13:18.1
-6,-3,13:18.1
-4,-3,13:18.1
-7,-2,13:18.1
-6,-2,13:17.1
-5,-2,13:18.1
-6,-1,13:18.1
-5,-1,13:18.1
-1,-1,13:18.1
-2,0,13:18.1
-1,0,13:18.1
-3,1,13:17.1
-2,1,13:17.1
3,1,13:18.1
-5,2,13:18.1
-4,2,13:18.1
1,2,13:18.1
2,2,13:17.1
3,2,13:18.1
4,2,13:18.1
-9,3,13:18.1
-5,3,13:18.1
-4,3,13:18.1
-3,3,13:18.1
1,3,13:18.1
2,3,13:18.1
3,3,13:18.1
-9,4,13:18.1
-8,4,13:18.1
-4,4,13:18.1
-2,4,13:17.1
-1,4,13:18.1
0,4,13:18.1
-9,5,13:18.1
-8,5,13:18.1
-7,5,13:17.1
-6,5,13:18.1
-2,5,13:18.1
-1,5,13:17.1
0,5,13:18.1
5,5,13:18.1
-9,6,13:18.1
-8,6,13:18.1
-2,6,13:18.1
-1,6,13:18.1
0,6,13:17.1
1,6,13:18.1
0,7,13:18.1
1,7,13:18.1
-6,8,13:18.1
-5,10,13:18.1
2,-7,14:18.1
2,-6,14:18.1
1,-5,14:18.1
-6,-3,14:18.1
-5,-3,14:18.1
-4,-3,14:18.1
0,-3,14:18.1
1,-3,14:18.1
-7,-2,14:18.1
-6,-2,14:18.1
-5,-2,14:17.1
-4,-2,14:18.1
-6,-1,14:18.1
-5,-1,14:18.1
-4,-1,14:18.1
-5,0,14:18.1
-2,0,14:18.1
-4,1,14:17.1
-3,1,14:17.1
-2,1,14:17.1
2,1,14:18.1
3,1,14:18.1
-5,2,14:18.1
-4,2,14:18.1
0,2,14:18.1
1,2,14:18.1
2,2,14:17.1
3,2,14:18.1
1,3,14:18.1
2,3,14:18.1
-8,4,14:18.1
-7,4,14:18.1
-6,4,14:18.1
-1,4,14:18.1
-9,5,14:18.1
-8,5,14:18.1
-7,5,14:17.1
-6,5,14:18.1
-2,5,14:18.1
-1,5,14:18.1
0,5,14:18.1
4,5,14:18.1
5,5,14:18.1
-8,6,14:18.1
-7,6,14:18.1
-1,6,14:18.1
0,6,14:18.1
-5,7,14:18.1
4,7,14:18.1
-6,8,14:18.1
-5,8,14:17.1
-4,8,14:18.1
-5,9,14:18.1
-5,10,14:18.1
2,-7,15:18.1
1,-6,15:18.1
2,-6,15:18.1
1,-5,15:18.1
0,-4,15:18.1
1,-4,15:18.1
-5,-3,15:18.1
-1,-3,15:18.1
0,-3,15:18.1
1,-3,15:17.1
2,-3,15:18.1
-6,-2,15:18.1
-5,-2,15:18.1
-4,-2,15:18.1
0,-2,15:18.1
1,-2,15:18.1
-6,-1,15:18.1
-5,-1,15:17.1
-4,-1,15:18.1
-2,-1,15:18.1
-5,0,15:18.1
-4,0,15:17.1
-3,0,15:18.1
-2,0,15:18.1
-1,0,15:18.1
-4,1,15:17.1
-3,1,15:17.1
-2,1,15:17.1
0,1,15:18.1
1,1,15:18.1
2,1,15:18.1
0,2,15:18.1
1,2,15:17.1
2,2,15:18.1
-6,3,15:18.1
0,3,15:18.1
1,3,15:18.1
2,3,15:18.1
-7,4,15:18.1
-6,4,15:17.1
-5,4,15:18.1
3,4,15:18.1
-8,5,15:18.1
-7,5,15:18.1
-6,5,15:18.1
2,5,15:18.1
3,5,15:17.1
4,5,15:18.1
5,5,15:18.1
-7,6,15:18.1
4,6,15:18.1
-6,7,15:18.1
-5,7,15:18.1
-4,7,15:18.1
4,7,15:18.1
-6,8,15:18.1
-5,8,15:17.1
-4,8,15:18.1
-6,9,15:18.1
-5,9,15:18.1
-4,9,15:18.1
1,-7,16:18.1
2,-7,16:18.1
0,-6,16:18.1
1,-6,16:17.1
2,-6,16:18.1
0,-5,16:18.1
1,-5,16:18.1
2,-5,16:18.1
-1,-4,16:18.1
0,-4,16:18.1
1,-4,16:18.1
-1,-3,16:18.1
0,-3,16:18.1
1,-3,16:17.1
2,-3,16:18.1
-5,-2,16:18.1
-1,-2,16:18.1
0,-2,16:18.1
1,-2,16:18.1
-6,-1,16:18.1
-5,-1,16:18.1
-4,-1,16:18.1
-3,-1,16:18.1
-2,-1,16:18.1
-1,-1,16:18.1
-5,0,16:18.1
-4,0,16:17.1
-3,0,16:18.1
-2,0,16:17.1
-1,0,16:18.1
-4,1,16:18.1
-3,1,16:17.1
-2,1,16:17.1
-1,1,16:17.1
0,1,16:17.1
1,1,16:18.1
-5,2,16:18.1
-4,2,16:18.1
-3,2,16:18.1
0,2,16:18.1
1,2,16:18.1
2,2,16:18.1
-7,3,16:18.1
-6,3,16:18.1
-5,3,16:18.1
-4,3,16:18.1
-3,3,16:18.1
-2,3,16:18.1
1,3,16:18.1
2,3,16:18.1
-7,4,16:18.1
-6,4,16:17.1
-5,4,16:18.1
-3,4,16:18.1
1,4,16:18.1
2,4,16:18.1
3,4,16:18.1
4,4,16:18.1
-7,5,16:18.1
-6,5,16:18.1
-5,5,16:18.1
-4,5,16:18.1
2,5,16:18.1
3,5,16:17.1
4,5,16:18.1
-5,6,16:18.1
-4,6,16:18.1
-3,6,16:18.1
3,6,16:18.1
4,6,16:18.1
-5,7,16:18.1
-4,7,16:17.1
-3,7,16:18.1
-6,8,16:18.1
-5,8,16:18.1
-4,8,16:18.1
-5,9,16:18.1
1,-7,17:18.1
0,-6,17:18.1
1,-6,17:17.1
2,-6,17:18.1
-9,-5,17:18.1
0,-5,17:18.1
1,-5,17:18.1
0,-4,17:18.1
-9,-3,17:18.1
-1,-3,17:18.1
0,-3,17:18.1
1,-3,17:18.1
-1,-2,17:18.1
0,-2,17:17.1
1,-2,17:18.1
-2,-1,17:18.1
-1,-1,17:18.1
0,-1,17:18.1
-3,0,17:18.1
-2,0,17:18.1
-1,0,17:18.1
-5,1,17:18.1
-4,1,17:18.1
-3,1,17:17.1
-2,1,17:17.1
-5,2,17:18.1
-4,2,17:17.1
-3,2,17:17.1
-2,2,17:18.1
-6,3,17:18.1
-5,3,17:17.1
-4,3,17:17.1
-3,3,17:18.1
-2,3,17:18.1
1,3,17:18.1
2,3,17:18.1
3,3,17:18.1
-7,4,17:18.1
-6,4,17:18.1
-5,4,17:18.1
-4,4,17:18.1
-3,4,17:18.1
-2,4,17:18.1
1,4,17:18.1
2,4,17:17.1
3,4,17:18.1
-6,5,17:18.1
-5,5,17:18.1
-4,5,17:18.1
-3,5,17:17.1
1,5,17:18.1
2,5,17:18.1
3,5,17:18.1
4,5,17:18.1
-9,6,17:18.1
-5,6,17:18.1
-4,6,17:17.1
-3,6,17:18.1
-2,6,17:17.1
2,6,17:18.1
3,6,17:18.1
-5,7,17:18.1
-4,7,17:18.1
-3,7,17:18.1
-4,8,17:18.1
0,-7,18:18.1
1,-7,18:18.1
0,-6,18:18.1
1,-6,18:17.1
-9,-5,18:18.1
-1,-5,18:18.1
0,-5,18:17.1
1,-5,18:18.1
2,-5,18:18.1
0,-4,18:18.1
-9,-3,18:18.1
-2,-2,18:18.1
-1,-2,18:18.1
0,-2,18:18.1
-2,-1,18:18.1
-1,-1,18:17.1
0,-1,18:18.1
-2,0,18:17.1
-1,0,18:17.1
0,0,18:18.1
-4,1,18:18.1
-3,1,18:17.1
-2,1,18:17.1
0,1,18:18.1
-5,2,18:18.1
-4,2,18:18.1
-3,2,18:18.1
-1,2,18:18.1
0,2,18:18.1
1,2,18:18.1
-4,3,18:18.1
-3,3,18:18.1
-2,3,18:18.1
0,3,18:18.1
1,3,18:17.1
2,3,18:18.1
-3,4,18:17.1
1,4,18:18.1
2,4,18:18.1
3,4,18:18.1
-4,5,18:18.1
-3,5,18:17.1
2,5,18:18.1
-9,6,18:18.1
-8,6,18:18.1
-5,6,18:18.1
-4,6,18:18.1
-3,6,18:18.1
-4,7,18:18.1
-7,8,18:18.1
-1,-6,19:18.1
0,-6,19:18.1
1,-6,19:18.1
-9,-5,19:18.1
-1,-5,19:18.1
0,-5,19:17.1
1,-5,19:18.1
-9,-4,19:18.1
-8,-4,19:18.1
-1,-4,19:18.1
0,-4,19:17.1
1,-4,19:18.1
-9,-3,19:18.1
0,-3,19:18.1
-1,-2,19:18.1
-2,-1,19:18.1
-1,-1,19:18.1
0,-1,19:18.1
-1,0,19:18.1
-3,1,19:17.1
-2,1,19:17.1
-1,1,19:18.1
0,1,19:18.1
1,1,19:18.1
-3,2,19:17.1
-1,2,19:18.1
0,2,19:17.1
1,2,19:18.1
-3,3,19:17.1
-1,3,19:18.1
0,3,19:18.1
1,3,19:17.1
-7,4,19:18.1
-7,5,19:18.1
-6,5,19:18.1
-8,6,19:18.1
-7,6,19:18.1
2,6,19:18.1
-7,7,19:18.1
-7,8,19:18.1
0,-6,20:18.1
-9,-5,20:18.1
-8,-5,20:18.1
-1,-5,20:18.1
0,-5,20:18.1
-9,-4,20:17.1
-8,-4,20:18.1
-7,-4,20:18.1
-2,-4,20:18.1
-1,-4,20:18.1
0,-4,20:17.1
1,-4,20:18.1
-9,-3,20:18.1
-8,-3,20:18.1
-3,-3,20:18.1
-2,-3,20:18.1
-1,-3,20:17.1
0,-3,20:18.1
1,-3,20:18.1
-2,-2,20:18.1
-4,-1,20:18.1
-5,0,20:18.1
-4,0,20:17.1
-3,0,20:18.1
-4,1,20:18.1
-3,1,20:17.1
-2,1,20:17.1
-1,1,20:17.1
0,1,20:18.1
-3,2,20:17.1
-1,2,20:17.1
0,2,20:17.1
1,2,20:18.1
0,3,20:18.1
-7,4,20:18.1
-6,4,20:18.1
-5,4,20:18.1
1,4,20:18.1
-8,5,20:18.1
-7,5,20:17.1
-6,5,20:18.1
1,5,20:18.1
2,5,20:18.1
-8,6,20:18.1
-7,6,20:18.1
-6,6,20:18.1
2,6,20:18.1
-7,7,20:18.1
-9,-5,21:18.1
-8,-5,21:18.1
0,-5,21:18.1
-9,-4,21:17.1
-8,-4,21:18.1
-7,-4,21:18.1
-3,-4,21:18.1
-2,-4,21:18.1
-1,-4,21:18.1
0,-4,21:18.1
-9,-3,21:18.1
-8,-3,21:18.1
-7,-3,21:18.1
-6,-3,21:18.1
-3,-3,21:18.1
-2,-3,21:17.1
-1,-3,21:17.1
0,-3,21:18.1
1,-3,21:18.1
-7,-2,21:18.1
-6,-2,21:17.1
-5,-2,21:18.1
-3,-2,21:18.1
-2,-2,21:17.1
-1,-2,21:18.1
1,-2,21:18.1
-6,-1,21:18.1
-5,-1,21:17.1
-4,-1,21:17.1
-3,-1,21:18.1
-5,0,21:18.1
-4,0,21:17.1
-3,0,21:17.1
-5,1,21:18.1
-4,1,21:18.1
-3,1,21:17.1
-6,3,21:18.1
-5,3,21:18.1
1,3,21:18.1
-7,4,21:18.1
-6,4,21:17.1
-5,4,21:18.1
0,4,21:18.1
1,4,21:18.1
2,4,21:18.1
-8,5,21:18.1
-7,5,21:18.1
-6,5,21:18.1
-5,5,21:18.1
0,5,21:18.1
1,5,21:17.1
2,5,21:18.1
-7,6,21:18.1
1,6,21:18.1
2,6,21:18.1
-8,-5,22:18.1
-9,-4,22:18.1
-8,-4,22:17.1
-7,-4,22:18.1
-2,-4,22:18.1
-8,-3,22:18.1
-7,-3,22:17.1
-6,-3,22:18.1
-5,-3,22:18.1
-3,-3,22:18.1
-2,-3,22:18.1
-1,-3,22:18.1
-7,-2,22:18.1
-6,-2,22:17.1
-5,-2,22:18.1
-3,-2,22:17.1
-2,-2,22:17.1
-1,-2,22:18.1
1,-2,22:18.1
-7,-1,22:18.1
-6,-1,22:18.1
-5,-1,22:18.1
-4,-1,22:18.1
-5,0,22:18.1
-4,0,22:18.1
-3,0,22:17.1
-4,1,22:18.1
-3,1,22:17.1
-5,2,22:18.1
0,2,22:18.1
-6,3,22:18.1
-5,3,22:18.1
-1,3,22:18.1
0,3,22:18.1
1,3,22:18.1
-7,4,22:18.1
-6,4,22:17.1
-5,4,22:18.1
0,4,22:18.1
1,4,22:17.1
2,4,22:18.1
-6,5,22:18.1
0,5,22:18.1
1,5,22:18.1
2,5,22:18.1
1,6,22:18.1
-8,-4,23:18.1
-7,-4,23:18.1
-8,-3,23:18.1
-7,-3,23:17.1
-6,-3,23:18.1
-2,-3,23:18.1
-1,-3,23:18.1
-7,-2,23:18.1
-6,-2,23:18.1
-5,-2,23:18.1
-3,-2,23:17.1
-2,-2,23:18.1
-1,-2,23:18.1
1,-2,23:18.1
-6,-1,23:18.1
-3,-1,23:17.1
-3,0,23:17.1
-3,1,23:17.1
-2,1,23:17.1
-5,2,23:18.1
-1,2,23:18.1
0,2,23:18.1
-6,3,23:18.1
-5,3,23:17.1
-4,3,23:18.1
-1,3,23:18.1
0,3,23:17.1
1,3,23:18.1
-6,4,23:18.1
-5,4,23:18.1
0,4,23:18.1
1,4,23:18.1
-7,-3,24:18.1
-2,-3,24:18.1
-1,-3,24:18.1
0,-3,24:18.1
-6,-2,24:18.1
-3,-2,24:18.1
-2,-2,24:18.1
-1,-2,24:17.1
0,-2,24:18.1
1,-2,24:18.1
-3,-1,24:18.1
-2,-1,24:18.1
-1,-1,24:18.1
-4,1,24:18.1
-3,1,24:17.1
-2,1,24:17.1
-1,1,24:18.1
0,1,24:18.1
-5,2,24:18.1
-4,2,24:17.1
-3,2,24:18.1
-1,2,24:17.1
0,2,24:17.1
1,2,24:18.1
-6,3,24:18.1
-5,3,24:17.1
-4,3,24:18.1
-1,3,24:18.1
0,3,24:18.1
1,3,24:18.1
-6,4,24:18.1
-5,4,24:18.1
-1,4,24:18.1
0,4,24:18.1
-1,-3,25:18.1
-7,-2,25:18.1
-2,-2,25:18.1
-1,-2,25:18.1
0,-2,25:18.1
-3,-1,25:18.1
-2,-1,25:18.1
-1,-1,25:17.1
0,-1,25:18.1
-2,0,25:18.1
-1,0,25:18.1
0,0,25:18.1
-4,1,25:18.1
-3,1,25:17.1
-2,1,25:18.1
0,1,25:18.1
-5,2,25:18.1
-4,2,25:17.1
-3,2,25:18.1
-2,2,25:18.1
-1,2,25:18.1
0,2,25:18.1
1,2,25:18.1
-6,3,25:18.1
-5,3,25:18.1
-4,3,25:18.1
-1,3,25:18.1
0,3,25:18.1
-5,4,25:18.1
-6,6,25:18.1
-7,-2,26:18.1
-6,-2,26:18.1
-1,-2,26:18.1
-6,-1,26:18.1
-5,-1,26:18.1
-2,-1,26:18.1
-1,-1,26:18.1
-3,0,26:18.1
-2,0,26:17.1
-1,0,26:18.1
0,0,26:18.1
-4,1,26:17.1
-3,1,26:17.1
-2,1,26:18.1
-5,2,26:18.1
-4,2,26:18.1
-3,2,26:18.1
-2,2,26:18.1
-4,3,26:18.1
-8,4,26:18.1
-6,5,26:18.1
1,5,26:18.1
-6,6,26:18.1
-7,-2,27:18.1
-6,-2,27:18.1
-5,-2,27:18.1
-7,-1,27:18.1
-6,-1,27:17.1
-5,-1,27:18.1
-3,-1,27:18.1
-2,-1,27:18.1
-6,0,27:18.1
-5,0,27:18.1
-4,0,27:18.1
-3,0,27:17.1
-2,0,27:17.1
-1,0,27:18.1
-3,1,27:17.1
-2,1,27:17.1
-1,1,27:18.1
-4,2,27:18.1
-3,2,27:18.1
0,3,27:18.1
-8,4,27:18.1
-7,4,27:18.1
-6,4,27:18.1
-5,4,27:18.1
0,4,27:18.1
1,4,27:18.1
-6,5,27:18.1
1,5,27:18.1
-6,6,27:18.1
-6,-2,28:18.1
-7,-1,28:18.1
-6,-1,28:18.1
-5,-1,28:18.1
-4,-1,28:18.1
-6,0,28:18.1
-5,0,28:17.1
-4,0,28:18.1
-3,0,28:18.1
-2,0,28:18.1
-5,1,28:18.1
-4,1,28:18.1
-3,1,28:17.1
-2,1,28:18.1
-1,2,28:18.1
-5,3,28:18.1
-2,3,28:18.1
-1,3,28:18.1
0,3,28:18.1
1,3,28:18.1
-7,4,28:18.1
-6,4,28:17.1
-5,4,28:18.1
-1,4,28:18.1
0,4,28:17.1
1,4,28:18.1
-7,5,28:18.1
-6,5,28:18.1
-5,5,28:18.1
0,5,28:18.1
1,5,28:18.1
-6,6,28:18.1
-4,-4,29:18.1
-3,-3,29:18.1
-5,-1,29:18.1
-6,0,29:18.1
-5,0,29:18.1
-4,0,29:17.1
-3,0,29:17.1
-5,1,29:18.1
-3,1,29:17.1
-5,2,29:18.1
-2,2,29:18.1
-1,2,29:18.1
0,2,29:18.1
-6,3,29:18.1
-5,3,29:18.1
-4,3,29:18.1
-2,3,29:18.1
-1,3,29:17.1
0,3,29:18.1
-7,4,29:18.1
-6,4,29:17.1
-5,4,29:18.1
-4,4,29:18.1
-2,4,29:18.1
-1,4,29:18.1
0,4,29:18.1
1,4,29:18.1
-6,5,29:18.1
-5,5,29:18.1
0,5,29:18.1
-4,-4,30:18.1
-4,-3,30:18.1
-3,-3,30:18.1
-5,-2,30:18.1
-4,-2,30:18.1
-3,-2,30:18.1
-4,-1,30:18.1
-4,0,30:18.1
-3,1,30:17.1
-2,1,30:17.1
-5,2,30:18.1
-4,2,30:18.1
-2,2,30:17.1
-1,2,30:17.1
-6,3,30:18.1
-5,3,30:17.1
-4,3,30:18.1
-3,3,30:18.1
-2,3,30:18.1
-1,3,30:18.1
0,3,30:18.1
-6,4,30:18.1
-5,4,30:18.1
-4,4,30:18.1
-3,4,30:18.1
-1,4,30:18.1
-5,5,30:18.1
-4,-3,31:18.1
-3,-3,31:18.1
-5,-2,31:18.1
-4,-2,31:17.1
-3,-2,31:18.1
-5,-1,31:18.1
-4,-1,31:18.1
-3,-1,31:18.1
-4,0,31:18.1
-3,1,31:17.1
-5,2,31:18.1
-4,2,31:17.1
-3,2,31:18.1
-6,3,31:18.1
-5,3,31:18.1
-4,3,31:18.1
-3,3,31:18.1
-5,4,31:18.1
-4,4,31:18.1
-3,4,31:18.1
-4,5,31:18.1
-4,-2,32:18.1
-3,-2,32:18.1
-5,-1,32:18.1
-4,-1,32:17.1
-3,-1,32:18.1
-2,-1,32:18.1
0,-1,32:18.1
-5,0,32:18.1
-4,0,32:18.1
-3,0,32:18.1
-2,0,32:18.1
-4,1,32:18.1
-3,1,32:17.1
-2,1,32:18.1
-5,2,32:18.1
-4,2,32:17.1
-3,2,32:17.1
-5,3,32:18.1
-4,3,32:18.1
-3,3,32:18.1
-4,4,32:18.1
-4,-1,33:18.1
-3,-1,33:18.1
-2,-1,33:18.1
-1,-1,33:18.1
0,-1,33:18.1
-4,0,33:18.1
-3,0,33:17.1
-2,0,33:17.1
-1,0,33:18.1
-4,1,33:18.1
-3,1,33:17.1
-2,1,33:18.1
-5,2,33:18.1
-4,2,33:18.1
-3,2,33:18.1
-2,2,33:17.1
-2,5,33:18.1
-2,-1,34:18.1
-3,0,34:18.1
-2,0,34:18.1
-1,0,34:18.1
-4,1,34:18.1
-3,1,34:17.1
-2,1,34:18.1
-3,2,34:18.1
-2,2,34:18.1
-3,3,34:18.1
-2,3,34:18.1
-1,3,34:18.1
-2,4,34:18.1
-2,5,34:18.1
-4,-2,35:18.1
-3,1,35:17.1
-3,2,35:18.1
-2,2,35:18.1
-5,3,35:18.1
-3,3,35:18.1
-2,3,35:17.1
-1,3,35:18.1
-2,4,35:18.1
-1,4,35:18.1
-4,-2,36:18.1
-4,-1,36:18.1
-5,0,36:18.1
-4,0,36:18.1
-3,0,36:18.1
-6,1,36:18.1
-4,1,36:18.1
-3,1,36:17.1
-2,1,36:18.1
0,1,36:18.1
1,1,36:18.1
-3,2,36:17.1
-2,2,36:18.1
-5,3,36:18.1
-4,3,36:18.1
-3,3,36:18.1
-2,3,36:18.1
-1,3,36:18.1
-1,4,36:18.1
-3,-1,37:18.1
-2,-1,37:18.1
-4,0,37:17.1
-3,0,37:18.1
-6,1,37:18.1
-5,1,37:18.1
-4,1,37:18.1
-3,1,37:17.1
-2,1,37:17.1
-1,1,37:18.1
0,1,37:18.1
-4,2,37:18.1
-3,2,37:18.1
-2,2,37:18.1
-1,2,37:18.1
-4,3,37:18.1
-3,3,37:18.1
-2,3,37:18.1
-2,4,37:18.1
-4,0,38:18.1
-3,0,38:18.1
-2,0,38:18.1
-5,1,38:18.1
-4,1,38:17.1
-3,1,38:17.1
-2,1,38:18.1
-1,1,38:18.1
-5,2,38:18.1
-4,2,38:18.1
-3,2,38:18.1
-2,2,38:18.1
-4,3,38:18.1
-3,3,38:18.1
-2,3,38:18.1
-3,0,39:18.1
-4,1,39:18.1
-3,1,39:17.1
-2,1,39:17.1
-4,2,39:18.1
-3,2,39:18.1
-2,2,39:18.1
-3,3,39:18.1
-3,1,40:17.1
-2,1,40:18.1
-1,1,40:18.1
-3,2,40:18.1
-3,0,41:18.1
-4,1,41:18.1
-3,1,41:17.1
-3,2,41:18.1
-3,3,41:18.1
-3,-1,42:18.1
-3,0,42:18.1
-3,1,42:17.1
-2,1,42:18.1
-3,0,43:18.1
-4,1,43:18.1
-3,1,43:18.1
-3,2,43:18.1
-3,1,44:18.1
-2,1,44:18.1
-3,0,45:18.1
-3,1,45:18.1
-3,1,46:18.1
-3,0,14:106.1
-4,0,14:106.1
-4,1,13:106.8
-3,0,13:106.1
-4,0,13:106.1
-4,1,12:106.8
-3,0,12:106.1
-4,0,12:106.1
-4,1,11:106.8
-4,0,11:106.1
-2,-1,10:106.1
-3,-1,10:106.1
-2,-1,9:106.1
-3,-1,9:106.1
-3,2,8:106.4
-4,1,8:106.8
-3,-1,8:106.1
-3,2,7:106.4
-4,1,7:106.8
-3,-1,7:106.1
-3,2,6:106.4
-4,1,6:106.8
-2,0,6:106.1
-3,-1,6:106.1
-3,2,5:106.4
-4,1,5:106.8
-2,0,5:106.1
-3,-1,5:106.1
-3,2,4:106.4
-4,1,4:106.8
-2,0,4:106.1
-3,-1,4:106.1
-3,3,3:106.4
-2,2,3:106.2
-5,2,3:106.8
-4,1,3:106.8
-2,0,3:106.1
-4,-1,3:106.8
-3,-2,3:106.1
-1,3,2:106.2
-3,3,2:106.4
-2,2,2:106.2
-5,2,2:106.8
0,1,2:106.2
-4,1,2:106.8
-2,0,2:106.1
-2,-1,2:106.2
-4,-1,2:106.8
-3,-2,2:106.1
-1,5,1:106.4
-2,4,1:106.4
-4,4,1:106.2
-6,4,1:106.8
-1,3,1:106.2
-3,3,1:106.4
-5,3,1:106.1
-2,2,1:106.2
-5,2,1:106.8
0,1,1:106.2
-4,1,1:106.8
-6,1,1:106.8
-2,0,1:106.1
-4,0,1:106.8
-2,-1,1:106.2
-4,-1,1:106.8
-3,-2,1:106.1
-5,-2,1:106.8
-1,5,0:106.4
-4,5,0:106.2
-2,4,0:106.4
-4,4,0:106.2
-6,4,0:106.8
-1,3,0:106.2
-5,3,0:106.1
-2,2,0:106.2
-5,2,0:106.8
2,1,0:106.2
0,1,0:106.2
-4,1,0:106.8
-6,1,0:106.8
1,0,0:106.2
-2,0,0:106.1
-4,0,0:106.8
0,-1,0:106.1
-2,-1,0:106.2
-4,-1,0:106.8
-3,-2,0:106.1
-5,-2,0:106.8
-2,-3,0:106.1
-4,-3,0:106.1
-6,-3,0:106.8
-1,-4,0:106.1
-6,1,-1:106.8
