[META]
version=2.0
spawnOnBlockType=2
spawnSunlight=True
spawnDarkness=True
spawnWater=False
spawnLava=False
underFill=False
randomRotation=True
dig=True
tree=True
branch=False
needsFoundation=True
rarity=20
collisionPercentage=20
spawnElevationMin=0
spawnElevationMax=200
spawnInBiome=Custom
[DATA]
0,-5,-3:17.1
2,-5,-3:17.1
-2,-4,-3:17.1
-1,-4,-3:17.1
0,-4,-3:17.1
1,-4,-3:17.1
0,-3,-3:17.1
3,-3,-3:17.1
-3,-2,-3:17.1
0,-2,-3:17.1
2,-2,-3:17.1
3,-2,-3:17.1
4,-2,-3:17.1
-3,-1,-3:17.1
-2,-1,-3:17.1
0,-1,-3:17.1
1,-1,-3:17.1
2,-1,-3:17.1
0,0,-3:17.1
1,0,-3:17.5
2,0,-3:17.1
-1,1,-3:17.1
0,1,-3:17.1
3,1,-3:17.1
-3,2,-3:17.1
-2,2,-3:17.1
0,2,-3:17.1
-2,3,-3:17.1
1,3,-3:17.1
2,3,-3:17.1
-3,4,-3:17.1
1,4,-3:17.1
-2,-4,-2:17.1
-1,-4,-2:17.1
0,-4,-2:17.1
1,-4,-2:17.1
-1,-3,-2:17.1
0,-3,-2:17.1
2,-3,-2:17.1
-3,-2,-2:17.1
-1,-2,-2:17.1
0,-2,-2:17.1
2,-2,-2:17.1
3,-2,-2:17.1
4,-2,-2:17.1
-3,-1,-2:17.1
-2,-1,-2:17.1
0,-1,-2:17.1
1,-1,-2:17.1
2,-1,-2:17.1
3,-1,-2:17.1
-1,0,-2:17.1
0,0,-2:17.1
1,0,-2:17.1
-1,1,-2:17.1
0,1,-2:17.1
1,1,-2:17.1
3,1,-2:17.1
-3,2,-2:17.1
-2,2,-2:17.1
-1,2,-2:17.1
0,2,-2:17.1
-2,3,-2:17.1
0,3,-2:17.1
1,3,-2:17.1
1,4,-2:17.1
-2,-4,-1:17.1
-1,-4,-1:17.1
1,-4,-1:17.1
-1,-3,-1:17.1
0,-3,-1:17.1
-3,-2,-1:17.1
0,-2,-1:17.1
2,-2,-1:17.1
3,-2,-1:17.1
-2,-1,-1:17.1
-1,-1,-1:17.1
0,-1,-1:17.1
1,-1,-1:17.1
2,-1,-1:17.1
-2,0,-1:17.1
-1,0,-1:17.1
0,0,-1:17.1
1,0,-1:17.1
-1,1,-1:17.1
0,1,-1:17.1
-2,2,-1:17.1
-1,2,-1:17.1
0,2,-1:17.1
-3,3,-1:17.1
0,3,-1:17.1
1,3,-1:17.1
-1,-4,0:17.1
1,-4,0:17.1
0,-3,0:17.1
-3,-2,0:17.1
0,-2,0:17.1
2,-2,0:17.1
3,-2,0:17.1
4,-2,0:17.1
-2,-1,0:17.1
-1,-1,0:17.1
0,-1,0:17.1
1,-1,0:17.1
2,-1,0:17.1
-1,0,0:17.1
0,0,0:17.1
-1,1,0:17.1
0,1,0:17.1
-2,2,0:17.1
0,2,0:17.1
-3,3,0:17.1
1,3,0:17.1
0,-3,1:17.1
0,-2,1:17.1
3,-2,1:17.1
-2,-1,1:17.1
0,-1,1:17.1
1,-1,1:17.1
2,-1,1:17.1
-1,0,1:17.1
0,0,1:17.1
-1,1,1:17.1
0,1,1:17.1
-2,2,1:17.1
-3,-5,2:18.1
0,-2,2:17.1
0,-1,2:17.1
1,-1,2:17.1
2,-1,2:17.1
-1,0,2:17.1
0,0,2:17.1
0,1,2:17.1
-3,-5,3:18.1
-2,-5,3:18.1
-3,-4,3:18.1
-2,-4,3:18.1
0,-2,3:17.1
0,-1,3:17.1
1,-1,3:17.1
-1,0,3:17.1
0,0,3:17.1
-4,3,3:18.1
4,3,3:18.1
-3,-5,4:18.1
-2,-5,4:18.1
3,-5,4:18.1
4,-5,4:18.1
-3,-4,4:18.1
-2,-4,4:17.1
-1,-4,4:18.1
0,-2,4:17.1
0,-1,4:17.1
1,-1,4:17.1
-1,0,4:17.1
3,1,4:18.1
5,1,4:18.1
-3,2,4:18.1
3,2,4:18.1
4,2,4:18.1
-4,3,4:18.1
4,3,4:18.1
-2,-5,5:18.1
3,-5,5:18.1
-5,-4,5:18.1
-4,-4,5:18.1
-3,-4,5:18.1
-2,-4,5:18.1
-1,-4,5:18.1
2,-4,5:18.1
3,-4,5:18.1
4,-4,5:18.1
-2,-3,5:18.1
-1,-3,5:17.1
0,-3,5:18.1
3,-3,5:18.1
-3,-2,5:18.1
0,-2,5:17.1
0,-1,5:17.1
1,-1,5:17.1
-1,0,5:17.1
2,0,5:18.1
-5,1,5:18.1
-3,1,5:18.1
2,1,5:18.1
3,1,5:18.1
4,1,5:18.1
5,1,5:18.1
-4,2,5:18.1
-3,2,5:17.1
2,2,5:18.1
3,2,5:17.1
4,2,5:18.1
-4,3,5:18.1
3,3,5:18.1
4,3,5:18.1
-4,-6,6:18.1
7,-6,6:18.1
-4,-5,6:18.1
-3,-5,6:18.1
2,-5,6:18.1
-4,-4,6:18.1
-3,-4,6:18.1
-2,-4,6:18.1
-1,-4,6:18.1
0,-4,6:18.1
2,-4,6:18.1
3,-4,6:17.1
4,-4,6:18.1
-3,-3,6:18.1
-2,-3,6:18.1
-1,-3,6:18.1
0,-3,6:18.1
1,-3,6:18.1
2,-3,6:18.1
3,-3,6:18.1
4,-3,6:18.1
-3,-2,6:18.1
-1,-2,6:18.1
0,-2,6:17.1
1,-2,6:18.1
2,-2,6:18.1
0,-1,6:17.1
1,-1,6:17.1
-1,0,6:17.1
0,0,6:18.1
1,0,6:18.1
2,0,6:18.1
3,0,6:18.1
-5,1,6:18.1
-4,1,6:18.1
-3,1,6:18.1
-2,1,6:18.1
1,1,6:18.1
2,1,6:17.1
3,1,6:18.1
-4,2,6:18.1
-3,2,6:17.1
-2,2,6:18.1
2,2,6:18.1
3,2,6:18.1
4,2,6:18.1
-4,3,6:18.1
-3,3,6:18.1
2,3,6:18.1
3,3,6:18.1
5,-7,7:18.1
5,-6,7:18.1
6,-6,7:18.1
7,-6,7:18.1
-4,-5,7:18.1
-3,-5,7:18.1
-4,-4,7:18.1
-3,-4,7:17.1
-2,-4,7:18.1
0,-4,7:18.1
2,-4,7:18.1
3,-4,7:18.1
-3,-3,7:18.1
-2,-3,7:18.1
0,-3,7:18.1
1,-3,7:18.1
2,-3,7:17.1
3,-3,7:18.1
-1,-2,7:18.1
0,-2,7:17.1
1,-2,7:17.1
2,-2,7:18.1
0,-1,7:17.1
1,-1,7:17.1
2,-1,7:18.1
-2,0,7:18.1
-1,0,7:17.1
0,0,7:18.1
1,0,7:17.1
2,0,7:18.1
-3,1,7:18.1
-2,1,7:17.1
-1,1,7:18.1
0,1,7:18.1
1,1,7:18.1
2,1,7:17.1
3,1,7:18.1
-4,2,7:18.1
-3,2,7:18.1
-2,2,7:18.1
2,2,7:18.1
-3,3,7:18.1
5,-7,8:18.1
6,-7,8:18.1
4,-6,8:18.1
5,-6,8:17.1
6,-6,8:18.1
5,-5,8:18.1
6,-5,8:18.1
-3,-4,8:18.1
-2,-4,8:18.1
-3,-3,8:18.1
-2,-3,8:17.1
-1,-3,8:18.1
0,-3,8:18.1
1,-3,8:18.1
2,-3,8:18.1
-2,-2,8:18.1
-1,-2,8:17.1
0,-2,8:17.1
1,-2,8:18.1
2,-2,8:18.1
-1,-1,8:18.1
0,-1,8:17.1
1,-1,8:17.1
-3,0,8:18.1
-2,0,8:18.1
-1,0,8:17.1
0,0,8:18.1
1,0,8:17.1
2,0,8:18.1
-3,1,8:18.1
-2,1,8:17.1
-1,1,8:17.1
1,1,8:18.1
-3,2,8:18.1
-2,2,8:18.1
5,-7,9:18.1
-5,-6,9:18.1
4,-6,9:18.1
5,-6,9:18.1
6,-6,9:18.1
-6,-5,9:18.1
4,-5,9:18.1
5,-5,9:17.1
6,-5,9:18.1
-3,-4,9:18.1
-2,-4,9:18.1
-1,-4,9:18.1
4,-4,9:18.1
5,-4,9:18.1
-2,-3,9:18.1
-1,-3,9:18.1
0,-3,9:18.1
4,-3,9:18.1
-2,-2,9:18.1
-1,-2,9:17.1
0,-2,9:17.1
1,-2,9:18.1
3,-2,9:18.1
-2,-1,9:18.1
-1,-1,9:17.1
0,-1,9:17.1
1,-1,9:17.1
-2,0,9:18.1
-1,0,9:17.1
0,0,9:17.1
-3,1,9:18.1
-2,1,9:18.1
-1,1,9:18.1
-2,2,9:18.1
-1,2,9:18.1
5,4,9:18.1
4,5,9:18.1
5,5,9:18.1
6,5,9:18.1
-5,-6,10:18.1
-4,-6,10:18.1
4,-6,10:18.1
5,-6,10:18.1
-6,-5,10:18.1
-5,-5,10:18.1
-4,-5,10:18.1
4,-5,10:18.1
5,-5,10:17.1
6,-5,10:18.1
-5,-4,10:18.1
3,-4,10:18.1
4,-4,10:17.1
5,-4,10:18.1
-1,-3,10:18.1
2,-3,10:18.1
3,-3,10:18.1
4,-3,10:18.1
-4,-2,10:18.1
-2,-2,10:18.1
-1,-2,10:18.1
0,-2,10:18.1
1,-2,10:17.1
2,-2,10:17.1
3,-2,10:18.1
-2,-1,10:18.1
-1,-1,10:18.1
0,-1,10:17.1
1,-1,10:17.1
2,-1,10:18.1
-2,0,10:18.1
-1,0,10:17.1
0,0,10:17.1
1,0,10:18.1
-2,1,10:18.1
-1,1,10:18.1
0,1,10:18.1
-1,2,10:18.1
-4,3,10:18.1
4,4,10:18.1
5,4,10:18.1
6,4,10:18.1
4,5,10:18.1
5,5,10:18.1
6,5,10:18.1
-5,-6,11:18.1
-4,-6,11:18.1
-5,-5,11:18.1
-4,-5,11:17.1
-3,-5,11:18.1
4,-5,11:18.1
5,-5,11:18.1
-5,-4,11:18.1
3,-4,11:18.1
4,-4,11:17.1
5,-4,11:18.1
1,-3,11:18.1
2,-3,11:18.1
3,-3,11:17.1
4,-3,11:18.1
-4,-2,11:18.1
-3,-2,11:18.1
-2,-2,11:17.1
1,-2,11:18.1
2,-2,11:17.1
3,-2,11:18.1
-1,-1,11:18.1
0,-1,11:17.1
1,-1,11:17.1
2,-1,11:18.1
3,-1,11:18.1
-2,0,11:18.1
-1,0,11:17.1
0,0,11:17.1
6,0,11:18.1
7,0,11:18.1
-1,1,11:18.1
0,1,11:17.1
1,1,11:17.1
1,2,11:18.1
2,2,11:18.1
-6,3,11:18.1
-5,3,11:18.1
-4,3,11:18.1
3,4,11:18.1
4,4,11:18.1
5,4,11:18.1
6,4,11:18.1
-4,5,11:18.1
4,5,11:17.1
5,5,11:17.1
6,5,11:18.1
-4,-6,12:18.1
-3,-6,12:18.1
-5,-5,12:18.1
-4,-5,12:17.1
-3,-5,12:18.1
-4,-4,12:18.1
-3,-4,12:18.1
-2,-4,12:18.1
4,-4,12:18.1
-3,-3,12:18.1
2,-3,12:18.1
3,-3,12:18.1
1,-2,12:18.1
2,-2,12:18.1
3,-2,12:18.1
-3,-1,12:18.1
-2,-1,12:17.1
-1,-1,12:17.1
0,-1,12:17.1
1,-1,12:17.1
2,-1,12:18.1
-1,0,12:17.1
0,0,12:17.1
1,0,12:18.1
4,0,12:18.1
5,0,12:18.1
6,0,12:18.1
7,0,12:18.1
0,1,12:17.1
1,1,12:17.1
2,1,12:18.1
5,1,12:18.1
-5,2,12:18.1
0,2,12:18.1
1,2,12:17.1
2,2,12:18.1
-6,3,12:18.1
-5,3,12:18.1
-4,3,12:18.1
1,3,12:18.1
2,3,12:18.1
3,3,12:18.1
-5,4,12:18.1
-4,4,12:18.1
2,4,12:18.1
3,4,12:17.1
4,4,12:18.1
5,4,12:18.1
-4,5,12:18.1
3,5,12:18.1
4,5,12:17.1
5,5,12:18.1
6,5,12:18.1
5,-6,13:18.1
-4,-5,13:18.1
-3,-5,13:18.1
-4,-4,13:18.1
-3,-4,13:17.1
-2,-4,13:18.1
-4,-3,13:18.1
-3,-3,13:18.1
-2,-3,13:18.1
-2,-1,13:18.1
-1,-1,13:18.1
0,-1,13:17.1
1,-1,13:17.1
5,-1,13:18.1
-2,0,13:18.1
-1,0,13:18.1
0,0,13:18.1
1,0,13:18.1
4,0,13:18.1
5,0,13:17.1
6,0,13:18.1
7,0,13:18.1
0,1,13:18.1
1,1,13:18.1
4,1,13:18.1
5,1,13:18.1
6,1,13:18.1
-5,2,13:18.1
-4,2,13:18.1
0,2,13:18.1
1,2,13:17.1
2,2,13:18.1
-5,3,13:18.1
-4,3,13:17.1
-3,3,13:18.1
1,3,13:18.1
2,3,13:17.1
3,3,13:18.1
4,3,13:18.1
8,3,13:18.1
-5,4,13:18.1
-4,4,13:18.1
-3,4,13:18.1
2,4,13:18.1
3,4,13:17.1
4,4,13:18.1
7,4,13:18.1
-2,5,13:18.1
3,5,13:18.1
4,5,13:18.1
5,-6,14:18.1
-3,-5,14:18.1
4,-5,14:18.1
-4,-4,14:18.1
-3,-4,14:18.1
-2,-4,14:17.1
-3,-3,14:18.1
-2,-3,14:18.1
-1,-3,14:18.1
-2,-2,14:18.1
-1,-1,14:17.1
0,-1,14:17.1
1,-1,14:17.1
5,-1,14:18.1
0,0,14:18.1
4,0,14:18.1
5,0,14:17.1
6,0,14:18.1
5,1,14:18.1
-4,2,14:18.1
-3,2,14:18.1
1,2,14:18.1
6,2,14:18.1
-5,3,14:18.1
-4,3,14:17.1
-3,3,14:18.1
2,3,14:18.1
3,3,14:18.1
5,3,14:18.1
6,3,14:18.1
7,3,14:18.1
8,3,14:18.1
-4,4,14:18.1
3,4,14:18.1
4,4,14:18.1
7,4,14:18.1
-3,5,14:18.1
-2,5,14:18.1
-1,5,14:18.1
4,-6,15:18.1
5,-6,15:18.1
3,-5,15:18.1
4,-5,15:17.1
5,-5,15:18.1
-3,-4,15:18.1
-2,-4,15:18.1
-1,-4,15:18.1
4,-4,15:18.1
-3,-3,15:18.1
-2,-3,15:17.1
-1,-3,15:18.1
-2,-2,15:18.1
-1,-2,15:17.1
0,-2,15:18.1
-2,-1,15:18.1
-1,-1,15:17.1
0,-1,15:17.1
1,-1,15:17.1
4,0,15:17.1
-4,1,15:18.1
-3,1,15:18.1
-2,1,15:18.1
4,1,15:18.1
-4,2,15:18.1
-3,2,15:17.1
-2,2,15:18.1
3,2,15:18.1
4,2,15:18.1
5,2,15:18.1
6,2,15:18.1
7,2,15:18.1
-4,3,15:18.1
-3,3,15:18.1
-2,3,15:18.1
5,3,15:18.1
6,3,15:17.1
7,3,15:18.1
6,4,15:18.1
7,4,15:18.1
-2,5,15:18.1
3,-6,16:18.1
4,-6,16:18.1
3,-5,16:18.1
4,-5,16:17.1
5,-5,16:18.1
-2,-4,16:18.1
3,-4,16:18.1
4,-4,16:18.1
5,-4,16:18.1
-2,-3,16:18.1
-1,-3,16:18.1
1,-3,16:18.1
3,-3,16:18.1
-2,-2,16:18.1
-1,-2,16:17.1
0,-2,16:18.1
1,-2,16:17.1
-1,-1,16:18.1
0,-1,16:17.1
1,-1,16:17.1
2,-1,16:17.1
3,-1,16:17.1
-2,0,16:18.1
-3,1,16:18.1
-2,1,16:18.1
-1,1,16:18.1
3,1,16:18.1
4,1,16:18.1
-4,2,16:18.1
-3,2,16:17.1
-2,2,16:18.1
3,2,16:18.1
4,2,16:18.1
5,2,16:18.1
6,2,16:18.1
-3,3,16:18.1
0,3,16:18.1
5,3,16:18.1
6,3,16:17.1
7,3,16:18.1
-1,4,16:18.1
0,4,16:18.1
1,4,16:18.1
6,4,16:18.1
-1,5,16:17.1
0,5,16:18.1
3,-5,17:18.1
4,-5,17:18.1
2,-4,17:18.1
3,-4,17:17.1
4,-4,17:18.1
1,-3,17:18.1
2,-3,17:18.1
3,-3,17:18.1
4,-3,17:18.1
-1,-2,17:18.1
0,-2,17:18.1
2,-2,17:18.1
-1,-1,17:18.1
0,-1,17:17.1
1,-1,17:17.1
-2,0,17:18.1
-1,0,17:17.1
0,0,17:17.1
-3,1,17:18.1
-2,1,17:17.1
-1,1,17:17.1
4,1,17:18.1
5,1,17:18.1
-3,2,17:18.1
-2,2,17:18.1
-1,2,17:18.1
0,2,17:18.1
3,2,17:18.1
4,2,17:18.1
5,2,17:17.1
6,2,17:18.1
-1,3,17:18.1
0,3,17:17.1
1,3,17:18.1
4,3,17:18.1
5,3,17:18.1
6,3,17:18.1
-1,4,17:17.1
0,4,17:18.1
1,4,17:18.1
-1,5,17:18.1
0,5,17:18.1
-4,-4,18:18.1
1,-4,18:18.1
2,-4,18:18.1
3,-4,18:18.1
1,-3,18:18.1
2,-3,18:17.1
3,-3,18:18.1
1,-2,18:17.1
2,-2,18:17.1
3,-2,18:18.1
-1,-1,18:18.1
0,-1,18:17.1
1,-1,18:17.1
3,-1,18:18.1
-1,0,18:18.1
0,0,18:18.1
2,0,18:18.1
3,0,18:18.1
4,0,18:18.1
-2,1,18:18.1
-1,1,18:18.1
3,1,18:18.1
4,1,18:17.1
5,1,18:18.1
-5,2,18:18.1
-2,2,18:18.1
-1,2,18:18.1
0,2,18:17.1
1,2,18:18.1
4,2,18:18.1
5,2,18:18.1
6,2,18:18.1
-1,3,18:18.1
0,3,18:17.1
1,3,18:18.1
5,3,18:18.1
-5,4,18:18.1
-1,4,18:18.1
0,4,18:18.1
-4,-4,19:18.1
-3,-4,19:18.1
2,-4,19:18.1
1,-3,19:18.1
2,-3,19:18.1
3,-3,19:18.1
1,-2,19:18.1
2,-2,19:18.1
0,-1,19:17.1
1,-1,19:17.1
2,-1,19:18.1
3,-1,19:18.1
4,-1,19:18.1
-1,0,19:18.1
0,0,19:17.1
1,0,19:18.1
2,0,19:18.1
3,0,19:17.1
4,0,19:18.1
-1,1,19:18.1
0,1,19:17.1
2,1,19:18.1
3,1,19:18.1
4,1,19:17.1
5,1,19:18.1
-6,2,19:18.1
-5,2,19:18.1
0,2,19:18.1
4,2,19:18.1
-5,3,19:18.1
-4,3,19:18.1
0,3,19:18.1
1,3,19:18.1
-5,4,19:18.1
-4,4,19:18.1
5,4,19:18.1
-4,-4,20:18.1
-3,-4,20:18.1
-2,-4,20:18.1
-3,-3,20:18.1
-2,-3,20:18.1
-1,-3,20:18.1
-1,-2,20:17.1
0,-2,20:18.1
1,-2,20:18.1
2,-2,20:18.1
0,-1,20:17.1
1,-1,20:17.1
2,-1,20:17.1
3,-1,20:18.1
0,0,20:17.1
1,0,20:18.1
2,0,20:17.1
3,0,20:17.1
4,0,20:18.1
-1,1,20:18.1
0,1,20:18.1
2,1,20:18.1
3,1,20:18.1
4,1,20:18.1
-6,2,20:18.1
-5,2,20:18.1
-4,2,20:18.1
-3,2,20:18.1
4,2,20:18.1
-5,3,20:18.1
-4,3,20:17.1
4,3,20:18.1
5,3,20:18.1
-5,4,20:18.1
-4,4,20:18.1
5,4,20:18.1
5,5,20:18.1
-4,-5,21:18.1
-3,-5,21:18.1
-4,-4,21:18.1
-3,-4,21:17.1
-2,-4,21:18.1
-1,-4,21:18.1
-3,-3,21:18.1
-2,-3,21:17.1
-1,-3,21:17.1
0,-3,21:18.1
-2,-2,21:18.1
-1,-2,21:17.1
0,-2,21:17.1
1,-2,21:18.1
-1,-1,21:18.1
0,-1,21:17.1
1,-1,21:18.1
2,-1,21:18.1
-1,0,21:18.1
0,0,21:18.1
1,0,21:18.1
2,0,21:18.1
-3,1,21:18.1
-1,1,21:18.1
-4,2,21:18.1
-3,2,21:17.1
3,2,21:18.1
4,2,21:18.1
-5,3,21:18.1
-4,3,21:18.1
-3,3,21:18.1
4,3,21:17.1
5,3,21:18.1
-4,4,21:18.1
4,4,21:18.1
5,4,21:18.1
-3,-5,22:18.1
3,-5,22:18.1
-4,-4,22:18.1
-3,-4,22:17.1
-2,-4,22:18.1
-1,-4,22:18.1
-2,-3,22:18.1
-1,-3,22:18.1
0,-3,22:18.1
-1,-2,22:18.1
0,-2,22:18.1
1,-2,22:18.1
-1,-1,22:18.1
0,-1,22:17.1
1,-1,22:18.1
-3,0,22:18.1
-1,0,22:18.1
0,0,22:18.1
1,0,22:18.1
-4,1,22:18.1
-3,1,22:18.1
-2,1,22:18.1
3,1,22:18.1
4,1,22:18.1
5,1,22:18.1
-4,2,22:18.1
-3,2,22:17.1
3,2,22:18.1
4,2,22:17.1
5,2,22:18.1
-4,3,22:18.1
-3,3,22:18.1
3,3,22:18.1
4,3,22:18.1
5,3,22:18.1
4,4,22:18.1
3,-5,23:18.1
-3,-4,23:18.1
-2,-4,23:18.1
2,-4,23:18.1
3,-4,23:18.1
-2,-3,23:18.1
-1,-3,23:18.1
-1,-2,23:18.1
0,-2,23:18.1
-1,-1,23:18.1
0,-1,23:17.1
1,-1,23:17.1
2,-1,23:18.1
-3,0,23:18.1
-2,0,23:18.1
-1,0,23:18.1
0,0,23:18.1
1,0,23:18.1
2,0,23:18.1
3,0,23:18.1
4,0,23:18.1
-3,1,23:18.1
-2,1,23:17.1
-1,1,23:18.1
2,1,23:18.1
3,1,23:17.1
4,1,23:18.1
5,1,23:18.1
-4,2,23:18.1
-3,2,23:18.1
-2,2,23:18.1
3,2,23:18.1
4,2,23:18.1
5,2,23:18.1
-3,3,23:18.1
4,3,23:18.1
2,-5,24:18.1
2,-4,24:17.1
3,-4,24:18.1
-1,-3,24:18.1
-3,-2,24:18.1
0,-2,24:18.1
-2,-1,24:18.1
-1,-1,24:18.1
0,-1,24:17.1
1,-1,24:17.1
2,-1,24:18.1
3,-1,24:18.1
-2,0,24:18.1
-1,0,24:17.1
0,0,24:18.1
1,0,24:18.1
2,0,24:17.1
3,0,24:17.1
4,0,24:18.1
-3,1,24:18.1
-2,1,24:17.1
-1,1,24:18.1
0,1,24:18.1
2,1,24:18.1
3,1,24:18.1
4,1,24:18.1
-2,2,24:18.1
-4,-4,25:18.1
2,-4,25:18.1
2,-3,25:17.1
3,-3,25:18.1
-3,-2,25:18.1
0,-2,25:18.1
-1,-1,25:18.1
0,-1,25:17.1
2,-1,25:18.1
-2,0,25:18.1
-1,0,25:17.1
0,0,25:18.1
1,0,25:18.1
2,0,25:18.1
3,0,25:18.1
-2,1,25:18.1
-1,1,25:18.1
2,1,25:18.1
-4,-4,26:18.1
-4,-3,26:18.1
-3,-3,26:18.1
1,-3,26:18.1
2,-3,26:18.1
-3,-2,26:18.1
1,-2,26:17.1
-1,-1,26:17.1
0,-1,26:17.1
1,-1,26:18.1
-1,0,26:18.1
0,0,26:18.1
1,0,26:18.1
4,3,26:18.1
-4,-4,27:18.1
-4,-3,27:18.1
-3,-3,27:17.1
-2,-3,27:18.1
1,-3,27:18.1
-3,-2,27:18.1
-2,-2,27:18.1
-1,-2,27:18.1
0,-2,27:17.1
1,-2,27:17.1
-1,-1,27:18.1
0,-1,27:17.1
1,-1,27:17.1
0,0,27:18.1
3,2,27:18.1
4,2,27:18.1
-4,3,27:18.1
3,3,27:18.1
4,3,27:18.1
-1,-5,28:18.1
-3,-4,28:18.1
-4,-3,28:18.1
-3,-3,28:18.1
-2,-3,28:18.1
-1,-3,28:18.1
0,-3,28:18.1
1,-3,28:18.1
-3,-2,28:18.1
-2,-2,28:17.1
-1,-2,28:18.1
0,-2,28:18.1
1,-2,28:18.1
-2,-1,28:18.1
-1,-1,28:18.1
0,-1,28:17.1
0,0,28:18.1
1,1,28:18.1
2,1,28:18.1
3,1,28:18.1
-3,2,28:18.1
2,2,28:18.1
3,2,28:17.1
4,2,28:18.1
-4,3,28:18.1
-3,3,28:18.1
2,3,28:18.1
3,3,28:18.1
4,3,28:18.1
-1,-6,29:18.1
-1,-5,29:18.1
-3,-3,29:18.1
-2,-3,29:18.1
-4,-2,29:18.1
-3,-2,29:18.1
-2,-2,29:18.1
-1,-2,29:17.1
0,-2,29:17.1
1,-2,29:18.1
-2,-1,29:18.1
0,-1,29:17.1
1,-1,29:18.1
0,0,29:18.1
1,0,29:18.1
2,0,29:18.1
3,0,29:18.1
-3,1,29:18.1
-2,1,29:18.1
1,1,29:18.1
2,1,29:17.1
3,1,29:18.1
-4,2,29:18.1
-3,2,29:17.1
-2,2,29:18.1
1,2,29:18.1
2,2,29:18.1
3,2,29:18.1
4,2,29:18.1
-3,3,29:18.1
3,3,29:18.1
-1,-5,30:18.1
-1,-4,30:18.1
-1,-3,30:18.1
-2,-2,30:18.1
-1,-2,30:18.1
0,-2,30:18.1
0,-1,30:17.1
1,-1,30:17.1
2,-1,30:18.1
-1,0,30:18.1
0,0,30:18.1
1,0,30:17.1
2,0,30:17.1
3,0,30:18.1
-3,1,30:18.1
-2,1,30:17.1
0,1,30:18.1
1,1,30:18.1
2,1,30:18.1
3,1,30:18.1
-3,2,30:18.1
-2,2,30:18.1
2,2,30:18.1
-2,-5,31:18.1
-1,-5,31:18.1
-1,-4,31:17.1
0,-4,31:18.1
-1,-3,31:18.1
0,-3,31:18.1
1,-2,31:18.1
-2,-1,31:18.1
-1,-1,31:18.1
0,-1,31:17.1
1,-1,31:18.1
2,-1,31:18.1
-2,0,31:18.1
-1,0,31:17.1
0,0,31:18.1
1,0,31:18.1
2,0,31:18.1
-3,1,31:18.1
-2,1,31:18.1
-1,1,31:18.1
1,1,31:18.1
-2,-4,32:18.1
-1,-4,32:18.1
0,-4,32:18.1
-1,-3,32:17.1
0,-2,32:18.1
1,-2,32:18.1
3,-2,32:18.1
-2,-1,32:18.1
-1,-1,32:18.1
0,-1,32:17.1
1,-1,32:18.1
-2,0,32:18.1
-1,0,32:17.1
0,0,32:17.1
-2,1,32:18.1
-1,1,32:18.1
0,1,32:18.1
-1,-3,33:18.1
0,-3,33:18.1
1,-3,33:18.1
0,-2,33:17.1
1,-2,33:17.1
2,-2,33:18.1
3,-2,33:18.1
-1,-1,33:18.1
0,-1,33:17.1
1,-1,33:18.1
-2,0,33:18.1
-1,0,33:18.1
0,0,33:18.1
1,0,33:17.1
-1,1,33:18.1
1,-3,34:18.1
0,-2,34:18.1
1,-2,34:18.1
2,-2,34:18.1
-1,-1,34:18.1
0,-1,34:17.1
1,-1,34:18.1
0,0,34:18.1
1,-2,35:18.1
-1,-1,35:18.1
0,-1,35:17.1
1,-1,35:18.1
-1,0,35:18.1
0,0,35:18.1
1,0,35:18.1
0,1,35:18.1
-1,-1,36:18.1
0,-1,36:18.1
1,-1,36:18.1
0,0,36:18.1
0,-2,37:18.1
0,-1,37:18.1
0,0,37:18.1
-1,-1,38:18.1
0,-1,38:18.1
0,-1,39:18.1
1,-1,39:18.1
0,-1,40:18.1
0,0,5:106.2
-2,0,5:106.8
-1,-1,5:106.8
1,0,4:106.4
0,0,4:106.2
-2,0,4:106.8
-1,-1,4:106.8
1,-2,4:106.1
1,0,3:106.4
-2,0,3:106.8
2,-1,3:106.2
-1,-1,3:106.8
1,-2,3:106.3
-1,-2,3:106.8
1,0,2:106.4
-2,0,2:106.8
-1,-1,2:106.8
1,-2,2:106.3
-1,-2,2:106.8
0,2,1:106.4
-1,2,1:106.4
-3,2,1:106.8
1,1,1:106.2
1,0,1:106.4
-2,0,1:106.8
-1,-1,1:106.8
-3,-1,1:106.8
1,-2,1:106.3
-1,-2,1:106.8
1,-3,1:106.2
1,4,0:106.4
-3,4,0:106.4
2,3,0:106.2
0,3,0:106.4
-2,3,0:106.4
-1,2,0:106.4
1,1,0:106.2
1,0,0:106.4
-2,0,0:106.8
4,-1,0:106.4
3,-1,0:106.2
-3,-1,0:106.8
1,-2,0:106.3
-1,-2,0:106.8
3,-3,0:106.1
2,-3,0:106.1
1,-3,0:106.2
-1,-3,0:106.8
-3,-3,0:106.1
0,-4,0:106.8
-2,-4,0:106.8
1,4,-1:106.4
-2,3,-1:106.4
-3,-1,-1:106.8
1,-2,-1:106.3
-1,-2,-1:106.8
2,-3,-1:106.1
1,-3,-1:106.2
-3,-3,-1:106.1
1,-2,-2:106.3
1,-3,-2:106.2
1,-2,-3:106.3
1,-3,-3:106.2
