[META]
version=2.0
spawnOnBlockType=2
spawnSunlight=True
spawnDarkness=True
spawnWater=False
spawnLava=False
underFill=False
randomRotation=True
dig=True
tree=True
branch=False
needsFoundation=True
rarity=5
collisionPercentage=20
spawnElevationMin=0
spawnElevationMax=200
spawnInBiome=Custom
[DATA]
0,0,-3:17.1
0,1,-3:17.1
0,2,-3:17.1
-1,0,-2:17.1
0,0,-2:17.1
0,0,-1:17.1
0,0,0:17.1
0,0,1:17.1
1,-1,2:17.1
2,-1,2:18.1
-1,0,2:18.1
0,0,2:17.1
1,-1,3:18.1
-2,0,3:18.1
-1,0,3:18.1
0,0,3:17.1
1,0,3:18.1
0,2,3:18.1
-1,-1,4:18.1
-2,0,4:18.1
-1,0,4:17.1
0,0,4:17.1
1,0,4:18.1
-1,1,4:18.1
0,1,4:18.1
-1,-2,5:18.1
-1,-1,5:17.1
0,-1,5:18.1
-1,0,5:18.1
0,0,5:18.1
0,1,5:17.1
1,1,5:18.1
0,2,5:18.1
-1,-1,6:18.1
0,0,6:18.1
0,1,6:18.1
1,1,6:17.1
2,1,6:18.1
1,2,6:18.1
2,2,6:18.1
0,0,7:18.1
1,1,7:18.1
0,0,8:18.1
2,0,4:106.2
1,-1,4:106.1
0,-1,4:106.1
2,0,3:106.2
0,-1,3:106.1
2,0,2:106.2
0,-1,2:106.1
0,1,1:106.4
2,0,1:106.2
-1,0,1:106.8
0,-1,1:106.1
0,1,0:106.4
2,0,0:106.2
-1,0,0:106.8
0,-1,0:106.1
0,-1,-1:106.1
