[META]
version=2.0
spawnOnBlockType=2
spawnSunlight=True
spawnDarkness=True
spawnWater=False
spawnLava=False
underFill=False
randomRotation=True
dig=True
tree=False
branch=False
needsFoundation=True
rarity=50
collisionPercentage=20
spawnElevationMin=0
spawnElevationMax=200
spawnInBiome=CustomRedwood Forest
[DATA]
4,-5,-3:17.1
0,-4,-3:17.1
-2,-3,-3:17.1
4,-2,-3:17.1
1,-1,-3:17.1
-1,0,-3:17.1
3,1,-3:17.1
1,2,-3:17.1
0,-4,-2:17.1
3,-4,-2:17.1
-2,-3,-2:17.1
2,-3,-2:17.1
-2,-2,-2:17.1
4,-2,-2:17.1
1,-1,-2:17.1
-1,0,-2:17.1
3,1,-2:17.1
2,2,-2:17.1
3,-4,-1:17.1
0,-3,-1:17.1
2,-3,-1:17.1
-2,-2,-1:17.1
3,-2,-1:17.1
-1,-1,-1:17.1
1,-1,-1:17.1
0,0,-1:17.1
1,0,-1:17.1
2,1,-1:17.1
3,-4,0:17.1
0,-3,0:17.1
2,-3,0:17.1
-2,-2,0:17.1
0,-2,0:17.1
1,-2,0:17.1
3,-2,0:17.1
-1,-1,0:17.1
0,-1,0:17.1
1,-1,0:17.1
0,0,0:17.1
1,0,0:17.1
2,1,0:17.1
2,-3,1:17.1
0,-2,1:17.1
1,-2,1:17.1
-1,-1,1:17.1
0,-1,1:17.1
1,-1,1:17.1
1,0,1:17.1
0,-2,2:17.1
1,-2,2:17.1
0,-1,2:17.1
1,-1,2:17.1
0,-2,3:17.1
1,-2,3:17.1
0,-1,3:17.1
1,-1,3:17.1
0,-2,4:17.1
1,-2,4:17.1
0,-1,4:17.1
1,-1,4:17.1
0,-2,5:17.1
1,-2,5:17.1
0,-1,5:17.1
1,-1,5:17.1
0,-2,6:17.1
1,-2,6:17.1
0,-1,6:17.1
1,-1,6:17.1
0,-2,7:17.1
1,-2,7:17.1
0,-1,7:17.1
1,-1,7:17.1
0,-2,8:17.1
1,-2,8:17.1
0,-1,8:17.1
1,-1,8:17.1
0,-2,9:17.1
1,-2,9:17.1
0,-1,9:17.1
1,-1,9:17.1
0,-2,10:17.1
1,-2,10:17.1
0,-1,10:17.1
1,-1,10:17.1
0,-2,11:17.1
1,-2,11:17.1
0,-1,11:17.1
1,-1,11:17.1
0,-2,12:17.1
1,-2,12:17.1
0,-1,12:17.1
1,-1,12:17.1
0,-2,13:17.1
1,-2,13:17.1
0,-1,13:17.1
1,-1,13:17.1
0,-2,14:17.1
1,-2,14:17.1
0,-1,14:17.1
1,-1,14:17.1
0,-2,15:17.1
1,-2,15:17.1
0,-1,15:17.1
1,-1,15:17.1
0,-4,16:18.1
1,-4,16:18.1
-2,-2,16:18.1
-1,-2,16:18.1
0,-2,16:17.1
1,-2,16:17.1
-2,-1,16:18.1
-1,-1,16:18.1
0,-1,16:17.1
1,-1,16:17.1
2,-1,16:18.1
-1,0,16:18.1
-5,-3,17:18.1
-2,-3,17:18.1
-5,-2,17:18.1
-3,-2,17:17.1
-2,-2,17:18.1
-1,-2,17:18.1
0,-2,17:17.1
1,-2,17:17.1
-5,-1,17:18.1
-3,-1,17:18.1
-2,-1,17:17.1
-1,-1,17:17.1
0,-1,17:17.1
1,-1,17:17.1
-4,0,17:18.1
-3,0,17:18.1
0,-3,18:18.1
1,-3,18:18.1
0,-2,18:17.1
1,-2,18:17.1
2,-2,18:18.1
-2,-1,18:18.1
-1,-1,18:18.1
0,-1,18:17.1
1,-1,18:17.1
2,-1,18:18.1
0,0,18:17.1
1,0,18:18.1
-1,1,18:18.1
0,1,18:18.1
1,1,18:17.1
2,1,18:18.1
0,2,18:18.1
1,2,18:18.1
1,3,18:18.1
2,3,18:18.1
4,-5,19:18.1
2,-4,19:18.1
4,-4,19:18.1
-1,-3,19:18.1
2,-3,19:17.1
3,-3,19:18.1
4,-3,19:17.1
5,-3,19:18.1
-2,-2,19:18.1
0,-2,19:17.1
1,-2,19:17.1
2,-2,19:18.1
3,-2,19:17.1
4,-2,19:18.1
6,-2,19:18.1
-1,-1,19:18.1
0,-1,19:17.1
1,-1,19:17.1
2,-1,19:18.1
0,0,19:18.1
1,0,19:18.1
0,1,19:18.1
-2,-6,20:18.1
-3,-5,20:18.1
-2,-5,20:18.1
1,-5,20:18.1
-3,-4,20:18.1
-2,-4,20:18.1
-1,-4,20:17.1
0,-4,20:18.1
1,-4,20:18.1
-2,-3,20:18.1
0,-3,20:17.1
-2,-2,20:18.1
-1,-2,20:18.1
0,-2,20:17.1
1,-2,20:17.1
2,-2,20:18.1
3,-2,20:18.1
0,-1,20:17.1
1,-1,20:17.1
1,0,20:18.1
0,-2,21:17.1
1,-2,21:17.1
0,-1,21:17.1
1,-1,21:17.1
1,-4,22:18.1
4,-4,22:18.1
2,-3,22:18.1
3,-3,22:17.1
4,-3,22:18.1
0,-2,22:17.1
1,-2,22:17.1
2,-2,22:17.1
3,-2,22:18.1
5,-2,22:18.1
0,-1,22:17.1
1,-1,22:17.1
2,-1,22:18.1
3,-1,22:17.1
4,-1,22:18.1
1,0,22:18.1
3,0,22:18.1
4,0,22:18.1
5,0,22:18.1
3,1,22:18.1
0,-2,23:17.1
1,-2,23:17.1
-1,-1,23:18.1
0,-1,23:17.1
1,-1,23:17.1
0,0,23:18.1
1,0,23:17.1
2,0,23:18.1
0,1,23:18.1
1,1,23:17.1
0,2,23:17.1
1,2,23:18.1
2,2,23:18.1
-2,3,23:18.1
0,3,23:18.1
-1,4,23:18.1
0,4,23:18.1
-2,-5,24:18.1
-1,-5,24:18.1
-3,-4,24:18.1
-2,-4,24:18.1
0,-4,24:17.1
1,-4,24:18.1
-2,-3,24:18.1
-1,-3,24:18.1
0,-3,24:18.1
1,-3,24:17.1
2,-3,24:18.1
-4,-2,24:18.1
-2,-2,24:17.1
-1,-2,24:18.1
0,-2,24:17.1
1,-2,24:17.1
-4,-1,24:18.1
-1,-1,24:17.1
0,-1,24:17.1
1,-1,24:17.1
2,-1,24:18.1
3,-1,24:18.1
-4,0,24:18.1
-3,0,24:18.1
-2,0,24:17.1
-1,0,24:18.1
0,0,24:18.1
1,0,24:18.1
-1,1,24:18.1
1,1,24:18.1
-3,2,24:18.1
-1,-3,25:18.1
0,-3,25:18.1
0,-2,25:17.1
1,-2,25:17.1
-1,-1,25:18.1
0,-1,25:17.1
1,-1,25:17.1
2,-1,25:18.1
0,0,25:18.1
-1,1,25:18.1
0,1,25:18.1
0,-6,26:18.1
-1,-5,26:18.1
0,-5,26:18.1
1,-5,26:18.1
-3,-4,26:18.1
-2,-4,26:18.1
-1,-4,26:17.1
0,-4,26:18.1
1,-4,26:18.1
-3,-3,26:18.1
-2,-3,26:18.1
-1,-3,26:18.1
0,-3,26:17.1
0,-2,26:17.1
1,-2,26:17.1
0,-1,26:17.1
1,-1,26:17.1
0,-3,27:18.1
1,-3,27:18.1
-1,-2,27:18.1
0,-2,27:17.1
1,-2,27:17.1
2,-2,27:18.1
3,-2,27:18.1
-2,-1,27:18.1
-1,-1,27:18.1
0,-1,27:17.1
1,-1,27:17.1
-2,0,27:18.1
2,0,27:18.1
3,0,27:18.1
0,1,27:18.1
5,-5,28:18.1
5,-4,28:18.1
1,-3,28:18.1
4,-3,28:18.1
5,-3,28:17.1
6,-3,28:18.1
0,-2,28:17.1
1,-2,28:17.1
3,-2,28:17.1
4,-2,28:17.1
5,-2,28:18.1
6,-2,28:18.1
0,-1,28:17.1
1,-1,28:17.1
2,-1,28:17.1
3,-1,28:18.1
4,-1,28:18.1
5,-1,28:17.1
6,-1,28:18.1
8,-1,28:18.1
0,0,28:18.1
3,0,28:18.1
4,0,28:18.1
5,0,28:18.1
6,0,28:17.1
7,0,28:18.1
8,0,28:18.1
1,1,28:18.1
2,1,28:18.1
4,1,28:18.1
5,1,28:18.1
6,1,28:18.1
7,1,28:18.1
6,2,28:18.1
7,2,28:18.1
-1,-4,29:18.1
-2,-3,29:18.1
2,-3,29:18.1
-1,-2,29:18.1
0,-2,29:17.1
1,-2,29:17.1
2,-2,29:18.1
0,-1,29:17.1
1,-1,29:17.1
2,-1,29:18.1
-1,0,29:18.1
0,0,29:18.1
1,0,29:18.1
0,-2,30:17.1
1,-2,30:17.1
-3,-1,30:18.1
-2,-1,30:18.1
-1,-1,30:17.1
0,-1,30:17.1
1,-1,30:17.1
-5,0,30:18.1
-4,0,30:18.1
-3,0,30:18.1
-2,0,30:17.1
0,0,30:17.1
2,0,30:18.1
3,0,30:18.1
-7,1,30:18.1
-6,1,30:18.1
-5,1,30:18.1
-4,1,30:17.1
-3,1,30:17.1
-2,1,30:18.1
-1,1,30:18.1
1,1,30:17.1
-6,2,30:18.1
-5,2,30:17.1
-3,2,30:18.1
-1,2,30:18.1
0,2,30:18.1
1,2,30:18.1
2,2,30:17.1
3,2,30:18.1
4,2,30:18.1
5,2,30:18.1
-7,3,30:18.1
0,3,30:18.1
1,3,30:18.1
2,3,30:17.1
3,3,30:18.1
6,3,30:18.1
-5,4,30:18.1
-4,4,30:18.1
-1,4,30:18.1
0,4,30:18.1
1,4,30:17.1
2,4,30:18.1
3,4,30:18.1
4,4,30:18.1
3,5,30:18.1
1,6,30:18.1
-2,-3,31:18.1
0,-3,31:18.1
1,-3,31:18.1
-4,-2,31:18.1
-3,-2,31:18.1
-1,-2,31:18.1
0,-2,31:17.1
1,-2,31:17.1
2,-2,31:18.1
-4,-1,31:18.1
-2,-1,31:18.1
-1,-1,31:18.1
0,-1,31:17.1
1,-1,31:17.1
2,-1,31:18.1
-3,0,31:18.1
-1,0,31:18.1
0,0,31:18.1
1,0,31:18.1
2,0,31:18.1
3,0,31:18.1
-4,1,31:18.1
-3,1,31:18.1
-2,1,31:18.1
-1,1,31:18.1
0,1,31:18.1
1,1,31:18.1
2,1,31:18.1
4,1,31:18.1
0,2,31:18.1
1,2,31:18.1
2,2,31:18.1
3,2,31:18.1
4,2,31:18.1
-3,3,31:18.1
2,3,31:18.1
4,3,31:18.1
2,4,31:18.1
-4,-7,32:18.1
-5,-6,32:18.1
-6,-5,32:18.1
-4,-5,32:18.1
-5,-4,32:18.1
-4,-4,32:18.1
-3,-4,32:18.1
-2,-4,32:18.1
-5,-3,32:18.1
-4,-3,32:17.1
-3,-3,32:18.1
-2,-3,32:18.1
0,-3,32:18.1
-6,-2,32:18.1
-5,-2,32:18.1
-4,-2,32:18.1
-3,-2,32:17.1
-2,-2,32:17.1
-1,-2,32:17.1
0,-2,32:17.1
1,-2,32:17.1
-4,-1,32:17.1
-3,-1,32:18.1
-1,-1,32:18.1
0,-1,32:17.1
1,-1,32:17.1
-6,0,32:18.1
-5,0,32:17.1
-4,0,32:18.1
-2,0,32:18.1
-1,0,32:18.1
-3,1,32:18.1
-6,2,32:18.1
-5,2,32:18.1
-4,2,32:18.1
-2,-4,33:18.1
0,-4,33:18.1
0,-3,33:18.1
1,-3,33:18.1
3,-3,33:18.1
-4,-2,33:18.1
-3,-2,33:18.1
-2,-2,33:18.1
-1,-2,33:18.1
0,-2,33:17.1
1,-2,33:17.1
2,-2,33:18.1
3,-2,33:18.1
-2,-1,33:18.1
0,-1,33:17.1
1,-1,33:17.1
2,-1,33:18.1
-2,0,33:18.1
-1,0,33:18.1
2,0,33:18.1
5,-7,34:18.1
6,-7,34:18.1
1,-6,34:18.1
2,-6,34:18.1
3,-6,34:18.1
4,-6,34:18.1
5,-6,34:18.1
7,-6,34:18.1
-1,-5,34:18.1
0,-5,34:18.1
1,-5,34:17.1
2,-5,34:18.1
3,-5,34:17.1
4,-5,34:18.1
5,-5,34:18.1
1,-4,34:18.1
2,-4,34:17.1
3,-4,34:18.1
4,-4,34:18.1
1,-3,34:17.1
2,-3,34:18.1
4,-3,34:18.1
0,-2,34:17.1
1,-2,34:17.1
0,-1,34:17.1
0,-2,35:17.1
1,-2,35:17.1
0,-1,35:17.1
1,-4,36:18.1
-1,-3,36:18.1
1,-3,36:18.1
3,-3,36:18.1
0,-2,36:17.1
1,-2,36:17.1
0,-1,36:17.1
3,-1,36:18.1
2,-4,37:18.1
3,-4,37:18.1
1,-3,37:18.1
3,-3,37:17.1
4,-3,37:18.1
5,-3,37:18.1
0,-2,37:17.1
1,-2,37:17.1
2,-2,37:17.1
3,-2,37:18.1
5,-2,37:18.1
0,-1,37:17.1
2,-1,37:18.1
3,-1,37:18.1
2,0,37:18.1
2,1,37:18.1
3,1,37:18.1
-2,-6,38:18.1
-1,-6,38:18.1
-2,-5,38:18.1
-1,-5,38:18.1
-4,-4,38:18.1
-3,-4,38:18.1
-2,-4,38:17.1
0,-4,38:18.1
-4,-3,38:18.1
-3,-3,38:18.1
-2,-3,38:18.1
-1,-3,38:17.1
-2,-2,38:18.1
-1,-2,38:18.1
0,-2,38:17.1
1,-2,38:17.1
-2,-1,38:18.1
0,-1,38:17.1
1,-1,38:18.1
1,0,38:18.1
-1,1,38:18.1
0,-4,39:18.1
0,-3,39:18.1
1,-3,39:18.1
-1,-2,39:18.1
0,-2,39:17.1
1,-2,39:17.1
-3,-1,39:18.1
0,-1,39:17.1
2,-1,39:18.1
-3,0,39:18.1
-2,0,39:18.1
-1,0,39:17.1
1,0,39:18.1
2,0,39:18.1
-4,1,39:18.1
-2,1,39:17.1
-1,1,39:18.1
-3,2,39:18.1
-2,2,39:18.1
-1,2,39:18.1
-3,3,39:18.1
-2,3,39:18.1
-1,3,39:18.1
0,3,39:18.1
2,-6,40:18.1
3,-6,40:18.1
4,-6,40:18.1
5,-6,40:18.1
2,-5,40:18.1
3,-5,40:18.1
1,-4,40:18.1
2,-4,40:17.1
4,-4,40:18.1
0,-3,40:18.1
1,-3,40:17.1
2,-3,40:18.1
3,-3,40:18.1
4,-3,40:18.1
6,-3,40:18.1
0,-2,40:17.1
1,-2,40:17.1
4,-2,40:18.1
0,-1,40:17.1
0,-2,41:17.1
4,-2,41:18.1
0,-1,41:17.1
2,-1,41:18.1
3,-1,41:18.1
1,0,41:17.1
2,0,41:17.1
3,0,41:18.1
5,0,41:18.1
0,1,41:18.1
3,1,41:18.1
1,2,41:18.1
2,2,41:18.1
3,2,41:18.1
4,2,41:18.1
2,3,41:18.1
4,3,41:18.1
3,4,41:18.1
4,4,41:18.1
-2,-7,42:18.1
-3,-6,42:18.1
-2,-6,42:18.1
-4,-5,42:18.1
-3,-5,42:18.1
-2,-5,42:18.1
-1,-5,42:18.1
0,-5,42:18.1
-3,-4,42:18.1
-2,-4,42:17.1
0,-4,42:18.1
-4,-3,42:18.1
-2,-3,42:18.1
-1,-3,42:17.1
-2,-2,42:18.1
0,-2,42:17.1
0,-1,42:17.1
0,-2,43:17.1
0,-1,43:17.1
0,-5,44:18.1
-1,-4,44:18.1
2,-4,44:18.1
-3,-3,44:18.1
0,-3,44:18.1
1,-3,44:18.1
2,-3,44:18.1
-2,-2,44:18.1
0,-2,44:17.1
2,-2,44:18.1
3,-2,44:18.1
4,-2,44:18.1
-2,-1,44:18.1
0,-1,44:17.1
1,-1,44:18.1
2,-1,44:18.1
-1,0,44:18.1
1,0,44:18.1
0,1,44:18.1
0,-2,45:17.1
0,-1,45:17.1
1,-5,46:18.1
0,-4,46:18.1
-2,-3,46:18.1
-1,-3,46:18.1
2,-3,46:18.1
-2,-2,46:18.1
-1,-2,46:18.1
0,-2,46:17.1
1,-2,46:18.1
-3,-1,46:18.1
-2,-1,46:18.1
0,-1,46:17.1
1,-1,46:18.1
2,0,46:18.1
-1,1,46:18.1
0,1,46:18.1
0,-2,47:17.1
2,-2,47:18.1
0,-1,47:17.1
1,-1,47:18.1
2,-1,47:18.1
1,0,47:18.1
0,-3,48:18.1
1,-3,48:18.1
-1,-2,48:18.1
0,-2,48:18.1
1,-2,48:18.1
-2,-1,48:18.1
-1,-1,48:18.1
0,-1,48:17.1
1,-1,48:18.1
-2,0,48:18.1
-1,0,48:18.1
1,0,48:18.1
0,1,48:18.1
1,1,48:18.1
-1,-3,49:18.1
0,-2,49:18.1
-2,-1,49:18.1
0,-1,49:17.1
2,-1,49:18.1
0,1,49:18.1
0,-2,50:18.1
1,-2,50:18.1
0,-1,50:17.1
-1,0,50:18.1
-1,-2,51:18.1
-2,-1,51:18.1
-1,-1,51:18.1
0,-1,51:17.1
1,-1,51:18.1
0,0,51:18.1
1,0,51:18.1
0,1,51:18.1
0,-3,52:18.1
-1,-2,52:18.1
0,-2,52:18.1
2,-2,52:18.1
0,-1,52:17.1
2,-1,52:18.1
-2,0,52:18.1
-1,0,52:18.1
0,0,52:18.1
-1,1,52:18.1
0,1,52:18.1
1,1,52:18.1
0,-2,53:18.1
-1,-1,53:18.1
0,-1,53:17.1
-1,0,53:18.1
0,1,53:18.1
-1,-2,54:18.1
0,-2,54:18.1
0,-1,54:17.1
0,0,54:18.1
