[META]
version=2.0
spawnOnBlockType=2
spawnSunlight=True
spawnDarkness=True
spawnWater=False
spawnLava=False
underFill=False
randomRotation=True
dig=True
tree=True
branch=False
needsFoundation=True
rarity=5
collisionPercentage=20
spawnElevationMin=0
spawnElevationMax=200
spawnInBiome=Custom
[DATA]
-1,0,-3:17.1
0,0,-3:17.1
-1,1,-3:17.1
0,1,-3:17.1
-1,0,-2:17.1
0,0,-2:17.1
-1,1,-2:17.1
0,1,-2:17.1
-1,0,-1:17.1
0,0,-1:17.1
-1,1,-1:17.1
0,1,-1:17.1
-1,0,0:17.1
0,0,0:17.1
-1,1,0:17.1
0,1,0:17.1
-1,0,1:17.1
0,0,1:17.1
-1,1,1:17.1
0,1,1:17.1
-3,-4,2:18.1
-1,-4,2:18.1
0,-4,2:18.1
1,-4,2:18.1
-3,-3,2:18.1
0,-3,2:18.1
1,-3,2:18.1
2,-3,2:18.1
-4,-2,2:18.1
-3,-2,2:18.1
-2,-2,2:18.1
0,-2,2:18.1
3,-2,2:18.1
4,-2,2:18.1
-5,-1,2:18.1
-3,-1,2:18.1
-1,-1,2:18.1
0,-1,2:18.1
1,-1,2:18.1
2,-1,2:18.1
3,-1,2:18.1
-6,0,2:18.1
-4,0,2:18.1
-3,0,2:18.1
-2,0,2:18.1
-1,0,2:17.1
0,0,2:17.1
1,0,2:18.1
2,0,2:18.1
3,0,2:18.1
4,0,2:18.1
-7,1,2:18.1
-5,1,2:18.1
-4,1,2:18.1
-3,1,2:18.1
-2,1,2:18.1
-1,1,2:17.1
0,1,2:17.1
1,1,2:18.1
2,1,2:18.1
3,1,2:18.1
-4,2,2:18.1
-3,2,2:18.1
-1,2,2:18.1
0,2,2:18.1
3,2,2:18.1
-6,3,2:18.1
-5,3,2:18.1
-4,3,2:18.1
-3,3,2:18.1
-2,3,2:18.1
-1,3,2:18.1
0,3,2:18.1
1,3,2:18.1
-5,4,2:18.1
-3,4,2:18.1
-2,4,2:18.1
-1,4,2:18.1
0,4,2:18.1
1,4,2:18.1
3,4,2:18.1
-4,5,2:18.1
-3,5,2:18.1
-1,5,2:18.1
0,5,2:18.1
2,5,2:18.1
-4,6,2:18.1
-2,6,2:18.1
0,6,2:18.1
1,6,2:18.1
-1,-7,3:18.1
-3,-6,3:18.1
-1,-6,3:18.1
1,-6,3:18.1
-3,-5,3:18.1
-1,-5,3:18.1
0,-5,3:18.1
1,-5,3:18.1
-3,-4,3:18.1
-1,-4,3:17.1
3,-4,3:18.1
-5,-3,3:18.1
-4,-3,3:18.1
-3,-3,3:18.1
-2,-3,3:18.1
-1,-3,3:17.1
1,-3,3:18.1
2,-3,3:18.1
3,-3,3:18.1
4,-3,3:18.1
-4,-2,3:18.1
-3,-2,3:18.1
-2,-2,3:17.1
-1,-2,3:17.1
0,-2,3:18.1
1,-2,3:18.1
2,-2,3:18.1
5,-2,3:18.1
-6,-1,3:18.1
-5,-1,3:18.1
-4,-1,3:18.1
-2,-1,3:18.1
-1,-1,3:17.1
0,-1,3:18.1
1,-1,3:18.1
2,-1,3:17.1
3,-1,3:18.1
4,-1,3:18.1
5,-1,3:18.1
6,-1,3:18.1
-7,0,3:18.1
-6,0,3:18.1
-5,0,3:18.1
-3,0,3:18.1
-2,0,3:18.1
-1,0,3:17.1
0,0,3:17.1
1,0,3:17.1
2,0,3:17.1
3,0,3:17.1
4,0,3:17.1
5,0,3:18.1
6,0,3:18.1
-7,1,3:18.1
-6,1,3:18.1
-5,1,3:17.1
-4,1,3:17.1
-3,1,3:17.1
-2,1,3:17.1
-1,1,3:17.1
0,1,3:17.1
1,1,3:18.1
2,1,3:18.1
3,1,3:18.1
4,1,3:18.1
5,1,3:18.1
-6,2,3:18.1
-5,2,3:18.1
-4,2,3:18.1
-3,2,3:17.1
-2,2,3:18.1
-1,2,3:18.1
0,2,3:17.1
1,2,3:18.1
2,2,3:18.1
3,2,3:18.1
4,2,3:18.1
5,2,3:18.1
-4,3,3:18.1
-3,3,3:18.1
-1,3,3:18.1
0,3,3:17.1
1,3,3:17.1
2,3,3:18.1
4,3,3:18.1
-4,4,3:18.1
-2,4,3:18.1
-1,4,3:18.1
0,4,3:17.1
1,4,3:18.1
2,4,3:18.1
3,4,3:18.1
-3,5,3:18.1
-2,5,3:18.1
0,5,3:17.1
1,5,3:18.1
2,5,3:18.1
3,5,3:18.1
-1,6,3:18.1
0,6,3:18.1
1,6,3:18.1
2,6,3:18.1
-1,7,3:18.1
0,7,3:18.1
1,7,3:18.1
-2,-6,4:18.1
-2,-5,4:18.1
-1,-5,4:18.1
-2,-4,4:18.1
-1,-4,4:18.1
1,-4,4:18.1
-3,-3,4:18.1
-2,-3,4:18.1
-1,-3,4:18.1
0,-3,4:18.1
1,-3,4:18.1
3,-3,4:18.1
-4,-2,4:18.1
-3,-2,4:18.1
-2,-2,4:18.1
-1,-2,4:18.1
0,-2,4:18.1
1,-2,4:18.1
2,-2,4:18.1
3,-2,4:18.1
4,-2,4:18.1
-5,-1,4:18.1
-4,-1,4:18.1
-3,-1,4:18.1
-2,-1,4:18.1
-1,-1,4:18.1
0,-1,4:18.1
1,-1,4:18.1
2,-1,4:18.1
3,-1,4:18.1
-4,0,4:18.1
-3,0,4:18.1
-2,0,4:18.1
-1,0,4:17.1
0,0,4:17.1
1,0,4:18.1
2,0,4:18.1
3,0,4:18.1
4,0,4:18.1
5,0,4:18.1
-5,1,4:18.1
-4,1,4:18.1
-2,1,4:18.1
-1,1,4:17.1
0,1,4:17.1
1,1,4:18.1
2,1,4:18.1
3,1,4:18.1
4,1,4:18.1
-4,2,4:18.1
-2,2,4:18.1
-1,2,4:18.1
0,2,4:18.1
1,2,4:18.1
2,2,4:18.1
4,2,4:18.1
-3,3,4:18.1
-2,3,4:18.1
-1,3,4:18.1
0,3,4:18.1
1,3,4:18.1
-5,4,4:18.1
-4,4,4:18.1
-3,4,4:18.1
-1,4,4:18.1
0,4,4:18.1
1,4,4:18.1
3,4,4:18.1
4,4,4:18.1
-2,5,4:18.1
0,5,4:18.1
1,5,4:18.1
2,5,4:18.1
-2,6,4:18.1
1,6,4:18.1
-2,7,4:18.1
-2,-5,5:18.1
1,-5,5:18.1
-3,-4,5:18.1
-2,-4,5:18.1
-1,-4,5:18.1
1,-4,5:18.1
2,-4,5:18.1
-5,-3,5:18.1
-4,-3,5:18.1
-3,-3,5:18.1
-2,-3,5:18.1
-1,-3,5:18.1
1,-3,5:18.1
3,-3,5:18.1
-5,-2,5:18.1
-3,-2,5:18.1
-1,-2,5:18.1
0,-2,5:18.1
2,-2,5:18.1
3,-2,5:18.1
-6,-1,5:18.1
-4,-1,5:18.1
-3,-1,5:18.1
-2,-1,5:18.1
-1,-1,5:18.1
0,-1,5:18.1
2,-1,5:18.1
3,-1,5:18.1
4,-1,5:18.1
-5,0,5:18.1
-4,0,5:18.1
-3,0,5:18.1
-2,0,5:18.1
-1,0,5:17.1
0,0,5:17.1
1,0,5:18.1
2,0,5:18.1
3,0,5:18.1
-4,1,5:18.1
-3,1,5:18.1
-2,1,5:18.1
-1,1,5:17.1
0,1,5:17.1
1,1,5:18.1
2,1,5:18.1
3,1,5:18.1
4,1,5:18.1
-6,2,5:18.1
-5,2,5:18.1
-4,2,5:18.1
-3,2,5:18.1
-2,2,5:18.1
-1,2,5:18.1
0,2,5:18.1
1,2,5:18.1
-5,3,5:18.1
-4,3,5:18.1
-2,3,5:18.1
-1,3,5:18.1
1,3,5:18.1
2,3,5:18.1
-4,4,5:18.1
-1,4,5:18.1
0,4,5:18.1
2,4,5:18.1
-3,5,5:18.1
-2,5,5:18.1
-1,5,5:18.1
0,5,5:18.1
2,5,5:18.1
-2,6,5:18.1
-2,-5,6:18.1
0,-5,6:18.1
-2,-4,6:18.1
-1,-4,6:18.1
0,-4,6:18.1
-2,-3,6:18.1
-1,-3,6:18.1
0,-3,6:18.1
1,-3,6:18.1
-3,-2,6:18.1
-2,-2,6:18.1
-1,-2,6:18.1
0,-2,6:17.1
1,-2,6:18.1
2,-2,6:18.1
-3,-1,6:18.1
-2,-1,6:18.1
-1,-1,6:18.1
0,-1,6:17.1
1,-1,6:18.1
2,-1,6:18.1
3,-1,6:18.1
4,-1,6:18.1
5,-1,6:18.1
-4,0,6:18.1
-3,0,6:17.1
-2,0,6:17.1
-1,0,6:17.1
0,0,6:17.1
1,0,6:18.1
2,0,6:18.1
3,0,6:18.1
4,0,6:18.1
-5,1,6:18.1
-4,1,6:18.1
-2,1,6:18.1
-1,1,6:17.1
0,1,6:17.1
1,1,6:17.1
2,1,6:17.1
3,1,6:18.1
-5,2,6:18.1
-4,2,6:18.1
-3,2,6:18.1
-1,2,6:17.1
0,2,6:18.1
1,2,6:18.1
2,2,6:18.1
3,2,6:18.1
4,2,6:18.1
5,2,6:18.1
-3,3,6:18.1
-2,3,6:18.1
-1,3,6:17.1
0,3,6:18.1
1,3,6:18.1
2,3,6:18.1
3,3,6:18.1
-2,4,6:18.1
-1,4,6:18.1
1,4,6:18.1
-1,5,6:18.1
0,5,6:18.1
0,6,6:18.1
-1,-5,7:18.1
-3,-4,7:18.1
-2,-4,7:18.1
-1,-4,7:18.1
2,-4,7:18.1
-2,-3,7:18.1
-1,-3,7:18.1
1,-3,7:18.1
2,-3,7:18.1
-5,-2,7:18.1
-4,-2,7:18.1
-2,-2,7:18.1
-1,-2,7:18.1
0,-2,7:18.1
3,-2,7:18.1
-4,-1,7:18.1
-1,-1,7:18.1
0,-1,7:18.1
2,-1,7:18.1
3,-1,7:18.1
4,-1,7:18.1
-4,0,7:18.1
-3,0,7:18.1
-2,0,7:18.1
-1,0,7:17.1
0,0,7:17.1
1,0,7:18.1
2,0,7:18.1
-5,1,7:18.1
-4,1,7:18.1
-3,1,7:18.1
-2,1,7:18.1
-1,1,7:17.1
0,1,7:17.1
1,1,7:18.1
2,1,7:18.1
3,1,7:18.1
4,1,7:18.1
5,1,7:18.1
-4,2,7:18.1
-2,2,7:18.1
-1,2,7:18.1
0,2,7:18.1
1,2,7:18.1
2,2,7:18.1
3,2,7:18.1
4,2,7:18.1
-6,3,7:18.1
-5,3,7:18.1
-4,3,7:18.1
-1,3,7:18.1
0,3,7:18.1
1,3,7:18.1
2,3,7:18.1
-5,4,7:18.1
-4,4,7:18.1
-3,4,7:18.1
-2,4,7:18.1
-1,4,7:18.1
0,4,7:18.1
2,4,7:18.1
3,4,7:18.1
-4,5,7:18.1
-2,5,7:18.1
2,5,7:18.1
-2,6,7:18.1
-2,-4,8:18.1
0,-4,8:18.1
1,-4,8:18.1
-5,-3,8:18.1
-4,-3,8:18.1
-1,-3,8:18.1
0,-3,8:18.1
-4,-2,8:18.1
-3,-2,8:18.1
-2,-2,8:18.1
-1,-2,8:18.1
0,-2,8:18.1
1,-2,8:18.1
2,-2,8:18.1
3,-2,8:18.1
4,-2,8:18.1
-4,-1,8:18.1
-2,-1,8:18.1
0,-1,8:18.1
1,-1,8:18.1
-6,0,8:18.1
-5,0,8:18.1
-4,0,8:18.1
-3,0,8:18.1
-2,0,8:18.1
-1,0,8:17.1
0,0,8:17.1
1,0,8:18.1
2,0,8:18.1
3,0,8:18.1
4,0,8:18.1
5,0,8:18.1
-4,1,8:18.1
-3,1,8:18.1
-2,1,8:18.1
-1,1,8:17.1
0,1,8:17.1
1,1,8:18.1
2,1,8:18.1
3,1,8:18.1
-5,2,8:18.1
-3,2,8:18.1
-2,2,8:18.1
-1,2,8:18.1
0,2,8:18.1
1,2,8:18.1
-5,3,8:18.1
-3,3,8:18.1
-2,3,8:18.1
-1,3,8:18.1
0,3,8:18.1
2,3,8:18.1
0,4,8:18.1
0,5,8:18.1
-2,-4,9:18.1
-1,-4,9:18.1
0,-4,9:18.1
-1,-3,9:18.1
0,-3,9:18.1
1,-3,9:18.1
-2,-2,9:18.1
-1,-2,9:17.1
0,-2,9:18.1
1,-2,9:18.1
2,-2,9:18.1
-4,-1,9:18.1
-2,-1,9:18.1
-1,-1,9:17.1
1,-1,9:18.1
4,-1,9:18.1
-5,0,9:18.1
-4,0,9:18.1
-3,0,9:18.1
-1,0,9:17.1
0,0,9:17.1
1,0,9:17.1
2,0,9:17.1
3,0,9:18.1
-5,1,9:18.1
-4,1,9:18.1
-3,1,9:17.1
-2,1,9:17.1
-1,1,9:17.1
0,1,9:17.1
1,1,9:18.1
2,1,9:18.1
3,1,9:18.1
4,1,9:18.1
-5,2,9:18.1
-4,2,9:18.1
-2,2,9:18.1
-1,2,9:18.1
0,2,9:17.1
1,2,9:18.1
2,2,9:18.1
-3,3,9:18.1
-2,3,9:18.1
0,3,9:17.1
1,3,9:18.1
2,3,9:18.1
3,3,9:18.1
-3,4,9:18.1
-2,4,9:18.1
-1,4,9:18.1
0,4,9:18.1
1,4,9:18.1
2,4,9:18.1
-2,5,9:18.1
0,5,9:18.1
1,5,9:18.1
-1,-4,10:18.1
-3,-3,10:18.1
-2,-3,10:18.1
-1,-3,10:18.1
1,-3,10:18.1
-3,-2,10:18.1
-1,-2,10:18.1
0,-2,10:18.1
1,-2,10:18.1
-3,-1,10:18.1
-2,-1,10:18.1
0,-1,10:18.1
1,-1,10:18.1
2,-1,10:18.1
3,-1,10:18.1
4,-1,10:18.1
-4,0,10:18.1
-3,0,10:18.1
-1,0,10:17.1
0,0,10:17.1
1,0,10:18.1
2,0,10:18.1
4,0,10:18.1
-5,1,10:18.1
-3,1,10:18.1
-2,1,10:18.1
-1,1,10:17.1
0,1,10:17.1
1,1,10:18.1
2,1,10:18.1
3,1,10:18.1
-4,2,10:18.1
-3,2,10:18.1
-2,2,10:18.1
-1,2,10:18.1
0,2,10:18.1
1,2,10:18.1
2,2,10:18.1
-4,3,10:18.1
-3,3,10:18.1
-2,3,10:18.1
-1,3,10:18.1
0,3,10:18.1
2,3,10:18.1
-4,4,10:18.1
0,4,10:18.1
1,4,10:18.1
-2,-3,11:18.1
0,-3,11:18.1
-2,-2,11:18.1
-1,-2,11:18.1
0,-2,11:18.1
-4,-1,11:18.1
-2,-1,11:18.1
-1,-1,11:18.1
0,-1,11:18.1
1,-1,11:18.1
2,-1,11:18.1
-4,0,11:18.1
-3,0,11:18.1
-2,0,11:18.1
-1,0,11:17.1
0,0,11:17.1
1,0,11:18.1
2,0,11:18.1
3,0,11:18.1
-4,1,11:18.1
-3,1,11:18.1
-2,1,11:18.1
-1,1,11:17.1
0,1,11:17.1
1,1,11:18.1
2,1,11:18.1
-3,2,11:18.1
-2,2,11:18.1
-1,2,11:18.1
0,2,11:18.1
1,2,11:18.1
-2,3,11:18.1
-1,3,11:18.1
0,3,11:18.1
1,3,11:18.1
-1,4,11:18.1
0,-4,12:18.1
-3,-3,12:18.1
0,-3,12:18.1
2,-3,12:18.1
-3,-2,12:18.1
-2,-2,12:18.1
-1,-2,12:18.1
0,-2,12:18.1
1,-2,12:18.1
2,-2,12:18.1
3,-2,12:18.1
-4,-1,12:18.1
-2,-1,12:18.1
-1,-1,12:18.1
0,-1,12:17.1
1,-1,12:18.1
2,-1,12:18.1
-5,0,12:18.1
-4,0,12:18.1
-3,0,12:18.1
-2,0,12:17.1
-1,0,12:17.1
0,0,12:17.1
1,0,12:18.1
2,0,12:18.1
-4,1,12:18.1
-3,1,12:18.1
-2,1,12:18.1
-1,1,12:17.1
0,1,12:17.1
1,1,12:17.1
2,1,12:18.1
3,1,12:18.1
-3,2,12:18.1
-2,2,12:18.1
-1,2,12:17.1
0,2,12:18.1
1,2,12:18.1
3,2,12:18.1
-4,3,12:18.1
-3,3,12:18.1
-2,3,12:18.1
-1,3,12:18.1
0,3,12:18.1
1,3,12:18.1
2,3,12:18.1
-3,4,12:18.1
-1,4,12:18.1
1,4,12:18.1
-1,-3,13:18.1
0,-3,13:18.1
-2,-2,13:18.1
-1,-2,13:18.1
0,-2,13:18.1
2,-2,13:18.1
-4,-1,13:18.1
-2,-1,13:18.1
-1,-1,13:18.1
0,-1,13:18.1
1,-1,13:18.1
2,-1,13:18.1
-3,0,13:18.1
-2,0,13:18.1
-1,0,13:17.1
0,0,13:17.1
1,0,13:18.1
2,0,13:18.1
3,0,13:18.1
-3,1,13:18.1
-2,1,13:18.1
-1,1,13:17.1
0,1,13:17.1
1,1,13:18.1
3,1,13:18.1
-3,2,13:18.1
-2,2,13:18.1
-1,2,13:18.1
0,2,13:18.1
1,2,13:18.1
2,2,13:18.1
-1,3,13:18.1
0,3,13:18.1
1,3,13:18.1
1,4,13:18.1
2,4,13:18.1
0,-3,14:18.1
-3,-2,14:18.1
0,-2,14:18.1
1,-2,14:18.1
-3,-1,14:18.1
-2,-1,14:18.1
-1,-1,14:18.1
0,-1,14:18.1
1,-1,14:18.1
-2,0,14:18.1
-1,0,14:17.1
0,0,14:17.1
1,0,14:18.1
2,0,14:18.1
-2,1,14:18.1
-1,1,14:17.1
0,1,14:17.1
1,1,14:18.1
-2,2,14:18.1
-1,2,14:18.1
0,2,14:18.1
1,2,14:18.1
2,2,14:18.1
3,2,14:18.1
-3,3,14:18.1
-2,3,14:18.1
0,3,14:18.1
2,3,14:18.1
-2,4,14:18.1
0,4,14:18.1
-1,-3,15:18.1
-1,-2,15:18.1
0,-2,15:18.1
1,-2,15:18.1
2,-2,15:18.1
-3,-1,15:18.1
-2,-1,15:18.1
-1,-1,15:17.1
0,-1,15:18.1
1,-1,15:18.1
-4,0,15:18.1
-3,0,15:18.1
-2,0,15:18.1
-1,0,15:17.1
0,0,15:17.1
1,0,15:17.1
2,0,15:18.1
-3,1,15:18.1
-2,1,15:17.1
-1,1,15:17.1
0,1,15:17.1
1,1,15:18.1
2,1,15:18.1
-3,2,15:18.1
-2,2,15:18.1
-1,2,15:18.1
0,2,15:17.1
1,2,15:18.1
2,2,15:18.1
-1,3,15:18.1
0,3,15:18.1
1,3,15:18.1
1,4,15:18.1
-1,-2,16:18.1
-3,-1,16:18.1
-2,-1,16:18.1
-1,-1,16:18.1
0,-1,16:18.1
1,-1,16:18.1
-2,0,16:18.1
-1,0,16:17.1
0,0,16:17.1
1,0,16:18.1
-1,1,16:17.1
0,1,16:17.1
1,1,16:18.1
-3,2,16:18.1
-2,2,16:18.1
-1,2,16:18.1
0,2,16:18.1
1,2,16:18.1
2,2,16:18.1
-3,3,16:18.1
-2,3,16:18.1
0,3,16:18.1
1,3,16:18.1
-1,4,16:18.1
0,4,16:18.1
-1,-2,17:18.1
0,-2,17:18.1
1,-2,17:18.1
-2,-1,17:18.1
-1,-1,17:18.1
0,-1,17:18.1
-3,0,17:18.1
-2,0,17:18.1
-1,0,17:17.1
0,0,17:17.1
1,0,17:18.1
2,0,17:18.1
3,0,17:18.1
-3,1,17:18.1
-2,1,17:18.1
-1,1,17:17.1
0,1,17:17.1
1,1,17:18.1
2,1,17:18.1
-3,2,17:18.1
-1,2,17:18.1
0,2,17:18.1
1,2,17:18.1
-2,-2,18:18.1
0,-2,18:18.1
-2,-1,18:18.1
-1,-1,18:18.1
0,-1,18:17.1
1,-1,18:18.1
-3,0,18:18.1
-2,0,18:17.1
-1,0,18:17.1
0,0,18:17.1
1,0,18:18.1
2,0,18:18.1
-2,1,18:18.1
-1,1,18:17.1
0,1,18:17.1
1,1,18:17.1
2,1,18:18.1
-2,2,18:18.1
-1,2,18:17.1
1,2,18:18.1
-2,3,18:18.1
-1,3,18:18.1
0,3,18:18.1
1,3,18:18.1
0,4,18:18.1
-2,-1,19:18.1
-1,-1,19:18.1
0,-1,19:18.1
1,-1,19:18.1
2,-1,19:18.1
-2,0,19:18.1
-1,0,19:17.1
0,0,19:17.1
1,0,19:18.1
-3,1,19:18.1
-2,1,19:18.1
-1,1,19:17.1
0,1,19:17.1
1,1,19:18.1
-2,2,19:18.1
-1,2,19:18.1
0,2,19:18.1
1,2,19:18.1
-1,3,19:18.1
-1,-1,20:18.1
0,-1,20:18.1
-1,0,20:17.1
0,0,20:17.1
-1,1,20:17.1
0,1,20:17.1
-1,2,20:18.1
0,2,20:18.1
-1,0,21:17.1
0,0,21:17.1
-2,1,21:18.1
-1,1,21:17.1
0,1,21:17.1
-3,-1,22:18.1
0,-1,22:18.1
-2,0,22:18.1
-1,0,22:17.1
0,0,22:17.1
2,0,22:18.1
-2,1,22:18.1
-1,1,22:17.1
0,1,22:17.1
1,1,22:18.1
-1,3,22:18.1
0,3,22:18.1
0,-3,23:18.1
-1,-2,23:18.1
0,-2,23:18.1
-3,-1,23:18.1
-2,-1,23:18.1
-1,-1,23:18.1
1,-1,23:18.1
-2,0,23:18.1
-1,0,23:17.1
0,0,23:17.1
1,0,23:18.1
2,0,23:18.1
-3,1,23:18.1
-2,1,23:18.1
-1,1,23:17.1
0,1,23:17.1
1,1,23:18.1
2,1,23:18.1
-2,2,23:18.1
0,2,23:18.1
1,2,23:18.1
-1,3,23:18.1
0,3,23:18.1
0,-2,24:18.1
-1,-1,24:18.1
0,-1,24:18.1
-2,0,24:18.1
-1,0,24:17.1
0,0,24:17.1
1,0,24:18.1
-2,1,24:18.1
-1,1,24:17.1
0,1,24:17.1
1,1,24:18.1
-1,2,24:18.1
0,2,24:18.1
-1,0,25:18.1
0,0,25:18.1
-1,1,25:18.1
0,1,25:18.1
-1,0,26:18.1
0,0,26:18.1
-1,1,26:18.1
0,1,26:18.1
-1,0,27:18.1
0,0,27:18.1
-1,1,27:18.1
0,1,27:18.1
