[META]
version=2.0
spawnOnBlockType=9
spawnSunlight=True
spawnDarkness=True
spawnWater=True
spawnLava=False
underFill=False
randomRotation=True
dig=True
tree=True
branch=False
needsFoundation=True
rarity=50
collisionPercentage=20
spawnElevationMin=0
spawnElevationMax=60
spawnInBiome=Custom
[DATA]
0,7,-8:17.13
-5,8,-8:17.13
0,8,-8:17.13
0,7,-7:17.13
-5,8,-7:17.13
0,8,-7:17.13
0,7,-6:17.13
-5,8,-6:17.13
0,8,-6:17.13
0,7,-5:17.13
-5,8,-5:17.13
0,8,-5:17.13
0,3,-4:17.13
-5,4,-4:17.13
1,5,-4:17.13
0,7,-4:17.13
-5,8,-4:17.13
0,8,-4:17.13
0,3,-3:17.13
-5,4,-3:17.13
1,5,-3:17.13
0,7,-3:17.13
-5,8,-3:17.13
0,8,-3:17.13
-4,3,-2:17.13
0,3,-2:17.13
-5,4,-2:17.13
1,5,-2:17.13
0,7,-2:17.13
-5,8,-2:17.13
0,8,-2:17.13
-4,3,-1:17.13
0,3,-1:17.13
-5,4,-1:17.13
1,5,-1:17.13
0,7,-1:17.13
-5,8,-1:17.13
0,8,-1:17.13
-4,3,0:17.13
0,3,0:17.13
-5,4,0:17.13
1,5,0:17.13
0,7,0:17.13
-5,8,0:17.13
0,8,0:17.13
-4,3,1:17.13
0,3,1:17.13
-5,4,1:17.13
1,5,1:17.13
0,7,1:17.13
-5,8,1:17.13
-4,8,1:17.13
0,8,1:17.13
-4,3,2:17.13
0,3,2:17.13
-5,4,2:17.13
1,5,2:17.13
0,7,2:17.13
-5,8,2:17.13
-4,8,2:17.13
0,8,2:17.13
-4,3,3:17.13
0,3,3:17.13
-5,4,3:17.13
0,5,3:17.13
0,7,3:17.13
-5,8,3:17.13
-4,8,3:17.13
0,8,3:17.13
-4,3,4:17.13
0,3,4:17.13
-5,4,4:17.13
0,5,4:17.13
0,7,4:17.13
-5,8,4:17.13
-4,8,4:17.13
0,8,4:17.13
-4,3,5:17.13
0,3,5:17.13
-5,4,5:17.13
0,5,5:17.13
0,7,5:17.13
-5,8,5:17.13
-4,8,5:17.13
0,8,5:17.13
-4,3,6:17.13
-3,3,6:17.13
-2,3,6:17.13
-1,3,6:17.13
0,3,6:17.13
-5,4,6:17.13
-4,4,6:17.13
-3,4,6:17.13
-2,4,6:17.13
-1,4,6:17.13
0,4,6:17.13
-5,5,6:17.13
-4,5,6:17.13
-3,5,6:17.13
-2,5,6:17.13
-1,5,6:17.13
0,5,6:17.13
-5,6,6:17.13
-4,6,6:17.13
-3,6,6:17.13
-2,6,6:17.13
-1,6,6:17.13
0,6,6:17.13
-5,7,6:17.13
-4,7,6:17.13
-3,7,6:17.13
-2,7,6:17.13
-1,7,6:17.13
0,7,6:17.13
-5,8,6:17.13
-4,8,6:17.13
-3,8,6:17.13
-2,8,6:17.13
-1,8,6:17.13
0,8,6:17.13
-4,3,7:17.13
-3,3,7:17.13
-2,3,7:17.13
0,3,7:17.13
-5,4,7:17.13
-4,4,7:17.13
-3,4,7:17.13
-2,4,7:17.13
-1,4,7:17.13
-5,5,7:17.13
-4,5,7:17.13
-3,5,7:17.13
-2,5,7:17.13
-1,5,7:17.13
0,5,7:17.13
-5,6,7:17.13
-4,6,7:17.13
-3,6,7:17.13
-2,6,7:17.13
-1,6,7:17.13
0,6,7:17.13
-4,7,7:17.13
-3,7,7:17.13
-2,7,7:17.13
-1,7,7:17.13
0,7,7:17.13
-5,8,7:17.13
-4,8,7:17.13
-3,8,7:17.13
-2,8,7:17.13
0,8,7:17.13
-4,3,8:17.13
-1,3,8:17.13
-5,4,8:17.13
-4,4,8:17.13
-3,4,8:17.13
-2,4,8:17.13
-1,4,8:17.13
-4,5,8:17.13
-3,5,8:17.13
-2,5,8:17.13
-1,5,8:17.13
0,5,8:17.13
-4,6,8:17.13
-3,6,8:17.13
-2,6,8:17.13
-1,6,8:17.13
-4,7,8:17.13
-3,7,8:17.13
-2,7,8:17.13
-1,7,8:17.13
0,7,8:17.13
-4,8,8:17.13
0,8,8:17.13
-4,3,9:17.13
-5,4,9:17.13
-4,4,9:17.13
-3,4,9:17.13
-2,4,9:17.13
-1,4,9:17.13
-4,5,9:17.13
-3,5,9:17.13
-2,5,9:17.13
-1,5,9:17.13
0,5,9:17.13
-4,6,9:17.13
-3,6,9:17.13
-2,6,9:17.13
-1,6,9:17.13
-4,7,9:17.13
-3,7,9:17.13
-2,7,9:17.13
-1,7,9:17.13
0,7,9:17.13
-4,4,10:17.13
-3,4,10:17.13
-2,4,10:17.13
-1,4,10:17.13
-4,5,10:17.13
-3,5,10:17.13
-2,5,10:17.13
-1,5,10:17.13
0,5,10:17.13
-4,6,10:17.13
-3,6,10:17.13
-2,6,10:17.13
-1,6,10:17.13
-4,7,10:17.13
-3,7,10:17.13
-2,7,10:17.13
-1,7,10:17.13
0,7,10:17.13
-4,4,11:17.13
-3,4,11:17.13
-2,4,11:17.13
-1,4,11:17.13
-4,5,11:17.13
-3,5,11:17.13
-2,5,11:17.13
-1,5,11:17.13
-5,6,11:17.13
-4,6,11:17.13
-3,6,11:17.13
-2,6,11:17.13
-1,6,11:17.13
-4,7,11:17.13
-3,7,11:17.13
-2,7,11:17.13
-1,7,11:17.13
-3,4,12:17.13
-2,4,12:17.13
-4,5,12:17.13
-3,5,12:17.13
-2,5,12:17.13
-1,5,12:17.13
-5,6,12:17.13
-4,6,12:17.13
-3,6,12:17.13
-2,6,12:17.13
-1,6,12:17.13
-3,7,12:17.13
-2,7,12:17.13
-3,4,13:17.13
-2,4,13:17.13
-4,5,13:17.13
-3,5,13:17.13
-2,5,13:17.13
-1,5,13:17.13
-4,6,13:17.13
-3,6,13:17.13
-2,6,13:17.13
-1,6,13:17.13
-3,7,13:17.13
-2,7,13:17.13
-3,3,14:17.13
-3,4,14:17.13
-2,4,14:17.13
-4,5,14:17.13
-3,5,14:17.13
-2,5,14:17.13
-1,5,14:17.13
-4,6,14:17.13
-3,6,14:17.13
-2,6,14:17.13
-1,6,14:17.13
-3,7,14:17.13
-2,7,14:17.13
-6,-9,15:18.1
-5,-9,15:18.1
-4,-9,15:18.1
-3,-9,15:18.1
-7,-8,15:18.1
-6,-8,15:18.1
-5,-8,15:18.1
-4,-8,15:18.1
-3,-8,15:18.1
-2,-8,15:18.1
-8,-7,15:18.1
-7,-7,15:18.1
-6,-7,15:18.1
-5,-7,15:18.1
-4,-7,15:18.1
-3,-7,15:18.1
-2,-7,15:18.1
-1,-7,15:18.1
-9,-6,15:18.1
-8,-6,15:18.1
-7,-6,15:18.1
-6,-6,15:18.1
-5,-6,15:17.13
-4,-6,15:17.13
-3,-6,15:18.1
-2,-6,15:18.1
-1,-6,15:18.1
-9,-5,15:18.1
-8,-5,15:18.1
-7,-5,15:18.1
-6,-5,15:17.13
-5,-5,15:17.13
-4,-5,15:17.13
-3,-5,15:18.1
-2,-5,15:18.1
-1,-5,15:18.1
-9,-4,15:18.1
-8,-4,15:18.1
-7,-4,15:18.1
-6,-4,15:18.1
-5,-4,15:17.13
-4,-4,15:17.13
-3,-4,15:18.1
-2,-4,15:18.1
-8,-3,15:18.1
-7,-3,15:18.1
-6,-3,15:18.1
-5,-3,15:18.1
-4,-3,15:17.13
-3,-3,15:18.1
-7,-2,15:18.1
-6,-2,15:18.1
-5,-2,15:18.1
-4,-2,15:17.13
-4,-1,15:17.13
-4,0,15:17.13
-4,1,15:17.13
-4,2,15:17.13
-3,5,15:17.13
-2,5,15:17.13
-3,6,15:17.13
-2,6,15:17.13
-5,-9,16:18.1
-4,-9,16:18.1
-7,-8,16:18.1
-6,-8,16:18.1
-5,-8,16:18.1
-4,-8,16:18.1
-3,-8,16:18.1
-2,-8,16:18.1
-8,-7,16:18.1
-7,-7,16:18.1
-6,-7,16:18.1
-5,-7,16:18.1
-4,-7,16:18.1
-3,-7,16:18.1
-2,-7,16:18.1
-8,-6,16:18.1
-7,-6,16:18.1
-6,-6,16:18.1
-5,-6,16:18.1
-4,-6,16:18.1
-3,-6,16:18.1
-2,-6,16:18.1
-1,-6,16:18.1
-9,-5,16:18.1
-8,-5,16:18.1
-7,-5,16:18.1
-6,-5,16:18.1
-5,-5,16:18.1
-4,-5,16:18.1
-3,-5,16:18.1
-2,-5,16:18.1
-8,-4,16:18.1
-7,-4,16:18.1
-6,-4,16:18.1
-5,-4,16:18.1
-4,-4,16:18.1
-3,-4,16:18.1
-2,-4,16:18.1
-8,-3,16:18.1
-7,-3,16:18.1
-6,-3,16:18.1
-5,-3,16:18.1
-4,-3,16:18.1
-6,-2,16:18.1
-3,5,16:17.13
-2,5,16:17.13
-3,6,16:17.13
-2,6,16:17.13
-3,5,17:17.13
-2,5,17:17.13
-3,6,17:17.13
-2,6,17:17.13
-3,5,18:17.13
-2,5,18:17.13
-3,6,18:17.13
-2,6,18:17.13
-3,5,19:17.13
-2,5,19:17.13
-3,6,19:17.13
-2,6,19:17.13
-3,5,20:17.13
-2,5,20:17.13
-4,6,20:17.13
-3,6,20:17.13
-2,6,20:17.13
-3,5,21:17.13
-2,5,21:17.13
-3,6,21:17.13
-2,6,21:17.13
-8,7,21:18.1
-7,7,21:18.1
-6,7,21:17.13
-5,7,21:17.13
-9,8,21:18.1
-8,8,21:18.1
-7,8,21:17.13
-6,8,21:18.1
-5,8,21:18.1
-10,9,21:18.1
-9,9,21:18.1
-8,9,21:18.1
-7,9,21:17.13
-6,9,21:18.1
-5,9,21:18.1
-4,9,21:18.1
-10,10,21:18.1
-9,10,21:18.1
-8,10,21:18.1
-7,10,21:17.13
-6,10,21:18.1
-5,10,21:18.1
-4,10,21:18.1
-10,11,21:18.1
-9,11,21:18.1
-8,11,21:18.1
-7,11,21:18.1
-6,11,21:18.1
-5,11,21:18.1
-4,11,21:18.1
-9,12,21:18.1
-8,12,21:18.1
-7,12,21:18.1
-6,12,21:18.1
-5,12,21:18.1
-8,13,21:18.1
-7,13,21:18.1
-6,13,21:18.1
2,-1,22:18.1
3,-1,22:18.1
4,-1,22:18.1
5,-1,22:18.1
1,0,22:18.1
2,0,22:18.1
3,0,22:18.1
4,0,22:18.1
5,0,22:18.1
6,0,22:18.1
0,1,22:18.1
1,1,22:18.1
2,1,22:18.1
3,1,22:18.1
4,1,22:18.1
5,1,22:18.1
6,1,22:18.1
7,1,22:18.1
0,2,22:18.1
1,2,22:18.1
2,2,22:18.1
3,2,22:17.13
4,2,22:17.13
5,2,22:18.1
6,2,22:18.1
7,2,22:18.1
0,3,22:18.1
1,3,22:18.1
2,3,22:17.13
3,3,22:17.13
4,3,22:18.1
5,3,22:18.1
6,3,22:18.1
7,3,22:18.1
0,4,22:17.13
1,4,22:17.13
2,4,22:18.1
3,4,22:18.1
4,4,22:18.1
5,4,22:18.1
6,4,22:18.1
-3,5,22:17.13
-2,5,22:17.13
-1,5,22:17.13
0,5,22:17.13
2,5,22:18.1
3,5,22:18.1
4,5,22:18.1
5,5,22:18.1
-9,6,22:18.1
-8,6,22:18.1
-7,6,22:18.1
-3,6,22:17.13
-2,6,22:17.13
-10,7,22:18.1
-9,7,22:18.1
-8,7,22:18.1
-7,7,22:18.1
-6,7,22:18.1
-11,8,22:18.1
-10,8,22:18.1
-9,8,22:18.1
-8,8,22:18.1
-7,8,22:17.13
-6,8,22:18.1
-5,8,22:18.1
-11,9,22:18.1
-10,9,22:18.1
-9,9,22:18.1
-8,9,22:17.13
-7,9,22:18.1
-6,9,22:18.1
-5,9,22:18.1
-11,10,22:18.1
-10,10,22:18.1
-9,10,22:18.1
-8,10,22:18.1
-7,10,22:18.1
-6,10,22:18.1
-5,10,22:18.1
-4,10,22:18.1
-10,11,22:18.1
-9,11,22:18.1
-8,11,22:18.1
-7,11,22:18.1
-6,11,22:18.1
-5,11,22:18.1
-9,12,22:18.1
-8,12,22:18.1
-7,12,22:18.1
-6,12,22:18.1
-5,12,22:18.1
-7,13,22:18.1
3,-1,23:18.1
4,-1,23:18.1
1,0,23:18.1
2,0,23:18.1
3,0,23:18.1
4,0,23:18.1
5,0,23:18.1
6,0,23:18.1
1,1,23:18.1
2,1,23:18.1
3,1,23:18.1
4,1,23:18.1
5,1,23:18.1
6,1,23:18.1
0,2,23:18.1
1,2,23:18.1
2,2,23:18.1
3,2,23:18.1
4,2,23:18.1
5,2,23:18.1
6,2,23:18.1
7,2,23:18.1
1,3,23:18.1
2,3,23:18.1
3,3,23:18.1
4,3,23:18.1
5,3,23:18.1
6,3,23:18.1
7,3,23:18.1
1,4,23:18.1
2,4,23:18.1
3,4,23:18.1
4,4,23:17.13
5,4,23:18.1
6,4,23:18.1
7,4,23:18.1
-3,5,23:17.13
-2,5,23:17.13
1,5,23:17.13
2,5,23:17.13
3,5,23:17.13
4,5,23:17.13
5,5,23:18.1
6,5,23:18.1
7,5,23:18.1
-8,6,23:18.1
-3,6,23:17.13
-2,6,23:17.13
1,6,23:18.1
2,6,23:18.1
3,6,23:18.1
4,6,23:18.1
5,6,23:18.1
6,6,23:18.1
7,6,23:18.1
-10,7,23:18.1
-9,7,23:18.1
-8,7,23:18.1
-7,7,23:18.1
-6,7,23:18.1
2,7,23:18.1
3,7,23:18.1
4,7,23:18.1
5,7,23:18.1
6,7,23:18.1
-10,8,23:18.1
-9,8,23:18.1
-8,8,23:18.1
-7,8,23:18.1
-6,8,23:18.1
3,8,23:18.1
4,8,23:18.1
5,8,23:18.1
-11,9,23:18.1
-10,9,23:18.1
-9,9,23:18.1
-8,9,23:18.1
-7,9,23:18.1
-6,9,23:18.1
-5,9,23:18.1
-10,10,23:18.1
-9,10,23:18.1
-8,10,23:18.1
-7,10,23:18.1
-6,10,23:18.1
-10,11,23:18.1
-9,11,23:18.1
-8,11,23:18.1
-7,11,23:18.1
-6,11,23:18.1
-8,12,23:18.1
4,1,24:18.1
2,2,24:18.1
3,2,24:18.1
4,2,24:18.1
5,2,24:18.1
6,2,24:18.1
2,3,24:18.1
3,3,24:18.1
4,3,24:18.1
5,3,24:18.1
6,3,24:18.1
1,4,24:18.1
2,4,24:18.1
3,4,24:18.1
4,4,24:18.1
5,4,24:18.1
6,4,24:18.1
7,4,24:18.1
-3,5,24:17.13
-2,5,24:17.13
1,5,24:18.1
2,5,24:18.1
3,5,24:18.1
4,5,24:18.1
5,5,24:18.1
6,5,24:18.1
7,5,24:18.1
-3,6,24:17.13
-2,6,24:17.13
2,6,24:18.1
3,6,24:18.1
4,6,24:18.1
5,6,24:18.1
6,6,24:18.1
2,7,24:18.1
3,7,24:18.1
4,7,24:18.1
5,7,24:18.1
6,7,24:18.1
4,8,24:18.1
-3,5,25:17.13
-2,5,25:17.13
-3,6,25:17.13
-2,6,25:17.13
-3,5,26:17.13
-2,5,26:17.13
-3,6,26:17.13
-2,6,26:17.13
-3,5,27:17.13
-2,5,27:17.13
-3,6,27:17.13
-2,6,27:17.13
-3,5,28:17.13
-2,5,28:17.13
-3,6,28:17.13
-2,6,28:17.13
-5,3,29:18.1
-4,3,29:18.1
-3,3,29:18.1
-6,4,29:18.1
-5,4,29:18.1
-4,4,29:18.1
-3,4,29:18.1
-2,4,29:18.1
-7,5,29:18.1
-6,5,29:18.1
-5,5,29:18.1
-4,5,29:18.1
-3,5,29:17.13
-2,5,29:17.13
-1,5,29:18.1
-7,6,29:18.1
-6,6,29:18.1
-5,6,29:18.1
-4,6,29:17.13
-3,6,29:17.13
-2,6,29:17.13
-1,6,29:18.1
-7,7,29:18.1
-6,7,29:18.1
-5,7,29:18.1
-4,7,29:18.1
-3,7,29:18.1
-2,7,29:18.1
-1,7,29:18.1
-6,8,29:18.1
-5,8,29:18.1
-4,8,29:18.1
-3,8,29:18.1
-2,8,29:18.1
-5,9,29:18.1
-4,9,29:18.1
-3,9,29:18.1
-5,2,30:18.1
-4,2,30:18.1
-3,2,30:18.1
-6,3,30:18.1
-5,3,30:18.1
-4,3,30:18.1
-3,3,30:18.1
-2,3,30:18.1
-7,4,30:18.1
-6,4,30:18.1
-5,4,30:18.1
-4,4,30:18.1
-3,4,30:18.1
-2,4,30:18.1
-1,4,30:18.1
-7,5,30:18.1
-6,5,30:18.1
-5,5,30:18.1
-4,5,30:17.13
-3,5,30:17.13
-2,5,30:17.13
-1,5,30:18.1
-7,6,30:18.1
-6,6,30:18.1
-5,6,30:18.1
-4,6,30:18.1
-3,6,30:17.13
-2,6,30:17.13
-1,6,30:18.1
-6,7,30:18.1
-5,7,30:18.1
-4,7,30:18.1
-3,7,30:18.1
-2,7,30:18.1
-6,8,30:18.1
-5,8,30:18.1
-4,8,30:18.1
-3,8,30:18.1
-2,8,30:18.1
-4,9,30:18.1
-4,2,31:18.1
-3,2,31:18.1
-2,2,31:18.1
-6,3,31:18.1
-5,3,31:18.1
-4,3,31:18.1
-3,3,31:18.1
-2,3,31:18.1
-1,3,31:18.1
-6,4,31:18.1
-5,4,31:18.1
-4,4,31:18.1
-3,4,31:18.1
-2,4,31:18.1
-1,4,31:18.1
0,4,31:18.1
-7,5,31:18.1
-6,5,31:18.1
-5,5,31:18.1
-4,5,31:18.1
-3,5,31:17.13
-2,5,31:17.13
-1,5,31:18.1
0,5,31:18.1
-6,6,31:18.1
-5,6,31:18.1
-4,6,31:18.1
-3,6,31:17.13
-2,6,31:17.13
-1,6,31:18.1
0,6,31:18.1
-6,7,31:18.1
-5,7,31:18.1
-4,7,31:18.1
-3,7,31:18.1
-2,7,31:18.1
-1,7,31:18.1
-4,8,31:18.1
-3,8,31:18.1
-2,8,31:18.1
-3,2,32:18.1
-5,3,32:18.1
-4,3,32:18.1
-3,3,32:18.1
-2,3,32:18.1
-1,3,32:18.1
-5,4,32:18.1
-4,4,32:18.1
-3,4,32:18.1
-2,4,32:18.1
-1,4,32:18.1
-6,5,32:18.1
-5,5,32:18.1
-4,5,32:18.1
-3,5,32:18.1
-2,5,32:18.1
-1,5,32:18.1
0,5,32:18.1
-5,6,32:18.1
-4,6,32:18.1
-3,6,32:18.1
-2,6,32:18.1
-1,6,32:18.1
-5,7,32:18.1
-4,7,32:18.1
-3,7,32:18.1
-2,7,32:18.1
-1,7,32:18.1
-3,8,32:18.1
-3,5,33:18.1
-2,5,33:18.1
-3,6,33:18.1
-2,6,33:18.1
