[META]
version=2.0
spawnOnBlockType=9
spawnSunlight=True
spawnDarkness=True
spawnWater=True
spawnLava=False
underFill=False
randomRotation=True
dig=True
tree=True
branch=False
needsFoundation=True
rarity=50
collisionPercentage=20
spawnElevationMin=0
spawnElevationMax=60
spawnInBiome=Custom
[DATA]
-6,2,-8:17.13
-4,3,-8:17.13
-3,8,-8:17.13
-5,9,-8:17.13
-6,2,-7:17.13
-4,3,-7:17.13
-3,8,-7:17.13
-5,9,-7:17.13
-6,2,-6:17.13
-4,3,-6:17.13
-3,8,-6:17.13
-5,9,-6:17.13
-6,2,-5:17.13
-4,3,-5:17.13
-3,8,-5:17.13
-5,9,-5:17.13
-6,2,-4:17.13
-4,3,-4:17.13
-8,7,-4:17.13
-3,8,-4:17.13
-5,9,-4:17.13
-6,2,-3:17.13
-4,3,-3:17.13
-3,4,-3:17.13
-8,7,-3:17.13
-3,8,-3:17.13
-5,9,-3:17.13
-6,2,-2:17.13
-4,3,-2:17.13
-8,4,-2:17.13
-3,4,-2:17.13
-8,7,-2:17.13
-7,8,-2:17.13
-3,8,-2:17.13
-5,9,-2:17.13
-6,2,-1:17.13
-4,3,-1:17.13
-8,4,-1:17.13
-3,4,-1:17.13
-8,7,-1:17.13
-7,8,-1:17.13
-3,8,-1:17.13
-5,9,-1:17.13
-6,2,0:17.13
-4,3,0:17.13
-8,4,0:17.13
-3,4,0:17.13
-8,7,0:17.13
-7,8,0:17.13
-3,8,0:17.13
-5,9,0:17.13
-6,2,1:17.13
-4,3,1:17.13
-8,4,1:17.13
-3,4,1:17.13
-8,7,1:17.13
-7,8,1:17.13
-5,8,1:17.13
-3,8,1:17.13
-6,2,2:17.13
-4,3,2:17.13
-8,4,2:17.13
-3,4,2:17.13
-8,7,2:17.13
-7,8,2:17.13
-5,8,2:17.13
-3,8,2:17.13
-6,2,3:17.13
-4,3,3:17.13
-8,4,3:17.13
-3,4,3:17.13
-8,7,3:17.13
-7,8,3:17.13
-5,8,3:17.13
-3,8,3:17.13
-6,2,4:17.13
-4,3,4:17.13
-8,4,4:17.13
-3,4,4:17.13
-8,7,4:17.13
-7,8,4:17.13
-5,8,4:17.13
-3,8,4:17.13
-6,2,5:17.13
-4,3,5:17.13
-8,4,5:17.13
-3,4,5:17.13
-8,7,5:17.13
-7,8,5:17.13
-5,8,5:17.13
-3,8,5:17.13
-7,3,6:17.13
-6,3,6:17.13
-5,3,6:17.13
-4,3,6:17.13
-8,4,6:17.13
-7,4,6:17.13
-6,4,6:17.13
-5,4,6:17.13
-4,4,6:17.13
-3,4,6:17.13
-8,5,6:17.13
-7,5,6:17.13
-6,5,6:17.13
-5,5,6:17.13
-4,5,6:17.13
-3,5,6:17.13
-8,6,6:17.13
-7,6,6:17.13
-6,6,6:17.13
-5,6,6:17.13
-4,6,6:17.13
-3,6,6:17.13
-8,7,6:17.13
-7,7,6:17.13
-6,7,6:17.13
-5,7,6:17.13
-4,7,6:17.13
-3,7,6:17.13
-7,8,6:17.13
-6,8,6:17.13
-5,8,6:17.13
-4,8,6:17.13
-3,8,6:17.13
-6,3,7:17.13
-5,3,7:17.13
-4,3,7:17.13
-8,4,7:17.13
-7,4,7:17.13
-6,4,7:17.13
-5,4,7:17.13
-4,4,7:17.13
-3,4,7:17.13
-8,5,7:17.13
-7,5,7:17.13
-6,5,7:17.13
-5,5,7:17.13
-4,5,7:17.13
-3,5,7:17.13
-8,6,7:17.13
-7,6,7:17.13
-6,6,7:17.13
-5,6,7:17.13
-4,6,7:17.13
-3,6,7:17.13
-8,7,7:17.13
-7,7,7:17.13
-6,7,7:17.13
-5,7,7:17.13
-4,7,7:17.13
-3,7,7:17.13
-7,8,7:17.13
-6,8,7:17.13
-5,8,7:17.13
-6,3,8:17.13
-4,3,8:17.13
-8,4,8:17.13
-7,4,8:17.13
-6,4,8:17.13
-5,4,8:17.13
-4,4,8:17.13
-3,4,8:17.13
-7,5,8:17.13
-6,5,8:17.13
-5,5,8:17.13
-4,5,8:17.13
-7,6,8:17.13
-6,6,8:17.13
-5,6,8:17.13
-4,6,8:17.13
-8,7,8:17.13
-7,7,8:17.13
-6,7,8:17.13
-5,7,8:17.13
-4,7,8:17.13
-3,7,8:17.13
-7,8,8:17.13
-5,8,8:17.13
-6,3,9:17.13
-5,3,9:17.13
-8,4,9:17.13
-7,4,9:17.13
-6,4,9:17.13
-5,4,9:17.13
-4,4,9:17.13
-3,4,9:17.13
-7,5,9:17.13
-6,5,9:17.13
-5,5,9:17.13
-4,5,9:17.13
-7,6,9:17.13
-6,6,9:17.13
-5,6,9:17.13
-4,6,9:17.13
-8,7,9:17.13
-7,7,9:17.13
-6,7,9:17.13
-5,7,9:17.13
-4,7,9:17.13
-6,8,9:17.13
-5,8,9:17.13
-6,3,10:17.13
-6,4,10:17.13
-5,4,10:17.13
-4,4,10:17.13
-8,5,10:17.13
-7,5,10:17.13
-6,5,10:17.13
-5,5,10:17.13
-4,5,10:17.13
-7,6,10:17.13
-6,6,10:17.13
-5,6,10:17.13
-4,6,10:17.13
-6,7,10:17.13
-5,7,10:17.13
-4,7,10:17.13
-5,8,10:17.13
-6,4,11:17.13
-5,4,11:17.13
-4,4,11:17.13
-7,5,11:17.13
-6,5,11:17.13
-5,5,11:17.13
-4,5,11:17.13
-7,6,11:17.13
-6,6,11:17.13
-5,6,11:17.13
-4,6,11:17.13
-6,7,11:17.13
-5,7,11:17.13
-4,7,11:17.13
-5,8,11:17.13
-6,4,12:17.13
-5,4,12:17.13
-7,5,12:17.13
-6,5,12:17.13
-5,5,12:17.13
-4,5,12:17.13
-7,6,12:17.13
-6,6,12:17.13
-5,6,12:17.13
-4,6,12:17.13
-6,7,12:17.13
-5,7,12:17.13
-5,8,12:17.13
-6,4,13:17.13
-5,4,13:17.13
-7,5,13:17.13
-6,5,13:17.13
-5,5,13:17.13
-4,5,13:17.13
-7,6,13:17.13
-6,6,13:17.13
-5,6,13:17.13
-4,6,13:17.13
-6,7,13:17.13
-5,7,13:17.13
-6,4,14:17.13
-5,4,14:17.13
-7,5,14:17.13
-6,5,14:17.13
-5,5,14:17.13
-4,5,14:17.13
-7,6,14:17.13
-6,6,14:17.13
-5,6,14:17.13
-4,6,14:17.13
-6,7,14:17.13
-5,7,14:17.13
-6,5,15:17.13
-5,5,15:17.13
-6,6,15:17.13
-5,6,15:17.13
-6,4,16:17.13
-6,5,16:17.13
-5,5,16:17.13
-6,6,16:17.13
-5,6,16:17.13
-8,-9,17:18.1
-7,-9,17:18.1
-6,-9,17:18.1
-9,-8,17:18.1
-8,-8,17:18.1
-7,-8,17:18.1
-6,-8,17:18.1
-5,-8,17:18.1
-10,-7,17:18.1
-9,-7,17:18.1
-8,-7,17:18.1
-7,-7,17:18.1
-6,-7,17:18.1
-5,-7,17:18.1
-4,-7,17:18.1
-2,-7,17:18.1
-1,-7,17:18.1
0,-7,17:18.1
-10,-6,17:18.1
-9,-6,17:18.1
-8,-6,17:18.1
-7,-6,17:17.13
-6,-6,17:18.1
-5,-6,17:18.1
-4,-6,17:18.1
-3,-6,17:18.1
-2,-6,17:18.1
-1,-6,17:18.1
0,-6,17:18.1
1,-6,17:18.1
-10,-5,17:18.1
-9,-5,17:18.1
-8,-5,17:18.1
-7,-5,17:18.1
-6,-5,17:17.13
-5,-5,17:18.1
-4,-5,17:18.1
-3,-5,17:18.1
-2,-5,17:18.1
-1,-5,17:18.1
0,-5,17:18.1
1,-5,17:18.1
2,-5,17:18.1
-9,-4,17:18.1
-8,-4,17:18.1
-7,-4,17:18.1
-6,-4,17:17.13
-5,-4,17:18.1
-4,-4,17:18.1
-3,-4,17:18.1
-2,-4,17:17.13
-1,-4,17:17.13
0,-4,17:18.1
1,-4,17:18.1
2,-4,17:18.1
-8,-3,17:18.1
-7,-3,17:18.1
-6,-3,17:17.13
-4,-3,17:18.1
-3,-3,17:17.13
-2,-3,17:18.1
-1,-3,17:18.1
0,-3,17:18.1
1,-3,17:18.1
2,-3,17:18.1
3,-3,17:18.1
-5,-2,17:17.13
-4,-2,17:17.13
-3,-2,17:18.1
-2,-2,17:18.1
-1,-2,17:18.1
0,-2,17:17.13
1,-2,17:18.1
2,-2,17:18.1
3,-2,17:18.1
-5,-1,17:17.13
-3,-1,17:18.1
-2,-1,17:17.13
-1,-1,17:17.13
0,-1,17:18.1
1,-1,17:18.1
2,-1,17:18.1
3,-1,17:18.1
-5,0,17:17.13
-4,0,17:17.13
-3,0,17:17.13
-2,0,17:18.1
-1,0,17:18.1
0,0,17:18.1
1,0,17:18.1
2,0,17:18.1
-6,1,17:17.13
-5,1,17:17.13
-1,1,17:18.1
0,1,17:18.1
1,1,17:18.1
-6,2,17:17.13
-6,3,17:17.13
-6,5,17:17.13
-5,5,17:17.13
-6,6,17:17.13
-5,6,17:17.13
-7,-9,18:18.1
-9,-8,18:18.1
-8,-8,18:18.1
-7,-8,18:18.1
-6,-8,18:18.1
-5,-8,18:18.1
-9,-7,18:18.1
-8,-7,18:18.1
-7,-7,18:18.1
-6,-7,18:18.1
-5,-7,18:18.1
-1,-7,18:18.1
-10,-6,18:18.1
-9,-6,18:18.1
-8,-6,18:18.1
-7,-6,18:18.1
-6,-6,18:18.1
-5,-6,18:18.1
-4,-6,18:18.1
-3,-6,18:18.1
-2,-6,18:18.1
-1,-6,18:18.1
0,-6,18:18.1
1,-6,18:18.1
-9,-5,18:18.1
-8,-5,18:18.1
-7,-5,18:18.1
-6,-5,18:18.1
-5,-5,18:18.1
-3,-5,18:18.1
-2,-5,18:18.1
-1,-5,18:18.1
0,-5,18:18.1
1,-5,18:18.1
-9,-4,18:18.1
-8,-4,18:18.1
-7,-4,18:18.1
-6,-4,18:18.1
-5,-4,18:18.1
-4,-4,18:18.1
-3,-4,18:18.1
-2,-4,18:18.1
-1,-4,18:18.1
0,-4,18:18.1
1,-4,18:18.1
2,-4,18:18.1
-7,-3,18:18.1
-3,-3,18:18.1
-2,-3,18:18.1
-1,-3,18:18.1
0,-3,18:18.1
1,-3,18:18.1
2,-3,18:18.1
-3,-2,18:18.1
-2,-2,18:18.1
-1,-2,18:18.1
0,-2,18:18.1
1,-2,18:18.1
2,-2,18:18.1
3,-2,18:18.1
-2,-1,18:18.1
-1,-1,18:18.1
0,-1,18:18.1
1,-1,18:18.1
2,-1,18:18.1
-2,0,18:18.1
-1,0,18:18.1
0,0,18:18.1
1,0,18:18.1
2,0,18:18.1
0,1,18:18.1
-6,5,18:17.13
-5,5,18:17.13
-6,6,18:17.13
-5,6,18:17.13
-6,5,19:17.13
-5,5,19:17.13
-6,6,19:17.13
-5,6,19:17.13
-6,5,20:17.13
-5,5,20:17.13
-6,6,20:17.13
-5,6,20:17.13
-6,7,20:17.13
-6,8,20:17.13
-5,9,20:17.13
-4,9,20:17.13
-1,9,20:18.1
0,9,20:18.1
1,9,20:18.1
-3,10,20:17.13
-2,10,20:17.13
-1,10,20:18.1
0,10,20:18.1
1,10,20:18.1
2,10,20:18.1
-3,11,20:18.1
-2,11,20:17.13
-1,11,20:18.1
0,11,20:18.1
1,11,20:18.1
2,11,20:18.1
3,11,20:18.1
-3,12,20:18.1
-2,12,20:18.1
-1,12,20:17.13
0,12,20:17.13
1,12,20:18.1
2,12,20:18.1
3,12,20:18.1
-3,13,20:18.1
-2,13,20:18.1
-1,13,20:18.1
0,13,20:18.1
1,13,20:18.1
2,13,20:18.1
3,13,20:18.1
-2,14,20:18.1
-1,14,20:18.1
0,14,20:18.1
1,14,20:18.1
2,14,20:18.1
-1,15,20:18.1
0,15,20:18.1
1,15,20:18.1
-6,5,21:17.13
-5,5,21:17.13
-6,6,21:17.13
-5,6,21:17.13
-6,9,21:17.13
0,9,21:18.1
-7,10,21:17.13
-6,10,21:17.13
-2,10,21:18.1
-1,10,21:18.1
0,10,21:18.1
1,10,21:18.1
2,10,21:18.1
-11,11,21:18.1
-10,11,21:18.1
-9,11,21:18.1
-7,11,21:17.13
-6,11,21:17.13
-2,11,21:18.1
-1,11,21:18.1
0,11,21:18.1
1,11,21:18.1
2,11,21:18.1
-12,12,21:18.1
-11,12,21:18.1
-10,12,21:18.1
-9,12,21:18.1
-8,12,21:17.13
-7,12,21:17.13
-3,12,21:18.1
-2,12,21:18.1
-1,12,21:18.1
0,12,21:18.1
1,12,21:18.1
2,12,21:18.1
3,12,21:18.1
-13,13,21:18.1
-12,13,21:18.1
-11,13,21:18.1
-10,13,21:18.1
-9,13,21:17.13
-8,13,21:17.13
-7,13,21:17.13
-6,13,21:18.1
-2,13,21:18.1
-1,13,21:18.1
0,13,21:18.1
1,13,21:18.1
2,13,21:18.1
-13,14,21:18.1
-12,14,21:18.1
-11,14,21:18.1
-10,14,21:17.13
-9,14,21:18.1
-8,14,21:17.13
-7,14,21:18.1
-6,14,21:18.1
-5,14,21:18.1
-2,14,21:18.1
-1,14,21:18.1
0,14,21:18.1
1,14,21:18.1
2,14,21:18.1
-13,15,21:18.1
-12,15,21:18.1
-11,15,21:18.1
-10,15,21:18.1
-9,15,21:18.1
-8,15,21:17.13
-7,15,21:18.1
-6,15,21:18.1
-5,15,21:18.1
0,15,21:18.1
-12,16,21:18.1
-11,16,21:18.1
-10,16,21:18.1
-9,16,21:18.1
-8,16,21:18.1
-7,16,21:18.1
-6,16,21:18.1
-5,16,21:18.1
-11,17,21:18.1
-10,17,21:18.1
-9,17,21:18.1
-8,17,21:18.1
-7,17,21:18.1
-6,17,21:18.1
-9,18,21:18.1
-8,18,21:18.1
-7,18,21:18.1
-6,5,22:17.13
-5,5,22:17.13
-6,6,22:17.13
-5,6,22:17.13
-10,11,22:18.1
-12,12,22:18.1
-11,12,22:18.1
-10,12,22:18.1
-9,12,22:18.1
-8,12,22:18.1
-6,12,22:18.1
-5,12,22:17.13
-4,12,22:18.1
-12,13,22:18.1
-11,13,22:18.1
-10,13,22:18.1
-9,13,22:18.1
-8,13,22:18.1
-7,13,22:18.1
-6,13,22:18.1
-5,13,22:17.13
-4,13,22:18.1
-3,13,22:18.1
-13,14,22:18.1
-12,14,22:18.1
-11,14,22:18.1
-10,14,22:18.1
-9,14,22:18.1
-8,14,22:18.1
-7,14,22:18.1
-6,14,22:18.1
-5,14,22:17.13
-4,14,22:18.1
-3,14,22:18.1
-2,14,22:18.1
-12,15,22:18.1
-11,15,22:18.1
-10,15,22:18.1
-9,15,22:18.1
-8,15,22:18.1
-7,15,22:18.1
-6,15,22:18.1
-5,15,22:17.13
-4,15,22:18.1
-3,15,22:18.1
-2,15,22:18.1
-12,16,22:18.1
-11,16,22:18.1
-10,16,22:18.1
-9,16,22:18.1
-8,16,22:18.1
-7,16,22:18.1
-6,16,22:18.1
-5,16,22:18.1
-4,16,22:18.1
-3,16,22:18.1
-2,16,22:18.1
-10,17,22:18.1
-9,17,22:18.1
-8,17,22:18.1
-7,17,22:18.1
-6,17,22:18.1
-5,17,22:18.1
-4,17,22:18.1
-3,17,22:18.1
-8,18,22:18.1
-6,18,22:18.1
-5,18,22:18.1
-4,18,22:18.1
-6,5,23:17.13
-5,5,23:17.13
-6,6,23:17.13
-5,6,23:17.13
-5,12,23:18.1
-7,13,23:18.1
-6,13,23:18.1
-5,13,23:18.1
-4,13,23:18.1
-3,13,23:18.1
-7,14,23:18.1
-6,14,23:18.1
-5,14,23:18.1
-4,14,23:18.1
-3,14,23:18.1
-8,15,23:18.1
-7,15,23:18.1
-6,15,23:18.1
-5,15,23:18.1
-4,15,23:18.1
-3,15,23:18.1
-2,15,23:18.1
-7,16,23:18.1
-6,16,23:18.1
-5,16,23:18.1
-4,16,23:18.1
-3,16,23:18.1
-7,17,23:18.1
-6,17,23:18.1
-5,17,23:18.1
-4,17,23:18.1
-3,17,23:18.1
-5,18,23:18.1
-6,5,24:17.13
-5,5,24:17.13
-6,6,24:17.13
-5,6,24:17.13
-6,5,25:17.13
-5,5,25:17.13
-6,6,25:17.13
-5,6,25:17.13
-6,5,26:17.13
-5,5,26:17.13
-6,6,26:17.13
-5,6,26:17.13
-10,-1,27:18.1
-9,-1,27:18.1
-8,-1,27:18.1
-11,0,27:18.1
-10,0,27:18.1
-9,0,27:18.1
-8,0,27:18.1
-7,0,27:18.1
-12,1,27:18.1
-11,1,27:18.1
-10,1,27:18.1
-9,1,27:18.1
-8,1,27:18.1
-7,1,27:18.1
-6,1,27:18.1
-12,2,27:18.1
-11,2,27:18.1
-10,2,27:18.1
-9,2,27:17.13
-8,2,27:18.1
-7,2,27:18.1
-6,2,27:18.1
-12,3,27:18.1
-11,3,27:18.1
-10,3,27:18.1
-9,3,27:18.1
-8,3,27:17.13
-7,3,27:18.1
-6,3,27:18.1
-12,4,27:18.1
-11,4,27:18.1
-10,4,27:18.1
-9,4,27:18.1
-8,4,27:17.13
-7,4,27:18.1
-13,5,27:18.1
-12,5,27:18.1
-11,5,27:18.1
-10,5,27:18.1
-9,5,27:18.1
-8,5,27:18.1
-7,5,27:17.13
-6,5,27:17.13
-5,5,27:17.13
-14,6,27:18.1
-13,6,27:18.1
-12,6,27:18.1
-11,6,27:18.1
-10,6,27:18.1
-9,6,27:17.13
-8,6,27:17.13
-7,6,27:17.13
-6,6,27:17.13
-5,6,27:17.13
-14,7,27:18.1
-13,7,27:18.1
-12,7,27:18.1
-11,7,27:17.13
-10,7,27:17.13
-9,7,27:18.1
-8,7,27:18.1
-14,8,27:18.1
-13,8,27:18.1
-12,8,27:18.1
-11,8,27:18.1
-10,8,27:18.1
-9,8,27:18.1
-8,8,27:18.1
-13,9,27:18.1
-12,9,27:18.1
-11,9,27:18.1
-10,9,27:18.1
-9,9,27:18.1
-12,10,27:18.1
-11,10,27:18.1
-10,10,27:18.1
-9,-1,28:18.1
-11,0,28:18.1
-10,0,28:18.1
-9,0,28:18.1
-8,0,28:18.1
-7,0,28:18.1
-11,1,28:18.1
-10,1,28:18.1
-9,1,28:18.1
-8,1,28:18.1
-7,1,28:18.1
-12,2,28:18.1
-11,2,28:18.1
-10,2,28:18.1
-9,2,28:18.1
-8,2,28:18.1
-7,2,28:18.1
-6,2,28:18.1
-13,3,28:18.1
-12,3,28:18.1
-11,3,28:18.1
-10,3,28:18.1
-9,3,28:17.13
-8,3,28:18.1
-7,3,28:18.1
-6,3,28:18.1
-13,4,28:18.1
-12,4,28:18.1
-11,4,28:18.1
-10,4,28:17.13
-9,4,28:17.13
-8,4,28:18.1
-7,4,28:18.1
-6,4,28:18.1
-4,4,28:18.1
-3,4,28:18.1
-2,4,28:18.1
-13,5,28:18.1
-12,5,28:18.1
-11,5,28:18.1
-10,5,28:17.13
-9,5,28:17.13
-8,5,28:18.1
-7,5,28:18.1
-6,5,28:17.13
-5,5,28:17.13
-4,5,28:18.1
-3,5,28:18.1
-2,5,28:18.1
-1,5,28:18.1
-13,6,28:18.1
-12,6,28:18.1
-11,6,28:18.1
-10,6,28:18.1
-9,6,28:18.1
-8,6,28:18.1
-6,6,28:17.13
-5,6,28:17.13
-4,6,28:18.1
-3,6,28:18.1
-2,6,28:18.1
-1,6,28:18.1
0,6,28:18.1
-14,7,28:18.1
-13,7,28:18.1
-12,7,28:18.1
-11,7,28:18.1
-10,7,28:18.1
-9,7,28:18.1
-8,7,28:18.1
-6,7,28:17.13
-5,7,28:17.13
-4,7,28:17.13
-3,7,28:17.13
-2,7,28:18.1
-1,7,28:18.1
0,7,28:18.1
-13,8,28:18.1
-12,8,28:18.1
-11,8,28:18.1
-10,8,28:18.1
-9,8,28:18.1
-6,8,28:18.1
-5,8,28:18.1
-4,8,28:18.1
-3,8,28:18.1
-2,8,28:18.1
-1,8,28:18.1
0,8,28:18.1
-13,9,28:18.1
-12,9,28:18.1
-11,9,28:18.1
-10,9,28:18.1
-9,9,28:18.1
-5,9,28:18.1
-4,9,28:18.1
-3,9,28:18.1
-2,9,28:18.1
-1,9,28:18.1
-11,10,28:18.1
-4,10,28:18.1
-3,10,28:18.1
-2,10,28:18.1
-9,0,29:18.1
-11,1,29:18.1
-10,1,29:18.1
-9,1,29:18.1
-8,1,29:18.1
-7,1,29:18.1
-12,2,29:18.1
-11,2,29:18.1
-10,2,29:18.1
-9,2,29:18.1
-8,2,29:18.1
-7,2,29:18.1
-12,3,29:18.1
-11,3,29:18.1
-10,3,29:18.1
-9,3,29:18.1
-8,3,29:18.1
-7,3,29:18.1
-6,3,29:18.1
-13,4,29:18.1
-12,4,29:18.1
-11,4,29:18.1
-10,4,29:18.1
-9,4,29:18.1
-8,4,29:18.1
-7,4,29:18.1
-3,4,29:18.1
-12,5,29:18.1
-11,5,29:18.1
-10,5,29:18.1
-9,5,29:18.1
-8,5,29:18.1
-7,5,29:18.1
-6,5,29:17.13
-5,5,29:17.13
-4,5,29:18.1
-3,5,29:18.1
-2,5,29:18.1
-1,5,29:18.1
-12,6,29:18.1
-11,6,29:18.1
-10,6,29:18.1
-9,6,29:18.1
-8,6,29:18.1
-6,6,29:17.13
-5,6,29:17.13
-4,6,29:18.1
-3,6,29:18.1
-2,6,29:18.1
-1,6,29:18.1
-10,7,29:18.1
-6,7,29:18.1
-5,7,29:17.13
-4,7,29:18.1
-3,7,29:18.1
-2,7,29:18.1
-1,7,29:18.1
0,7,29:18.1
-5,8,29:17.13
-4,8,29:18.1
-3,8,29:18.1
-2,8,29:18.1
-1,8,29:18.1
-5,9,29:18.1
-4,9,29:18.1
-3,9,29:18.1
-2,9,29:18.1
-1,9,29:18.1
-3,10,29:18.1
-6,0,30:18.1
-5,0,30:18.1
-4,0,30:18.1
-7,1,30:18.1
-6,1,30:18.1
-5,1,30:18.1
-4,1,30:18.1
-3,1,30:18.1
-8,2,30:18.1
-7,2,30:18.1
-6,2,30:18.1
-5,2,30:18.1
-4,2,30:18.1
-3,2,30:18.1
-2,2,30:18.1
-8,3,30:18.1
-7,3,30:18.1
-6,3,30:18.1
-5,3,30:17.13
-4,3,30:18.1
-3,3,30:18.1
-2,3,30:18.1
-8,4,30:18.1
-7,4,30:18.1
-6,4,30:17.13
-5,4,30:17.13
-4,4,30:18.1
-3,4,30:18.1
-2,4,30:18.1
-7,5,30:18.1
-6,5,30:17.13
-5,5,30:17.13
-4,5,30:18.1
-3,5,30:18.1
-7,6,30:17.13
-6,6,30:17.13
-5,6,30:17.13
-4,6,30:18.1
-3,6,30:18.1
-6,7,30:18.1
-5,7,30:18.1
-4,7,30:18.1
-3,7,30:18.1
-2,7,30:18.1
-7,8,30:18.1
-6,8,30:18.1
-5,8,30:18.1
-4,8,30:18.1
-3,8,30:18.1
-2,8,30:18.1
-1,8,30:18.1
-7,9,30:18.1
-6,9,30:18.1
-5,9,30:18.1
-4,9,30:17.13
-3,9,30:18.1
-2,9,30:18.1
-1,9,30:18.1
-7,10,30:18.1
-6,10,30:18.1
-5,10,30:18.1
-4,10,30:18.1
-3,10,30:18.1
-2,10,30:18.1
-1,10,30:18.1
-6,11,30:18.1
-5,11,30:18.1
-4,11,30:18.1
-3,11,30:18.1
-2,11,30:18.1
-5,12,30:18.1
-4,12,30:18.1
-3,12,30:18.1
-6,0,31:18.1
-5,0,31:18.1
-4,0,31:18.1
-7,1,31:18.1
-6,1,31:18.1
-5,1,31:18.1
-4,1,31:18.1
-3,1,31:18.1
-8,2,31:18.1
-7,2,31:18.1
-6,2,31:18.1
-5,2,31:18.1
-4,2,31:18.1
-3,2,31:18.1
-2,2,31:18.1
-8,3,31:18.1
-7,3,31:18.1
-6,3,31:18.1
-5,3,31:17.13
-4,3,31:18.1
-3,3,31:18.1
-2,3,31:18.1
-9,4,31:18.1
-8,4,31:18.1
-7,4,31:18.1
-6,4,31:18.1
-5,4,31:18.1
-4,4,31:18.1
-3,4,31:18.1
-2,4,31:18.1
-10,5,31:18.1
-9,5,31:18.1
-8,5,31:18.1
-7,5,31:18.1
-6,5,31:17.13
-5,5,31:17.13
-4,5,31:18.1
-3,5,31:18.1
-11,6,31:18.1
-10,6,31:18.1
-9,6,31:18.1
-8,6,31:18.1
-7,6,31:18.1
-6,6,31:17.13
-5,6,31:17.13
-4,6,31:18.1
-11,7,31:18.1
-10,7,31:18.1
-9,7,31:18.1
-8,7,31:17.13
-7,7,31:17.13
-6,7,31:18.1
-5,7,31:18.1
-4,7,31:18.1
-3,7,31:18.1
-2,7,31:18.1
-11,8,31:18.1
-10,8,31:18.1
-9,8,31:18.1
-8,8,31:18.1
-7,8,31:18.1
-6,8,31:18.1
-5,8,31:18.1
-4,8,31:18.1
-3,8,31:18.1
-2,8,31:18.1
-10,9,31:18.1
-9,9,31:18.1
-8,9,31:18.1
-7,9,31:18.1
-6,9,31:18.1
-5,9,31:18.1
-4,9,31:18.1
-3,9,31:18.1
-2,9,31:18.1
-1,9,31:18.1
-9,10,31:18.1
-8,10,31:18.1
-7,10,31:18.1
-6,10,31:18.1
-5,10,31:18.1
-4,10,31:18.1
-3,10,31:18.1
-2,10,31:18.1
-6,11,31:18.1
-5,11,31:18.1
-4,11,31:18.1
-3,11,31:18.1
-2,11,31:18.1
-4,12,31:18.1
-5,0,32:18.1
-7,1,32:18.1
-6,1,32:18.1
-5,1,32:18.1
-4,1,32:18.1
-3,1,32:18.1
-7,2,32:18.1
-6,2,32:18.1
-5,2,32:18.1
-4,2,32:18.1
-3,2,32:18.1
-8,3,32:18.1
-7,3,32:18.1
-6,3,32:18.1
-5,3,32:18.1
-4,3,32:18.1
-3,3,32:18.1
-2,3,32:18.1
-8,4,32:18.1
-7,4,32:18.1
-6,4,32:18.1
-5,4,32:18.1
-4,4,32:18.1
-3,4,32:18.1
-10,5,32:18.1
-9,5,32:18.1
-8,5,32:18.1
-7,5,32:18.1
-6,5,32:17.13
-5,5,32:17.13
-4,5,32:18.1
-3,5,32:18.1
-10,6,32:18.1
-9,6,32:18.1
-8,6,32:18.1
-7,6,32:18.1
-6,6,32:17.13
-5,6,32:17.13
-4,6,32:18.1
-11,7,32:18.1
-10,7,32:18.1
-9,7,32:18.1
-8,7,32:18.1
-7,7,32:17.13
-6,7,32:18.1
-5,7,32:18.1
-4,7,32:18.1
-10,8,32:18.1
-9,8,32:18.1
-8,8,32:18.1
-7,8,32:18.1
-6,8,32:18.1
-5,8,32:18.1
-4,8,32:18.1
-10,9,32:18.1
-9,9,32:18.1
-8,9,32:18.1
-7,9,32:18.1
-6,9,32:18.1
-5,9,32:18.1
-8,10,32:18.1
-7,10,32:18.1
-6,10,32:18.1
-7,4,33:18.1
-6,4,33:18.1
-5,4,33:18.1
-9,5,33:18.1
-8,5,33:18.1
-7,5,33:18.1
-6,5,33:17.13
-5,5,33:17.13
-4,5,33:18.1
-9,6,33:18.1
-8,6,33:18.1
-7,6,33:18.1
-6,6,33:17.13
-5,6,33:17.13
-4,6,33:18.1
-3,6,33:18.1
-10,7,33:18.1
-9,7,33:18.1
-8,7,33:18.1
-7,7,33:18.1
-6,7,33:17.13
-5,7,33:18.1
-4,7,33:18.1
-3,7,33:18.1
-9,8,33:18.1
-8,8,33:18.1
-7,8,33:18.1
-6,8,33:18.1
-5,8,33:18.1
-4,8,33:18.1
-3,8,33:18.1
-9,9,33:18.1
-8,9,33:18.1
-7,9,33:18.1
-6,9,33:18.1
-5,9,33:18.1
-4,9,33:18.1
-7,10,33:18.1
-6,10,33:18.1
-5,10,33:18.1
-6,2,34:18.1
-5,2,34:18.1
-4,2,34:18.1
-7,3,34:18.1
-6,3,34:18.1
-5,3,34:18.1
-4,3,34:18.1
-3,3,34:18.1
-8,4,34:18.1
-7,4,34:18.1
-6,4,34:18.1
-5,4,34:18.1
-4,4,34:18.1
-3,4,34:18.1
-2,4,34:18.1
-8,5,34:18.1
-7,5,34:18.1
-6,5,34:17.13
-5,5,34:17.13
-4,5,34:18.1
-3,5,34:18.1
-2,5,34:18.1
-8,6,34:18.1
-7,6,34:18.1
-6,6,34:17.13
-5,6,34:17.13
-4,6,34:18.1
-3,6,34:18.1
-2,6,34:18.1
-9,7,34:18.1
-8,7,34:18.1
-7,7,34:18.1
-6,7,34:18.1
-5,7,34:18.1
-4,7,34:18.1
-3,7,34:18.1
-8,8,34:18.1
-7,8,34:18.1
-6,8,34:18.1
-5,8,34:18.1
-4,8,34:18.1
-8,9,34:18.1
-7,9,34:18.1
-6,9,34:18.1
-5,9,34:18.1
-4,9,34:18.1
-6,10,34:18.1
-5,2,35:18.1
-7,3,35:18.1
-6,3,35:18.1
-5,3,35:18.1
-4,3,35:18.1
-3,3,35:18.1
-7,4,35:18.1
-6,4,35:18.1
-5,4,35:18.1
-4,4,35:18.1
-3,4,35:18.1
-8,5,35:18.1
-7,5,35:18.1
-6,5,35:18.1
-5,5,35:18.1
-4,5,35:18.1
-3,5,35:18.1
-2,5,35:18.1
-7,6,35:18.1
-6,6,35:18.1
-5,6,35:18.1
-4,6,35:18.1
-3,6,35:18.1
-7,7,35:18.1
-6,7,35:18.1
-5,7,35:18.1
-4,7,35:18.1
-3,7,35:18.1
-5,8,35:18.1
-6,5,36:18.1
-5,5,36:18.1
-6,6,36:18.1
-5,6,36:18.1
