[META]
version=2.0
spawnOnBlockType=9
spawnSunlight=True
spawnDarkness=True
spawnWater=True
spawnLava=False
underFill=False
randomRotation=True
dig=True
tree=True
branch=False
needsFoundation=True
rarity=50
collisionPercentage=20
spawnElevationMin=0
spawnElevationMax=60
spawnInBiome=Custom
[DATA]
-5,-2,-8:17.13
-2,0,-8:17.13
-8,1,-8:17.13
-8,2,-8:17.13
-2,4,-8:17.13
-5,-2,-7:17.13
-2,0,-7:17.13
-8,1,-7:17.13
-8,2,-7:17.13
-2,4,-7:17.13
-5,-2,-6:17.13
-2,0,-6:17.13
-8,1,-6:17.13
-8,2,-6:17.13
-2,4,-6:17.13
-5,-2,-5:17.13
-2,0,-5:17.13
-8,1,-5:17.13
-8,2,-5:17.13
-2,4,-5:17.13
-5,-2,-4:17.13
-2,0,-4:17.13
-8,1,-4:17.13
-8,2,-4:17.13
-3,4,-4:17.13
-2,4,-4:17.13
-5,-2,-3:17.13
-3,-1,-3:17.13
-2,0,-3:17.13
-8,1,-3:17.13
-8,2,-3:17.13
-3,4,-3:17.13
-2,4,-3:17.13
-5,5,-3:17.13
-5,-2,-2:17.13
-3,-1,-2:17.13
-2,0,-2:17.13
-8,1,-2:17.13
-8,2,-2:17.13
-3,4,-2:17.13
-2,4,-2:17.13
-5,5,-2:17.13
-5,-2,-1:17.13
-3,-1,-1:17.13
-2,0,-1:17.13
-8,1,-1:17.13
-8,2,-1:17.13
-3,4,-1:17.13
-2,4,-1:17.13
-5,5,-1:17.13
-5,-2,0:17.13
-3,-1,0:17.13
-2,0,0:17.13
-8,1,0:17.13
-8,2,0:17.13
-3,4,0:17.13
-2,4,0:17.13
-5,5,0:17.13
-5,-2,1:17.13
-3,-1,1:17.13
-2,0,1:17.13
-8,1,1:17.13
-8,2,1:17.13
-3,4,1:17.13
-2,4,1:17.13
-5,5,1:17.13
-5,-2,2:17.13
-3,-1,2:17.13
-2,0,2:17.13
-8,1,2:17.13
-8,2,2:17.13
-5,4,2:17.13
-3,4,2:17.13
-2,4,2:17.13
-5,-2,3:17.13
-3,-1,3:17.13
-2,0,3:17.13
-8,1,3:17.13
-8,2,3:17.13
-5,4,3:17.13
-3,4,3:17.13
-2,4,3:17.13
-5,-2,4:17.13
-3,-1,4:17.13
-2,0,4:17.13
-8,1,4:17.13
-7,2,4:17.13
-5,4,4:17.13
-3,4,4:17.13
-2,4,4:17.13
-6,-1,5:17.13
-5,-1,5:17.13
-4,-1,5:17.13
-3,-1,5:17.13
-7,0,5:17.13
-6,0,5:17.13
-5,0,5:17.13
-4,0,5:17.13
-3,0,5:17.13
-2,0,5:17.13
-8,1,5:17.13
-7,1,5:17.13
-6,1,5:17.13
-5,1,5:17.13
-4,1,5:17.13
-3,1,5:17.13
-2,1,5:17.13
-7,2,5:17.13
-6,2,5:17.13
-5,2,5:17.13
-4,2,5:17.13
-3,2,5:17.13
-2,2,5:17.13
-7,3,5:17.13
-6,3,5:17.13
-5,3,5:17.13
-4,3,5:17.13
-3,3,5:17.13
-2,3,5:17.13
-6,4,5:17.13
-5,4,5:17.13
-4,4,5:17.13
-3,4,5:17.13
-5,-1,6:17.13
-4,-1,6:17.13
-3,-1,6:17.13
-6,0,6:17.13
-5,0,6:17.13
-4,0,6:17.13
-3,0,6:17.13
-2,0,6:17.13
-7,1,6:17.13
-6,1,6:17.13
-5,1,6:17.13
-4,1,6:17.13
-3,1,6:17.13
-2,1,6:17.13
-7,2,6:17.13
-6,2,6:17.13
-5,2,6:17.13
-4,2,6:17.13
-3,2,6:17.13
-2,2,6:17.13
-6,3,6:17.13
-5,3,6:17.13
-4,3,6:17.13
-3,3,6:17.13
-5,4,6:17.13
-4,4,6:17.13
-3,4,6:17.13
-5,-1,7:17.13
-3,-1,7:17.13
-6,0,7:17.13
-5,0,7:17.13
-4,0,7:17.13
-3,0,7:17.13
-2,0,7:17.13
-7,1,7:17.13
-6,1,7:17.13
-5,1,7:17.13
-4,1,7:17.13
-3,1,7:17.13
-7,2,7:17.13
-6,2,7:17.13
-5,2,7:17.13
-4,2,7:17.13
-3,2,7:17.13
-6,3,7:17.13
-5,3,7:17.13
-4,3,7:17.13
-3,3,7:17.13
-5,4,7:17.13
-3,4,7:17.13
-5,-1,8:17.13
-3,-1,8:17.13
-6,0,8:17.13
-5,0,8:17.13
-4,0,8:17.13
-3,0,8:17.13
-2,0,8:17.13
-7,1,8:17.13
-6,1,8:17.13
-5,1,8:17.13
-4,1,8:17.13
-3,1,8:17.13
-7,2,8:17.13
-6,2,8:17.13
-5,2,8:17.13
-4,2,8:17.13
-3,2,8:17.13
-6,3,8:17.13
-5,3,8:17.13
-4,3,8:17.13
-3,3,8:17.13
-5,4,8:17.13
-3,4,8:17.13
-5,-1,9:17.13
-5,0,9:17.13
-4,0,9:17.13
-3,0,9:17.13
-7,1,9:17.13
-6,1,9:17.13
-5,1,9:17.13
-4,1,9:17.13
-3,1,9:17.13
-7,2,9:17.13
-6,2,9:17.13
-5,2,9:17.13
-4,2,9:17.13
-3,2,9:17.13
-5,3,9:17.13
-4,3,9:17.13
-3,3,9:17.13
-5,4,9:17.13
-5,0,10:17.13
-4,0,10:17.13
-3,0,10:17.13
-6,1,10:17.13
-5,1,10:17.13
-4,1,10:17.13
-3,1,10:17.13
-6,2,10:17.13
-5,2,10:17.13
-4,2,10:17.13
-3,2,10:17.13
-5,3,10:17.13
-4,3,10:17.13
-3,3,10:17.13
-5,0,11:17.13
-4,0,11:17.13
-6,1,11:17.13
-5,1,11:17.13
-4,1,11:17.13
-3,1,11:17.13
-6,2,11:17.13
-5,2,11:17.13
-4,2,11:17.13
-3,2,11:17.13
-5,3,11:17.13
-4,3,11:17.13
-5,0,12:17.13
-4,0,12:17.13
-6,1,12:17.13
-5,1,12:17.13
-4,1,12:17.13
-3,1,12:17.13
-6,2,12:17.13
-5,2,12:17.13
-4,2,12:17.13
-3,2,12:17.13
-5,3,12:17.13
-4,3,12:17.13
-5,0,13:17.13
-4,0,13:17.13
-6,1,13:17.13
-5,1,13:17.13
-4,1,13:17.13
-3,1,13:17.13
-2,1,13:17.13
-6,2,13:17.13
-5,2,13:17.13
-4,2,13:17.13
-3,2,13:17.13
-1,2,13:17.13
-5,3,13:17.13
-4,3,13:17.13
-5,1,14:17.13
-4,1,14:17.13
-5,2,14:17.13
-4,2,14:17.13
-1,2,14:17.13
0,2,14:17.13
1,2,14:17.13
2,3,14:17.13
-4,0,15:17.13
-5,1,15:17.13
-4,1,15:17.13
-5,2,15:17.13
-4,2,15:17.13
7,2,15:18.1
8,2,15:18.1
9,2,15:18.1
-5,3,15:17.13
3,3,15:17.13
4,3,15:17.13
6,3,15:18.1
7,3,15:18.1
8,3,15:18.1
9,3,15:18.1
10,3,15:18.1
-5,4,15:17.13
5,4,15:17.13
6,4,15:17.13
7,4,15:17.13
8,4,15:18.1
9,4,15:18.1
10,4,15:18.1
11,4,15:18.1
4,5,15:18.1
5,5,15:17.13
6,5,15:18.1
7,5,15:18.1
8,5,15:17.13
9,5,15:18.1
10,5,15:18.1
11,5,15:18.1
3,6,15:18.1
4,6,15:18.1
5,6,15:18.1
6,6,15:17.13
7,6,15:18.1
8,6,15:18.1
9,6,15:18.1
10,6,15:18.1
11,6,15:18.1
3,7,15:18.1
4,7,15:18.1
5,7,15:18.1
6,7,15:17.13
7,7,15:18.1
8,7,15:18.1
9,7,15:18.1
10,7,15:18.1
3,8,15:18.1
4,8,15:18.1
5,8,15:18.1
6,8,15:18.1
7,8,15:18.1
8,8,15:18.1
9,8,15:18.1
4,9,15:18.1
5,9,15:18.1
6,9,15:18.1
7,9,15:18.1
8,9,15:18.1
5,10,15:18.1
6,10,15:18.1
7,10,15:18.1
4,-7,16:18.1
5,-7,16:18.1
6,-7,16:18.1
3,-6,16:18.1
4,-6,16:18.1
5,-6,16:18.1
6,-6,16:18.1
7,-6,16:18.1
2,-5,16:18.1
3,-5,16:18.1
4,-5,16:18.1
5,-5,16:18.1
6,-5,16:18.1
7,-5,16:18.1
8,-5,16:18.1
2,-4,16:18.1
3,-4,16:18.1
4,-4,16:18.1
5,-4,16:17.13
6,-4,16:18.1
7,-4,16:18.1
8,-4,16:18.1
2,-3,16:18.1
3,-3,16:18.1
4,-3,16:18.1
5,-3,16:18.1
6,-3,16:18.1
7,-3,16:18.1
8,-3,16:18.1
-3,-2,16:17.13
3,-2,16:18.1
4,-2,16:18.1
5,-2,16:18.1
6,-2,16:18.1
7,-2,16:18.1
-3,-1,16:17.13
4,-1,16:18.1
5,-1,16:18.1
6,-1,16:18.1
-4,0,16:17.13
-5,1,16:17.13
-4,1,16:17.13
-5,2,16:17.13
-4,2,16:17.13
8,2,16:18.1
6,3,16:18.1
7,3,16:18.1
8,3,16:18.1
9,3,16:18.1
10,3,16:18.1
-5,4,16:17.13
6,4,16:18.1
7,4,16:18.1
8,4,16:18.1
9,4,16:18.1
10,4,16:18.1
-6,5,16:17.13
4,5,16:18.1
5,5,16:18.1
6,5,16:18.1
7,5,16:18.1
8,5,16:18.1
9,5,16:18.1
10,5,16:18.1
11,5,16:18.1
-6,6,16:17.13
4,6,16:18.1
5,6,16:18.1
6,6,16:18.1
7,6,16:18.1
8,6,16:18.1
9,6,16:18.1
10,6,16:18.1
3,7,16:18.1
4,7,16:18.1
5,7,16:18.1
6,7,16:18.1
7,7,16:18.1
8,7,16:18.1
9,7,16:18.1
10,7,16:18.1
4,8,16:18.1
5,8,16:18.1
6,8,16:18.1
7,8,16:18.1
8,8,16:18.1
4,9,16:18.1
5,9,16:18.1
6,9,16:18.1
7,9,16:18.1
8,9,16:18.1
6,10,16:18.1
0,-12,17:18.1
1,-12,17:18.1
2,-12,17:18.1
-1,-11,17:18.1
0,-11,17:18.1
1,-11,17:18.1
2,-11,17:18.1
3,-11,17:18.1
-2,-10,17:18.1
-1,-10,17:18.1
0,-10,17:18.1
1,-10,17:18.1
2,-10,17:18.1
3,-10,17:18.1
4,-10,17:18.1
-2,-9,17:18.1
-1,-9,17:18.1
0,-9,17:18.1
1,-9,17:17.13
2,-9,17:18.1
3,-9,17:18.1
4,-9,17:18.1
-2,-8,17:18.1
-1,-8,17:18.1
0,-8,17:17.13
1,-8,17:18.1
2,-8,17:18.1
3,-8,17:18.1
4,-8,17:18.1
5,-8,17:18.1
-1,-7,17:18.1
0,-7,17:17.13
1,-7,17:18.1
2,-7,17:18.1
3,-7,17:18.1
4,-7,17:18.1
5,-7,17:18.1
6,-7,17:18.1
0,-6,17:17.13
1,-6,17:18.1
2,-6,17:18.1
3,-6,17:18.1
4,-6,17:18.1
5,-6,17:18.1
6,-6,17:18.1
7,-6,17:18.1
-1,-5,17:17.13
1,-5,17:18.1
2,-5,17:18.1
3,-5,17:17.13
4,-5,17:17.13
5,-5,17:18.1
6,-5,17:18.1
7,-5,17:18.1
-2,-4,17:17.13
-1,-4,17:17.13
0,-4,17:17.13
1,-4,17:17.13
2,-4,17:17.13
3,-4,17:17.13
4,-4,17:17.13
5,-4,17:18.1
6,-4,17:18.1
7,-4,17:18.1
8,-4,17:18.1
-2,-3,17:17.13
-1,-3,17:17.13
0,-3,17:17.13
1,-3,17:17.13
2,-3,17:18.1
3,-3,17:18.1
4,-3,17:18.1
5,-3,17:18.1
6,-3,17:18.1
7,-3,17:18.1
3,-2,17:18.1
4,-2,17:18.1
5,-2,17:18.1
6,-2,17:18.1
7,-2,17:18.1
5,-1,17:18.1
-5,1,17:17.13
-4,1,17:17.13
-5,2,17:17.13
-4,2,17:17.13
-11,7,17:18.1
-10,7,17:18.1
-9,7,17:18.1
-7,7,17:17.13
-12,8,17:18.1
-11,8,17:18.1
-10,8,17:18.1
-9,8,17:18.1
-8,8,17:17.13
-7,8,17:17.13
-13,9,17:18.1
-12,9,17:18.1
-11,9,17:18.1
-10,9,17:18.1
-9,9,17:17.13
-8,9,17:18.1
-7,9,17:18.1
-13,10,17:18.1
-12,10,17:18.1
-11,10,17:18.1
-10,10,17:17.13
-9,10,17:17.13
-8,10,17:18.1
-7,10,17:18.1
-13,11,17:18.1
-12,11,17:18.1
-11,11,17:18.1
-10,11,17:18.1
-9,11,17:18.1
-8,11,17:18.1
-7,11,17:18.1
-12,12,17:18.1
-11,12,17:18.1
-10,12,17:18.1
-9,12,17:18.1
-8,12,17:18.1
-11,13,17:18.1
-10,13,17:18.1
-9,13,17:18.1
1,-12,18:18.1
-1,-11,18:18.1
0,-11,18:18.1
1,-11,18:18.1
2,-11,18:18.1
3,-11,18:18.1
-1,-10,18:18.1
0,-10,18:18.1
1,-10,18:18.1
2,-10,18:18.1
3,-10,18:18.1
-2,-9,18:18.1
-1,-9,18:18.1
0,-9,18:18.1
1,-9,18:18.1
2,-9,18:18.1
3,-9,18:18.1
4,-9,18:18.1
-1,-8,18:18.1
0,-8,18:18.1
1,-8,18:18.1
2,-8,18:18.1
3,-8,18:18.1
4,-8,18:18.1
-1,-7,18:18.1
0,-7,18:18.1
1,-7,18:18.1
2,-7,18:18.1
3,-7,18:18.1
4,-7,18:18.1
5,-7,18:18.1
6,-7,18:18.1
1,-6,18:18.1
2,-6,18:18.1
3,-6,18:18.1
4,-6,18:18.1
5,-6,18:18.1
6,-6,18:18.1
1,-5,18:18.1
2,-5,18:18.1
3,-5,18:18.1
4,-5,18:18.1
5,-5,18:18.1
6,-5,18:18.1
7,-5,18:18.1
2,-4,18:18.1
3,-4,18:18.1
4,-4,18:18.1
5,-4,18:18.1
6,-4,18:18.1
2,-3,18:18.1
3,-3,18:18.1
4,-3,18:18.1
5,-3,18:18.1
6,-3,18:18.1
4,-2,18:18.1
-5,0,18:17.13
-5,1,18:17.13
-4,1,18:17.13
-5,2,18:17.13
-4,2,18:17.13
-3,3,18:17.13
-3,4,18:17.13
-3,5,18:17.13
-3,6,18:18.1
-2,6,18:17.13
-1,6,18:18.1
-11,7,18:18.1
-10,7,18:18.1
-9,7,18:18.1
-4,7,18:18.1
-3,7,18:18.1
-2,7,18:17.13
-1,7,18:18.1
0,7,18:18.1
-12,8,18:18.1
-11,8,18:18.1
-10,8,18:18.1
-9,8,18:18.1
-8,8,18:18.1
-5,8,18:18.1
-4,8,18:18.1
-3,8,18:18.1
-2,8,18:17.13
-1,8,18:18.1
0,8,18:18.1
1,8,18:18.1
-13,9,18:18.1
-12,9,18:18.1
-11,9,18:18.1
-10,9,18:18.1
-9,9,18:18.1
-8,9,18:18.1
-7,9,18:18.1
-5,9,18:18.1
-4,9,18:18.1
-3,9,18:18.1
-2,9,18:17.13
-1,9,18:18.1
0,9,18:18.1
1,9,18:18.1
-13,10,18:18.1
-12,10,18:18.1
-11,10,18:18.1
-10,10,18:17.13
-9,10,18:18.1
-8,10,18:18.1
-7,10,18:18.1
-5,10,18:18.1
-4,10,18:18.1
-3,10,18:18.1
-2,10,18:18.1
-1,10,18:18.1
0,10,18:18.1
1,10,18:18.1
-13,11,18:18.1
-12,11,18:18.1
-11,11,18:18.1
-10,11,18:18.1
-9,11,18:18.1
-8,11,18:18.1
-7,11,18:18.1
-4,11,18:18.1
-3,11,18:18.1
-2,11,18:18.1
-1,11,18:18.1
0,11,18:18.1
-12,12,18:18.1
-11,12,18:18.1
-10,12,18:18.1
-9,12,18:18.1
-8,12,18:18.1
-3,12,18:18.1
-2,12,18:18.1
-1,12,18:18.1
-11,13,18:18.1
-10,13,18:18.1
-9,13,18:18.1
-5,-2,19:17.13
-5,-1,19:17.13
-5,1,19:17.13
-4,1,19:17.13
-5,2,19:17.13
-4,2,19:17.13
-2,6,19:18.1
-10,7,19:18.1
-4,7,19:18.1
-3,7,19:18.1
-2,7,19:18.1
-1,7,19:18.1
0,7,19:18.1
-12,8,19:18.1
-11,8,19:18.1
-10,8,19:18.1
-9,8,19:18.1
-8,8,19:18.1
-4,8,19:18.1
-3,8,19:18.1
-2,8,19:18.1
-1,8,19:18.1
0,8,19:18.1
-12,9,19:18.1
-11,9,19:18.1
-10,9,19:18.1
-9,9,19:18.1
-8,9,19:18.1
-5,9,19:18.1
-4,9,19:18.1
-3,9,19:18.1
-2,9,19:18.1
-1,9,19:18.1
0,9,19:18.1
1,9,19:18.1
-13,10,19:18.1
-12,10,19:18.1
-11,10,19:18.1
-10,10,19:18.1
-9,10,19:18.1
-8,10,19:18.1
-7,10,19:18.1
-4,10,19:18.1
-3,10,19:18.1
-2,10,19:18.1
-1,10,19:18.1
0,10,19:18.1
-12,11,19:18.1
-11,11,19:18.1
-10,11,19:18.1
-9,11,19:18.1
-8,11,19:18.1
-4,11,19:18.1
-3,11,19:18.1
-2,11,19:18.1
-1,11,19:18.1
0,11,19:18.1
-12,12,19:18.1
-11,12,19:18.1
-10,12,19:18.1
-9,12,19:18.1
-8,12,19:18.1
-2,12,19:18.1
-10,13,19:18.1
-5,-3,20:17.13
-5,-2,20:17.13
-5,1,20:17.13
-4,1,20:17.13
-5,2,20:17.13
-4,2,20:17.13
-5,-5,21:17.13
-5,-4,21:17.13
-5,1,21:17.13
-4,1,21:17.13
-5,2,21:17.13
-4,2,21:17.13
-6,-11,22:18.1
-5,-11,22:18.1
-4,-11,22:18.1
-7,-10,22:18.1
-6,-10,22:18.1
-5,-10,22:18.1
-4,-10,22:18.1
-3,-10,22:18.1
-8,-9,22:18.1
-7,-9,22:18.1
-6,-9,22:18.1
-5,-9,22:18.1
-4,-9,22:18.1
-3,-9,22:18.1
-2,-9,22:18.1
-8,-8,22:18.1
-7,-8,22:18.1
-6,-8,22:18.1
-5,-8,22:17.13
-4,-8,22:18.1
-3,-8,22:18.1
-2,-8,22:18.1
-8,-7,22:18.1
-7,-7,22:18.1
-6,-7,22:18.1
-5,-7,22:17.13
-4,-7,22:18.1
-3,-7,22:18.1
-2,-7,22:18.1
-7,-6,22:18.1
-6,-6,22:18.1
-5,-6,22:17.13
-4,-6,22:18.1
-3,-6,22:18.1
-6,-5,22:18.1
-5,-5,22:18.1
-4,-5,22:18.1
-5,1,22:17.13
-4,1,22:17.13
-5,2,22:17.13
-4,2,22:17.13
-5,-11,23:18.1
-7,-10,23:18.1
-6,-10,23:18.1
-5,-10,23:18.1
-4,-10,23:18.1
-3,-10,23:18.1
-7,-9,23:18.1
-6,-9,23:18.1
-5,-9,23:18.1
-4,-9,23:18.1
-3,-9,23:18.1
-8,-8,23:18.1
-7,-8,23:18.1
-6,-8,23:18.1
-5,-8,23:18.1
-4,-8,23:18.1
-3,-8,23:18.1
-2,-8,23:18.1
-7,-7,23:18.1
-6,-7,23:18.1
-5,-7,23:18.1
-4,-7,23:18.1
-3,-7,23:18.1
-7,-6,23:18.1
-6,-6,23:18.1
-5,-6,23:18.1
-4,-6,23:18.1
-3,-6,23:18.1
-5,-5,23:18.1
-5,0,23:17.13
-5,1,23:17.13
-4,1,23:17.13
-5,2,23:17.13
-4,2,23:17.13
-5,-1,24:17.13
-4,-1,24:17.13
-5,1,24:17.13
-4,1,24:17.13
-5,2,24:17.13
-4,2,24:17.13
-3,-4,25:17.13
-3,-3,25:17.13
-4,-2,25:17.13
-5,1,25:17.13
-4,1,25:17.13
-5,2,25:17.13
-4,2,25:17.13
-4,-8,26:18.1
-3,-8,26:18.1
-2,-8,26:18.1
-5,-7,26:18.1
-4,-7,26:18.1
-3,-7,26:18.1
-2,-7,26:18.1
-1,-7,26:18.1
-6,-6,26:18.1
-5,-6,26:18.1
-4,-6,26:18.1
-3,-6,26:18.1
-2,-6,26:18.1
-1,-6,26:18.1
0,-6,26:18.1
-6,-5,26:18.1
-5,-5,26:18.1
-4,-5,26:18.1
-3,-5,26:17.13
-2,-5,26:18.1
-1,-5,26:18.1
0,-5,26:18.1
-6,-4,26:18.1
-5,-4,26:18.1
-4,-4,26:18.1
-3,-4,26:18.1
-2,-4,26:18.1
-1,-4,26:18.1
0,-4,26:18.1
-5,-3,26:18.1
-4,-3,26:18.1
-3,-3,26:18.1
-2,-3,26:18.1
-1,-3,26:18.1
-4,-2,26:18.1
-3,-2,26:18.1
-2,-2,26:18.1
-5,0,26:17.13
-5,1,26:17.13
-4,1,26:17.13
-5,2,26:17.13
-4,2,26:17.13
-3,-8,27:18.1
-5,-7,27:18.1
-4,-7,27:18.1
-3,-7,27:18.1
-2,-7,27:18.1
-1,-7,27:18.1
-5,-6,27:18.1
-4,-6,27:18.1
-3,-6,27:18.1
-2,-6,27:18.1
-1,-6,27:18.1
-6,-5,27:18.1
-5,-5,27:18.1
-4,-5,27:18.1
-3,-5,27:18.1
-2,-5,27:18.1
-1,-5,27:18.1
0,-5,27:18.1
-5,-4,27:18.1
-4,-4,27:18.1
-3,-4,27:18.1
-2,-4,27:18.1
-1,-4,27:18.1
-5,-3,27:18.1
-4,-3,27:18.1
-3,-3,27:18.1
-2,-3,27:18.1
-1,-3,27:18.1
-3,-2,27:18.1
-6,-1,27:17.13
-6,0,27:17.13
-5,1,27:17.13
-4,1,27:17.13
-5,2,27:17.13
-4,2,27:17.13
-3,2,27:18.1
-6,3,27:18.1
-5,3,27:17.13
-4,3,27:18.1
-3,3,27:18.1
-2,3,27:18.1
-7,4,27:18.1
-6,4,27:18.1
-5,4,27:18.1
-4,4,27:17.13
-3,4,27:18.1
-2,4,27:18.1
-1,4,27:18.1
-7,5,27:18.1
-6,5,27:18.1
-5,5,27:18.1
-4,5,27:17.13
-3,5,27:18.1
-2,5,27:18.1
-1,5,27:18.1
-7,6,27:18.1
-6,6,27:18.1
-5,6,27:18.1
-4,6,27:18.1
-3,6,27:18.1
-2,6,27:18.1
-1,6,27:18.1
-6,7,27:18.1
-5,7,27:18.1
-4,7,27:18.1
-3,7,27:18.1
-2,7,27:18.1
-5,8,27:18.1
-4,8,27:18.1
-3,8,27:18.1
-9,-6,28:18.1
-8,-6,28:18.1
-7,-6,28:18.1
-10,-5,28:18.1
-9,-5,28:18.1
-8,-5,28:18.1
-7,-5,28:18.1
-6,-5,28:18.1
-11,-4,28:18.1
-10,-4,28:18.1
-9,-4,28:18.1
-8,-4,28:18.1
-7,-4,28:18.1
-6,-4,28:18.1
-5,-4,28:18.1
-11,-3,28:18.1
-10,-3,28:18.1
-9,-3,28:18.1
-8,-3,28:17.13
-7,-3,28:18.1
-6,-3,28:18.1
-5,-3,28:18.1
-11,-2,28:18.1
-10,-2,28:18.1
-9,-2,28:18.1
-8,-2,28:18.1
-7,-2,28:17.13
-6,-2,28:18.1
-5,-2,28:18.1
-10,-1,28:18.1
-9,-1,28:18.1
-8,-1,28:18.1
-7,-1,28:18.1
-6,-1,28:18.1
-9,0,28:18.1
-8,0,28:18.1
-7,0,28:18.1
-8,1,28:18.1
-7,1,28:18.1
-6,1,28:18.1
-5,1,28:17.13
-4,1,28:17.13
-9,2,28:18.1
-8,2,28:18.1
-7,2,28:18.1
-6,2,28:18.1
-5,2,28:17.13
-4,2,28:17.13
-10,3,28:18.1
-9,3,28:18.1
-8,3,28:18.1
-7,3,28:18.1
-6,3,28:17.13
-5,3,28:17.13
-4,3,28:18.1
-3,3,28:18.1
-2,3,28:18.1
-10,4,28:18.1
-9,4,28:18.1
-8,4,28:18.1
-7,4,28:17.13
-6,4,28:18.1
-5,4,28:18.1
-4,4,28:18.1
-3,4,28:18.1
-2,4,28:18.1
-10,5,28:18.1
-9,5,28:18.1
-8,5,28:18.1
-7,5,28:18.1
-6,5,28:18.1
-5,5,28:18.1
-4,5,28:18.1
-3,5,28:18.1
-2,5,28:18.1
-1,5,28:18.1
-9,6,28:18.1
-8,6,28:18.1
-7,6,28:18.1
-6,6,28:18.1
-5,6,28:18.1
-4,6,28:18.1
-3,6,28:18.1
-2,6,28:18.1
-8,7,28:18.1
-7,7,28:18.1
-6,7,28:18.1
-5,7,28:18.1
-4,7,28:18.1
-3,7,28:18.1
-2,7,28:18.1
-4,8,28:18.1
-8,-6,29:18.1
-10,-5,29:18.1
-9,-5,29:18.1
-8,-5,29:18.1
-7,-5,29:18.1
-6,-5,29:18.1
-10,-4,29:18.1
-9,-4,29:18.1
-8,-4,29:18.1
-7,-4,29:18.1
-6,-4,29:18.1
-11,-3,29:18.1
-10,-3,29:18.1
-9,-3,29:18.1
-8,-3,29:18.1
-7,-3,29:18.1
-6,-3,29:18.1
-5,-3,29:18.1
-10,-2,29:18.1
-9,-2,29:18.1
-8,-2,29:18.1
-7,-2,29:18.1
-6,-2,29:18.1
-10,-1,29:18.1
-9,-1,29:18.1
-8,-1,29:18.1
-7,-1,29:18.1
-6,-1,29:18.1
-10,0,29:18.1
-9,0,29:18.1
-8,0,29:18.1
-7,0,29:18.1
-6,0,29:18.1
-11,1,29:18.1
-10,1,29:18.1
-9,1,29:18.1
-8,1,29:18.1
-7,1,29:17.13
-6,1,29:17.13
-5,1,29:17.13
-4,1,29:17.13
-11,2,29:18.1
-10,2,29:18.1
-9,2,29:18.1
-8,2,29:17.13
-7,2,29:18.1
-6,2,29:18.1
-5,2,29:17.13
-4,2,29:17.13
-11,3,29:18.1
-10,3,29:18.1
-9,3,29:18.1
-8,3,29:18.1
-7,3,29:18.1
-6,3,29:18.1
-5,3,29:18.1
-4,3,29:18.1
-3,3,29:18.1
-10,4,29:18.1
-9,4,29:18.1
-8,4,29:18.1
-7,4,29:18.1
-6,4,29:17.13
-5,4,29:18.1
-4,4,29:18.1
-3,4,29:18.1
-9,5,29:18.1
-8,5,29:18.1
-7,5,29:18.1
-6,5,29:18.1
-5,5,29:18.1
-4,5,29:18.1
-3,5,29:18.1
-9,6,29:18.1
-8,6,29:18.1
-7,6,29:18.1
-6,6,29:18.1
-5,6,29:18.1
-4,6,29:18.1
-7,7,29:18.1
-6,7,29:18.1
-5,7,29:18.1
-9,-2,30:18.1
-8,-2,30:18.1
-7,-2,30:18.1
-10,-1,30:18.1
-9,-1,30:18.1
-8,-1,30:18.1
-7,-1,30:18.1
-6,-1,30:18.1
-5,-1,30:18.1
-4,-1,30:18.1
-3,-1,30:18.1
-2,-1,30:18.1
-11,0,30:18.1
-10,0,30:18.1
-9,0,30:18.1
-8,0,30:18.1
-7,0,30:18.1
-6,0,30:18.1
-5,0,30:18.1
-4,0,30:18.1
-3,0,30:18.1
-2,0,30:18.1
-1,0,30:18.1
-11,1,30:18.1
-10,1,30:18.1
-9,1,30:18.1
-8,1,30:17.13
-7,1,30:18.1
-6,1,30:18.1
-5,1,30:17.13
-4,1,30:17.13
-3,1,30:18.1
-2,1,30:18.1
-1,1,30:18.1
0,1,30:18.1
-11,2,30:18.1
-10,2,30:18.1
-9,2,30:18.1
-8,2,30:18.1
-7,2,30:18.1
-6,2,30:18.1
-5,2,30:17.13
-4,2,30:17.13
-3,2,30:17.13
-2,2,30:18.1
-1,2,30:18.1
0,2,30:18.1
-10,3,30:18.1
-9,3,30:18.1
-8,3,30:18.1
-7,3,30:18.1
-6,3,30:18.1
-5,3,30:18.1
-4,3,30:18.1
-3,3,30:18.1
-2,3,30:18.1
-1,3,30:18.1
0,3,30:18.1
-10,4,30:18.1
-9,4,30:18.1
-8,4,30:18.1
-7,4,30:18.1
-6,4,30:18.1
-5,4,30:18.1
-4,4,30:18.1
-3,4,30:18.1
-2,4,30:18.1
-1,4,30:18.1
-8,5,30:18.1
-7,5,30:18.1
-6,5,30:18.1
-5,5,30:18.1
-4,5,30:18.1
-3,5,30:18.1
-2,5,30:18.1
-8,6,30:18.1
-7,6,30:18.1
-6,6,30:18.1
-5,6,30:18.1
-4,6,30:18.1
-6,7,30:18.1
-5,-4,31:18.1
-4,-4,31:18.1
-3,-4,31:18.1
-6,-3,31:18.1
-5,-3,31:18.1
-4,-3,31:18.1
-3,-3,31:18.1
-2,-3,31:18.1
-8,-2,31:18.1
-7,-2,31:18.1
-6,-2,31:18.1
-5,-2,31:18.1
-4,-2,31:18.1
-3,-2,31:18.1
-2,-2,31:18.1
-1,-2,31:18.1
-10,-1,31:18.1
-9,-1,31:18.1
-8,-1,31:18.1
-7,-1,31:18.1
-6,-1,31:18.1
-5,-1,31:18.1
-4,-1,31:17.13
-3,-1,31:18.1
-2,-1,31:18.1
-1,-1,31:18.1
-10,0,31:18.1
-9,0,31:18.1
-8,0,31:18.1
-7,0,31:18.1
-6,0,31:18.1
-5,0,31:17.13
-4,0,31:18.1
-3,0,31:18.1
-2,0,31:18.1
-1,0,31:18.1
-11,1,31:18.1
-10,1,31:18.1
-9,1,31:18.1
-8,1,31:18.1
-7,1,31:18.1
-6,1,31:18.1
-5,1,31:17.13
-4,1,31:17.13
-3,1,31:18.1
-2,1,31:18.1
-1,1,31:18.1
-10,2,31:18.1
-9,2,31:18.1
-8,2,31:18.1
-7,2,31:18.1
-6,2,31:18.1
-5,2,31:17.13
-4,2,31:17.13
-3,2,31:18.1
-2,2,31:18.1
-1,2,31:18.1
0,2,31:18.1
-10,3,31:18.1
-9,3,31:18.1
-8,3,31:18.1
-7,3,31:18.1
-6,3,31:18.1
-5,3,31:18.1
-4,3,31:18.1
-3,3,31:18.1
-2,3,31:18.1
-1,3,31:18.1
-8,4,31:18.1
-6,4,31:18.1
-5,4,31:18.1
-4,4,31:18.1
-3,4,31:18.1
-2,4,31:18.1
-1,4,31:18.1
-4,5,31:18.1
-3,5,31:18.1
-6,-4,32:18.1
-5,-4,32:18.1
-4,-4,32:18.1
-7,-3,32:18.1
-6,-3,32:18.1
-5,-3,32:18.1
-4,-3,32:18.1
-3,-3,32:18.1
-2,-3,32:18.1
-8,-2,32:18.1
-7,-2,32:18.1
-6,-2,32:18.1
-5,-2,32:18.1
-4,-2,32:18.1
-3,-2,32:18.1
-2,-2,32:18.1
-8,-1,32:18.1
-7,-1,32:18.1
-6,-1,32:18.1
-5,-1,32:17.13
-4,-1,32:18.1
-3,-1,32:18.1
-2,-1,32:18.1
-1,-1,32:18.1
-8,0,32:18.1
-7,0,32:18.1
-6,0,32:18.1
-5,0,32:18.1
-4,0,32:17.13
-3,0,32:18.1
-2,0,32:18.1
-1,0,32:18.1
-9,1,32:18.1
-8,1,32:18.1
-7,1,32:18.1
-6,1,32:18.1
-5,1,32:17.13
-4,1,32:17.13
-3,1,32:18.1
-2,1,32:18.1
-1,1,32:18.1
-9,2,32:18.1
-8,2,32:18.1
-7,2,32:18.1
-6,2,32:17.13
-5,2,32:17.13
-4,2,32:17.13
-3,2,32:18.1
-2,2,32:18.1
-9,3,32:18.1
-8,3,32:18.1
-7,3,32:18.1
-6,3,32:18.1
-5,3,32:18.1
-4,3,32:18.1
-3,3,32:18.1
-8,4,32:18.1
-7,4,32:18.1
-6,4,32:18.1
-5,4,32:18.1
-4,4,32:18.1
-7,5,32:18.1
-6,5,32:18.1
-5,5,32:18.1
-5,-4,33:18.1
-7,-3,33:18.1
-6,-3,33:18.1
-5,-3,33:18.1
-4,-3,33:18.1
-3,-3,33:18.1
-7,-2,33:18.1
-6,-2,33:18.1
-5,-2,33:18.1
-4,-2,33:18.1
-3,-2,33:18.1
-2,-2,33:18.1
-8,-1,33:18.1
-7,-1,33:18.1
-6,-1,33:18.1
-5,-1,33:18.1
-4,-1,33:18.1
-3,-1,33:18.1
-2,-1,33:18.1
-8,0,33:18.1
-7,0,33:18.1
-6,0,33:18.1
-5,0,33:18.1
-4,0,33:18.1
-3,0,33:18.1
-2,0,33:18.1
-1,0,33:18.1
-8,1,33:18.1
-7,1,33:18.1
-6,1,33:18.1
-5,1,33:17.13
-4,1,33:17.13
-3,1,33:18.1
-2,1,33:18.1
-1,1,33:18.1
-9,2,33:18.1
-8,2,33:18.1
-7,2,33:18.1
-6,2,33:18.1
-5,2,33:17.13
-4,2,33:17.13
-3,2,33:18.1
-2,2,33:18.1
-1,2,33:18.1
-8,3,33:18.1
-7,3,33:18.1
-6,3,33:18.1
-5,3,33:18.1
-4,3,33:18.1
-3,3,33:18.1
-2,3,33:18.1
-8,4,33:18.1
-7,4,33:18.1
-6,4,33:18.1
-5,4,33:18.1
-4,4,33:18.1
-3,4,33:18.1
-6,5,33:18.1
-5,-2,34:18.1
-4,-2,34:18.1
-7,-1,34:18.1
-6,-1,34:18.1
-5,-1,34:18.1
-4,-1,34:18.1
-3,-1,34:18.1
-2,-1,34:18.1
-7,0,34:18.1
-6,0,34:18.1
-5,0,34:18.1
-4,0,34:18.1
-3,0,34:18.1
-2,0,34:18.1
-8,1,34:18.1
-7,1,34:18.1
-6,1,34:18.1
-5,1,34:18.1
-4,1,34:18.1
-3,1,34:18.1
-2,1,34:18.1
-1,1,34:18.1
-7,2,34:18.1
-6,2,34:18.1
-5,2,34:18.1
-4,2,34:18.1
-3,2,34:18.1
-2,2,34:18.1
-7,3,34:18.1
-6,3,34:18.1
-5,3,34:18.1
-4,3,34:18.1
-3,3,34:18.1
-2,3,34:18.1
-5,4,34:18.1
-4,4,34:18.1
-5,1,35:18.1
-4,1,35:18.1
-5,2,35:18.1
-4,2,35:18.1
