[META]
version=2.0
spawnOnBlockType=2
spawnSunlight=True
spawnDarkness=True
spawnWater=False
spawnLava=False
underFill=False
randomRotation=True
dig=True
tree=True
branch=False
needsFoundation=True
rarity=10
collisionPercentage=20
spawnElevationMin=0
spawnElevationMax=200
spawnInBiome=Custom
[DATA]
-1,1,0:17.1
-1,1,1:17.1
-1,1,2:17.1
-3,-3,3:18.1
-4,-2,3:18.1
-3,-2,3:18.1
-2,-2,3:18.1
-1,-2,3:18.1
0,-2,3:18.1
1,-2,3:18.1
-5,-1,3:18.1
-3,-1,3:18.1
-2,-1,3:18.1
-1,-1,3:18.1
0,-1,3:18.1
1,-1,3:18.1
3,-1,3:18.1
-5,0,3:18.1
-4,0,3:18.1
-3,0,3:18.1
-2,0,3:18.1
-1,0,3:18.1
0,0,3:17.9
1,0,3:18.1
2,0,3:18.1
-4,1,3:18.1
-3,1,3:17.5
-2,1,3:17.5
-1,1,3:17.1
0,1,3:17.5
1,1,3:18.1
2,1,3:18.1
-5,2,3:18.1
-4,2,3:18.1
-3,2,3:18.1
-2,2,3:17.9
-1,2,3:18.1
0,2,3:18.1
1,2,3:18.1
2,2,3:18.1
3,2,3:18.1
-4,3,3:18.1
-3,3,3:18.1
-2,3,3:17.9
-1,3,3:18.1
1,3,3:18.1
-2,4,3:18.1
-1,4,3:18.1
0,4,3:18.1
1,4,3:18.1
2,4,3:18.1
-2,5,3:18.1
0,-2,4:18.1
-3,-1,4:18.1
-2,-1,4:18.1
-1,-1,4:18.1
0,-1,4:18.1
-4,0,4:18.1
-3,0,4:18.1
-2,0,4:18.1
-1,0,4:18.1
0,0,4:18.1
1,0,4:18.1
2,0,4:18.1
-4,1,4:18.1
-3,1,4:18.1
-2,1,4:18.1
-1,1,4:17.1
0,1,4:18.1
1,1,4:18.1
-4,2,4:18.1
-3,2,4:18.1
-2,2,4:18.1
-1,2,4:18.1
0,2,4:18.1
1,2,4:18.1
-3,3,4:18.1
-2,3,4:18.1
-1,3,4:18.1
0,3,4:18.1
-1,4,4:18.1
0,4,4:18.1
0,-1,5:18.1
1,-1,5:18.1
-3,0,5:18.1
-2,0,5:18.1
-1,0,5:18.1
0,0,5:18.1
1,0,5:18.1
-2,1,5:18.1
-1,1,5:17.1
0,1,5:18.1
1,1,5:18.1
-2,2,5:18.1
-1,2,5:18.1
0,2,5:18.1
-1,3,5:18.1
0,3,5:18.1
-1,4,5:18.1
-3,-2,6:18.1
-2,-2,6:18.1
-4,-1,6:18.1
-3,-1,6:18.1
-2,-1,6:18.1
-1,-1,6:18.1
0,-1,6:18.1
1,-1,6:18.1
-4,0,6:18.1
-3,0,6:18.1
-1,0,6:18.1
0,0,6:18.1
1,0,6:18.1
2,0,6:18.1
-4,1,6:18.1
-3,1,6:18.1
-2,1,6:18.1
-1,1,6:17.1
0,1,6:18.1
1,1,6:18.1
2,1,6:18.1
-4,2,6:18.1
-3,2,6:18.1
-2,2,6:18.1
-1,2,6:18.1
0,2,6:18.1
1,2,6:18.1
-3,3,6:18.1
-2,3,6:18.1
-1,3,6:18.1
0,3,6:18.1
1,3,6:18.1
0,4,6:18.1
1,4,6:18.1
-1,-1,7:18.1
0,-1,7:18.1
-3,0,7:18.1
-2,0,7:18.1
-1,0,7:18.1
0,0,7:18.1
1,0,7:18.1
-2,1,7:18.1
-1,1,7:17.1
0,1,7:18.1
1,1,7:18.1
-3,2,7:18.1
-2,2,7:18.1
-1,2,7:18.1
0,2,7:18.1
1,2,7:18.1
-1,3,7:18.1
0,-1,8:18.1
-1,0,8:18.1
0,0,8:18.1
-3,1,8:18.1
-2,1,8:18.1
-1,1,8:17.1
0,1,8:18.1
-3,2,8:18.1
-1,2,8:18.1
0,-2,9:18.1
-3,-1,9:18.1
-2,-1,9:18.1
-1,-1,9:18.1
0,-1,9:18.1
-3,0,9:18.1
-1,0,9:18.1
0,0,9:18.1
1,0,9:18.1
-3,1,9:18.1
-2,1,9:18.1
-1,1,9:17.1
0,1,9:18.1
1,1,9:18.1
-3,2,9:18.1
-2,2,9:18.1
-1,2,9:18.1
0,2,9:18.1
1,2,9:18.1
-3,3,9:18.1
-2,3,9:18.1
-1,3,9:18.1
1,3,9:18.1
0,4,9:18.1
-1,-1,10:18.1
-1,0,10:18.1
-3,1,10:18.1
-2,1,10:18.1
-1,1,10:17.1
0,1,10:18.1
1,1,10:18.1
-2,2,10:18.1
-1,2,10:18.1
0,2,10:18.1
1,2,10:18.1
-2,3,10:18.1
-1,3,10:18.1
-1,0,11:18.1
-1,1,11:17.1
-2,2,11:18.1
-1,2,11:18.1
0,0,12:18.1
-1,1,12:18.1
-2,2,12:18.1
-1,2,12:18.1
-1,0,13:18.1
-2,1,13:18.1
-1,1,13:18.1
0,1,13:18.1
-1,1,14:18.1
-1,1,15:18.1
