[META]
version=2.0
spawnOnBlockType=2
spawnSunlight=True
spawnDarkness=False
spawnWater=False
spawnLava=False
underFill=True
randomRotation=True
dig=True
tree=True
branch=False
needsFoundation=True
rarity=10
collisionPercentage=2
spawnElevationMin=0
spawnElevationMax=128
spawnInBiome=Custom
[DATA]
1,-4,-2:17.1
4,-4,-2:17.1
-2,-2,-2:17.1
-1,-1,-2:17.1
0,-1,-2:17.1
2,0,-2:17.1
3,0,-2:17.1
0,1,-2:17.1
4,1,-2:17.1
-1,2,-2:17.1
1,-3,-1:17.1
3,-3,-1:17.1
2,-2,-1:17.1
0,-1,-1:17.1
1,-1,-1:17.1
0,0,-1:17.1
0,1,-1:17.1
1,-2,0:17.1
1,-1,0:17.1
0,0,0:17.1
2,-3,1:18.1
4,-2,1:18.1
-2,-1,1:18.1
1,-1,1:17.1
0,0,1:17.1
4,1,1:18.1
-1,2,1:18.1
4,2,1:18.1
1,-3,2:18.1
-1,-2,2:18.1
1,-2,2:18.1
3,-2,2:18.1
-1,-1,2:18.1
0,-1,2:18.1
1,-1,2:18.1
2,-1,2:18.1
3,-1,2:18.1
4,-1,2:18.1
-2,0,2:18.1
-1,0,2:18.1
0,0,2:17.1
2,0,2:18.1
3,0,2:18.1
-1,1,2:18.1
2,1,2:18.1
3,1,2:18.1
0,2,2:18.1
1,2,2:18.1
3,2,2:18.1
-2,3,2:18.1
1,3,2:18.1
0,-4,3:18.1
-2,-3,3:18.1
3,-3,3:18.1
-4,-1,3:18.1
-1,-1,3:18.1
1,-1,3:18.1
2,-1,3:18.1
0,0,3:17.1
1,0,3:18.1
0,1,3:18.1
1,1,3:18.1
-3,2,3:18.1
-2,2,3:18.1
-1,2,3:18.1
3,2,3:18.1
1,4,3:18.1
-1,-3,4:18.1
0,-3,4:18.1
2,-3,4:18.1
-2,-2,4:18.1
-1,-2,4:18.1
1,-2,4:18.1
2,-2,4:18.1
3,-2,4:18.1
-3,-1,4:18.1
-2,-1,4:18.1
-1,-1,4:18.1
3,-1,4:18.1
4,-1,4:18.1
-3,0,4:18.1
-2,0,4:18.1
0,0,4:17.1
2,0,4:18.1
3,0,4:18.1
-2,1,4:18.1
-1,1,4:18.1
2,1,4:18.1
3,1,4:18.1
4,1,4:18.1
0,2,4:18.1
2,2,4:18.1
1,3,4:18.1
0,-2,5:18.1
-2,-1,5:18.1
0,-1,5:18.1
1,-1,5:18.1
2,-1,5:18.1
-2,0,5:18.1
-1,0,5:18.1
0,0,5:17.1
1,0,5:18.1
2,0,5:18.1
-1,1,5:18.1
0,1,5:18.1
1,1,5:18.1
2,1,5:18.1
0,2,5:18.1
1,2,5:18.1
1,-3,6:18.1
-1,-2,6:18.1
1,-2,6:18.1
2,-2,6:18.1
3,-1,6:18.1
-1,0,6:18.1
0,0,6:17.1
2,0,6:18.1
0,1,6:18.1
0,3,6:18.1
-1,-1,7:18.1
0,-1,7:18.1
1,-1,7:18.1
-1,0,7:18.1
0,0,7:18.1
1,0,7:18.1
-2,1,7:18.1
-1,1,7:18.1
0,1,7:17.1
1,1,7:18.1
2,1,7:18.1
-1,2,7:18.1
0,2,7:18.1
1,2,7:18.1
1,-2,8:18.1
2,-2,8:18.1
-2,-1,8:18.1
2,0,8:18.1
-3,1,8:18.1
0,1,8:17.1
2,1,8:18.1
-1,3,8:18.1
1,3,8:18.1
0,-2,9:18.1
0,-1,9:18.1
1,-1,9:18.1
-2,0,9:18.1
-1,0,9:18.1
0,0,9:18.1
1,0,9:18.1
-2,1,9:18.1
-1,1,9:17.1
0,1,9:18.1
1,1,9:18.1
-2,2,9:18.1
-1,2,9:18.1
0,2,9:18.1
-2,3,9:18.1
-1,-1,10:18.1
2,-1,10:18.1
-3,0,10:18.1
2,0,10:18.1
-1,1,10:17.1
-3,2,10:18.1
-2,2,10:18.1
1,2,10:18.1
-1,3,10:18.1
0,3,10:18.1
-2,0,11:18.1
-1,0,11:18.1
0,0,11:18.1
1,0,11:18.1
-2,1,11:18.1
-1,1,11:18.1
0,1,11:18.1
1,1,11:18.1
-2,2,11:18.1
-1,2,11:17.1
0,2,11:18.1
-2,1,12:18.1
0,1,12:18.1
-1,2,12:17.1
-2,3,12:18.1
-1,3,12:18.1
0,0,13:18.1
-1,1,13:18.1
0,1,13:18.1
1,1,13:18.1
-2,2,13:18.1
-1,2,13:18.1
0,2,13:18.1
-2,2,14:18.1
-1,2,14:18.1
-2,3,14:18.1
-1,3,14:18.1
-1,1,15:18.1
-2,2,15:18.1
-1,2,15:18.1
0,2,15:18.1
-1,3,15:18.1
-1,2,16:18.1
-2,3,16:18.1
-2,3,17:18.1
