[META]
version=2.0
spawnOnBlockType=9
spawnSunlight=True
spawnDarkness=True
spawnWater=True
spawnLava=False
underFill=False
randomRotation=True
dig=True
tree=True
branch=False
needsFoundation=True
rarity=50
collisionPercentage=20
spawnElevationMin=0
spawnElevationMax=60
spawnInBiome=Custom
[DATA]
-1,-7,-8:17.13
-2,-2,-8:17.13
-1,-7,-7:17.13
-2,-2,-7:17.13
-1,-7,-6:17.13
-2,-2,-6:17.13
-1,-7,-5:17.13
-2,-2,-5:17.13
-1,-7,-4:17.13
3,-5,-4:17.13
-3,-4,-4:17.13
-2,-2,-4:17.13
0,-1,-4:17.13
2,-1,-4:17.13
-1,-7,-3:17.13
2,-6,-3:17.13
3,-5,-3:17.13
-3,-4,-3:17.13
4,-3,-3:17.13
-2,-2,-3:17.13
0,-1,-3:17.13
2,-1,-3:17.13
-1,-7,-2:17.13
2,-6,-2:17.13
3,-5,-2:17.13
-3,-4,-2:17.13
4,-3,-2:17.13
-2,-2,-2:17.13
0,-1,-2:17.13
2,-1,-2:17.13
-1,-7,-1:17.13
2,-6,-1:17.13
3,-5,-1:17.13
-3,-4,-1:17.13
4,-3,-1:17.13
-2,-2,-1:17.13
0,-1,-1:17.13
2,-1,-1:17.13
-1,-7,0:17.13
2,-6,0:17.13
3,-5,0:17.13
-3,-4,0:17.13
4,-3,0:17.13
-2,-2,0:17.13
0,-1,0:17.13
2,-1,0:17.13
-1,-7,1:17.13
2,-6,1:17.13
3,-5,1:17.13
-3,-4,1:17.13
4,-3,1:17.13
-2,-2,1:17.13
0,-1,1:17.13
2,-1,1:17.13
-1,-7,2:17.13
2,-6,2:17.13
3,-5,2:17.13
-3,-4,2:17.13
4,-3,2:17.13
-2,-2,2:17.13
0,-1,2:17.13
2,-1,2:17.13
-1,-6,3:17.13
2,-6,3:17.13
3,-5,3:17.13
-3,-4,3:17.13
4,-3,3:17.13
-2,-2,3:17.13
0,-1,3:17.13
2,-1,3:17.13
-1,-6,4:17.13
2,-6,4:17.13
3,-5,4:17.13
-3,-4,4:17.13
4,-3,4:17.13
-2,-2,4:17.13
0,-1,4:17.13
2,-1,4:17.13
-1,-6,5:17.13
2,-6,5:17.13
3,-5,5:17.13
-3,-4,5:17.13
3,-3,5:17.13
-2,-2,5:17.13
0,-1,5:17.13
2,-1,5:17.13
-1,-6,6:17.13
0,-6,6:17.13
1,-6,6:17.13
2,-6,6:17.13
-2,-5,6:17.13
-1,-5,6:17.13
0,-5,6:17.13
1,-5,6:17.13
2,-5,6:17.13
3,-5,6:17.13
-3,-4,6:17.13
-2,-4,6:17.13
-1,-4,6:17.13
0,-4,6:17.13
1,-4,6:17.13
2,-4,6:17.13
3,-4,6:17.13
-2,-3,6:17.13
-1,-3,6:17.13
0,-3,6:17.13
1,-3,6:17.13
2,-3,6:17.13
3,-3,6:17.13
-2,-2,6:17.13
-1,-2,6:17.13
0,-2,6:17.13
1,-2,6:17.13
2,-2,6:17.13
3,-2,6:17.13
-1,-1,6:17.13
0,-1,6:17.13
1,-1,6:17.13
2,-1,6:17.13
-1,-6,7:17.13
0,-6,7:17.13
1,-6,7:17.13
-1,-5,7:17.13
0,-5,7:17.13
1,-5,7:17.13
2,-5,7:17.13
3,-5,7:17.13
-2,-4,7:17.13
-1,-4,7:17.13
0,-4,7:17.13
1,-4,7:17.13
2,-4,7:17.13
3,-4,7:17.13
-2,-3,7:17.13
-1,-3,7:17.13
0,-3,7:17.13
1,-3,7:17.13
2,-3,7:17.13
3,-3,7:17.13
-2,-2,7:17.13
-1,-2,7:17.13
0,-2,7:17.13
1,-2,7:17.13
2,-2,7:17.13
0,-1,7:17.13
1,-1,7:17.13
2,-1,7:17.13
0,-6,8:17.13
1,-6,8:17.13
-1,-5,8:17.13
0,-5,8:17.13
1,-5,8:17.13
2,-5,8:17.13
3,-5,8:17.13
-2,-4,8:17.13
-1,-4,8:17.13
0,-4,8:17.13
1,-4,8:17.13
2,-4,8:17.13
-1,-3,8:17.13
0,-3,8:17.13
1,-3,8:17.13
2,-3,8:17.13
3,-3,8:17.13
-2,-2,8:17.13
-1,-2,8:17.13
0,-2,8:17.13
1,-2,8:17.13
2,-2,8:17.13
0,-1,8:17.13
2,-1,8:17.13
0,-6,9:17.13
1,-6,9:17.13
-1,-5,9:17.13
0,-5,9:17.13
1,-5,9:17.13
2,-5,9:17.13
3,-5,9:17.13
-2,-4,9:17.13
-1,-4,9:17.13
0,-4,9:17.13
1,-4,9:17.13
2,-4,9:17.13
-1,-3,9:17.13
0,-3,9:17.13
1,-3,9:17.13
2,-3,9:17.13
3,-3,9:17.13
-2,-2,9:17.13
-1,-2,9:17.13
0,-2,9:17.13
1,-2,9:17.13
2,-2,9:17.13
0,-1,9:17.13
2,-1,9:17.13
0,-6,10:17.13
0,-5,10:17.13
1,-5,10:17.13
2,-5,10:17.13
-2,-4,10:17.13
-1,-4,10:17.13
0,-4,10:17.13
1,-4,10:17.13
2,-4,10:17.13
-1,-3,10:17.13
0,-3,10:17.13
1,-3,10:17.13
2,-3,10:17.13
3,-3,10:17.13
-1,-2,10:17.13
0,-2,10:17.13
1,-2,10:17.13
2,-2,10:17.13
0,-1,10:17.13
0,-5,11:17.13
1,-5,11:17.13
2,-5,11:17.13
-1,-4,11:17.13
0,-4,11:17.13
1,-4,11:17.13
2,-4,11:17.13
-1,-3,11:17.13
0,-3,11:17.13
1,-3,11:17.13
2,-3,11:17.13
-1,-2,11:17.13
0,-2,11:17.13
1,-2,11:17.13
2,-2,11:17.13
0,-1,11:17.13
0,-5,12:17.13
1,-5,12:17.13
-1,-4,12:17.13
0,-4,12:17.13
1,-4,12:17.13
2,-4,12:17.13
-1,-3,12:17.13
0,-3,12:17.13
1,-3,12:17.13
2,-3,12:17.13
0,-2,12:17.13
1,-2,12:17.13
0,-1,12:17.13
0,-5,13:17.13
1,-5,13:17.13
-1,-4,13:17.13
0,-4,13:17.13
1,-4,13:17.13
2,-4,13:17.13
-1,-3,13:17.13
0,-3,13:17.13
1,-3,13:17.13
2,-3,13:17.13
0,-2,13:17.13
1,-2,13:17.13
0,-5,14:17.13
1,-5,14:17.13
-1,-4,14:17.13
0,-4,14:17.13
1,-4,14:17.13
2,-4,14:17.13
-1,-3,14:17.13
0,-3,14:17.13
1,-3,14:17.13
2,-3,14:17.13
0,-2,14:17.13
1,-2,14:17.13
0,-4,15:17.13
1,-4,15:17.13
0,-3,15:17.13
1,-3,15:17.13
0,-4,16:17.13
1,-4,16:17.13
0,-3,16:17.13
1,-3,16:17.13
0,-4,17:17.13
1,-4,17:17.13
0,-3,17:17.13
1,-3,17:17.13
0,-4,18:17.13
1,-4,18:17.13
0,-3,18:17.13
1,-3,18:17.13
0,-4,19:17.13
1,-4,19:17.13
0,-3,19:17.13
1,-3,19:17.13
0,-2,19:17.13
1,-1,19:17.13
1,0,19:17.13
0,1,19:17.13
0,2,19:17.13
-2,3,19:18.1
-1,3,19:17.13
0,3,19:18.1
-3,4,19:18.1
-2,4,19:18.1
-1,4,19:17.13
0,4,19:18.1
1,4,19:18.1
-4,5,19:18.1
-3,5,19:18.1
-2,5,19:18.1
-1,5,19:17.13
0,5,19:18.1
1,5,19:18.1
2,5,19:18.1
-4,6,19:18.1
-3,6,19:18.1
-2,6,19:18.1
-1,6,19:17.13
0,6,19:18.1
1,6,19:18.1
2,6,19:18.1
-4,7,19:18.1
-3,7,19:18.1
-2,7,19:18.1
-1,7,19:18.1
0,7,19:18.1
1,7,19:18.1
2,7,19:18.1
-3,8,19:18.1
-2,8,19:18.1
-1,8,19:18.1
0,8,19:18.1
1,8,19:18.1
-2,9,19:18.1
-1,9,19:18.1
0,9,19:18.1
0,-4,20:17.13
1,-4,20:17.13
0,-3,20:17.13
1,-3,20:17.13
1,0,20:17.13
2,1,20:17.13
2,2,20:17.13
3,2,20:18.1
4,2,20:18.1
5,2,20:18.1
-1,3,20:18.1
2,3,20:18.1
3,3,20:17.13
4,3,20:18.1
5,3,20:18.1
6,3,20:18.1
-3,4,20:18.1
-2,4,20:18.1
-1,4,20:18.1
0,4,20:18.1
1,4,20:18.1
2,4,20:18.1
3,4,20:17.13
4,4,20:18.1
5,4,20:18.1
6,4,20:18.1
7,4,20:18.1
-3,5,20:18.1
-2,5,20:18.1
-1,5,20:18.1
0,5,20:18.1
1,5,20:18.1
2,5,20:18.1
3,5,20:18.1
4,5,20:17.13
5,5,20:18.1
6,5,20:18.1
7,5,20:18.1
-4,6,20:18.1
-3,6,20:18.1
-2,6,20:18.1
-1,6,20:18.1
0,6,20:18.1
1,6,20:18.1
2,6,20:18.1
3,6,20:18.1
4,6,20:18.1
5,6,20:18.1
6,6,20:18.1
7,6,20:18.1
-3,7,20:18.1
-2,7,20:18.1
-1,7,20:18.1
0,7,20:18.1
1,7,20:18.1
2,7,20:18.1
3,7,20:18.1
4,7,20:18.1
5,7,20:18.1
6,7,20:18.1
-3,8,20:18.1
-2,8,20:18.1
-1,8,20:18.1
0,8,20:18.1
1,8,20:18.1
3,8,20:18.1
4,8,20:18.1
5,8,20:18.1
-1,9,20:18.1
0,-4,21:17.13
1,-4,21:17.13
0,-3,21:17.13
1,-3,21:17.13
4,2,21:18.1
2,3,21:18.1
3,3,21:18.1
4,3,21:18.1
5,3,21:18.1
6,3,21:18.1
2,4,21:18.1
3,4,21:18.1
4,4,21:18.1
5,4,21:18.1
6,4,21:18.1
1,5,21:18.1
2,5,21:18.1
3,5,21:18.1
4,5,21:18.1
5,5,21:18.1
6,5,21:18.1
7,5,21:18.1
2,6,21:18.1
3,6,21:18.1
4,6,21:18.1
5,6,21:18.1
6,6,21:18.1
2,7,21:18.1
3,7,21:18.1
4,7,21:18.1
5,7,21:18.1
6,7,21:18.1
4,8,21:18.1
0,-4,22:17.13
1,-4,22:17.13
0,-3,22:17.13
1,-3,22:17.13
0,-4,23:17.13
1,-4,23:17.13
0,-3,23:17.13
1,-3,23:17.13
0,-4,24:17.13
1,-4,24:17.13
0,-3,24:17.13
1,-3,24:17.13
0,-2,24:17.13
3,-2,24:18.1
4,-2,24:18.1
5,-2,24:18.1
0,-1,24:17.13
1,-1,24:17.13
2,-1,24:18.1
3,-1,24:18.1
4,-1,24:18.1
5,-1,24:18.1
6,-1,24:18.1
1,0,24:18.1
2,0,24:17.13
3,0,24:17.13
4,0,24:18.1
5,0,24:18.1
6,0,24:18.1
7,0,24:18.1
1,1,24:18.1
2,1,24:18.1
3,1,24:17.13
4,1,24:17.13
5,1,24:18.1
6,1,24:18.1
7,1,24:18.1
1,2,24:18.1
2,2,24:18.1
3,2,24:18.1
4,2,24:18.1
5,2,24:18.1
6,2,24:18.1
7,2,24:18.1
2,3,24:18.1
3,3,24:18.1
4,3,24:18.1
5,3,24:18.1
6,3,24:18.1
3,4,24:18.1
4,4,24:18.1
5,4,24:18.1
-2,-4,25:17.13
-1,-4,25:17.13
0,-4,25:17.13
1,-4,25:17.13
0,-3,25:17.13
1,-3,25:17.13
2,-2,25:18.1
3,-2,25:18.1
4,-2,25:18.1
0,-1,25:17.13
1,-1,25:18.1
2,-1,25:18.1
3,-1,25:18.1
4,-1,25:18.1
5,-1,25:18.1
6,-1,25:18.1
0,0,25:17.13
1,0,25:17.13
2,0,25:17.13
3,0,25:18.1
4,0,25:18.1
5,0,25:18.1
6,0,25:18.1
0,1,25:18.1
1,1,25:18.1
2,1,25:18.1
3,1,25:17.13
4,1,25:18.1
5,1,25:18.1
6,1,25:18.1
7,1,25:18.1
0,2,25:18.1
1,2,25:18.1
2,2,25:18.1
3,2,25:18.1
4,2,25:18.1
5,2,25:18.1
6,2,25:18.1
1,3,25:18.1
2,3,25:18.1
3,3,25:18.1
4,3,25:18.1
5,3,25:18.1
6,3,25:18.1
2,4,25:18.1
3,4,25:18.1
4,4,25:18.1
-7,-7,26:18.1
-6,-7,26:18.1
-5,-7,26:18.1
-8,-6,26:18.1
-7,-6,26:18.1
-6,-6,26:18.1
-5,-6,26:18.1
-4,-6,26:18.1
-9,-5,26:18.1
-8,-5,26:18.1
-7,-5,26:18.1
-6,-5,26:18.1
-5,-5,26:18.1
-4,-5,26:18.1
-3,-5,26:18.1
-9,-4,26:18.1
-8,-4,26:18.1
-7,-4,26:18.1
-6,-4,26:17.13
-5,-4,26:17.13
-4,-4,26:17.13
-3,-4,26:17.13
0,-4,26:17.13
1,-4,26:17.13
-9,-3,26:18.1
-8,-3,26:18.1
-7,-3,26:18.1
-6,-3,26:18.1
-5,-3,26:18.1
-4,-3,26:18.1
-3,-3,26:18.1
0,-3,26:17.13
1,-3,26:17.13
2,-3,26:18.1
-8,-2,26:18.1
-7,-2,26:18.1
-6,-2,26:18.1
-5,-2,26:18.1
-4,-2,26:18.1
-1,-2,26:18.1
0,-2,26:18.1
1,-2,26:17.13
2,-2,26:18.1
3,-2,26:18.1
-7,-1,26:18.1
-6,-1,26:18.1
-5,-1,26:18.1
-2,-1,26:18.1
-1,-1,26:18.1
0,-1,26:18.1
1,-1,26:17.13
2,-1,26:18.1
3,-1,26:18.1
4,-1,26:18.1
5,-1,26:18.1
-2,0,26:18.1
-1,0,26:18.1
0,0,26:18.1
1,0,26:17.13
2,0,26:18.1
3,0,26:18.1
4,0,26:18.1
5,0,26:18.1
-3,1,26:18.1
-2,1,26:18.1
-1,1,26:18.1
0,1,26:17.13
1,1,26:18.1
2,1,26:18.1
3,1,26:18.1
4,1,26:18.1
5,1,26:18.1
6,1,26:18.1
-3,2,26:18.1
-2,2,26:18.1
-1,2,26:18.1
0,2,26:17.13
1,2,26:18.1
2,2,26:18.1
3,2,26:18.1
4,2,26:18.1
5,2,26:18.1
-3,3,26:18.1
-2,3,26:18.1
-1,3,26:18.1
0,3,26:18.1
1,3,26:18.1
2,3,26:18.1
3,3,26:18.1
4,3,26:18.1
5,3,26:18.1
-2,4,26:18.1
-1,4,26:18.1
0,4,26:18.1
1,4,26:18.1
2,4,26:18.1
3,4,26:18.1
-1,5,26:18.1
0,5,26:18.1
1,5,26:18.1
-6,-7,27:18.1
-8,-6,27:18.1
-7,-6,27:18.1
-6,-6,27:18.1
-5,-6,27:18.1
-4,-6,27:18.1
-8,-5,27:18.1
-7,-5,27:18.1
-6,-5,27:18.1
-5,-5,27:18.1
-4,-5,27:18.1
-9,-4,27:18.1
-8,-4,27:18.1
-7,-4,27:18.1
-6,-4,27:18.1
-5,-4,27:18.1
-4,-4,27:18.1
-3,-4,27:18.1
0,-4,27:17.13
1,-4,27:17.13
-8,-3,27:18.1
-7,-3,27:18.1
-6,-3,27:18.1
-5,-3,27:18.1
-4,-3,27:18.1
0,-3,27:17.13
1,-3,27:17.13
2,-3,27:18.1
3,-3,27:18.1
4,-3,27:18.1
-8,-2,27:18.1
-7,-2,27:18.1
-6,-2,27:18.1
-5,-2,27:18.1
-4,-2,27:18.1
-1,-2,27:18.1
0,-2,27:18.1
1,-2,27:18.1
2,-2,27:17.13
3,-2,27:18.1
4,-2,27:18.1
5,-2,27:18.1
-6,-1,27:18.1
-1,-1,27:18.1
0,-1,27:18.1
1,-1,27:18.1
2,-1,27:17.13
3,-1,27:18.1
4,-1,27:18.1
5,-1,27:18.1
6,-1,27:18.1
-2,0,27:18.1
-1,0,27:18.1
0,0,27:18.1
1,0,27:18.1
2,0,27:18.1
3,0,27:17.13
4,0,27:18.1
5,0,27:18.1
6,0,27:18.1
-2,1,27:18.1
-1,1,27:18.1
0,1,27:18.1
1,1,27:18.1
2,1,27:18.1
3,1,27:18.1
4,1,27:18.1
5,1,27:18.1
6,1,27:18.1
-3,2,27:18.1
-2,2,27:18.1
-1,2,27:18.1
0,2,27:18.1
1,2,27:18.1
2,2,27:18.1
3,2,27:18.1
4,2,27:18.1
5,2,27:18.1
-2,3,27:18.1
-1,3,27:18.1
0,3,27:18.1
1,3,27:18.1
2,3,27:18.1
3,3,27:18.1
4,3,27:18.1
-2,4,27:18.1
-1,4,27:18.1
0,4,27:18.1
1,4,27:18.1
2,4,27:18.1
0,5,27:18.1
0,-4,28:17.13
1,-4,28:17.13
0,-3,28:17.13
1,-3,28:17.13
3,-3,28:18.1
1,-2,28:18.1
2,-2,28:18.1
3,-2,28:18.1
4,-2,28:18.1
5,-2,28:18.1
1,-1,28:18.1
2,-1,28:18.1
3,-1,28:18.1
4,-1,28:18.1
5,-1,28:18.1
0,0,28:18.1
1,0,28:18.1
2,0,28:18.1
3,0,28:18.1
4,0,28:18.1
5,0,28:18.1
6,0,28:18.1
1,1,28:18.1
2,1,28:18.1
3,1,28:18.1
4,1,28:18.1
5,1,28:18.1
1,2,28:18.1
2,2,28:18.1
3,2,28:18.1
4,2,28:18.1
5,2,28:18.1
3,3,28:18.1
0,-4,29:17.13
1,-4,29:17.13
0,-3,29:17.13
1,-3,29:17.13
-3,-8,30:18.1
-2,-8,30:18.1
-1,-8,30:18.1
-4,-7,30:18.1
-3,-7,30:18.1
-2,-7,30:18.1
-1,-7,30:18.1
0,-7,30:18.1
2,-7,30:18.1
3,-7,30:18.1
4,-7,30:18.1
-5,-6,30:18.1
-4,-6,30:18.1
-3,-6,30:18.1
-2,-6,30:18.1
-1,-6,30:18.1
0,-6,30:18.1
1,-6,30:18.1
2,-6,30:18.1
3,-6,30:18.1
4,-6,30:18.1
5,-6,30:18.1
-5,-5,30:18.1
-4,-5,30:18.1
-3,-5,30:18.1
-2,-5,30:17.13
-1,-5,30:18.1
0,-5,30:18.1
1,-5,30:18.1
2,-5,30:18.1
3,-5,30:18.1
4,-5,30:18.1
5,-5,30:18.1
6,-5,30:18.1
-5,-4,30:18.1
-4,-4,30:18.1
-3,-4,30:18.1
-2,-4,30:18.1
-1,-4,30:17.13
0,-4,30:17.13
1,-4,30:17.13
2,-4,30:17.13
3,-4,30:17.13
4,-4,30:18.1
5,-4,30:18.1
6,-4,30:18.1
-4,-3,30:18.1
-3,-3,30:18.1
-2,-3,30:18.1
-1,-3,30:18.1
0,-3,30:17.13
1,-3,30:17.13
2,-3,30:18.1
3,-3,30:18.1
4,-3,30:18.1
5,-3,30:18.1
6,-3,30:18.1
-3,-2,30:18.1
-2,-2,30:18.1
-1,-2,30:18.1
1,-2,30:18.1
2,-2,30:18.1
3,-2,30:18.1
4,-2,30:18.1
5,-2,30:18.1
2,-1,30:18.1
3,-1,30:18.1
4,-1,30:18.1
-2,-8,31:18.1
-4,-7,31:18.1
-3,-7,31:18.1
-2,-7,31:18.1
-1,-7,31:18.1
0,-7,31:18.1
3,-7,31:18.1
-4,-6,31:18.1
-3,-6,31:18.1
-2,-6,31:18.1
-1,-6,31:18.1
0,-6,31:18.1
1,-6,31:18.1
2,-6,31:18.1
3,-6,31:18.1
4,-6,31:18.1
5,-6,31:18.1
-5,-5,31:18.1
-4,-5,31:18.1
-3,-5,31:18.1
-2,-5,31:18.1
-1,-5,31:18.1
0,-5,31:18.1
1,-5,31:18.1
2,-5,31:18.1
3,-5,31:18.1
4,-5,31:18.1
5,-5,31:18.1
-4,-4,31:18.1
-3,-4,31:18.1
-2,-4,31:18.1
-1,-4,31:18.1
0,-4,31:17.13
1,-4,31:17.13
2,-4,31:18.1
3,-4,31:18.1
4,-4,31:18.1
5,-4,31:18.1
6,-4,31:18.1
-4,-3,31:18.1
-3,-3,31:18.1
-2,-3,31:18.1
-1,-3,31:18.1
0,-3,31:17.13
1,-3,31:17.13
2,-3,31:18.1
3,-3,31:18.1
4,-3,31:18.1
5,-3,31:18.1
-2,-2,31:18.1
1,-2,31:18.1
2,-2,31:18.1
3,-2,31:18.1
4,-2,31:18.1
5,-2,31:18.1
3,-1,31:18.1
-1,-5,32:18.1
0,-5,32:18.1
1,-5,32:18.1
-2,-4,32:18.1
-1,-4,32:18.1
0,-4,32:17.13
1,-4,32:17.13
2,-4,32:18.1
-3,-3,32:18.1
-2,-3,32:18.1
-1,-3,32:18.1
0,-3,32:17.13
1,-3,32:17.13
2,-3,32:18.1
3,-3,32:18.1
-3,-2,32:18.1
-2,-2,32:18.1
-1,-2,32:18.1
0,-2,32:17.13
1,-2,32:18.1
2,-2,32:18.1
3,-2,32:18.1
-3,-1,32:18.1
-2,-1,32:18.1
-1,-1,32:18.1
0,-1,32:18.1
1,-1,32:18.1
2,-1,32:18.1
3,-1,32:18.1
-2,0,32:18.1
-1,0,32:18.1
0,0,32:18.1
1,0,32:18.1
2,0,32:18.1
-1,1,32:18.1
0,1,32:18.1
1,1,32:18.1
-1,-7,33:18.1
0,-7,33:18.1
1,-7,33:18.1
-2,-6,33:18.1
-1,-6,33:18.1
0,-6,33:18.1
1,-6,33:18.1
2,-6,33:18.1
-3,-5,33:18.1
-2,-5,33:18.1
-1,-5,33:18.1
0,-5,33:18.1
1,-5,33:18.1
2,-5,33:18.1
3,-5,33:18.1
-3,-4,33:18.1
-2,-4,33:18.1
-1,-4,33:18.1
0,-4,33:17.13
1,-4,33:17.13
2,-4,33:18.1
3,-4,33:18.1
-3,-3,33:18.1
-2,-3,33:18.1
-1,-3,33:18.1
0,-3,33:17.13
1,-3,33:17.13
2,-3,33:18.1
3,-3,33:18.1
-3,-2,33:18.1
-2,-2,33:18.1
-1,-2,33:18.1
0,-2,33:18.1
1,-2,33:18.1
2,-2,33:18.1
3,-2,33:18.1
-2,-1,33:18.1
-1,-1,33:18.1
0,-1,33:18.1
1,-1,33:18.1
2,-1,33:18.1
-2,0,33:18.1
-1,0,33:18.1
0,0,33:18.1
1,0,33:18.1
2,0,33:18.1
0,1,33:18.1
0,-7,34:18.1
-2,-6,34:18.1
-1,-6,34:18.1
0,-6,34:18.1
1,-6,34:18.1
2,-6,34:18.1
-2,-5,34:18.1
-1,-5,34:18.1
0,-5,34:18.1
1,-5,34:18.1
2,-5,34:18.1
-3,-4,34:18.1
-2,-4,34:18.1
-1,-4,34:18.1
0,-4,34:18.1
1,-4,34:18.1
2,-4,34:18.1
3,-4,34:18.1
-2,-3,34:18.1
-1,-3,34:18.1
0,-3,34:18.1
1,-3,34:18.1
2,-3,34:18.1
-2,-2,34:18.1
-1,-2,34:18.1
0,-2,34:18.1
1,-2,34:18.1
2,-2,34:18.1
0,-1,34:18.1
0,-4,35:18.1
1,-4,35:18.1
0,-3,35:18.1
1,-3,35:18.1
