[META]
version=2.0
spawnOnBlockType=9
spawnSunlight=True
spawnDarkness=True
spawnWater=True
spawnLava=False
underFill=False
randomRotation=True
dig=True
tree=True
branch=False
needsFoundation=True
rarity=50
collisionPercentage=20
spawnElevationMin=0
spawnElevationMax=60
spawnInBiome=Custom
[DATA]
-2,-4,-8:17.13
-1,-4,-8:17.13
4,-2,-8:17.13
3,0,-8:17.13
-1,1,-8:17.13
-2,-4,-7:17.13
-1,-4,-7:17.13
4,-2,-7:17.13
3,0,-7:17.13
-1,1,-7:17.13
-2,-4,-6:17.13
-1,-4,-6:17.13
4,-2,-6:17.13
3,0,-6:17.13
-1,1,-6:17.13
-2,-4,-5:17.13
-1,-4,-5:17.13
4,-2,-5:17.13
3,0,-5:17.13
-1,1,-5:17.13
-2,-4,-4:17.13
-1,-4,-4:17.13
4,-2,-4:17.13
3,0,-4:17.13
-2,1,-4:17.13
-1,1,-4:17.13
1,-5,-3:17.13
-2,-4,-3:17.13
-1,-4,-3:17.13
4,-2,-3:17.13
3,0,-3:17.13
-2,1,-3:17.13
-1,1,-3:17.13
3,1,-3:17.13
1,-5,-2:17.13
-2,-4,-2:17.13
-1,-4,-2:17.13
4,-2,-2:17.13
3,0,-2:17.13
-2,1,-2:17.13
-1,1,-2:17.13
3,1,-2:17.13
1,-5,-1:17.13
-2,-4,-1:17.13
-1,-4,-1:17.13
4,-2,-1:17.13
3,0,-1:17.13
-2,1,-1:17.13
-1,1,-1:17.13
3,1,-1:17.13
1,-5,0:17.13
-2,-4,0:17.13
-1,-4,0:17.13
4,-2,0:17.13
3,0,0:17.13
-2,1,0:17.13
-1,1,0:17.13
3,1,0:17.13
1,-5,1:17.13
-2,-4,1:17.13
-1,-4,1:17.13
4,-2,1:17.13
3,0,1:17.13
-2,1,1:17.13
-1,1,1:17.13
3,1,1:17.13
1,-5,2:17.13
-2,-4,2:17.13
-1,-4,2:17.13
4,-2,2:17.13
3,0,2:17.13
-2,1,2:17.13
-1,1,2:17.13
3,1,2:17.13
1,-5,3:17.13
-2,-4,3:17.13
-1,-4,3:17.13
4,-2,3:17.13
3,0,3:17.13
-2,1,3:17.13
-1,1,3:17.13
3,1,3:17.13
1,-5,4:17.13
-2,-4,4:17.13
-1,-4,4:17.13
0,-2,4:3.0
1,-2,4:3.0
4,-2,4:17.13
0,-1,4:3.0
1,-1,4:3.0
3,0,4:17.13
-2,1,4:17.13
-1,1,4:17.13
3,1,4:17.13
-2,-4,5:17.13
-1,-4,5:17.13
0,-4,5:17.13
1,-4,5:17.13
2,-4,5:17.13
-2,-3,5:17.13
-1,-3,5:17.13
0,-3,5:17.13
1,-3,5:17.13
2,-3,5:17.13
3,-3,5:17.13
-2,-2,5:17.13
-1,-2,5:17.13
0,-2,5:17.13
1,-2,5:17.13
2,-2,5:17.13
3,-2,5:17.13
-2,-1,5:17.13
-1,-1,5:17.13
0,-1,5:17.13
1,-1,5:17.13
2,-1,5:17.13
3,-1,5:17.13
-2,0,5:17.13
-1,0,5:17.13
0,0,5:17.13
1,0,5:17.13
2,0,5:17.13
3,0,5:17.13
-2,1,5:17.13
-1,1,5:17.13
0,1,5:17.13
1,1,5:17.13
2,1,5:17.13
3,1,5:17.13
-2,-4,6:17.13
-1,-4,6:17.13
0,-4,6:17.13
1,-4,6:17.13
-1,-3,6:17.13
0,-3,6:17.13
1,-3,6:17.13
2,-3,6:17.13
-2,-2,6:17.13
-1,-2,6:17.13
0,-2,6:17.13
1,-2,6:17.13
2,-2,6:17.13
3,-2,6:17.13
-2,-1,6:17.13
-1,-1,6:17.13
0,-1,6:17.13
1,-1,6:17.13
2,-1,6:17.13
3,-1,6:17.13
-1,0,6:17.13
0,0,6:17.13
1,0,6:17.13
2,0,6:17.13
3,0,6:17.13
-2,1,6:17.13
-1,1,6:17.13
0,1,6:17.13
1,1,6:17.13
3,1,6:17.13
-1,-4,7:17.13
1,-4,7:17.13
-1,-3,7:17.13
0,-3,7:17.13
1,-3,7:17.13
2,-3,7:17.13
-1,-2,7:17.13
0,-2,7:17.13
1,-2,7:17.13
2,-2,7:17.13
3,-2,7:17.13
-1,-1,7:17.13
0,-1,7:17.13
1,-1,7:17.13
2,-1,7:17.13
-1,0,7:17.13
0,0,7:17.13
1,0,7:17.13
2,0,7:17.13
3,0,7:17.13
-1,1,7:17.13
-1,-4,8:17.13
1,-4,8:17.13
-1,-3,8:17.13
0,-3,8:17.13
1,-3,8:17.13
2,-3,8:17.13
-1,-2,8:17.13
0,-2,8:17.13
1,-2,8:17.13
2,-2,8:17.13
3,-2,8:17.13
-1,-1,8:17.13
0,-1,8:17.13
1,-1,8:17.13
2,-1,8:17.13
-1,0,8:17.13
0,0,8:17.13
1,0,8:17.13
2,0,8:17.13
3,0,8:17.13
-1,1,8:17.13
1,-4,9:17.13
-1,-3,9:17.13
0,-3,9:17.13
1,-3,9:17.13
-1,-2,9:17.13
0,-2,9:17.13
1,-2,9:17.13
2,-2,9:17.13
3,-2,9:17.13
-1,-1,9:17.13
0,-1,9:17.13
1,-1,9:17.13
2,-1,9:17.13
-1,0,9:17.13
0,0,9:17.13
1,0,9:17.13
2,0,9:17.13
-1,1,9:17.13
-1,-3,10:17.13
0,-3,10:17.13
1,-3,10:17.13
-1,-2,10:17.13
0,-2,10:17.13
1,-2,10:17.13
2,-2,10:17.13
-1,-1,10:17.13
0,-1,10:17.13
1,-1,10:17.13
2,-1,10:17.13
-1,0,10:17.13
0,0,10:17.13
1,0,10:17.13
2,0,10:17.13
0,-3,11:17.13
1,-3,11:17.13
-1,-2,11:17.13
0,-2,11:17.13
1,-2,11:17.13
2,-2,11:17.13
-1,-1,11:17.13
0,-1,11:17.13
1,-1,11:17.13
2,-1,11:17.13
0,0,11:17.13
1,0,11:17.13
0,-3,12:17.13
1,-3,12:17.13
-1,-2,12:17.13
0,-2,12:17.13
1,-2,12:17.13
2,-2,12:17.13
-1,-1,12:17.13
0,-1,12:17.13
1,-1,12:17.13
2,-1,12:17.13
0,0,12:17.13
1,0,12:17.13
0,-3,13:17.13
1,-3,13:17.13
-1,-2,13:17.13
0,-2,13:17.13
1,-2,13:17.13
2,-2,13:17.13
-1,-1,13:17.13
0,-1,13:17.13
1,-1,13:17.13
2,-1,13:17.13
0,0,13:17.13
1,0,13:17.13
0,-2,14:17.13
1,-2,14:17.13
0,-1,14:17.13
1,-1,14:17.13
0,-2,15:17.13
1,-2,15:17.13
0,-1,15:17.13
1,-1,15:17.13
0,-2,16:17.13
1,-2,16:17.13
0,-1,16:17.13
1,-1,16:17.13
0,-2,17:17.13
1,-2,17:17.13
0,-1,17:17.13
1,-1,17:17.13
0,0,17:17.13
0,-2,18:17.13
1,-2,18:17.13
0,-1,18:17.13
1,-1,18:17.13
0,1,18:17.13
6,1,18:18.1
7,1,18:18.1
8,1,18:18.1
1,2,18:17.13
2,2,18:17.13
5,2,18:18.1
6,2,18:18.1
7,2,18:18.1
8,2,18:18.1
9,2,18:18.1
1,3,18:17.13
3,3,18:17.13
4,3,18:17.13
5,3,18:17.13
6,3,18:17.13
7,3,18:18.1
8,3,18:18.1
9,3,18:18.1
10,3,18:18.1
1,4,18:17.13
2,4,18:18.1
3,4,18:18.1
4,4,18:18.1
5,4,18:18.1
6,4,18:18.1
7,4,18:17.13
8,4,18:18.1
9,4,18:18.1
10,4,18:18.1
-2,5,18:18.1
-1,5,18:18.1
0,5,18:17.13
1,5,18:18.1
2,5,18:17.13
3,5,18:17.13
4,5,18:18.1
5,5,18:18.1
6,5,18:18.1
7,5,18:18.1
8,5,18:18.1
9,5,18:18.1
10,5,18:18.1
-3,6,18:18.1
-2,6,18:18.1
-1,6,18:18.1
0,6,18:17.13
1,6,18:18.1
2,6,18:17.13
3,6,18:18.1
4,6,18:17.13
5,6,18:18.1
6,6,18:18.1
7,6,18:18.1
8,6,18:18.1
9,6,18:18.1
-4,7,18:18.1
-3,7,18:18.1
-2,7,18:18.1
-1,7,18:17.13
0,7,18:18.1
1,7,18:18.1
2,7,18:18.1
3,7,18:17.13
4,7,18:18.1
5,7,18:18.1
6,7,18:18.1
7,7,18:18.1
8,7,18:18.1
-4,8,18:18.1
-3,8,18:18.1
-2,8,18:18.1
-1,8,18:17.13
0,8,18:18.1
1,8,18:18.1
2,8,18:18.1
3,8,18:18.1
4,8,18:18.1
5,8,18:18.1
6,8,18:18.1
-4,9,18:18.1
-3,9,18:18.1
-2,9,18:18.1
-1,9,18:18.1
0,9,18:18.1
1,9,18:18.1
2,9,18:18.1
3,9,18:18.1
4,9,18:18.1
5,9,18:18.1
-3,10,18:18.1
-2,10,18:18.1
-1,10,18:18.1
0,10,18:18.1
1,10,18:18.1
2,10,18:18.1
3,10,18:18.1
4,10,18:18.1
-2,11,18:18.1
-1,11,18:18.1
0,11,18:18.1
-1,-2,19:17.13
0,-2,19:17.13
1,-2,19:17.13
0,-1,19:17.13
1,-1,19:17.13
7,1,19:18.1
5,2,19:18.1
6,2,19:18.1
7,2,19:18.1
8,2,19:18.1
9,2,19:18.1
4,3,19:18.1
5,3,19:18.1
6,3,19:18.1
7,3,19:18.1
8,3,19:18.1
9,3,19:18.1
2,4,19:18.1
3,4,19:18.1
4,4,19:18.1
5,4,19:18.1
6,4,19:18.1
7,4,19:18.1
8,4,19:18.1
9,4,19:18.1
10,4,19:18.1
-1,5,19:18.1
1,5,19:18.1
2,5,19:18.1
3,5,19:18.1
4,5,19:18.1
5,5,19:18.1
6,5,19:18.1
7,5,19:18.1
8,5,19:18.1
9,5,19:18.1
-3,6,19:18.1
-2,6,19:18.1
-1,6,19:18.1
0,6,19:18.1
1,6,19:18.1
2,6,19:18.1
3,6,19:18.1
4,6,19:18.1
5,6,19:18.1
6,6,19:18.1
7,6,19:18.1
8,6,19:18.1
9,6,19:18.1
-3,7,19:18.1
-2,7,19:18.1
-1,7,19:18.1
0,7,19:18.1
1,7,19:18.1
2,7,19:18.1
3,7,19:18.1
4,7,19:18.1
5,7,19:18.1
6,7,19:18.1
7,7,19:18.1
-4,8,19:18.1
-3,8,19:18.1
-2,8,19:18.1
-1,8,19:18.1
0,8,19:18.1
1,8,19:18.1
2,8,19:18.1
3,8,19:18.1
4,8,19:18.1
5,8,19:18.1
6,8,19:18.1
-3,9,19:18.1
-2,9,19:18.1
-1,9,19:18.1
0,9,19:18.1
1,9,19:18.1
2,9,19:18.1
3,9,19:18.1
4,9,19:18.1
5,9,19:18.1
-3,10,19:18.1
-2,10,19:18.1
-1,10,19:18.1
0,10,19:18.1
1,10,19:18.1
3,10,19:18.1
-1,11,19:18.1
-10,-7,20:18.1
-9,-7,20:18.1
-8,-7,20:18.1
-11,-6,20:18.1
-10,-6,20:18.1
-9,-6,20:18.1
-8,-6,20:18.1
-7,-6,20:18.1
-12,-5,20:18.1
-11,-5,20:18.1
-10,-5,20:18.1
-9,-5,20:18.1
-8,-5,20:18.1
-7,-5,20:18.1
-6,-5,20:18.1
-12,-4,20:18.1
-11,-4,20:18.1
-10,-4,20:18.1
-9,-4,20:17.13
-8,-4,20:18.1
-7,-4,20:18.1
-6,-4,20:18.1
-12,-3,20:18.1
-11,-3,20:18.1
-10,-3,20:18.1
-9,-3,20:18.1
-8,-3,20:17.13
-7,-3,20:17.13
-6,-3,20:18.1
-11,-2,20:18.1
-10,-2,20:18.1
-9,-2,20:18.1
-8,-2,20:18.1
-7,-2,20:18.1
-6,-2,20:17.13
-5,-2,20:17.13
-2,-2,20:17.13
0,-2,20:17.13
1,-2,20:17.13
-10,-1,20:18.1
-9,-1,20:18.1
-8,-1,20:18.1
-4,-1,20:17.13
-3,-1,20:17.13
0,-1,20:17.13
1,-1,20:17.13
-9,-7,21:18.1
-11,-6,21:18.1
-10,-6,21:18.1
-9,-6,21:18.1
-8,-6,21:18.1
-7,-6,21:18.1
-11,-5,21:18.1
-10,-5,21:18.1
-9,-5,21:18.1
-8,-5,21:18.1
-7,-5,21:18.1
-12,-4,21:18.1
-11,-4,21:18.1
-10,-4,21:18.1
-9,-4,21:18.1
-8,-4,21:18.1
-7,-4,21:18.1
-6,-4,21:18.1
-11,-3,21:18.1
-10,-3,21:18.1
-9,-3,21:18.1
-8,-3,21:18.1
-7,-3,21:18.1
0,-3,21:17.13
-11,-2,21:18.1
-10,-2,21:18.1
-9,-2,21:18.1
-8,-2,21:18.1
-7,-2,21:18.1
0,-2,21:17.13
1,-2,21:17.13
-9,-1,21:18.1
0,-1,21:17.13
1,-1,21:17.13
2,-1,21:17.13
3,-1,21:17.13
-8,0,21:18.1
-7,0,21:18.1
-6,0,21:18.1
-5,0,21:17.13
-4,0,21:17.13
3,0,21:17.13
-9,1,21:18.1
-8,1,21:18.1
-7,1,21:18.1
-6,1,21:17.13
-5,1,21:18.1
4,1,21:17.13
5,1,21:18.1
6,1,21:18.1
-10,2,21:18.1
-9,2,21:18.1
-8,2,21:18.1
-7,2,21:18.1
-6,2,21:17.13
-5,2,21:18.1
-4,2,21:18.1
3,2,21:18.1
4,2,21:17.13
5,2,21:18.1
6,2,21:18.1
7,2,21:18.1
-10,3,21:18.1
-9,3,21:18.1
-8,3,21:18.1
-7,3,21:17.13
-6,3,21:18.1
-5,3,21:18.1
-4,3,21:18.1
2,3,21:18.1
3,3,21:18.1
4,3,21:18.1
5,3,21:17.13
6,3,21:18.1
7,3,21:18.1
8,3,21:18.1
-10,4,21:18.1
-9,4,21:18.1
-8,4,21:18.1
-7,4,21:18.1
-6,4,21:18.1
-5,4,21:18.1
-4,4,21:18.1
2,4,21:18.1
3,4,21:18.1
4,4,21:18.1
5,4,21:17.13
6,4,21:18.1
7,4,21:18.1
8,4,21:18.1
-9,5,21:18.1
-8,5,21:18.1
-7,5,21:18.1
-6,5,21:18.1
-5,5,21:18.1
2,5,21:18.1
3,5,21:18.1
4,5,21:18.1
5,5,21:18.1
6,5,21:18.1
7,5,21:18.1
8,5,21:18.1
-8,6,21:18.1
-7,6,21:18.1
-6,6,21:18.1
3,6,21:18.1
4,6,21:18.1
5,6,21:18.1
6,6,21:18.1
7,6,21:18.1
4,7,21:18.1
5,7,21:18.1
6,7,21:18.1
-1,-4,22:17.13
0,-4,22:17.13
0,-2,22:17.13
1,-2,22:17.13
7,-2,22:18.1
8,-2,22:18.1
9,-2,22:18.1
0,-1,22:17.13
1,-1,22:17.13
6,-1,22:18.1
7,-1,22:18.1
8,-1,22:18.1
9,-1,22:18.1
10,-1,22:18.1
-7,0,22:18.1
4,0,22:17.13
5,0,22:17.13
6,0,22:17.13
7,0,22:18.1
8,0,22:18.1
9,0,22:18.1
10,0,22:18.1
11,0,22:18.1
-9,1,22:18.1
-8,1,22:18.1
-7,1,22:18.1
-6,1,22:18.1
-5,1,22:18.1
5,1,22:18.1
6,1,22:18.1
7,1,22:17.13
8,1,22:17.13
9,1,22:18.1
10,1,22:18.1
11,1,22:18.1
-9,2,22:18.1
-8,2,22:18.1
-7,2,22:18.1
-6,2,22:18.1
-5,2,22:18.1
3,2,22:18.1
4,2,22:18.1
5,2,22:18.1
6,2,22:18.1
7,2,22:18.1
8,2,22:18.1
9,2,22:18.1
10,2,22:18.1
11,2,22:18.1
-10,3,22:18.1
-9,3,22:18.1
-8,3,22:18.1
-7,3,22:18.1
-6,3,22:18.1
-5,3,22:18.1
-4,3,22:18.1
3,3,22:18.1
4,3,22:18.1
5,3,22:18.1
6,3,22:18.1
7,3,22:18.1
8,3,22:18.1
9,3,22:18.1
10,3,22:18.1
-9,4,22:18.1
-8,4,22:18.1
-7,4,22:18.1
-6,4,22:18.1
-5,4,22:18.1
2,4,22:18.1
3,4,22:18.1
4,4,22:18.1
5,4,22:18.1
6,4,22:18.1
7,4,22:18.1
8,4,22:18.1
9,4,22:18.1
-9,5,22:18.1
-8,5,22:18.1
-7,5,22:18.1
-6,5,22:18.1
-5,5,22:18.1
3,5,22:18.1
4,5,22:18.1
5,5,22:18.1
6,5,22:18.1
7,5,22:18.1
-7,6,22:18.1
3,6,22:18.1
4,6,22:18.1
5,6,22:18.1
6,6,22:18.1
7,6,22:18.1
5,7,22:18.1
-2,-12,23:18.1
-1,-12,23:18.1
0,-12,23:18.1
-3,-11,23:18.1
-2,-11,23:18.1
-1,-11,23:18.1
0,-11,23:18.1
1,-11,23:18.1
-4,-10,23:18.1
-3,-10,23:18.1
-2,-10,23:18.1
-1,-10,23:18.1
0,-10,23:18.1
1,-10,23:18.1
2,-10,23:18.1
-4,-9,23:18.1
-3,-9,23:18.1
-2,-9,23:18.1
-1,-9,23:17.13
0,-9,23:18.1
1,-9,23:18.1
2,-9,23:18.1
-4,-8,23:18.1
-3,-8,23:18.1
-2,-8,23:17.13
-1,-8,23:18.1
0,-8,23:18.1
1,-8,23:18.1
2,-8,23:18.1
-3,-7,23:18.1
-2,-7,23:18.1
-1,-7,23:17.13
0,-7,23:18.1
1,-7,23:18.1
-2,-6,23:18.1
-1,-6,23:17.13
0,-6,23:18.1
-1,-5,23:17.13
-6,-2,23:18.1
-5,-2,23:18.1
-4,-2,23:18.1
0,-2,23:17.13
1,-2,23:17.13
8,-2,23:18.1
-7,-1,23:18.1
-6,-1,23:18.1
-5,-1,23:18.1
-4,-1,23:18.1
-3,-1,23:18.1
0,-1,23:17.13
1,-1,23:17.13
6,-1,23:18.1
7,-1,23:18.1
8,-1,23:18.1
9,-1,23:18.1
10,-1,23:18.1
-8,0,23:18.1
-7,0,23:18.1
-6,0,23:18.1
-5,0,23:18.1
-4,0,23:18.1
-3,0,23:18.1
-2,0,23:18.1
-1,0,23:17.13
0,0,23:17.13
6,0,23:18.1
7,0,23:18.1
8,0,23:18.1
9,0,23:18.1
10,0,23:18.1
-8,1,23:18.1
-7,1,23:18.1
-6,1,23:18.1
-5,1,23:17.13
-4,1,23:17.13
-3,1,23:17.13
-2,1,23:17.13
-1,1,23:17.13
5,1,23:18.1
6,1,23:18.1
7,1,23:18.1
8,1,23:18.1
9,1,23:18.1
10,1,23:18.1
11,1,23:18.1
-8,2,23:18.1
-7,2,23:18.1
-6,2,23:18.1
-5,2,23:18.1
-4,2,23:18.1
-3,2,23:18.1
-2,2,23:18.1
6,2,23:18.1
7,2,23:18.1
8,2,23:18.1
9,2,23:18.1
10,2,23:18.1
-7,3,23:18.1
-6,3,23:18.1
-5,3,23:18.1
-4,3,23:18.1
-3,3,23:18.1
6,3,23:18.1
7,3,23:18.1
8,3,23:18.1
9,3,23:18.1
10,3,23:18.1
-6,4,23:18.1
-5,4,23:18.1
-4,4,23:18.1
8,4,23:18.1
-3,-12,24:18.1
-2,-12,24:18.1
-1,-12,24:18.1
-4,-11,24:18.1
-3,-11,24:18.1
-2,-11,24:18.1
-1,-11,24:18.1
0,-11,24:18.1
1,-11,24:18.1
-5,-10,24:18.1
-4,-10,24:18.1
-3,-10,24:18.1
-2,-10,24:18.1
-1,-10,24:18.1
0,-10,24:18.1
1,-10,24:18.1
-5,-9,24:18.1
-4,-9,24:18.1
-3,-9,24:18.1
-2,-9,24:17.13
-1,-9,24:18.1
0,-9,24:18.1
1,-9,24:18.1
2,-9,24:18.1
-5,-8,24:18.1
-4,-8,24:18.1
-3,-8,24:18.1
-2,-8,24:18.1
-1,-8,24:18.1
0,-8,24:18.1
1,-8,24:18.1
-4,-7,24:18.1
-3,-7,24:18.1
-2,-7,24:18.1
-1,-7,24:18.1
0,-7,24:18.1
1,-7,24:18.1
-3,-6,24:18.1
-2,-6,24:18.1
-1,-6,24:18.1
-5,-2,24:18.1
0,-2,24:17.13
1,-2,24:17.13
-7,-1,24:18.1
-6,-1,24:18.1
-5,-1,24:18.1
-4,-1,24:18.1
-3,-1,24:18.1
0,-1,24:17.13
1,-1,24:17.13
-7,0,24:18.1
-6,0,24:18.1
-5,0,24:18.1
-4,0,24:18.1
-3,0,24:18.1
-8,1,24:18.1
-7,1,24:18.1
-6,1,24:18.1
-5,1,24:18.1
-4,1,24:18.1
-3,1,24:18.1
-2,1,24:18.1
-1,1,24:18.1
-7,2,24:18.1
-6,2,24:18.1
-5,2,24:18.1
-4,2,24:18.1
-3,2,24:18.1
-2,2,24:18.1
-1,2,24:17.13
0,2,24:18.1
-7,3,24:18.1
-6,3,24:18.1
-5,3,24:18.1
-4,3,24:18.1
-3,3,24:18.1
-2,3,24:17.13
-1,3,24:18.1
0,3,24:18.1
1,3,24:18.1
-5,4,24:18.1
-4,4,24:18.1
-3,4,24:18.1
-2,4,24:17.13
-1,4,24:18.1
0,4,24:18.1
1,4,24:18.1
-5,5,24:18.1
-4,5,24:18.1
-3,5,24:18.1
-2,5,24:18.1
-1,5,24:18.1
0,5,24:18.1
1,5,24:18.1
-4,6,24:18.1
-3,6,24:18.1
-2,6,24:18.1
-1,6,24:18.1
0,6,24:18.1
-3,7,24:18.1
-2,7,24:18.1
-1,7,24:18.1
-2,-12,25:18.1
-4,-11,25:18.1
-3,-11,25:18.1
-2,-11,25:18.1
-1,-11,25:18.1
0,-11,25:18.1
-4,-10,25:18.1
-3,-10,25:18.1
-2,-10,25:18.1
-1,-10,25:18.1
0,-10,25:18.1
-5,-9,25:18.1
-4,-9,25:18.1
-3,-9,25:18.1
-2,-9,25:18.1
-1,-9,25:18.1
0,-9,25:18.1
1,-9,25:18.1
-4,-8,25:18.1
-3,-8,25:18.1
-2,-8,25:18.1
-1,-8,25:18.1
0,-8,25:18.1
-4,-7,25:18.1
-3,-7,25:18.1
-2,-7,25:18.1
-1,-7,25:18.1
0,-7,25:18.1
-2,-6,25:18.1
0,-2,25:17.13
1,-2,25:17.13
0,-1,25:17.13
1,-1,25:17.13
-2,1,25:18.1
-4,2,25:18.1
-3,2,25:18.1
-2,2,25:18.1
-1,2,25:18.1
0,2,25:18.1
-4,3,25:18.1
-3,3,25:18.1
-2,3,25:18.1
-1,3,25:18.1
0,3,25:18.1
-5,4,25:18.1
-4,4,25:18.1
-3,4,25:18.1
-2,4,25:18.1
-1,4,25:18.1
0,4,25:18.1
1,4,25:18.1
-4,5,25:18.1
-3,5,25:18.1
-2,5,25:18.1
-1,5,25:18.1
0,5,25:18.1
-4,6,25:18.1
-3,6,25:18.1
-2,6,25:18.1
-1,6,25:18.1
0,6,25:18.1
-2,7,25:18.1
0,-2,26:17.13
1,-2,26:17.13
0,-1,26:17.13
1,-1,26:17.13
-1,-2,27:17.13
0,-2,27:17.13
1,-2,27:17.13
0,-1,27:17.13
1,-1,27:17.13
0,-2,28:17.13
1,-2,28:17.13
-1,-1,28:17.13
0,-1,28:17.13
1,-1,28:17.13
-2,0,28:17.13
3,-6,29:18.1
4,-6,29:18.1
5,-6,29:18.1
2,-5,29:18.1
3,-5,29:18.1
4,-5,29:18.1
5,-5,29:18.1
6,-5,29:18.1
1,-4,29:18.1
2,-4,29:18.1
3,-4,29:18.1
4,-4,29:18.1
5,-4,29:18.1
6,-4,29:18.1
7,-4,29:18.1
-3,-3,29:18.1
-2,-3,29:18.1
-1,-3,29:18.1
1,-3,29:18.1
2,-3,29:18.1
3,-3,29:17.13
4,-3,29:17.13
5,-3,29:18.1
6,-3,29:18.1
7,-3,29:18.1
-4,-2,29:18.1
-3,-2,29:18.1
-2,-2,29:18.1
-1,-2,29:18.1
0,-2,29:17.13
1,-2,29:17.13
2,-2,29:17.13
3,-2,29:17.13
4,-2,29:17.13
5,-2,29:18.1
6,-2,29:18.1
7,-2,29:18.1
-5,-1,29:18.1
-4,-1,29:18.1
-3,-1,29:18.1
-2,-1,29:18.1
-1,-1,29:18.1
0,-1,29:17.13
1,-1,29:17.13
2,-1,29:18.1
3,-1,29:18.1
4,-1,29:18.1
5,-1,29:18.1
6,-1,29:18.1
7,-1,29:18.1
-5,0,29:18.1
-4,0,29:18.1
-3,0,29:18.1
-2,0,29:17.13
-1,0,29:18.1
0,0,29:18.1
1,0,29:18.1
2,0,29:18.1
3,0,29:18.1
4,0,29:18.1
5,0,29:18.1
6,0,29:18.1
-5,1,29:18.1
-4,1,29:18.1
-3,1,29:18.1
-2,1,29:18.1
-1,1,29:18.1
0,1,29:18.1
1,1,29:18.1
3,1,29:18.1
4,1,29:18.1
5,1,29:18.1
-4,2,29:18.1
-3,2,29:18.1
-2,2,29:18.1
-1,2,29:18.1
0,2,29:18.1
-3,3,29:18.1
-2,3,29:18.1
-1,3,29:18.1
4,-6,30:18.1
2,-5,30:18.1
3,-5,30:18.1
4,-5,30:18.1
5,-5,30:18.1
6,-5,30:18.1
2,-4,30:18.1
3,-4,30:18.1
4,-4,30:18.1
5,-4,30:18.1
6,-4,30:18.1
-2,-3,30:18.1
1,-3,30:18.1
2,-3,30:18.1
3,-3,30:18.1
4,-3,30:18.1
5,-3,30:18.1
6,-3,30:18.1
7,-3,30:18.1
-4,-2,30:18.1
-3,-2,30:18.1
-2,-2,30:18.1
-1,-2,30:18.1
0,-2,30:17.13
1,-2,30:17.13
2,-2,30:18.1
3,-2,30:18.1
4,-2,30:18.1
5,-2,30:18.1
6,-2,30:18.1
7,-2,30:18.1
-4,-1,30:18.1
-3,-1,30:18.1
-2,-1,30:18.1
-1,-1,30:18.1
0,-1,30:17.13
1,-1,30:17.13
2,-1,30:18.1
3,-1,30:18.1
4,-1,30:18.1
5,-1,30:18.1
6,-1,30:18.1
-5,0,30:18.1
-4,0,30:18.1
-3,0,30:18.1
-2,0,30:18.1
-1,0,30:18.1
0,0,30:18.1
1,0,30:18.1
2,0,30:18.1
3,0,30:18.1
4,0,30:18.1
5,0,30:18.1
6,0,30:18.1
-4,1,30:18.1
-3,1,30:18.1
-2,1,30:18.1
-1,1,30:18.1
0,1,30:18.1
4,1,30:18.1
-4,2,30:18.1
-3,2,30:18.1
-2,2,30:18.1
-1,2,30:18.1
0,2,30:18.1
-2,3,30:18.1
-1,-3,31:18.1
0,-3,31:18.1
1,-3,31:17.13
-2,-2,31:18.1
-1,-2,31:18.1
0,-2,31:17.13
1,-2,31:17.13
2,-2,31:18.1
-3,-1,31:18.1
-2,-1,31:18.1
-1,-1,31:18.1
0,-1,31:17.13
1,-1,31:17.13
2,-1,31:18.1
3,-1,31:18.1
-3,0,31:18.1
-2,0,31:18.1
-1,0,31:18.1
0,0,31:17.13
1,0,31:18.1
2,0,31:18.1
3,0,31:18.1
-3,1,31:18.1
-2,1,31:18.1
-1,1,31:18.1
0,1,31:18.1
1,1,31:18.1
2,1,31:18.1
3,1,31:18.1
-2,2,31:18.1
-1,2,31:18.1
0,2,31:18.1
1,2,31:18.1
2,2,31:18.1
-1,3,31:18.1
0,3,31:18.1
1,3,31:18.1
0,-6,32:18.1
1,-6,32:18.1
2,-6,32:18.1
-1,-5,32:18.1
0,-5,32:18.1
1,-5,32:18.1
2,-5,32:18.1
3,-5,32:18.1
-2,-4,32:18.1
-1,-4,32:18.1
0,-4,32:18.1
1,-4,32:18.1
2,-4,32:18.1
3,-4,32:18.1
4,-4,32:18.1
-2,-3,32:18.1
-1,-3,32:18.1
0,-3,32:18.1
1,-3,32:17.13
2,-3,32:18.1
3,-3,32:18.1
4,-3,32:18.1
-2,-2,32:18.1
-1,-2,32:18.1
0,-2,32:17.13
1,-2,32:17.13
2,-2,32:18.1
3,-2,32:18.1
4,-2,32:18.1
-2,-1,32:18.1
-1,-1,32:18.1
0,-1,32:17.13
1,-1,32:17.13
2,-1,32:18.1
3,-1,32:18.1
-3,0,32:18.1
-2,0,32:18.1
-1,0,32:18.1
0,0,32:18.1
1,0,32:18.1
2,0,32:18.1
3,0,32:18.1
-2,1,32:18.1
-1,1,32:18.1
0,1,32:18.1
1,1,32:18.1
2,1,32:18.1
-2,2,32:18.1
-1,2,32:18.1
0,2,32:18.1
1,2,32:18.1
2,2,32:18.1
0,3,32:18.1
1,-6,33:18.1
-1,-5,33:18.1
0,-5,33:18.1
1,-5,33:18.1
2,-5,33:18.1
3,-5,33:18.1
-2,-4,33:18.1
-1,-4,33:18.1
0,-4,33:18.1
1,-4,33:18.1
2,-4,33:18.1
3,-4,33:18.1
-3,-3,33:18.1
-2,-3,33:18.1
-1,-3,33:18.1
0,-3,33:18.1
1,-3,33:18.1
2,-3,33:18.1
3,-3,33:18.1
4,-3,33:18.1
-3,-2,33:18.1
-2,-2,33:18.1
-1,-2,33:18.1
0,-2,33:17.13
1,-2,33:17.13
2,-2,33:18.1
3,-2,33:18.1
4,-2,33:18.1
-3,-1,33:18.1
-2,-1,33:18.1
-1,-1,33:18.1
0,-1,33:17.13
1,-1,33:17.13
2,-1,33:18.1
3,-1,33:18.1
4,-1,33:18.1
-2,0,33:18.1
-1,0,33:18.1
0,0,33:18.1
1,0,33:18.1
2,0,33:18.1
3,0,33:18.1
-1,1,33:18.1
0,1,33:18.1
1,1,33:18.1
2,1,33:18.1
0,-5,34:18.1
1,-5,34:18.1
-2,-4,34:18.1
-1,-4,34:18.1
0,-4,34:18.1
1,-4,34:18.1
2,-4,34:18.1
3,-4,34:18.1
-2,-3,34:18.1
-1,-3,34:18.1
0,-3,34:18.1
1,-3,34:18.1
2,-3,34:18.1
3,-3,34:18.1
-3,-2,34:18.1
-2,-2,34:18.1
-1,-2,34:18.1
0,-2,34:18.1
1,-2,34:18.1
2,-2,34:18.1
3,-2,34:18.1
4,-2,34:18.1
-2,-1,34:18.1
-1,-1,34:18.1
0,-1,34:18.1
1,-1,34:18.1
2,-1,34:18.1
3,-1,34:18.1
-2,0,34:18.1
-1,0,34:18.1
0,0,34:18.1
1,0,34:18.1
2,0,34:18.1
3,0,34:18.1
0,1,34:18.1
1,1,34:18.1
0,-2,35:18.1
1,-2,35:18.1
0,-1,35:18.1
1,-1,35:18.1
