[META]
version=2.0
spawnOnBlockType=2
spawnSunlight=True
spawnDarkness=True
spawnWater=False
spawnLava=False
underFill=False
randomRotation=True
dig=True
tree=True
branch=False
needsFoundation=True
rarity=30
collisionPercentage=60
spawnElevationMin=0
spawnElevationMax=230
spawnInBiome=Custom
[DATA]
0,0,-1:17.1
0,-1,0:18.1
-1,0,0:18.1
0,0,0:17.1
1,0,0:18.1
0,1,0:18.1
0,-2,1:18.1
-1,-1,1:18.1
0,-1,1:18.1
1,-1,1:18.1
-2,0,1:18.1
-1,0,1:18.1
0,0,1:17.1
1,0,1:18.1
2,0,1:18.1
-1,1,1:18.1
0,1,1:18.1
1,1,1:18.1
0,2,1:18.1
-1,-2,2:18.1
0,-2,2:18.1
1,-2,2:18.1
-2,-1,2:18.1
-1,-1,2:18.1
0,-1,2:18.1
1,-1,2:18.1
2,-1,2:18.1
-2,0,2:18.1
-1,0,2:18.1
0,0,2:17.1
1,0,2:18.1
2,0,2:18.1
-2,1,2:18.1
-1,1,2:18.1
0,1,2:18.1
1,1,2:18.1
2,1,2:18.1
-1,2,2:18.1
0,2,2:18.1
1,2,2:18.1
0,-2,3:18.1
-1,-1,3:18.1
0,-1,3:18.1
1,-1,3:18.1
-2,0,3:18.1
-1,0,3:18.1
0,0,3:17.1
1,0,3:18.1
2,0,3:18.1
-1,1,3:18.1
0,1,3:18.1
1,1,3:18.1
0,2,3:18.1
0,-1,4:18.1
-1,0,4:18.1
0,0,4:17.1
1,0,4:18.1
0,1,4:18.1
0,-1,5:18.1
-1,0,5:18.1
0,0,5:17.1
1,0,5:18.1
0,1,5:18.1
0,0,6:18.1
0,0,7:18.1
