[META]
version=2.0
spawnOnBlockType=9
spawnSunlight=True
spawnDarkness=True
spawnWater=True
spawnLava=False
underFill=False
randomRotation=True
dig=True
tree=True
branch=False
needsFoundation=True
rarity=50
collisionPercentage=20
spawnElevationMin=0
spawnElevationMax=60
spawnInBiome=Custom
[DATA]
-5,2,-8:17.13
-6,4,-8:17.13
-6,5,-8:17.13
0,7,-8:17.13
-5,2,-7:17.13
-6,4,-7:17.13
-6,5,-7:17.13
0,7,-7:17.13
-5,2,-6:17.13
-6,4,-6:17.13
-6,5,-6:17.13
0,7,-6:17.13
-5,2,-5:17.13
-6,4,-5:17.13
-6,5,-5:17.13
0,7,-5:17.13
-2,8,-5:17.13
-2,1,-4:17.13
-5,2,-4:17.13
-6,4,-4:17.13
-6,5,-4:17.13
-4,6,-4:17.13
0,7,-4:17.13
-2,8,-4:17.13
-2,1,-3:17.13
-5,2,-3:17.13
0,2,-3:17.13
-6,4,-3:17.13
-6,5,-3:17.13
-4,6,-3:17.13
0,7,-3:17.13
-2,8,-3:17.13
-2,1,-2:17.13
-5,2,-2:17.13
0,2,-2:17.13
-6,4,-2:17.13
-6,5,-2:17.13
-4,6,-2:17.13
0,7,-2:17.13
-2,8,-2:17.13
-2,1,-1:17.13
-5,2,-1:17.13
0,2,-1:17.13
-6,4,-1:17.13
-6,5,-1:17.13
-4,6,-1:17.13
0,7,-1:17.13
-2,8,-1:17.13
-2,1,0:17.13
-5,2,0:17.13
0,2,0:17.13
-6,4,0:17.13
-6,5,0:17.13
-4,6,0:17.13
0,7,0:17.13
-2,8,0:17.13
-2,1,1:17.13
-5,2,1:17.13
0,3,1:17.13
-6,4,1:17.13
-6,5,1:17.13
-4,6,1:17.13
0,7,1:17.13
-2,8,1:17.13
-2,1,2:17.13
-5,2,2:17.13
0,3,2:17.13
-6,4,2:17.13
-6,5,2:17.13
-4,6,2:17.13
0,7,2:17.13
-2,8,2:17.13
-2,1,3:17.13
-5,2,3:17.13
0,3,3:17.13
-6,4,3:17.13
-6,5,3:17.13
-4,6,3:17.13
0,7,3:17.13
-2,8,3:17.13
-2,1,4:17.13
-5,2,4:17.13
0,3,4:17.13
-6,4,4:17.13
-6,5,4:17.13
-4,6,4:17.13
-2,7,4:17.13
0,7,4:17.13
-2,1,5:17.13
-4,2,5:17.13
-3,2,5:17.13
-2,2,5:17.13
-1,2,5:17.13
-5,3,5:17.13
-4,3,5:17.13
-3,3,5:17.13
-2,3,5:17.13
-1,3,5:17.13
0,3,5:17.13
-6,4,5:17.13
-5,4,5:17.13
-4,4,5:17.13
-3,4,5:17.13
-2,4,5:17.13
-1,4,5:17.13
0,4,5:17.13
-6,5,5:17.13
-5,5,5:17.13
-4,5,5:17.13
-3,5,5:17.13
-2,5,5:17.13
-1,5,5:17.13
0,5,5:17.13
-5,6,5:17.13
-4,6,5:17.13
-3,6,5:17.13
-2,6,5:17.13
-1,6,5:17.13
0,6,5:17.13
-4,7,5:17.13
-3,7,5:17.13
-2,7,5:17.13
-1,7,5:17.13
-3,2,6:17.13
-2,2,6:17.13
-5,3,6:17.13
-4,3,6:17.13
-3,3,6:17.13
-2,3,6:17.13
-1,3,6:17.13
0,3,6:17.13
-5,4,6:17.13
-4,4,6:17.13
-3,4,6:17.13
-2,4,6:17.13
-1,4,6:17.13
0,4,6:17.13
-5,5,6:17.13
-4,5,6:17.13
-3,5,6:17.13
-2,5,6:17.13
-1,5,6:17.13
0,5,6:17.13
-4,6,6:17.13
-3,6,6:17.13
-2,6,6:17.13
-1,6,6:17.13
0,6,6:17.13
-3,7,6:17.13
-2,7,6:17.13
-2,2,7:17.13
-5,3,7:17.13
-4,3,7:17.13
-3,3,7:17.13
-2,3,7:17.13
-1,3,7:17.13
0,3,7:17.13
-5,4,7:17.13
-4,4,7:17.13
-3,4,7:17.13
-2,4,7:17.13
-1,4,7:17.13
-5,5,7:17.13
-4,5,7:17.13
-3,5,7:17.13
-2,5,7:17.13
-1,5,7:17.13
-4,6,7:17.13
-3,6,7:17.13
-2,6,7:17.13
-1,6,7:17.13
0,6,7:17.13
-2,7,7:17.13
-2,2,8:17.13
-5,3,8:17.13
-4,3,8:17.13
-3,3,8:17.13
-2,3,8:17.13
-1,3,8:17.13
-5,4,8:17.13
-4,4,8:17.13
-3,4,8:17.13
-2,4,8:17.13
-1,4,8:17.13
-5,5,8:17.13
-4,5,8:17.13
-3,5,8:17.13
-2,5,8:17.13
-1,5,8:17.13
-4,6,8:17.13
-3,6,8:17.13
-2,6,8:17.13
-1,6,8:17.13
-2,7,8:17.13
-2,2,9:17.13
-4,3,9:17.13
-3,3,9:17.13
-2,3,9:17.13
-1,3,9:17.13
-5,4,9:17.13
-4,4,9:17.13
-3,4,9:17.13
-2,4,9:17.13
-1,4,9:17.13
-5,5,9:17.13
-4,5,9:17.13
-3,5,9:17.13
-2,5,9:17.13
-1,5,9:17.13
-3,6,9:17.13
-2,6,9:17.13
-1,6,9:17.13
-2,7,9:17.13
-4,3,10:17.13
-3,3,10:17.13
-2,3,10:17.13
-1,3,10:17.13
-4,4,10:17.13
-3,4,10:17.13
-2,4,10:17.13
-1,4,10:17.13
-4,5,10:17.13
-3,5,10:17.13
-2,5,10:17.13
-1,5,10:17.13
-3,6,10:17.13
-2,6,10:17.13
-1,6,10:17.13
-3,3,11:17.13
-2,3,11:17.13
-4,4,11:17.13
-3,4,11:17.13
-2,4,11:17.13
-1,4,11:17.13
-4,5,11:17.13
-3,5,11:17.13
-2,5,11:17.13
-1,5,11:17.13
-3,6,11:17.13
-2,6,11:17.13
-3,3,12:17.13
-2,3,12:17.13
-4,4,12:17.13
-3,4,12:17.13
-2,4,12:17.13
-1,4,12:17.13
-4,5,12:17.13
-3,5,12:17.13
-2,5,12:17.13
-1,5,12:17.13
-3,6,12:17.13
-2,6,12:17.13
-3,3,13:17.13
-2,3,13:17.13
-4,4,13:17.13
-3,4,13:17.13
-2,4,13:17.13
-1,4,13:17.13
-4,5,13:17.13
-3,5,13:17.13
-2,5,13:17.13
-1,5,13:17.13
-3,6,13:17.13
-2,6,13:17.13
-3,4,14:17.13
-2,4,14:17.13
-3,5,14:17.13
-2,5,14:17.13
-3,4,15:17.13
-2,4,15:17.13
-3,5,15:17.13
-2,5,15:17.13
-3,2,16:17.13
-3,3,16:17.13
-3,4,16:17.13
-2,4,16:17.13
-3,5,16:17.13
-2,5,16:17.13
-6,-7,17:18.1
-5,-7,17:18.1
-4,-7,17:18.1
-7,-6,17:18.1
-6,-6,17:18.1
-5,-6,17:18.1
-4,-6,17:18.1
-3,-6,17:18.1
-8,-5,17:18.1
-7,-5,17:18.1
-6,-5,17:18.1
-5,-5,17:18.1
-4,-5,17:18.1
-3,-5,17:18.1
-2,-5,17:18.1
-1,-5,17:18.1
0,-5,17:18.1
1,-5,17:18.1
-8,-4,17:18.1
-7,-4,17:18.1
-6,-4,17:18.1
-5,-4,17:17.13
-4,-4,17:18.1
-3,-4,17:18.1
-2,-4,17:18.1
-1,-4,17:18.1
0,-4,17:18.1
1,-4,17:18.1
2,-4,17:18.1
-8,-3,17:18.1
-7,-3,17:18.1
-6,-3,17:18.1
-5,-3,17:17.13
-4,-3,17:18.1
-3,-3,17:18.1
-2,-3,17:18.1
-1,-3,17:18.1
0,-3,17:18.1
1,-3,17:18.1
2,-3,17:18.1
3,-3,17:18.1
-7,-2,17:18.1
-6,-2,17:18.1
-5,-2,17:18.1
-4,-2,17:17.13
-3,-2,17:18.1
-2,-2,17:18.1
-1,-2,17:17.13
0,-2,17:17.13
1,-2,17:18.1
2,-2,17:18.1
3,-2,17:18.1
-6,-1,17:18.1
-5,-1,17:18.1
-4,-1,17:17.13
-3,-1,17:17.13
-2,-1,17:17.13
-1,-1,17:18.1
0,-1,17:18.1
1,-1,17:18.1
2,-1,17:18.1
3,-1,17:18.1
-3,0,17:17.13
-2,0,17:18.1
-1,0,17:18.1
0,0,17:18.1
1,0,17:18.1
2,0,17:18.1
-3,1,17:17.13
-1,1,17:18.1
0,1,17:18.1
1,1,17:18.1
-3,4,17:17.13
-2,4,17:17.13
-3,5,17:17.13
-2,5,17:17.13
-5,-7,18:18.1
-3,-7,18:18.1
-2,-7,18:18.1
-1,-7,18:18.1
-7,-6,18:18.1
-6,-6,18:18.1
-5,-6,18:18.1
-4,-6,18:18.1
-3,-6,18:18.1
-2,-6,18:18.1
-1,-6,18:18.1
0,-6,18:18.1
-7,-5,18:18.1
-6,-5,18:18.1
-5,-5,18:18.1
-4,-5,18:18.1
-3,-5,18:18.1
-2,-5,18:18.1
-1,-5,18:18.1
0,-5,18:18.1
1,-5,18:18.1
-8,-4,18:18.1
-7,-4,18:18.1
-6,-4,18:18.1
-5,-4,18:18.1
-4,-4,18:18.1
-3,-4,18:18.1
-2,-4,18:17.13
-1,-4,18:18.1
0,-4,18:18.1
1,-4,18:18.1
2,-4,18:18.1
-7,-3,18:18.1
-6,-3,18:18.1
-5,-3,18:18.1
-4,-3,18:18.1
-3,-3,18:18.1
-2,-3,18:17.13
-1,-3,18:18.1
0,-3,18:18.1
1,-3,18:18.1
2,-3,18:18.1
-7,-2,18:18.1
-6,-2,18:18.1
-5,-2,18:18.1
-4,-2,18:18.1
-3,-2,18:17.13
-2,-2,18:18.1
-1,-2,18:18.1
0,-2,18:18.1
1,-2,18:18.1
2,-2,18:18.1
3,-2,18:18.1
-5,-1,18:18.1
-3,-1,18:18.1
-2,-1,18:18.1
-1,-1,18:18.1
0,-1,18:18.1
1,-1,18:18.1
2,-1,18:18.1
-2,0,18:18.1
-1,0,18:18.1
0,0,18:18.1
1,0,18:18.1
2,0,18:18.1
0,1,18:18.1
-3,4,18:17.13
-2,4,18:17.13
-3,5,18:17.13
-2,5,18:17.13
-2,-7,19:18.1
-4,-6,19:18.1
-3,-6,19:18.1
-2,-6,19:18.1
-1,-6,19:18.1
0,-6,19:18.1
-4,-5,19:18.1
-3,-5,19:18.1
-2,-5,19:18.1
-1,-5,19:18.1
0,-5,19:18.1
-5,-4,19:18.1
-4,-4,19:18.1
-3,-4,19:18.1
-2,-4,19:18.1
-1,-4,19:18.1
0,-4,19:18.1
1,-4,19:18.1
-4,-3,19:18.1
-3,-3,19:18.1
-2,-3,19:18.1
-1,-3,19:18.1
0,-3,19:18.1
-4,-2,19:18.1
-3,-2,19:18.1
-2,-2,19:18.1
-1,-2,19:18.1
0,-2,19:18.1
-2,-1,19:18.1
-3,4,19:17.13
-2,4,19:17.13
-3,5,19:17.13
-2,5,19:17.13
-3,4,20:17.13
-2,4,20:17.13
-3,5,20:17.13
-2,5,20:17.13
-3,4,21:17.13
-2,4,21:17.13
-3,5,21:17.13
-2,5,21:17.13
-3,4,22:17.13
-2,4,22:17.13
-3,5,22:17.13
-2,5,22:17.13
-3,4,23:17.13
-2,4,23:17.13
-3,5,23:17.13
-2,5,23:17.13
-7,-2,24:18.1
-6,-2,24:18.1
-5,-2,24:18.1
-8,-1,24:18.1
-7,-1,24:18.1
-6,-1,24:18.1
-5,-1,24:18.1
-4,-1,24:18.1
-9,0,24:18.1
-8,0,24:18.1
-7,0,24:18.1
-6,0,24:18.1
-5,0,24:18.1
-4,0,24:18.1
-3,0,24:18.1
-9,1,24:18.1
-8,1,24:18.1
-7,1,24:18.1
-6,1,24:17.13
-5,1,24:17.13
-4,1,24:18.1
-3,1,24:18.1
-9,2,24:18.1
-8,2,24:18.1
-7,2,24:18.1
-6,2,24:18.1
-5,2,24:17.13
-4,2,24:17.13
-3,2,24:18.1
-8,3,24:18.1
-7,3,24:18.1
-6,3,24:18.1
-5,3,24:18.1
-4,3,24:18.1
-3,3,24:17.13
-7,4,24:18.1
-6,4,24:18.1
-5,4,24:18.1
-3,4,24:17.13
-2,4,24:17.13
-3,5,24:17.13
-2,5,24:17.13
-3,6,24:17.13
-6,-3,25:18.1
-5,-3,25:18.1
-4,-3,25:18.1
-7,-2,25:18.1
-6,-2,25:18.1
-5,-2,25:18.1
-4,-2,25:18.1
-3,-2,25:18.1
-8,-1,25:18.1
-7,-1,25:18.1
-6,-1,25:18.1
-5,-1,25:18.1
-4,-1,25:18.1
-3,-1,25:18.1
-2,-1,25:18.1
-1,-1,25:18.1
-8,0,25:18.1
-7,0,25:18.1
-6,0,25:18.1
-5,0,25:17.13
-4,0,25:18.1
-3,0,25:18.1
-2,0,25:18.1
-1,0,25:18.1
0,0,25:18.1
-9,1,25:18.1
-8,1,25:18.1
-7,1,25:18.1
-6,1,25:18.1
-5,1,25:18.1
-4,1,25:18.1
-3,1,25:18.1
-2,1,25:18.1
-1,1,25:18.1
0,1,25:18.1
1,1,25:18.1
-8,2,25:18.1
-7,2,25:18.1
-6,2,25:18.1
-5,2,25:18.1
-4,2,25:18.1
-3,2,25:18.1
-2,2,25:17.13
-1,2,25:18.1
0,2,25:18.1
1,2,25:18.1
-8,3,25:18.1
-7,3,25:18.1
-6,3,25:18.1
-5,3,25:18.1
-4,3,25:18.1
-3,3,25:18.1
-2,3,25:17.13
-1,3,25:18.1
0,3,25:18.1
1,3,25:18.1
-6,4,25:18.1
-4,4,25:18.1
-3,4,25:17.13
-2,4,25:17.13
-1,4,25:18.1
0,4,25:18.1
-3,5,25:17.13
-2,5,25:17.13
-1,5,25:18.1
-3,7,25:17.13
-2,7,25:18.1
-1,7,25:18.1
-4,8,25:17.13
-3,8,25:17.13
-2,8,25:18.1
-1,8,25:18.1
0,8,25:18.1
-5,9,25:18.1
-4,9,25:17.13
-3,9,25:18.1
-2,9,25:17.13
-1,9,25:18.1
0,9,25:18.1
1,9,25:18.1
-5,10,25:18.1
-4,10,25:18.1
-3,10,25:18.1
-2,10,25:17.13
-1,10,25:18.1
0,10,25:18.1
1,10,25:18.1
-5,11,25:18.1
-4,11,25:18.1
-3,11,25:18.1
-2,11,25:18.1
-1,11,25:18.1
0,11,25:18.1
1,11,25:18.1
-4,12,25:18.1
-3,12,25:18.1
-2,12,25:18.1
-1,12,25:18.1
0,12,25:18.1
-3,13,25:18.1
-2,13,25:18.1
-1,13,25:18.1
-5,-3,26:18.1
-7,-2,26:18.1
-6,-2,26:18.1
-5,-2,26:18.1
-4,-2,26:18.1
-3,-2,26:18.1
-7,-1,26:18.1
-6,-1,26:18.1
-5,-1,26:18.1
-4,-1,26:18.1
-3,-1,26:18.1
-2,-1,26:18.1
-8,0,26:18.1
-7,0,26:18.1
-6,0,26:18.1
-5,0,26:18.1
-4,0,26:18.1
-3,0,26:18.1
-2,0,26:18.1
-1,0,26:18.1
0,0,26:18.1
-7,1,26:18.1
-6,1,26:18.1
-5,1,26:18.1
-4,1,26:18.1
-3,1,26:18.1
-2,1,26:18.1
-1,1,26:18.1
0,1,26:18.1
1,1,26:18.1
-7,2,26:18.1
-6,2,26:18.1
-5,2,26:18.1
-4,2,26:18.1
-3,2,26:18.1
-2,2,26:18.1
-1,2,26:18.1
0,2,26:18.1
1,2,26:18.1
2,2,26:18.1
-5,3,26:18.1
-4,3,26:18.1
-3,3,26:18.1
-2,3,26:18.1
-1,3,26:18.1
0,3,26:18.1
1,3,26:18.1
2,3,26:18.1
3,3,26:18.1
-4,4,26:18.1
-3,4,26:17.13
-2,4,26:17.13
-1,4,26:17.13
0,4,26:17.13
1,4,26:18.1
2,4,26:18.1
3,4,26:18.1
-4,5,26:17.13
-3,5,26:17.13
-2,5,26:17.13
-1,5,26:18.1
0,5,26:18.1
1,5,26:18.1
2,5,26:18.1
3,5,26:18.1
-5,6,26:18.1
-4,6,26:18.1
-3,6,26:18.1
-2,6,26:18.1
-1,6,26:18.1
0,6,26:18.1
1,6,26:18.1
2,6,26:18.1
-6,7,26:18.1
-5,7,26:18.1
-4,7,26:18.1
-3,7,26:18.1
-2,7,26:18.1
-1,7,26:18.1
0,7,26:18.1
1,7,26:18.1
-7,8,26:18.1
-6,8,26:18.1
-5,8,26:18.1
-4,8,26:18.1
-3,8,26:18.1
-2,8,26:18.1
-1,8,26:18.1
0,8,26:18.1
-7,9,26:18.1
-6,9,26:18.1
-5,9,26:18.1
-4,9,26:17.13
-3,9,26:18.1
-2,9,26:18.1
-1,9,26:18.1
0,9,26:18.1
-7,10,26:18.1
-6,10,26:18.1
-5,10,26:18.1
-4,10,26:18.1
-3,10,26:18.1
-2,10,26:18.1
-1,10,26:18.1
0,10,26:18.1
1,10,26:18.1
-6,11,26:18.1
-5,11,26:18.1
-4,11,26:18.1
-3,11,26:18.1
-2,11,26:18.1
-1,11,26:18.1
0,11,26:18.1
-5,12,26:18.1
-4,12,26:18.1
-3,12,26:18.1
-2,12,26:18.1
-1,12,26:18.1
0,12,26:18.1
-2,13,26:18.1
0,1,27:18.1
-8,2,27:18.1
-7,2,27:18.1
-6,2,27:18.1
-2,2,27:18.1
-1,2,27:18.1
0,2,27:18.1
1,2,27:18.1
2,2,27:18.1
-9,3,27:18.1
-8,3,27:18.1
-7,3,27:18.1
-6,3,27:18.1
-5,3,27:18.1
-2,3,27:18.1
-1,3,27:18.1
0,3,27:18.1
1,3,27:18.1
2,3,27:18.1
-10,4,27:18.1
-9,4,27:18.1
-8,4,27:18.1
-7,4,27:18.1
-6,4,27:18.1
-5,4,27:18.1
-4,4,27:18.1
-3,4,27:17.13
-2,4,27:17.13
-1,4,27:18.1
0,4,27:18.1
1,4,27:18.1
2,4,27:18.1
3,4,27:18.1
-10,5,27:18.1
-9,5,27:18.1
-8,5,27:18.1
-7,5,27:17.13
-6,5,27:17.13
-5,5,27:17.13
-4,5,27:18.1
-3,5,27:17.13
-2,5,27:17.13
-1,5,27:18.1
0,5,27:18.1
1,5,27:18.1
2,5,27:18.1
-10,6,27:18.1
-9,6,27:18.1
-8,6,27:18.1
-7,6,27:18.1
-6,6,27:17.13
-5,6,27:18.1
-4,6,27:18.1
-3,6,27:17.13
-2,6,27:18.1
-1,6,27:18.1
0,6,27:18.1
1,6,27:18.1
2,6,27:18.1
-9,7,27:18.1
-8,7,27:18.1
-7,7,27:18.1
-6,7,27:17.13
-5,7,27:18.1
-4,7,27:18.1
-3,7,27:18.1
-2,7,27:18.1
0,7,27:18.1
-9,8,27:18.1
-8,8,27:18.1
-7,8,27:18.1
-6,8,27:18.1
-5,8,27:18.1
-4,8,27:18.1
-3,8,27:18.1
-2,8,27:18.1
-8,9,27:18.1
-7,9,27:18.1
-6,9,27:18.1
-5,9,27:18.1
-4,9,27:18.1
-3,9,27:18.1
-2,9,27:18.1
-1,9,27:18.1
-7,10,27:18.1
-6,10,27:18.1
-5,10,27:18.1
-4,10,27:18.1
-3,10,27:18.1
-2,10,27:18.1
-6,11,27:18.1
-5,11,27:18.1
-4,11,27:18.1
-3,11,27:18.1
-2,11,27:18.1
-4,12,27:18.1
-4,0,28:18.1
-3,0,28:18.1
-2,0,28:18.1
-5,1,28:18.1
-4,1,28:18.1
-3,1,28:18.1
-2,1,28:18.1
-1,1,28:18.1
-7,2,28:18.1
-6,2,28:18.1
-5,2,28:18.1
-4,2,28:18.1
-3,2,28:18.1
-2,2,28:18.1
-1,2,28:18.1
0,2,28:18.1
-9,3,28:18.1
-8,3,28:18.1
-7,3,28:18.1
-6,3,28:18.1
-5,3,28:18.1
-4,3,28:18.1
-3,3,28:17.13
-2,3,28:18.1
-1,3,28:18.1
0,3,28:18.1
-9,4,28:18.1
-8,4,28:18.1
-7,4,28:18.1
-6,4,28:18.1
-5,4,28:18.1
-4,4,28:18.1
-3,4,28:17.13
-2,4,28:17.13
-1,4,28:18.1
0,4,28:18.1
-10,5,28:18.1
-9,5,28:18.1
-8,5,28:18.1
-7,5,28:18.1
-6,5,28:18.1
-5,5,28:18.1
-4,5,28:18.1
-3,5,28:17.13
-2,5,28:17.13
-1,5,28:18.1
0,5,28:18.1
-9,6,28:18.1
-8,6,28:18.1
-7,6,28:18.1
-6,6,28:18.1
-5,6,28:18.1
-4,6,28:18.1
-3,6,28:18.1
-2,6,28:17.13
-1,6,28:18.1
0,6,28:18.1
1,6,28:18.1
-9,7,28:18.1
-8,7,28:18.1
-7,7,28:18.1
-6,7,28:18.1
-5,7,28:18.1
-4,7,28:18.1
-3,7,28:18.1
-2,7,28:17.13
-1,7,28:18.1
0,7,28:18.1
1,7,28:18.1
-8,8,28:18.1
-7,8,28:18.1
-6,8,28:18.1
-5,8,28:18.1
-4,8,28:18.1
-3,8,28:18.1
-2,8,28:18.1
-1,8,28:18.1
0,8,28:18.1
1,8,28:18.1
-8,9,28:18.1
-7,9,28:18.1
-6,9,28:18.1
-5,9,28:18.1
-4,9,28:18.1
-3,9,28:18.1
-2,9,28:18.1
-1,9,28:18.1
0,9,28:18.1
-6,10,28:18.1
-3,10,28:18.1
-2,10,28:18.1
-1,10,28:18.1
-3,0,29:18.1
-5,1,29:18.1
-4,1,29:18.1
-3,1,29:18.1
-2,1,29:18.1
-1,1,29:18.1
-5,2,29:18.1
-4,2,29:18.1
-3,2,29:18.1
-2,2,29:18.1
-1,2,29:18.1
0,2,29:18.1
-6,3,29:18.1
-5,3,29:18.1
-4,3,29:18.1
-3,3,29:18.1
-2,3,29:18.1
-1,3,29:18.1
0,3,29:18.1
1,3,29:18.1
-5,4,29:18.1
-4,4,29:18.1
-3,4,29:17.13
-2,4,29:17.13
-1,4,29:18.1
0,4,29:18.1
1,4,29:18.1
-5,5,29:18.1
-4,5,29:18.1
-3,5,29:17.13
-2,5,29:17.13
-1,5,29:18.1
0,5,29:18.1
1,5,29:18.1
-4,6,29:18.1
-3,6,29:18.1
-2,6,29:18.1
-1,6,29:18.1
0,6,29:18.1
-5,7,29:18.1
-4,7,29:18.1
-3,7,29:18.1
-2,7,29:18.1
-1,7,29:18.1
0,7,29:18.1
1,7,29:18.1
-4,8,29:18.1
-3,8,29:18.1
-2,8,29:18.1
-1,8,29:18.1
0,8,29:18.1
-4,9,29:18.1
-3,9,29:18.1
-2,9,29:18.1
-1,9,29:18.1
0,9,29:18.1
-2,10,29:18.1
-2,1,30:18.1
-5,2,30:18.1
-4,2,30:18.1
-3,2,30:18.1
-2,2,30:18.1
-1,2,30:18.1
0,2,30:18.1
-6,3,30:18.1
-5,3,30:18.1
-4,3,30:18.1
-3,3,30:18.1
-2,3,30:18.1
-1,3,30:18.1
0,3,30:18.1
-7,4,30:18.1
-6,4,30:18.1
-5,4,30:18.1
-4,4,30:18.1
-3,4,30:17.13
-2,4,30:17.13
-1,4,30:18.1
0,4,30:18.1
1,4,30:18.1
-7,5,30:18.1
-6,5,30:18.1
-5,5,30:18.1
-4,5,30:17.13
-3,5,30:17.13
-2,5,30:17.13
-1,5,30:18.1
0,5,30:18.1
1,5,30:18.1
-7,6,30:18.1
-6,6,30:18.1
-5,6,30:18.1
-4,6,30:18.1
-3,6,30:18.1
-2,6,30:18.1
-1,6,30:18.1
0,6,30:18.1
1,6,30:18.1
-6,7,30:18.1
-5,7,30:18.1
-4,7,30:18.1
-3,7,30:18.1
-2,7,30:18.1
-1,7,30:18.1
0,7,30:18.1
-5,8,30:18.1
-4,8,30:18.1
-3,8,30:18.1
-2,8,30:18.1
-1,8,30:18.1
-5,1,31:18.1
-4,1,31:18.1
-3,1,31:18.1
-6,2,31:18.1
-5,2,31:18.1
-4,2,31:18.1
-3,2,31:18.1
-2,2,31:18.1
-7,3,31:18.1
-6,3,31:18.1
-5,3,31:18.1
-4,3,31:18.1
-3,3,31:18.1
-2,3,31:18.1
-1,3,31:18.1
0,3,31:18.1
-7,4,31:18.1
-6,4,31:18.1
-5,4,31:18.1
-4,4,31:17.13
-3,4,31:17.13
-2,4,31:17.13
-1,4,31:18.1
0,4,31:18.1
-7,5,31:18.1
-6,5,31:18.1
-5,5,31:18.1
-4,5,31:18.1
-3,5,31:17.13
-2,5,31:17.13
-1,5,31:18.1
0,5,31:18.1
1,5,31:18.1
-6,6,31:18.1
-5,6,31:18.1
-4,6,31:18.1
-3,6,31:18.1
-2,6,31:18.1
-1,6,31:18.1
0,6,31:18.1
-6,7,31:18.1
-5,7,31:18.1
-4,7,31:18.1
-3,7,31:18.1
-2,7,31:18.1
-1,7,31:18.1
0,7,31:18.1
-4,8,31:18.1
-3,8,31:18.1
-2,8,31:18.1
-4,1,32:18.1
-6,2,32:18.1
-5,2,32:18.1
-4,2,32:18.1
-3,2,32:18.1
-2,2,32:18.1
-6,3,32:18.1
-5,3,32:18.1
-4,3,32:18.1
-3,3,32:18.1
-2,3,32:18.1
-1,3,32:18.1
-7,4,32:18.1
-6,4,32:18.1
-5,4,32:18.1
-4,4,32:18.1
-3,4,32:18.1
-2,4,32:18.1
-1,4,32:18.1
-6,5,32:18.1
-5,5,32:18.1
-4,5,32:18.1
-3,5,32:18.1
-2,5,32:18.1
-1,5,32:18.1
0,5,32:18.1
-6,6,32:18.1
-5,6,32:18.1
-4,6,32:18.1
-3,6,32:18.1
-2,6,32:18.1
-1,6,32:18.1
-5,7,32:18.1
-4,7,32:18.1
-3,7,32:18.1
-2,7,32:18.1
-1,7,32:18.1
-3,8,32:18.1
-3,4,33:18.1
-2,4,33:18.1
-3,5,33:18.1
-2,5,33:18.1
