[META]
version=2.0
spawnOnBlockType=2
spawnSunlight=True
spawnDarkness=True
spawnWater=False
spawnLava=False
underFill=False
randomRotation=True
dig=True
tree=True
branch=False
needsFoundation=True
rarity=30
collisionPercentage=60
spawnElevationMin=0
spawnElevationMax=230
spawnInBiome=Custom
[DATA]
0,-2,-1:18.1
1,-2,-1:18.1
-1,-1,-1:18.1
1,-1,-1:17.1
2,-1,-1:18.1
0,0,-1:18.1
1,0,-1:18.1
0,-3,0:18.1
1,-3,0:18.1
2,-3,0:18.1
-1,-2,0:18.1
0,-2,0:18.1
1,-2,0:18.1
2,-2,0:18.1
3,-2,0:18.1
-1,-1,0:18.1
0,-1,0:18.1
1,-1,0:17.1
3,-1,0:18.1
-1,0,0:18.1
0,0,0:18.1
1,0,0:18.1
3,0,0:18.1
0,1,0:18.1
1,1,0:18.1
2,1,0:18.1
0,-3,1:18.1
1,-3,1:18.1
0,-2,1:18.1
2,-2,1:18.1
-2,-1,1:18.1
0,-1,1:18.1
1,-1,1:17.1
2,-1,1:18.1
3,-1,1:18.1
0,0,1:18.1
1,0,1:18.1
2,0,1:18.1
1,1,1:18.1
1,-3,2:18.1
0,-2,2:18.1
2,-2,2:18.1
-1,-1,2:18.1
1,-1,2:18.1
2,-1,2:18.1
0,0,2:18.1
2,0,2:18.1
1,1,2:18.1
1,-2,3:18.1
0,-1,3:18.1
1,-1,3:18.1
1,0,3:18.1
1,-1,4:18.1
