[META]
version=2.0
spawnOnBlockType=2,3
spawnSunlight=True
spawnDarkness=False
spawnWater=False
spawnLava=False
underFill=True
randomRotation=True
dig=False
tree=True
branch=False
needsFoundation=True
rarity=50
collisionPercentage=10
spawnElevationMin=0
spawnElevationMax=250
spawnInBiome=CustomBirchForest
[DATA]
0,0,0:17.2
0,0,1:17.2
0,0,2:17.2
0,0,3:17.2
0,0,4:17.2
0,0,5:17.2
0,0,6:17.2
0,0,7:17.2
0,0,8:17.2
0,-1,8:18.2
-1,0,8:18.2
0,1,8:18.2
-1,1,8:18.2
-1,-1,8:18.2
1,0,8:18.2
1,-1,8:18.2
0,-1,9:18.2
-1,0,9:18.2
-2,0,9:18.2
-1,1,9:18.2
-1,2,9:18.2
0,1,9:18.2
-1,-1,9:18.2
0,-2,9:18.2
1,-1,9:18.2
1,0,9:18.2
1,1,9:18.2
3,0,9:18.2
2,0,9:18.2
2,-1,9:18.2
0,0,9:17.2
1,0,10:18.2
1,1,10:18.2
1,2,10:18.2
2,1,10:18.2
0,1,10:18.2
-1,1,10:18.2
-1,0,10:18.2
-1,-1,10:18.2
-2,0,10:18.2
-2,1,10:18.2
-1,-2,10:18.2
0,-1,10:18.2
0,-2,10:18.2
1,-2,10:18.2
1,-1,10:18.2
0,-3,10:18.2
-2,-1,10:18.2
0,2,10:18.2
0,0,10:17.2
-1,1,11:18.2
-1,-1,11:18.2
0,-1,11:18.2
-1,0,11:18.2
0,-2,11:18.2
1,-1,11:18.2
1,0,11:18.2
0,1,11:18.2
1,1,11:18.2
2,0,11:18.2
0,2,11:18.2
-1,2,11:18.2
-2,0,11:18.2
-2,-1,11:18.2
-3,0,11:18.2
0,0,11:17.2
-1,-1,12:18.2
-1,-2,12:18.2
-2,-1,12:18.2
-1,0,12:18.2
-1,1,12:18.2
-2,1,12:18.2
-2,0,12:18.2
-1,2,12:18.2
-2,2,12:18.2
-3,1,12:18.2
0,1,12:18.2
2,2,12:18.2
1,1,12:18.2
2,1,12:18.2
1,2,12:18.2
1,-1,12:18.2
1,0,12:18.2
0,-1,12:18.2
0,-2,12:18.2
0,0,12:17.2
0,-2,13:18.2
0,-3,13:18.2
0,-1,13:18.2
1,-1,13:18.2
1,-2,13:18.2
2,-1,13:18.2
1,0,13:18.2
1,1,13:18.2
0,1,13:18.2
0,2,13:18.2
-1,1,13:18.2
-1,0,13:18.2
-1,-1,13:18.2
-2,0,13:18.2
-2,1,13:18.2
-3,0,13:18.2
-2,-1,13:18.2
-1,2,13:18.2
1,2,13:18.2
0,0,13:17.2
-1,-1,14:18.2
-1,-2,14:18.2
0,-1,14:18.2
0,-2,14:18.2
1,-1,14:18.2
1,0,14:18.2
2,0,14:18.2
1,1,14:18.2
0,1,14:18.2
-1,1,14:18.2
-1,0,14:18.2
-2,0,14:18.2
0,0,14:17.2
-2,0,15:18.2
-2,1,15:18.2
-3,0,15:18.2
-3,1,15:18.2
-2,2,15:18.2
-1,2,15:18.2
-1,1,15:18.2
-1,0,15:18.2
0,2,15:18.2
0,1,15:18.2
1,1,15:18.2
1,0,15:18.2
2,1,15:18.2
1,-1,15:18.2
1,-2,15:18.2
2,-1,15:18.2
0,-2,15:18.2
0,-3,15:18.2
0,-1,15:18.2
-1,-1,15:18.2
-1,-2,15:18.2
0,0,15:17.2
-1,-1,16:18.2
-2,-1,16:18.2
-1,-2,16:18.2
0,-2,16:18.2
0,-1,16:18.2
1,-1,16:18.2
1,0,16:18.2
2,0,16:18.2
1,1,16:18.2
0,1,16:18.2
1,2,16:18.2
0,2,16:18.2
-1,2,16:18.2
-1,1,16:18.2
-1,0,16:18.2
-2,0,16:18.2
-2,1,16:18.2
1,-2,16:18.2
0,0,16:17.2
1,-1,17:18.2
0,-2,17:18.2
0,-1,17:18.2
-1,-1,17:18.2
-1,0,17:18.2
-2,0,17:18.2
-1,1,17:18.2
0,1,17:18.2
0,2,17:18.2
1,1,17:18.2
1,0,17:18.2
2,1,17:18.2
-1,-2,17:18.2
1,-2,17:18.2
2,0,17:18.2
0,-3,17:18.2
2,-1,17:18.2
-2,1,17:18.2
0,0,17:17.2
-1,0,18:18.2
-1,-1,18:18.2
0,1,18:18.2
0,2,18:18.2
-1,1,18:18.2
-1,2,18:18.2
-2,1,18:18.2
0,-1,18:18.2
0,-2,18:18.2
1,-1,18:18.2
1,0,18:18.2
1,1,18:18.2
2,0,18:18.2
-1,-2,18:18.2
-2,-1,18:18.2
0,0,18:17.2
-1,0,19:18.2
-1,1,19:18.2
0,1,19:18.2
1,1,19:18.2
1,2,19:18.2
0,2,19:18.2
2,2,19:18.2
2,1,19:18.2
1,0,19:18.2
2,3,19:18.2
1,-1,19:18.2
2,-1,19:18.2
0,-1,19:18.2
0,-2,19:18.2
-1,-1,19:18.2
-1,2,19:18.2
-2,1,19:18.2
0,0,19:17.2
0,2,20:18.2
0,3,20:18.2
0,1,20:18.2
-1,1,20:18.2
-1,0,20:18.2
-2,0,20:18.2
-1,-1,20:18.2
-1,-2,20:18.2
0,-1,20:18.2
1,-1,20:18.2
1,1,20:18.2
1,0,20:18.2
2,0,20:18.2
1,2,20:18.2
0,0,20:17.2
-1,1,21:18.2
-1,2,21:18.2
-2,1,21:18.2
-2,2,21:18.2
-1,-1,21:18.2
-1,0,21:18.2
0,-1,21:18.2
0,-2,21:18.2
1,-1,21:18.2
1,0,21:18.2
1,1,21:18.2
0,1,21:18.2
2,0,21:18.2
-2,-1,21:18.2
0,2,21:18.2
0,0,21:17.2
-1,1,22:18.2
-1,0,22:18.2
-2,0,22:18.2
-1,-1,22:18.2
-1,-2,22:18.2
0,-1,22:18.2
0,-2,22:18.2
1,0,22:18.2
0,1,22:18.2
0,2,22:18.2
1,-1,22:18.2
1,-2,22:18.2
0,0,22:17.2
0,-1,23:18.2
-1,0,23:18.2
1,0,23:18.2
0,1,23:18.2
-1,1,23:18.2
-1,-1,23:18.2
-2,1,23:18.2
-1,2,23:18.2
-2,0,23:18.2
1,1,23:18.2
2,1,23:18.2
0,0,23:17.2
0,0,24:17.2
-1,0,24:18.2
-1,1,24:18.2
0,1,24:18.2
-1,-1,24:18.2
0,-1,24:18.2
1,0,24:18.2
1,-1,24:18.2
0,2,24:18.2
-1,0,25:18.2
0,-1,25:18.2
1,0,25:18.2
0,1,25:18.2
0,0,25:17.2
0,0,26:18.2
0,0,-1:17.2
0,0,-2:17.2
