[META]
version=2.0
spawnOnBlockType=2
spawnSunlight=True
spawnDarkness=True
spawnWater=False
spawnLava=False
underFill=False
randomRotation=True
dig=True
tree=True
branch=False
needsFoundation=True
rarity=15
collisionPercentage=20
spawnElevationMin=0
spawnElevationMax=200
spawnInBiome=Custom
[DATA]
0,-1,-3:162.0
0,-1,-2:162.0
0,-1,-1:162.0
0,-1,0:162.0
0,-1,1:162.0
0,-1,2:162.0
0,-1,3:162.0
0,-1,4:162.0
0,-1,5:162.0
0,0,6:162.0
0,0,7:162.0
0,-1,8:161.0
1,-1,8:161.0
2,-1,8:161.0
3,-1,8:161.0
-1,0,8:161.0
0,0,8:162.0
1,0,8:161.0
2,0,8:161.0
3,0,8:161.0
4,0,8:161.0
-1,1,8:161.0
0,1,8:161.0
1,1,8:162.0
2,1,8:162.0
3,1,8:161.0
4,1,8:161.0
-1,2,8:161.0
0,2,8:161.0
1,2,8:161.0
2,2,8:161.0
3,2,8:161.0
4,2,8:161.0
0,3,8:161.0
1,3,8:161.0
2,3,8:161.0
3,3,8:161.0
-2,-2,9:162.0
-1,-1,9:162.0
0,0,9:161.0
1,0,9:161.0
2,0,9:161.0
0,1,9:161.0
1,1,9:161.0
2,1,9:161.0
3,1,9:161.0
0,2,9:161.0
1,2,9:161.0
2,2,9:161.0
-4,-4,10:161.0
-3,-4,10:161.0
-2,-4,10:161.0
-1,-4,10:161.0
0,-4,10:161.0
-4,-3,10:161.0
-3,-3,10:161.0
-2,-3,10:161.0
-1,-3,10:161.0
0,-3,10:161.0
-4,-2,10:161.0
-3,-2,10:161.0
-2,-2,10:162.0
-1,-2,10:161.0
0,-2,10:161.0
-4,-1,10:161.0
-3,-1,10:161.0
-2,-1,10:161.0
-1,-1,10:161.0
0,-1,10:161.0
-4,0,10:161.0
-3,0,10:161.0
-2,0,10:161.0
-1,0,10:161.0
0,0,10:161.0
-3,-3,11:161.0
-2,-3,11:161.0
-1,-3,11:161.0
-3,-2,11:161.0
-2,-2,11:161.0
-1,-2,11:161.0
-3,-1,11:161.0
-2,-1,11:161.0
-1,-1,11:161.0
