[META]
version=2.0
spawnOnBlockType=2
spawnSunlight=True
spawnDarkness=True
spawnWater=False
spawnLava=False
underFill=False
randomRotation=True
dig=True
tree=True
branch=False
needsFoundation=True
rarity=15
collisionPercentage=20
spawnElevationMin=0
spawnElevationMax=200
spawnInBiome=Custom
[DATA]
1,-1,-2:162.0
1,-1,-1:162.0
1,-1,0:162.0
1,-1,1:162.0
1,-1,2:162.0
1,-1,3:162.0
1,-1,4:162.0
1,-1,5:162.0
-3,-2,6:161.0
-2,-2,6:161.0
-1,-2,6:161.0
1,-2,6:161.0
-4,-1,6:161.0
-3,-1,6:161.0
-2,-1,6:161.0
-1,-1,6:162.0
0,-1,6:162.0
1,-1,6:162.0
2,-1,6:161.0
-4,0,6:161.0
-3,0,6:161.0
-2,0,6:162.0
-1,0,6:161.0
0,0,6:161.0
-4,1,6:161.0
-3,1,6:161.0
-2,1,6:161.0
-1,1,6:161.0
0,1,6:161.0
-3,2,6:161.0
-2,2,6:161.0
-1,2,6:161.0
0,-2,7:161.0
1,-2,7:161.0
2,-2,7:161.0
-3,-1,7:161.0
-2,-1,7:161.0
-1,-1,7:161.0
0,-1,7:161.0
1,-1,7:162.0
2,-1,7:161.0
3,-1,7:161.0
-3,0,7:161.0
-2,0,7:161.0
-1,0,7:161.0
1,0,7:161.0
2,0,7:161.0
-3,1,7:161.0
-2,1,7:161.0
-1,1,7:161.0
2,-2,8:162.0
1,-1,8:161.0
2,-1,8:161.0
2,-2,9:162.0
2,-5,10:161.0
3,-5,10:161.0
4,-5,10:161.0
1,-4,10:161.0
2,-4,10:161.0
3,-4,10:161.0
4,-4,10:161.0
5,-4,10:161.0
1,-3,10:161.0
2,-3,10:161.0
3,-3,10:162.0
4,-3,10:161.0
5,-3,10:161.0
1,-2,10:161.0
2,-2,10:161.0
3,-2,10:161.0
4,-2,10:161.0
5,-2,10:161.0
2,-1,10:161.0
3,-1,10:161.0
4,-1,10:161.0
2,-4,11:161.0
3,-4,11:161.0
4,-4,11:161.0
2,-3,11:161.0
3,-3,11:161.0
4,-3,11:161.0
2,-2,11:161.0
3,-2,11:161.0
4,-2,11:161.0
