[META]
version=2.0
spawnOnBlockType=2
spawnSunlight=True
spawnDarkness=True
spawnWater=False
spawnLava=False
underFill=False
randomRotation=True
dig=True
tree=True
branch=False
needsFoundation=True
rarity=15
collisionPercentage=20
spawnElevationMin=0
spawnElevationMax=200
spawnInBiome=Custom
[DATA]
-1,0,0:162.0
-1,0,1:162.0
-2,0,2:162.0
-1,0,2:162.0
-1,-2,3:162.0
-1,-1,3:162.0
-3,0,3:162.0
0,1,3:162.0
0,2,3:162.0
-3,-4,4:161.0
-2,-4,4:161.0
-4,-3,4:161.0
-3,-3,4:161.0
-2,-3,4:162.0
-5,-2,4:161.0
-4,-2,4:161.0
-3,-2,4:161.0
-6,-1,4:161.0
-5,-1,4:161.0
-4,-1,4:162.0
0,-1,4:162.0
-5,0,4:161.0
-4,0,4:161.0
-3,0,4:161.0
-1,0,4:161.0
1,0,4:161.0
-4,1,4:161.0
-3,1,4:161.0
-2,1,4:161.0
-1,1,4:161.0
0,1,4:161.0
1,1,4:161.0
2,1,4:161.0
-3,2,4:161.0
-2,2,4:161.0
-1,2,4:161.0
0,2,4:161.0
1,2,4:162.0
2,2,4:161.0
3,2,4:161.0
-3,3,4:161.0
-2,3,4:161.0
-1,3,4:162.0
0,3,4:161.0
1,3,4:161.0
2,3,4:161.0
-2,4,4:161.0
-1,4,4:161.0
0,4,4:161.0
1,4,4:161.0
-1,5,4:161.0
-4,-7,5:161.0
-3,-7,5:161.0
-2,-7,5:161.0
-5,-6,5:161.0
-4,-6,5:161.0
-3,-6,5:161.0
-2,-6,5:161.0
-1,-6,5:161.0
-6,-5,5:161.0
-5,-5,5:161.0
-4,-5,5:161.0
-3,-5,5:161.0
-2,-5,5:161.0
-1,-5,5:161.0
-7,-4,5:161.0
-6,-4,5:161.0
-5,-4,5:161.0
-4,-4,5:161.0
-3,-4,5:162.0
-2,-4,5:161.0
-1,-4,5:161.0
1,-4,5:161.0
-7,-3,5:161.0
-6,-3,5:161.0
-5,-3,5:161.0
-4,-3,5:161.0
-3,-3,5:161.0
-2,-3,5:161.0
-1,-3,5:161.0
0,-3,5:161.0
1,-3,5:161.0
2,-3,5:161.0
-7,-2,5:161.0
-6,-2,5:161.0
-5,-2,5:161.0
-4,-2,5:161.0
-3,-2,5:161.0
-2,-2,5:161.0
-1,-2,5:161.0
0,-2,5:161.0
1,-2,5:162.0
2,-2,5:161.0
3,-2,5:161.0
-8,-1,5:161.0
-7,-1,5:161.0
-6,-1,5:161.0
-5,-1,5:162.0
-4,-1,5:161.0
-3,-1,5:161.0
-2,-1,5:161.0
-1,-1,5:161.0
0,-1,5:161.0
2,-1,5:161.0
-8,0,5:161.0
-7,0,5:161.0
-6,0,5:161.0
-5,0,5:161.0
-4,0,5:161.0
-3,0,5:161.0
-2,0,5:161.0
-1,0,5:161.0
0,0,5:161.0
1,0,5:161.0
2,0,5:161.0
3,0,5:161.0
-7,1,5:161.0
-6,1,5:161.0
-5,1,5:161.0
-4,1,5:161.0
-3,1,5:161.0
-2,1,5:161.0
-1,1,5:161.0
0,1,5:161.0
1,1,5:161.0
2,1,5:161.0
3,1,5:161.0
4,1,5:161.0
5,1,5:161.0
-7,2,5:161.0
-6,2,5:161.0
-5,2,5:161.0
-4,2,5:161.0
-3,2,5:161.0
-2,2,5:161.0
-1,2,5:161.0
0,2,5:161.0
1,2,5:161.0
2,2,5:161.0
3,2,5:161.0
4,2,5:161.0
5,2,5:161.0
6,2,5:161.0
-6,3,5:161.0
-5,3,5:161.0
-4,3,5:161.0
-3,3,5:161.0
-2,3,5:161.0
-1,3,5:161.0
0,3,5:161.0
1,3,5:161.0
2,3,5:162.0
3,3,5:161.0
4,3,5:161.0
5,3,5:161.0
6,3,5:161.0
-6,4,5:161.0
-5,4,5:161.0
-4,4,5:161.0
-3,4,5:161.0
-2,4,5:162.0
-1,4,5:161.0
0,4,5:161.0
1,4,5:161.0
2,4,5:161.0
3,4,5:161.0
4,4,5:161.0
5,4,5:161.0
-6,5,5:161.0
-5,5,5:161.0
-4,5,5:161.0
-3,5,5:161.0
-2,5,5:161.0
-1,5,5:161.0
0,5,5:161.0
1,5,5:161.0
2,5,5:161.0
3,5,5:161.0
4,5,5:161.0
-5,6,5:161.0
-4,6,5:161.0
-3,6,5:161.0
-2,6,5:161.0
-1,6,5:161.0
0,6,5:161.0
1,6,5:161.0
2,6,5:161.0
3,6,5:161.0
-4,7,5:161.0
-3,7,5:161.0
-2,7,5:161.0
-1,7,5:161.0
0,7,5:161.0
1,7,5:161.0
-2,8,5:161.0
-1,8,5:161.0
1,-7,6:161.0
2,-7,6:161.0
-3,-6,6:161.0
0,-6,6:161.0
1,-6,6:161.0
2,-6,6:161.0
3,-6,6:161.0
-4,-5,6:161.0
-3,-5,6:161.0
-2,-5,6:161.0
-1,-5,6:161.0
0,-5,6:161.0
1,-5,6:161.0
2,-5,6:161.0
3,-5,6:161.0
4,-5,6:161.0
-5,-4,6:161.0
-4,-4,6:161.0
-3,-4,6:161.0
-2,-4,6:161.0
-1,-4,6:161.0
0,-4,6:161.0
1,-4,6:161.0
2,-4,6:161.0
3,-4,6:161.0
4,-4,6:161.0
-6,-3,6:161.0
-5,-3,6:161.0
-4,-3,6:161.0
-3,-3,6:161.0
-2,-3,6:161.0
-1,-3,6:161.0
0,-3,6:161.0
1,-3,6:161.0
2,-3,6:162.0
3,-3,6:161.0
4,-3,6:161.0
5,-3,6:161.0
-6,-2,6:161.0
-5,-2,6:161.0
-4,-2,6:161.0
-3,-2,6:161.0
-2,-2,6:161.0
-1,-2,6:161.0
0,-2,6:161.0
1,-2,6:161.0
2,-2,6:161.0
3,-2,6:161.0
4,-2,6:161.0
5,-2,6:161.0
-7,-1,6:161.0
-6,-1,6:161.0
-5,-1,6:161.0
-4,-1,6:161.0
-3,-1,6:161.0
-2,-1,6:161.0
-1,-1,6:161.0
0,-1,6:161.0
1,-1,6:161.0
2,-1,6:161.0
3,-1,6:161.0
4,-1,6:161.0
-7,0,6:161.0
-6,0,6:161.0
-5,0,6:161.0
-4,0,6:161.0
-3,0,6:161.0
-2,0,6:161.0
-1,0,6:161.0
0,0,6:161.0
1,0,6:161.0
2,0,6:161.0
3,0,6:161.0
-6,1,6:161.0
-5,1,6:161.0
-4,1,6:161.0
-3,1,6:161.0
-2,1,6:161.0
-1,1,6:161.0
0,1,6:161.0
1,1,6:161.0
2,1,6:161.0
-6,2,6:161.0
-5,2,6:161.0
-4,2,6:161.0
-3,2,6:161.0
-2,2,6:161.0
-1,2,6:161.0
0,2,6:161.0
1,2,6:161.0
2,2,6:161.0
3,2,6:161.0
4,2,6:161.0
-5,3,6:161.0
-4,3,6:161.0
-3,3,6:161.0
-2,3,6:161.0
-1,3,6:161.0
0,3,6:161.0
1,3,6:161.0
2,3,6:161.0
3,3,6:161.0
4,3,6:161.0
5,3,6:161.0
-5,4,6:161.0
-4,4,6:161.0
-3,4,6:161.0
-2,4,6:161.0
-1,4,6:161.0
0,4,6:161.0
1,4,6:161.0
2,4,6:161.0
3,4,6:161.0
-4,5,6:161.0
-3,5,6:161.0
-2,5,6:161.0
-1,5,6:161.0
0,5,6:161.0
1,5,6:161.0
2,5,6:161.0
-3,6,6:161.0
-2,6,6:161.0
-1,6,6:161.0
0,6,6:161.0
1,6,6:161.0
-2,7,6:161.0
-1,7,6:161.0
1,-6,7:161.0
0,-5,7:161.0
1,-5,7:161.0
2,-5,7:161.0
-1,-4,7:161.0
0,-4,7:161.0
1,-4,7:161.0
2,-4,7:161.0
3,-4,7:161.0
-2,-3,7:161.0
-1,-3,7:161.0
0,-3,7:161.0
1,-3,7:161.0
2,-3,7:161.0
3,-3,7:161.0
4,-3,7:161.0
-5,-2,7:161.0
-4,-2,7:161.0
-1,-2,7:161.0
0,-2,7:161.0
1,-2,7:161.0
2,-2,7:161.0
3,-2,7:161.0
-5,-1,7:161.0
-4,-1,7:161.0
-3,-1,7:161.0
0,-1,7:161.0
1,-1,7:161.0
2,-1,7:161.0
3,-1,7:161.0
-4,0,7:161.0
-3,0,7:161.0
-2,0,7:161.0
1,0,7:161.0
2,0,7:161.0
-4,1,7:161.0
-3,1,7:161.0
-2,1,7:161.0
-1,1,7:161.0
-3,2,7:161.0
-2,2,7:161.0
2,2,7:161.0
1,3,7:161.0
2,3,7:161.0
3,3,7:161.0
-1,4,7:161.0
0,4,7:161.0
1,4,7:161.0
2,4,7:161.0
-2,5,7:161.0
-1,5,7:161.0
0,5,7:161.0
1,5,7:161.0
-1,6,7:161.0
1,-4,8:161.0
0,-3,8:161.0
1,-3,8:161.0
2,-3,8:161.0
1,-2,8:161.0
2,-2,8:161.0
