[META]
version=2.0
spawnOnBlockType=2
spawnSunlight=True
spawnDarkness=True
spawnWater=False
spawnLava=False
underFill=False
randomRotation=True
dig=True
tree=True
branch=False
needsFoundation=True
rarity=15
collisionPercentage=20
spawnElevationMin=0
spawnElevationMax=200
spawnInBiome=Custom
[DATA]
0,-1,-1:162.0
0,-1,0:162.0
0,-1,1:162.0
0,-1,2:162.0
0,-1,3:162.0
0,-1,4:162.0
0,-1,5:162.0
0,-1,6:162.0
0,-1,7:162.0
0,0,8:162.0
0,0,9:162.0
0,-1,10:161.0
1,-1,10:161.0
2,-1,10:161.0
3,-1,10:161.0
-1,0,10:161.0
0,0,10:162.0
1,0,10:161.0
2,0,10:161.0
3,0,10:161.0
4,0,10:161.0
-1,1,10:161.0
0,1,10:161.0
1,1,10:162.0
2,1,10:162.0
3,1,10:161.0
4,1,10:161.0
-1,2,10:161.0
0,2,10:161.0
1,2,10:161.0
2,2,10:161.0
3,2,10:161.0
4,2,10:161.0
0,3,10:161.0
1,3,10:161.0
2,3,10:161.0
3,3,10:161.0
-2,-2,11:162.0
-1,-1,11:162.0
0,0,11:161.0
1,0,11:161.0
2,0,11:161.0
0,1,11:161.0
1,1,11:161.0
2,1,11:161.0
3,1,11:161.0
0,2,11:161.0
1,2,11:161.0
2,2,11:161.0
-4,-4,12:161.0
-3,-4,12:161.0
-2,-4,12:161.0
-1,-4,12:161.0
0,-4,12:161.0
-4,-3,12:161.0
-3,-3,12:161.0
-2,-3,12:161.0
-1,-3,12:161.0
0,-3,12:161.0
-4,-2,12:161.0
-3,-2,12:161.0
-2,-2,12:162.0
-1,-2,12:161.0
0,-2,12:161.0
-4,-1,12:161.0
-3,-1,12:161.0
-2,-1,12:161.0
-1,-1,12:161.0
0,-1,12:161.0
-4,0,12:161.0
-3,0,12:161.0
-2,0,12:161.0
-1,0,12:161.0
0,0,12:161.0
-3,-3,13:161.0
-2,-3,13:161.0
-1,-3,13:161.0
-3,-2,13:161.0
-2,-2,13:161.0
-1,-2,13:161.0
-3,-1,13:161.0
-2,-1,13:161.0
-1,-1,13:161.0
