[META]
version=2.0
spawnOnBlockType=2
spawnSunlight=True
spawnDarkness=True
spawnWater=False
spawnLava=False
underFill=False
randomRotation=True
dig=True
tree=True
branch=False
needsFoundation=True
rarity=15
collisionPercentage=20
spawnElevationMin=0
spawnElevationMax=200
spawnInBiome=Custom
[DATA]
-1,-1,0:162.0
-1,-1,1:162.0
-1,-1,2:162.0
-2,-2,3:161.0
-3,-1,3:161.0
-2,-1,3:161.0
-1,-1,3:162.0
-2,0,3:161.0
-3,-3,4:161.0
-2,-3,4:161.0
-4,-2,4:161.0
-3,-2,4:161.0
-2,-2,4:161.0
-1,-2,4:161.0
-4,-1,4:161.0
-3,-1,4:161.0
-2,-1,4:162.0
-1,-1,4:162.0
-4,0,4:161.0
-3,0,4:161.0
-2,0,4:161.0
-1,0,4:161.0
-3,1,4:161.0
-2,1,4:161.0
-2,-2,5:161.0
-3,-1,5:161.0
-2,-1,5:161.0
-1,-1,5:161.0
0,-1,5:162.0
-3,0,5:161.0
-2,0,5:161.0
2,-3,6:161.0
1,-2,6:161.0
2,-2,6:161.0
3,-2,6:161.0
0,-1,6:161.0
1,-1,6:162.0
2,-1,6:161.0
3,-1,6:161.0
4,-1,6:161.0
0,0,6:161.0
1,0,6:161.0
2,0,6:161.0
3,0,6:161.0
1,1,6:161.0
2,1,6:161.0
1,-5,7:161.0
2,-5,7:161.0
3,-5,7:161.0
0,-4,7:161.0
1,-4,7:161.0
2,-4,7:161.0
3,-4,7:161.0
4,-4,7:161.0
-1,-3,7:161.0
0,-3,7:161.0
1,-3,7:161.0
2,-3,7:161.0
3,-3,7:161.0
4,-3,7:161.0
5,-3,7:161.0
-2,-2,7:161.0
-1,-2,7:161.0
0,-2,7:161.0
1,-2,7:161.0
2,-2,7:161.0
3,-2,7:161.0
4,-2,7:161.0
5,-2,7:161.0
6,-2,7:161.0
-2,-1,7:161.0
-1,-1,7:161.0
0,-1,7:161.0
1,-1,7:161.0
2,-1,7:162.0
3,-1,7:161.0
4,-1,7:161.0
5,-1,7:161.0
6,-1,7:161.0
-2,0,7:161.0
-1,0,7:161.0
0,0,7:161.0
1,0,7:161.0
2,0,7:161.0
3,0,7:161.0
4,0,7:161.0
5,0,7:161.0
-1,1,7:161.0
0,1,7:161.0
1,1,7:161.0
2,1,7:161.0
3,1,7:161.0
4,1,7:161.0
5,1,7:161.0
0,2,7:161.0
1,2,7:161.0
2,2,7:161.0
3,2,7:161.0
4,2,7:161.0
2,3,7:161.0
3,3,7:161.0
2,-4,8:161.0
3,-4,8:161.0
0,-3,8:161.0
1,-3,8:161.0
2,-3,8:161.0
3,-3,8:161.0
4,-3,8:161.0
-1,-2,8:161.0
0,-2,8:161.0
1,-2,8:161.0
2,-2,8:161.0
3,-2,8:161.0
4,-2,8:161.0
5,-2,8:161.0
-1,-1,8:161.0
0,-1,8:161.0
1,-1,8:161.0
2,-1,8:162.0
3,-1,8:161.0
4,-1,8:161.0
5,-1,8:161.0
-1,0,8:161.0
0,0,8:161.0
1,0,8:161.0
2,0,8:161.0
3,0,8:161.0
4,0,8:161.0
0,1,8:161.0
1,1,8:161.0
2,1,8:161.0
3,1,8:161.0
2,2,8:161.0
3,2,8:161.0
2,-2,9:161.0
1,-1,9:161.0
2,-1,9:161.0
3,-1,9:161.0
1,0,9:161.0
2,0,9:161.0
