[META]
version=2.0
spawnOnBlockType=2
spawnSunlight=True
spawnDarkness=True
spawnWater=False
spawnLava=False
underFill=False
randomRotation=True
dig=True
tree=True
branch=False
needsFoundation=True
rarity=15
collisionPercentage=20
spawnElevationMin=0
spawnElevationMax=200
spawnInBiome=Custom
[DATA]
0,1,0:162.0
0,1,1:162.0
0,1,2:162.0
0,1,3:162.0
-1,2,3:162.0
-1,0,4:162.0
1,1,4:162.0
-2,3,4:162.0
-2,-1,5:162.0
0,-1,5:162.0
2,0,5:161.0
0,1,5:161.0
1,1,5:162.0
2,1,5:161.0
3,1,5:161.0
0,2,5:161.0
1,2,5:161.0
2,2,5:161.0
-2,3,5:162.0
1,3,5:161.0
1,-2,6:162.0
-3,-1,6:162.0
-2,-1,6:162.0
2,-1,6:161.0
0,0,6:161.0
1,0,6:161.0
2,0,6:161.0
3,0,6:161.0
-1,1,6:161.0
0,1,6:161.0
1,1,6:161.0
2,1,6:162.0
3,1,6:161.0
4,1,6:161.0
-3,2,6:162.0
-1,2,6:161.0
0,2,6:161.0
1,2,6:162.0
2,2,6:161.0
3,2,6:161.0
0,3,6:161.0
1,3,6:161.0
2,3,6:161.0
-2,4,6:162.0
1,4,6:161.0
2,-3,7:162.0
-4,-2,7:162.0
-2,-2,7:162.0
2,-1,7:162.0
2,0,7:161.0
1,1,7:161.0
2,1,7:161.0
-4,2,7:162.0
0,2,7:161.0
1,2,7:161.0
-1,3,7:162.0
-2,5,7:162.0
3,-4,8:162.0
-5,-3,8:162.0
-2,-3,8:162.0
-4,-1,8:162.0
-1,-1,8:162.0
2,-1,8:162.0
-4,2,8:162.0
-1,3,8:162.0
-3,6,8:162.0
-2,-5,9:161.0
3,-5,9:161.0
4,-5,9:161.0
-6,-4,9:161.0
-5,-4,9:161.0
-3,-4,9:161.0
-2,-4,9:162.0
-1,-4,9:161.0
2,-4,9:161.0
3,-4,9:162.0
4,-4,9:161.0
-6,-3,9:161.0
-5,-3,9:162.0
-4,-3,9:161.0
-2,-3,9:161.0
0,-3,9:161.0
2,-3,9:161.0
3,-3,9:161.0
-5,-2,9:161.0
-4,-2,9:161.0
-3,-2,9:161.0
-2,-2,9:161.0
-1,-2,9:161.0
0,-2,9:161.0
1,-2,9:161.0
3,-2,9:161.0
-5,-1,9:161.0
-4,-1,9:162.0
-2,-1,9:161.0
-1,-1,9:162.0
0,-1,9:161.0
3,-1,9:161.0
4,-1,9:161.0
-4,0,9:161.0
-2,0,9:161.0
-1,0,9:161.0
2,0,9:161.0
3,0,9:162.0
4,0,9:161.0
5,0,9:161.0
-5,1,9:161.0
-4,1,9:161.0
-3,1,9:161.0
-2,1,9:161.0
-1,1,9:161.0
1,1,9:161.0
2,1,9:161.0
3,1,9:161.0
4,1,9:161.0
-6,2,9:161.0
-5,2,9:162.0
-4,2,9:161.0
-3,2,9:161.0
-2,2,9:162.0
-1,2,9:161.0
0,2,9:161.0
1,2,9:161.0
2,2,9:161.0
3,2,9:161.0
-5,3,9:161.0
-4,3,9:161.0
-3,3,9:161.0
-2,3,9:161.0
-1,3,9:161.0
0,3,9:162.0
1,3,9:161.0
2,3,9:161.0
-3,4,9:161.0
-2,4,9:162.0
-1,4,9:161.0
0,4,9:161.0
-3,5,9:161.0
-2,5,9:161.0
-1,5,9:161.0
-4,6,9:161.0
-3,6,9:162.0
-2,6,9:161.0
-3,7,9:161.0
-3,-7,10:161.0
-2,-7,10:161.0
-1,-7,10:161.0
3,-7,10:161.0
4,-7,10:161.0
-6,-6,10:161.0
-5,-6,10:161.0
-4,-6,10:161.0
-3,-6,10:161.0
-2,-6,10:161.0
-1,-6,10:161.0
0,-6,10:161.0
2,-6,10:161.0
3,-6,10:161.0
4,-6,10:161.0
5,-6,10:161.0
-7,-5,10:161.0
-6,-5,10:161.0
-5,-5,10:161.0
-4,-5,10:161.0
-3,-5,10:161.0
-2,-5,10:162.0
-1,-5,10:161.0
0,-5,10:161.0
1,-5,10:161.0
2,-5,10:161.0
3,-5,10:161.0
4,-5,10:162.0
5,-5,10:161.0
6,-5,10:161.0
-8,-4,10:161.0
-7,-4,10:161.0
-6,-4,10:162.0
-5,-4,10:161.0
-4,-4,10:161.0
-3,-4,10:161.0
-2,-4,10:161.0
-1,-4,10:161.0
0,-4,10:161.0
1,-4,10:161.0
2,-4,10:161.0
3,-4,10:161.0
4,-4,10:161.0
5,-4,10:161.0
6,-4,10:161.0
-8,-3,10:161.0
-7,-3,10:161.0
-6,-3,10:161.0
-5,-3,10:161.0
-4,-3,10:162.0
-3,-3,10:161.0
-2,-3,10:161.0
-1,-3,10:161.0
0,-3,10:161.0
1,-3,10:161.0
2,-3,10:162.0
3,-3,10:161.0
4,-3,10:161.0
5,-3,10:161.0
-7,-2,10:161.0
-6,-2,10:161.0
-5,-2,10:161.0
-4,-2,10:161.0
-3,-2,10:161.0
-2,-2,10:161.0
-1,-2,10:161.0
0,-2,10:162.0
1,-2,10:161.0
2,-2,10:161.0
3,-2,10:161.0
4,-2,10:161.0
5,-2,10:161.0
-6,-1,10:161.0
-5,-1,10:161.0
-4,-1,10:161.0
-3,-1,10:161.0
-2,-1,10:161.0
-1,-1,10:161.0
0,-1,10:161.0
1,-1,10:161.0
2,-1,10:161.0
3,-1,10:161.0
4,-1,10:161.0
5,-1,10:161.0
6,-1,10:161.0
-7,0,10:161.0
-6,0,10:161.0
-5,0,10:161.0
-4,0,10:162.0
-3,0,10:161.0
-2,0,10:162.0
-1,0,10:161.0
0,0,10:161.0
1,0,10:161.0
2,0,10:161.0
3,0,10:161.0
4,0,10:161.0
5,0,10:161.0
6,0,10:161.0
-7,1,10:161.0
-6,1,10:161.0
-5,1,10:161.0
-4,1,10:161.0
-3,1,10:161.0
-2,1,10:161.0
-1,1,10:161.0
0,1,10:161.0
1,1,10:161.0
2,1,10:161.0
3,1,10:161.0
4,1,10:162.0
5,1,10:161.0
6,1,10:161.0
-8,2,10:161.0
-7,2,10:161.0
-6,2,10:162.0
-5,2,10:161.0
-4,2,10:161.0
-3,2,10:161.0
-2,2,10:162.0
-1,2,10:161.0
0,2,10:161.0
1,2,10:161.0
2,2,10:161.0
3,2,10:161.0
4,2,10:161.0
5,2,10:161.0
6,2,10:161.0
-8,3,10:161.0
-7,3,10:161.0
-6,3,10:161.0
-5,3,10:161.0
-4,3,10:161.0
-3,3,10:161.0
-2,3,10:161.0
-1,3,10:161.0
0,3,10:161.0
1,3,10:162.0
2,3,10:161.0
3,3,10:161.0
4,3,10:161.0
5,3,10:161.0
-7,4,10:161.0
-6,4,10:161.0
-5,4,10:161.0
-4,4,10:161.0
-3,4,10:162.0
-2,4,10:161.0
-1,4,10:161.0
0,4,10:161.0
1,4,10:161.0
2,4,10:161.0
3,4,10:161.0
4,4,10:161.0
-6,5,10:161.0
-5,5,10:161.0
-4,5,10:161.0
-3,5,10:161.0
-2,5,10:161.0
-1,5,10:161.0
0,5,10:161.0
1,5,10:161.0
2,5,10:161.0
-6,6,10:161.0
-5,6,10:161.0
-4,6,10:162.0
-3,6,10:161.0
-2,6,10:161.0
-1,6,10:161.0
0,6,10:161.0
1,6,10:161.0
-5,7,10:161.0
-4,7,10:161.0
-3,7,10:161.0
-2,7,10:161.0
-4,8,10:161.0
-3,8,10:161.0
-2,-6,11:161.0
3,-6,11:161.0
-5,-5,11:161.0
-4,-5,11:161.0
-3,-5,11:161.0
-2,-5,11:161.0
-1,-5,11:161.0
2,-5,11:161.0
3,-5,11:161.0
4,-5,11:161.0
-6,-4,11:161.0
-5,-4,11:161.0
-4,-4,11:161.0
-3,-4,11:161.0
-2,-4,11:161.0
-1,-4,11:161.0
0,-4,11:161.0
1,-4,11:161.0
2,-4,11:161.0
3,-4,11:161.0
4,-4,11:161.0
-7,-3,11:161.0
-6,-3,11:161.0
-5,-3,11:161.0
-4,-3,11:161.0
-3,-3,11:161.0
-2,-3,11:161.0
-1,-3,11:161.0
0,-3,11:161.0
1,-3,11:161.0
2,-3,11:161.0
3,-3,11:161.0
-6,-2,11:161.0
-5,-2,11:161.0
-4,-2,11:161.0
-3,-2,11:161.0
-2,-2,11:161.0
-1,-2,11:161.0
0,-2,11:161.0
1,-2,11:161.0
2,-2,11:161.0
3,-2,11:161.0
4,-2,11:161.0
-5,-1,11:161.0
-4,-1,11:161.0
-3,-1,11:161.0
-2,-1,11:161.0
-1,-1,11:161.0
0,-1,11:161.0
1,-1,11:161.0
2,-1,11:161.0
3,-1,11:161.0
4,-1,11:161.0
-5,0,11:161.0
-4,0,11:161.0
-3,0,11:161.0
-2,0,11:161.0
-1,0,11:161.0
0,0,11:161.0
1,0,11:161.0
2,0,11:161.0
3,0,11:161.0
4,0,11:161.0
5,0,11:161.0
-6,1,11:161.0
-5,1,11:161.0
-4,1,11:161.0
-3,1,11:161.0
-2,1,11:161.0
-1,1,11:161.0
0,1,11:161.0
1,1,11:161.0
2,1,11:161.0
3,1,11:161.0
4,1,11:161.0
5,1,11:161.0
-7,2,11:161.0
-6,2,11:161.0
-5,2,11:161.0
-4,2,11:161.0
-3,2,11:161.0
-2,2,11:161.0
-1,2,11:161.0
0,2,11:161.0
1,2,11:161.0
2,2,11:161.0
3,2,11:161.0
4,2,11:161.0
-7,3,11:161.0
-6,3,11:161.0
-5,3,11:161.0
-4,3,11:161.0
-3,3,11:161.0
-2,3,11:161.0
-1,3,11:161.0
0,3,11:161.0
1,3,11:161.0
2,3,11:161.0
3,3,11:161.0
-6,4,11:161.0
-5,4,11:161.0
-4,4,11:161.0
-3,4,11:161.0
-2,4,11:161.0
-1,4,11:161.0
0,4,11:161.0
1,4,11:161.0
2,4,11:161.0
-5,5,11:161.0
-4,5,11:161.0
-3,5,11:161.0
-2,5,11:161.0
-1,5,11:161.0
0,5,11:161.0
-4,6,11:161.0
-3,6,11:161.0
-2,6,11:161.0
-4,7,11:161.0
-3,7,11:161.0
-3,-3,12:161.0
-2,-3,12:161.0
-4,-2,12:161.0
-3,-2,12:161.0
3,-1,12:161.0
2,0,12:161.0
3,0,12:161.0
-4,1,12:161.0
-3,1,12:161.0
2,1,12:161.0
-4,2,12:161.0
-3,2,12:161.0
-2,2,12:161.0
-3,3,12:161.0
-2,3,12:161.0
-1,3,12:161.0
-3,4,12:161.0
-2,4,12:161.0
