[META]
version=2.0
spawnOnBlockType=2
spawnSunlight=True
spawnDarkness=True
spawnWater=False
spawnLava=False
underFill=False
randomRotation=True
dig=True
tree=True
branch=False
needsFoundation=True
rarity=25
collisionPercentage=20
spawnElevationMin=0
spawnElevationMax=200
spawnInBiome=Custom
[DATA]
-3,-1,-3:17.3
-5,0,-3:17.3
-4,0,-3:17.3
-3,0,-3:17.3
-2,0,-3:17.3
-1,0,-3:17.3
-4,1,-3:17.3
-3,1,-3:17.3
-2,1,-3:17.3
-5,2,-3:17.3
-4,2,-3:17.3
-3,2,-3:17.3
-1,2,-3:17.3
-3,3,-3:17.3
-3,-1,-2:17.3
-5,0,-2:17.3
-4,0,-2:17.3
-3,0,-2:17.3
-2,0,-2:17.3
-1,0,-2:17.3
-4,1,-2:17.3
-3,1,-2:17.3
-2,1,-2:17.3
-5,2,-2:17.3
-4,2,-2:17.3
-3,2,-2:17.3
-1,2,-2:17.3
-3,3,-2:17.3
-3,-1,-1:17.3
-5,0,-1:17.3
-4,0,-1:17.3
-3,0,-1:17.3
-2,0,-1:17.3
-1,0,-1:17.3
-4,1,-1:17.3
-3,1,-1:17.3
-2,1,-1:17.3
-5,2,-1:17.3
-4,2,-1:17.3
-3,2,-1:17.3
-1,2,-1:17.3
-3,3,-1:17.3
-3,-1,0:17.3
-5,0,0:17.3
-4,0,0:17.3
-3,0,0:17.3
-2,0,0:17.3
-1,0,0:17.3
-4,1,0:17.3
-3,1,0:17.3
-2,1,0:17.3
-5,2,0:17.3
-4,2,0:17.3
-3,2,0:17.3
-1,2,0:17.3
-3,3,0:17.3
-4,0,1:17.3
-3,0,1:17.3
-2,0,1:17.3
-4,1,1:17.3
-3,1,1:17.3
-2,1,1:17.3
-4,2,1:17.3
-3,2,1:17.3
-3,0,2:17.3
-4,1,2:17.3
-3,1,2:17.3
-2,1,2:17.3
-3,2,2:17.3
-3,0,3:17.3
-4,1,3:17.3
-3,1,3:17.3
-2,1,3:17.3
-3,2,3:17.3
-3,0,4:17.3
-4,1,4:17.3
-3,1,4:17.3
-2,1,4:17.3
-3,2,4:17.3
-3,-2,5:18.3
-2,-2,5:18.3
-4,-1,5:18.3
-3,-1,5:18.3
-2,-1,5:18.3
-5,0,5:18.3
-4,0,5:18.3
-3,0,5:17.3
-2,0,5:18.3
-1,0,5:18.3
-4,1,5:17.3
-3,1,5:17.3
-2,1,5:17.3
-1,1,5:18.3
-3,2,5:17.3
-2,2,5:18.3
-3,-1,6:18.3
-2,-1,6:18.3
-1,-1,6:18.3
-4,0,6:18.3
-3,0,6:17.3
-2,0,6:17.3
-1,0,6:18.3
0,0,6:18.3
-4,1,6:17.3
-3,1,6:17.3
-2,1,6:17.3
-1,1,6:18.3
0,1,6:18.3
-3,2,6:17.3
-2,2,6:18.3
-1,2,6:18.3
-3,3,6:18.3
-2,3,6:18.3
-1,-1,7:17.3
-3,0,7:17.3
-2,0,7:18.3
-1,0,7:18.3
-4,1,7:17.3
-3,1,7:17.3
-2,1,7:17.3
-1,1,7:18.3
-3,2,7:17.3
-2,2,7:18.3
-3,3,7:18.3
0,-3,8:18.3
1,-3,8:18.3
-1,-2,8:18.3
0,-2,8:17.3
1,-2,8:18.3
2,-2,8:18.3
-1,-1,8:18.3
0,-1,8:18.3
1,-1,8:18.3
-3,0,8:17.3
-1,0,8:18.3
0,0,8:17.3
1,0,8:18.3
-4,1,8:17.3
-3,1,8:17.3
-2,1,8:17.3
0,1,8:18.3
-3,2,8:17.3
1,-5,9:18.3
0,-4,9:18.3
1,-4,9:18.3
2,-4,9:18.3
-1,-3,9:18.3
0,-3,9:18.3
1,-3,9:17.3
2,-3,9:18.3
3,-3,9:18.3
-2,-2,9:18.3
-1,-2,9:18.3
0,-2,9:18.3
1,-2,9:18.3
2,-2,9:18.3
3,-2,9:18.3
-2,-1,9:18.3
-1,-1,9:18.3
0,-1,9:18.3
1,-1,9:18.3
2,-1,9:18.3
3,-1,9:18.3
-3,0,9:17.3
-1,0,9:18.3
0,0,9:18.3
1,0,9:17.3
2,0,9:18.3
3,0,9:18.3
-4,1,9:17.3
-3,1,9:17.3
-2,1,9:17.3
-1,1,9:18.3
0,1,9:18.3
1,1,9:18.3
2,1,9:18.3
-3,2,9:17.3
-2,2,9:17.3
0,2,9:18.3
1,2,9:18.3
-4,3,9:17.3
-3,3,9:17.3
-2,3,9:17.3
-4,4,9:17.3
-3,4,9:17.3
-3,5,9:17.3
0,-3,10:18.3
1,-3,10:18.3
-1,-2,10:18.3
0,-2,10:18.3
1,-2,10:18.3
2,-2,10:18.3
-1,-1,10:18.3
0,-1,10:18.3
1,-1,10:18.3
2,-1,10:18.3
-5,0,10:17.7
-4,0,10:17.7
-3,0,10:17.3
0,0,10:18.3
1,0,10:18.3
-6,1,10:17.7
-5,1,10:17.7
-4,1,10:17.3
-3,1,10:17.3
-2,1,10:17.3
-3,2,10:17.3
-4,5,10:17.3
-2,5,10:17.3
-3,6,10:17.3
-7,-2,11:18.3
-9,-1,11:18.3
-8,-1,11:18.3
-7,-1,11:18.3
-6,-1,11:18.3
-8,0,11:18.3
-7,0,11:18.3
-6,0,11:17.3
-3,0,11:17.3
-8,1,11:18.3
-7,1,11:17.3
-4,1,11:17.3
-3,1,11:17.3
-2,1,11:17.3
-9,2,11:18.3
-8,2,11:18.3
-7,2,11:18.3
-3,2,11:17.3
-8,3,11:18.3
-4,4,11:18.3
-3,4,11:18.3
-2,4,11:18.3
-1,4,11:18.3
-5,5,11:18.3
-4,5,11:18.3
-3,5,11:18.3
-2,5,11:18.3
-1,5,11:17.3
0,5,11:18.3
-7,6,11:18.3
-6,6,11:18.3
-5,6,11:17.3
-4,6,11:18.3
-3,6,11:18.3
-2,6,11:18.3
-1,6,11:18.3
0,6,11:18.3
-7,7,11:18.3
-6,7,11:18.3
-5,7,11:18.3
-4,7,11:18.3
-3,7,11:18.3
-2,7,11:17.3
-1,7,11:18.3
-6,8,11:18.3
-5,8,11:18.3
-4,8,11:18.3
-3,8,11:18.3
-2,8,11:18.3
-5,9,11:18.3
-4,9,11:18.3
-3,9,11:18.3
-8,-3,12:18.3
-7,-3,12:18.3
-9,-2,12:18.3
-8,-2,12:18.3
-7,-2,12:18.3
-6,-2,12:18.3
-10,-1,12:18.3
-9,-1,12:18.3
-8,-1,12:18.3
-7,-1,12:17.3
-6,-1,12:18.3
-5,-1,12:18.3
-10,0,12:18.3
-9,0,12:18.3
-8,0,12:18.3
-7,0,12:18.3
-6,0,12:18.3
-5,0,12:18.3
-3,0,12:17.3
-9,1,12:18.3
-8,1,12:18.3
-7,1,12:18.3
-6,1,12:18.3
-5,1,12:18.3
-4,1,12:17.3
-3,1,12:17.3
-2,1,12:17.3
-10,2,12:18.3
-9,2,12:18.3
-8,2,12:17.3
-7,2,12:18.3
-6,2,12:18.3
-3,2,12:17.3
-10,3,12:18.3
-9,3,12:18.3
-8,3,12:18.3
-7,3,12:18.3
-5,3,12:18.3
-4,3,12:18.3
-3,3,12:18.3
-2,3,12:18.3
-1,3,12:18.3
0,3,12:18.3
-9,4,12:18.3
-8,4,12:18.3
-6,4,12:18.3
-5,4,12:18.3
-4,4,12:18.3
-3,4,12:18.3
-2,4,12:18.3
-1,4,12:18.3
0,4,12:18.3
1,4,12:18.3
-7,5,12:18.3
-6,5,12:18.3
-5,5,12:18.3
-4,5,12:18.3
-3,5,12:18.3
-2,5,12:18.3
-1,5,12:18.3
0,5,12:17.3
1,5,12:18.3
2,5,12:18.3
-8,6,12:18.3
-7,6,12:18.3
-6,6,12:18.3
-5,6,12:18.3
-4,6,12:18.3
-3,6,12:18.3
-2,6,12:18.3
-1,6,12:18.3
0,6,12:18.3
1,6,12:18.3
2,6,12:18.3
-9,7,12:18.3
-8,7,12:18.3
-7,7,12:18.3
-6,7,12:17.3
-5,7,12:18.3
-4,7,12:18.3
-3,7,12:18.3
-2,7,12:18.3
-1,7,12:18.3
0,7,12:18.3
1,7,12:18.3
-8,8,12:18.3
-7,8,12:18.3
-6,8,12:18.3
-5,8,12:18.3
-4,8,12:18.3
-3,8,12:18.3
-2,8,12:17.3
-1,8,12:18.3
0,8,12:18.3
-7,9,12:18.3
-6,9,12:18.3
-5,9,12:18.3
-4,9,12:18.3
-3,9,12:18.3
-2,9,12:18.3
-1,9,12:18.3
-6,10,12:18.3
-5,10,12:18.3
-4,10,12:18.3
-3,10,12:18.3
-2,10,12:18.3
-7,-2,13:18.3
-8,-1,13:18.3
-7,-1,13:18.3
-6,-1,13:18.3
-9,0,13:18.3
-8,0,13:18.3
-7,0,13:18.3
-6,0,13:18.3
-3,0,13:17.3
-8,1,13:18.3
-7,1,13:18.3
-4,1,13:17.3
-3,1,13:17.3
-2,1,13:17.3
-9,2,13:18.3
-8,2,13:18.3
-7,2,13:18.3
-3,2,13:17.3
-9,3,13:18.3
-8,3,13:18.3
-4,4,13:18.3
-3,4,13:18.3
-2,4,13:18.3
-1,4,13:18.3
-5,5,13:18.3
-4,5,13:18.3
-3,5,13:18.3
-2,5,13:18.3
-1,5,13:18.3
0,5,13:18.3
-6,6,13:18.3
-5,6,13:18.3
-4,6,13:18.3
-3,6,13:18.3
-2,6,13:18.3
-1,6,13:18.3
0,6,13:18.3
1,6,13:18.3
-7,7,13:18.3
-6,7,13:18.3
-5,7,13:18.3
-4,7,13:18.3
-3,7,13:18.3
-2,7,13:18.3
-1,7,13:18.3
0,7,13:18.3
-7,8,13:18.3
-6,8,13:18.3
-5,8,13:18.3
-4,8,13:18.3
-3,8,13:18.3
-2,8,13:18.3
-1,8,13:18.3
-5,9,13:18.3
-4,9,13:18.3
-3,9,13:18.3
-3,0,14:17.3
-2,0,14:18.3
-4,1,14:17.3
-3,1,14:17.3
-2,1,14:17.3
-1,1,14:18.3
-4,2,14:18.3
-3,2,14:17.3
-2,2,14:18.3
-3,3,14:18.3
-3,5,14:18.3
-2,5,14:18.3
-4,6,14:18.3
-3,6,14:18.3
-2,6,14:18.3
-1,6,14:18.3
-5,7,14:18.3
-4,7,14:18.3
-3,7,14:18.3
-3,-3,15:17.3
-4,-2,15:17.3
-3,-2,15:17.3
-2,-2,15:17.3
-4,-1,15:17.3
-3,-1,15:17.3
-2,-1,15:17.3
-1,-1,15:18.3
-4,0,15:17.3
-3,0,15:17.3
-2,0,15:17.3
-1,0,15:18.3
0,0,15:18.3
-4,1,15:17.3
-3,1,15:17.3
-2,1,15:17.3
-1,1,15:18.3
0,1,15:18.3
-5,2,15:18.3
-4,2,15:18.3
-3,2,15:17.3
-2,2,15:18.3
-1,2,15:18.3
-4,3,15:18.3
-3,3,15:18.3
-2,3,15:18.3
-3,4,15:18.3
-3,-4,16:17.3
-4,-3,16:17.3
-2,-3,16:17.3
-2,-2,16:18.3
-2,-1,16:18.3
-3,0,16:17.3
-2,0,16:18.3
-4,1,16:17.3
-3,1,16:17.3
-2,1,16:17.3
-1,1,16:18.3
-4,2,16:18.3
-3,2,16:17.3
-2,2,16:18.3
-3,3,16:18.3
-4,-6,17:18.3
-3,-6,17:18.3
-2,-6,17:18.3
-5,-5,17:18.3
-4,-5,17:18.3
-3,-5,17:17.3
-2,-5,17:18.3
-1,-5,17:18.3
-4,-4,17:17.3
-3,-4,17:18.3
-2,-4,17:17.3
-1,-4,17:18.3
-4,-3,17:18.3
-2,-3,17:18.3
-3,0,17:17.3
-4,1,17:17.3
-3,1,17:17.3
-2,1,17:17.3
-3,2,17:17.3
-3,-7,18:18.3
-2,-7,18:18.3
-1,-7,18:18.3
-6,-6,18:18.3
-5,-6,18:18.3
-4,-6,18:18.3
-3,-6,18:17.3
-2,-6,18:18.3
-1,-6,18:18.3
0,-6,18:18.3
-6,-5,18:18.3
-5,-5,18:17.3
-4,-5,18:18.3
-3,-5,18:18.3
-2,-5,18:18.3
-1,-5,18:17.3
0,-5,18:18.3
-5,-4,18:18.3
-4,-4,18:18.3
-3,-4,18:18.3
-2,-4,18:18.3
-1,-4,18:18.3
-4,-3,18:18.3
-3,-3,18:18.3
-2,-3,18:18.3
-3,-2,18:18.3
-3,0,18:17.3
-4,1,18:17.3
-3,1,18:17.3
-2,1,18:17.3
-1,1,18:17.7
0,1,18:17.7
-3,2,18:17.3
-2,2,18:17.7
-1,2,18:17.7
-3,3,18:17.3
-3,4,18:17.3
-3,-9,19:18.3
-2,-9,19:18.3
-1,-9,19:18.3
-6,-8,19:18.3
-5,-8,19:18.3
-4,-8,19:18.3
-3,-8,19:18.3
-2,-8,19:18.3
-1,-8,19:18.3
0,-8,19:18.3
-7,-7,19:18.3
-6,-7,19:18.3
-5,-7,19:18.3
-4,-7,19:18.3
-3,-7,19:18.3
-2,-7,19:17.3
-1,-7,19:18.3
0,-7,19:18.3
1,-7,19:18.3
-8,-6,19:18.3
-7,-6,19:18.3
-6,-6,19:17.3
-5,-6,19:18.3
-4,-6,19:18.3
-3,-6,19:18.3
-2,-6,19:18.3
-1,-6,19:18.3
0,-6,19:18.3
1,-6,19:18.3
2,-6,19:18.3
-7,-5,19:18.3
-6,-5,19:18.3
-5,-5,19:18.3
-4,-5,19:18.3
-3,-5,19:18.3
-2,-5,19:18.3
-1,-5,19:18.3
0,-5,19:17.3
1,-5,19:18.3
2,-5,19:18.3
-6,-4,19:18.3
-5,-4,19:18.3
-4,-4,19:18.3
-3,-4,19:18.3
-2,-4,19:18.3
-1,-4,19:18.3
0,-4,19:18.3
1,-4,19:18.3
-5,-3,19:18.3
-4,-3,19:18.3
-3,-3,19:18.3
-2,-3,19:18.3
-1,-3,19:18.3
0,-3,19:18.3
-4,-2,19:18.3
-3,-2,19:18.3
-2,-2,19:18.3
-3,0,19:17.3
-5,1,19:17.7
-4,1,19:17.3
-3,1,19:17.3
-2,1,19:17.3
1,1,19:17.3
-4,2,19:17.3
-3,2,19:17.3
0,2,19:17.3
-3,5,19:17.3
-2,-7,20:18.3
-1,-7,20:18.3
-6,-6,20:18.3
-5,-6,20:18.3
-4,-6,20:18.3
-3,-6,20:18.3
-2,-6,20:18.3
-1,-6,20:18.3
0,-6,20:18.3
-5,-5,20:18.3
-4,-5,20:18.3
-3,-5,20:18.3
-2,-5,20:18.3
-1,-5,20:18.3
0,-5,20:18.3
1,-5,20:18.3
-4,-4,20:18.3
-3,-4,20:18.3
-2,-4,20:18.3
-1,-4,20:18.3
0,-4,20:18.3
-2,-1,20:17.3
-4,0,20:17.3
-3,0,20:17.3
-6,1,20:17.3
-4,1,20:17.3
-3,1,20:17.3
-2,1,20:17.3
2,1,20:17.3
-3,2,20:17.3
-2,2,20:17.3
-5,3,20:17.3
1,3,20:17.3
-3,6,20:17.3
-1,-2,21:17.3
-5,-1,21:17.3
-3,0,21:17.3
3,0,21:17.3
-7,1,21:17.3
-4,1,21:17.3
-3,1,21:17.3
-2,1,21:17.3
-3,2,21:17.3
-1,3,21:17.3
-5,4,21:17.3
2,4,21:17.3
-2,7,21:17.3
-1,-5,22:18.3
0,-5,22:18.3
-3,-4,22:18.3
-2,-4,22:18.3
-1,-4,22:18.3
0,-4,22:18.3
1,-4,22:18.3
-6,-3,22:18.3
-5,-3,22:18.3
-4,-3,22:18.3
-3,-3,22:18.3
-2,-3,22:17.3
-1,-3,22:18.3
0,-3,22:17.3
1,-3,22:18.3
2,-3,22:18.3
-7,-2,22:18.3
-6,-2,22:17.3
-5,-2,22:18.3
-4,-2,22:18.3
-3,-2,22:18.3
-2,-2,22:18.3
-1,-2,22:18.3
0,-2,22:18.3
1,-2,22:18.3
2,-2,22:18.3
3,-2,22:18.3
-8,-1,22:18.3
-7,-1,22:18.3
-6,-1,22:18.3
-5,-1,22:18.3
-4,-1,22:18.3
-3,-1,22:18.3
-2,-1,22:18.3
-1,-1,22:18.3
0,-1,22:18.3
1,-1,22:18.3
2,-1,22:18.3
3,-1,22:18.3
4,-1,22:18.3
-8,0,22:18.3
-7,0,22:18.3
-6,0,22:18.3
-5,0,22:18.3
-4,0,22:18.3
-3,0,22:17.3
-2,0,22:18.3
-1,0,22:18.3
0,0,22:18.3
1,0,22:18.3
2,0,22:18.3
3,0,22:18.3
4,0,22:17.3
5,0,22:18.3
-9,1,22:18.3
-8,1,22:17.3
-7,1,22:18.3
-6,1,22:18.3
-5,1,22:18.3
-4,1,22:17.3
-3,1,22:17.3
-2,1,22:17.3
-1,1,22:18.3
0,1,22:18.3
1,1,22:18.3
2,1,22:18.3
3,1,22:18.3
4,1,22:18.3
-8,2,22:18.3
-7,2,22:18.3
-6,2,22:18.3
-5,2,22:18.3
-4,2,22:18.3
-3,2,22:17.3
-2,2,22:18.3
-1,2,22:18.3
0,2,22:18.3
1,2,22:18.3
2,2,22:18.3
3,2,22:18.3
4,2,22:18.3
-7,3,22:18.3
-6,3,22:18.3
-5,3,22:18.3
-4,3,22:18.3
-3,3,22:18.3
-2,3,22:18.3
-1,3,22:18.3
0,3,22:18.3
1,3,22:18.3
2,3,22:18.3
3,3,22:18.3
4,3,22:18.3
-6,4,22:18.3
-5,4,22:18.3
-4,4,22:18.3
-3,4,22:18.3
-2,4,22:18.3
-1,4,22:17.3
0,4,22:18.3
1,4,22:18.3
2,4,22:18.3
3,4,22:17.3
4,4,22:18.3
-6,5,22:18.3
-5,5,22:17.3
-4,5,22:18.3
-3,5,22:18.3
-2,5,22:18.3
-1,5,22:18.3
0,5,22:18.3
1,5,22:18.3
2,5,22:17.3
3,5,22:18.3
-5,6,22:18.3
-4,6,22:18.3
-3,6,22:18.3
-2,6,22:18.3
-1,6,22:18.3
0,6,22:18.3
1,6,22:18.3
2,6,22:18.3
-4,7,22:18.3
-3,7,22:18.3
-2,7,22:18.3
-1,7,22:18.3
1,7,22:18.3
-3,8,22:18.3
-2,8,22:17.3
-1,8,22:18.3
-2,9,22:18.3
-3,-6,23:18.3
-2,-6,23:18.3
-1,-6,23:18.3
0,-6,23:18.3
1,-6,23:18.3
-5,-5,23:18.3
-4,-5,23:18.3
-3,-5,23:18.3
-2,-5,23:18.3
-1,-5,23:18.3
0,-5,23:18.3
1,-5,23:18.3
2,-5,23:18.3
-7,-4,23:18.3
-6,-4,23:18.3
-5,-4,23:18.3
-4,-4,23:18.3
-3,-4,23:17.3
-2,-4,23:18.3
-1,-4,23:18.3
0,-4,23:17.3
1,-4,23:18.3
2,-4,23:18.3
3,-4,23:18.3
-8,-3,23:18.3
-7,-3,23:18.3
-6,-3,23:18.3
-5,-3,23:18.3
-4,-3,23:18.3
-3,-3,23:18.3
-2,-3,23:18.3
-1,-3,23:18.3
0,-3,23:18.3
1,-3,23:17.3
2,-3,23:18.3
3,-3,23:18.3
4,-3,23:18.3
-9,-2,23:18.3
-8,-2,23:18.3
-7,-2,23:18.3
-6,-2,23:17.3
-5,-2,23:18.3
-4,-2,23:18.3
-3,-2,23:18.3
-2,-2,23:18.3
-1,-2,23:18.3
0,-2,23:18.3
1,-2,23:18.3
2,-2,23:18.3
3,-2,23:18.3
4,-2,23:18.3
-10,-1,23:18.3
-9,-1,23:18.3
-8,-1,23:18.3
-7,-1,23:18.3
-6,-1,23:18.3
-5,-1,23:18.3
-4,-1,23:18.3
-3,-1,23:18.3
-2,-1,23:18.3
-1,-1,23:18.3
0,-1,23:18.3
1,-1,23:18.3
2,-1,23:18.3
3,-1,23:18.3
4,-1,23:18.3
5,-1,23:18.3
-10,0,23:18.3
-9,0,23:18.3
-8,0,23:18.3
-7,0,23:18.3
-6,0,23:18.3
-5,0,23:18.3
-4,0,23:17.3
-3,0,23:18.3
-2,0,23:18.3
-1,0,23:18.3
0,0,23:18.3
1,0,23:18.3
2,0,23:18.3
3,0,23:18.3
4,0,23:17.3
5,0,23:18.3
6,0,23:18.3
-10,1,23:18.3
-9,1,23:17.3
-8,1,23:18.3
-7,1,23:18.3
-6,1,23:18.3
-5,1,23:18.3
-4,1,23:18.3
-3,1,23:18.3
-2,1,23:17.3
-1,1,23:18.3
0,1,23:18.3
1,1,23:18.3
2,1,23:18.3
3,1,23:18.3
4,1,23:18.3
5,1,23:18.3
6,1,23:18.3
-10,2,23:18.3
-9,2,23:18.3
-8,2,23:18.3
-7,2,23:18.3
-6,2,23:18.3
-5,2,23:18.3
-4,2,23:17.3
-3,2,23:18.3
-2,2,23:18.3
-1,2,23:18.3
0,2,23:18.3
1,2,23:18.3
2,2,23:18.3
3,2,23:18.3
4,2,23:18.3
5,2,23:18.3
6,2,23:18.3
-10,3,23:18.3
-9,3,23:18.3
-8,3,23:18.3
-7,3,23:18.3
-6,3,23:18.3
-5,3,23:18.3
-4,3,23:18.3
-3,3,23:18.3
-2,3,23:18.3
-1,3,23:18.3
0,3,23:18.3
1,3,23:18.3
2,3,23:18.3
3,3,23:18.3
4,3,23:18.3
5,3,23:18.3
6,3,23:18.3
-10,4,23:18.3
-9,4,23:18.3
-8,4,23:18.3
-7,4,23:18.3
-6,4,23:18.3
-5,4,23:18.3
-4,4,23:18.3
-3,4,23:18.3
-2,4,23:18.3
-1,4,23:18.3
0,4,23:18.3
1,4,23:18.3
2,4,23:18.3
3,4,23:18.3
4,4,23:17.3
5,4,23:18.3
6,4,23:18.3
-9,5,23:18.3
-8,5,23:18.3
-7,5,23:18.3
-6,5,23:18.3
-5,5,23:18.3
-4,5,23:18.3
-3,5,23:18.3
-2,5,23:18.3
-1,5,23:18.3
0,5,23:17.3
1,5,23:18.3
2,5,23:18.3
3,5,23:18.3
4,5,23:18.3
5,5,23:18.3
-8,6,23:18.3
-7,6,23:18.3
-6,6,23:17.3
-5,6,23:18.3
-4,6,23:18.3
-3,6,23:18.3
-2,6,23:18.3
-1,6,23:18.3
0,6,23:18.3
1,6,23:18.3
2,6,23:17.3
3,6,23:18.3
4,6,23:18.3
-7,7,23:18.3
-6,7,23:18.3
-5,7,23:18.3
-4,7,23:18.3
-3,7,23:18.3
-2,7,23:18.3
-1,7,23:18.3
0,7,23:18.3
1,7,23:18.3
2,7,23:18.3
3,7,23:18.3
-6,8,23:18.3
-5,8,23:18.3
-4,8,23:18.3
-3,8,23:18.3
-2,8,23:18.3
-1,8,23:18.3
0,8,23:18.3
1,8,23:18.3
2,8,23:18.3
-5,9,23:18.3
-4,9,23:18.3
-3,9,23:18.3
-2,9,23:17.3
-1,9,23:18.3
0,9,23:18.3
1,9,23:18.3
-4,10,23:18.3
-3,10,23:18.3
-2,10,23:18.3
-1,10,23:18.3
-1,-5,24:18.3
0,-5,24:18.3
-4,-4,24:18.3
-3,-4,24:18.3
-2,-4,24:18.3
-1,-4,24:18.3
0,-4,24:18.3
1,-4,24:18.3
-6,-3,24:18.3
-5,-3,24:18.3
-4,-3,24:18.3
-3,-3,24:18.3
-2,-3,24:18.3
-1,-3,24:18.3
0,-3,24:18.3
1,-3,24:18.3
2,-3,24:18.3
-7,-2,24:18.3
-6,-2,24:18.3
-5,-2,24:18.3
-4,-2,24:18.3
-3,-2,24:18.3
-2,-2,24:18.3
-1,-2,24:18.3
0,-2,24:18.3
1,-2,24:18.3
2,-2,24:18.3
-8,-1,24:18.3
-7,-1,24:18.3
-6,-1,24:18.3
-5,-1,24:18.3
-4,-1,24:18.3
-3,-1,24:18.3
-2,-1,24:18.3
-1,-1,24:18.3
0,-1,24:18.3
1,-1,24:18.3
2,-1,24:18.3
3,-1,24:18.3
-9,0,24:18.3
-8,0,24:18.3
-7,0,24:18.3
-6,0,24:18.3
-5,0,24:18.3
-4,0,24:18.3
-3,0,24:18.3
-2,0,24:18.3
-1,0,24:18.3
0,0,24:18.3
1,0,24:18.3
2,0,24:18.3
3,0,24:18.3
4,0,24:18.3
-9,1,24:18.3
-8,1,24:18.3
-7,1,24:18.3
-6,1,24:18.3
-5,1,24:18.3
-4,1,24:18.3
-3,1,24:18.3
-2,1,24:18.3
-1,1,24:18.3
0,1,24:18.3
1,1,24:18.3
2,1,24:18.3
3,1,24:18.3
4,1,24:18.3
-9,2,24:18.3
-8,2,24:18.3
-7,2,24:18.3
-6,2,24:18.3
-5,2,24:18.3
-4,2,24:18.3
-3,2,24:18.3
-2,2,24:18.3
-1,2,24:18.3
0,2,24:18.3
1,2,24:18.3
2,2,24:18.3
3,2,24:18.3
4,2,24:18.3
-9,3,24:18.3
-8,3,24:18.3
-7,3,24:18.3
-6,3,24:18.3
-5,3,24:18.3
-4,3,24:18.3
-3,3,24:18.3
-2,3,24:18.3
-1,3,24:18.3
0,3,24:18.3
1,3,24:18.3
2,3,24:18.3
3,3,24:18.3
4,3,24:18.3
-8,4,24:18.3
-7,4,24:18.3
-6,4,24:18.3
-5,4,24:18.3
-4,4,24:18.3
-3,4,24:18.3
-2,4,24:18.3
-1,4,24:18.3
0,4,24:18.3
1,4,24:18.3
2,4,24:18.3
3,4,24:18.3
4,4,24:18.3
-7,5,24:18.3
-6,5,24:18.3
-5,5,24:18.3
-4,5,24:18.3
-3,5,24:18.3
-2,5,24:18.3
-1,5,24:18.3
0,5,24:18.3
1,5,24:18.3
2,5,24:18.3
3,5,24:18.3
-6,6,24:18.3
-5,6,24:18.3
-4,6,24:18.3
-3,6,24:18.3
-2,6,24:18.3
-1,6,24:18.3
0,6,24:18.3
1,6,24:18.3
2,6,24:18.3
-5,7,24:18.3
-4,7,24:18.3
-3,7,24:18.3
-2,7,24:18.3
-1,7,24:18.3
0,7,24:18.3
1,7,24:18.3
-4,8,24:18.3
-3,8,24:18.3
-2,8,24:18.3
-1,8,24:18.3
0,8,24:18.3
-3,9,24:18.3
-2,9,24:18.3
-1,-3,25:18.3
0,-3,25:18.3
-4,-2,25:18.3
-2,-2,25:18.3
-1,-2,25:18.3
0,-2,25:18.3
-6,-1,25:18.3
-5,-1,25:18.3
-4,-1,25:18.3
-2,-1,25:18.3
-1,-1,25:18.3
-7,0,25:18.3
-6,0,25:18.3
-5,0,25:18.3
-4,0,25:18.3
-2,0,25:18.3
1,0,25:18.3
-6,1,25:18.3
-5,1,25:18.3
0,1,25:18.3
1,1,25:18.3
2,1,25:18.3
0,2,25:18.3
1,2,25:18.3
2,2,25:18.3
-6,3,25:18.3
-5,3,25:18.3
0,3,25:18.3
1,3,25:18.3
2,3,25:18.3
-6,4,25:18.3
-5,4,25:18.3
-4,4,25:18.3
2,4,25:18.3
-5,5,25:18.3
-4,5,25:18.3
-3,5,25:18.3
-4,6,25:18.3
-3,6,25:18.3
-1,-3,21:127.8
0,-2,21:127.9
-6,-1,21:127.11
-3,-1,21:127.8
2,0,21:127.11
-5,1,21:127.11
-1,1,21:127.9
-7,2,21:127.10
-2,6,21:127.8
-1,4,21:127.10
-3,3,20:106.4
-3,3,21:106.4
-9,0,22:106.8
5,2,22:106.2
-9,3,22:106.0
-8,3,22:106.8
-2,0,21:106.3
3,6,22:106.2
-5,7,22:106.8
2,7,22:106.4
-4,8,22:106.4
-3,4,21:106.0
-2,0,20:106.7
-3,3,19:106.4
-2,0,19:106.7
-4,2,18:106.8
-5,1,18:106.8
-2,0,18:106.7
-6,-4,18:106.8
1,-6,18:106.2
-3,-8,18:106.1
-2,2,17:106.2
-4,2,17:106.8
-1,1,17:106.2
-5,1,17:106.8
-2,0,17:106.7
-5,1,16:106.8
-5,1,15:106.8
-4,8,14:106.4
-5,8,14:106.4
-6,7,14:106.8
-5,1,14:106.8
-4,0,14:106.1
-3,-1,14:106.1
1,7,13:106.4
-2,2,13:106.2
-4,2,13:106.8
-1,1,13:106.2
-5,1,13:106.8
-2,0,13:106.1
-4,0,13:106.1
-3,-1,13:106.1
-9,-1,13:106.8
-2,2,12:106.2
-4,2,12:106.8
-1,1,12:106.2
-2,0,12:106.1
-4,0,12:106.1
-3,-1,12:106.1
-4,10,11:106.4
-8,7,11:106.8
-9,7,11:106.0
1,6,11:106.2
-2,2,11:106.2
-4,2,11:106.8
-1,1,11:106.2
-9,1,11:106.8
-2,0,11:106.1
-4,0,11:106.1
-3,-1,11:106.1
-2,2,10:106.2
-4,2,10:106.8
-1,1,10:106.2
-2,0,10:106.1
-6,0,10:106.1
-3,-1,10:106.1
-4,2,9:106.8
-2,0,9:106.1
-3,-1,9:106.1
-4,2,8:106.8
-2,0,8:106.1
-3,-1,8:106.1
-4,2,7:106.8
-3,-1,7:106.1
-3,-1,4:106.1
