[META]
version=2.0
spawnOnBlockType=2
spawnSunlight=True
spawnDarkness=True
spawnWater=False
spawnLava=False
underFill=False
randomRotation=True
dig=True
tree=True
branch=False
needsFoundation=True
rarity=25
collisionPercentage=20
spawnElevationMin=0
spawnElevationMax=200
spawnInBiome=Custom
[DATA]
1,-2,-3:17.3
0,-1,-3:17.3
1,-1,-3:17.3
2,-1,-3:17.3
-1,0,-3:17.3
0,0,-3:17.3
1,0,-3:17.3
2,0,-3:17.3
3,0,-3:17.3
0,1,-3:17.3
1,1,-3:17.3
2,1,-3:17.3
0,2,-3:17.3
1,-2,-2:17.3
0,-1,-2:17.3
1,-1,-2:17.3
2,-1,-2:17.3
-1,0,-2:17.3
0,0,-2:17.3
1,0,-2:17.3
2,0,-2:17.3
3,0,-2:17.3
0,1,-2:17.3
1,1,-2:17.3
2,1,-2:17.3
0,2,-2:17.3
1,-2,-1:17.3
0,-1,-1:17.3
1,-1,-1:17.3
2,-1,-1:17.3
-1,0,-1:17.3
0,0,-1:17.3
1,0,-1:17.3
2,0,-1:17.3
3,0,-1:17.3
0,1,-1:17.3
1,1,-1:17.3
2,1,-1:17.3
0,2,-1:17.3
1,-2,0:17.3
0,-1,0:17.3
1,-1,0:17.3
2,-1,0:17.3
-1,0,0:17.3
0,0,0:17.3
1,0,0:17.3
2,0,0:17.3
3,0,0:17.3
0,1,0:17.3
1,1,0:17.3
2,1,0:17.3
0,2,0:17.3
0,-1,1:17.3
1,-1,1:17.3
2,-1,1:17.3
0,0,1:17.3
1,0,1:17.3
2,0,1:17.3
0,1,1:17.3
1,1,1:17.3
2,1,1:17.3
1,-1,2:17.3
2,-1,2:17.3
0,0,2:17.3
1,0,2:17.3
2,0,2:17.3
1,1,2:17.3
1,-1,3:17.3
0,0,3:17.3
1,0,3:17.3
2,0,3:17.3
1,1,3:17.3
1,-1,4:17.3
0,0,4:17.3
1,0,4:17.3
2,0,4:17.3
1,1,4:17.3
1,-1,5:17.3
0,0,5:17.3
1,0,5:17.3
2,0,5:17.3
0,1,5:18.3
1,1,5:17.3
2,1,5:18.3
1,2,5:18.3
0,-2,6:17.3
0,-1,6:17.3
1,-1,6:17.3
-1,0,6:18.3
0,0,6:17.3
1,0,6:17.3
2,0,6:17.3
3,0,6:18.3
-1,1,6:18.3
0,1,6:18.3
1,1,6:17.3
2,1,6:18.3
3,1,6:18.3
0,2,6:18.3
1,2,6:17.3
2,2,6:18.3
1,3,6:18.3
-2,-5,7:17.3
-1,-4,7:17.3
-1,-3,7:17.3
0,-1,7:17.3
1,-1,7:17.3
0,0,7:17.3
1,0,7:17.3
2,0,7:17.3
0,1,7:18.3
1,1,7:17.3
2,1,7:18.3
1,2,7:18.3
-2,-8,8:18.3
-1,-8,8:18.3
-3,-7,8:18.3
-2,-7,8:18.3
-1,-7,8:18.3
0,-7,8:18.3
-4,-6,8:18.3
-3,-6,8:18.3
-2,-6,8:17.3
-1,-6,8:18.3
0,-6,8:18.3
1,-6,8:18.3
-5,-5,8:18.3
-4,-5,8:18.3
-3,-5,8:18.3
-2,-5,8:18.3
-1,-5,8:18.3
0,-5,8:18.3
-3,-4,8:18.3
-2,-4,8:18.3
-1,-4,8:18.3
-2,-3,8:18.3
5,-2,8:17.7
1,-1,8:17.3
2,-1,8:17.7
3,-1,8:17.7
4,-1,8:17.7
0,0,8:17.3
1,0,8:17.3
2,0,8:17.3
3,0,8:17.7
4,0,8:17.7
1,1,8:17.3
2,1,8:17.7
3,1,8:17.7
-2,-10,9:18.3
-1,-10,9:18.3
-3,-9,9:18.3
-2,-9,9:18.3
-1,-9,9:18.3
0,-9,9:18.3
-4,-8,9:18.3
-3,-8,9:18.3
-2,-8,9:18.3
-1,-8,9:18.3
0,-8,9:18.3
1,-8,9:18.3
-5,-7,9:18.3
-4,-7,9:18.3
-3,-7,9:18.3
-2,-7,9:18.3
-1,-7,9:18.3
0,-7,9:18.3
1,-7,9:18.3
-6,-6,9:18.3
-5,-6,9:18.3
-4,-6,9:18.3
-3,-6,9:18.3
-2,-6,9:17.3
-1,-6,9:18.3
0,-6,9:18.3
1,-6,9:18.3
2,-6,9:18.3
-6,-5,9:18.3
-5,-5,9:18.3
-4,-5,9:18.3
-3,-5,9:18.3
-2,-5,9:18.3
-1,-5,9:18.3
0,-5,9:18.3
1,-5,9:18.3
2,-5,9:18.3
-5,-4,9:18.3
-4,-4,9:18.3
-3,-4,9:18.3
-2,-4,9:18.3
-1,-4,9:18.3
0,-4,9:18.3
1,-4,9:18.3
-4,-3,9:18.3
-3,-3,9:18.3
-2,-3,9:18.3
-1,-3,9:18.3
0,-3,9:18.3
6,-3,9:17.3
-3,-2,9:18.3
-2,-2,9:18.3
1,-1,9:17.3
0,0,9:17.3
1,0,9:17.3
2,0,9:17.3
0,1,9:17.7
1,1,9:17.3
5,1,9:17.7
-2,-9,10:18.3
-1,-9,10:18.3
-3,-8,10:18.3
-2,-8,10:18.3
-1,-8,10:18.3
-3,-7,10:18.3
-2,-7,10:18.3
-1,-7,10:18.3
0,-7,10:18.3
-4,-6,10:18.3
-3,-6,10:18.3
-2,-6,10:18.3
-1,-6,10:18.3
0,-6,10:18.3
6,-6,10:18.3
7,-6,10:18.3
-5,-5,10:18.3
-4,-5,10:18.3
-3,-5,10:18.3
-2,-5,10:18.3
-1,-5,10:18.3
0,-5,10:18.3
1,-5,10:18.3
5,-5,10:18.3
6,-5,10:18.3
7,-5,10:18.3
8,-5,10:18.3
9,-5,10:18.3
-4,-4,10:18.3
-3,-4,10:18.3
-2,-4,10:18.3
-1,-4,10:18.3
0,-4,10:18.3
5,-4,10:18.3
6,-4,10:18.3
7,-4,10:17.3
8,-4,10:18.3
9,-4,10:18.3
-3,-3,10:18.3
-2,-3,10:18.3
6,-3,10:18.3
7,-3,10:18.3
8,-3,10:18.3
7,-2,10:18.3
8,-2,10:18.3
1,-1,10:17.3
0,0,10:17.3
1,0,10:17.3
2,0,10:17.3
-2,1,10:17.7
-1,1,10:17.7
0,1,10:17.7
1,1,10:17.3
-3,2,10:17.7
6,2,10:17.3
-2,-7,11:18.3
6,-7,11:18.3
7,-7,11:18.3
-2,-6,11:18.3
-1,-6,11:18.3
5,-6,11:18.3
6,-6,11:18.3
7,-6,11:18.3
8,-6,11:18.3
9,-6,11:18.3
-3,-5,11:18.3
-2,-5,11:18.3
-1,-5,11:18.3
4,-5,11:18.3
5,-5,11:18.3
6,-5,11:18.3
7,-5,11:18.3
8,-5,11:18.3
9,-5,11:18.3
10,-5,11:18.3
-3,-4,11:18.3
4,-4,11:18.3
5,-4,11:18.3
6,-4,11:18.3
7,-4,11:17.3
8,-4,11:18.3
9,-4,11:18.3
10,-4,11:18.3
5,-3,11:18.3
6,-3,11:18.3
7,-3,11:18.3
8,-3,11:18.3
9,-3,11:18.3
6,-2,11:18.3
7,-2,11:18.3
8,-2,11:18.3
9,-2,11:18.3
1,-1,11:17.3
5,-1,11:18.3
6,-1,11:18.3
7,-1,11:18.3
8,-1,11:18.3
0,0,11:17.3
1,0,11:17.3
2,0,11:17.3
4,0,11:18.3
5,0,11:18.3
6,0,11:18.3
7,0,11:18.3
8,0,11:18.3
1,1,11:17.3
4,1,11:18.3
5,1,11:18.3
6,1,11:18.3
7,1,11:18.3
8,1,11:18.3
9,1,11:18.3
3,2,11:18.3
4,2,11:18.3
5,2,11:18.3
6,2,11:17.3
7,2,11:18.3
8,2,11:18.3
9,2,11:18.3
-4,3,11:17.3
3,3,11:18.3
4,3,11:18.3
5,3,11:18.3
6,3,11:18.3
7,3,11:18.3
8,3,11:18.3
4,4,11:18.3
5,4,11:18.3
6,4,11:18.3
7,4,11:18.3
5,5,11:18.3
6,5,11:18.3
7,-6,12:18.3
8,-6,12:18.3
6,-5,12:18.3
7,-5,12:18.3
8,-5,12:18.3
9,-5,12:18.3
5,-4,12:18.3
6,-4,12:18.3
7,-4,12:18.3
8,-4,12:18.3
9,-4,12:18.3
6,-3,12:18.3
7,-3,12:18.3
8,-3,12:18.3
7,-2,12:18.3
8,-2,12:18.3
1,-1,12:17.3
0,0,12:17.3
1,0,12:17.3
2,0,12:17.3
6,0,12:18.3
7,0,12:18.3
-5,1,12:18.3
-4,1,12:18.3
1,1,12:17.3
5,1,12:18.3
6,1,12:18.3
7,1,12:18.3
8,1,12:18.3
-6,2,12:18.3
-5,2,12:18.3
-4,2,12:18.3
5,2,12:18.3
6,2,12:18.3
7,2,12:18.3
8,2,12:18.3
-7,3,12:18.3
-6,3,12:18.3
-5,3,12:18.3
-4,3,12:18.3
-3,3,12:18.3
4,3,12:18.3
5,3,12:18.3
6,3,12:18.3
7,3,12:18.3
-8,4,12:18.3
-7,4,12:18.3
-6,4,12:18.3
-5,4,12:17.3
-4,4,12:18.3
-3,4,12:18.3
-2,4,12:18.3
5,4,12:18.3
6,4,12:18.3
-7,5,12:18.3
-6,5,12:18.3
-5,5,12:18.3
-4,5,12:18.3
-3,5,12:18.3
-6,6,12:18.3
-5,6,12:18.3
-4,6,12:18.3
-3,6,12:18.3
-5,7,12:18.3
-4,7,12:18.3
8,-5,13:18.3
7,-4,13:18.3
8,-4,13:18.3
7,-3,13:18.3
1,-1,13:17.3
-5,0,13:18.3
-4,0,13:18.3
0,0,13:17.3
1,0,13:17.3
2,0,13:17.3
-6,1,13:18.3
-5,1,13:18.3
-4,1,13:18.3
-3,1,13:18.3
1,1,13:17.3
7,1,13:18.3
-7,2,13:18.3
-6,2,13:18.3
-5,2,13:18.3
-4,2,13:18.3
-3,2,13:18.3
-2,2,13:18.3
6,2,13:18.3
7,2,13:18.3
-8,3,13:18.3
-7,3,13:18.3
-6,3,13:18.3
-5,3,13:18.3
-4,3,13:18.3
-3,3,13:18.3
-2,3,13:18.3
-1,3,13:18.3
5,3,13:18.3
6,3,13:18.3
-9,4,13:18.3
-8,4,13:18.3
-7,4,13:18.3
-6,4,13:18.3
-5,4,13:17.3
-4,4,13:18.3
-3,4,13:18.3
-2,4,13:18.3
-1,4,13:18.3
-9,5,13:18.3
-8,5,13:18.3
-7,5,13:18.3
-6,5,13:18.3
-5,5,13:18.3
-4,5,13:18.3
-3,5,13:18.3
-2,5,13:18.3
-1,5,13:18.3
-8,6,13:18.3
-7,6,13:18.3
-6,6,13:18.3
-5,6,13:18.3
-4,6,13:18.3
-3,6,13:18.3
-2,6,13:18.3
-7,7,13:18.3
-6,7,13:18.3
-5,7,13:18.3
-4,7,13:18.3
-3,7,13:18.3
-5,8,13:18.3
-4,8,13:18.3
1,-2,14:18.3
0,-1,14:18.3
1,-1,14:17.3
2,-1,14:18.3
0,0,14:17.3
1,0,14:17.3
2,0,14:17.3
-4,1,14:18.3
1,1,14:17.3
-6,2,14:18.3
-5,2,14:18.3
-4,2,14:18.3
-3,2,14:18.3
-7,3,14:18.3
-6,3,14:18.3
-5,3,14:18.3
-4,3,14:18.3
-3,3,14:18.3
-7,4,14:18.3
-6,4,14:18.3
-5,4,14:18.3
-4,4,14:18.3
-3,4,14:18.3
-2,4,14:18.3
-8,5,14:18.3
-7,5,14:18.3
-6,5,14:18.3
-5,5,14:18.3
-4,5,14:18.3
-3,5,14:18.3
-7,6,14:18.3
-6,6,14:18.3
-5,6,14:18.3
-4,6,14:18.3
-3,6,14:18.3
-5,7,14:18.3
-4,7,14:18.3
0,-3,15:18.3
1,-3,15:18.3
2,-3,15:18.3
-1,-2,15:18.3
0,-2,15:18.3
1,-2,15:17.3
2,-2,15:18.3
3,-2,15:18.3
-1,-1,15:18.3
0,-1,15:18.3
1,-1,15:17.3
2,-1,15:18.3
3,-1,15:18.3
-1,0,15:18.3
0,0,15:17.3
1,0,15:17.3
2,0,15:17.3
1,1,15:17.3
-5,3,15:18.3
-5,4,15:18.3
-4,4,15:18.3
-6,5,15:18.3
-5,5,15:18.3
-4,5,15:18.3
-5,6,15:18.3
1,-3,16:18.3
0,-2,16:18.3
1,-2,16:18.3
2,-2,16:18.3
-1,-1,16:18.3
0,-1,16:18.3
1,-1,16:17.3
2,-1,16:18.3
3,-1,16:18.3
-1,0,16:18.3
0,0,16:17.3
1,0,16:17.3
2,0,16:17.3
3,0,16:18.3
0,1,16:18.3
1,1,16:17.3
2,1,16:18.3
3,1,16:18.3
1,2,16:18.3
2,2,16:18.3
1,-1,17:17.3
0,0,17:17.3
1,0,17:17.3
2,0,17:17.3
3,0,17:18.3
0,1,17:18.3
1,1,17:17.3
2,1,17:18.3
3,1,17:18.3
4,1,17:18.3
0,2,17:18.3
1,2,17:18.3
2,2,17:17.3
3,2,17:18.3
4,2,17:18.3
1,3,17:18.3
2,3,17:18.3
3,3,17:18.3
0,-3,18:17.3
1,-2,18:17.3
1,-1,18:17.3
0,0,18:17.3
1,0,18:17.3
2,0,18:17.3
1,1,18:17.3
2,1,18:18.3
3,1,18:18.3
1,2,18:18.3
2,2,18:18.3
-1,-4,19:17.3
1,-1,19:17.3
2,-1,19:17.7
5,-1,19:17.7
0,0,19:17.3
1,0,19:17.3
2,0,19:17.3
3,0,19:17.7
4,0,19:17.7
1,1,19:17.3
2,1,19:17.3
2,2,19:17.3
-2,-6,20:18.3
-3,-5,20:18.3
-2,-5,20:17.3
-1,-5,20:18.3
0,-5,20:18.3
4,-5,20:18.3
-3,-4,20:18.3
-2,-4,20:18.3
-1,-4,20:18.3
0,-4,20:17.3
1,-4,20:18.3
3,-4,20:18.3
4,-4,20:18.3
5,-4,20:18.3
-2,-3,20:18.3
-1,-3,20:18.3
0,-3,20:18.3
1,-3,20:18.3
2,-3,20:18.3
3,-3,20:18.3
4,-3,20:18.3
5,-3,20:18.3
6,-3,20:18.3
7,-3,20:18.3
-3,-2,20:18.3
-2,-2,20:18.3
-1,-2,20:18.3
0,-2,20:18.3
1,-2,20:17.3
2,-2,20:18.3
3,-2,20:17.3
4,-2,20:18.3
5,-2,20:18.3
6,-2,20:17.3
7,-2,20:18.3
8,-2,20:18.3
-4,-1,20:18.3
-3,-1,20:17.7
-2,-1,20:18.3
-1,-1,20:18.3
0,-1,20:18.3
1,-1,20:17.3
2,-1,20:18.3
3,-1,20:18.3
4,-1,20:18.3
5,-1,20:18.3
6,-1,20:18.3
7,-1,20:18.3
-3,0,20:18.3
-2,0,20:17.7
-1,0,20:17.7
0,0,20:17.3
1,0,20:17.3
2,0,20:17.3
3,0,20:18.3
4,0,20:18.3
5,0,20:18.3
6,0,20:18.3
7,0,20:18.3
-2,1,20:18.3
-1,1,20:18.3
0,1,20:17.3
1,1,20:17.3
2,1,20:18.3
3,1,20:18.3
4,1,20:18.3
5,1,20:17.3
6,1,20:18.3
-3,2,20:18.3
-2,2,20:18.3
-1,2,20:17.7
0,2,20:18.3
1,2,20:18.3
2,2,20:18.3
3,2,20:17.3
4,2,20:18.3
5,2,20:18.3
-3,3,20:18.3
-2,3,20:17.3
-1,3,20:18.3
0,3,20:18.3
1,3,20:17.3
2,3,20:18.3
3,3,20:18.3
4,3,20:18.3
-3,4,20:18.3
-2,4,20:17.3
-1,4,20:18.3
0,4,20:18.3
1,4,20:18.3
-4,5,20:18.3
-3,5,20:18.3
-2,5,20:18.3
-1,5,20:18.3
-2,6,20:18.3
3,-7,21:18.3
4,-7,21:18.3
-2,-6,21:18.3
2,-6,21:18.3
3,-6,21:18.3
4,-6,21:18.3
5,-6,21:18.3
7,-6,21:18.3
8,-6,21:18.3
-3,-5,21:18.3
-2,-5,21:18.3
-1,-5,21:18.3
1,-5,21:18.3
2,-5,21:18.3
3,-5,21:18.3
4,-5,21:18.3
5,-5,21:18.3
6,-5,21:18.3
7,-5,21:18.3
8,-5,21:18.3
9,-5,21:18.3
-4,-4,21:18.3
-3,-4,21:18.3
-2,-4,21:18.3
-1,-4,21:18.3
0,-4,21:18.3
1,-4,21:18.3
2,-4,21:18.3
3,-4,21:18.3
4,-4,21:18.3
5,-4,21:18.3
6,-4,21:18.3
7,-4,21:18.3
8,-4,21:18.3
9,-4,21:18.3
10,-4,21:18.3
-5,-3,21:18.3
-4,-3,21:18.3
-3,-3,21:18.3
-2,-3,21:18.3
-1,-3,21:18.3
0,-3,21:18.3
1,-3,21:17.3
2,-3,21:18.3
3,-3,21:18.3
4,-3,21:17.3
5,-3,21:18.3
6,-3,21:18.3
7,-3,21:17.3
8,-3,21:18.3
9,-3,21:18.3
10,-3,21:18.3
-6,-2,21:18.3
-5,-2,21:18.3
-4,-2,21:18.3
-3,-2,21:18.3
-2,-2,21:18.3
-1,-2,21:18.3
0,-2,21:18.3
1,-2,21:18.3
2,-2,21:18.3
3,-2,21:18.3
4,-2,21:18.3
5,-2,21:18.3
6,-2,21:18.3
7,-2,21:18.3
8,-2,21:18.3
9,-2,21:18.3
-6,-1,21:18.3
-5,-1,21:18.3
-4,-1,21:17.3
-3,-1,21:18.3
-2,-1,21:18.3
-1,-1,21:18.3
0,-1,21:17.3
1,-1,21:17.3
2,-1,21:18.3
3,-1,21:18.3
4,-1,21:18.3
5,-1,21:18.3
6,-1,21:18.3
7,-1,21:18.3
8,-1,21:18.3
9,-1,21:18.3
-5,0,21:18.3
-4,0,21:18.3
-3,0,21:18.3
-2,0,21:18.3
-1,0,21:18.3
0,0,21:17.3
1,0,21:17.3
2,0,21:17.3
3,0,21:17.3
4,0,21:18.3
5,0,21:18.3
6,0,21:18.3
7,0,21:18.3
8,0,21:18.3
9,0,21:18.3
-5,1,21:18.3
-4,1,21:18.3
-3,1,21:18.3
-2,1,21:18.3
-1,1,21:17.3
0,1,21:18.3
1,1,21:17.3
2,1,21:18.3
3,1,21:18.3
4,1,21:18.3
5,1,21:18.3
6,1,21:17.3
7,1,21:18.3
8,1,21:18.3
-4,2,21:18.3
-3,2,21:18.3
-2,2,21:18.3
-1,2,21:18.3
0,2,21:17.3
1,2,21:18.3
2,2,21:18.3
3,2,21:18.3
4,2,21:18.3
5,2,21:18.3
6,2,21:18.3
7,2,21:18.3
-4,3,21:18.3
-3,3,21:18.3
-2,3,21:18.3
-1,3,21:18.3
0,3,21:18.3
1,3,21:18.3
2,3,21:18.3
3,3,21:18.3
4,3,21:17.3
5,3,21:18.3
6,3,21:18.3
-5,4,21:18.3
-4,4,21:18.3
-3,4,21:18.3
-2,4,21:18.3
-1,4,21:18.3
0,4,21:18.3
1,4,21:17.3
2,4,21:18.3
3,4,21:18.3
4,4,21:18.3
5,4,21:18.3
-5,5,21:18.3
-4,5,21:18.3
-3,5,21:17.3
-2,5,21:18.3
-1,5,21:18.3
0,5,21:18.3
1,5,21:18.3
2,5,21:18.3
4,5,21:18.3
-4,6,21:18.3
-3,6,21:18.3
-2,6,21:18.3
-1,6,21:18.3
1,6,21:18.3
-3,7,21:18.3
-2,7,21:18.3
3,-6,22:18.3
4,-6,22:18.3
-4,-5,22:18.3
-3,-5,22:18.3
2,-5,22:18.3
3,-5,22:18.3
4,-5,22:18.3
5,-5,22:18.3
8,-5,22:18.3
-6,-4,22:18.3
-5,-4,22:18.3
-4,-4,22:18.3
-3,-4,22:18.3
-2,-4,22:18.3
1,-4,22:18.3
2,-4,22:17.3
3,-4,22:18.3
4,-4,22:18.3
5,-4,22:18.3
6,-4,22:18.3
7,-4,22:18.3
8,-4,22:18.3
9,-4,22:18.3
-7,-3,22:18.3
-6,-3,22:18.3
-5,-3,22:18.3
-4,-3,22:18.3
-3,-3,22:18.3
-2,-3,22:18.3
-1,-3,22:18.3
0,-3,22:18.3
1,-3,22:18.3
2,-3,22:18.3
3,-3,22:18.3
4,-3,22:18.3
5,-3,22:18.3
6,-3,22:18.3
7,-3,22:18.3
8,-3,22:18.3
9,-3,22:18.3
-8,-2,22:18.3
-7,-2,22:18.3
-6,-2,22:18.3
-5,-2,22:17.3
-4,-2,22:18.3
-3,-2,22:18.3
-2,-2,22:18.3
-1,-2,22:17.3
0,-2,22:18.3
1,-2,22:18.3
2,-2,22:18.3
3,-2,22:18.3
4,-2,22:18.3
5,-2,22:18.3
6,-2,22:18.3
7,-2,22:18.3
8,-2,22:18.3
-8,-1,22:18.3
-7,-1,22:18.3
-6,-1,22:18.3
-5,-1,22:18.3
-4,-1,22:18.3
-3,-1,22:18.3
-2,-1,22:18.3
-1,-1,22:18.3
0,-1,22:18.3
1,-1,22:17.3
2,-1,22:18.3
3,-1,22:18.3
4,-1,22:18.3
5,-1,22:18.3
6,-1,22:18.3
7,-1,22:18.3
8,-1,22:18.3
-7,0,22:18.3
-6,0,22:18.3
-5,0,22:18.3
-4,0,22:18.3
-3,0,22:18.3
-2,0,22:18.3
-1,0,22:18.3
0,0,22:17.3
1,0,22:17.3
2,0,22:18.3
3,0,22:18.3
4,0,22:17.3
5,0,22:18.3
6,0,22:18.3
7,0,22:18.3
-6,1,22:18.3
-5,1,22:18.3
-4,1,22:18.3
-3,1,22:18.3
-2,1,22:17.3
-1,1,22:18.3
0,1,22:18.3
1,1,22:17.3
2,1,22:18.3
3,1,22:18.3
4,1,22:18.3
5,1,22:18.3
6,1,22:18.3
-4,2,22:18.3
-3,2,22:18.3
-2,2,22:18.3
-1,2,22:18.3
0,2,22:18.3
1,2,22:18.3
2,2,22:18.3
3,2,22:18.3
4,2,22:18.3
5,2,22:18.3
-3,3,22:18.3
-2,3,22:18.3
-1,3,22:17.3
0,3,22:18.3
1,3,22:18.3
2,3,22:18.3
3,3,22:18.3
4,3,22:18.3
-3,4,22:18.3
-2,4,22:18.3
-1,4,22:18.3
0,4,22:18.3
1,4,22:18.3
2,4,22:18.3
3,4,22:18.3
4,4,22:18.3
-4,5,22:18.3
-3,5,22:18.3
-2,5,22:18.3
-1,5,22:18.3
0,5,22:18.3
1,5,22:17.3
2,5,22:18.3
3,5,22:18.3
-3,6,22:18.3
-2,6,22:18.3
0,6,22:18.3
1,6,22:18.3
2,6,22:18.3
3,6,22:18.3
1,7,22:18.3
2,7,22:18.3
3,-5,23:18.3
-3,-4,23:18.3
2,-4,23:18.3
3,-4,23:18.3
4,-4,23:18.3
-5,-3,23:18.3
-4,-3,23:18.3
-3,-3,23:18.3
-2,-3,23:18.3
2,-3,23:18.3
3,-3,23:18.3
4,-3,23:18.3
5,-3,23:18.3
6,-3,23:18.3
-6,-2,23:18.3
-5,-2,23:18.3
-4,-2,23:18.3
-3,-2,23:18.3
-2,-2,23:18.3
-1,-2,23:18.3
1,-2,23:18.3
2,-2,23:18.3
3,-2,23:18.3
4,-2,23:18.3
5,-2,23:18.3
6,-2,23:18.3
7,-2,23:18.3
-7,-1,23:18.3
-6,-1,23:18.3
-5,-1,23:18.3
-4,-1,23:18.3
-3,-1,23:18.3
-2,-1,23:18.3
-1,-1,23:18.3
1,-1,23:18.3
2,-1,23:18.3
3,-1,23:18.3
4,-1,23:18.3
5,-1,23:18.3
6,-1,23:18.3
-5,0,23:18.3
-4,0,23:18.3
-3,0,23:18.3
-2,0,23:18.3
-1,0,23:18.3
0,0,23:18.3
1,0,23:18.3
2,0,23:18.3
3,0,23:18.3
4,0,23:18.3
-3,1,23:18.3
-2,1,23:18.3
-1,1,23:18.3
0,1,23:18.3
1,1,23:18.3
2,1,23:18.3
3,1,23:18.3
4,1,23:18.3
-2,2,23:18.3
-1,2,23:18.3
0,2,23:18.3
1,2,23:18.3
2,2,23:18.3
3,2,23:18.3
-2,3,23:18.3
-1,3,23:18.3
0,3,23:18.3
1,3,23:18.3
2,3,23:18.3
-2,4,23:18.3
-1,4,23:18.3
0,4,23:18.3
1,4,23:18.3
2,4,23:18.3
-3,5,23:18.3
-2,5,23:18.3
1,5,23:18.3
2,5,23:18.3
2,6,23:18.3
0,-1,19:127.11
0,1,19:127.11
3,1,19:127.9
-4,4,11:106.4
-4,3,20:106.8
7,2,20:106.0
6,2,20:106.2
6,-4,20:106.2
1,-5,20:106.2
-1,-6,20:106.1
5,4,20:106.0
-1,-6,21:106.1
0,-5,21:106.2
2,2,15:106.0
1,2,15:106.4
2,1,15:106.2
1,2,14:106.4
2,1,14:106.2
-1,0,14:106.8
1,2,13:106.4
2,1,13:106.2
0,1,13:106.8
-1,0,13:106.8
1,2,12:106.4
2,1,12:106.2
0,1,12:106.8
-1,0,12:106.8
5,3,20:106.4
-5,3,11:106.8
1,2,11:106.4
2,1,11:106.2
0,1,11:106.12
-1,0,11:106.8
7,3,10:106.0
6,3,10:106.4
7,2,10:106.2
1,2,10:106.4
6,1,10:106.1
2,1,10:106.2
-1,0,10:106.8
1,2,9:106.4
2,1,9:106.2
-1,0,9:106.8
6,-2,9:106.4
7,-3,9:106.2
6,-4,9:106.1
1,2,8:106.4
-1,0,8:106.8
4,-2,8:106.1
1,-2,8:106.1
-1,0,7:106.8
1,-2,7:106.1
0,-2,7:106.1
1,-2,6:106.1
0,-1,5:106.8
1,-2,5:106.1
