[META]
version=2.0
spawnOnBlockType=2
spawnSunlight=True
spawnDarkness=True
spawnWater=False
spawnLava=False
underFill=False
randomRotation=True
dig=True
tree=True
branch=False
needsFoundation=True
rarity=25
collisionPercentage=20
spawnElevationMin=0
spawnElevationMax=200
spawnInBiome=Custom
[DATA]
-1,0,0:17.3
-1,0,1:17.3
-1,0,2:17.3
-1,-1,3:18.3
0,-1,3:18.3
-2,0,3:18.3
-1,0,3:17.3
0,0,3:18.3
1,0,3:18.3
-1,1,3:17.3
0,1,3:18.3
1,1,3:18.3
-1,2,3:17.3
0,2,3:18.3
-1,0,4:17.3
0,0,4:18.3
0,1,4:18.3
-2,2,4:18.3
-1,2,4:18.3
-4,3,4:18.3
-3,3,4:18.3
-2,3,4:17.3
-1,3,4:18.3
-5,4,4:18.3
-4,4,4:18.3
-3,4,4:18.3
-2,4,4:18.3
-1,4,4:18.3
-4,5,4:18.3
-3,5,4:18.3
-2,5,4:18.3
-1,-1,5:17.3
-1,0,5:17.3
-3,1,5:18.3
-2,1,5:18.3
-5,2,5:18.3
-4,2,5:18.3
-3,2,5:18.3
-2,2,5:18.3
-1,2,5:18.3
-5,3,5:18.3
-4,3,5:18.3
-3,3,5:18.3
-2,3,5:18.3
-1,3,5:18.3
0,3,5:18.3
-6,4,5:18.3
-5,4,5:18.3
-4,4,5:18.3
-3,4,5:17.3
-2,4,5:18.3
-1,4,5:18.3
0,4,5:18.3
-6,5,5:18.3
-5,5,5:18.3
-4,5,5:18.3
-3,5,5:18.3
-2,5,5:18.3
-1,5,5:18.3
0,5,5:18.3
-5,6,5:18.3
-4,6,5:18.3
-3,6,5:18.3
-2,6,5:18.3
-1,6,5:18.3
-3,7,5:18.3
-2,7,5:18.3
-1,-5,6:18.3
-2,-4,6:18.3
-1,-4,6:18.3
0,-4,6:18.3
-2,-3,6:18.3
-1,-3,6:18.3
0,-3,6:18.3
1,-3,6:18.3
2,-3,6:18.3
-3,-2,6:18.3
-2,-2,6:18.3
-1,-2,6:17.3
0,-2,6:18.3
1,-2,6:18.3
-2,-1,6:18.3
-1,-1,6:18.3
0,-1,6:18.3
-1,0,6:17.3
-3,2,6:18.3
-2,2,6:18.3
-4,3,6:18.3
-3,3,6:18.3
-2,3,6:18.3
-5,4,6:18.3
-4,4,6:18.3
-3,4,6:18.3
-2,4,6:18.3
-1,4,6:18.3
-5,5,6:18.3
-4,5,6:18.3
-3,5,6:18.3
-2,5,6:18.3
-1,5,6:18.3
-3,6,6:18.3
-2,6,6:18.3
-2,-6,7:18.3
-1,-6,7:18.3
0,-6,7:18.3
-3,-5,7:18.3
-2,-5,7:18.3
-1,-5,7:18.3
0,-5,7:18.3
1,-5,7:18.3
-3,-4,7:18.3
-2,-4,7:18.3
-1,-4,7:18.3
0,-4,7:18.3
1,-4,7:18.3
2,-4,7:18.3
-4,-3,7:18.3
-3,-3,7:18.3
-2,-3,7:18.3
-1,-3,7:17.3
0,-3,7:18.3
1,-3,7:18.3
2,-3,7:18.3
3,-3,7:18.3
-4,-2,7:18.3
-3,-2,7:18.3
-2,-2,7:18.3
-1,-2,7:18.3
0,-2,7:18.3
1,-2,7:18.3
2,-2,7:18.3
3,-2,7:18.3
-3,-1,7:18.3
-2,-1,7:18.3
-1,-1,7:18.3
0,-1,7:18.3
1,-1,7:18.3
2,-1,7:18.3
-3,0,7:18.3
-2,0,7:18.3
-1,0,7:17.3
0,0,7:18.3
1,0,7:18.3
2,0,7:18.3
-2,1,7:18.3
-1,1,7:18.3
0,1,7:18.3
-3,3,7:18.3
-4,4,7:18.3
-3,4,7:18.3
-2,4,7:18.3
-2,5,7:18.3
-1,-5,8:18.3
0,-5,8:18.3
-2,-4,8:18.3
-1,-4,8:18.3
0,-4,8:18.3
1,-4,8:18.3
-3,-3,8:18.3
-2,-3,8:18.3
-1,-3,8:18.3
0,-3,8:18.3
1,-3,8:18.3
2,-3,8:18.3
-3,-2,8:18.3
-2,-2,8:18.3
-1,-2,8:18.3
0,-2,8:18.3
1,-2,8:18.3
-2,-1,8:18.3
-1,-1,8:18.3
0,-1,8:18.3
1,-1,8:18.3
-2,0,8:18.3
-1,0,8:17.3
0,0,8:18.3
-1,1,8:18.3
0,-4,9:18.3
-2,-3,9:18.3
-1,-3,9:18.3
0,-3,9:18.3
1,-3,9:18.3
-1,-2,9:18.3
0,-2,9:18.3
-1,0,9:17.3
-1,-1,10:18.3
-1,0,10:17.3
-2,1,10:18.3
0,1,10:18.3
1,2,10:18.3
-1,-3,11:18.3
0,-3,11:18.3
-2,-2,11:18.3
-1,-2,11:18.3
0,-2,11:18.3
1,-2,11:18.3
-2,-1,11:18.3
-1,-1,11:17.3
0,-1,11:18.3
1,-1,11:18.3
-3,0,11:18.3
-2,0,11:18.3
-1,0,11:17.3
0,0,11:18.3
1,0,11:18.3
-4,1,11:18.3
-3,1,11:18.3
-2,1,11:17.3
-1,1,11:18.3
0,1,11:17.3
1,1,11:18.3
2,1,11:18.3
-5,2,11:18.3
-4,2,11:18.3
-3,2,11:18.3
-2,2,11:18.3
-1,2,11:18.3
0,2,11:18.3
1,2,11:17.3
2,2,11:18.3
-4,3,11:18.3
-3,3,11:18.3
-2,3,11:18.3
-1,3,11:18.3
0,3,11:18.3
1,3,11:18.3
-3,4,11:18.3
-2,4,11:18.3
-1,-4,12:18.3
0,-4,12:18.3
1,-4,12:18.3
-2,-3,12:18.3
-1,-3,12:18.3
0,-3,12:18.3
1,-3,12:18.3
2,-3,12:18.3
-3,-2,12:18.3
-2,-2,12:18.3
-1,-2,12:18.3
0,-2,12:17.3
1,-2,12:18.3
2,-2,12:18.3
3,-2,12:18.3
-4,-1,12:18.3
-3,-1,12:18.3
-2,-1,12:18.3
-1,-1,12:18.3
0,-1,12:18.3
1,-1,12:18.3
2,-1,12:18.3
3,-1,12:18.3
-4,0,12:18.3
-3,0,12:18.3
-2,0,12:18.3
-1,0,12:17.3
0,0,12:18.3
1,0,12:18.3
2,0,12:18.3
-5,1,12:18.3
-4,1,12:18.3
-3,1,12:18.3
-2,1,12:18.3
-1,1,12:18.3
0,1,12:18.3
1,1,12:18.3
2,1,12:18.3
3,1,12:18.3
-6,2,12:18.3
-5,2,12:18.3
-4,2,12:18.3
-3,2,12:17.3
-2,2,12:18.3
-1,2,12:18.3
0,2,12:18.3
1,2,12:17.3
2,2,12:18.3
3,2,12:18.3
-5,3,12:18.3
-4,3,12:18.3
-3,3,12:18.3
-2,3,12:18.3
-1,3,12:18.3
0,3,12:18.3
1,3,12:18.3
2,3,12:18.3
3,3,12:18.3
-5,4,12:18.3
-4,4,12:18.3
-3,4,12:18.3
-2,4,12:18.3
-1,4,12:18.3
0,4,12:18.3
1,4,12:18.3
2,4,12:18.3
-4,5,12:18.3
-3,5,12:18.3
-2,5,12:18.3
0,5,12:18.3
1,5,12:18.3
-3,6,12:18.3
-2,-6,13:18.3
-1,-6,13:18.3
-3,-5,13:18.3
-2,-5,13:18.3
-1,-5,13:18.3
0,-5,13:18.3
1,-5,13:18.3
-4,-4,13:18.3
-3,-4,13:18.3
-2,-4,13:18.3
-1,-4,13:18.3
0,-4,13:18.3
1,-4,13:18.3
2,-4,13:18.3
-4,-3,13:18.3
-3,-3,13:18.3
-2,-3,13:18.3
-1,-3,13:17.3
0,-3,13:18.3
1,-3,13:18.3
2,-3,13:18.3
3,-3,13:18.3
-5,-2,13:18.3
-4,-2,13:18.3
-3,-2,13:18.3
-2,-2,13:18.3
-1,-2,13:18.3
0,-2,13:18.3
1,-2,13:17.3
2,-2,13:18.3
3,-2,13:18.3
4,-2,13:18.3
-5,-1,13:18.3
-4,-1,13:18.3
-3,-1,13:18.3
-2,-1,13:18.3
-1,-1,13:18.3
0,-1,13:18.3
1,-1,13:18.3
2,-1,13:18.3
3,-1,13:18.3
4,-1,13:18.3
-6,0,13:18.3
-5,0,13:18.3
-4,0,13:18.3
-3,0,13:18.3
-2,0,13:17.3
-1,0,13:18.3
0,0,13:17.3
1,0,13:18.3
2,0,13:18.3
3,0,13:18.3
4,0,13:18.3
-6,1,13:18.3
-5,1,13:18.3
-4,1,13:18.3
-3,1,13:18.3
-2,1,13:18.3
-1,1,13:18.3
0,1,13:18.3
1,1,13:18.3
2,1,13:17.3
3,1,13:18.3
4,1,13:18.3
5,1,13:18.3
-7,2,13:18.3
-6,2,13:18.3
-5,2,13:18.3
-4,2,13:17.3
-3,2,13:18.3
-2,2,13:18.3
-1,2,13:18.3
0,2,13:18.3
1,2,13:18.3
2,2,13:18.3
3,2,13:18.3
4,2,13:18.3
5,2,13:18.3
-7,3,13:18.3
-6,3,13:18.3
-5,3,13:18.3
-4,3,13:18.3
-3,3,13:18.3
-2,3,13:17.3
-1,3,13:18.3
0,3,13:17.3
1,3,13:18.3
2,3,13:18.3
3,3,13:18.3
4,3,13:18.3
-6,4,13:18.3
-5,4,13:18.3
-4,4,13:18.3
-3,4,13:18.3
-2,4,13:18.3
-1,4,13:18.3
0,4,13:18.3
1,4,13:18.3
2,4,13:18.3
3,4,13:18.3
-5,5,13:18.3
-4,5,13:18.3
-3,5,13:18.3
-2,5,13:18.3
-1,5,13:18.3
0,5,13:18.3
1,5,13:18.3
2,5,13:18.3
-4,6,13:18.3
-3,6,13:18.3
-2,6,13:18.3
-1,6,13:18.3
0,6,13:18.3
1,6,13:18.3
-2,7,13:18.3
-1,7,13:18.3
-2,-5,14:18.3
-1,-5,14:18.3
-3,-4,14:18.3
-2,-4,14:18.3
-1,-4,14:18.3
0,-4,14:18.3
1,-4,14:18.3
-3,-3,14:18.3
-2,-3,14:18.3
-1,-3,14:18.3
0,-3,14:18.3
1,-3,14:18.3
2,-3,14:18.3
-4,-2,14:18.3
-3,-2,14:18.3
-2,-2,14:18.3
-1,-2,14:18.3
0,-2,14:18.3
1,-2,14:18.3
2,-2,14:18.3
-4,-1,14:18.3
-3,-1,14:18.3
-2,-1,14:18.3
-1,-1,14:18.3
0,-1,14:18.3
1,-1,14:18.3
2,-1,14:18.3
3,-1,14:18.3
-4,0,14:18.3
-3,0,14:18.3
-2,0,14:18.3
-1,0,14:18.3
0,0,14:18.3
1,0,14:18.3
2,0,14:18.3
3,0,14:18.3
-5,1,14:18.3
-4,1,14:18.3
-3,1,14:18.3
-2,1,14:18.3
-1,1,14:18.3
0,1,14:18.3
1,1,14:18.3
2,1,14:18.3
3,1,14:18.3
4,1,14:18.3
-5,2,14:18.3
-4,2,14:18.3
-3,2,14:18.3
-2,2,14:18.3
-1,2,14:18.3
0,2,14:18.3
1,2,14:18.3
2,2,14:18.3
3,2,14:18.3
4,2,14:18.3
-6,3,14:18.3
-5,3,14:18.3
-4,3,14:18.3
-3,3,14:18.3
-2,3,14:18.3
-1,3,14:18.3
0,3,14:18.3
1,3,14:18.3
2,3,14:18.3
3,3,14:18.3
-5,4,14:18.3
-4,4,14:18.3
-3,4,14:18.3
-2,4,14:18.3
-1,4,14:18.3
0,4,14:18.3
1,4,14:18.3
2,4,14:18.3
-3,5,14:18.3
-2,5,14:18.3
-1,5,14:18.3
0,5,14:18.3
1,5,14:18.3
-2,6,14:18.3
-1,6,14:18.3
-1,-4,15:18.3
-2,-3,15:18.3
-1,-3,15:18.3
-3,-2,15:18.3
-2,-2,15:18.3
-1,-2,15:18.3
0,-2,15:18.3
-2,-1,15:18.3
1,0,15:18.3
2,0,15:18.3
-1,1,15:18.3
0,1,15:18.3
2,1,15:18.3
3,1,15:18.3
-2,2,15:18.3
-1,2,15:18.3
0,2,15:18.3
2,2,15:18.3
3,2,15:18.3
-3,3,15:18.3
-2,3,15:18.3
-1,3,15:18.3
-2,4,15:18.3
-1,4,15:18.3
0,0,10:127.9
-2,0,10:127.11
-1,1,10:127.10
-4,-2,12:106.8
2,-1,11:106.2
0,2,10:106.4
-3,5,11:106.4
-4,4,11:106.8
-3,-3,12:106.1
-3,-1,8:106.4
-3,5,7:106.4
0,2,7:106.4
-1,1,6:106.4
0,0,6:106.2
-2,0,6:106.8
-3,6,4:106.4
