[META]
version=2.0
spawnOnBlockType=2,12
spawnSunlight=True
spawnDarkness=True
spawnWater=False
spawnLava=False
underFill=False
randomRotation=True
dig=True
tree=True
branch=False
needsFoundation=True
rarity=25
collisionPercentage=20
spawnElevationMin=0
spawnElevationMax=55
spawnInBiome=Custom
[DATA]
-4,1,-4:17.3
-4,2,-4:17.3
-4,1,-3:17.3
-4,2,-3:17.3
-4,1,-2:17.3
-4,1,-1:17.3
-4,1,0:17.3
-3,1,0:17.3
-3,2,1:17.3
-2,2,1:17.3
-2,1,2:17.3
-1,1,2:17.3
0,1,2:17.3
1,-1,3:17.3
0,0,3:17.3
1,0,3:17.3
1,-1,4:17.3
2,-5,5:18.3
-2,-1,5:18.3
1,-1,5:17.3
2,-1,5:17.3
6,-1,5:18.3
2,3,5:18.3
2,-5,6:18.3
2,-2,6:18.3
-2,-1,6:18.3
2,-1,6:17.3
3,-1,6:18.3
6,-1,6:18.3
2,0,6:18.3
3,0,6:0
2,3,6:18.3
2,-4,7:18.3
2,-2,7:18.3
3,-2,7:18.3
-1,-1,7:18.3
1,-1,7:18.3
2,-1,7:17.3
3,-1,7:18.3
5,-1,7:18.3
2,0,7:18.3
3,0,7:18.3
2,2,7:18.3
2,-3,8:18.3
0,-1,8:18.3
1,-1,8:18.3
2,-1,8:18.3
4,-1,8:18.3
2,1,8:18.3
