[META]
version=2.0
spawnOnBlockType=2,12
spawnSunlight=True
spawnDarkness=True
spawnWater=False
spawnLava=False
underFill=False
randomRotation=True
dig=True
tree=True
branch=False
needsFoundation=True
rarity=25
collisionPercentage=20
spawnElevationMin=0
spawnElevationMax=55
spawnInBiome=Custom
[DATA]
2,0,0:17.3
2,0,1:17.3
1,0,2:17.3
2,0,2:17.3
0,0,3:17.3
1,0,3:17.3
0,0,4:17.3
0,-2,5:18.3
-1,-1,5:18.3
0,-1,5:18.3
1,-1,5:18.3
-2,0,5:18.3
-1,0,5:18.3
0,0,5:17.3
1,0,5:18.3
2,0,5:18.3
-1,1,5:18.3
0,1,5:18.3
1,1,5:18.3
0,2,5:18.3
0,-1,6:18.3
-1,0,6:18.3
0,0,6:17.3
1,0,6:18.3
0,1,6:18.3
0,-4,7:18.3
0,-3,7:18.3
-4,0,7:18.3
-3,0,7:18.3
0,0,7:17.3
3,0,7:18.3
4,0,7:18.3
0,3,7:18.3
0,4,7:18.3
-3,-3,8:18.3
0,-3,8:18.3
3,-3,8:18.3
-2,-2,8:18.3
0,-2,8:18.3
2,-2,8:18.3
-1,-1,8:18.3
0,-1,8:18.3
1,-1,8:18.3
-3,0,8:18.3
-2,0,8:18.3
-1,0,8:18.3
0,0,8:17.3
1,0,8:18.3
2,0,8:18.3
3,0,8:18.3
-1,1,8:18.3
0,1,8:18.3
1,1,8:18.3
-2,2,8:18.3
0,2,8:18.3
2,2,8:18.3
-3,3,8:18.3
0,3,8:18.3
3,3,8:18.3
-2,-2,9:18.3
0,-2,9:18.3
2,-2,9:18.3
-1,-1,9:18.3
0,-1,9:18.3
1,-1,9:18.3
-2,0,9:18.3
-1,0,9:18.3
0,0,9:18.3
1,0,9:18.3
2,0,9:18.3
-1,1,9:18.3
0,1,9:18.3
1,1,9:18.3
-2,2,9:18.3
0,2,9:18.3
2,2,9:18.3
0,-1,10:18.3
-1,0,10:18.3
0,0,10:18.3
1,0,10:18.3
0,1,10:18.3
1,0,7:127.9
0,-1,7:127.8
