[META]
version=2.0
spawnOnBlockType=2,12
spawnSunlight=True
spawnDarkness=True
spawnWater=False
spawnLava=False
underFill=False
randomRotation=True
dig=True
tree=True
branch=False
needsFoundation=True
rarity=25
collisionPercentage=20
spawnElevationMin=0
spawnElevationMax=55
spawnInBiome=Custom
[DATA]
2,6,-3:17.3
2,7,-3:17.3
2,6,-2:17.3
0,5,-1:17.3
1,5,-1:17.3
1,6,-1:17.3
1,3,0:17.3
1,4,0:17.3
1,5,0:17.3
0,2,1:17.3
0,3,1:17.3
-1,1,2:17.3
-1,2,2:17.3
-2,1,3:17.3
-3,0,4:17.3
-2,1,4:17.3
-3,0,5:17.3
-2,1,5:17.3
-2,2,5:17.3
-3,-1,6:17.3
-3,0,6:17.3
-2,2,6:17.3
-3,3,6:17.3
-3,-1,7:17.3
-2,2,7:18.3
-3,4,7:17.3
-5,5,7:18.3
1,5,7:18.3
-2,8,7:18.3
-7,-5,8:18.3
1,-5,8:18.3
-3,-4,8:18.3
-3,-2,8:0
-6,-1,8:18.3
-3,-1,8:17.3
0,-1,8:18.3
-3,2,8:18.3
-2,2,8:18.3
-7,3,8:18.3
1,3,8:18.3
-5,5,8:18.3
-2,5,8:17.3
-1,5,8:0
1,5,8:18.3
-2,8,8:18.3
-7,-5,9:18.3
1,-5,9:18.3
-3,-4,9:18.3
-4,-2,9:0
-3,-2,9:18.3
-6,-1,9:18.3
-4,-1,9:18.3
-3,-1,9:17.3
-2,-1,9:18.3
0,-1,9:18.3
-3,0,9:18.3
-3,2,9:18.3
-7,3,9:18.3
-2,3,9:18.3
1,3,9:18.3
-2,4,9:0
-4,5,9:18.3
-2,5,9:18.3
0,5,9:18.3
-2,7,9:18.3
-6,-4,10:18.3
0,-4,10:18.3
-3,-3,10:18.3
-4,-2,10:18.3
-2,-2,10:18.3
-5,-1,10:18.3
-3,-1,10:18.3
-1,-1,10:18.3
-4,0,10:18.3
-2,0,10:18.3
-3,1,10:18.3
-6,2,10:18.3
0,2,10:18.3
-2,4,10:18.3
-3,5,10:18.3
-2,5,10:18.3
-1,5,10:18.3
-2,6,10:18.3
-5,-3,11:18.3
-1,-3,11:18.3
-4,-2,11:18.3
-2,-2,11:18.3
-4,0,11:18.3
-2,0,11:18.3
-5,1,11:18.3
-1,1,11:18.3
-2,5,11:18.3
