[META]
version=2.0
spawnOnBlockType=2
spawnSunlight=True
spawnDarkness=True
spawnWater=False
spawnLava=False
underFill=False
randomRotation=True
dig=True
tree=True
branch=False
needsFoundation=True
rarity=25
collisionPercentage=20
spawnElevationMin=0
spawnElevationMax=200
spawnInBiome=Custom
[DATA]
0,0,0:17.3
0,0,1:17.3
0,0,2:17.3
0,0,3:17.3
-1,0,4:18.3
0,0,4:17.3
0,1,4:18.3
1,-2,5:18.3
-1,-1,5:18.3
0,-1,5:18.3
1,-1,5:18.3
2,-1,5:18.3
-2,0,5:18.3
-1,0,5:18.3
0,0,5:17.3
1,0,5:18.3
2,0,5:18.3
-2,1,5:18.3
-1,1,5:18.3
0,1,5:18.3
1,1,5:18.3
-1,2,5:18.3
0,2,5:18.3
0,-1,6:18.3
1,-1,6:18.3
-1,0,6:18.3
0,0,6:17.3
1,0,6:18.3
0,1,6:18.3
1,-3,7:17.3
0,-2,7:17.3
0,-1,7:17.3
0,0,7:17.3
2,-4,8:17.3
1,-3,8:17.3
0,0,8:17.3
1,1,8:17.3
2,2,8:17.3
2,-5,9:18.3
3,-5,9:18.3
4,-5,9:18.3
1,-4,9:18.3
2,-4,9:17.3
3,-4,9:18.3
4,-4,9:18.3
1,-3,9:18.3
2,-3,9:18.3
3,-3,9:18.3
4,-3,9:18.3
3,-2,9:18.3
0,0,9:17.3
2,2,9:17.3
3,3,9:17.3
2,-7,10:18.3
3,-7,10:18.3
1,-6,10:18.3
2,-6,10:18.3
3,-6,10:18.3
4,-6,10:18.3
5,-6,10:18.3
0,-5,10:18.3
1,-5,10:18.3
2,-5,10:18.3
3,-5,10:17.3
4,-5,10:18.3
5,-5,10:18.3
6,-5,10:18.3
0,-4,10:18.3
1,-4,10:17.3
2,-4,10:18.3
3,-4,10:18.3
4,-4,10:18.3
5,-4,10:18.3
6,-4,10:18.3
0,-3,10:18.3
1,-3,10:18.3
2,-3,10:18.3
3,-3,10:17.3
4,-3,10:18.3
5,-3,10:18.3
6,-3,10:18.3
1,-2,10:18.3
2,-2,10:18.3
3,-2,10:18.3
4,-2,10:18.3
5,-2,10:18.3
2,-1,10:18.3
3,-1,10:18.3
4,-1,10:18.3
-2,0,10:17.7
-1,0,10:17.7
0,0,10:17.3
2,2,10:18.3
3,2,10:18.3
1,3,10:18.3
2,3,10:18.3
3,3,10:17.3
4,3,10:18.3
3,4,10:18.3
2,-5,11:18.3
3,-5,11:18.3
4,-5,11:18.3
1,-4,11:18.3
2,-4,11:18.3
3,-4,11:18.3
4,-4,11:18.3
5,-4,11:18.3
2,-3,11:18.3
3,-3,11:18.3
4,-3,11:18.3
3,-2,11:18.3
-3,0,11:17.7
-2,0,11:17.7
0,0,11:17.3
3,0,11:18.3
2,1,11:18.3
3,1,11:18.3
4,1,11:18.3
1,2,11:18.3
2,2,11:18.3
3,2,11:18.3
4,2,11:18.3
5,2,11:18.3
0,3,11:18.3
1,3,11:18.3
2,3,11:18.3
3,3,11:17.3
4,3,11:18.3
5,3,11:18.3
6,3,11:18.3
1,4,11:18.3
2,4,11:18.3
3,4,11:18.3
4,4,11:18.3
5,4,11:18.3
2,5,11:18.3
3,5,11:18.3
4,5,11:18.3
3,6,11:18.3
-4,-1,12:18.3
-3,-1,12:18.3
-5,0,12:18.3
-4,0,12:18.3
-3,0,12:17.3
0,0,12:17.3
-4,1,12:18.3
-3,1,12:18.3
2,2,12:18.3
3,2,12:18.3
2,3,12:18.3
3,3,12:18.3
4,3,12:18.3
2,4,12:18.3
3,4,12:18.3
-4,-3,13:18.3
-5,-2,13:18.3
-4,-2,13:18.3
-3,-2,13:18.3
-6,-1,13:18.3
-5,-1,13:18.3
-4,-1,13:18.3
-3,-1,13:18.3
-2,-1,13:18.3
-7,0,13:18.3
-6,0,13:18.3
-5,0,13:18.3
-4,0,13:17.3
-3,0,13:18.3
-2,0,13:18.3
-1,0,13:18.3
0,0,13:17.3
-6,1,13:18.3
-5,1,13:18.3
-4,1,13:18.3
-3,1,13:18.3
-2,1,13:18.3
-5,2,13:18.3
-4,2,13:18.3
-3,2,13:18.3
-4,3,13:18.3
-4,-1,14:18.3
-3,-1,14:18.3
-5,0,14:18.3
-4,0,14:18.3
-3,0,14:18.3
-2,0,14:18.3
0,0,14:17.3
-4,1,14:18.3
0,0,15:17.3
0,0,16:17.3
-1,-1,17:17.3
1,-1,17:17.3
0,0,17:17.3
1,0,17:18.3
0,-4,18:18.3
-1,-3,18:18.3
0,-3,18:18.3
1,-3,18:18.3
2,-3,18:18.3
-3,-2,18:18.3
-2,-2,18:18.3
-1,-2,18:18.3
0,-2,18:17.3
1,-2,18:18.3
2,-2,18:17.3
3,-2,18:18.3
-3,-1,18:18.3
-2,-1,18:17.3
-1,-1,18:18.3
0,-1,18:18.3
1,-1,18:18.3
2,-1,18:18.3
-3,0,18:18.3
-2,0,18:18.3
-1,0,18:18.3
0,0,18:17.3
1,0,18:18.3
-3,1,18:18.3
-2,1,18:18.3
-1,1,18:17.3
0,1,18:17.3
1,1,18:18.3
-2,2,18:18.3
-1,2,18:18.3
0,2,18:18.3
1,2,18:17.3
2,2,18:18.3
1,3,18:18.3
-1,-6,19:18.3
0,-6,19:18.3
1,-6,19:18.3
-3,-5,19:18.3
-2,-5,19:18.3
-1,-5,19:18.3
0,-5,19:18.3
1,-5,19:18.3
2,-5,19:18.3
3,-5,19:18.3
-4,-4,19:18.3
-3,-4,19:18.3
-2,-4,19:18.3
-1,-4,19:18.3
0,-4,19:18.3
1,-4,19:18.3
2,-4,19:18.3
3,-4,19:18.3
4,-4,19:18.3
-5,-3,19:18.3
-4,-3,19:18.3
-3,-3,19:18.3
-2,-3,19:18.3
-1,-3,19:17.3
0,-3,19:18.3
1,-3,19:17.3
2,-3,19:18.3
3,-3,19:18.3
4,-3,19:18.3
5,-3,19:18.3
-6,-2,19:18.3
-5,-2,19:18.3
-4,-2,19:18.3
-3,-2,19:17.3
-2,-2,19:18.3
-1,-2,19:18.3
0,-2,19:18.3
1,-2,19:18.3
2,-2,19:18.3
3,-2,19:17.3
4,-2,19:18.3
5,-2,19:18.3
6,-2,19:18.3
-5,-1,19:18.3
-4,-1,19:18.3
-3,-1,19:18.3
-2,-1,19:18.3
-1,-1,19:18.3
0,-1,19:18.3
1,-1,19:18.3
2,-1,19:18.3
3,-1,19:18.3
4,-1,19:18.3
5,-1,19:18.3
-4,0,19:18.3
-3,0,19:18.3
-2,0,19:18.3
-1,0,19:18.3
0,0,19:17.3
1,0,19:18.3
2,0,19:18.3
3,0,19:18.3
4,0,19:18.3
-4,1,19:18.3
-3,1,19:18.3
-2,1,19:18.3
-1,1,19:18.3
0,1,19:18.3
1,1,19:18.3
2,1,19:18.3
3,1,19:18.3
4,1,19:18.3
-5,2,19:18.3
-4,2,19:18.3
-3,2,19:18.3
-2,2,19:17.3
-1,2,19:18.3
0,2,19:18.3
1,2,19:18.3
2,2,19:17.3
3,2,19:18.3
4,2,19:18.3
5,2,19:18.3
-4,3,19:18.3
-3,3,19:18.3
-2,3,19:18.3
-1,3,19:18.3
0,3,19:18.3
1,3,19:18.3
2,3,19:18.3
3,3,19:18.3
4,3,19:18.3
-3,4,19:18.3
-2,4,19:18.3
-1,4,19:18.3
1,4,19:18.3
2,4,19:18.3
3,4,19:18.3
-2,5,19:18.3
2,5,19:18.3
-1,-4,20:18.3
0,-4,20:18.3
1,-4,20:18.3
-2,-3,20:18.3
-1,-3,20:18.3
0,-3,20:18.3
1,-3,20:18.3
2,-3,20:18.3
3,-3,20:18.3
-4,-2,20:18.3
-3,-2,20:18.3
-2,-2,20:18.3
-1,-2,20:18.3
0,-2,20:18.3
1,-2,20:18.3
2,-2,20:18.3
3,-2,20:18.3
4,-2,20:18.3
-3,-1,20:18.3
-2,-1,20:18.3
-1,-1,20:18.3
0,-1,20:18.3
1,-1,20:18.3
2,-1,20:18.3
3,-1,20:18.3
-3,0,20:18.3
-2,0,20:18.3
-1,0,20:18.3
0,0,20:18.3
1,0,20:18.3
2,0,20:18.3
3,0,20:18.3
-3,1,20:18.3
-2,1,20:18.3
-1,1,20:18.3
0,1,20:18.3
1,1,20:18.3
2,1,20:18.3
3,1,20:18.3
-3,2,20:18.3
-2,2,20:18.3
-1,2,20:18.3
0,2,20:18.3
1,2,20:18.3
2,2,20:18.3
3,2,20:18.3
-2,3,20:18.3
2,3,20:18.3
0,-2,21:18.3
1,-2,21:18.3
2,-2,21:18.3
-1,-1,21:18.3
0,-1,21:18.3
1,-1,21:18.3
-1,0,21:18.3
0,0,21:18.3
1,0,21:18.3
0,1,21:18.3
0,-1,17:127.8
-1,0,17:127.11
0,1,17:127.10
-4,0,16:106.8
3,-3,18:106.2
1,-4,18:106.1
0,2,17:106.0
-3,2,18:106.4
3,2,18:106.2
-4,0,17:106.8
2,3,18:106.4
3,-2,17:106.0
1,0,16:106.2
-4,0,18:106.8
1,0,15:106.2
-1,0,15:106.8
-4,0,15:106.8
1,0,14:106.2
-1,0,14:106.8
1,0,13:106.2
1,0,12:106.2
1,0,11:106.2
-3,-1,11:106.1
1,0,10:106.2
3,2,9:106.2
1,0,9:106.2
3,-4,8:106.2
1,0,4:106.2
