[META]
version=2.0
spawnOnBlockType=2,12
spawnSunlight=True
spawnDarkness=True
spawnWater=False
spawnLava=False
underFill=False
randomRotation=True
dig=True
tree=True
branch=False
needsFoundation=True
rarity=25
collisionPercentage=20
spawnElevationMin=0
spawnElevationMax=55
spawnInBiome=Custom
[DATA]
2,2,0:17.3
2,2,1:17.3
2,2,2:17.3
2,2,3:17.3
2,2,4:17.3
1,1,5:17.3
2,2,5:17.3
1,1,6:17.3
0,0,7:17.3
1,1,7:17.3
0,0,8:17.3
0,-4,9:18.3
0,-1,9:18.3
-4,0,9:18.3
-1,0,9:18.3
0,0,9:17.3
1,0,9:18.3
4,0,9:18.3
0,1,9:18.3
0,4,9:18.3
0,-3,10:18.3
0,-1,10:18.3
-3,0,10:18.3
-1,0,10:18.3
0,0,10:18.3
1,0,10:18.3
3,0,10:18.3
0,1,10:18.3
0,3,10:18.3
-3,-3,11:18.3
3,-3,11:18.3
0,-2,11:18.3
-1,-1,11:18.3
0,-1,11:18.3
1,-1,11:18.3
-2,0,11:18.3
-1,0,11:18.3
0,0,11:18.3
1,0,11:18.3
2,0,11:18.3
-1,1,11:18.3
0,1,11:18.3
1,1,11:18.3
0,2,11:18.3
-3,3,11:18.3
3,3,11:18.3
-2,-2,12:18.3
0,-2,12:18.3
2,-2,12:18.3
-2,0,12:18.3
2,0,12:18.3
-2,2,12:18.3
0,2,12:18.3
2,2,12:18.3
0,-3,13:18.3
-3,0,13:18.3
3,0,13:18.3
0,3,13:18.3
0,1,8:127.10
-1,0,8:127.11
