[META]
version=2.0
spawnOnBlockType=2
spawnSunlight=True
spawnDarkness=True
spawnWater=False
spawnLava=False
underFill=False
randomRotation=True
dig=True
tree=True
branch=False
needsFoundation=True
rarity=25
collisionPercentage=20
spawnElevationMin=0
spawnElevationMax=200
spawnInBiome=Custom
[DATA]
-1,1,0:17.3
-1,1,1:17.3
-1,-1,2:18.3
-1,0,2:18.3
-1,1,2:17.3
-1,-3,3:18.3
-2,-2,3:18.3
-1,-2,3:18.3
0,-2,3:18.3
-3,-1,3:18.3
-2,-1,3:18.3
-1,-1,3:17.3
0,-1,3:18.3
1,-1,3:18.3
-3,0,3:18.3
-2,0,3:18.3
-1,0,3:17.3
0,0,3:18.3
-2,1,3:18.3
-1,1,3:17.3
-2,-4,4:18.3
-1,-4,4:18.3
0,-4,4:18.3
-3,-3,4:18.3
-2,-3,4:18.3
-1,-3,4:18.3
0,-3,4:18.3
1,-3,4:18.3
-3,-2,4:18.3
-2,-2,4:18.3
-1,-2,4:17.3
0,-2,4:18.3
1,-2,4:18.3
2,-2,4:18.3
-2,-1,4:18.3
-1,-1,4:18.3
0,-1,4:18.3
1,-1,4:18.3
2,-1,4:18.3
-1,0,4:18.3
0,0,4:18.3
1,0,4:18.3
-1,1,4:17.3
0,1,4:18.3
-1,-3,5:18.3
-2,-2,5:18.3
-1,-2,5:18.3
0,-2,5:18.3
-1,-1,5:18.3
0,-1,5:18.3
1,-1,5:18.3
-1,1,5:17.3
-1,1,6:17.3
-1,2,6:17.3
-1,1,7:17.3
-1,3,7:17.3
-2,-1,8:18.3
-1,-1,8:18.3
0,-1,8:18.3
-3,0,8:18.3
-2,0,8:18.3
-1,0,8:18.3
0,0,8:18.3
1,0,8:18.3
-3,1,8:18.3
-2,1,8:18.3
-1,1,8:17.3
0,1,8:18.3
1,1,8:18.3
-3,2,8:18.3
-2,2,8:18.3
-1,2,8:18.3
0,2,8:18.3
1,2,8:18.3
-2,3,8:18.3
-1,3,8:18.3
0,3,8:18.3
-2,4,8:18.3
-1,4,8:17.3
0,-3,9:18.3
-2,-2,9:18.3
-1,-2,9:18.3
0,-2,9:18.3
1,-2,9:18.3
-4,-1,9:18.3
-3,-1,9:18.3
-2,-1,9:18.3
-1,-1,9:18.3
0,-1,9:18.3
1,-1,9:18.3
2,-1,9:18.3
-4,0,9:18.3
-3,0,9:18.3
-2,0,9:17.3
-1,0,9:18.3
0,0,9:17.3
1,0,9:18.3
2,0,9:18.3
3,0,9:18.3
-5,1,9:18.3
-4,1,9:18.3
-3,1,9:18.3
-2,1,9:18.3
-1,1,9:18.3
0,1,9:18.3
1,1,9:18.3
2,1,9:18.3
3,1,9:18.3
-5,2,9:18.3
-4,2,9:18.3
-3,2,9:18.3
-2,2,9:18.3
-1,2,9:17.3
0,2,9:18.3
1,2,9:18.3
2,2,9:18.3
-4,3,9:18.3
-3,3,9:18.3
-2,3,9:18.3
-1,3,9:18.3
0,3,9:18.3
1,3,9:18.3
-3,4,9:18.3
-2,4,9:18.3
-1,4,9:18.3
0,4,9:18.3
1,4,9:18.3
-1,5,9:18.3
0,5,9:18.3
-1,-5,10:18.3
0,-5,10:18.3
-3,-4,10:18.3
-2,-4,10:18.3
-1,-4,10:18.3
0,-4,10:18.3
1,-4,10:18.3
-3,-3,10:18.3
-2,-3,10:18.3
-1,-3,10:18.3
0,-3,10:18.3
1,-3,10:18.3
2,-3,10:18.3
-4,-2,10:18.3
-3,-2,10:18.3
-2,-2,10:18.3
-1,-2,10:18.3
0,-2,10:18.3
1,-2,10:18.3
2,-2,10:18.3
3,-2,10:18.3
-5,-1,10:18.3
-4,-1,10:18.3
-3,-1,10:18.3
-2,-1,10:17.3
-1,-1,10:18.3
0,-1,10:18.3
1,-1,10:17.3
2,-1,10:18.3
3,-1,10:18.3
-6,0,10:18.3
-5,0,10:18.3
-4,0,10:18.3
-3,0,10:17.3
-2,0,10:18.3
-1,0,10:18.3
0,0,10:18.3
1,0,10:18.3
2,0,10:18.3
3,0,10:18.3
4,0,10:18.3
-6,1,10:18.3
-5,1,10:18.3
-4,1,10:18.3
-3,1,10:18.3
-2,1,10:18.3
-1,1,10:18.3
0,1,10:18.3
1,1,10:18.3
2,1,10:18.3
3,1,10:18.3
4,1,10:18.3
-5,2,10:18.3
-4,2,10:18.3
-3,2,10:18.3
-2,2,10:17.3
-1,2,10:18.3
0,2,10:18.3
1,2,10:17.3
2,2,10:18.3
3,2,10:18.3
-5,3,10:18.3
-4,3,10:18.3
-3,3,10:18.3
-2,3,10:18.3
-1,3,10:18.3
0,3,10:17.3
1,3,10:18.3
2,3,10:18.3
-4,4,10:18.3
-3,4,10:18.3
-2,4,10:18.3
-1,4,10:18.3
0,4,10:18.3
1,4,10:18.3
2,4,10:18.3
-3,5,10:18.3
-2,5,10:18.3
-1,5,10:18.3
0,5,10:18.3
1,5,10:18.3
-1,6,10:18.3
0,6,10:18.3
-1,-4,11:18.3
0,-4,11:18.3
-2,-3,11:18.3
-1,-3,11:18.3
0,-3,11:18.3
-3,-2,11:18.3
-2,-2,11:18.3
-1,-2,11:18.3
0,-2,11:18.3
1,-2,11:18.3
-3,-1,11:18.3
-2,-1,11:18.3
-1,-1,11:18.3
0,-1,11:18.3
1,-1,11:18.3
2,-1,11:18.3
-5,0,11:18.3
-4,0,11:18.3
-3,0,11:18.3
-2,0,11:18.3
-1,0,11:18.3
0,0,11:18.3
1,0,11:18.3
2,0,11:18.3
3,0,11:18.3
-5,1,11:18.3
-4,1,11:18.3
-3,1,11:18.3
-2,1,11:18.3
-1,1,11:18.3
0,1,11:18.3
1,1,11:18.3
2,1,11:18.3
3,1,11:18.3
-4,2,11:18.3
-3,2,11:18.3
-2,2,11:18.3
-1,2,11:18.3
0,2,11:18.3
1,2,11:18.3
-3,3,11:18.3
-2,3,11:18.3
-1,3,11:18.3
0,3,11:18.3
1,3,11:18.3
-3,4,11:18.3
-2,4,11:18.3
-1,4,11:18.3
0,4,11:18.3
-1,5,11:18.3
0,5,11:18.3
-1,-3,12:18.3
-2,-2,12:18.3
-1,-2,12:18.3
0,-2,12:18.3
-2,-1,12:18.3
-1,-1,12:18.3
0,-1,12:18.3
1,-1,12:18.3
-3,0,12:18.3
-2,0,12:18.3
-1,0,12:18.3
0,0,12:18.3
1,0,12:18.3
2,0,12:18.3
-3,1,12:18.3
-2,1,12:18.3
-1,1,12:18.3
0,1,12:18.3
1,1,12:18.3
-2,2,12:18.3
-1,2,12:18.3
0,2,12:18.3
-1,3,12:18.3
-3,3,8:106.8
1,-1,8:106.2
-3,-1,8:106.1
0,3,7:106.2
-2,1,7:106.8
-1,2,5:106.4
0,1,3:106.2
-1,-1,1:106.0
