[META]
version=2.0
spawnOnBlockType=2,12
spawnSunlight=True
spawnDarkness=True
spawnWater=False
spawnLava=False
underFill=False
randomRotation=True
dig=True
tree=True
branch=False
needsFoundation=True
rarity=25
collisionPercentage=20
spawnElevationMin=0
spawnElevationMax=55
spawnInBiome=Custom
[DATA]
2,-1,0:17.3
2,-1,1:17.3
2,-1,2:17.3
1,-1,3:17.3
2,-1,3:17.3
2,-4,4:18.3
0,-2,4:18.3
1,-1,4:17.3
3,-5,5:18.3
-1,-3,5:18.3
2,-3,5:18.3
5,-3,5:18.3
1,-2,5:18.3
2,-2,5:17.3
-3,-1,5:18.3
0,-1,5:17.3
1,-1,5:17.3
2,0,5:17.3
-1,1,5:18.3
3,-4,6:18.3
3,-3,6:17.3
4,-3,6:18.3
-1,-2,6:18.3
2,-2,6:17.3
3,-2,6:18.3
-2,-1,6:18.3
-1,-1,6:17.3
0,-1,6:17.3
-1,0,6:18.3
2,0,6:17.3
3,1,6:17.3
3,-3,7:17.3
-1,-1,7:17.3
3,-1,7:18.3
4,0,7:18.3
1,1,7:18.3
3,1,7:17.3
5,1,7:18.3
3,3,7:18.3
4,-5,8:18.3
2,-3,8:18.3
4,-3,8:17.3
6,-3,8:18.3
-2,-2,8:18.3
1,-1,8:18.3
4,-1,8:18.3
5,-1,8:18.3
-4,0,8:18.3
-2,0,8:17.3
0,0,8:18.3
3,0,8:18.3
2,1,8:18.3
3,1,8:17.3
4,1,8:18.3
-2,2,8:18.3
3,2,8:18.3
1,3,8:18.3
5,3,8:18.3
2,-5,9:18.3
6,-5,9:18.3
4,-4,9:18.3
3,-3,9:18.3
4,-3,9:17.3
5,-3,9:18.3
-4,-2,9:18.3
0,-2,9:18.3
4,-2,9:18.3
-2,-1,9:18.3
2,-1,9:18.3
6,-1,9:18.3
-3,0,9:18.3
-2,0,9:17.3
-1,0,9:18.3
2,0,9:18.3
4,0,9:18.3
-2,1,9:18.3
3,1,9:18.3
-4,2,9:18.3
0,2,9:18.3
2,2,9:18.3
4,2,9:18.3
3,-4,10:18.3
5,-4,10:18.3
4,-3,10:18.3
3,-2,10:18.3
5,-2,10:18.3
-3,-1,10:18.3
-1,-1,10:18.3
-2,0,10:18.3
-3,1,10:18.3
-1,1,10:18.3
-2,1,8:127.10
4,-2,8:127.10
5,-3,8:127.9
3,2,7:127.10
4,1,7:127.9
