[META]
version=2.0
spawnOnBlockType=2,12
spawnSunlight=True
spawnDarkness=True
spawnWater=False
spawnLava=False
underFill=False
randomRotation=True
dig=True
tree=True
branch=False
needsFoundation=True
rarity=25
collisionPercentage=20
spawnElevationMin=0
spawnElevationMax=55
spawnInBiome=Custom
[DATA]
0,0,0:17.3
0,0,1:17.3
0,0,2:17.3
0,0,3:17.3
0,0,4:17.3
0,0,5:17.3
0,0,6:17.3
0,-3,7:18.3
-3,0,7:18.3
0,0,7:17.3
3,0,7:18.3
0,3,7:18.3
-3,-3,8:18.3
3,-3,8:18.3
0,-2,8:18.3
-2,0,8:18.3
0,0,8:17.3
2,0,8:18.3
0,2,8:18.3
-3,3,8:18.3
3,3,8:18.3
0,-4,9:18.3
-2,-2,9:18.3
2,-2,9:18.3
0,-1,9:18.3
-4,0,9:18.3
-1,0,9:18.3
0,0,9:17.3
1,0,9:18.3
4,0,9:18.3
-1,1,9:18.3
0,1,9:18.3
1,1,9:18.3
-2,2,9:18.3
2,2,9:18.3
0,4,9:18.3
0,-3,10:18.3
0,-2,10:18.3
-1,-1,10:18.3
0,-1,10:18.3
1,-1,10:18.3
-3,0,10:18.3
-2,0,10:18.3
-1,0,10:18.3
0,0,10:17.3
1,0,10:18.3
2,0,10:18.3
3,0,10:18.3
-1,1,10:18.3
0,1,10:18.3
1,1,10:18.3
0,2,10:18.3
0,3,10:18.3
-2,-5,11:18.3
2,-5,11:18.3
-5,-2,11:18.3
-2,-2,11:18.3
2,-2,11:18.3
5,-2,11:18.3
0,-1,11:18.3
-1,0,11:18.3
0,0,11:17.3
1,0,11:18.3
0,1,11:18.3
-5,2,11:18.3
-2,2,11:18.3
2,2,11:18.3
5,2,11:18.3
-2,5,11:18.3
2,5,11:18.3
-1,-4,12:18.3
1,-4,12:18.3
0,-2,12:18.3
-4,-1,12:18.3
0,-1,12:18.3
4,-1,12:18.3
-2,0,12:18.3
-1,0,12:18.3
0,0,12:17.3
1,0,12:18.3
2,0,12:18.3
-4,1,12:18.3
0,1,12:18.3
4,1,12:18.3
0,2,12:18.3
-1,4,12:18.3
1,4,12:18.3
0,-3,13:18.3
0,-1,13:18.3
-3,0,13:18.3
-1,0,13:18.3
0,0,13:18.3
1,0,13:18.3
3,0,13:18.3
0,1,13:18.3
0,3,13:18.3
0,1,8:127.10
1,0,8:127.9
-1,0,8:127.11
0,-1,8:127.8
