[META]
version=2.0
spawnOnBlockType=2
spawnSunlight=True
spawnDarkness=True
spawnWater=False
spawnLava=False
underFill=False
randomRotation=True
dig=True
tree=True
branch=False
needsFoundation=True
rarity=25
collisionPercentage=20
spawnElevationMin=0
spawnElevationMax=200
spawnInBiome=Custom
[DATA]
-1,-1,-3:17.3
-2,0,-3:17.3
-1,0,-3:17.3
0,0,-3:17.3
1,0,-3:17.3
-3,1,-3:17.3
-2,1,-3:17.3
-1,1,-3:17.3
0,1,-3:17.3
-2,2,-3:17.3
-1,2,-3:17.3
0,2,-3:17.3
1,2,-3:17.3
-1,3,-3:17.3
-1,-1,-2:17.3
-2,0,-2:17.3
-1,0,-2:17.3
0,0,-2:17.3
1,0,-2:17.3
-3,1,-2:17.3
-2,1,-2:17.3
-1,1,-2:17.3
0,1,-2:17.3
-2,2,-2:17.3
-1,2,-2:17.3
0,2,-2:17.3
1,2,-2:17.3
-1,3,-2:17.3
-1,-1,-1:17.3
-2,0,-1:17.3
-1,0,-1:17.3
0,0,-1:17.3
1,0,-1:17.3
-3,1,-1:17.3
-2,1,-1:17.3
-1,1,-1:17.3
0,1,-1:17.3
-2,2,-1:17.3
-1,2,-1:17.3
0,2,-1:17.3
1,2,-1:17.3
-1,3,-1:17.3
-1,-1,0:17.3
-2,0,0:17.3
-1,0,0:17.3
0,0,0:17.3
1,0,0:17.3
-3,1,0:17.3
-2,1,0:17.3
-1,1,0:17.3
0,1,0:17.3
-2,2,0:17.3
-1,2,0:17.3
0,2,0:17.3
1,2,0:17.3
-1,3,0:17.3
-2,0,1:17.3
-1,0,1:17.3
0,0,1:17.3
-2,1,1:17.3
-1,1,1:17.3
0,1,1:17.3
-2,2,1:17.3
-1,2,1:17.3
0,2,1:17.3
-1,0,2:17.3
-2,1,2:17.3
-1,1,2:17.3
0,1,2:17.3
-1,2,2:17.3
-1,0,3:17.3
-2,1,3:17.3
-1,1,3:17.3
0,1,3:17.3
-1,2,3:17.3
-2,-1,4:18.3
-1,-1,4:18.3
-3,0,4:18.3
-2,0,4:17.3
-1,0,4:17.3
0,0,4:18.3
-3,1,4:18.3
-2,1,4:17.3
-1,1,4:17.3
0,1,4:17.3
-3,2,4:18.3
-2,2,4:18.3
-1,2,4:17.3
-2,3,4:18.3
-1,3,4:17.3
-2,0,5:18.3
-1,0,5:17.3
-3,1,5:18.3
-2,1,5:17.3
-1,1,5:17.3
0,1,5:17.3
-2,2,5:18.3
-1,2,5:17.3
-1,3,5:18.3
0,3,5:18.3
-1,4,5:18.3
0,4,5:17.3
1,4,5:18.3
0,5,5:18.3
1,5,5:18.3
2,5,5:18.3
1,6,5:18.3
-1,0,6:17.3
-2,1,6:17.3
-1,1,6:17.3
0,1,6:17.3
-1,2,6:17.3
-1,3,6:18.3
0,3,6:18.3
1,3,6:18.3
-2,4,6:18.3
-1,4,6:18.3
0,4,6:18.3
1,4,6:18.3
2,4,6:18.3
-2,5,6:18.3
-1,5,6:18.3
0,5,6:18.3
1,5,6:17.3
2,5,6:18.3
3,5,6:18.3
-1,6,6:18.3
0,6,6:18.3
1,6,6:18.3
2,6,6:18.3
0,7,6:18.3
1,7,6:18.3
-1,-2,7:17.3
-2,-1,7:17.3
-1,-1,7:17.3
0,-1,7:17.3
-2,0,7:17.3
-1,0,7:17.3
0,0,7:17.3
-2,1,7:17.3
-1,1,7:17.3
0,1,7:17.3
-1,2,7:17.3
-1,4,7:18.3
0,4,7:18.3
0,5,7:18.3
1,5,7:18.3
1,6,7:18.3
-1,-5,8:18.3
-2,-4,8:18.3
-1,-4,8:18.3
0,-4,8:18.3
1,-4,8:18.3
-2,-3,8:18.3
-1,-3,8:17.3
0,-3,8:18.3
1,-3,8:18.3
2,-3,8:18.3
-2,-2,8:18.3
-1,-2,8:18.3
1,-2,8:17.3
2,-2,8:18.3
-1,-1,8:18.3
1,-1,8:18.3
-1,0,8:17.3
-2,1,8:17.3
-1,1,8:17.3
0,1,8:17.3
-1,2,8:17.3
-2,-6,9:18.3
-1,-6,9:18.3
0,-6,9:18.3
-3,-5,9:18.3
-2,-5,9:18.3
-1,-5,9:18.3
0,-5,9:18.3
1,-5,9:18.3
2,-5,9:18.3
-4,-4,9:18.3
-3,-4,9:18.3
-2,-4,9:18.3
-1,-4,9:18.3
0,-4,9:17.3
1,-4,9:18.3
2,-4,9:18.3
3,-4,9:18.3
-4,-3,9:18.3
-3,-3,9:18.3
-2,-3,9:17.3
-1,-3,9:18.3
0,-3,9:18.3
1,-3,9:18.3
2,-3,9:17.3
3,-3,9:18.3
4,-3,9:18.3
-3,-2,9:18.3
-2,-2,9:18.3
-1,-2,9:18.3
0,-2,9:18.3
1,-2,9:18.3
2,-2,9:18.3
3,-2,9:18.3
-2,-1,9:18.3
-1,-1,9:18.3
0,-1,9:18.3
1,-1,9:18.3
2,-1,9:18.3
-1,0,9:17.3
-2,1,9:17.3
-1,1,9:17.3
0,1,9:17.3
-1,2,9:17.3
0,2,9:18.3
1,2,9:18.3
2,3,9:18.3
-1,-5,10:18.3
-2,-4,10:18.3
-1,-4,10:18.3
0,-4,10:18.3
1,-4,10:18.3
-3,-3,10:18.3
-2,-3,10:18.3
-1,-3,10:18.3
0,-3,10:18.3
1,-3,10:18.3
2,-3,10:18.3
-1,-2,10:18.3
0,-2,10:18.3
1,-2,10:18.3
-1,0,10:17.3
-2,1,10:17.3
-1,1,10:17.3
0,1,10:17.3
2,1,10:18.3
-1,2,10:17.3
0,2,10:17.7
1,2,10:17.7
2,2,10:18.3
3,2,10:18.3
0,3,10:18.3
1,3,10:18.3
2,3,10:17.7
3,3,10:18.3
4,3,10:18.3
1,4,10:18.3
2,4,10:18.3
3,4,10:18.3
2,5,10:18.3
-1,-3,11:18.3
0,-3,11:18.3
-1,0,11:17.3
-2,1,11:17.3
-1,1,11:17.3
0,1,11:17.3
-1,2,11:17.3
1,2,11:18.3
2,2,11:18.3
1,3,11:18.3
2,3,11:18.3
3,3,11:18.3
2,4,11:18.3
-1,-1,12:17.3
-3,0,12:17.3
-1,0,12:17.3
1,0,12:17.3
-2,1,12:17.3
-1,1,12:17.3
0,1,12:17.3
-3,2,12:17.3
-1,2,12:17.3
-1,3,12:17.3
0,3,12:17.3
-1,-4,13:18.3
-3,-3,13:18.3
-2,-3,13:18.3
-1,-3,13:18.3
0,-3,13:18.3
1,-3,13:18.3
2,-3,13:18.3
-4,-2,13:18.3
-3,-2,13:18.3
-2,-2,13:17.3
-1,-2,13:18.3
0,-2,13:17.3
1,-2,13:18.3
2,-2,13:18.3
3,-2,13:18.3
4,-2,13:18.3
-5,-1,13:18.3
-4,-1,13:17.3
-3,-1,13:18.3
-2,-1,13:18.3
-1,-1,13:18.3
0,-1,13:18.3
1,-1,13:18.3
2,-1,13:17.3
3,-1,13:18.3
4,-1,13:18.3
-6,0,13:18.3
-5,0,13:18.3
-4,0,13:18.3
-3,0,13:18.3
-2,0,13:18.3
-1,0,13:18.3
0,0,13:18.3
1,0,13:18.3
2,0,13:18.3
-5,1,13:18.3
-4,1,13:18.3
-3,1,13:18.3
-2,1,13:18.3
-1,1,13:17.3
0,1,13:17.3
1,1,13:17.3
2,1,13:18.3
-5,2,13:18.3
-4,2,13:18.3
-3,2,13:18.3
-2,2,13:18.3
-1,2,13:18.3
0,2,13:18.3
1,2,13:18.3
2,2,13:18.3
-5,3,13:18.3
-4,3,13:17.3
-3,3,13:18.3
-2,3,13:18.3
-1,3,13:18.3
0,3,13:18.3
1,3,13:18.3
-6,4,13:18.3
-5,4,13:18.3
-4,4,13:18.3
-3,4,13:18.3
-2,4,13:18.3
-1,4,13:17.3
0,4,13:18.3
1,4,13:17.3
2,4,13:18.3
-3,5,13:18.3
-2,5,13:18.3
-1,5,13:18.3
0,5,13:18.3
1,5,13:18.3
2,5,13:18.3
-2,6,13:18.3
-1,6,13:18.3
-3,-5,14:18.3
-2,-5,14:18.3
-1,-5,14:18.3
0,-5,14:18.3
-4,-4,14:18.3
-3,-4,14:18.3
-2,-4,14:18.3
-1,-4,14:18.3
0,-4,14:18.3
1,-4,14:18.3
2,-4,14:18.3
3,-4,14:18.3
-5,-3,14:18.3
-4,-3,14:18.3
-3,-3,14:18.3
-2,-3,14:17.3
-1,-3,14:18.3
0,-3,14:17.3
1,-3,14:18.3
2,-3,14:18.3
3,-3,14:18.3
4,-3,14:18.3
-6,-2,14:18.3
-5,-2,14:18.3
-4,-2,14:17.3
-3,-2,14:18.3
-2,-2,14:18.3
-1,-2,14:18.3
0,-2,14:18.3
1,-2,14:18.3
2,-2,14:18.3
3,-2,14:17.3
4,-2,14:18.3
5,-2,14:18.3
-7,-1,14:18.3
-6,-1,14:18.3
-5,-1,14:17.3
-4,-1,14:18.3
-3,-1,14:18.3
-2,-1,14:18.3
-1,-1,14:18.3
0,-1,14:18.3
1,-1,14:18.3
2,-1,14:18.3
3,-1,14:18.3
4,-1,14:18.3
5,-1,14:18.3
-7,0,14:18.3
-6,0,14:18.3
-5,0,14:18.3
-4,0,14:18.3
-3,0,14:18.3
-2,0,14:17.3
-1,0,14:18.3
0,0,14:17.3
1,0,14:18.3
2,0,14:18.3
3,0,14:18.3
4,0,14:18.3
5,0,14:18.3
-6,1,14:18.3
-5,1,14:18.3
-4,1,14:18.3
-3,1,14:18.3
-2,1,14:18.3
-1,1,14:18.3
0,1,14:18.3
1,1,14:18.3
2,1,14:17.3
3,1,14:18.3
4,1,14:18.3
5,1,14:18.3
-6,2,14:18.3
-5,2,14:18.3
-4,2,14:18.3
-3,2,14:18.3
-2,2,14:18.3
-1,2,14:17.3
0,2,14:18.3
1,2,14:18.3
2,2,14:18.3
3,2,14:18.3
4,2,14:18.3
-7,3,14:18.3
-6,3,14:18.3
-5,3,14:18.3
-4,3,14:18.3
-3,3,14:18.3
-2,3,14:18.3
-1,3,14:18.3
0,3,14:18.3
1,3,14:18.3
2,3,14:18.3
-7,4,14:18.3
-6,4,14:18.3
-5,4,14:17.3
-4,4,14:18.3
-3,4,14:18.3
-2,4,14:18.3
-1,4,14:18.3
0,4,14:18.3
1,4,14:18.3
2,4,14:18.3
3,4,14:18.3
-6,5,14:18.3
-5,5,14:18.3
-4,5,14:18.3
-3,5,14:18.3
-2,5,14:18.3
-1,5,14:17.3
0,5,14:18.3
1,5,14:18.3
2,5,14:17.3
3,5,14:18.3
4,5,14:18.3
-5,6,14:18.3
-4,6,14:18.3
-3,6,14:18.3
-2,6,14:18.3
-1,6,14:18.3
0,6,14:18.3
1,6,14:18.3
2,6,14:18.3
3,6,14:18.3
4,6,14:18.3
-3,7,14:18.3
-2,7,14:18.3
-1,7,14:18.3
2,7,14:18.3
3,7,14:18.3
-2,-4,15:18.3
-1,-4,15:18.3
-3,-3,15:18.3
-2,-3,15:18.3
-1,-3,15:18.3
0,-3,15:18.3
1,-3,15:18.3
2,-3,15:18.3
-4,-2,15:18.3
-3,-2,15:18.3
-2,-2,15:18.3
-1,-2,15:18.3
0,-2,15:18.3
1,-2,15:18.3
2,-2,15:18.3
3,-2,15:18.3
-5,-1,15:18.3
-4,-1,15:18.3
-3,-1,15:18.3
-2,-1,15:18.3
-1,-1,15:18.3
0,-1,15:18.3
1,-1,15:18.3
2,-1,15:18.3
3,-1,15:18.3
4,-1,15:18.3
-5,0,15:18.3
-4,0,15:18.3
-3,0,15:18.3
-2,0,15:18.3
-1,0,15:18.3
0,0,15:18.3
1,0,15:18.3
2,0,15:18.3
3,0,15:18.3
4,0,15:18.3
-5,1,15:18.3
-4,1,15:18.3
-3,1,15:18.3
-2,1,15:18.3
-1,1,15:18.3
0,1,15:18.3
1,1,15:18.3
2,1,15:18.3
3,1,15:18.3
-5,2,15:18.3
-4,2,15:18.3
-3,2,15:18.3
-2,2,15:18.3
-1,2,15:18.3
0,2,15:18.3
1,2,15:18.3
2,2,15:18.3
-6,3,15:18.3
-5,3,15:18.3
-4,3,15:18.3
-3,3,15:18.3
-2,3,15:18.3
-1,3,15:18.3
0,3,15:18.3
1,3,15:18.3
-6,4,15:18.3
-5,4,15:18.3
-4,4,15:18.3
-3,4,15:18.3
-2,4,15:18.3
-1,4,15:18.3
0,4,15:18.3
1,4,15:18.3
2,4,15:18.3
-5,5,15:18.3
-4,5,15:18.3
-3,5,15:18.3
-2,5,15:18.3
-1,5,15:18.3
0,5,15:18.3
1,5,15:18.3
2,5,15:18.3
3,5,15:18.3
-2,6,15:18.3
2,6,15:18.3
-1,-2,16:18.3
0,-2,16:18.3
1,-2,16:18.3
-1,-1,16:18.3
0,-1,16:18.3
1,-1,16:18.3
2,-1,16:18.3
0,0,16:18.3
1,0,16:18.3
2,0,16:18.3
-3,1,16:18.3
1,1,16:18.3
-4,2,16:18.3
-3,2,16:18.3
-2,2,16:18.3
-4,3,16:18.3
-3,3,16:18.3
-2,3,16:18.3
-4,4,16:18.3
-3,4,16:18.3
-2,0,12:127.8
0,0,12:127.8
-3,1,12:127.11
-2,2,12:127.10
0,2,12:127.9
1,3,9:106.4
-5,-3,13:106.0
1,1,12:106.2
-4,-3,13:106.8
5,-1,13:106.2
-6,1,13:106.8
-1,3,11:106.4
-2,2,11:106.8
1,1,11:106.2
-2,0,11:106.8
-1,3,10:106.4
-2,2,10:106.8
1,1,10:106.2
-2,0,10:106.8
-4,-3,10:106.8
1,-4,13:106.1
-1,3,9:106.4
-2,2,9:106.8
1,1,9:106.2
-2,0,9:106.8
-1,3,8:106.4
-2,2,8:106.8
1,1,8:106.2
-2,0,8:106.8
3,-3,8:106.2
2,-4,8:106.1
-2,-5,8:106.1
-1,3,7:106.4
-2,2,7:106.8
1,1,7:106.2
1,-1,7:106.2
-2,2,6:106.8
1,1,6:106.2
0,6,5:106.4
2,4,5:106.2
-2,2,3:106.8
