[META]
version=2.0
spawnOnBlockType=2,12
spawnSunlight=True
spawnDarkness=True
spawnWater=False
spawnLava=False
underFill=False
randomRotation=True
dig=True
tree=True
branch=False
needsFoundation=True
rarity=25
collisionPercentage=20
spawnElevationMin=0
spawnElevationMax=55
spawnInBiome=Custom
[DATA]
2,7,-2:17.3
2,6,-1:17.3
2,7,-1:17.3
2,4,0:17.3
2,5,0:17.3
2,6,0:17.3
1,3,1:17.3
1,4,1:17.3
0,2,2:17.3
0,3,2:17.3
-1,2,3:17.3
-2,1,4:17.3
-1,2,4:17.3
-2,1,5:17.3
-2,0,6:17.3
-2,1,6:17.3
-2,0,7:17.3
-6,-4,8:18.3
2,-4,8:18.3
-2,-3,8:18.3
-5,0,8:18.3
-2,0,8:17.3
1,0,8:18.3
-2,3,8:18.3
-6,4,8:18.3
2,4,8:18.3
-6,-4,9:18.3
2,-4,9:18.3
-2,-3,9:18.3
-2,-1,9:18.3
-5,0,9:18.3
-3,0,9:18.3
-2,0,9:17.3
-1,0,9:18.3
1,0,9:18.3
-2,1,9:18.3
-2,3,9:18.3
-6,4,9:18.3
2,4,9:18.3
-5,-3,10:18.3
1,-3,10:18.3
-2,-2,10:18.3
-3,-1,10:18.3
-1,-1,10:18.3
-4,0,10:18.3
-2,0,10:18.3
0,0,10:18.3
-3,1,10:18.3
-1,1,10:18.3
-2,2,10:18.3
-5,3,10:18.3
1,3,10:18.3
-4,-2,11:18.3
0,-2,11:18.3
-3,-1,11:18.3
-1,-1,11:18.3
-3,1,11:18.3
-1,1,11:18.3
-4,2,11:18.3
0,2,11:18.3
