[META]
version=2.0
spawnOnBlockType=2,12
spawnSunlight=True
spawnDarkness=True
spawnWater=False
spawnLava=False
underFill=False
randomRotation=True
dig=True
tree=True
branch=False
needsFoundation=True
rarity=25
collisionPercentage=20
spawnElevationMin=0
spawnElevationMax=55
spawnInBiome=Custom
[DATA]
-8,8,-5:17.3
-8,8,-4:17.3
-8,7,-3:17.3
-8,8,-3:17.3
-8,7,-2:17.3
-8,7,-1:17.3
-8,6,0:17.3
-8,7,0:17.3
-8,5,1:17.3
-8,6,1:17.3
-7,7,1:17.3
-8,3,2:17.3
-8,4,2:17.3
-8,5,2:17.3
-6,7,2:17.3
-7,2,3:17.3
-7,3,3:17.3
-5,7,3:17.3
-6,1,4:17.3
-6,2,4:17.3
-5,7,4:17.3
-5,1,5:17.3
-4,7,5:17.3
-4,0,6:17.3
-5,1,6:17.3
-4,7,6:17.3
-4,0,7:17.3
-3,7,7:17.3
-4,-1,8:17.3
-4,0,8:17.3
-3,3,8:18.3
-7,7,8:18.3
-3,7,8:17.3
1,7,8:18.3
-3,11,8:18.3
-4,-1,9:17.3
-3,3,9:18.3
-3,6,9:18.3
-7,7,9:18.3
-4,7,9:18.3
-3,7,9:17.3
-2,7,9:18.3
1,7,9:18.3
-3,8,9:18.3
-3,11,9:18.3
-8,-5,10:18.3
0,-5,10:18.3
-4,-4,10:18.3
-7,-1,10:18.3
-4,-1,10:17.3
-1,-1,10:18.3
-4,2,10:18.3
-8,3,10:18.3
0,3,10:18.3
-3,4,10:18.3
-3,6,10:18.3
-2,6,10:18.3
-6,7,10:18.3
-4,7,10:18.3
-3,7,10:18.3
-2,7,10:18.3
0,7,10:18.3
-3,8,10:18.3
-3,10,10:18.3
-8,-5,11:18.3
0,-5,11:18.3
-4,-4,11:18.3
-4,-2,11:18.3
-7,-1,11:18.3
-5,-1,11:18.3
-4,-1,11:17.3
-3,-1,11:18.3
-1,-1,11:18.3
-4,0,11:18.3
-4,2,11:18.3
-8,3,11:18.3
0,3,11:18.3
-3,5,11:18.3
-5,7,11:18.3
-1,7,11:18.3
-3,9,11:18.3
-7,-4,12:18.3
-1,-4,12:18.3
-4,-3,12:18.3
-5,-2,12:18.3
-3,-2,12:18.3
-6,-1,12:18.3
-4,-1,12:18.3
-2,-1,12:18.3
-5,0,12:18.3
-3,0,12:18.3
-4,1,12:18.3
-7,2,12:18.3
-1,2,12:18.3
-6,-3,13:18.3
-2,-3,13:18.3
-5,-2,13:18.3
-3,-2,13:18.3
-5,0,13:18.3
-3,0,13:18.3
-6,1,13:18.3
-2,1,13:18.3
