[META]
version=2.0
spawnOnBlockType=2,12
spawnSunlight=True
spawnDarkness=True
spawnWater=False
spawnLava=False
underFill=False
randomRotation=True
dig=True
tree=True
branch=False
needsFoundation=True
rarity=25
collisionPercentage=20
spawnElevationMin=0
spawnElevationMax=55
spawnInBiome=Custom
[DATA]
4,-2,0:17.3
5,-3,1:17.3
3,-2,1:17.3
4,-2,1:17.3
5,-4,2:17.3
5,-3,2:17.3
2,-2,2:17.3
3,-2,2:17.3
5,-4,3:17.3
6,-4,3:17.3
2,-2,3:17.3
2,-1,3:17.3
6,-7,4:18.3
6,-5,4:18.3
3,-4,4:18.3
5,-4,4:18.3
6,-4,4:17.3
7,-4,4:18.3
9,-4,4:18.3
6,-3,4:18.3
1,-1,4:17.3
2,-1,4:17.3
6,-1,4:18.3
4,-6,5:18.3
6,-6,5:18.3
8,-6,5:18.3
5,-5,5:18.3
6,-5,5:18.3
7,-5,5:18.3
4,-4,5:18.3
5,-4,5:18.3
6,-4,5:18.3
7,-4,5:18.3
8,-4,5:18.3
5,-3,5:18.3
6,-3,5:18.3
7,-3,5:18.3
4,-2,5:18.3
6,-2,5:18.3
8,-2,5:18.3
0,-1,5:17.3
1,-1,5:17.3
5,-5,6:18.3
7,-5,6:18.3
6,-4,6:18.3
5,-3,6:18.3
7,-3,6:18.3
-1,-1,6:17.3
0,-1,6:17.3
-1,-4,7:18.3
-3,-3,7:18.3
1,-3,7:18.3
-1,-2,7:18.3
-4,-1,7:18.3
-2,-1,7:18.3
-1,-1,7:17.3
0,-1,7:18.3
2,-1,7:18.3
-1,0,7:18.3
-3,1,7:18.3
1,1,7:18.3
-1,2,7:18.3
-3,-5,8:18.3
1,-5,8:18.3
-5,-3,8:18.3
-1,-3,8:18.3
3,-3,8:18.3
-2,-2,8:18.3
-1,-2,8:18.3
0,-2,8:18.3
-3,-1,8:18.3
-2,-1,8:18.3
-1,-1,8:18.3
0,-1,8:18.3
1,-1,8:18.3
-2,0,8:18.3
-1,0,8:18.3
0,0,8:18.3
-5,1,8:18.3
-1,1,8:18.3
3,1,8:18.3
-3,3,8:18.3
1,3,8:18.3
-3,-4,9:18.3
1,-4,9:18.3
-4,-3,9:18.3
-3,-3,9:18.3
-2,-3,9:18.3
0,-3,9:18.3
1,-3,9:18.3
2,-3,9:18.3
-3,-2,9:18.3
-2,-2,9:18.3
-1,-2,9:18.3
0,-2,9:18.3
1,-2,9:18.3
-2,-1,9:18.3
-1,-1,9:18.3
0,-1,9:18.3
-3,0,9:18.3
-2,0,9:18.3
-1,0,9:18.3
0,0,9:18.3
1,0,9:18.3
-4,1,9:18.3
-3,1,9:18.3
-2,1,9:18.3
0,1,9:18.3
1,1,9:18.3
2,1,9:18.3
-3,2,9:18.3
1,2,9:18.3
-3,-3,10:18.3
1,-3,10:18.3
-2,-2,10:18.3
0,-2,10:18.3
-1,-1,10:18.3
-2,0,10:18.3
0,0,10:18.3
-3,1,10:18.3
1,1,10:18.3
-2,-1,6:127.11
-1,-2,6:127.8
7,-4,3:127.9
