[META]
version=2.0
spawnOnBlockType=2,12
spawnSunlight=True
spawnDarkness=True
spawnWater=False
spawnLava=False
underFill=False
randomRotation=True
dig=True
tree=True
branch=False
needsFoundation=True
rarity=25
collisionPercentage=20
spawnElevationMin=0
spawnElevationMax=55
spawnInBiome=Custom
[DATA]
1,-1,0:17.3
0,0,0:17.3
1,0,0:17.3
2,0,0:17.3
1,1,0:17.3
1,0,1:17.3
2,0,1:17.3
1,1,1:17.3
1,0,2:17.3
1,0,3:17.3
0,0,4:17.3
1,0,4:17.3
0,0,5:17.3
1,0,5:17.3
0,0,6:17.3
0,0,7:17.3
0,0,8:17.3
0,0,9:17.3
0,0,10:17.3
0,0,11:17.3
0,-3,12:18.3
-3,0,12:18.3
0,0,12:17.3
3,0,12:18.3
0,3,12:18.3
-3,-3,13:18.3
3,-3,13:18.3
0,-2,13:18.3
-2,0,13:18.3
0,0,13:17.3
2,0,13:18.3
0,2,13:18.3
-3,3,13:18.3
3,3,13:18.3
0,-4,14:18.3
-2,-2,14:18.3
2,-2,14:18.3
0,-1,14:18.3
-4,0,14:18.3
-1,0,14:18.3
0,0,14:17.3
1,0,14:18.3
4,0,14:18.3
-1,1,14:18.3
0,1,14:18.3
1,1,14:18.3
-2,2,14:18.3
2,2,14:18.3
0,4,14:18.3
0,-3,15:18.3
0,-2,15:18.3
-1,-1,15:18.3
0,-1,15:18.3
1,-1,15:18.3
-3,0,15:18.3
-2,0,15:18.3
-1,0,15:18.3
0,0,15:17.3
1,0,15:18.3
2,0,15:18.3
3,0,15:18.3
-1,1,15:18.3
0,1,15:18.3
1,1,15:18.3
0,2,15:18.3
0,3,15:18.3
-2,-5,16:18.3
2,-5,16:18.3
-5,-2,16:18.3
-2,-2,16:18.3
2,-2,16:18.3
5,-2,16:18.3
0,-1,16:18.3
-1,0,16:18.3
0,0,16:17.3
1,0,16:18.3
0,1,16:18.3
-5,2,16:18.3
-2,2,16:18.3
2,2,16:18.3
5,2,16:18.3
-2,5,16:18.3
2,5,16:18.3
-1,-4,17:18.3
1,-4,17:18.3
0,-2,17:18.3
-4,-1,17:18.3
0,-1,17:18.3
4,-1,17:18.3
-2,0,17:18.3
-1,0,17:18.3
0,0,17:17.3
1,0,17:18.3
2,0,17:18.3
-4,1,17:18.3
0,1,17:18.3
4,1,17:18.3
0,2,17:18.3
-1,4,17:18.3
1,4,17:18.3
0,-3,18:18.3
0,-1,18:18.3
-3,0,18:18.3
-1,0,18:18.3
0,0,18:18.3
1,0,18:18.3
3,0,18:18.3
0,1,18:18.3
0,3,18:18.3
0,1,13:127.10
1,0,13:127.9
-1,0,13:127.11
0,-1,13:127.8
