[META]
version=2.0
spawnOnBlockType=2
spawnSunlight=True
spawnDarkness=True
spawnWater=False
spawnLava=False
underFill=False
randomRotation=True
dig=True
tree=True
branch=False
needsFoundation=True
rarity=25
collisionPercentage=20
spawnElevationMin=0
spawnElevationMax=200
spawnInBiome=Custom
[DATA]
0,0,0:17.3
0,0,1:17.3
0,0,2:17.3
0,0,3:17.3
0,0,4:17.3
-1,1,4:18.3
0,1,4:17.3
1,1,4:18.3
-1,2,4:18.3
0,2,4:17.3
1,2,4:18.3
2,2,4:18.3
-2,3,4:18.3
-1,3,4:18.3
0,3,4:18.3
1,3,4:18.3
-3,4,4:18.3
-2,4,4:18.3
-1,4,4:18.3
2,-1,5:18.3
-1,0,5:18.3
0,0,5:17.3
1,0,5:18.3
-2,1,5:18.3
-1,1,5:18.3
0,1,5:18.3
1,1,5:18.3
2,1,5:18.3
3,1,5:18.3
-3,2,5:18.3
-2,2,5:18.3
-1,2,5:18.3
0,2,5:18.3
1,2,5:18.3
2,2,5:18.3
3,2,5:18.3
-4,3,5:18.3
-3,3,5:18.3
-2,3,5:18.3
-1,3,5:18.3
0,3,5:17.3
1,3,5:18.3
2,3,5:18.3
3,3,5:18.3
-4,4,5:18.3
-3,4,5:18.3
-2,4,5:18.3
-1,4,5:18.3
0,4,5:18.3
1,4,5:18.3
2,4,5:18.3
-3,5,5:18.3
-2,5,5:18.3
-1,5,5:18.3
0,5,5:18.3
1,5,5:18.3
-2,6,5:18.3
-1,6,5:18.3
1,-3,6:18.3
2,-3,6:18.3
0,-2,6:18.3
1,-2,6:18.3
2,-2,6:18.3
3,-2,6:18.3
4,-2,6:18.3
0,-1,6:18.3
1,-1,6:18.3
2,-1,6:17.7
3,-1,6:18.3
4,-1,6:18.3
5,-1,6:18.3
0,0,6:17.3
1,0,6:17.7
2,0,6:18.3
3,0,6:18.3
4,0,6:18.3
-1,1,6:18.3
0,1,6:18.3
1,1,6:18.3
2,1,6:18.3
3,1,6:18.3
-1,2,6:18.3
0,2,6:18.3
1,2,6:18.3
2,2,6:18.3
-3,3,6:18.3
-2,3,6:18.3
-1,3,6:18.3
0,3,6:18.3
1,3,6:18.3
-3,4,6:18.3
-2,4,6:18.3
-1,4,6:18.3
0,4,6:18.3
-2,5,6:18.3
-1,5,6:18.3
1,-5,7:18.3
2,-5,7:18.3
0,-4,7:18.3
1,-4,7:18.3
2,-4,7:18.3
3,-4,7:18.3
-1,-3,7:18.3
0,-3,7:18.3
1,-3,7:18.3
2,-3,7:18.3
3,-3,7:18.3
4,-3,7:18.3
5,-3,7:18.3
-1,-2,7:18.3
0,-2,7:18.3
1,-2,7:18.3
2,-2,7:18.3
3,-2,7:17.3
4,-2,7:18.3
5,-2,7:18.3
-1,-1,7:18.3
0,-1,7:18.3
1,-1,7:18.3
2,-1,7:18.3
3,-1,7:18.3
4,-1,7:18.3
5,-1,7:18.3
6,-1,7:18.3
0,0,7:17.3
1,0,7:18.3
2,0,7:18.3
3,0,7:18.3
4,0,7:18.3
5,0,7:18.3
6,0,7:18.3
2,1,7:18.3
3,1,7:18.3
4,1,7:18.3
5,1,7:18.3
3,2,7:18.3
4,2,7:18.3
1,-4,8:18.3
2,-4,8:18.3
1,-3,8:18.3
2,-3,8:18.3
3,-3,8:18.3
0,-2,8:18.3
1,-2,8:18.3
2,-2,8:18.3
3,-2,8:18.3
4,-2,8:18.3
0,-1,8:18.3
1,-1,8:18.3
2,-1,8:18.3
3,-1,8:18.3
4,-1,8:18.3
5,-1,8:18.3
0,0,8:17.3
2,0,8:18.3
3,0,8:18.3
4,0,8:18.3
5,0,8:18.3
3,1,8:18.3
4,1,8:18.3
0,-1,9:17.3
0,0,9:17.3
0,-4,10:18.3
-1,-3,10:18.3
0,-3,10:18.3
1,-3,10:18.3
2,-3,10:18.3
-2,-2,10:18.3
-1,-2,10:18.3
0,-2,10:17.3
1,-2,10:18.3
0,-1,10:18.3
0,0,10:17.3
0,-6,11:18.3
1,-6,11:18.3
-1,-5,11:18.3
0,-5,11:18.3
1,-5,11:18.3
2,-5,11:18.3
-2,-4,11:18.3
-1,-4,11:18.3
0,-4,11:18.3
1,-4,11:18.3
2,-4,11:18.3
-3,-3,11:18.3
-2,-3,11:18.3
-1,-3,11:18.3
0,-3,11:17.3
1,-3,11:18.3
2,-3,11:18.3
3,-3,11:18.3
-3,-2,11:18.3
-2,-2,11:18.3
-1,-2,11:18.3
0,-2,11:18.3
1,-2,11:18.3
2,-2,11:18.3
3,-2,11:18.3
-2,-1,11:18.3
-1,-1,11:18.3
0,-1,11:18.3
1,-1,11:18.3
2,-1,11:18.3
-1,0,11:18.3
0,0,11:17.3
1,0,11:18.3
-1,1,11:17.3
0,-5,12:18.3
-1,-4,12:18.3
0,-4,12:18.3
1,-4,12:18.3
-1,-3,12:18.3
0,-3,12:18.3
1,-3,12:18.3
2,-3,12:18.3
-2,-2,12:18.3
-1,-2,12:18.3
0,-2,12:18.3
1,-2,12:18.3
-1,-1,12:18.3
0,-1,12:18.3
-1,0,12:18.3
0,0,12:17.3
-2,1,12:18.3
-1,1,12:18.3
0,1,12:18.3
-3,2,12:18.3
-2,2,12:17.3
-1,2,12:18.3
-4,3,12:18.3
-3,3,12:18.3
-2,3,12:18.3
-1,3,12:18.3
-3,4,12:18.3
-2,4,12:18.3
-1,-1,13:18.3
0,-1,13:18.3
-3,0,13:18.3
-2,0,13:18.3
-1,0,13:18.3
0,0,13:17.3
1,0,13:18.3
-4,1,13:18.3
-3,1,13:18.3
-2,1,13:18.3
-1,1,13:18.3
0,1,13:18.3
1,1,13:18.3
-5,2,13:18.3
-4,2,13:18.3
-3,2,13:18.3
-2,2,13:18.3
-1,2,13:18.3
0,2,13:18.3
-5,3,13:18.3
-4,3,13:18.3
-3,3,13:17.3
-2,3,13:18.3
-1,3,13:18.3
0,3,13:18.3
-5,4,13:18.3
-4,4,13:18.3
-3,4,13:18.3
-2,4,13:18.3
-1,4,13:18.3
0,4,13:18.3
-4,5,13:18.3
-3,5,13:18.3
-2,5,13:18.3
-1,5,13:18.3
-3,6,13:18.3
-2,6,13:18.3
-1,-2,14:18.3
0,-2,14:18.3
1,-2,14:18.3
-2,-1,14:18.3
-1,-1,14:17.3
0,-1,14:18.3
1,-1,14:18.3
2,-1,14:18.3
-2,0,14:18.3
-1,0,14:18.3
0,0,14:18.3
1,0,14:17.3
2,0,14:18.3
3,0,14:18.3
-2,1,14:18.3
-1,1,14:17.3
0,1,14:18.3
1,1,14:18.3
2,1,14:18.3
-4,2,14:18.3
-3,2,14:18.3
-2,2,14:18.3
-1,2,14:18.3
0,2,14:18.3
1,2,14:18.3
2,2,14:18.3
-4,3,14:18.3
-3,3,14:18.3
-2,3,14:18.3
-1,3,14:18.3
0,3,14:18.3
1,3,14:18.3
-3,4,14:18.3
-2,4,14:18.3
-1,-4,15:18.3
0,-4,15:18.3
1,-4,15:18.3
-2,-3,15:18.3
-1,-3,15:18.3
0,-3,15:18.3
1,-3,15:18.3
2,-3,15:18.3
3,-3,15:18.3
-4,-2,15:18.3
-3,-2,15:18.3
-2,-2,15:18.3
-1,-2,15:18.3
0,-2,15:18.3
1,-2,15:18.3
2,-2,15:18.3
3,-2,15:18.3
4,-2,15:18.3
-5,-1,15:18.3
-4,-1,15:18.3
-3,-1,15:18.3
-2,-1,15:17.3
-1,-1,15:18.3
0,-1,15:18.3
1,-1,15:17.3
2,-1,15:18.3
3,-1,15:18.3
4,-1,15:18.3
5,-1,15:18.3
-5,0,15:18.3
-4,0,15:18.3
-3,0,15:18.3
-2,0,15:18.3
-1,0,15:18.3
0,0,15:18.3
1,0,15:18.3
2,0,15:18.3
3,0,15:18.3
4,0,15:18.3
5,0,15:18.3
-6,1,15:18.3
-5,1,15:18.3
-4,1,15:18.3
-3,1,15:18.3
-2,1,15:17.3
-1,1,15:18.3
0,1,15:18.3
1,1,15:18.3
2,1,15:17.3
3,1,15:18.3
4,1,15:18.3
-6,2,15:18.3
-5,2,15:18.3
-4,2,15:18.3
-3,2,15:18.3
-2,2,15:18.3
-1,2,15:18.3
0,2,15:17.3
1,2,15:18.3
2,2,15:18.3
3,2,15:18.3
4,2,15:18.3
-5,3,15:18.3
-4,3,15:18.3
-3,3,15:18.3
-2,3,15:18.3
-1,3,15:18.3
0,3,15:18.3
1,3,15:18.3
2,3,15:18.3
3,3,15:18.3
-4,4,15:18.3
-3,4,15:18.3
-2,4,15:18.3
-1,4,15:18.3
0,4,15:18.3
1,4,15:18.3
2,4,15:18.3
-3,5,15:18.3
-2,5,15:18.3
0,5,15:18.3
1,5,15:18.3
0,-3,16:18.3
1,-3,16:18.3
-2,-2,16:18.3
-1,-2,16:18.3
0,-2,16:18.3
1,-2,16:18.3
2,-2,16:18.3
3,-2,16:18.3
-4,-1,16:18.3
-3,-1,16:18.3
-2,-1,16:18.3
-1,-1,16:18.3
0,-1,16:18.3
1,-1,16:18.3
2,-1,16:18.3
3,-1,16:18.3
-4,0,16:18.3
-3,0,16:18.3
-2,0,16:18.3
-1,0,16:18.3
0,0,16:18.3
1,0,16:18.3
2,0,16:18.3
3,0,16:18.3
4,0,16:18.3
-5,1,16:18.3
-4,1,16:18.3
-3,1,16:18.3
-2,1,16:18.3
-1,1,16:18.3
0,1,16:18.3
1,1,16:18.3
2,1,16:18.3
3,1,16:18.3
-5,2,16:18.3
-4,2,16:18.3
-3,2,16:18.3
-2,2,16:18.3
-1,2,16:18.3
0,2,16:18.3
1,2,16:18.3
2,2,16:18.3
3,2,16:18.3
-4,3,16:18.3
-3,3,16:18.3
-2,3,16:18.3
-1,3,16:18.3
0,3,16:18.3
1,3,16:18.3
2,3,16:18.3
-2,4,16:18.3
-1,4,16:18.3
0,4,16:18.3
1,4,16:18.3
-1,0,10:127.11
0,1,11:127.10
1,0,12:127.9
0,1,10:106.4
2,2,13:106.0
1,2,13:106.2
2,1,13:106.0
0,-3,13:106.1
-1,-3,13:106.1
1,3,12:106.2
1,2,12:106.2
-4,2,12:106.8
-3,1,12:106.1
-4,1,12:106.0
-1,-4,14:106.0
1,3,11:106.2
1,2,11:106.2
-1,-3,14:106.1
1,3,10:106.2
1,2,10:106.2
1,3,13:106.2
-1,1,10:106.0
1,0,10:106.2
0,-3,14:106.1
-2,-3,10:106.8
1,-4,10:106.1
1,2,9:106.2
0,1,9:106.4
1,0,9:106.2
0,1,8:106.4
1,0,8:106.2
0,1,7:106.4
-2,-2,7:106.8
4,1,6:106.4
6,0,6:106.0
5,0,6:106.2
5,-1,5:106.0
0,-1,5:106.1
0,4,4:106.4
-3,3,4:106.8
0,-1,4:106.1
