[META]
version=2.0
spawnOnBlockType=2
spawnSunlight=True
spawnDarkness=True
spawnWater=False
spawnLava=False
underFill=False
randomRotation=True
dig=True
tree=True
branch=False
needsFoundation=True
rarity=25
collisionPercentage=20
spawnElevationMin=0
spawnElevationMax=55
spawnInBiome=Custom
[DATA]
-1,-4,-6:17.3
-1,-4,-5:17.3
-1,-4,-4:17.3
-1,-4,-3:17.3
-1,-4,-2:17.3
-1,-4,-1:17.3
-1,-4,0:17.3
-1,-3,1:17.3
-1,-2,2:17.3
-1,-1,3:17.3
-1,-1,4:17.3
-1,0,5:17.3
-1,0,6:17.3
-5,-3,7:18.3
3,-3,7:18.3
-1,1,7:17.3
-5,5,7:18.3
3,5,7:18.3
-5,-3,8:18.3
3,-3,8:18.3
-1,1,8:17.3
-5,5,8:18.3
3,5,8:18.3
-4,-2,9:18.3
2,-2,9:18.3
-1,0,9:18.3
-2,1,9:18.3
-1,1,9:17.3
0,1,9:18.3
-1,2,9:18.3
0,2,9:0
-4,4,9:18.3
2,4,9:18.3
-3,-1,10:18.3
1,-1,10:18.3
-2,0,10:18.3
0,0,10:18.3
-1,1,10:18.3
-2,2,10:18.3
0,2,10:18.3
-3,3,10:18.3
1,3,10:18.3
-1,-1,11:18.3
-1,0,11:18.3
-3,1,11:18.3
-2,1,11:18.3
0,1,11:18.3
1,1,11:18.3
-1,2,11:18.3
-1,3,11:18.3
-1,-1,12:18.3
-3,1,12:18.3
1,1,12:18.3
-1,3,12:18.3
-1,-2,13:18.3
-4,1,13:18.3
2,1,13:18.3
-1,4,13:18.3
