[META]
version=2.0
spawnOnBlockType=2
spawnSunlight=True
spawnDarkness=True
spawnWater=True
spawnLava=False
underFill=False
randomRotation=True
dig=True
tree=True
branch=False
needsFoundation=True
rarity=25
collisionPercentage=50
spawnElevationMin=40
spawnElevationMax=52
spawnInBiome=Custom
[DATA]
-1,-4,-4:17.3
0,-4,-4:17.3
1,-4,-4:17.3
2,-4,-4:17.3
3,-4,-4:17.3
4,-4,-4:17.3
-2,-3,-4:17.3
-1,-3,-4:17.3
0,-3,-4:17.3
1,-3,-4:17.3
2,-3,-4:17.3
3,-3,-4:17.3
4,-3,-4:17.3
5,-3,-4:17.3
-3,-2,-4:17.3
-2,-2,-4:17.3
-1,-2,-4:17.3
0,-2,-4:17.3
1,-2,-4:17.3
2,-2,-4:17.3
3,-2,-4:17.3
4,-2,-4:17.3
5,-2,-4:17.3
-3,-1,-4:17.3
-2,-1,-4:17.3
-1,-1,-4:17.3
0,-1,-4:17.3
1,-1,-4:17.3
2,-1,-4:17.3
3,-1,-4:17.3
4,-1,-4:17.3
5,-1,-4:17.3
-2,0,-4:17.3
-1,0,-4:17.3
0,0,-4:17.3
1,0,-4:17.3
2,0,-4:17.3
3,0,-4:17.3
4,0,-4:17.3
-1,1,-4:17.3
0,1,-4:17.3
1,1,-4:17.3
2,1,-4:17.3
3,1,-4:17.3
0,2,-4:17.3
1,2,-4:17.3
2,2,-4:17.3
1,3,-4:17.3
0,-4,-3:17.3
1,-4,-3:17.3
2,-4,-3:17.3
-2,-3,-3:17.3
-1,-3,-3:17.3
0,-3,-3:17.3
1,-3,-3:17.3
2,-3,-3:17.3
3,-3,-3:17.3
4,-3,-3:17.3
-2,-2,-3:17.3
-1,-2,-3:17.3
0,-2,-3:17.3
1,-2,-3:17.3
2,-2,-3:17.3
3,-2,-3:17.3
4,-2,-3:17.3
5,-2,-3:17.3
-2,-1,-3:17.3
-1,-1,-3:17.3
0,-1,-3:17.3
1,-1,-3:17.3
2,-1,-3:17.3
3,-1,-3:17.3
4,-1,-3:17.3
5,-1,-3:17.3
-2,0,-3:17.3
-1,0,-3:17.3
0,0,-3:17.3
1,0,-3:17.3
2,0,-3:17.3
3,0,-3:17.3
4,0,-3:17.3
5,0,-3:17.3
-1,1,-3:17.3
0,1,-3:17.3
1,1,-3:17.3
2,1,-3:17.3
3,1,-3:17.3
4,1,-3:17.3
-1,2,-3:17.3
0,2,-3:17.3
1,2,-3:17.3
2,2,-3:17.3
3,2,-3:17.3
0,3,-3:17.3
1,3,-3:17.3
2,3,-3:17.3
1,-3,-2:17.3
2,-3,-2:17.3
-1,-2,-2:17.3
0,-2,-2:17.3
1,-2,-2:17.3
2,-2,-2:17.3
3,-2,-2:17.3
-1,-1,-2:17.3
0,-1,-2:17.3
1,-1,-2:17.3
2,-1,-2:17.3
3,-1,-2:17.3
4,-1,-2:17.3
-1,0,-2:17.3
0,0,-2:17.3
1,0,-2:17.3
2,0,-2:17.3
3,0,-2:17.3
4,0,-2:17.3
-1,1,-2:17.3
0,1,-2:17.3
1,1,-2:17.3
2,1,-2:17.3
3,1,-2:17.3
4,1,-2:17.3
0,2,-2:17.3
1,2,-2:17.3
2,2,-2:17.3
3,2,-2:17.3
1,3,-2:17.3
1,-3,-1:17.3
0,-2,-1:17.3
1,-2,-1:17.3
2,-2,-1:17.3
-1,-1,-1:17.3
0,-1,-1:17.3
1,-1,-1:17.3
2,-1,-1:17.3
3,-1,-1:17.3
0,0,-1:17.3
1,0,-1:17.3
2,0,-1:17.3
1,1,-1:17.3
1,-3,0:17.3
0,-2,0:17.3
1,-2,0:17.3
2,-2,0:17.3
-1,-1,0:17.3
0,-1,0:17.3
1,-1,0:17.3
2,-1,0:17.3
3,-1,0:17.3
0,0,0:17.3
1,0,0:17.3
2,0,0:17.3
1,1,0:17.3
1,-3,1:17.3
0,-2,1:17.3
1,-2,1:17.3
2,-2,1:17.3
-1,-1,1:17.3
0,-1,1:17.3
1,-1,1:17.3
2,-1,1:17.3
3,-1,1:17.3
0,0,1:17.3
1,0,1:17.3
2,0,1:17.3
1,1,1:17.3
1,-3,2:17.3
0,-2,2:17.3
1,-2,2:17.3
2,-2,2:17.3
-1,-1,2:17.3
0,-1,2:17.3
1,-1,2:17.3
2,-1,2:17.3
3,-1,2:17.3
0,0,2:17.3
1,0,2:17.3
2,0,2:17.3
1,1,2:17.3
0,-2,3:17.3
1,-2,3:17.3
2,-2,3:17.3
0,-1,3:17.3
1,-1,3:17.3
2,-1,3:17.3
0,0,3:17.3
1,0,3:17.3
2,0,3:17.3
0,-2,4:17.3
1,-2,4:17.3
2,-2,4:17.3
0,-1,4:17.3
1,-1,4:17.3
2,-1,4:17.3
0,0,4:17.3
1,0,4:17.3
2,0,4:17.3
0,-2,5:17.3
1,-2,5:17.3
2,-2,5:17.3
0,-1,5:17.3
1,-1,5:17.3
2,-1,5:17.3
0,0,5:17.3
1,0,5:17.3
2,0,5:17.3
0,-2,6:17.3
1,-2,6:17.3
2,-2,6:17.3
0,-1,6:17.3
1,-1,6:17.3
2,-1,6:17.3
0,0,6:17.3
1,0,6:17.3
2,0,6:17.3
0,-2,7:17.3
1,-2,7:17.3
2,-2,7:17.3
0,-1,7:17.3
1,-1,7:17.3
2,-1,7:17.3
0,0,7:17.3
1,0,7:17.3
2,0,7:17.3
0,-2,8:17.3
1,-2,8:17.3
2,-2,8:17.3
0,-1,8:17.3
1,-1,8:17.3
2,-1,8:17.3
0,0,8:17.3
1,0,8:17.3
2,0,8:17.3
1,-2,9:17.3
0,-1,9:17.3
1,-1,9:17.3
2,-1,9:17.3
1,0,9:17.3
1,-2,10:17.3
0,-1,10:17.3
1,-1,10:17.3
2,-1,10:17.3
1,0,10:17.3
1,-2,11:17.3
0,-1,11:17.3
1,-1,11:17.3
2,-1,11:17.3
1,0,11:17.3
1,-2,12:17.3
0,-1,12:17.3
1,-1,12:17.3
2,-1,12:17.3
1,0,12:17.3
1,-2,13:17.3
0,-1,13:17.3
1,-1,13:17.3
2,-1,13:17.3
1,0,13:17.3
1,-2,14:17.3
0,-1,14:17.3
1,-1,14:17.3
2,-1,14:17.3
1,0,14:17.3
1,-2,15:17.3
0,-1,15:17.3
1,-1,15:17.3
2,-1,15:17.3
1,0,15:17.3
1,-2,16:17.3
0,-1,16:17.3
1,-1,16:17.3
2,-1,16:17.3
1,0,16:17.3
1,-2,17:17.3
0,-1,17:17.3
1,-1,17:17.3
2,-1,17:17.3
1,0,17:17.3
1,-1,18:17.3
1,-1,19:17.3
1,-1,20:17.3
1,-1,21:17.3
1,-1,22:17.3
2,-1,22:17.3
2,-2,23:17.3
1,-1,23:17.3
2,-3,24:17.3
1,-1,24:17.3
3,-4,25:17.3
1,-1,25:17.3
3,-5,26:17.3
1,-1,26:17.3
4,-5,27:17.3
0,-2,27:17.3
1,-1,27:17.3
4,-6,28:17.3
-1,-3,28:17.3
1,-1,28:17.3
5,-7,29:17.3
-1,-3,29:17.3
1,-1,29:17.3
1,0,29:17.3
5,-8,30:17.3
-2,-4,30:17.3
1,-1,30:17.3
2,-1,30:17.3
0,0,30:17.3
1,0,30:17.3
6,-9,31:17.3
-3,-5,31:17.3
1,-1,31:17.3
3,-1,31:17.3
0,0,31:17.3
0,1,31:17.3
1,1,31:17.3
6,-9,32:17.3
-3,-5,32:17.3
0,-1,32:17.3
1,-1,32:17.3
2,-1,32:17.3
4,0,32:17.3
0,1,32:17.3
0,2,32:17.3
1,2,32:17.3
7,-10,33:17.3
-4,-6,33:17.3
0,-2,33:17.3
1,-2,33:17.3
1,-1,33:17.3
3,-1,33:17.3
0,0,33:17.3
1,0,33:17.3
5,0,33:17.3
0,2,33:17.3
0,3,33:17.3
1,3,33:17.3
7,-11,34:17.3
-5,-7,34:17.3
-1,-3,34:17.3
1,-3,34:17.3
2,-3,34:17.3
0,-2,34:17.3
1,-1,34:17.3
4,-1,34:17.3
0,0,34:17.3
6,0,34:17.3
0,1,34:17.3
0,3,34:17.3
0,4,34:17.3
1,4,34:17.3
8,-12,35:17.3
-5,-7,35:17.3
1,-4,35:17.3
2,-4,35:17.3
-1,-3,35:17.3
0,-3,35:17.3
1,-2,35:17.3
1,-1,35:17.3
5,-1,35:17.3
2,0,35:17.3
7,0,35:17.3
0,1,35:17.3
0,2,35:17.3
0,4,35:17.3
0,5,35:17.3
1,5,35:17.3
8,-13,36:17.3
-6,-8,36:17.3
1,-5,36:17.3
-2,-4,36:17.3
0,-4,36:17.3
3,-4,36:17.3
2,-3,36:17.3
0,-1,36:17.3
1,-1,36:17.3
6,-1,36:17.3
1,0,36:17.3
3,0,36:17.3
8,1,36:17.3
0,2,36:17.3
0,3,36:17.3
-1,5,36:17.3
0,5,36:17.3
1,6,36:17.3
9,-13,37:17.3
-7,-9,37:17.3
0,-6,37:17.3
0,-5,37:17.3
3,-5,37:17.3
-3,-4,37:17.3
3,-3,37:17.3
0,-2,37:17.3
1,-1,37:17.3
2,-1,37:17.3
7,-1,37:17.3
-1,0,37:17.3
1,0,37:17.3
3,1,37:17.3
9,1,37:17.3
0,3,37:17.3
0,4,37:17.3
0,5,37:17.3
-1,6,37:17.3
1,7,37:17.3
9,-14,38:17.3
-7,-9,38:17.3
0,-7,38:17.3
-1,-6,38:17.3
4,-6,38:17.3
-3,-5,38:17.3
3,-4,38:17.3
-1,-3,38:17.3
2,-2,38:17.3
1,-1,38:17.3
8,-1,38:17.3
-2,0,38:17.3
0,0,38:17.3
3,0,38:17.3
4,1,38:17.3
10,1,38:17.3
0,4,38:17.3
0,5,38:17.3
0,6,38:17.3
-1,7,38:17.3
1,8,38:17.3
10,-15,39:17.3
-8,-10,39:17.3
0,-8,39:17.3
-1,-7,39:17.3
4,-7,39:17.3
-4,-5,39:17.3
4,-5,39:17.3
-2,-4,39:17.3
4,-4,39:17.3
3,-2,39:17.3
0,-1,39:17.3
1,-1,39:17.3
9,-1,39:17.3
-1,0,39:17.3
4,0,39:17.3
-3,1,39:17.3
11,1,39:17.3
5,2,39:17.3
0,5,39:17.3
0,6,39:17.3
0,7,39:17.3
-1,8,39:17.3
1,9,39:17.3
14,-22,40:18.3
15,-22,40:18.3
16,-22,40:18.3
13,-21,40:18.3
14,-21,40:18.3
15,-21,40:18.3
16,-21,40:18.3
17,-21,40:18.3
-5,-20,40:18.3
-4,-20,40:18.3
-3,-20,40:18.3
13,-20,40:18.3
14,-20,40:18.3
15,-20,40:17.3
16,-20,40:18.3
17,-20,40:18.3
-6,-19,40:18.3
-5,-19,40:18.3
-4,-19,40:18.3
-3,-19,40:18.3
-2,-19,40:18.3
13,-19,40:18.3
14,-19,40:18.3
15,-19,40:18.3
16,-19,40:18.3
17,-19,40:18.3
-6,-18,40:18.3
-5,-18,40:18.3
-4,-18,40:17.3
-3,-18,40:18.3
-2,-18,40:18.3
14,-18,40:18.3
15,-18,40:18.3
16,-18,40:18.3
-6,-17,40:18.3
-5,-17,40:18.3
-4,-17,40:18.3
-3,-17,40:18.3
-2,-17,40:18.3
0,-17,40:18.3
1,-17,40:18.3
2,-17,40:18.3
-6,-16,40:18.3
-5,-16,40:18.3
-4,-16,40:17.3
-3,-16,40:18.3
-2,-16,40:18.3
-1,-16,40:18.3
0,-16,40:18.3
1,-16,40:18.3
2,-16,40:18.3
3,-16,40:18.3
10,-16,40:17.3
12,-16,40:18.3
13,-16,40:18.3
14,-16,40:18.3
-6,-15,40:18.3
-5,-15,40:18.3
-4,-15,40:18.3
-3,-15,40:18.3
-2,-15,40:18.3
-1,-15,40:18.3
0,-15,40:18.3
1,-15,40:17.3
2,-15,40:18.3
3,-15,40:18.3
11,-15,40:18.3
12,-15,40:18.3
13,-15,40:18.3
14,-15,40:18.3
15,-15,40:18.3
-9,-14,40:18.3
-8,-14,40:18.3
-7,-14,40:18.3
-5,-14,40:18.3
-4,-14,40:18.3
-3,-14,40:18.3
-2,-14,40:18.3
-1,-14,40:18.3
0,-14,40:17.3
1,-14,40:17.3
2,-14,40:18.3
3,-14,40:18.3
11,-14,40:18.3
12,-14,40:18.3
13,-14,40:17.3
14,-14,40:18.3
15,-14,40:18.3
17,-14,40:18.3
18,-14,40:18.3
19,-14,40:18.3
-10,-13,40:18.3
-9,-13,40:18.3
-8,-13,40:18.3
-7,-13,40:18.3
-6,-13,40:18.3
-4,-13,40:18.3
-3,-13,40:18.3
-2,-13,40:18.3
-1,-13,40:18.3
0,-13,40:18.3
1,-13,40:18.3
2,-13,40:18.3
3,-13,40:18.3
11,-13,40:18.3
12,-13,40:18.3
13,-13,40:18.3
14,-13,40:18.3
15,-13,40:18.3
16,-13,40:18.3
17,-13,40:18.3
18,-13,40:18.3
19,-13,40:18.3
20,-13,40:18.3
-21,-12,40:18.3
-20,-12,40:18.3
-19,-12,40:18.3
-13,-12,40:18.3
-12,-12,40:18.3
-11,-12,40:18.3
-10,-12,40:18.3
-9,-12,40:18.3
-8,-12,40:17.3
-7,-12,40:18.3
-6,-12,40:18.3
-4,-12,40:18.3
-3,-12,40:18.3
-2,-12,40:17.3
-1,-12,40:18.3
0,-12,40:18.3
1,-12,40:17.3
2,-12,40:18.3
3,-12,40:18.3
12,-12,40:18.3
13,-12,40:18.3
14,-12,40:18.3
16,-12,40:18.3
17,-12,40:18.3
18,-12,40:17.3
19,-12,40:18.3
20,-12,40:18.3
-22,-11,40:18.3
-21,-11,40:18.3
-20,-11,40:18.3
-19,-11,40:18.3
-18,-11,40:18.3
-14,-11,40:18.3
-13,-11,40:18.3
-12,-11,40:18.3
-11,-11,40:18.3
-10,-11,40:18.3
-9,-11,40:18.3
-8,-11,40:18.3
-7,-11,40:18.3
-6,-11,40:18.3
-4,-11,40:18.3
-3,-11,40:18.3
-2,-11,40:18.3
-1,-11,40:18.3
0,-11,40:18.3
1,-11,40:18.3
2,-11,40:18.3
3,-11,40:18.3
4,-11,40:18.3
5,-11,40:18.3
6,-11,40:18.3
7,-11,40:18.3
8,-11,40:18.3
16,-11,40:18.3
17,-11,40:18.3
18,-11,40:18.3
19,-11,40:18.3
20,-11,40:18.3
-22,-10,40:18.3
-21,-10,40:18.3
-20,-10,40:17.3
-19,-10,40:18.3
-18,-10,40:18.3
-14,-10,40:18.3
-13,-10,40:18.3
-12,-10,40:17.3
-11,-10,40:18.3
-10,-10,40:18.3
-9,-10,40:18.3
-8,-10,40:17.3
-7,-10,40:18.3
-6,-10,40:18.3
-5,-10,40:18.3
-3,-10,40:18.3
-2,-10,40:18.3
-1,-10,40:17.3
0,-10,40:18.3
1,-10,40:18.3
2,-10,40:18.3
3,-10,40:18.3
4,-10,40:18.3
5,-10,40:18.3
6,-10,40:18.3
7,-10,40:18.3
8,-10,40:18.3
9,-10,40:18.3
17,-10,40:18.3
18,-10,40:18.3
19,-10,40:18.3
-22,-9,40:18.3
-21,-9,40:18.3
-20,-9,40:18.3
-19,-9,40:18.3
-18,-9,40:18.3
-14,-9,40:18.3
-13,-9,40:18.3
-12,-9,40:18.3
-11,-9,40:18.3
-10,-9,40:18.3
-9,-9,40:18.3
-8,-9,40:18.3
-7,-9,40:17.3
-6,-9,40:18.3
-5,-9,40:18.3
-3,-9,40:18.3
-2,-9,40:18.3
-1,-9,40:18.3
0,-9,40:18.3
1,-9,40:18.3
2,-9,40:18.3
3,-9,40:18.3
4,-9,40:18.3
5,-9,40:17.3
6,-9,40:18.3
7,-9,40:17.3
8,-9,40:18.3
9,-9,40:18.3
-21,-8,40:18.3
-20,-8,40:18.3
-19,-8,40:18.3
-17,-8,40:18.3
-16,-8,40:18.3
-15,-8,40:18.3
-13,-8,40:18.3
-12,-8,40:18.3
-11,-8,40:18.3
-10,-8,40:18.3
-9,-8,40:18.3
-8,-8,40:18.3
-7,-8,40:18.3
-6,-8,40:18.3
-5,-8,40:18.3
-3,-8,40:18.3
-2,-8,40:18.3
-1,-8,40:17.3
0,-8,40:17.3
1,-8,40:18.3
2,-8,40:18.3
3,-8,40:18.3
4,-8,40:18.3
5,-8,40:18.3
6,-8,40:18.3
7,-8,40:18.3
8,-8,40:18.3
9,-8,40:18.3
10,-8,40:18.3
11,-8,40:18.3
12,-8,40:18.3
-18,-7,40:18.3
-17,-7,40:18.3
-16,-7,40:18.3
-15,-7,40:18.3
-14,-7,40:18.3
-13,-7,40:18.3
-12,-7,40:18.3
-11,-7,40:17.3
-10,-7,40:18.3
-9,-7,40:18.3
-8,-7,40:18.3
-7,-7,40:18.3
-6,-7,40:18.3
-5,-7,40:18.3
-4,-7,40:18.3
-3,-7,40:18.3
-2,-7,40:18.3
-1,-7,40:18.3
0,-7,40:18.3
1,-7,40:18.3
2,-7,40:18.3
3,-7,40:18.3
4,-7,40:17.3
5,-7,40:17.3
6,-7,40:18.3
7,-7,40:17.3
8,-7,40:17.3
9,-7,40:18.3
10,-7,40:18.3
11,-7,40:18.3
12,-7,40:18.3
13,-7,40:18.3
-18,-6,40:18.3
-17,-6,40:18.3
-16,-6,40:17.3
-15,-6,40:18.3
-14,-6,40:18.3
-13,-6,40:18.3
-12,-6,40:18.3
-11,-6,40:18.3
-10,-6,40:18.3
-9,-6,40:18.3
-6,-6,40:18.3
-5,-6,40:17.3
-4,-6,40:18.3
-3,-6,40:18.3
-2,-6,40:18.3
-1,-6,40:18.3
0,-6,40:18.3
1,-6,40:18.3
2,-6,40:18.3
3,-6,40:18.3
4,-6,40:18.3
5,-6,40:18.3
6,-6,40:18.3
7,-6,40:18.3
8,-6,40:18.3
9,-6,40:17.3
10,-6,40:18.3
11,-6,40:17.3
12,-6,40:18.3
13,-6,40:18.3
14,-6,40:18.3
15,-6,40:18.3
-18,-5,40:18.3
-17,-5,40:18.3
-16,-5,40:18.3
-15,-5,40:18.3
-14,-5,40:18.3
-12,-5,40:18.3
-11,-5,40:18.3
-10,-5,40:18.3
-6,-5,40:18.3
-5,-5,40:18.3
-4,-5,40:17.3
-3,-5,40:18.3
-2,-5,40:18.3
-1,-5,40:18.3
0,-5,40:18.3
1,-5,40:18.3
2,-5,40:17.3
3,-5,40:18.3
4,-5,40:18.3
5,-5,40:17.3
6,-5,40:18.3
7,-5,40:18.3
8,-5,40:18.3
9,-5,40:18.3
10,-5,40:18.3
11,-5,40:18.3
12,-5,40:18.3
13,-5,40:18.3
14,-5,40:18.3
15,-5,40:18.3
16,-5,40:18.3
-17,-4,40:18.3
-16,-4,40:18.3
-15,-4,40:18.3
-10,-4,40:18.3
-9,-4,40:18.3
-8,-4,40:18.3
-6,-4,40:18.3
-5,-4,40:18.3
-4,-4,40:18.3
-3,-4,40:18.3
-2,-4,40:17.3
-1,-4,40:18.3
0,-4,40:18.3
1,-4,40:18.3
2,-4,40:18.3
3,-4,40:18.3
4,-4,40:18.3
5,-4,40:18.3
6,-4,40:18.3
7,-4,40:18.3
8,-4,40:18.3
9,-4,40:18.3
10,-4,40:18.3
11,-4,40:18.3
12,-4,40:18.3
13,-4,40:18.3
14,-4,40:17.3
15,-4,40:18.3
16,-4,40:18.3
-11,-3,40:18.3
-10,-3,40:18.3
-9,-3,40:18.3
-8,-3,40:18.3
-7,-3,40:18.3
-6,-3,40:18.3
-5,-3,40:18.3
-4,-3,40:17.3
-3,-3,40:18.3
-2,-3,40:18.3
-1,-3,40:18.3
0,-3,40:18.3
1,-3,40:18.3
2,-3,40:18.3
3,-3,40:18.3
4,-3,40:17.3
5,-3,40:18.3
6,-3,40:18.3
7,-3,40:18.3
8,-3,40:18.3
9,-3,40:18.3
10,-3,40:18.3
12,-3,40:18.3
13,-3,40:18.3
14,-3,40:18.3
15,-3,40:18.3
16,-3,40:18.3
17,-3,40:18.3
18,-3,40:18.3
19,-3,40:18.3
-11,-2,40:18.3
-10,-2,40:18.3
-9,-2,40:17.3
-8,-2,40:18.3
-7,-2,40:18.3
-6,-2,40:18.3
-5,-2,40:17.3
-4,-2,40:18.3
-3,-2,40:18.3
-2,-2,40:18.3
-1,-2,40:18.3
4,-2,40:18.3
5,-2,40:18.3
6,-2,40:17.3
7,-2,40:18.3
8,-2,40:17.3
9,-2,40:18.3
10,-2,40:18.3
11,-2,40:18.3
12,-2,40:18.3
13,-2,40:18.3
14,-2,40:18.3
15,-2,40:18.3
16,-2,40:18.3
17,-2,40:18.3
18,-2,40:18.3
19,-2,40:18.3
20,-2,40:18.3
-14,-1,40:18.3
-13,-1,40:18.3
-12,-1,40:18.3
-11,-1,40:18.3
-10,-1,40:18.3
-9,-1,40:18.3
-8,-1,40:18.3
-7,-1,40:17.3
-6,-1,40:17.3
-5,-1,40:18.3
-4,-1,40:18.3
-3,-1,40:18.3
-1,-1,40:17.3
1,-1,40:17.3
2,-1,40:17.3
4,-1,40:18.3
5,-1,40:18.3
6,-1,40:18.3
7,-1,40:18.3
8,-1,40:18.3
9,-1,40:18.3
10,-1,40:17.3
11,-1,40:18.3
12,-1,40:18.3
13,-1,40:17.3
14,-1,40:18.3
15,-1,40:18.3
16,-1,40:18.3
17,-1,40:18.3
18,-1,40:17.3
19,-1,40:18.3
20,-1,40:18.3
-15,0,40:18.3
-14,0,40:18.3
-13,0,40:18.3
-12,0,40:18.3
-11,0,40:18.3
-10,0,40:18.3
-9,0,40:18.3
-8,0,40:18.3
-7,0,40:18.3
-6,0,40:18.3
-5,0,40:18.3
-4,0,40:18.3
-2,0,40:17.3
1,0,40:17.3
2,0,40:18.3
3,0,40:18.3
5,0,40:18.3
6,0,40:18.3
7,0,40:18.3
8,0,40:18.3
9,0,40:18.3
10,0,40:18.3
11,0,40:18.3
12,0,40:18.3
13,0,40:18.3
14,0,40:18.3
15,0,40:18.3
16,0,40:18.3
17,0,40:18.3
18,0,40:18.3
19,0,40:18.3
20,0,40:18.3
-15,1,40:18.3
-14,1,40:18.3
-13,1,40:17.3
-12,1,40:18.3
-11,1,40:18.3
-10,1,40:18.3
-9,1,40:17.3
-8,1,40:18.3
-7,1,40:18.3
-6,1,40:18.3
-5,1,40:18.3
-4,1,40:18.3
0,1,40:18.3
1,1,40:18.3
2,1,40:18.3
3,1,40:18.3
4,1,40:18.3
5,1,40:17.3
6,1,40:18.3
7,1,40:18.3
8,1,40:17.3
9,1,40:18.3
10,1,40:18.3
11,1,40:18.3
12,1,40:18.3
13,1,40:18.3
14,1,40:18.3
17,1,40:18.3
18,1,40:18.3
19,1,40:18.3
-15,2,40:18.3
-14,2,40:18.3
-13,2,40:18.3
-12,2,40:18.3
-11,2,40:18.3
-10,2,40:18.3
-9,2,40:18.3
-8,2,40:18.3
-7,2,40:18.3
-6,2,40:17.3
-5,2,40:18.3
-4,2,40:18.3
-3,2,40:17.3
0,2,40:18.3
1,2,40:18.3
2,2,40:17.3
3,2,40:18.3
4,2,40:18.3
5,2,40:18.3
6,2,40:18.3
7,2,40:18.3
8,2,40:18.3
9,2,40:18.3
10,2,40:18.3
11,2,40:18.3
12,2,40:17.3
13,2,40:18.3
14,2,40:18.3
15,2,40:18.3
16,2,40:18.3
-14,3,40:18.3
-13,3,40:18.3
-12,3,40:18.3
-10,3,40:18.3
-9,3,40:18.3
-8,3,40:18.3
-7,3,40:18.3
-6,3,40:18.3
-5,3,40:18.3
-4,3,40:18.3
-3,3,40:18.3
-2,3,40:18.3
0,3,40:18.3
1,3,40:18.3
2,3,40:18.3
3,3,40:18.3
4,3,40:18.3
5,3,40:18.3
6,3,40:17.3
7,3,40:18.3
8,3,40:18.3
9,3,40:18.3
10,3,40:18.3
11,3,40:18.3
12,3,40:18.3
13,3,40:18.3
14,3,40:18.3
15,3,40:18.3
16,3,40:18.3
17,3,40:18.3
-8,4,40:18.3
-7,4,40:18.3
-6,4,40:18.3
-5,4,40:18.3
-4,4,40:17.3
-3,4,40:18.3
-2,4,40:18.3
-1,4,40:18.3
1,4,40:18.3
2,4,40:18.3
3,4,40:17.3
4,4,40:18.3
5,4,40:18.3
6,4,40:18.3
7,4,40:18.3
8,4,40:18.3
11,4,40:18.3
12,4,40:18.3
13,4,40:18.3
14,4,40:18.3
15,4,40:17.3
16,4,40:18.3
17,4,40:18.3
-9,5,40:18.3
-8,5,40:18.3
-7,5,40:18.3
-6,5,40:18.3
-5,5,40:18.3
-4,5,40:18.3
-3,5,40:18.3
-2,5,40:18.3
-1,5,40:18.3
0,5,40:18.3
1,5,40:18.3
2,5,40:18.3
3,5,40:18.3
4,5,40:18.3
5,5,40:18.3
6,5,40:17.3
7,5,40:18.3
8,5,40:18.3
13,5,40:18.3
14,5,40:18.3
15,5,40:18.3
16,5,40:18.3
17,5,40:18.3
-20,6,40:18.3
-19,6,40:18.3
-18,6,40:18.3
-13,6,40:18.3
-12,6,40:18.3
-11,6,40:18.3
-9,6,40:18.3
-8,6,40:18.3
-7,6,40:17.3
-6,6,40:17.3
-5,6,40:17.3
-4,6,40:18.3
-3,6,40:18.3
-2,6,40:17.3
-1,6,40:18.3
0,6,40:17.3
2,6,40:18.3
3,6,40:18.3
4,6,40:18.3
5,6,40:18.3
6,6,40:18.3
7,6,40:18.3
8,6,40:18.3
14,6,40:18.3
15,6,40:18.3
16,6,40:18.3
17,6,40:18.3
18,6,40:18.3
-21,7,40:18.3
-20,7,40:18.3
-19,7,40:18.3
-18,7,40:18.3
-17,7,40:18.3
-14,7,40:18.3
-13,7,40:18.3
-12,7,40:18.3
-11,7,40:18.3
-10,7,40:18.3
-9,7,40:18.3
-8,7,40:18.3
-7,7,40:18.3
-6,7,40:18.3
-5,7,40:18.3
-4,7,40:18.3
-3,7,40:18.3
-2,7,40:18.3
-1,7,40:18.3
0,7,40:17.3
1,7,40:18.3
5,7,40:18.3
6,7,40:18.3
7,7,40:18.3
9,7,40:18.3
10,7,40:18.3
11,7,40:18.3
14,7,40:18.3
15,7,40:18.3
16,7,40:17.3
17,7,40:18.3
18,7,40:18.3
-21,8,40:18.3
-20,8,40:18.3
-19,8,40:17.3
-18,8,40:18.3
-17,8,40:18.3
-14,8,40:18.3
-13,8,40:18.3
-12,8,40:17.3
-11,8,40:18.3
-10,8,40:18.3
-8,8,40:18.3
-7,8,40:18.3
-6,8,40:18.3
-5,8,40:18.3
-4,8,40:18.3
-3,8,40:18.3
-2,8,40:18.3
-1,8,40:18.3
0,8,40:17.3
1,8,40:18.3
2,8,40:18.3
8,8,40:18.3
9,8,40:18.3
10,8,40:18.3
11,8,40:18.3
12,8,40:18.3
14,8,40:18.3
15,8,40:18.3
16,8,40:18.3
17,8,40:18.3
18,8,40:18.3
-21,9,40:18.3
-20,9,40:18.3
-19,9,40:18.3
-18,9,40:18.3
-17,9,40:18.3
-15,9,40:18.3
-14,9,40:18.3
-13,9,40:18.3
-12,9,40:18.3
-11,9,40:18.3
-10,9,40:18.3
-2,9,40:18.3
-1,9,40:17.3
0,9,40:17.3
1,9,40:18.3
2,9,40:18.3
3,9,40:18.3
8,9,40:18.3
9,9,40:18.3
10,9,40:17.3
11,9,40:18.3
12,9,40:18.3
15,9,40:18.3
16,9,40:18.3
17,9,40:18.3
-20,10,40:18.3
-19,10,40:18.3
-18,10,40:18.3
-16,10,40:18.3
-15,10,40:18.3
-14,10,40:18.3
-13,10,40:18.3
-12,10,40:18.3
-11,10,40:18.3
-8,10,40:18.3
-7,10,40:18.3
-6,10,40:18.3
-2,10,40:18.3
-1,10,40:18.3
0,10,40:18.3
1,10,40:17.3
2,10,40:18.3
3,10,40:18.3
4,10,40:18.3
6,10,40:18.3
7,10,40:18.3
8,10,40:18.3
9,10,40:18.3
10,10,40:18.3
11,10,40:18.3
12,10,40:18.3
-16,11,40:18.3
-15,11,40:18.3
-14,11,40:17.3
-13,11,40:18.3
-12,11,40:18.3
-9,11,40:18.3
-8,11,40:18.3
-7,11,40:18.3
-6,11,40:18.3
-5,11,40:18.3
-1,11,40:18.3
0,11,40:18.3
1,11,40:18.3
2,11,40:18.3
3,11,40:18.3
4,11,40:18.3
5,11,40:18.3
6,11,40:18.3
7,11,40:18.3
8,11,40:18.3
9,11,40:18.3
10,11,40:18.3
11,11,40:18.3
-16,12,40:18.3
-15,12,40:18.3
-14,12,40:18.3
-13,12,40:18.3
-12,12,40:18.3
-9,12,40:18.3
-8,12,40:18.3
-7,12,40:17.3
-6,12,40:18.3
-5,12,40:18.3
0,12,40:18.3
1,12,40:18.3
2,12,40:18.3
3,12,40:17.3
4,12,40:18.3
5,12,40:18.3
6,12,40:18.3
7,12,40:17.3
8,12,40:18.3
9,12,40:18.3
-15,13,40:18.3
-14,13,40:18.3
-13,13,40:18.3
-10,13,40:18.3
-9,13,40:18.3
-8,13,40:18.3
-7,13,40:18.3
-6,13,40:18.3
-5,13,40:18.3
-3,13,40:18.3
-2,13,40:18.3
-1,13,40:18.3
1,13,40:18.3
2,13,40:18.3
3,13,40:18.3
4,13,40:18.3
5,13,40:18.3
6,13,40:18.3
7,13,40:18.3
8,13,40:18.3
9,13,40:18.3
-10,14,40:18.3
-9,14,40:18.3
-8,14,40:17.3
-7,14,40:18.3
-6,14,40:18.3
-4,14,40:18.3
-3,14,40:18.3
-2,14,40:18.3
-1,14,40:18.3
0,14,40:18.3
1,14,40:18.3
2,14,40:18.3
3,14,40:18.3
4,14,40:18.3
6,14,40:18.3
7,14,40:18.3
8,14,40:18.3
-10,15,40:18.3
-9,15,40:18.3
-8,15,40:18.3
-7,15,40:18.3
-6,15,40:18.3
-4,15,40:18.3
-3,15,40:18.3
-2,15,40:17.3
-1,15,40:18.3
0,15,40:18.3
1,15,40:18.3
2,15,40:18.3
3,15,40:18.3
-9,16,40:18.3
-8,16,40:18.3
-7,16,40:18.3
-4,16,40:18.3
-3,16,40:18.3
-2,16,40:18.3
-1,16,40:18.3
0,16,40:18.3
1,16,40:17.3
2,16,40:18.3
3,16,40:18.3
-3,17,40:18.3
-2,17,40:18.3
-1,17,40:18.3
0,17,40:18.3
1,17,40:18.3
2,17,40:18.3
3,17,40:18.3
0,18,40:18.3
1,18,40:18.3
2,18,40:18.3
3,18,40:18.3
4,18,40:18.3
0,19,40:18.3
1,19,40:18.3
2,19,40:17.3
3,19,40:18.3
4,19,40:18.3
0,20,40:18.3
1,20,40:18.3
2,20,40:18.3
3,20,40:18.3
4,20,40:18.3
1,21,40:18.3
2,21,40:18.3
3,21,40:18.3
9,-22,41:18.3
10,-22,41:18.3
11,-22,41:18.3
15,-22,41:18.3
-5,-21,41:18.3
-4,-21,41:18.3
-3,-21,41:18.3
8,-21,41:18.3
9,-21,41:18.3
10,-21,41:18.3
11,-21,41:18.3
12,-21,41:18.3
14,-21,41:18.3
15,-21,41:18.3
16,-21,41:18.3
-6,-20,41:18.3
-5,-20,41:18.3
-4,-20,41:18.3
-3,-20,41:18.3
-2,-20,41:18.3
2,-20,41:18.3
3,-20,41:18.3
4,-20,41:18.3
5,-20,41:18.3
8,-20,41:18.3
9,-20,41:18.3
10,-20,41:17.3
11,-20,41:18.3
12,-20,41:18.3
13,-20,41:18.3
14,-20,41:18.3
15,-20,41:18.3
16,-20,41:18.3
17,-20,41:18.3
-6,-19,41:18.3
-5,-19,41:18.3
-4,-19,41:17.3
-3,-19,41:18.3
-2,-19,41:18.3
-1,-19,41:18.3
1,-19,41:18.3
2,-19,41:18.3
3,-19,41:18.3
4,-19,41:18.3
5,-19,41:18.3
6,-19,41:18.3
8,-19,41:18.3
9,-19,41:18.3
10,-19,41:18.3
11,-19,41:18.3
12,-19,41:18.3
14,-19,41:18.3
15,-19,41:18.3
16,-19,41:18.3
-6,-18,41:18.3
-5,-18,41:18.3
-4,-18,41:18.3
-3,-18,41:18.3
-2,-18,41:18.3
-1,-18,41:18.3
0,-18,41:18.3
1,-18,41:18.3
2,-18,41:18.3
3,-18,41:17.3
4,-18,41:17.3
5,-18,41:18.3
6,-18,41:18.3
9,-18,41:18.3
10,-18,41:18.3
11,-18,41:18.3
12,-18,41:18.3
15,-18,41:18.3
-5,-17,41:18.3
-4,-17,41:18.3
-3,-17,41:18.3
-2,-17,41:17.3
-1,-17,41:18.3
0,-17,41:18.3
1,-17,41:18.3
2,-17,41:18.3
3,-17,41:18.3
4,-17,41:18.3
5,-17,41:18.3
6,-17,41:18.3
9,-17,41:18.3
10,-17,41:18.3
11,-17,41:18.3
12,-17,41:18.3
13,-17,41:18.3
-13,-16,41:18.3
-12,-16,41:18.3
-11,-16,41:18.3
-6,-16,41:18.3
-5,-16,41:18.3
-4,-16,41:18.3
-3,-16,41:18.3
-2,-16,41:18.3
-1,-16,41:18.3
0,-16,41:18.3
1,-16,41:18.3
2,-16,41:18.3
3,-16,41:18.3
4,-16,41:18.3
5,-16,41:18.3
7,-16,41:18.3
8,-16,41:18.3
9,-16,41:18.3
10,-16,41:18.3
11,-16,41:17.3
12,-16,41:18.3
13,-16,41:18.3
-14,-15,41:18.3
-13,-15,41:18.3
-12,-15,41:18.3
-11,-15,41:18.3
-10,-15,41:18.3
-5,-15,41:18.3
-4,-15,41:18.3
-3,-15,41:18.3
-2,-15,41:18.3
-1,-15,41:18.3
0,-15,41:18.3
1,-15,41:18.3
2,-15,41:18.3
3,-15,41:18.3
5,-15,41:18.3
6,-15,41:18.3
7,-15,41:18.3
8,-15,41:18.3
9,-15,41:18.3
10,-15,41:18.3
11,-15,41:18.3
12,-15,41:18.3
13,-15,41:18.3
14,-15,41:18.3
-14,-14,41:18.3
-13,-14,41:18.3
-12,-14,41:17.3
-11,-14,41:18.3
-10,-14,41:18.3
-8,-14,41:18.3
-4,-14,41:18.3
-2,-14,41:18.3
-1,-14,41:18.3
0,-14,41:18.3
1,-14,41:18.3
2,-14,41:18.3
3,-14,41:18.3
4,-14,41:18.3
5,-14,41:18.3
6,-14,41:18.3
7,-14,41:18.3
8,-14,41:17.3
9,-14,41:18.3
10,-14,41:18.3
11,-14,41:18.3
12,-14,41:18.3
13,-14,41:18.3
14,-14,41:18.3
15,-14,41:18.3
18,-14,41:18.3
-14,-13,41:18.3
-13,-13,41:18.3
-12,-13,41:18.3
-11,-13,41:18.3
-10,-13,41:18.3
-9,-13,41:18.3
-8,-13,41:18.3
-7,-13,41:18.3
-3,-13,41:18.3
-2,-13,41:18.3
-1,-13,41:18.3
0,-13,41:18.3
1,-13,41:18.3
2,-13,41:17.3
3,-13,41:18.3
4,-13,41:18.3
5,-13,41:18.3
6,-13,41:17.3
7,-13,41:18.3
8,-13,41:18.3
9,-13,41:18.3
10,-13,41:18.3
11,-13,41:18.3
12,-13,41:18.3
13,-13,41:18.3
14,-13,41:18.3
17,-13,41:18.3
18,-13,41:18.3
19,-13,41:18.3
-20,-12,41:18.3
-13,-12,41:18.3
-12,-12,41:18.3
-11,-12,41:18.3
-10,-12,41:18.3
-9,-12,41:18.3
-8,-12,41:18.3
-7,-12,41:18.3
-6,-12,41:18.3
-4,-12,41:18.3
-3,-12,41:18.3
-2,-12,41:18.3
-1,-12,41:18.3
0,-12,41:18.3
1,-12,41:18.3
2,-12,41:18.3
3,-12,41:18.3
4,-12,41:18.3
5,-12,41:18.3
6,-12,41:18.3
7,-12,41:18.3
8,-12,41:18.3
9,-12,41:17.3
10,-12,41:18.3
11,-12,41:18.3
13,-12,41:18.3
16,-12,41:18.3
17,-12,41:18.3
18,-12,41:18.3
19,-12,41:18.3
20,-12,41:18.3
-21,-11,41:18.3
-20,-11,41:18.3
-19,-11,41:18.3
-13,-11,41:18.3
-12,-11,41:18.3
-11,-11,41:18.3
-10,-11,41:18.3
-9,-11,41:18.3
-8,-11,41:18.3
-7,-11,41:18.3
-4,-11,41:18.3
-3,-11,41:18.3
-2,-11,41:18.3
-1,-11,41:18.3
0,-11,41:18.3
1,-11,41:18.3
2,-11,41:18.3
3,-11,41:18.3
5,-11,41:18.3
6,-11,41:18.3
7,-11,41:18.3
8,-11,41:18.3
9,-11,41:18.3
10,-11,41:18.3
11,-11,41:18.3
17,-11,41:18.3
18,-11,41:18.3
19,-11,41:18.3
-22,-10,41:18.3
-21,-10,41:18.3
-20,-10,41:18.3
-19,-10,41:18.3
-18,-10,41:18.3
-14,-10,41:18.3
-13,-10,41:18.3
-12,-10,41:18.3
-11,-10,41:18.3
-10,-10,41:18.3
-9,-10,41:18.3
-8,-10,41:18.3
-7,-10,41:18.3
-6,-10,41:18.3
-5,-10,41:18.3
-4,-10,41:18.3
-3,-10,41:18.3
-2,-10,41:18.3
-1,-10,41:18.3
0,-10,41:18.3
1,-10,41:18.3
4,-10,41:18.3
5,-10,41:18.3
6,-10,41:18.3
7,-10,41:18.3
8,-10,41:18.3
9,-10,41:17.3
10,-10,41:18.3
11,-10,41:18.3
18,-10,41:18.3
-21,-9,41:18.3
-20,-9,41:18.3
-19,-9,41:18.3
-14,-9,41:18.3
-13,-9,41:18.3
-12,-9,41:18.3
-11,-9,41:17.3
-10,-9,41:18.3
-9,-9,41:18.3
-8,-9,41:18.3
-7,-9,41:18.3
-6,-9,41:18.3
-5,-9,41:18.3
-4,-9,41:18.3
-3,-9,41:17.3
-2,-9,41:18.3
-1,-9,41:17.3
0,-9,41:18.3
1,-9,41:18.3
2,-9,41:18.3
3,-9,41:18.3
4,-9,41:18.3
5,-9,41:18.3
6,-9,41:18.3
7,-9,41:18.3
8,-9,41:18.3
9,-9,41:18.3
10,-9,41:18.3
11,-9,41:18.3
-20,-8,41:18.3
-16,-8,41:18.3
-15,-8,41:18.3
-14,-8,41:18.3
-13,-8,41:18.3
-12,-8,41:18.3
-11,-8,41:18.3
-10,-8,41:18.3
-9,-8,41:17.3
-8,-8,41:18.3
-7,-8,41:18.3
-6,-8,41:18.3
-5,-8,41:18.3
-4,-8,41:18.3
-3,-8,41:18.3
-2,-8,41:18.3
-1,-8,41:18.3
0,-8,41:18.3
1,-8,41:18.3
2,-8,41:18.3
3,-8,41:18.3
4,-8,41:18.3
5,-8,41:18.3
6,-8,41:17.3
7,-8,41:18.3
8,-8,41:18.3
9,-8,41:18.3
10,-8,41:18.3
11,-8,41:18.3
-17,-7,41:18.3
-16,-7,41:18.3
-15,-7,41:18.3
-14,-7,41:18.3
-13,-7,41:17.3
-12,-7,41:18.3
-11,-7,41:18.3
-10,-7,41:18.3
-9,-7,41:18.3
-8,-7,41:18.3
-7,-7,41:18.3
-6,-7,41:18.3
-5,-7,41:18.3
-4,-7,41:17.3
-3,-7,41:18.3
-2,-7,41:18.3
-1,-7,41:18.3
0,-7,41:18.3
1,-7,41:18.3
2,-7,41:17.3
3,-7,41:17.3
4,-7,41:18.3
5,-7,41:18.3
6,-7,41:17.3
7,-7,41:18.3
8,-7,41:18.3
9,-7,41:18.3
10,-7,41:18.3
11,-7,41:18.3
12,-7,41:18.3
-18,-6,41:18.3
-17,-6,41:18.3
-16,-6,41:18.3
-15,-6,41:18.3
-14,-6,41:18.3
-13,-6,41:18.3
-12,-6,41:18.3
-11,-6,41:18.3
-10,-6,41:18.3
-9,-6,41:18.3
-8,-6,41:17.3
-7,-6,41:18.3
-6,-6,41:17.3
-5,-6,41:17.3
-4,-6,41:18.3
-3,-6,41:18.3
-2,-6,41:18.3
-1,-6,41:18.3
0,-6,41:18.3
1,-6,41:18.3
2,-6,41:18.3
3,-6,41:18.3
4,-6,41:18.3
5,-6,41:17.3
6,-6,41:18.3
7,-6,41:18.3
8,-6,41:18.3
9,-6,41:18.3
10,-6,41:18.3
11,-6,41:18.3
12,-6,41:18.3
13,-6,41:18.3
14,-6,41:18.3
-17,-5,41:18.3
-16,-5,41:18.3
-15,-5,41:18.3
-14,-5,41:18.3
-13,-5,41:18.3
-12,-5,41:18.3
-11,-5,41:18.3
-10,-5,41:18.3
-9,-5,41:18.3
-8,-5,41:18.3
-7,-5,41:18.3
-6,-5,41:18.3
-5,-5,41:18.3
-4,-5,41:18.3
-3,-5,41:17.3
-2,-5,41:18.3
-1,-5,41:18.3
0,-5,41:18.3
1,-5,41:18.3
2,-5,41:18.3
3,-5,41:18.3
4,-5,41:18.3
5,-5,41:17.3
6,-5,41:18.3
7,-5,41:18.3
8,-5,41:18.3
9,-5,41:18.3
10,-5,41:18.3
11,-5,41:17.3
12,-5,41:18.3
13,-5,41:18.3
14,-5,41:18.3
15,-5,41:18.3
-16,-4,41:18.3
-11,-4,41:18.3
-10,-4,41:18.3
-9,-4,41:17.3
-8,-4,41:18.3
-7,-4,41:18.3
-6,-4,41:18.3
-5,-4,41:18.3
-4,-4,41:18.3
-3,-4,41:17.3
-2,-4,41:18.3
-1,-4,41:18.3
0,-4,41:18.3
1,-4,41:18.3
2,-4,41:18.3
3,-4,41:18.3
4,-4,41:17.3
6,-4,41:18.3
7,-4,41:18.3
8,-4,41:18.3
9,-4,41:18.3
10,-4,41:18.3
11,-4,41:18.3
12,-4,41:18.3
13,-4,41:17.3
14,-4,41:18.3
15,-4,41:18.3
16,-4,41:18.3
-14,-3,41:18.3
-13,-3,41:18.3
-12,-3,41:18.3
-11,-3,41:18.3
-10,-3,41:18.3
-9,-3,41:18.3
-8,-3,41:18.3
-7,-3,41:18.3
-6,-3,41:18.3
-5,-3,41:18.3
-4,-3,41:18.3
-3,-3,41:18.3
-2,-3,41:18.3
-1,-3,41:18.3
2,-3,41:18.3
5,-3,41:18.3
6,-3,41:18.3
7,-3,41:18.3
8,-3,41:18.3
9,-3,41:17.3
10,-3,41:18.3
11,-3,41:18.3
12,-3,41:18.3
13,-3,41:18.3
14,-3,41:18.3
15,-3,41:18.3
18,-3,41:18.3
-15,-2,41:18.3
-14,-2,41:18.3
-13,-2,41:18.3
-12,-2,41:18.3
-11,-2,41:18.3
-10,-2,41:18.3
-9,-2,41:18.3
-8,-2,41:18.3
-7,-2,41:18.3
-6,-2,41:18.3
-5,-2,41:18.3
-4,-2,41:18.3
-3,-2,41:18.3
-2,-2,41:18.3
4,-2,41:18.3
5,-2,41:18.3
6,-2,41:18.3
7,-2,41:18.3
8,-2,41:18.3
9,-2,41:18.3
10,-2,41:18.3
11,-2,41:18.3
12,-2,41:18.3
13,-2,41:18.3
14,-2,41:18.3
17,-2,41:18.3
18,-2,41:18.3
19,-2,41:18.3
-15,-1,41:18.3
-14,-1,41:18.3
-13,-1,41:17.3
-12,-1,41:18.3
-11,-1,41:18.3
-10,-1,41:17.3
-9,-1,41:18.3
-8,-1,41:17.3
-7,-1,41:18.3
-6,-1,41:18.3
-5,-1,41:18.3
-4,-1,41:18.3
-2,-1,41:17.3
0,-1,41:17.3
1,-1,41:17.3
3,-1,41:17.3
5,-1,41:18.3
6,-1,41:18.3
7,-1,41:18.3
8,-1,41:18.3
9,-1,41:18.3
10,-1,41:18.3
11,-1,41:17.3
12,-1,41:18.3
13,-1,41:18.3
14,-1,41:18.3
15,-1,41:18.3
16,-1,41:18.3
17,-1,41:18.3
18,-1,41:18.3
19,-1,41:18.3
20,-1,41:18.3
-15,0,41:18.3
-14,0,41:18.3
-13,0,41:18.3
-12,0,41:18.3
-11,0,41:18.3
-10,0,41:18.3
-9,0,41:18.3
-8,0,41:18.3
-7,0,41:17.3
-6,0,41:18.3
-5,0,41:18.3
1,0,41:17.3
2,0,41:18.3
6,0,41:18.3
7,0,41:18.3
8,0,41:18.3
9,0,41:18.3
10,0,41:17.3
11,0,41:18.3
12,0,41:18.3
13,0,41:18.3
14,0,41:18.3
15,0,41:18.3
16,0,41:18.3
17,0,41:18.3
18,0,41:18.3
19,0,41:18.3
-15,1,41:18.3
-14,1,41:18.3
-13,1,41:18.3
-12,1,41:17.3
-11,1,41:18.3
-10,1,41:18.3
-9,1,41:18.3
-8,1,41:17.3
-7,1,41:18.3
-6,1,41:18.3
-5,1,41:18.3
-3,1,41:17.3
1,1,41:18.3
2,1,41:18.3
3,1,41:18.3
5,1,41:17.3
6,1,41:18.3
7,1,41:18.3
8,1,41:18.3
9,1,41:18.3
10,1,41:18.3
11,1,41:17.3
12,1,41:18.3
13,1,41:18.3
15,1,41:18.3
16,1,41:18.3
17,1,41:17.3
18,1,41:18.3
19,1,41:18.3
-14,2,41:18.3
-13,2,41:18.3
-12,2,41:18.3
-11,2,41:18.3
-10,2,41:18.3
-9,2,41:18.3
-8,2,41:18.3
-7,2,41:18.3
-6,2,41:18.3
-5,2,41:18.3
-4,2,41:17.3
0,2,41:18.3
1,2,41:18.3
2,2,41:18.3
3,2,41:18.3
4,2,41:18.3
5,2,41:18.3
6,2,41:18.3
7,2,41:18.3
8,2,41:18.3
9,2,41:18.3
10,2,41:18.3
11,2,41:18.3
12,2,41:18.3
13,2,41:18.3
14,2,41:18.3
15,2,41:18.3
16,2,41:18.3
17,2,41:18.3
18,2,41:18.3
19,2,41:18.3
-13,3,41:18.3
-12,3,41:18.3
-11,3,41:18.3
-9,3,41:18.3
-8,3,41:18.3
-7,3,41:18.3
-6,3,41:18.3
-5,3,41:18.3
-4,3,41:18.3
-3,3,41:18.3
1,3,41:18.3
2,3,41:18.3
3,3,41:18.3
4,3,41:18.3
5,3,41:18.3
6,3,41:18.3
7,3,41:18.3
8,3,41:18.3
9,3,41:17.3
10,3,41:18.3
11,3,41:18.3
12,3,41:18.3
13,3,41:18.3
14,3,41:18.3
15,3,41:18.3
16,3,41:17.3
17,3,41:18.3
18,3,41:18.3
19,3,41:18.3
20,3,41:18.3
-7,4,41:18.3
-6,4,41:18.3
-5,4,41:18.3
-4,4,41:18.3
-3,4,41:18.3
-2,4,41:18.3
-1,4,41:18.3
0,4,41:18.3
1,4,41:18.3
2,4,41:18.3
3,4,41:17.3
4,4,41:18.3
5,4,41:17.3
6,4,41:17.3
7,4,41:18.3
8,4,41:18.3
9,4,41:17.3
10,4,41:18.3
11,4,41:18.3
12,4,41:18.3
13,4,41:18.3
14,4,41:18.3
15,4,41:18.3
16,4,41:18.3
17,4,41:18.3
18,4,41:18.3
19,4,41:18.3
20,4,41:18.3
21,4,41:18.3
-8,5,41:18.3
-7,5,41:18.3
-6,5,41:18.3
-5,5,41:18.3
-4,5,41:18.3
-3,5,41:18.3
-2,5,41:18.3
-1,5,41:18.3
0,5,41:18.3
1,5,41:18.3
2,5,41:18.3
3,5,41:18.3
4,5,41:18.3
5,5,41:18.3
6,5,41:18.3
7,5,41:17.3
8,5,41:18.3
9,5,41:18.3
10,5,41:18.3
11,5,41:18.3
12,5,41:18.3
14,5,41:18.3
15,5,41:18.3
16,5,41:18.3
17,5,41:18.3
18,5,41:18.3
19,5,41:17.3
20,5,41:18.3
21,5,41:18.3
-19,6,41:18.3
-12,6,41:18.3
-9,6,41:18.3
-8,6,41:18.3
-7,6,41:18.3
-6,6,41:18.3
-5,6,41:18.3
-4,6,41:18.3
-3,6,41:18.3
-2,6,41:17.3
-1,6,41:18.3
0,6,41:17.3
1,6,41:18.3
2,6,41:18.3
3,6,41:18.3
4,6,41:17.3
5,6,41:18.3
6,6,41:18.3
7,6,41:18.3
8,6,41:18.3
9,6,41:18.3
10,6,41:17.3
11,6,41:18.3
12,6,41:18.3
15,6,41:18.3
16,6,41:18.3
17,6,41:18.3
18,6,41:18.3
19,6,41:18.3
20,6,41:18.3
21,6,41:18.3
-20,7,41:18.3
-19,7,41:18.3
-18,7,41:18.3
-13,7,41:18.3
-12,7,41:18.3
-11,7,41:18.3
-8,7,41:18.3
-7,7,41:18.3
-6,7,41:18.3
-5,7,41:18.3
-4,7,41:18.3
-3,7,41:18.3
-2,7,41:18.3
-1,7,41:18.3
0,7,41:17.3
1,7,41:17.3
2,7,41:18.3
3,7,41:18.3
4,7,41:18.3
5,7,41:18.3
6,7,41:17.3
7,7,41:18.3
8,7,41:17.3
9,7,41:18.3
10,7,41:18.3
11,7,41:18.3
12,7,41:18.3
14,7,41:18.3
15,7,41:18.3
16,7,41:18.3
17,7,41:18.3
18,7,41:18.3
19,7,41:18.3
20,7,41:18.3
-21,8,41:18.3
-20,8,41:18.3
-19,8,41:18.3
-18,8,41:18.3
-17,8,41:18.3
-14,8,41:18.3
-13,8,41:18.3
-12,8,41:18.3
-11,8,41:18.3
-10,8,41:18.3
-8,8,41:18.3
-7,8,41:18.3
-6,8,41:17.3
-5,8,41:18.3
-4,8,41:18.3
-3,8,41:18.3
-2,8,41:18.3
-1,8,41:18.3
0,8,41:17.3
1,8,41:18.3
2,8,41:18.3
3,8,41:18.3
4,8,41:18.3
5,8,41:18.3
6,8,41:18.3
7,8,41:18.3
8,8,41:18.3
9,8,41:18.3
10,8,41:18.3
11,8,41:18.3
13,8,41:18.3
14,8,41:18.3
15,8,41:18.3
16,8,41:18.3
17,8,41:18.3
-20,9,41:18.3
-19,9,41:18.3
-18,9,41:18.3
-14,9,41:18.3
-13,9,41:18.3
-12,9,41:18.3
-11,9,41:18.3
-8,9,41:18.3
-7,9,41:18.3
-6,9,41:18.3
-5,9,41:18.3
-4,9,41:18.3
-3,9,41:18.3
-2,9,41:18.3
-1,9,41:18.3
0,9,41:17.3
1,9,41:18.3
2,9,41:18.3
4,9,41:18.3
5,9,41:18.3
6,9,41:18.3
7,9,41:18.3
8,9,41:18.3
9,9,41:18.3
10,9,41:18.3
11,9,41:18.3
12,9,41:18.3
13,9,41:18.3
14,9,41:18.3
15,9,41:18.3
16,9,41:18.3
-19,10,41:18.3
-15,10,41:18.3
-14,10,41:18.3
-13,10,41:18.3
-12,10,41:18.3
-8,10,41:18.3
-7,10,41:18.3
-6,10,41:17.3
-5,10,41:18.3
-4,10,41:17.3
-3,10,41:18.3
-2,10,41:18.3
-1,10,41:17.3
0,10,41:18.3
1,10,41:18.3
2,10,41:18.3
3,10,41:18.3
4,10,41:18.3
5,10,41:18.3
6,10,41:18.3
7,10,41:18.3
9,10,41:18.3
10,10,41:18.3
11,10,41:18.3
12,10,41:18.3
13,10,41:18.3
14,10,41:17.3
15,10,41:18.3
16,10,41:18.3
-16,11,41:18.3
-15,11,41:18.3
-14,11,41:18.3
-13,11,41:18.3
-12,11,41:18.3
-8,11,41:18.3
-7,11,41:18.3
-6,11,41:18.3
-5,11,41:18.3
-4,11,41:18.3
-3,11,41:18.3
-2,11,41:18.3
-1,11,41:17.3
0,11,41:18.3
1,11,41:17.3
2,11,41:18.3
3,11,41:18.3
4,11,41:18.3
5,11,41:17.3
6,11,41:18.3
7,11,41:18.3
8,11,41:18.3
10,11,41:18.3
12,11,41:18.3
13,11,41:18.3
14,11,41:18.3
15,11,41:18.3
16,11,41:18.3
-15,12,41:18.3
-14,12,41:18.3
-13,12,41:18.3
-9,12,41:18.3
-8,12,41:18.3
-7,12,41:18.3
-6,12,41:18.3
-5,12,41:18.3
-4,12,41:18.3
-3,12,41:18.3
-2,12,41:18.3
-1,12,41:18.3
0,12,41:17.3
1,12,41:18.3
2,12,41:18.3
3,12,41:18.3
4,12,41:18.3
5,12,41:18.3
6,12,41:18.3
7,12,41:18.3
8,12,41:18.3
9,12,41:18.3
13,12,41:18.3
14,12,41:18.3
15,12,41:18.3
-14,13,41:18.3
-9,13,41:18.3
-8,13,41:18.3
-7,13,41:18.3
-6,13,41:18.3
-2,13,41:18.3
-1,13,41:18.3
0,13,41:18.3
1,13,41:18.3
2,13,41:18.3
3,13,41:18.3
4,13,41:18.3
5,13,41:18.3
6,13,41:18.3
7,13,41:18.3
8,13,41:18.3
12,13,41:18.3
13,13,41:18.3
14,13,41:18.3
15,13,41:18.3
16,13,41:18.3
-10,14,41:18.3
-9,14,41:18.3
-8,14,41:18.3
-7,14,41:18.3
-6,14,41:18.3
-3,14,41:18.3
-2,14,41:18.3
-1,14,41:18.3
0,14,41:18.3
1,14,41:18.3
3,14,41:18.3
7,14,41:18.3
12,14,41:18.3
13,14,41:18.3
14,14,41:17.3
15,14,41:18.3
16,14,41:18.3
-9,15,41:18.3
-8,15,41:18.3
-7,15,41:18.3
-4,15,41:18.3
-3,15,41:18.3
-2,15,41:18.3
-1,15,41:18.3
0,15,41:18.3
1,15,41:18.3
2,15,41:18.3
12,15,41:18.3
13,15,41:18.3
14,15,41:18.3
15,15,41:18.3
16,15,41:18.3
-8,16,41:18.3
-3,16,41:18.3
-2,16,41:18.3
-1,16,41:18.3
0,16,41:18.3
1,16,41:18.3
2,16,41:18.3
3,16,41:18.3
13,16,41:18.3
14,16,41:18.3
15,16,41:18.3
-2,17,41:18.3
0,17,41:18.3
1,17,41:18.3
2,17,41:18.3
1,18,41:18.3
2,18,41:18.3
3,18,41:18.3
0,19,41:18.3
1,19,41:18.3
2,19,41:18.3
3,19,41:18.3
4,19,41:18.3
1,20,41:18.3
2,20,41:18.3
3,20,41:18.3
2,21,41:18.3
6,-22,42:18.3
7,-22,42:18.3
8,-22,42:18.3
10,-22,42:18.3
-4,-21,42:18.3
5,-21,42:18.3
6,-21,42:18.3
7,-21,42:18.3
8,-21,42:18.3
9,-21,42:18.3
10,-21,42:18.3
11,-21,42:18.3
-5,-20,42:18.3
-4,-20,42:18.3
-3,-20,42:18.3
3,-20,42:18.3
4,-20,42:18.3
5,-20,42:18.3
6,-20,42:18.3
7,-20,42:17.3
8,-20,42:18.3
9,-20,42:18.3
10,-20,42:18.3
11,-20,42:18.3
12,-20,42:18.3
-6,-19,42:18.3
-5,-19,42:18.3
-4,-19,42:18.3
-3,-19,42:18.3
-2,-19,42:18.3
2,-19,42:18.3
3,-19,42:18.3
4,-19,42:18.3
5,-19,42:18.3
6,-19,42:18.3
7,-19,42:18.3
8,-19,42:18.3
9,-19,42:18.3
10,-19,42:18.3
11,-19,42:18.3
-5,-18,42:18.3
-4,-18,42:18.3
-3,-18,42:18.3
-2,-18,42:18.3
-1,-18,42:18.3
0,-18,42:18.3
1,-18,42:18.3
2,-18,42:18.3
3,-18,42:18.3
4,-18,42:18.3
5,-18,42:18.3
6,-18,42:18.3
7,-18,42:18.3
8,-18,42:18.3
10,-18,42:18.3
11,-18,42:18.3
-7,-17,42:18.3
-6,-17,42:18.3
-5,-17,42:18.3
-4,-17,42:18.3
-3,-17,42:18.3
-2,-17,42:18.3
-1,-17,42:18.3
0,-17,42:18.3
1,-17,42:18.3
2,-17,42:18.3
3,-17,42:18.3
4,-17,42:18.3
5,-17,42:18.3
6,-17,42:18.3
7,-17,42:18.3
10,-17,42:18.3
11,-17,42:18.3
12,-17,42:18.3
-12,-16,42:18.3
-10,-16,42:18.3
-9,-16,42:18.3
-8,-16,42:18.3
-7,-16,42:18.3
-6,-16,42:18.3
-5,-16,42:18.3
-4,-16,42:18.3
-3,-16,42:18.3
-2,-16,42:18.3
-1,-16,42:18.3
0,-16,42:17.3
1,-16,42:18.3
2,-16,42:18.3
3,-16,42:18.3
4,-16,42:18.3
5,-16,42:17.3
6,-16,42:18.3
7,-16,42:18.3
8,-16,42:18.3
9,-16,42:18.3
10,-16,42:18.3
11,-16,42:18.3
12,-16,42:18.3
13,-16,42:18.3
-13,-15,42:18.3
-12,-15,42:18.3
-11,-15,42:18.3
-10,-15,42:18.3
-9,-15,42:18.3
-8,-15,42:18.3
-7,-15,42:18.3
-6,-15,42:17.3
-5,-15,42:18.3
-4,-15,42:17.3
-3,-15,42:18.3
-2,-15,42:18.3
-1,-15,42:18.3
0,-15,42:18.3
1,-15,42:17.3
2,-15,42:18.3
3,-15,42:18.3
4,-15,42:18.3
5,-15,42:18.3
6,-15,42:18.3
7,-15,42:18.3
8,-15,42:18.3
9,-15,42:18.3
10,-15,42:18.3
11,-15,42:18.3
12,-15,42:18.3
-14,-14,42:18.3
-13,-14,42:18.3
-12,-14,42:18.3
-11,-14,42:18.3
-10,-14,42:18.3
-9,-14,42:17.3
-8,-14,42:18.3
-7,-14,42:18.3
-6,-14,42:18.3
-5,-14,42:17.3
-4,-14,42:18.3
-3,-14,42:18.3
-2,-14,42:18.3
-1,-14,42:18.3
0,-14,42:18.3
1,-14,42:18.3
2,-14,42:18.3
3,-14,42:18.3
4,-14,42:18.3
5,-14,42:18.3
6,-14,42:18.3
7,-14,42:18.3
8,-14,42:18.3
9,-14,42:18.3
10,-14,42:18.3
11,-14,42:18.3
-13,-13,42:18.3
-12,-13,42:18.3
-11,-13,42:18.3
-10,-13,42:18.3
-9,-13,42:18.3
-8,-13,42:18.3
-7,-13,42:18.3
-6,-13,42:18.3
-5,-13,42:18.3
-4,-13,42:18.3
-3,-13,42:18.3
0,-13,42:18.3
1,-13,42:18.3
2,-13,42:18.3
3,-13,42:18.3
4,-13,42:18.3
5,-13,42:18.3
6,-13,42:18.3
7,-13,42:18.3
8,-13,42:18.3
9,-13,42:18.3
10,-13,42:18.3
11,-13,42:18.3
12,-13,42:18.3
-12,-12,42:18.3
-10,-12,42:18.3
-9,-12,42:18.3
-8,-12,42:18.3
-6,-12,42:18.3
-5,-12,42:18.3
-4,-12,42:18.3
-1,-12,42:18.3
0,-12,42:18.3
1,-12,42:18.3
2,-12,42:18.3
3,-12,42:18.3
4,-12,42:18.3
5,-12,42:18.3
6,-12,42:18.3
7,-12,42:18.3
8,-12,42:18.3
9,-12,42:18.3
10,-12,42:18.3
11,-12,42:18.3
12,-12,42:18.3
13,-12,42:18.3
-11,-11,42:18.3
-10,-11,42:18.3
-9,-11,42:18.3
-7,-11,42:18.3
-6,-11,42:18.3
-5,-11,42:18.3
-3,-11,42:18.3
-1,-11,42:18.3
0,-11,42:18.3
1,-11,42:17.3
2,-11,42:17.3
3,-11,42:18.3
4,-11,42:18.3
6,-11,42:18.3
7,-11,42:18.3
8,-11,42:18.3
9,-11,42:17.3
10,-11,42:18.3
11,-11,42:17.3
12,-11,42:18.3
13,-11,42:18.3
-12,-10,42:18.3
-11,-10,42:18.3
-10,-10,42:18.3
-9,-10,42:18.3
-8,-10,42:18.3
-7,-10,42:18.3
-6,-10,42:18.3
-5,-10,42:18.3
-4,-10,42:18.3
-3,-10,42:18.3
-2,-10,42:17.3
-1,-10,42:18.3
0,-10,42:18.3
1,-10,42:17.3
2,-10,42:18.3
3,-10,42:18.3
4,-10,42:18.3
5,-10,42:18.3
6,-10,42:18.3
7,-10,42:18.3
8,-10,42:18.3
9,-10,42:18.3
10,-10,42:17.3
11,-10,42:18.3
12,-10,42:18.3
13,-10,42:18.3
-15,-9,42:18.3
-14,-9,42:18.3
-13,-9,42:18.3
-12,-9,42:18.3
-11,-9,42:18.3
-10,-9,42:17.3
-9,-9,42:18.3
-8,-9,42:18.3
-7,-9,42:18.3
-6,-9,42:17.3
-5,-9,42:18.3
-4,-9,42:18.3
-3,-9,42:18.3
-2,-9,42:18.3
-1,-9,42:18.3
0,-9,42:18.3
1,-9,42:18.3
2,-9,42:18.3
3,-9,42:18.3
4,-9,42:18.3
5,-9,42:18.3
6,-9,42:18.3
7,-9,42:18.3
8,-9,42:18.3
9,-9,42:18.3
10,-9,42:18.3
11,-9,42:18.3
12,-9,42:18.3
13,-9,42:18.3
-16,-8,42:18.3
-15,-8,42:18.3
-14,-8,42:18.3
-13,-8,42:18.3
-12,-8,42:18.3
-11,-8,42:18.3
-10,-8,42:18.3
-9,-8,42:17.3
-8,-8,42:18.3
-7,-8,42:18.3
-6,-8,42:17.3
-5,-8,42:17.3
-4,-8,42:18.3
-3,-8,42:18.3
-2,-8,42:18.3
-1,-8,42:18.3
0,-8,42:18.3
1,-8,42:17.3
2,-8,42:18.3
3,-8,42:18.3
4,-8,42:18.3
5,-8,42:18.3
6,-8,42:17.3
7,-8,42:18.3
8,-8,42:18.3
9,-8,42:18.3
10,-8,42:18.3
11,-8,42:17.3
12,-8,42:18.3
13,-8,42:18.3
14,-8,42:18.3
15,-8,42:18.3
16,-8,42:18.3
-16,-7,42:18.3
-15,-7,42:18.3
-14,-7,42:17.3
-13,-7,42:18.3
-12,-7,42:18.3
-11,-7,42:18.3
-10,-7,42:18.3
-9,-7,42:18.3
-8,-7,42:18.3
-7,-7,42:18.3
-6,-7,42:18.3
-5,-7,42:18.3
-4,-7,42:18.3
-3,-7,42:18.3
-2,-7,42:18.3
-1,-7,42:18.3
0,-7,42:18.3
1,-7,42:18.3
2,-7,42:17.3
3,-7,42:18.3
4,-7,42:18.3
5,-7,42:18.3
6,-7,42:17.3
7,-7,42:18.3
8,-7,42:18.3
9,-7,42:18.3
10,-7,42:18.3
11,-7,42:18.3
12,-7,42:18.3
13,-7,42:18.3
14,-7,42:18.3
15,-7,42:18.3
16,-7,42:18.3
17,-7,42:18.3
-16,-6,42:18.3
-15,-6,42:18.3
-14,-6,42:18.3
-13,-6,42:18.3
-12,-6,42:18.3
-11,-6,42:18.3
-10,-6,42:17.3
-9,-6,42:17.3
-8,-6,42:18.3
-7,-6,42:18.3
-6,-6,42:18.3
-5,-6,42:18.3
-4,-6,42:17.3
-3,-6,42:18.3
-2,-6,42:18.3
-1,-6,42:18.3
0,-6,42:18.3
1,-6,42:18.3
2,-6,42:18.3
3,-6,42:18.3
4,-6,42:18.3
5,-6,42:18.3
6,-6,42:17.3
7,-6,42:18.3
8,-6,42:18.3
9,-6,42:18.3
10,-6,42:18.3
11,-6,42:18.3
12,-6,42:18.3
13,-6,42:18.3
14,-6,42:18.3
15,-6,42:17.3
16,-6,42:18.3
17,-6,42:18.3
-16,-5,42:18.3
-15,-5,42:18.3
-14,-5,42:18.3
-13,-5,42:18.3
-12,-5,42:18.3
-11,-5,42:18.3
-10,-5,42:18.3
-9,-5,42:18.3
-8,-5,42:18.3
-7,-5,42:18.3
-6,-5,42:17.3
-5,-5,42:18.3
-4,-5,42:18.3
-3,-5,42:18.3
-2,-5,42:18.3
-1,-5,42:18.3
0,-5,42:18.3
1,-5,42:18.3
2,-5,42:18.3
3,-5,42:18.3
4,-5,42:18.3
5,-5,42:18.3
6,-5,42:18.3
7,-5,42:17.3
8,-5,42:18.3
9,-5,42:18.3
10,-5,42:18.3
11,-5,42:18.3
12,-5,42:18.3
13,-5,42:18.3
14,-5,42:18.3
15,-5,42:18.3
16,-5,42:18.3
17,-5,42:18.3
-17,-4,42:18.3
-16,-4,42:18.3
-15,-4,42:18.3
-14,-4,42:17.3
-13,-4,42:18.3
-12,-4,42:18.3
-11,-4,42:17.3
-10,-4,42:18.3
-9,-4,42:18.3
-8,-4,42:18.3
-7,-4,42:18.3
-6,-4,42:18.3
-5,-4,42:18.3
-4,-4,42:18.3
-3,-4,42:17.3
-2,-4,42:18.3
-1,-4,42:17.3
0,-4,42:18.3
1,-4,42:18.3
4,-4,42:18.3
5,-4,42:17.3
6,-4,42:17.3
7,-4,42:18.3
8,-4,42:17.3
9,-4,42:18.3
10,-4,42:18.3
11,-4,42:18.3
12,-4,42:18.3
13,-4,42:17.3
14,-4,42:18.3
15,-4,42:18.3
16,-4,42:18.3
-18,-3,42:18.3
-17,-3,42:18.3
-16,-3,42:18.3
-15,-3,42:18.3
-14,-3,42:18.3
-13,-3,42:18.3
-12,-3,42:18.3
-11,-3,42:18.3
-10,-3,42:18.3
-9,-3,42:18.3
-8,-3,42:18.3
-7,-3,42:18.3
-6,-3,42:18.3
-5,-3,42:17.3
-4,-3,42:18.3
-3,-3,42:18.3
-2,-3,42:18.3
-1,-3,42:18.3
0,-3,42:18.3
1,-3,42:18.3
4,-3,42:18.3
5,-3,42:18.3
6,-3,42:18.3
7,-3,42:18.3
8,-3,42:18.3
9,-3,42:18.3
10,-3,42:18.3
11,-3,42:18.3
12,-3,42:18.3
13,-3,42:18.3
14,-3,42:18.3
15,-3,42:18.3
16,-3,42:18.3
17,-3,42:18.3
-18,-2,42:18.3
-17,-2,42:18.3
-16,-2,42:17.3
-15,-2,42:18.3
-14,-2,42:18.3
-13,-2,42:18.3
-12,-2,42:18.3
-11,-2,42:18.3
-10,-2,42:18.3
-9,-2,42:18.3
-8,-2,42:17.3
-7,-2,42:18.3
-6,-2,42:18.3
-5,-2,42:18.3
-4,-2,42:17.3
-3,-2,42:18.3
-2,-2,42:18.3
-1,-2,42:18.3
0,-2,42:17.3
1,-2,42:17.3
3,-2,42:18.3
4,-2,42:18.3
5,-2,42:18.3
6,-2,42:18.3
7,-2,42:18.3
8,-2,42:18.3
9,-2,42:18.3
10,-2,42:18.3
11,-2,42:18.3
12,-2,42:18.3
13,-2,42:18.3
14,-2,42:18.3
15,-2,42:17.3
16,-2,42:18.3
17,-2,42:18.3
-18,-1,42:18.3
-17,-1,42:18.3
-16,-1,42:18.3
-15,-1,42:18.3
-14,-1,42:18.3
-13,-1,42:18.3
-12,-1,42:18.3
-11,-1,42:18.3
-10,-1,42:18.3
-9,-1,42:18.3
-8,-1,42:18.3
-7,-1,42:18.3
-6,-1,42:18.3
-5,-1,42:18.3
-4,-1,42:18.3
-3,-1,42:17.3
-2,-1,42:18.3
0,-1,42:17.3
1,-1,42:17.3
3,-1,42:18.3
4,-1,42:18.3
5,-1,42:17.3
6,-1,42:18.3
7,-1,42:18.3
8,-1,42:18.3
9,-1,42:18.3
10,-1,42:18.3
11,-1,42:18.3
12,-1,42:18.3
13,-1,42:18.3
14,-1,42:18.3
15,-1,42:18.3
16,-1,42:18.3
17,-1,42:18.3
-17,0,42:18.3
-16,0,42:18.3
-15,0,42:18.3
-14,0,42:18.3
-13,0,42:18.3
-12,0,42:18.3
-11,0,42:18.3
-10,0,42:18.3
-9,0,42:18.3
-8,0,42:18.3
-7,0,42:18.3
-6,0,42:18.3
-5,0,42:18.3
-4,0,42:18.3
-3,0,42:18.3
-2,0,42:18.3
-1,0,42:18.3
0,0,42:17.3
3,0,42:18.3
4,0,42:17.3
5,0,42:18.3
6,0,42:18.3
7,0,42:18.3
8,0,42:18.3
9,0,42:18.3
10,0,42:18.3
11,0,42:18.3
12,0,42:18.3
13,0,42:17.3
14,0,42:18.3
15,0,42:18.3
16,0,42:18.3
17,0,42:18.3
18,0,42:18.3
-14,1,42:18.3
-13,1,42:18.3
-12,1,42:18.3
-11,1,42:18.3
-10,1,42:18.3
-9,1,42:18.3
-8,1,42:18.3
-7,1,42:18.3
-6,1,42:18.3
-4,1,42:17.3
-3,1,42:18.3
-2,1,42:18.3
-1,1,42:18.3
0,1,42:18.3
1,1,42:18.3
3,1,42:18.3
4,1,42:18.3
5,1,42:17.3
6,1,42:18.3
7,1,42:18.3
8,1,42:17.3
9,1,42:18.3
10,1,42:18.3
11,1,42:18.3
12,1,42:18.3
13,1,42:18.3
14,1,42:18.3
15,1,42:18.3
16,1,42:17.3
17,1,42:18.3
18,1,42:18.3
19,1,42:18.3
-13,2,42:18.3
-12,2,42:18.3
-11,2,42:18.3
-10,2,42:18.3
-9,2,42:18.3
-8,2,42:18.3
-7,2,42:18.3
-5,2,42:18.3
-4,2,42:18.3
-3,2,42:18.3
-2,2,42:18.3
-1,2,42:17.3
0,2,42:18.3
1,2,42:18.3
2,2,42:18.3
3,2,42:18.3
4,2,42:18.3
5,2,42:18.3
6,2,42:17.3
7,2,42:17.3
8,2,42:18.3
9,2,42:18.3
10,2,42:18.3
11,2,42:18.3
12,2,42:18.3
13,2,42:18.3
14,2,42:18.3
15,2,42:18.3
16,2,42:18.3
17,2,42:18.3
18,2,42:18.3
-13,3,42:18.3
-12,3,42:18.3
-11,3,42:18.3
-10,3,42:18.3
-9,3,42:18.3
-8,3,42:18.3
-6,3,42:18.3
-5,3,42:17.3
-4,3,42:18.3
-3,3,42:18.3
-2,3,42:18.3
-1,3,42:18.3
0,3,42:18.3
1,3,42:18.3
2,3,42:18.3
3,3,42:18.3
4,3,42:18.3
5,3,42:18.3
6,3,42:17.3
7,3,42:17.3
8,3,42:18.3
9,3,42:18.3
10,3,42:18.3
11,3,42:18.3
14,3,42:18.3
15,3,42:18.3
16,3,42:18.3
17,3,42:18.3
18,3,42:18.3
19,3,42:18.3
-14,4,42:18.3
-13,4,42:18.3
-12,4,42:18.3
-11,4,42:17.3
-10,4,42:18.3
-9,4,42:18.3
-6,4,42:18.3
-5,4,42:18.3
-4,4,42:17.3
-3,4,42:18.3
-2,4,42:18.3
-1,4,42:18.3
0,4,42:18.3
1,4,42:18.3
2,4,42:17.3
3,4,42:18.3
4,4,42:18.3
5,4,42:18.3
6,4,42:18.3
7,4,42:18.3
8,4,42:18.3
9,4,42:18.3
10,4,42:18.3
11,4,42:18.3
15,4,42:18.3
16,4,42:18.3
17,4,42:18.3
18,4,42:18.3
19,4,42:18.3
20,4,42:18.3
-15,5,42:18.3
-14,5,42:18.3
-13,5,42:18.3
-12,5,42:18.3
-11,5,42:18.3
-10,5,42:18.3
-9,5,42:18.3
-7,5,42:18.3
-6,5,42:18.3
-5,5,42:18.3
-4,5,42:18.3
-3,5,42:18.3
-2,5,42:18.3
-1,5,42:18.3
0,5,42:18.3
1,5,42:18.3
2,5,42:18.3
3,5,42:18.3
4,5,42:17.3
5,5,42:18.3
6,5,42:17.3
7,5,42:18.3
8,5,42:18.3
9,5,42:18.3
10,5,42:18.3
11,5,42:18.3
16,5,42:18.3
17,5,42:18.3
18,5,42:18.3
19,5,42:18.3
20,5,42:18.3
21,5,42:18.3
-15,6,42:18.3
-14,6,42:18.3
-13,6,42:17.3
-12,6,42:18.3
-11,6,42:18.3
-10,6,42:18.3
-8,6,42:18.3
-7,6,42:18.3
-6,6,42:18.3
-5,6,42:18.3
-4,6,42:18.3
-3,6,42:18.3
-2,6,42:18.3
-1,6,42:18.3
0,6,42:18.3
1,6,42:18.3
2,6,42:18.3
3,6,42:18.3
4,6,42:18.3
5,6,42:18.3
6,6,42:18.3
7,6,42:18.3
8,6,42:18.3
9,6,42:18.3
10,6,42:18.3
11,6,42:18.3
12,6,42:18.3
18,6,42:18.3
19,6,42:18.3
20,6,42:18.3
-15,7,42:18.3
-14,7,42:18.3
-13,7,42:18.3
-12,7,42:18.3
-11,7,42:18.3
-10,7,42:18.3
-8,7,42:18.3
-7,7,42:18.3
-6,7,42:17.3
-5,7,42:18.3
-4,7,42:18.3
-3,7,42:18.3
-2,7,42:18.3
-1,7,42:18.3
0,7,42:18.3
1,7,42:18.3
2,7,42:18.3
3,7,42:18.3
4,7,42:18.3
5,7,42:18.3
6,7,42:18.3
7,7,42:18.3
8,7,42:17.3
9,7,42:18.3
10,7,42:18.3
11,7,42:18.3
14,7,42:18.3
15,7,42:18.3
16,7,42:18.3
19,7,42:18.3
-14,8,42:18.3
-13,8,42:18.3
-12,8,42:17.3
-11,8,42:18.3
-10,8,42:18.3
-9,8,42:18.3
-8,8,42:18.3
-7,8,42:18.3
-6,8,42:18.3
-5,8,42:18.3
-4,8,42:18.3
-3,8,42:17.3
-2,8,42:18.3
-1,8,42:18.3
0,8,42:18.3
1,8,42:18.3
2,8,42:18.3
4,8,42:18.3
5,8,42:18.3
6,8,42:18.3
7,8,42:18.3
8,8,42:18.3
9,8,42:18.3
10,8,42:18.3
11,8,42:18.3
13,8,42:18.3
14,8,42:18.3
15,8,42:18.3
16,8,42:18.3
17,8,42:18.3
-14,9,42:18.3
-13,9,42:18.3
-12,9,42:18.3
-11,9,42:17.3
-10,9,42:18.3
-9,9,42:18.3
-8,9,42:18.3
-7,9,42:18.3
-6,9,42:18.3
-5,9,42:18.3
-4,9,42:18.3
-3,9,42:18.3
-2,9,42:18.3
-1,9,42:18.3
0,9,42:17.3
1,9,42:18.3
2,9,42:18.3
5,9,42:18.3
6,9,42:18.3
7,9,42:18.3
8,9,42:18.3
9,9,42:17.3
10,9,42:18.3
11,9,42:18.3
12,9,42:18.3
13,9,42:18.3
14,9,42:18.3
15,9,42:17.3
16,9,42:18.3
17,9,42:18.3
-13,10,42:18.3
-12,10,42:18.3
-11,10,42:18.3
-10,10,42:18.3
-9,10,42:18.3
-8,10,42:18.3
-7,10,42:18.3
-6,10,42:18.3
-5,10,42:18.3
-4,10,42:18.3
-3,10,42:18.3
-2,10,42:18.3
-1,10,42:18.3
0,10,42:17.3
1,10,42:18.3
2,10,42:18.3
4,10,42:18.3
5,10,42:18.3
6,10,42:18.3
7,10,42:18.3
8,10,42:18.3
9,10,42:18.3
10,10,42:18.3
11,10,42:18.3
12,10,42:18.3
13,10,42:18.3
14,10,42:18.3
15,10,42:18.3
16,10,42:18.3
17,10,42:18.3
-12,11,42:18.3
-11,11,42:18.3
-10,11,42:18.3
-9,11,42:18.3
-8,11,42:18.3
-7,11,42:17.3
-6,11,42:18.3
-5,11,42:18.3
-4,11,42:18.3
-3,11,42:18.3
-2,11,42:18.3
-1,11,42:18.3
0,11,42:18.3
1,11,42:18.3
2,11,42:18.3
3,11,42:18.3
4,11,42:18.3
5,11,42:18.3
6,11,42:18.3
7,11,42:18.3
8,11,42:18.3
9,11,42:18.3
10,11,42:18.3
11,11,42:17.3
12,11,42:18.3
13,11,42:18.3
14,11,42:18.3
15,11,42:18.3
16,11,42:18.3
-9,12,42:18.3
-8,12,42:18.3
-7,12,42:18.3
-6,12,42:18.3
-5,12,42:18.3
-4,12,42:18.3
-2,12,42:18.3
-1,12,42:18.3
0,12,42:18.3
1,12,42:17.3
2,12,42:18.3
3,12,42:18.3
4,12,42:18.3
5,12,42:18.3
6,12,42:18.3
9,12,42:18.3
10,12,42:18.3
11,12,42:18.3
12,12,42:18.3
13,12,42:18.3
14,12,42:18.3
-8,13,42:18.3
-7,13,42:18.3
-6,13,42:18.3
-1,13,42:18.3
0,13,42:18.3
1,13,42:18.3
2,13,42:18.3
3,13,42:18.3
4,13,42:18.3
5,13,42:18.3
6,13,42:18.3
7,13,42:18.3
10,13,42:18.3
11,13,42:18.3
12,13,42:18.3
13,13,42:18.3
14,13,42:18.3
15,13,42:18.3
0,14,42:18.3
1,14,42:18.3
2,14,42:18.3
3,14,42:18.3
4,14,42:18.3
5,14,42:17.3
6,14,42:18.3
7,14,42:18.3
12,14,42:18.3
13,14,42:18.3
14,14,42:18.3
15,14,42:18.3
16,14,42:18.3
3,15,42:18.3
4,15,42:18.3
5,15,42:18.3
6,15,42:18.3
7,15,42:18.3
13,15,42:18.3
14,15,42:18.3
15,15,42:18.3
4,16,42:18.3
5,16,42:18.3
6,16,42:18.3
14,16,42:18.3
7,-22,43:18.3
6,-21,43:18.3
7,-21,43:18.3
8,-21,43:18.3
2,-20,43:18.3
3,-20,43:18.3
4,-20,43:18.3
5,-20,43:18.3
6,-20,43:18.3
7,-20,43:18.3
8,-20,43:18.3
9,-20,43:18.3
1,-19,43:18.3
2,-19,43:18.3
3,-19,43:18.3
4,-19,43:18.3
5,-19,43:18.3
6,-19,43:18.3
7,-19,43:18.3
8,-19,43:18.3
0,-18,43:18.3
1,-18,43:18.3
2,-18,43:18.3
3,-18,43:17.3
4,-18,43:18.3
5,-18,43:18.3
7,-18,43:18.3
8,-18,43:18.3
9,-18,43:18.3
-6,-17,43:18.3
-4,-17,43:18.3
-1,-17,43:18.3
0,-17,43:18.3
1,-17,43:18.3
2,-17,43:18.3
3,-17,43:18.3
4,-17,43:18.3
5,-17,43:18.3
6,-17,43:18.3
7,-17,43:18.3
8,-17,43:18.3
9,-17,43:18.3
10,-17,43:18.3
-9,-16,43:18.3
-7,-16,43:18.3
-6,-16,43:18.3
-5,-16,43:18.3
-4,-16,43:18.3
-3,-16,43:18.3
-2,-16,43:18.3
-1,-16,43:18.3
0,-16,43:18.3
1,-16,43:18.3
2,-16,43:18.3
3,-16,43:18.3
4,-16,43:18.3
5,-16,43:18.3
6,-16,43:18.3
7,-16,43:18.3
8,-16,43:17.3
9,-16,43:18.3
10,-16,43:18.3
11,-16,43:18.3
-10,-15,43:18.3
-9,-15,43:18.3
-8,-15,43:18.3
-7,-15,43:18.3
-6,-15,43:18.3
-5,-15,43:18.3
-4,-15,43:18.3
-3,-15,43:18.3
-2,-15,43:18.3
-1,-15,43:18.3
0,-15,43:18.3
1,-15,43:18.3
2,-15,43:18.3
3,-15,43:18.3
4,-15,43:17.3
5,-15,43:18.3
6,-15,43:18.3
7,-15,43:18.3
8,-15,43:18.3
9,-15,43:18.3
10,-15,43:18.3
11,-15,43:18.3
12,-15,43:18.3
-11,-14,43:18.3
-10,-14,43:18.3
-9,-14,43:18.3
-8,-14,43:18.3
-7,-14,43:18.3
-6,-14,43:18.3
-5,-14,43:18.3
-4,-14,43:18.3
-3,-14,43:18.3
0,-14,43:18.3
1,-14,43:18.3
2,-14,43:18.3
3,-14,43:18.3
4,-14,43:18.3
5,-14,43:17.3
6,-14,43:18.3
7,-14,43:18.3
8,-14,43:18.3
9,-14,43:18.3
10,-14,43:17.3
11,-14,43:18.3
12,-14,43:18.3
-10,-13,43:18.3
-9,-13,43:18.3
-8,-13,43:18.3
-6,-13,43:18.3
-5,-13,43:18.3
-4,-13,43:18.3
-1,-13,43:18.3
0,-13,43:18.3
1,-13,43:18.3
2,-13,43:18.3
3,-13,43:18.3
4,-13,43:18.3
5,-13,43:18.3
6,-13,43:18.3
7,-13,43:18.3
8,-13,43:18.3
9,-13,43:18.3
10,-13,43:18.3
11,-13,43:18.3
12,-13,43:18.3
-9,-12,43:18.3
-5,-12,43:18.3
-1,-12,43:18.3
0,-12,43:18.3
1,-12,43:17.3
2,-12,43:18.3
3,-12,43:18.3
4,-12,43:17.3
5,-12,43:18.3
6,-12,43:18.3
7,-12,43:18.3
8,-12,43:18.3
9,-12,43:17.3
10,-12,43:18.3
11,-12,43:18.3
12,-12,43:18.3
15,-12,43:18.3
16,-12,43:18.3
17,-12,43:18.3
-16,-11,43:18.3
-15,-11,43:18.3
-14,-11,43:18.3
-10,-11,43:18.3
-9,-11,43:18.3
-8,-11,43:18.3
-7,-11,43:18.3
-6,-11,43:18.3
-2,-11,43:17.3
-1,-11,43:18.3
0,-11,43:18.3
1,-11,43:17.3
2,-11,43:18.3
3,-11,43:18.3
4,-11,43:18.3
5,-11,43:18.3
6,-11,43:18.3
7,-11,43:18.3
8,-11,43:18.3
9,-11,43:18.3
10,-11,43:18.3
11,-11,43:18.3
12,-11,43:18.3
13,-11,43:18.3
14,-11,43:18.3
15,-11,43:18.3
16,-11,43:18.3
17,-11,43:18.3
18,-11,43:18.3
-17,-10,43:18.3
-16,-10,43:18.3
-15,-10,43:18.3
-14,-10,43:18.3
-13,-10,43:18.3
-11,-10,43:18.3
-10,-10,43:18.3
-9,-10,43:18.3
-8,-10,43:18.3
-7,-10,43:18.3
-6,-10,43:18.3
-5,-10,43:18.3
-1,-10,43:18.3
0,-10,43:18.3
1,-10,43:18.3
2,-10,43:17.3
3,-10,43:18.3
4,-10,43:18.3
5,-10,43:18.3
6,-10,43:18.3
7,-10,43:18.3
8,-10,43:18.3
9,-10,43:17.3
10,-10,43:18.3
11,-10,43:18.3
12,-10,43:18.3
14,-10,43:18.3
15,-10,43:18.3
16,-10,43:17.3
17,-10,43:18.3
18,-10,43:18.3
-17,-9,43:18.3
-16,-9,43:18.3
-15,-9,43:17.3
-14,-9,43:18.3
-13,-9,43:18.3
-12,-9,43:18.3
-11,-9,43:18.3
-10,-9,43:18.3
-9,-9,43:18.3
-8,-9,43:17.3
-7,-9,43:18.3
-6,-9,43:18.3
-5,-9,43:18.3
-4,-9,43:18.3
-3,-9,43:18.3
-2,-9,43:18.3
-1,-9,43:18.3
0,-9,43:18.3
1,-9,43:17.3
2,-9,43:18.3
3,-9,43:18.3
4,-9,43:18.3
5,-9,43:18.3
6,-9,43:18.3
7,-9,43:18.3
8,-9,43:18.3
9,-9,43:18.3
10,-9,43:18.3
11,-9,43:18.3
12,-9,43:18.3
14,-9,43:18.3
15,-9,43:18.3
16,-9,43:18.3
17,-9,43:18.3
18,-9,43:18.3
-17,-8,43:18.3
-16,-8,43:18.3
-15,-8,43:18.3
-14,-8,43:18.3
-13,-8,43:18.3
-11,-8,43:18.3
-10,-8,43:18.3
-9,-8,43:18.3
-8,-8,43:18.3
-7,-8,43:18.3
-6,-8,43:18.3
-5,-8,43:18.3
-4,-8,43:18.3
-3,-8,43:18.3
-2,-8,43:18.3
-1,-8,43:18.3
0,-8,43:18.3
1,-8,43:18.3
2,-8,43:18.3
3,-8,43:18.3
4,-8,43:18.3
5,-8,43:18.3
6,-8,43:18.3
7,-8,43:18.3
8,-8,43:18.3
9,-8,43:18.3
10,-8,43:18.3
11,-8,43:18.3
12,-8,43:18.3
13,-8,43:18.3
15,-8,43:18.3
16,-8,43:18.3
17,-8,43:18.3
-16,-7,43:18.3
-15,-7,43:18.3
-14,-7,43:18.3
-13,-7,43:18.3
-12,-7,43:18.3
-11,-7,43:18.3
-10,-7,43:18.3
-9,-7,43:18.3
-8,-7,43:18.3
-7,-7,43:18.3
-6,-7,43:18.3
-5,-7,43:18.3
-4,-7,43:17.3
-3,-7,43:17.3
-2,-7,43:17.3
-1,-7,43:18.3
0,-7,43:18.3
1,-7,43:18.3
2,-7,43:18.3
3,-7,43:17.3
4,-7,43:18.3
5,-7,43:17.3
6,-7,43:18.3
7,-7,43:17.3
8,-7,43:18.3
9,-7,43:18.3
10,-7,43:18.3
11,-7,43:18.3
12,-7,43:18.3
13,-7,43:18.3
14,-7,43:18.3
15,-7,43:18.3
16,-7,43:18.3
-15,-6,43:18.3
-14,-6,43:18.3
-13,-6,43:18.3
-12,-6,43:18.3
-11,-6,43:18.3
-10,-6,43:17.3
-9,-6,43:18.3
-8,-6,43:18.3
-7,-6,43:17.3
-6,-6,43:18.3
-5,-6,43:17.3
-4,-6,43:17.3
-3,-6,43:18.3
-2,-6,43:18.3
-1,-6,43:18.3
0,-6,43:18.3
1,-6,43:18.3
2,-6,43:17.3
3,-6,43:18.3
4,-6,43:17.3
5,-6,43:18.3
6,-6,43:18.3
7,-6,43:17.3
8,-6,43:17.3
9,-6,43:18.3
10,-6,43:18.3
11,-6,43:18.3
12,-6,43:17.3
13,-6,43:18.3
14,-6,43:18.3
15,-6,43:18.3
16,-6,43:18.3
17,-6,43:18.3
-15,-5,43:18.3
-14,-5,43:18.3
-13,-5,43:18.3
-12,-5,43:18.3
-11,-5,43:18.3
-10,-5,43:18.3
-9,-5,43:18.3
-8,-5,43:18.3
-7,-5,43:17.3
-6,-5,43:18.3
-5,-5,43:18.3
-4,-5,43:18.3
-3,-5,43:18.3
-2,-5,43:18.3
-1,-5,43:18.3
0,-5,43:18.3
1,-5,43:17.3
2,-5,43:18.3
3,-5,43:18.3
4,-5,43:18.3
5,-5,43:18.3
6,-5,43:17.3
7,-5,43:17.3
8,-5,43:18.3
9,-5,43:18.3
10,-5,43:17.3
11,-5,43:18.3
12,-5,43:18.3
13,-5,43:18.3
14,-5,43:18.3
15,-5,43:18.3
16,-5,43:18.3
-16,-4,43:18.3
-15,-4,43:18.3
-14,-4,43:18.3
-13,-4,43:18.3
-12,-4,43:18.3
-11,-4,43:18.3
-10,-4,43:18.3
-9,-4,43:18.3
-8,-4,43:18.3
-7,-4,43:18.3
-6,-4,43:18.3
-5,-4,43:18.3
-4,-4,43:18.3
-3,-4,43:18.3
-2,-4,43:18.3
-1,-4,43:18.3
0,-4,43:18.3
1,-4,43:18.3
2,-4,43:18.3
3,-4,43:18.3
4,-4,43:18.3
5,-4,43:18.3
6,-4,43:18.3
7,-4,43:18.3
8,-4,43:18.3
9,-4,43:18.3
10,-4,43:18.3
11,-4,43:18.3
12,-4,43:18.3
13,-4,43:18.3
14,-4,43:18.3
15,-4,43:18.3
-17,-3,43:18.3
-16,-3,43:18.3
-15,-3,43:18.3
-14,-3,43:18.3
-13,-3,43:18.3
-12,-3,43:18.3
-11,-3,43:18.3
-10,-3,43:18.3
-9,-3,43:18.3
-8,-3,43:18.3
-7,-3,43:18.3
-6,-3,43:18.3
-5,-3,43:17.3
-4,-3,43:18.3
-3,-3,43:18.3
-2,-3,43:18.3
-1,-3,43:17.3
0,-3,43:17.3
1,-3,43:17.3
2,-3,43:18.3
5,-3,43:18.3
6,-3,43:18.3
7,-3,43:18.3
8,-3,43:18.3
9,-3,43:18.3
10,-3,43:18.3
11,-3,43:18.3
12,-3,43:18.3
13,-3,43:18.3
14,-3,43:18.3
15,-3,43:18.3
16,-3,43:18.3
-18,-2,43:18.3
-17,-2,43:18.3
-16,-2,43:18.3
-15,-2,43:18.3
-14,-2,43:18.3
-11,-2,43:18.3
-10,-2,43:18.3
-9,-2,43:17.3
-8,-2,43:18.3
-7,-2,43:18.3
-6,-2,43:18.3
-5,-2,43:18.3
-4,-2,43:18.3
-3,-2,43:17.3
-2,-2,43:18.3
-1,-2,43:18.3
0,-2,43:17.3
4,-2,43:18.3
5,-2,43:18.3
6,-2,43:18.3
7,-2,43:18.3
8,-2,43:18.3
9,-2,43:18.3
10,-2,43:18.3
11,-2,43:18.3
13,-2,43:18.3
14,-2,43:18.3
15,-2,43:18.3
16,-2,43:18.3
17,-2,43:18.3
18,-2,43:18.3
19,-2,43:18.3
20,-2,43:18.3
-17,-1,43:18.3
-16,-1,43:18.3
-15,-1,43:18.3
-11,-1,43:18.3
-10,-1,43:18.3
-9,-1,43:18.3
-8,-1,43:17.3
-7,-1,43:17.3
-6,-1,43:18.3
-5,-1,43:18.3
-4,-1,43:18.3
-3,-1,43:18.3
-2,-1,43:18.3
-1,-1,43:17.3
1,-1,43:17.3
2,-1,43:17.3
3,-1,43:18.3
4,-1,43:18.3
5,-1,43:18.3
6,-1,43:17.3
7,-1,43:18.3
8,-1,43:18.3
9,-1,43:17.3
10,-1,43:18.3
11,-1,43:18.3
12,-1,43:18.3
13,-1,43:18.3
14,-1,43:18.3
15,-1,43:18.3
16,-1,43:18.3
17,-1,43:18.3
18,-1,43:18.3
19,-1,43:18.3
20,-1,43:18.3
21,-1,43:18.3
-16,0,43:18.3
-10,0,43:18.3
-9,0,43:18.3
-8,0,43:18.3
-7,0,43:18.3
-6,0,43:18.3
-5,0,43:18.3
-4,0,43:17.3
-3,0,43:18.3
-2,0,43:18.3
-1,0,43:18.3
1,0,43:18.3
2,0,43:18.3
3,0,43:18.3
4,0,43:18.3
5,0,43:17.3
6,0,43:17.3
7,0,43:17.3
8,0,43:18.3
9,0,43:18.3
10,0,43:18.3
11,0,43:18.3
12,0,43:18.3
13,0,43:18.3
14,0,43:18.3
15,0,43:18.3
16,0,43:18.3
17,0,43:18.3
18,0,43:18.3
19,0,43:17.3
20,0,43:18.3
21,0,43:18.3
-11,1,43:18.3
-10,1,43:18.3
-9,1,43:18.3
-8,1,43:18.3
-7,1,43:18.3
-6,1,43:18.3
-5,1,43:17.3
-4,1,43:18.3
-3,1,43:18.3
-2,1,43:18.3
-1,1,43:18.3
0,1,43:17.3
1,1,43:18.3
2,1,43:18.3
3,1,43:18.3
4,1,43:18.3
5,1,43:18.3
6,1,43:18.3
7,1,43:18.3
8,1,43:18.3
9,1,43:18.3
10,1,43:18.3
11,1,43:18.3
12,1,43:18.3
13,1,43:17.3
14,1,43:18.3
15,1,43:18.3
16,1,43:18.3
17,1,43:18.3
18,1,43:18.3
19,1,43:18.3
20,1,43:18.3
21,1,43:18.3
-11,2,43:18.3
-10,2,43:18.3
-9,2,43:17.3
-8,2,43:17.3
-7,2,43:18.3
-6,2,43:18.3
-5,2,43:18.3
-4,2,43:18.3
-3,2,43:18.3
-2,2,43:18.3
-1,2,43:18.3
0,2,43:18.3
1,2,43:18.3
2,2,43:17.3
3,2,43:18.3
4,2,43:18.3
5,2,43:18.3
6,2,43:18.3
7,2,43:17.3
8,2,43:18.3
9,2,43:18.3
11,2,43:18.3
12,2,43:18.3
13,2,43:18.3
14,2,43:18.3
15,2,43:18.3
16,2,43:18.3
17,2,43:18.3
18,2,43:18.3
19,2,43:18.3
20,2,43:18.3
-16,3,43:18.3
-15,3,43:18.3
-14,3,43:18.3
-12,3,43:18.3
-11,3,43:18.3
-10,3,43:18.3
-9,3,43:18.3
-8,3,43:18.3
-7,3,43:17.3
-6,3,43:17.3
-5,3,43:17.3
-4,3,43:17.3
-3,3,43:18.3
-2,3,43:18.3
-1,3,43:18.3
0,3,43:18.3
1,3,43:17.3
2,3,43:18.3
3,3,43:18.3
4,3,43:18.3
5,3,43:18.3
6,3,43:18.3
7,3,43:18.3
8,3,43:18.3
9,3,43:18.3
12,3,43:18.3
13,3,43:18.3
14,3,43:18.3
16,3,43:18.3
-17,4,43:18.3
-16,4,43:18.3
-15,4,43:18.3
-14,4,43:18.3
-13,4,43:18.3
-12,4,43:18.3
-11,4,43:18.3
-10,4,43:18.3
-9,4,43:18.3
-8,4,43:18.3
-7,4,43:18.3
-6,4,43:18.3
-5,4,43:18.3
-4,4,43:18.3
-3,4,43:18.3
-2,4,43:18.3
-1,4,43:18.3
0,4,43:18.3
1,4,43:18.3
2,4,43:18.3
3,4,43:18.3
4,4,43:18.3
5,4,43:18.3
6,4,43:18.3
7,4,43:18.3
8,4,43:18.3
9,4,43:18.3
10,4,43:18.3
11,4,43:18.3
-17,5,43:18.3
-16,5,43:18.3
-15,5,43:17.3
-14,5,43:18.3
-13,5,43:18.3
-12,5,43:18.3
-11,5,43:18.3
-10,5,43:18.3
-9,5,43:18.3
-8,5,43:18.3
-7,5,43:17.3
-6,5,43:18.3
-5,5,43:18.3
-4,5,43:18.3
-3,5,43:18.3
0,5,43:18.3
1,5,43:18.3
2,5,43:17.3
3,5,43:18.3
4,5,43:18.3
5,5,43:17.3
6,5,43:18.3
7,5,43:18.3
8,5,43:18.3
9,5,43:18.3
10,5,43:18.3
11,5,43:18.3
12,5,43:18.3
-17,6,43:18.3
-16,6,43:18.3
-15,6,43:18.3
-14,6,43:18.3
-13,6,43:18.3
-12,6,43:18.3
-11,6,43:18.3
-10,6,43:18.3
-9,6,43:18.3
-8,6,43:18.3
-7,6,43:18.3
-6,6,43:18.3
-5,6,43:18.3
-4,6,43:18.3
-3,6,43:18.3
0,6,43:18.3
1,6,43:18.3
2,6,43:18.3
3,6,43:18.3
4,6,43:18.3
5,6,43:18.3
6,6,43:18.3
7,6,43:18.3
8,6,43:18.3
9,6,43:18.3
10,6,43:17.3
11,6,43:18.3
12,6,43:18.3
-16,7,43:18.3
-15,7,43:18.3
-14,7,43:18.3
-13,7,43:18.3
-12,7,43:17.3
-11,7,43:18.3
-10,7,43:18.3
-8,7,43:18.3
-7,7,43:18.3
-6,7,43:18.3
-5,7,43:18.3
-4,7,43:18.3
-3,7,43:18.3
-2,7,43:18.3
1,7,43:18.3
2,7,43:18.3
3,7,43:17.3
4,7,43:18.3
5,7,43:18.3
6,7,43:18.3
7,7,43:18.3
8,7,43:18.3
9,7,43:18.3
10,7,43:18.3
11,7,43:18.3
12,7,43:18.3
15,7,43:18.3
-14,8,43:18.3
-13,8,43:18.3
-12,8,43:18.3
-11,8,43:18.3
-10,8,43:18.3
-9,8,43:18.3
-8,8,43:18.3
-7,8,43:18.3
-6,8,43:18.3
-5,8,43:18.3
-4,8,43:18.3
-3,8,43:18.3
-2,8,43:18.3
-1,8,43:18.3
0,8,43:18.3
1,8,43:18.3
2,8,43:18.3
3,8,43:18.3
4,8,43:18.3
5,8,43:17.3
6,8,43:18.3
7,8,43:18.3
8,8,43:18.3
9,8,43:18.3
10,8,43:18.3
11,8,43:18.3
14,8,43:18.3
15,8,43:18.3
16,8,43:18.3
-13,9,43:18.3
-12,9,43:18.3
-11,9,43:18.3
-10,9,43:18.3
-9,9,43:18.3
-8,9,43:18.3
-7,9,43:18.3
-6,9,43:18.3
-5,9,43:18.3
-4,9,43:18.3
-3,9,43:18.3
-2,9,43:18.3
-1,9,43:18.3
0,9,43:18.3
1,9,43:18.3
2,9,43:18.3
3,9,43:17.3
4,9,43:18.3
5,9,43:18.3
6,9,43:18.3
7,9,43:18.3
8,9,43:18.3
9,9,43:18.3
10,9,43:18.3
11,9,43:18.3
12,9,43:18.3
13,9,43:18.3
14,9,43:18.3
15,9,43:18.3
16,9,43:18.3
17,9,43:18.3
-12,10,43:18.3
-11,10,43:18.3
-10,10,43:18.3
-9,10,43:18.3
-8,10,43:17.3
-7,10,43:18.3
-6,10,43:18.3
-5,10,43:18.3
-4,10,43:18.3
-3,10,43:18.3
-2,10,43:17.3
-1,10,43:18.3
0,10,43:17.3
1,10,43:18.3
2,10,43:18.3
3,10,43:18.3
4,10,43:18.3
5,10,43:18.3
6,10,43:18.3
8,10,43:18.3
9,10,43:18.3
10,10,43:18.3
11,10,43:18.3
12,10,43:18.3
13,10,43:18.3
14,10,43:18.3
15,10,43:18.3
16,10,43:18.3
-11,11,43:18.3
-10,11,43:18.3
-9,11,43:18.3
-8,11,43:18.3
-7,11,43:18.3
-6,11,43:17.3
-5,11,43:18.3
-4,11,43:18.3
-3,11,43:18.3
-2,11,43:18.3
-1,11,43:18.3
0,11,43:17.3
1,11,43:18.3
2,11,43:18.3
3,11,43:18.3
4,11,43:18.3
8,11,43:18.3
9,11,43:18.3
10,11,43:18.3
11,11,43:17.3
12,11,43:18.3
13,11,43:18.3
15,11,43:18.3
-11,12,43:18.3
-10,12,43:18.3
-9,12,43:17.3
-8,12,43:18.3
-7,12,43:18.3
-6,12,43:18.3
-5,12,43:18.3
-4,12,43:18.3
-3,12,43:18.3
-2,12,43:18.3
-1,12,43:18.3
0,12,43:18.3
1,12,43:18.3
2,12,43:18.3
3,12,43:18.3
5,12,43:18.3
8,12,43:18.3
9,12,43:18.3
10,12,43:17.3
11,12,43:18.3
12,12,43:18.3
13,12,43:18.3
-11,13,43:18.3
-10,13,43:18.3
-9,13,43:18.3
-8,13,43:18.3
-7,13,43:18.3
-6,13,43:18.3
-5,13,43:18.3
-1,13,43:18.3
0,13,43:18.3
1,13,43:18.3
2,13,43:18.3
4,13,43:18.3
5,13,43:18.3
6,13,43:18.3
8,13,43:18.3
9,13,43:18.3
10,13,43:18.3
11,13,43:18.3
12,13,43:18.3
-10,14,43:18.3
-9,14,43:18.3
-8,14,43:18.3
1,14,43:18.3
3,14,43:18.3
4,14,43:18.3
5,14,43:18.3
6,14,43:18.3
7,14,43:18.3
9,14,43:18.3
10,14,43:18.3
11,14,43:18.3
4,15,43:18.3
5,15,43:18.3
6,15,43:18.3
5,16,43:18.3
3,-20,44:18.3
2,-19,44:18.3
3,-19,44:18.3
4,-19,44:18.3
1,-18,44:18.3
2,-18,44:18.3
3,-18,44:18.3
4,-18,44:18.3
5,-18,44:18.3
8,-18,44:18.3
2,-17,44:18.3
3,-17,44:18.3
4,-17,44:18.3
7,-17,44:18.3
8,-17,44:18.3
9,-17,44:18.3
3,-16,44:18.3
4,-16,44:18.3
5,-16,44:18.3
6,-16,44:18.3
7,-16,44:18.3
8,-16,44:18.3
9,-16,44:18.3
10,-16,44:18.3
2,-15,44:18.3
3,-15,44:18.3
4,-15,44:18.3
5,-15,44:18.3
6,-15,44:18.3
7,-15,44:18.3
8,-15,44:18.3
9,-15,44:18.3
10,-15,44:18.3
11,-15,44:18.3
-4,-14,44:18.3
-3,-14,44:18.3
-2,-14,44:18.3
1,-14,44:18.3
3,-14,44:18.3
4,-14,44:18.3
5,-14,44:18.3
6,-14,44:18.3
7,-14,44:18.3
8,-14,44:18.3
9,-14,44:18.3
10,-14,44:18.3
11,-14,44:18.3
12,-14,44:18.3
-5,-13,44:18.3
-4,-13,44:18.3
-3,-13,44:18.3
-2,-13,44:18.3
-1,-13,44:18.3
0,-13,44:18.3
1,-13,44:18.3
2,-13,44:18.3
3,-13,44:18.3
4,-13,44:18.3
5,-13,44:18.3
6,-13,44:18.3
7,-13,44:18.3
8,-13,44:17.3
9,-13,44:18.3
10,-13,44:18.3
11,-13,44:18.3
-5,-12,44:18.3
-4,-12,44:18.3
-3,-12,44:17.3
-2,-12,44:17.3
-1,-12,44:18.3
0,-12,44:18.3
1,-12,44:18.3
2,-12,44:18.3
3,-12,44:18.3
4,-12,44:18.3
5,-12,44:18.3
6,-12,44:18.3
7,-12,44:18.3
8,-12,44:18.3
9,-12,44:18.3
10,-12,44:18.3
11,-12,44:18.3
16,-12,44:18.3
-15,-11,44:18.3
-8,-11,44:18.3
-5,-11,44:18.3
-4,-11,44:18.3
-3,-11,44:18.3
-2,-11,44:18.3
-1,-11,44:18.3
0,-11,44:18.3
1,-11,44:17.3
2,-11,44:18.3
3,-11,44:18.3
4,-11,44:18.3
5,-11,44:18.3
6,-11,44:18.3
7,-11,44:18.3
8,-11,44:18.3
9,-11,44:18.3
10,-11,44:18.3
15,-11,44:18.3
16,-11,44:18.3
17,-11,44:18.3
-16,-10,44:18.3
-15,-10,44:18.3
-14,-10,44:18.3
-9,-10,44:18.3
-8,-10,44:18.3
-7,-10,44:18.3
-4,-10,44:18.3
-3,-10,44:18.3
-2,-10,44:18.3
-1,-10,44:18.3
0,-10,44:18.3
1,-10,44:18.3
2,-10,44:18.3
3,-10,44:18.3
4,-10,44:18.3
5,-10,44:17.3
6,-10,44:18.3
7,-10,44:18.3
8,-10,44:18.3
9,-10,44:18.3
10,-10,44:18.3
11,-10,44:18.3
14,-10,44:18.3
15,-10,44:18.3
16,-10,44:18.3
17,-10,44:18.3
18,-10,44:18.3
-17,-9,44:18.3
-16,-9,44:18.3
-15,-9,44:18.3
-14,-9,44:18.3
-13,-9,44:18.3
-10,-9,44:18.3
-9,-9,44:18.3
-8,-9,44:18.3
-7,-9,44:18.3
-6,-9,44:18.3
-5,-9,44:18.3
-4,-9,44:18.3
-3,-9,44:18.3
-2,-9,44:18.3
-1,-9,44:18.3
0,-9,44:18.3
1,-9,44:18.3
2,-9,44:18.3
3,-9,44:18.3
4,-9,44:18.3
5,-9,44:18.3
6,-9,44:17.3
7,-9,44:18.3
8,-9,44:18.3
9,-9,44:18.3
10,-9,44:18.3
15,-9,44:18.3
16,-9,44:18.3
17,-9,44:18.3
-16,-8,44:18.3
-15,-8,44:18.3
-14,-8,44:18.3
-13,-8,44:18.3
-12,-8,44:18.3
-11,-8,44:18.3
-10,-8,44:18.3
-9,-8,44:18.3
-8,-8,44:18.3
-7,-8,44:18.3
-6,-8,44:18.3
-5,-8,44:18.3
-4,-8,44:18.3
-3,-8,44:18.3
-2,-8,44:18.3
-1,-8,44:18.3
0,-8,44:18.3
1,-8,44:18.3
2,-8,44:18.3
3,-8,44:18.3
4,-8,44:18.3
5,-8,44:17.3
6,-8,44:18.3
7,-8,44:18.3
8,-8,44:18.3
9,-8,44:18.3
12,-8,44:18.3
13,-8,44:18.3
14,-8,44:18.3
15,-8,44:18.3
16,-8,44:18.3
-15,-7,44:18.3
-14,-7,44:18.3
-13,-7,44:18.3
-12,-7,44:18.3
-11,-7,44:18.3
-10,-7,44:18.3
-9,-7,44:18.3
-8,-7,44:18.3
-7,-7,44:18.3
-6,-7,44:17.3
-5,-7,44:18.3
-4,-7,44:18.3
-3,-7,44:18.3
-2,-7,44:18.3
-1,-7,44:18.3
0,-7,44:18.3
1,-7,44:18.3
2,-7,44:17.3
3,-7,44:18.3
4,-7,44:18.3
5,-7,44:18.3
6,-7,44:18.3
7,-7,44:18.3
8,-7,44:18.3
9,-7,44:18.3
10,-7,44:18.3
11,-7,44:18.3
12,-7,44:18.3
13,-7,44:18.3
14,-7,44:18.3
15,-7,44:18.3
16,-7,44:18.3
-14,-6,44:18.3
-13,-6,44:18.3
-12,-6,44:17.3
-11,-6,44:18.3
-10,-6,44:18.3
-9,-6,44:17.3
-8,-6,44:18.3
-7,-6,44:18.3
-6,-6,44:18.3
-5,-6,44:18.3
-4,-6,44:18.3
-3,-6,44:18.3
-2,-6,44:18.3
-1,-6,44:18.3
0,-6,44:18.3
1,-6,44:17.3
2,-6,44:18.3
3,-6,44:18.3
4,-6,44:18.3
5,-6,44:18.3
6,-6,44:18.3
7,-6,44:18.3
8,-6,44:18.3
9,-6,44:18.3
10,-6,44:18.3
11,-6,44:18.3
12,-6,44:18.3
13,-6,44:18.3
14,-6,44:17.3
15,-6,44:18.3
16,-6,44:18.3
17,-6,44:18.3
-14,-5,44:18.3
-13,-5,44:18.3
-12,-5,44:18.3
-11,-5,44:18.3
-10,-5,44:18.3
-9,-5,44:18.3
-8,-5,44:18.3
-7,-5,44:18.3
-6,-5,44:18.3
-5,-5,44:17.3
-4,-5,44:18.3
-3,-5,44:18.3
-2,-5,44:18.3
-1,-5,44:18.3
0,-5,44:18.3
1,-5,44:17.3
2,-5,44:18.3
3,-5,44:18.3
4,-5,44:17.3
5,-5,44:18.3
6,-5,44:18.3
7,-5,44:17.3
8,-5,44:17.3
9,-5,44:18.3
10,-5,44:18.3
11,-5,44:18.3
12,-5,44:18.3
13,-5,44:18.3
14,-5,44:18.3
15,-5,44:18.3
16,-5,44:18.3
17,-5,44:18.3
18,-5,44:18.3
-14,-4,44:18.3
-13,-4,44:18.3
-12,-4,44:17.3
-11,-4,44:18.3
-10,-4,44:18.3
-9,-4,44:18.3
-8,-4,44:18.3
-7,-4,44:17.3
-6,-4,44:18.3
-5,-4,44:18.3
-4,-4,44:17.3
-3,-4,44:17.3
-2,-4,44:18.3
-1,-4,44:17.3
0,-4,44:17.3
1,-4,44:17.3
2,-4,44:17.3
3,-4,44:18.3
4,-4,44:18.3
5,-4,44:17.3
6,-4,44:18.3
7,-4,44:18.3
8,-4,44:18.3
9,-4,44:17.3
10,-4,44:18.3
11,-4,44:18.3
12,-4,44:18.3
13,-4,44:18.3
14,-4,44:18.3
15,-4,44:18.3
16,-4,44:17.3
17,-4,44:18.3
18,-4,44:18.3
-18,-3,44:18.3
-17,-3,44:18.3
-16,-3,44:18.3
-14,-3,44:18.3
-13,-3,44:18.3
-12,-3,44:18.3
-11,-3,44:18.3
-10,-3,44:18.3
-9,-3,44:18.3
-8,-3,44:18.3
-7,-3,44:18.3
-6,-3,44:17.3
-5,-3,44:18.3
-4,-3,44:18.3
-3,-3,44:18.3
-2,-3,44:18.3
-1,-3,44:18.3
0,-3,44:17.3
1,-3,44:18.3
2,-3,44:18.3
3,-3,44:18.3
4,-3,44:18.3
5,-3,44:18.3
6,-3,44:18.3
7,-3,44:18.3
8,-3,44:18.3
9,-3,44:18.3
10,-3,44:18.3
11,-3,44:18.3
12,-3,44:18.3
13,-3,44:18.3
14,-3,44:18.3
15,-3,44:18.3
16,-3,44:18.3
17,-3,44:18.3
18,-3,44:18.3
-19,-2,44:18.3
-18,-2,44:18.3
-17,-2,44:18.3
-16,-2,44:18.3
-15,-2,44:18.3
-13,-2,44:18.3
-12,-2,44:18.3
-11,-2,44:18.3
-10,-2,44:18.3
-9,-2,44:18.3
-8,-2,44:18.3
-7,-2,44:18.3
-6,-2,44:18.3
-5,-2,44:18.3
-4,-2,44:17.3
-3,-2,44:18.3
-2,-2,44:18.3
-1,-2,44:18.3
0,-2,44:17.3
1,-2,44:18.3
2,-2,44:18.3
3,-2,44:18.3
4,-2,44:18.3
5,-2,44:18.3
6,-2,44:18.3
7,-2,44:17.3
8,-2,44:18.3
9,-2,44:18.3
10,-2,44:17.3
11,-2,44:18.3
12,-2,44:18.3
13,-2,44:18.3
14,-2,44:17.3
15,-2,44:18.3
16,-2,44:18.3
17,-2,44:18.3
19,-2,44:18.3
-19,-1,44:18.3
-18,-1,44:18.3
-17,-1,44:17.3
-16,-1,44:18.3
-15,-1,44:18.3
-11,-1,44:18.3
-10,-1,44:18.3
-9,-1,44:17.3
-8,-1,44:17.3
-7,-1,44:18.3
-6,-1,44:18.3
-5,-1,44:18.3
-4,-1,44:18.3
-3,-1,44:18.3
-2,-1,44:17.3
-1,-1,44:18.3
0,-1,44:17.3
1,-1,44:17.3
3,-1,44:17.3
4,-1,44:18.3
5,-1,44:18.3
6,-1,44:18.3
7,-1,44:18.3
8,-1,44:17.3
9,-1,44:18.3
10,-1,44:18.3
11,-1,44:18.3
12,-1,44:18.3
13,-1,44:17.3
14,-1,44:18.3
15,-1,44:18.3
16,-1,44:18.3
18,-1,44:18.3
19,-1,44:18.3
20,-1,44:18.3
-19,0,44:18.3
-18,0,44:18.3
-17,0,44:18.3
-16,0,44:18.3
-15,0,44:18.3
-11,0,44:18.3
-10,0,44:18.3
-9,0,44:18.3
-8,0,44:18.3
-7,0,44:18.3
-6,0,44:18.3
-5,0,44:17.3
-4,0,44:18.3
-3,0,44:18.3
-2,0,44:18.3
-1,0,44:17.3
0,0,44:18.3
1,0,44:18.3
2,0,44:18.3
4,0,44:18.3
5,0,44:18.3
6,0,44:17.3
7,0,44:17.3
8,0,44:18.3
9,0,44:17.3
10,0,44:18.3
11,0,44:18.3
12,0,44:18.3
13,0,44:18.3
14,0,44:18.3
15,0,44:18.3
17,0,44:18.3
18,0,44:18.3
19,0,44:18.3
20,0,44:18.3
21,0,44:18.3
-18,1,44:18.3
-17,1,44:18.3
-16,1,44:18.3
-10,1,44:18.3
-9,1,44:18.3
-8,1,44:18.3
-7,1,44:18.3
-6,1,44:17.3
-5,1,44:17.3
-4,1,44:18.3
-3,1,44:18.3
-2,1,44:18.3
-1,1,44:18.3
0,1,44:18.3
1,1,44:18.3
2,1,44:18.3
3,1,44:18.3
4,1,44:18.3
5,1,44:18.3
6,1,44:18.3
7,1,44:18.3
8,1,44:17.3
9,1,44:18.3
10,1,44:18.3
11,1,44:18.3
12,1,44:18.3
13,1,44:18.3
14,1,44:18.3
15,1,44:18.3
18,1,44:18.3
19,1,44:18.3
20,1,44:18.3
-11,2,44:18.3
-10,2,44:18.3
-9,2,44:18.3
-8,2,44:18.3
-7,2,44:17.3
-6,2,44:17.3
-5,2,44:18.3
-4,2,44:18.3
-3,2,44:18.3
-2,2,44:18.3
-1,2,44:18.3
0,2,44:17.3
1,2,44:18.3
2,2,44:18.3
3,2,44:18.3
4,2,44:18.3
5,2,44:17.3
6,2,44:18.3
7,2,44:18.3
8,2,44:18.3
9,2,44:18.3
10,2,44:18.3
12,2,44:18.3
13,2,44:18.3
14,2,44:18.3
19,2,44:18.3
-15,3,44:18.3
-10,3,44:18.3
-9,3,44:18.3
-8,3,44:18.3
-7,3,44:18.3
-6,3,44:18.3
-5,3,44:18.3
-4,3,44:18.3
-3,3,44:17.3
-2,3,44:18.3
-1,3,44:18.3
0,3,44:18.3
1,3,44:18.3
2,3,44:18.3
3,3,44:18.3
4,3,44:18.3
5,3,44:18.3
6,3,44:18.3
7,3,44:18.3
8,3,44:17.3
9,3,44:18.3
10,3,44:18.3
13,3,44:18.3
14,3,44:18.3
15,3,44:18.3
-16,4,44:18.3
-15,4,44:18.3
-14,4,44:18.3
-9,4,44:18.3
-8,4,44:18.3
-7,4,44:17.3
-6,4,44:18.3
-5,4,44:18.3
-4,4,44:18.3
-3,4,44:18.3
-2,4,44:18.3
-1,4,44:17.3
0,4,44:18.3
1,4,44:18.3
2,4,44:18.3
3,4,44:18.3
4,4,44:18.3
5,4,44:17.3
6,4,44:18.3
7,4,44:18.3
8,4,44:18.3
9,4,44:18.3
10,4,44:18.3
12,4,44:18.3
13,4,44:18.3
14,4,44:18.3
15,4,44:18.3
16,4,44:18.3
-17,5,44:18.3
-16,5,44:18.3
-15,5,44:18.3
-14,5,44:18.3
-13,5,44:18.3
-12,5,44:18.3
-9,5,44:18.3
-8,5,44:18.3
-7,5,44:18.3
-6,5,44:18.3
-5,5,44:18.3
-4,5,44:17.3
-3,5,44:18.3
-2,5,44:18.3
-1,5,44:18.3
0,5,44:18.3
1,5,44:18.3
2,5,44:17.3
3,5,44:18.3
4,5,44:18.3
5,5,44:17.3
6,5,44:18.3
7,5,44:18.3
8,5,44:18.3
9,5,44:18.3
10,5,44:18.3
11,5,44:18.3
12,5,44:18.3
13,5,44:18.3
14,5,44:17.3
15,5,44:18.3
16,5,44:18.3
-16,6,44:18.3
-15,6,44:18.3
-14,6,44:18.3
-13,6,44:18.3
-12,6,44:18.3
-11,6,44:18.3
-8,6,44:18.3
-7,6,44:18.3
-6,6,44:18.3
-5,6,44:18.3
-4,6,44:18.3
-3,6,44:18.3
-2,6,44:18.3
-1,6,44:18.3
0,6,44:18.3
1,6,44:18.3
2,6,44:17.3
3,6,44:18.3
4,6,44:18.3
5,6,44:17.3
6,6,44:18.3
7,6,44:18.3
8,6,44:17.3
9,6,44:18.3
10,6,44:18.3
11,6,44:18.3
12,6,44:18.3
13,6,44:18.3
14,6,44:18.3
15,6,44:18.3
16,6,44:18.3
-15,7,44:18.3
-14,7,44:18.3
-13,7,44:18.3
-12,7,44:18.3
-11,7,44:18.3
-10,7,44:18.3
-7,7,44:18.3
-6,7,44:18.3
-5,7,44:17.3
-4,7,44:18.3
-3,7,44:18.3
-2,7,44:18.3
-1,7,44:18.3
0,7,44:17.3
1,7,44:17.3
2,7,44:17.3
3,7,44:18.3
4,7,44:18.3
5,7,44:17.3
6,7,44:18.3
7,7,44:17.3
8,7,44:18.3
9,7,44:18.3
10,7,44:18.3
11,7,44:18.3
13,7,44:18.3
14,7,44:18.3
15,7,44:18.3
-13,8,44:18.3
-12,8,44:18.3
-11,8,44:18.3
-8,8,44:18.3
-7,8,44:18.3
-6,8,44:18.3
-5,8,44:18.3
-4,8,44:18.3
-3,8,44:18.3
-2,8,44:18.3
-1,8,44:18.3
0,8,44:18.3
1,8,44:18.3
2,8,44:18.3
3,8,44:18.3
4,8,44:18.3
5,8,44:18.3
6,8,44:18.3
7,8,44:18.3
8,8,44:18.3
9,8,44:18.3
10,8,44:18.3
-12,9,44:18.3
-9,9,44:18.3
-8,9,44:18.3
-7,9,44:18.3
-6,9,44:18.3
-5,9,44:18.3
-4,9,44:18.3
-3,9,44:18.3
-2,9,44:18.3
-1,9,44:18.3
0,9,44:18.3
1,9,44:18.3
2,9,44:18.3
3,9,44:18.3
4,9,44:17.3
5,9,44:18.3
6,9,44:18.3
7,9,44:18.3
8,9,44:18.3
9,9,44:18.3
11,9,44:18.3
-10,10,44:18.3
-9,10,44:18.3
-8,10,44:18.3
-7,10,44:18.3
-6,10,44:18.3
-5,10,44:18.3
-4,10,44:18.3
-3,10,44:18.3
-2,10,44:18.3
-1,10,44:18.3
0,10,44:18.3
1,10,44:18.3
2,10,44:18.3
3,10,44:17.3
4,10,44:18.3
5,10,44:18.3
6,10,44:18.3
7,10,44:18.3
8,10,44:18.3
9,10,44:18.3
10,10,44:18.3
11,10,44:18.3
12,10,44:18.3
-10,11,44:18.3
-9,11,44:18.3
-8,11,44:18.3
-7,11,44:18.3
-6,11,44:18.3
-5,11,44:18.3
-4,11,44:18.3
-3,11,44:18.3
-2,11,44:18.3
-1,11,44:18.3
0,11,44:17.3
1,11,44:18.3
2,11,44:18.3
3,11,44:18.3
4,11,44:18.3
5,11,44:18.3
6,11,44:18.3
7,11,44:18.3
8,11,44:17.3
9,11,44:18.3
10,11,44:18.3
11,11,44:18.3
12,11,44:18.3
13,11,44:18.3
-11,12,44:18.3
-10,12,44:18.3
-9,12,44:18.3
-8,12,44:18.3
-7,12,44:18.3
-6,12,44:18.3
-5,12,44:18.3
-2,12,44:18.3
-1,12,44:18.3
0,12,44:18.3
1,12,44:18.3
2,12,44:18.3
3,12,44:18.3
4,12,44:18.3
5,12,44:18.3
6,12,44:18.3
7,12,44:18.3
8,12,44:18.3
9,12,44:18.3
10,12,44:18.3
11,12,44:18.3
12,12,44:18.3
-10,13,44:18.3
-9,13,44:18.3
-8,13,44:18.3
-6,13,44:18.3
-1,13,44:18.3
0,13,44:18.3
1,13,44:18.3
2,13,44:18.3
3,13,44:18.3
4,13,44:18.3
5,13,44:17.3
6,13,44:18.3
7,13,44:18.3
8,13,44:18.3
9,13,44:18.3
10,13,44:18.3
11,13,44:18.3
-9,14,44:18.3
0,14,44:18.3
1,14,44:18.3
2,14,44:17.3
3,14,44:18.3
4,14,44:18.3
5,14,44:18.3
6,14,44:18.3
7,14,44:18.3
10,14,44:18.3
0,15,44:18.3
1,15,44:18.3
2,15,44:18.3
3,15,44:18.3
4,15,44:18.3
5,15,44:18.3
6,15,44:18.3
1,16,44:18.3
2,16,44:18.3
3,16,44:18.3
-5,-16,45:18.3
-4,-16,45:18.3
-3,-16,45:18.3
7,-16,45:18.3
8,-16,45:18.3
9,-16,45:18.3
-6,-15,45:18.3
-5,-15,45:18.3
-4,-15,45:18.3
-3,-15,45:18.3
-2,-15,45:18.3
6,-15,45:18.3
7,-15,45:18.3
8,-15,45:18.3
9,-15,45:18.3
10,-15,45:18.3
-6,-14,45:18.3
-5,-14,45:18.3
-4,-14,45:17.3
-3,-14,45:18.3
-2,-14,45:18.3
6,-14,45:18.3
7,-14,45:18.3
8,-14,45:17.3
9,-14,45:18.3
10,-14,45:18.3
-6,-13,45:18.3
-5,-13,45:18.3
-4,-13,45:18.3
-3,-13,45:18.3
-2,-13,45:17.3
1,-13,45:18.3
6,-13,45:18.3
7,-13,45:18.3
8,-13,45:18.3
9,-13,45:18.3
10,-13,45:18.3
-5,-12,45:18.3
-4,-12,45:18.3
-3,-12,45:18.3
-2,-12,45:18.3
-1,-12,45:18.3
0,-12,45:18.3
1,-12,45:18.3
2,-12,45:18.3
5,-12,45:18.3
7,-12,45:18.3
8,-12,45:18.3
9,-12,45:18.3
10,-12,45:18.3
-4,-11,45:18.3
-3,-11,45:18.3
-2,-11,45:18.3
-1,-11,45:18.3
0,-11,45:18.3
1,-11,45:18.3
2,-11,45:18.3
3,-11,45:18.3
4,-11,45:18.3
5,-11,45:18.3
6,-11,45:18.3
7,-11,45:18.3
8,-11,45:18.3
9,-11,45:18.3
10,-11,45:18.3
11,-11,45:18.3
-3,-10,45:18.3
-1,-10,45:18.3
0,-10,45:18.3
1,-10,45:18.3
2,-10,45:18.3
3,-10,45:18.3
4,-10,45:18.3
5,-10,45:18.3
6,-10,45:18.3
7,-10,45:18.3
8,-10,45:18.3
9,-10,45:17.3
10,-10,45:18.3
11,-10,45:18.3
12,-10,45:18.3
-6,-9,45:18.3
-5,-9,45:18.3
-4,-9,45:18.3
-3,-9,45:18.3
-1,-9,45:18.3
0,-9,45:18.3
1,-9,45:17.3
2,-9,45:18.3
3,-9,45:18.3
4,-9,45:18.3
5,-9,45:18.3
6,-9,45:18.3
7,-9,45:18.3
8,-9,45:17.3
9,-9,45:18.3
10,-9,45:17.3
11,-9,45:18.3
12,-9,45:18.3
-12,-8,45:18.3
-11,-8,45:18.3
-10,-8,45:18.3
-9,-8,45:18.3
-7,-8,45:18.3
-6,-8,45:18.3
-5,-8,45:18.3
-4,-8,45:18.3
-3,-8,45:18.3
-2,-8,45:18.3
-1,-8,45:18.3
0,-8,45:18.3
1,-8,45:17.3
2,-8,45:18.3
3,-8,45:18.3
4,-8,45:18.3
5,-8,45:17.3
6,-8,45:18.3
7,-8,45:18.3
8,-8,45:18.3
9,-8,45:18.3
10,-8,45:18.3
11,-8,45:18.3
12,-8,45:18.3
14,-8,45:18.3
-13,-7,45:18.3
-12,-7,45:18.3
-11,-7,45:18.3
-10,-7,45:18.3
-9,-7,45:18.3
-8,-7,45:18.3
-7,-7,45:18.3
-6,-7,45:18.3
-5,-7,45:18.3
-4,-7,45:17.3
-3,-7,45:18.3
-2,-7,45:18.3
-1,-7,45:18.3
0,-7,45:18.3
1,-7,45:17.3
2,-7,45:18.3
3,-7,45:18.3
4,-7,45:18.3
5,-7,45:18.3
6,-7,45:18.3
7,-7,45:18.3
8,-7,45:18.3
9,-7,45:18.3
10,-7,45:18.3
11,-7,45:18.3
13,-7,45:18.3
14,-7,45:18.3
15,-7,45:18.3
-14,-6,45:18.3
-13,-6,45:18.3
-12,-6,45:18.3
-11,-6,45:18.3
-10,-6,45:17.3
-9,-6,45:18.3
-8,-6,45:18.3
-7,-6,45:18.3
-6,-6,45:18.3
-5,-6,45:17.3
-4,-6,45:17.3
-3,-6,45:18.3
-2,-6,45:18.3
-1,-6,45:17.3
0,-6,45:18.3
1,-6,45:18.3
2,-6,45:18.3
3,-6,45:18.3
4,-6,45:18.3
5,-6,45:18.3
6,-6,45:18.3
7,-6,45:17.3
8,-6,45:17.3
9,-6,45:18.3
10,-6,45:18.3
12,-6,45:18.3
13,-6,45:18.3
14,-6,45:18.3
15,-6,45:18.3
16,-6,45:18.3
-13,-5,45:18.3
-12,-5,45:18.3
-11,-5,45:18.3
-10,-5,45:18.3
-9,-5,45:18.3
-8,-5,45:18.3
-7,-5,45:18.3
-6,-5,45:17.3
-5,-5,45:17.3
-4,-5,45:18.3
-3,-5,45:18.3
-2,-5,45:17.3
-1,-5,45:17.3
0,-5,45:18.3
1,-5,45:17.3
2,-5,45:18.3
3,-5,45:18.3
4,-5,45:17.3
5,-5,45:18.3
6,-5,45:18.3
7,-5,45:18.3
8,-5,45:18.3
9,-5,45:18.3
10,-5,45:18.3
13,-5,45:18.3
14,-5,45:18.3
15,-5,45:18.3
16,-5,45:18.3
17,-5,45:18.3
-14,-4,45:18.3
-13,-4,45:18.3
-12,-4,45:18.3
-11,-4,45:18.3
-10,-4,45:18.3
-9,-4,45:18.3
-8,-4,45:18.3
-7,-4,45:18.3
-6,-4,45:18.3
-5,-4,45:18.3
-4,-4,45:18.3
-3,-4,45:17.3
-2,-4,45:18.3
-1,-4,45:17.3
0,-4,45:18.3
1,-4,45:18.3
2,-4,45:17.3
3,-4,45:18.3
4,-4,45:18.3
5,-4,45:18.3
6,-4,45:18.3
7,-4,45:18.3
8,-4,45:18.3
9,-4,45:18.3
10,-4,45:18.3
11,-4,45:18.3
14,-4,45:18.3
15,-4,45:18.3
16,-4,45:18.3
17,-4,45:18.3
18,-4,45:18.3
-17,-3,45:18.3
-13,-3,45:18.3
-12,-3,45:18.3
-11,-3,45:18.3
-9,-3,45:18.3
-8,-3,45:18.3
-7,-3,45:17.3
-6,-3,45:17.3
-5,-3,45:18.3
-4,-3,45:18.3
-3,-3,45:18.3
-2,-3,45:18.3
-1,-3,45:18.3
0,-3,45:18.3
1,-3,45:18.3
2,-3,45:18.3
3,-3,45:18.3
4,-3,45:17.3
5,-3,45:18.3
6,-3,45:17.3
7,-3,45:17.3
8,-3,45:18.3
9,-3,45:18.3
10,-3,45:18.3
11,-3,45:18.3
13,-3,45:18.3
14,-3,45:18.3
15,-3,45:18.3
16,-3,45:18.3
17,-3,45:18.3
-18,-2,45:18.3
-17,-2,45:18.3
-16,-2,45:18.3
-12,-2,45:18.3
-10,-2,45:18.3
-9,-2,45:18.3
-8,-2,45:18.3
-7,-2,45:18.3
-6,-2,45:18.3
-5,-2,45:18.3
-4,-2,45:18.3
-3,-2,45:18.3
-2,-2,45:18.3
-1,-2,45:17.3
1,-2,45:17.3
2,-2,45:18.3
3,-2,45:18.3
4,-2,45:18.3
5,-2,45:18.3
6,-2,45:18.3
7,-2,45:18.3
8,-2,45:17.3
9,-2,45:18.3
10,-2,45:18.3
11,-2,45:18.3
12,-2,45:18.3
13,-2,45:18.3
14,-2,45:18.3
15,-2,45:18.3
16,-2,45:18.3
-19,-1,45:18.3
-18,-1,45:18.3
-17,-1,45:18.3
-16,-1,45:18.3
-15,-1,45:18.3
-11,-1,45:18.3
-10,-1,45:18.3
-9,-1,45:18.3
-8,-1,45:17.3
-7,-1,45:17.3
-6,-1,45:17.3
-5,-1,45:18.3
-4,-1,45:18.3
-3,-1,45:17.3
-2,-1,45:18.3
-1,-1,45:17.3
0,-1,45:17.3
1,-1,45:17.3
2,-1,45:18.3
3,-1,45:18.3
4,-1,45:17.3
5,-1,45:17.3
6,-1,45:18.3
7,-1,45:18.3
8,-1,45:18.3
9,-1,45:18.3
10,-1,45:18.3
11,-1,45:18.3
12,-1,45:18.3
13,-1,45:18.3
14,-1,45:18.3
15,-1,45:18.3
-18,0,45:18.3
-17,0,45:18.3
-16,0,45:18.3
-10,0,45:18.3
-9,0,45:18.3
-8,0,45:17.3
-7,0,45:18.3
-6,0,45:17.3
-5,0,45:18.3
-4,0,45:18.3
-3,0,45:18.3
-2,0,45:18.3
-1,0,45:18.3
0,0,45:18.3
1,0,45:18.3
2,0,45:18.3
3,0,45:18.3
4,0,45:18.3
5,0,45:18.3
6,0,45:18.3
7,0,45:18.3
8,0,45:18.3
9,0,45:18.3
10,0,45:18.3
11,0,45:18.3
12,0,45:18.3
13,0,45:18.3
14,0,45:18.3
-17,1,45:18.3
-10,1,45:18.3
-9,1,45:18.3
-8,1,45:18.3
-7,1,45:18.3
-6,1,45:18.3
-5,1,45:18.3
-4,1,45:17.3
-3,1,45:18.3
-2,1,45:18.3
-1,1,45:18.3
0,1,45:18.3
1,1,45:18.3
2,1,45:18.3
3,1,45:18.3
4,1,45:18.3
5,1,45:18.3
6,1,45:18.3
7,1,45:17.3
8,1,45:18.3
9,1,45:18.3
10,1,45:18.3
11,1,45:18.3
12,1,45:18.3
13,1,45:18.3
14,1,45:18.3
15,1,45:18.3
16,1,45:18.3
17,1,45:18.3
-14,2,45:18.3
-13,2,45:18.3
-12,2,45:18.3
-10,2,45:18.3
-9,2,45:18.3
-8,2,45:18.3
-7,2,45:18.3
-6,2,45:17.3
-5,2,45:17.3
-4,2,45:18.3
-3,2,45:18.3
-2,2,45:18.3
-1,2,45:18.3
0,2,45:18.3
1,2,45:17.3
2,2,45:18.3
3,2,45:18.3
4,2,45:18.3
5,2,45:18.3
6,2,45:18.3
7,2,45:18.3
8,2,45:18.3
9,2,45:18.3
10,2,45:18.3
11,2,45:18.3
12,2,45:17.3
13,2,45:18.3
14,2,45:18.3
15,2,45:18.3
16,2,45:18.3
17,2,45:18.3
18,2,45:18.3
-15,3,45:18.3
-14,3,45:18.3
-13,3,45:18.3
-12,3,45:18.3
-11,3,45:18.3
-10,3,45:18.3
-9,3,45:18.3
-8,3,45:18.3
-7,3,45:18.3
-6,3,45:17.3
-5,3,45:18.3
-4,3,45:18.3
-3,3,45:17.3
-2,3,45:18.3
-1,3,45:18.3
0,3,45:17.3
1,3,45:18.3
2,3,45:18.3
3,3,45:18.3
4,3,45:18.3
5,3,45:17.3
6,3,45:18.3
7,3,45:18.3
8,3,45:18.3
9,3,45:17.3
10,3,45:18.3
11,3,45:18.3
12,3,45:18.3
13,3,45:18.3
14,3,45:18.3
15,3,45:18.3
16,3,45:17.3
17,3,45:18.3
18,3,45:18.3
-15,4,45:18.3
-14,4,45:18.3
-13,4,45:17.3
-12,4,45:18.3
-11,4,45:18.3
-10,4,45:18.3
-9,4,45:17.3
-8,4,45:18.3
-7,4,45:18.3
-6,4,45:18.3
-5,4,45:17.3
-4,4,45:18.3
-3,4,45:17.3
-2,4,45:17.3
-1,4,45:18.3
0,4,45:18.3
1,4,45:18.3
2,4,45:18.3
3,4,45:18.3
4,4,45:18.3
5,4,45:18.3
6,4,45:18.3
7,4,45:18.3
8,4,45:18.3
9,4,45:18.3
11,4,45:18.3
12,4,45:18.3
13,4,45:18.3
14,4,45:18.3
15,4,45:18.3
16,4,45:18.3
17,4,45:18.3
18,4,45:18.3
-15,5,45:18.3
-14,5,45:18.3
-13,5,45:18.3
-12,5,45:18.3
-11,5,45:18.3
-10,5,45:18.3
-9,5,45:18.3
-8,5,45:18.3
-7,5,45:17.3
-6,5,45:18.3
-5,5,45:18.3
-4,5,45:18.3
-3,5,45:18.3
-2,5,45:18.3
-1,5,45:18.3
0,5,45:17.3
1,5,45:18.3
2,5,45:18.3
3,5,45:18.3
4,5,45:18.3
5,5,45:17.3
6,5,45:18.3
7,5,45:18.3
8,5,45:18.3
9,5,45:18.3
12,5,45:18.3
13,5,45:18.3
14,5,45:18.3
15,5,45:18.3
16,5,45:18.3
17,5,45:18.3
-14,6,45:18.3
-13,6,45:18.3
-12,6,45:18.3
-10,6,45:18.3
-9,6,45:18.3
-8,6,45:18.3
-7,6,45:18.3
-6,6,45:18.3
-5,6,45:18.3
-4,6,45:18.3
-3,6,45:18.3
-2,6,45:18.3
-1,6,45:18.3
0,6,45:18.3
1,6,45:17.3
2,6,45:17.3
3,6,45:18.3
4,6,45:18.3
5,6,45:18.3
6,6,45:17.3
7,6,45:18.3
8,6,45:18.3
9,6,45:18.3
10,6,45:18.3
13,6,45:18.3
14,6,45:18.3
15,6,45:18.3
-9,7,45:18.3
-8,7,45:18.3
-7,7,45:18.3
-6,7,45:18.3
-5,7,45:18.3
-4,7,45:18.3
-3,7,45:18.3
-2,7,45:17.3
-1,7,45:18.3
0,7,45:18.3
1,7,45:18.3
2,7,45:18.3
3,7,45:18.3
4,7,45:18.3
5,7,45:18.3
6,7,45:18.3
7,7,45:18.3
8,7,45:18.3
9,7,45:18.3
14,7,45:18.3
-10,8,45:18.3
-9,8,45:18.3
-8,8,45:18.3
-7,8,45:17.3
-6,8,45:18.3
-5,8,45:18.3
-4,8,45:18.3
-3,8,45:18.3
-2,8,45:18.3
-1,8,45:18.3
0,8,45:18.3
1,8,45:18.3
2,8,45:17.3
3,8,45:18.3
4,8,45:17.3
5,8,45:18.3
6,8,45:18.3
7,8,45:18.3
8,8,45:18.3
-10,9,45:18.3
-9,9,45:18.3
-8,9,45:17.3
-7,9,45:18.3
-6,9,45:18.3
-5,9,45:18.3
-3,9,45:18.3
-2,9,45:18.3
-1,9,45:18.3
0,9,45:18.3
1,9,45:18.3
2,9,45:17.3
3,9,45:18.3
4,9,45:18.3
5,9,45:18.3
6,9,45:18.3
7,9,45:18.3
8,9,45:18.3
-10,10,45:18.3
-9,10,45:18.3
-8,10,45:18.3
-7,10,45:18.3
-6,10,45:18.3
-1,10,45:18.3
0,10,45:18.3
1,10,45:18.3
2,10,45:18.3
3,10,45:18.3
4,10,45:18.3
5,10,45:18.3
6,10,45:18.3
7,10,45:18.3
8,10,45:18.3
9,10,45:18.3
-9,11,45:18.3
-8,11,45:18.3
-7,11,45:18.3
-3,11,45:18.3
-2,11,45:18.3
-1,11,45:18.3
0,11,45:18.3
1,11,45:18.3
2,11,45:18.3
3,11,45:17.3
4,11,45:17.3
5,11,45:17.3
6,11,45:18.3
7,11,45:18.3
8,11,45:18.3
9,11,45:18.3
10,11,45:18.3
-4,12,45:18.3
-3,12,45:18.3
-2,12,45:18.3
-1,12,45:18.3
0,12,45:18.3
1,12,45:18.3
2,12,45:18.3
3,12,45:18.3
4,12,45:18.3
5,12,45:18.3
6,12,45:18.3
7,12,45:18.3
8,12,45:18.3
9,12,45:18.3
-4,13,45:18.3
-3,13,45:18.3
-2,13,45:17.3
-1,13,45:18.3
0,13,45:18.3
1,13,45:18.3
2,13,45:18.3
3,13,45:18.3
4,13,45:18.3
5,13,45:18.3
6,13,45:18.3
7,13,45:18.3
8,13,45:18.3
-4,14,45:18.3
-3,14,45:18.3
-2,14,45:18.3
-1,14,45:18.3
0,14,45:18.3
1,14,45:18.3
2,14,45:18.3
3,14,45:18.3
4,14,45:18.3
5,14,45:18.3
6,14,45:18.3
-3,15,45:18.3
-2,15,45:18.3
-1,15,45:18.3
1,15,45:18.3
2,15,45:18.3
3,15,45:18.3
5,15,45:18.3
2,16,45:18.3
-4,-16,46:18.3
-3,-16,46:18.3
-2,-16,46:18.3
8,-16,46:18.3
-5,-15,46:18.3
-4,-15,46:18.3
-3,-15,46:18.3
-2,-15,46:18.3
-1,-15,46:18.3
7,-15,46:18.3
8,-15,46:18.3
9,-15,46:18.3
-6,-14,46:18.3
-5,-14,46:18.3
-4,-14,46:18.3
-3,-14,46:17.3
-2,-14,46:18.3
-1,-14,46:18.3
0,-14,46:18.3
6,-14,46:18.3
7,-14,46:18.3
8,-14,46:18.3
9,-14,46:18.3
10,-14,46:18.3
-10,-13,46:18.3
-9,-13,46:18.3
-8,-13,46:18.3
-5,-13,46:18.3
-4,-13,46:18.3
-3,-13,46:18.3
-2,-13,46:17.3
-1,-13,46:18.3
0,-13,46:18.3
7,-13,46:18.3
8,-13,46:18.3
9,-13,46:18.3
-11,-12,46:18.3
-10,-12,46:18.3
-9,-12,46:18.3
-8,-12,46:18.3
-7,-12,46:18.3
-4,-12,46:18.3
-3,-12,46:18.3
-2,-12,46:18.3
-1,-12,46:18.3
0,-12,46:18.3
1,-12,46:18.3
2,-12,46:18.3
3,-12,46:18.3
4,-12,46:18.3
5,-12,46:18.3
8,-12,46:18.3
9,-12,46:18.3
-11,-11,46:18.3
-10,-11,46:18.3
-9,-11,46:17.3
-8,-11,46:18.3
-7,-11,46:18.3
-6,-11,46:18.3
-5,-11,46:18.3
-4,-11,46:18.3
-3,-11,46:18.3
-2,-11,46:18.3
-1,-11,46:18.3
0,-11,46:18.3
1,-11,46:18.3
2,-11,46:18.3
3,-11,46:18.3
4,-11,46:18.3
5,-11,46:18.3
6,-11,46:18.3
8,-11,46:18.3
9,-11,46:18.3
10,-11,46:18.3
-11,-10,46:18.3
-10,-10,46:18.3
-9,-10,46:18.3
-8,-10,46:18.3
-7,-10,46:18.3
-6,-10,46:18.3
-5,-10,46:18.3
-4,-10,46:18.3
-3,-10,46:18.3
-2,-10,46:18.3
-1,-10,46:18.3
0,-10,46:18.3
1,-10,46:17.3
2,-10,46:18.3
3,-10,46:17.3
4,-10,46:17.3
5,-10,46:18.3
6,-10,46:18.3
7,-10,46:18.3
8,-10,46:18.3
9,-10,46:18.3
10,-10,46:18.3
11,-10,46:18.3
-11,-9,46:18.3
-10,-9,46:18.3
-9,-9,46:18.3
-8,-9,46:18.3
-7,-9,46:18.3
-6,-9,46:18.3
-5,-9,46:17.3
-4,-9,46:18.3
-3,-9,46:18.3
-2,-9,46:18.3
-1,-9,46:18.3
0,-9,46:18.3
1,-9,46:18.3
2,-9,46:18.3
3,-9,46:18.3
4,-9,46:18.3
5,-9,46:18.3
6,-9,46:18.3
7,-9,46:18.3
8,-9,46:18.3
9,-9,46:18.3
10,-9,46:18.3
11,-9,46:18.3
12,-9,46:18.3
-12,-8,46:18.3
-11,-8,46:18.3
-10,-8,46:18.3
-9,-8,46:18.3
-8,-8,46:18.3
-7,-8,46:18.3
-6,-8,46:17.3
-5,-8,46:18.3
-4,-8,46:18.3
-3,-8,46:18.3
-2,-8,46:17.3
-1,-8,46:18.3
0,-8,46:18.3
1,-8,46:18.3
2,-8,46:17.3
3,-8,46:17.3
4,-8,46:17.3
5,-8,46:18.3
6,-8,46:18.3
7,-8,46:17.3
8,-8,46:18.3
9,-8,46:18.3
10,-8,46:18.3
11,-8,46:18.3
-12,-7,46:18.3
-11,-7,46:18.3
-10,-7,46:17.3
-9,-7,46:18.3
-8,-7,46:18.3
-7,-7,46:17.3
-6,-7,46:18.3
-5,-7,46:17.3
-4,-7,46:18.3
-3,-7,46:18.3
-2,-7,46:18.3
-1,-7,46:18.3
0,-7,46:17.3
1,-7,46:18.3
2,-7,46:18.3
3,-7,46:18.3
4,-7,46:18.3
5,-7,46:17.3
6,-7,46:18.3
7,-7,46:18.3
8,-7,46:18.3
9,-7,46:17.3
10,-7,46:18.3
11,-7,46:18.3
-12,-6,46:18.3
-11,-6,46:18.3
-10,-6,46:18.3
-9,-6,46:18.3
-8,-6,46:18.3
-7,-6,46:18.3
-6,-6,46:18.3
-5,-6,46:18.3
-4,-6,46:18.3
-3,-6,46:18.3
-2,-6,46:17.3
-1,-6,46:17.3
0,-6,46:18.3
1,-6,46:17.3
2,-6,46:18.3
3,-6,46:17.3
4,-6,46:18.3
5,-6,46:18.3
6,-6,46:18.3
7,-6,46:18.3
8,-6,46:18.3
9,-6,46:18.3
10,-6,46:18.3
11,-6,46:18.3
-15,-5,46:18.3
-14,-5,46:18.3
-13,-5,46:18.3
-11,-5,46:18.3
-10,-5,46:18.3
-9,-5,46:18.3
-8,-5,46:17.3
-7,-5,46:17.3
-6,-5,46:18.3
-5,-5,46:18.3
-4,-5,46:18.3
-3,-5,46:18.3
-2,-5,46:17.3
-1,-5,46:17.3
0,-5,46:18.3
1,-5,46:17.3
2,-5,46:18.3
3,-5,46:18.3
4,-5,46:18.3
5,-5,46:18.3
6,-5,46:17.3
7,-5,46:18.3
8,-5,46:18.3
9,-5,46:18.3
10,-5,46:18.3
12,-5,46:18.3
13,-5,46:18.3
14,-5,46:18.3
-16,-4,46:18.3
-15,-4,46:18.3
-14,-4,46:18.3
-13,-4,46:18.3
-12,-4,46:18.3
-10,-4,46:18.3
-9,-4,46:18.3
-8,-4,46:17.3
-7,-4,46:18.3
-6,-4,46:18.3
-5,-4,46:18.3
-4,-4,46:18.3
-3,-4,46:18.3
-2,-4,46:18.3
-1,-4,46:17.3
0,-4,46:18.3
1,-4,46:18.3
2,-4,46:18.3
3,-4,46:18.3
4,-4,46:18.3
5,-4,46:17.3
6,-4,46:17.3
7,-4,46:18.3
8,-4,46:18.3
9,-4,46:18.3
10,-4,46:18.3
11,-4,46:18.3
12,-4,46:18.3
13,-4,46:18.3
14,-4,46:18.3
15,-4,46:18.3
-16,-3,46:18.3
-15,-3,46:18.3
-14,-3,46:17.3
-13,-3,46:18.3
-12,-3,46:18.3
-11,-3,46:18.3
-10,-3,46:18.3
-9,-3,46:18.3
-8,-3,46:18.3
-7,-3,46:18.3
-6,-3,46:18.3
-5,-3,46:18.3
-4,-3,46:18.3
-3,-3,46:18.3
-2,-3,46:17.3
-1,-3,46:18.3
0,-3,46:18.3
1,-3,46:17.3
2,-3,46:18.3
3,-3,46:18.3
4,-3,46:18.3
5,-3,46:18.3
6,-3,46:18.3
7,-3,46:18.3
8,-3,46:18.3
9,-3,46:18.3
10,-3,46:18.3
11,-3,46:18.3
12,-3,46:18.3
13,-3,46:17.3
14,-3,46:18.3
15,-3,46:18.3
-16,-2,46:18.3
-15,-2,46:18.3
-14,-2,46:18.3
-13,-2,46:18.3
-12,-2,46:18.3
-11,-2,46:18.3
-10,-2,46:18.3
-9,-2,46:18.3
-8,-2,46:17.3
-7,-2,46:18.3
-6,-2,46:18.3
-5,-2,46:17.3
-4,-2,46:18.3
-3,-2,46:18.3
-2,-2,46:18.3
-1,-2,46:18.3
0,-2,46:18.3
1,-2,46:18.3
2,-2,46:18.3
3,-2,46:18.3
4,-2,46:18.3
5,-2,46:18.3
6,-2,46:18.3
7,-2,46:18.3
8,-2,46:18.3
9,-2,46:17.3
10,-2,46:18.3
11,-2,46:18.3
12,-2,46:18.3
13,-2,46:18.3
14,-2,46:18.3
15,-2,46:18.3
-15,-1,46:18.3
-14,-1,46:18.3
-13,-1,46:17.3
-12,-1,46:18.3
-11,-1,46:17.3
-10,-1,46:18.3
-9,-1,46:17.3
-8,-1,46:18.3
-7,-1,46:18.3
-6,-1,46:18.3
-5,-1,46:17.3
-4,-1,46:17.3
-3,-1,46:18.3
-2,-1,46:17.3
-1,-1,46:17.3
0,-1,46:18.3
1,-1,46:18.3
2,-1,46:18.3
3,-1,46:18.3
4,-1,46:18.3
5,-1,46:17.3
6,-1,46:18.3
7,-1,46:18.3
8,-1,46:18.3
9,-1,46:18.3
10,-1,46:18.3
11,-1,46:18.3
12,-1,46:18.3
13,-1,46:18.3
14,-1,46:18.3
15,-1,46:18.3
-15,0,46:18.3
-14,0,46:18.3
-13,0,46:18.3
-12,0,46:18.3
-11,0,46:18.3
-10,0,46:18.3
-9,0,46:18.3
-8,0,46:18.3
-7,0,46:17.3
-6,0,46:17.3
-5,0,46:18.3
-4,0,46:18.3
-3,0,46:18.3
-2,0,46:18.3
-1,0,46:18.3
0,0,46:17.3
1,0,46:18.3
2,0,46:18.3
3,0,46:17.3
4,0,46:18.3
5,0,46:18.3
6,0,46:18.3
7,0,46:18.3
8,0,46:18.3
9,0,46:18.3
10,0,46:17.3
11,0,46:18.3
12,0,46:18.3
13,0,46:17.3
14,0,46:18.3
15,0,46:18.3
-14,1,46:18.3
-13,1,46:18.3
-12,1,46:18.3
-11,1,46:18.3
-10,1,46:18.3
-9,1,46:18.3
-8,1,46:18.3
-7,1,46:18.3
-6,1,46:17.3
-5,1,46:18.3
-4,1,46:18.3
-3,1,46:18.3
-2,1,46:18.3
-1,1,46:18.3
0,1,46:18.3
1,1,46:17.3
2,1,46:18.3
3,1,46:18.3
4,1,46:18.3
5,1,46:18.3
6,1,46:18.3
7,1,46:18.3
8,1,46:18.3
9,1,46:18.3
10,1,46:18.3
11,1,46:18.3
12,1,46:17.3
13,1,46:18.3
14,1,46:18.3
15,1,46:18.3
16,1,46:18.3
-13,2,46:18.3
-9,2,46:18.3
-8,2,46:18.3
-7,2,46:18.3
-6,2,46:18.3
-5,2,46:18.3
-4,2,46:18.3
-3,2,46:17.3
-2,2,46:18.3
-1,2,46:18.3
0,2,46:18.3
1,2,46:17.3
2,2,46:17.3
3,2,46:18.3
4,2,46:18.3
5,2,46:18.3
6,2,46:17.3
7,2,46:18.3
8,2,46:18.3
9,2,46:18.3
10,2,46:18.3
11,2,46:18.3
12,2,46:18.3
13,2,46:18.3
14,2,46:18.3
15,2,46:18.3
16,2,46:18.3
17,2,46:18.3
-14,3,46:18.3
-13,3,46:18.3
-12,3,46:18.3
-10,3,46:18.3
-9,3,46:18.3
-8,3,46:18.3
-7,3,46:18.3
-6,3,46:17.3
-5,3,46:17.3
-4,3,46:18.3
-3,3,46:18.3
-2,3,46:18.3
-1,3,46:18.3
0,3,46:18.3
1,3,46:18.3
2,3,46:18.3
3,3,46:18.3
4,3,46:18.3
5,3,46:18.3
6,3,46:18.3
7,3,46:17.3
8,3,46:18.3
9,3,46:18.3
10,3,46:18.3
11,3,46:17.3
12,3,46:18.3
13,3,46:18.3
14,3,46:18.3
15,3,46:18.3
16,3,46:18.3
17,3,46:18.3
18,3,46:18.3
-15,4,46:18.3
-14,4,46:18.3
-13,4,46:18.3
-12,4,46:18.3
-11,4,46:18.3
-10,4,46:18.3
-9,4,46:18.3
-8,4,46:18.3
-7,4,46:18.3
-6,4,46:18.3
-5,4,46:18.3
-4,4,46:18.3
-3,4,46:18.3
-2,4,46:18.3
-1,4,46:17.3
0,4,46:17.3
1,4,46:18.3
2,4,46:17.3
3,4,46:18.3
4,4,46:18.3
5,4,46:18.3
6,4,46:18.3
7,4,46:18.3
8,4,46:18.3
9,4,46:18.3
10,4,46:17.3
11,4,46:18.3
12,4,46:18.3
13,4,46:18.3
14,4,46:18.3
15,4,46:18.3
16,4,46:18.3
17,4,46:18.3
-14,5,46:18.3
-13,5,46:18.3
-12,5,46:18.3
-10,5,46:18.3
-9,5,46:18.3
-8,5,46:18.3
-7,5,46:18.3
-6,5,46:18.3
-5,5,46:18.3
-4,5,46:18.3
-3,5,46:18.3
-2,5,46:18.3
-1,5,46:18.3
0,5,46:18.3
1,5,46:18.3
2,5,46:18.3
3,5,46:18.3
4,5,46:18.3
5,5,46:18.3
6,5,46:18.3
7,5,46:18.3
8,5,46:18.3
9,5,46:18.3
10,5,46:18.3
11,5,46:18.3
12,5,46:18.3
13,5,46:18.3
14,5,46:18.3
15,5,46:18.3
16,5,46:18.3
-13,6,46:18.3
-9,6,46:18.3
-8,6,46:18.3
-7,6,46:18.3
-6,6,46:18.3
-5,6,46:18.3
-3,6,46:18.3
-2,6,46:18.3
-1,6,46:18.3
0,6,46:18.3
1,6,46:18.3
2,6,46:18.3
3,6,46:18.3
4,6,46:18.3
5,6,46:18.3
6,6,46:17.3
7,6,46:18.3
8,6,46:18.3
9,6,46:18.3
10,6,46:18.3
11,6,46:18.3
12,6,46:18.3
13,6,46:18.3
14,6,46:17.3
15,6,46:18.3
16,6,46:18.3
-8,7,46:18.3
-7,7,46:18.3
-6,7,46:18.3
-5,7,46:18.3
-4,7,46:18.3
-3,7,46:18.3
-2,7,46:18.3
-1,7,46:17.3
0,7,46:18.3
1,7,46:18.3
2,7,46:18.3
3,7,46:18.3
4,7,46:18.3
5,7,46:18.3
6,7,46:18.3
7,7,46:18.3
8,7,46:18.3
9,7,46:18.3
10,7,46:18.3
12,7,46:18.3
13,7,46:18.3
14,7,46:18.3
15,7,46:18.3
16,7,46:18.3
-9,8,46:18.3
-8,8,46:18.3
-7,8,46:18.3
-6,8,46:17.3
-5,8,46:18.3
-4,8,46:18.3
-3,8,46:18.3
-2,8,46:18.3
-1,8,46:18.3
0,8,46:18.3
1,8,46:18.3
2,8,46:18.3
3,8,46:18.3
4,8,46:18.3
5,8,46:18.3
6,8,46:18.3
7,8,46:18.3
8,8,46:18.3
9,8,46:18.3
10,8,46:18.3
11,8,46:18.3
13,8,46:18.3
14,8,46:18.3
15,8,46:18.3
-10,9,46:18.3
-9,9,46:18.3
-8,9,46:18.3
-7,9,46:18.3
-6,9,46:18.3
-5,9,46:18.3
-4,9,46:18.3
-2,9,46:18.3
-1,9,46:18.3
0,9,46:18.3
1,9,46:18.3
2,9,46:18.3
3,9,46:17.3
4,9,46:18.3
5,9,46:18.3
7,9,46:18.3
8,9,46:18.3
9,9,46:17.3
10,9,46:18.3
11,9,46:18.3
-9,10,46:18.3
-8,10,46:18.3
-7,10,46:18.3
-6,10,46:18.3
-5,10,46:18.3
0,10,46:18.3
1,10,46:18.3
2,10,46:17.3
3,10,46:18.3
4,10,46:18.3
5,10,46:18.3
6,10,46:18.3
7,10,46:18.3
8,10,46:18.3
9,10,46:18.3
10,10,46:18.3
11,10,46:18.3
-8,11,46:18.3
-6,11,46:18.3
-5,11,46:18.3
-4,11,46:18.3
-2,11,46:18.3
0,11,46:18.3
1,11,46:18.3
2,11,46:18.3
3,11,46:18.3
4,11,46:18.3
5,11,46:18.3
6,11,46:18.3
7,11,46:18.3
8,11,46:18.3
9,11,46:18.3
10,11,46:18.3
-7,12,46:18.3
-6,12,46:18.3
-5,12,46:18.3
-4,12,46:18.3
-3,12,46:18.3
-2,12,46:18.3
-1,12,46:18.3
1,12,46:18.3
2,12,46:18.3
3,12,46:18.3
4,12,46:18.3
5,12,46:18.3
6,12,46:18.3
-7,13,46:18.3
-6,13,46:18.3
-5,13,46:17.3
-4,13,46:18.3
-3,13,46:18.3
-2,13,46:18.3
-1,13,46:18.3
0,13,46:18.3
3,13,46:18.3
4,13,46:18.3
5,13,46:18.3
-7,14,46:18.3
-6,14,46:18.3
-5,14,46:18.3
-4,14,46:18.3
-3,14,46:18.3
-2,14,46:18.3
-1,14,46:18.3
-6,15,46:18.3
-5,15,46:18.3
-4,15,46:18.3
-2,15,46:18.3
-3,-16,47:18.3
-5,-15,47:18.3
-4,-15,47:18.3
-3,-15,47:18.3
-2,-15,47:18.3
-6,-14,47:18.3
-5,-14,47:18.3
-4,-14,47:18.3
-3,-14,47:18.3
-2,-14,47:18.3
-1,-14,47:18.3
-9,-13,47:18.3
-6,-13,47:18.3
-5,-13,47:18.3
-4,-13,47:17.3
-3,-13,47:18.3
-2,-13,47:18.3
-1,-13,47:18.3
0,-13,47:18.3
1,-13,47:18.3
2,-13,47:18.3
-10,-12,47:18.3
-9,-12,47:18.3
-8,-12,47:18.3
-6,-12,47:18.3
-5,-12,47:18.3
-4,-12,47:18.3
-3,-12,47:18.3
-2,-12,47:18.3
-1,-12,47:18.3
0,-12,47:18.3
1,-12,47:18.3
2,-12,47:18.3
3,-12,47:18.3
4,-12,47:18.3
7,-12,47:18.3
8,-12,47:18.3
9,-12,47:18.3
-11,-11,47:18.3
-10,-11,47:18.3
-9,-11,47:18.3
-8,-11,47:18.3
-7,-11,47:18.3
-5,-11,47:18.3
-4,-11,47:18.3
-3,-11,47:18.3
-2,-11,47:18.3
-1,-11,47:18.3
0,-11,47:18.3
1,-11,47:17.3
2,-11,47:18.3
3,-11,47:18.3
4,-11,47:18.3
5,-11,47:18.3
6,-11,47:18.3
7,-11,47:18.3
8,-11,47:18.3
9,-11,47:18.3
10,-11,47:18.3
-10,-10,47:18.3
-9,-10,47:18.3
-8,-10,47:18.3
-7,-10,47:18.3
-6,-10,47:18.3
-5,-10,47:18.3
-4,-10,47:18.3
-2,-10,47:18.3
-1,-10,47:18.3
0,-10,47:18.3
1,-10,47:17.3
2,-10,47:18.3
3,-10,47:18.3
4,-10,47:18.3
5,-10,47:18.3
6,-10,47:18.3
7,-10,47:18.3
8,-10,47:17.3
9,-10,47:18.3
10,-10,47:18.3
-10,-9,47:18.3
-9,-9,47:18.3
-8,-9,47:17.3
-7,-9,47:18.3
-6,-9,47:18.3
-5,-9,47:18.3
-4,-9,47:18.3
-3,-9,47:18.3
-2,-9,47:18.3
-1,-9,47:18.3
0,-9,47:18.3
1,-9,47:18.3
2,-9,47:17.3
3,-9,47:18.3
4,-9,47:18.3
5,-9,47:17.3
6,-9,47:18.3
7,-9,47:18.3
8,-9,47:18.3
9,-9,47:18.3
10,-9,47:18.3
-11,-8,47:18.3
-10,-8,47:18.3
-9,-8,47:18.3
-8,-8,47:18.3
-7,-8,47:18.3
-6,-8,47:18.3
-5,-8,47:18.3
-4,-8,47:18.3
-3,-8,47:18.3
-2,-8,47:18.3
-1,-8,47:18.3
0,-8,47:18.3
1,-8,47:17.3
2,-8,47:17.3
3,-8,47:18.3
4,-8,47:18.3
5,-8,47:18.3
6,-8,47:18.3
7,-8,47:18.3
8,-8,47:18.3
9,-8,47:18.3
10,-8,47:18.3
-12,-7,47:18.3
-11,-7,47:18.3
-10,-7,47:18.3
-9,-7,47:18.3
-8,-7,47:18.3
-7,-7,47:18.3
-6,-7,47:18.3
-5,-7,47:18.3
-4,-7,47:17.3
-3,-7,47:18.3
-2,-7,47:18.3
-1,-7,47:17.3
0,-7,47:18.3
1,-7,47:17.3
2,-7,47:18.3
3,-7,47:17.3
4,-7,47:18.3
5,-7,47:18.3
6,-7,47:18.3
7,-7,47:18.3
8,-7,47:18.3
9,-7,47:18.3
10,-7,47:18.3
11,-7,47:18.3
-11,-6,47:18.3
-10,-6,47:18.3
-9,-6,47:18.3
-8,-6,47:18.3
-7,-6,47:18.3
-6,-6,47:18.3
-5,-6,47:18.3
-4,-6,47:18.3
-3,-6,47:17.3
-2,-6,47:17.3
-1,-6,47:18.3
0,-6,47:18.3
1,-6,47:18.3
2,-6,47:18.3
3,-6,47:18.3
4,-6,47:18.3
5,-6,47:18.3
6,-6,47:18.3
7,-6,47:18.3
8,-6,47:17.3
9,-6,47:18.3
10,-6,47:18.3
-14,-5,47:18.3
-11,-5,47:18.3
-10,-5,47:18.3
-9,-5,47:17.3
-8,-5,47:18.3
-7,-5,47:18.3
-6,-5,47:18.3
-5,-5,47:18.3
-4,-5,47:18.3
-3,-5,47:18.3
-2,-5,47:18.3
-1,-5,47:18.3
0,-5,47:18.3
1,-5,47:17.3
2,-5,47:17.3
3,-5,47:18.3
4,-5,47:18.3
5,-5,47:18.3
6,-5,47:18.3
7,-5,47:18.3
8,-5,47:18.3
9,-5,47:18.3
10,-5,47:18.3
11,-5,47:18.3
12,-5,47:18.3
13,-5,47:18.3
-15,-4,47:18.3
-14,-4,47:18.3
-13,-4,47:18.3
-11,-4,47:18.3
-10,-4,47:18.3
-9,-4,47:18.3
-8,-4,47:18.3
-7,-4,47:18.3
-6,-4,47:18.3
-5,-4,47:18.3
-4,-4,47:17.3
-3,-4,47:18.3
-2,-4,47:17.3
-1,-4,47:18.3
0,-4,47:18.3
1,-4,47:17.3
2,-4,47:18.3
3,-4,47:18.3
4,-4,47:17.3
5,-4,47:18.3
6,-4,47:18.3
7,-4,47:18.3
8,-4,47:18.3
9,-4,47:18.3
10,-4,47:18.3
11,-4,47:18.3
12,-4,47:18.3
13,-4,47:18.3
14,-4,47:18.3
-16,-3,47:18.3
-15,-3,47:18.3
-14,-3,47:18.3
-13,-3,47:18.3
-12,-3,47:18.3
-11,-3,47:18.3
-10,-3,47:18.3
-9,-3,47:18.3
-8,-3,47:18.3
-7,-3,47:18.3
-6,-3,47:18.3
-5,-3,47:18.3
-4,-3,47:18.3
-3,-3,47:17.3
-2,-3,47:18.3
-1,-3,47:18.3
0,-3,47:18.3
1,-3,47:18.3
2,-3,47:18.3
3,-3,47:17.3
4,-3,47:17.3
5,-3,47:18.3
6,-3,47:18.3
7,-3,47:18.3
8,-3,47:18.3
9,-3,47:18.3
10,-3,47:18.3
11,-3,47:17.3
12,-3,47:18.3
13,-3,47:18.3
14,-3,47:18.3
15,-3,47:18.3
-15,-2,47:18.3
-14,-2,47:18.3
-13,-2,47:18.3
-12,-2,47:18.3
-11,-2,47:18.3
-10,-2,47:18.3
-9,-2,47:18.3
-8,-2,47:18.3
-7,-2,47:18.3
-6,-2,47:18.3
-5,-2,47:18.3
-4,-2,47:18.3
-3,-2,47:18.3
-2,-2,47:18.3
-1,-2,47:18.3
0,-2,47:18.3
1,-2,47:18.3
2,-2,47:18.3
3,-2,47:18.3
4,-2,47:18.3
5,-2,47:17.3
6,-2,47:18.3
7,-2,47:18.3
8,-2,47:18.3
9,-2,47:18.3
10,-2,47:17.3
11,-2,47:18.3
12,-2,47:18.3
13,-2,47:18.3
14,-2,47:18.3
-15,-1,47:18.3
-14,-1,47:18.3
-13,-1,47:18.3
-12,-1,47:18.3
-11,-1,47:18.3
-10,-1,47:17.3
-9,-1,47:18.3
-8,-1,47:18.3
-7,-1,47:18.3
-6,-1,47:18.3
-5,-1,47:17.3
-4,-1,47:17.3
-3,-1,47:17.3
-2,-1,47:17.3
-1,-1,47:17.3
0,-1,47:18.3
1,-1,47:18.3
2,-1,47:18.3
3,-1,47:18.3
4,-1,47:18.3
5,-1,47:18.3
6,-1,47:18.3
7,-1,47:17.3
8,-1,47:17.3
9,-1,47:18.3
10,-1,47:18.3
11,-1,47:18.3
12,-1,47:18.3
13,-1,47:18.3
14,-1,47:18.3
-14,0,47:18.3
-13,0,47:18.3
-12,0,47:18.3
-11,0,47:17.3
-10,0,47:18.3
-9,0,47:18.3
-8,0,47:17.3
-7,0,47:18.3
-6,0,47:17.3
-5,0,47:18.3
-4,0,47:17.3
-3,0,47:17.3
-2,0,47:17.3
-1,0,47:17.3
0,0,47:18.3
1,0,47:18.3
2,0,47:18.3
3,0,47:18.3
4,0,47:17.3
5,0,47:18.3
6,0,47:18.3
7,0,47:17.3
8,0,47:18.3
9,0,47:18.3
10,0,47:18.3
11,0,47:18.3
12,0,47:18.3
13,0,47:18.3
14,0,47:18.3
15,0,47:18.3
-13,1,47:18.3
-12,1,47:18.3
-11,1,47:18.3
-10,1,47:17.3
-9,1,47:18.3
-8,1,47:18.3
-7,1,47:18.3
-6,1,47:18.3
-5,1,47:18.3
-4,1,47:18.3
-3,1,47:18.3
-2,1,47:18.3
-1,1,47:18.3
0,1,47:18.3
1,1,47:18.3
2,1,47:18.3
3,1,47:18.3
4,1,47:18.3
5,1,47:17.3
6,1,47:17.3
7,1,47:18.3
8,1,47:17.3
9,1,47:18.3
10,1,47:18.3
11,1,47:18.3
12,1,47:18.3
13,1,47:18.3
14,1,47:18.3
-12,2,47:18.3
-11,2,47:18.3
-10,2,47:18.3
-9,2,47:17.3
-8,2,47:18.3
-7,2,47:18.3
-6,2,47:17.3
-5,2,47:18.3
-4,2,47:18.3
-3,2,47:17.3
-2,2,47:18.3
-1,2,47:17.3
0,2,47:18.3
1,2,47:17.3
2,2,47:18.3
3,2,47:18.3
4,2,47:18.3
5,2,47:17.3
6,2,47:18.3
7,2,47:18.3
8,2,47:18.3
9,2,47:18.3
10,2,47:18.3
11,2,47:18.3
12,2,47:18.3
13,2,47:18.3
-11,3,47:18.3
-10,3,47:18.3
-9,3,47:18.3
-8,3,47:18.3
-7,3,47:18.3
-6,3,47:17.3
-5,3,47:18.3
-4,3,47:18.3
-3,3,47:18.3
-2,3,47:18.3
-1,3,47:18.3
0,3,47:18.3
1,3,47:18.3
2,3,47:18.3
3,3,47:18.3
4,3,47:18.3
5,3,47:18.3
6,3,47:18.3
7,3,47:18.3
8,3,47:17.3
9,3,47:17.3
10,3,47:18.3
11,3,47:18.3
12,3,47:18.3
13,3,47:18.3
-10,4,47:18.3
-9,4,47:18.3
-8,4,47:18.3
-7,4,47:18.3
-6,4,47:18.3
-5,4,47:18.3
-4,4,47:18.3
-3,4,47:18.3
-2,4,47:18.3
-1,4,47:18.3
0,4,47:17.3
1,4,47:18.3
2,4,47:18.3
3,4,47:18.3
4,4,47:18.3
5,4,47:17.3
6,4,47:18.3
7,4,47:18.3
8,4,47:18.3
9,4,47:18.3
10,4,47:18.3
11,4,47:17.3
12,4,47:18.3
13,4,47:18.3
14,4,47:18.3
-8,5,47:18.3
-7,5,47:18.3
-6,5,47:17.3
-5,5,47:18.3
-4,5,47:18.3
-3,5,47:18.3
-2,5,47:18.3
-1,5,47:18.3
0,5,47:17.3
1,5,47:17.3
2,5,47:18.3
3,5,47:18.3
4,5,47:18.3
5,5,47:18.3
6,5,47:18.3
7,5,47:18.3
8,5,47:18.3
9,5,47:18.3
10,5,47:17.3
11,5,47:18.3
12,5,47:18.3
13,5,47:18.3
14,5,47:18.3
15,5,47:18.3
-8,6,47:18.3
-7,6,47:18.3
-6,6,47:18.3
-5,6,47:18.3
-4,6,47:18.3
-3,6,47:18.3
-2,6,47:18.3
-1,6,47:18.3
0,6,47:18.3
1,6,47:18.3
2,6,47:18.3
3,6,47:18.3
4,6,47:18.3
5,6,47:17.3
6,6,47:18.3
7,6,47:18.3
8,6,47:18.3
9,6,47:18.3
10,6,47:18.3
11,6,47:18.3
12,6,47:18.3
13,6,47:18.3
14,6,47:18.3
15,6,47:18.3
16,6,47:18.3
-7,7,47:18.3
-6,7,47:18.3
-5,7,47:18.3
-4,7,47:17.3
-3,7,47:18.3
-2,7,47:18.3
-1,7,47:18.3
0,7,47:18.3
1,7,47:17.3
2,7,47:18.3
3,7,47:18.3
4,7,47:18.3
5,7,47:17.3
6,7,47:18.3
7,7,47:18.3
9,7,47:18.3
10,7,47:18.3
11,7,47:18.3
13,7,47:18.3
14,7,47:18.3
15,7,47:18.3
-8,8,47:18.3
-7,8,47:18.3
-6,8,47:18.3
-5,8,47:18.3
-4,8,47:18.3
-3,8,47:18.3
-2,8,47:17.3
-1,8,47:18.3
0,8,47:18.3
1,8,47:18.3
2,8,47:18.3
3,8,47:18.3
4,8,47:18.3
5,8,47:18.3
6,8,47:18.3
7,8,47:18.3
8,8,47:18.3
9,8,47:18.3
10,8,47:18.3
14,8,47:18.3
-7,9,47:18.3
-6,9,47:18.3
-5,9,47:18.3
-4,9,47:18.3
-3,9,47:18.3
-2,9,47:18.3
-1,9,47:18.3
0,9,47:18.3
1,9,47:18.3
2,9,47:18.3
3,9,47:18.3
4,9,47:18.3
5,9,47:18.3
6,9,47:18.3
7,9,47:18.3
8,9,47:18.3
9,9,47:18.3
10,9,47:18.3
11,9,47:18.3
-6,10,47:18.3
-5,10,47:18.3
-4,10,47:18.3
-3,10,47:18.3
-2,10,47:18.3
-1,10,47:18.3
0,10,47:18.3
1,10,47:18.3
2,10,47:18.3
3,10,47:18.3
4,10,47:18.3
6,10,47:18.3
7,10,47:18.3
8,10,47:17.3
9,10,47:18.3
10,10,47:18.3
-6,11,47:18.3
-5,11,47:18.3
-4,11,47:17.3
-3,11,47:17.3
-2,11,47:18.3
-1,11,47:18.3
1,11,47:18.3
2,11,47:18.3
3,11,47:18.3
6,11,47:18.3
7,11,47:18.3
8,11,47:18.3
9,11,47:18.3
10,11,47:18.3
-6,12,47:18.3
-5,12,47:18.3
-4,12,47:18.3
-3,12,47:18.3
-2,12,47:18.3
-1,12,47:18.3
2,12,47:18.3
7,12,47:18.3
8,12,47:18.3
9,12,47:18.3
-7,13,47:18.3
-6,13,47:18.3
-5,13,47:18.3
-4,13,47:18.3
-3,13,47:18.3
-2,13,47:18.3
-6,14,47:18.3
-5,14,47:18.3
-4,14,47:18.3
-5,15,47:18.3
-4,-15,48:18.3
-5,-14,48:18.3
-4,-14,48:18.3
-3,-14,48:18.3
-6,-13,48:18.3
-5,-13,48:18.3
-4,-13,48:18.3
-3,-13,48:18.3
-2,-13,48:18.3
1,-13,48:18.3
-5,-12,48:18.3
-4,-12,48:18.3
-3,-12,48:18.3
0,-12,48:18.3
1,-12,48:18.3
2,-12,48:18.3
4,-12,48:18.3
5,-12,48:18.3
6,-12,48:18.3
8,-12,48:18.3
-8,-11,48:18.3
-4,-11,48:18.3
-3,-11,48:18.3
-2,-11,48:18.3
-1,-11,48:18.3
0,-11,48:18.3
1,-11,48:18.3
2,-11,48:18.3
3,-11,48:18.3
4,-11,48:18.3
5,-11,48:18.3
6,-11,48:18.3
7,-11,48:18.3
8,-11,48:18.3
9,-11,48:18.3
-9,-10,48:18.3
-8,-10,48:18.3
-7,-10,48:18.3
-6,-10,48:18.3
-5,-10,48:18.3
-4,-10,48:18.3
-3,-10,48:18.3
-2,-10,48:18.3
-1,-10,48:18.3
0,-10,48:18.3
1,-10,48:18.3
2,-10,48:18.3
3,-10,48:18.3
4,-10,48:18.3
5,-10,48:17.3
6,-10,48:18.3
7,-10,48:18.3
8,-10,48:18.3
9,-10,48:18.3
10,-10,48:18.3
-10,-9,48:18.3
-9,-9,48:18.3
-8,-9,48:18.3
-7,-9,48:18.3
-6,-9,48:18.3
-5,-9,48:18.3
-4,-9,48:18.3
-3,-9,48:18.3
-2,-9,48:17.3
-1,-9,48:18.3
0,-9,48:17.3
1,-9,48:18.3
2,-9,48:18.3
3,-9,48:18.3
4,-9,48:18.3
5,-9,48:18.3
6,-9,48:18.3
7,-9,48:18.3
8,-9,48:18.3
9,-9,48:18.3
10,-9,48:18.3
-9,-8,48:18.3
-8,-8,48:18.3
-7,-8,48:18.3
-6,-8,48:18.3
-5,-8,48:17.3
-4,-8,48:18.3
-3,-8,48:17.3
-2,-8,48:18.3
-1,-8,48:17.3
0,-8,48:18.3
1,-8,48:17.3
2,-8,48:18.3
3,-8,48:18.3
4,-8,48:18.3
5,-8,48:18.3
6,-8,48:18.3
7,-8,48:18.3
8,-8,48:18.3
9,-8,48:18.3
10,-8,48:18.3
11,-8,48:18.3
-9,-7,48:18.3
-8,-7,48:18.3
-7,-7,48:18.3
-6,-7,48:17.3
-5,-7,48:18.3
-4,-7,48:18.3
-3,-7,48:17.3
-2,-7,48:17.3
-1,-7,48:18.3
0,-7,48:18.3
1,-7,48:18.3
2,-7,48:18.3
3,-7,48:18.3
4,-7,48:18.3
5,-7,48:18.3
7,-7,48:18.3
8,-7,48:18.3
9,-7,48:17.3
10,-7,48:18.3
11,-7,48:18.3
12,-7,48:18.3
13,-7,48:18.3
14,-7,48:18.3
-10,-6,48:18.3
-9,-6,48:18.3
-8,-6,48:18.3
-7,-6,48:18.3
-6,-6,48:17.3
-5,-6,48:17.3
-4,-6,48:18.3
-3,-6,48:18.3
-2,-6,48:18.3
-1,-6,48:17.3
0,-6,48:18.3
1,-6,48:17.3
2,-6,48:18.3
3,-6,48:18.3
4,-6,48:18.3
5,-6,48:18.3
6,-6,48:18.3
7,-6,48:18.3
8,-6,48:18.3
9,-6,48:18.3
10,-6,48:18.3
11,-6,48:18.3
12,-6,48:18.3
13,-6,48:18.3
14,-6,48:18.3
15,-6,48:18.3
-11,-5,48:18.3
-10,-5,48:18.3
-9,-5,48:18.3
-8,-5,48:18.3
-7,-5,48:18.3
-6,-5,48:18.3
-5,-5,48:18.3
-4,-5,48:18.3
-3,-5,48:18.3
-2,-5,48:18.3
-1,-5,48:18.3
0,-5,48:18.3
1,-5,48:17.3
2,-5,48:17.3
3,-5,48:18.3
4,-5,48:18.3
5,-5,48:18.3
6,-5,48:18.3
7,-5,48:18.3
8,-5,48:18.3
9,-5,48:18.3
10,-5,48:18.3
11,-5,48:18.3
12,-5,48:18.3
13,-5,48:17.3
14,-5,48:18.3
15,-5,48:18.3
-10,-4,48:18.3
-9,-4,48:18.3
-8,-4,48:18.3
-7,-4,48:18.3
-6,-4,48:18.3
-5,-4,48:18.3
-4,-4,48:17.3
-3,-4,48:18.3
-2,-4,48:18.3
-1,-4,48:17.3
0,-4,48:18.3
1,-4,48:18.3
2,-4,48:18.3
3,-4,48:18.3
4,-4,48:18.3
5,-4,48:17.3
6,-4,48:18.3
7,-4,48:18.3
8,-4,48:18.3
10,-4,48:18.3
11,-4,48:18.3
12,-4,48:18.3
13,-4,48:18.3
14,-4,48:18.3
15,-4,48:18.3
-11,-3,48:18.3
-10,-3,48:18.3
-9,-3,48:18.3
-8,-3,48:18.3
-7,-3,48:18.3
-6,-3,48:18.3
-5,-3,48:18.3
-4,-3,48:18.3
-3,-3,48:17.3
-2,-3,48:18.3
-1,-3,48:18.3
0,-3,48:17.3
1,-3,48:18.3
2,-3,48:18.3
3,-3,48:18.3
4,-3,48:18.3
5,-3,48:17.3
6,-3,48:17.3
7,-3,48:18.3
8,-3,48:18.3
9,-3,48:18.3
10,-3,48:18.3
11,-3,48:18.3
12,-3,48:18.3
13,-3,48:18.3
14,-3,48:18.3
-11,-2,48:18.3
-10,-2,48:18.3
-9,-2,48:17.3
-8,-2,48:17.3
-7,-2,48:18.3
-6,-2,48:18.3
-5,-2,48:18.3
-4,-2,48:18.3
-3,-2,48:18.3
-2,-2,48:18.3
-1,-2,48:18.3
0,-2,48:17.3
1,-2,48:18.3
2,-2,48:18.3
3,-2,48:18.3
4,-2,48:18.3
5,-2,48:18.3
6,-2,48:18.3
7,-2,48:18.3
8,-2,48:18.3
9,-2,48:18.3
10,-2,48:18.3
11,-2,48:17.3
12,-2,48:18.3
13,-2,48:18.3
-12,-1,48:18.3
-11,-1,48:18.3
-10,-1,48:18.3
-9,-1,48:18.3
-8,-1,48:17.3
-7,-1,48:18.3
-6,-1,48:18.3
-5,-1,48:17.3
-4,-1,48:18.3
-3,-1,48:18.3
-2,-1,48:18.3
-1,-1,48:18.3
0,-1,48:18.3
1,-1,48:18.3
2,-1,48:18.3
3,-1,48:18.3
4,-1,48:18.3
5,-1,48:18.3
6,-1,48:17.3
7,-1,48:17.3
8,-1,48:18.3
9,-1,48:18.3
10,-1,48:18.3
11,-1,48:18.3
12,-1,48:18.3
13,-1,48:18.3
