
#######################################################################
# +-----------------------------------------------------------------+ #
# |                            BO3 object                           | #
# +-----------------------------------------------------------------+ #
#######################################################################

# This is the config file of a custom object.
# If you add this object correctly to your BiomeConfigs, it will spawn in the world.

# This is the creator of this BO3 object
Author: Piginabag

# A short description of this BO3 object
Description: No description given

# The BO3 version, don't change this! It can be used by external applications to do a version check.
Version: 3

# The settings mode, WriteAll, WriteWithoutComments or WriteDisable. See WorldConfig.
SettingsMode: WriteDisable


#######################################################################
# +-----------------------------------------------------------------+ #
# |                          Main settings                          | #
# +-----------------------------------------------------------------+ #
#######################################################################

# This needs to be set to true to spawn the object in the Tree and Sapling resources.
Tree: false

# The frequency of the BO3 from 1 to 200. Tries this many times to spawn this BO3 when using the CustomObject(...) resource.
# Ignored by Tree(..), Sapling(..) and CustomStructure(..)
Frequency: 1

# The rarity of the BO3 from 0 to 100. Each spawn attempt has rarity% chance to succeed when using the CustomObject(...) resource.
# Ignored by Tree(..), Sapling(..) and CustomStructure(..)
Rarity: 100.0

# If you set this to true, the BO3 will be placed with a random rotation.
RotateRandomly: true

# The spawn height of the BO3 - randomY, highestBlock or highestSolidBlock.
SpawnHeight: randomY

# The offset from the spawn height to spawn this BO3
# Ex. SpawnHeight = highestSolidBlock, SpawnHeightOffset = 3; This object will spawn 3 blocks above the highest solid block
SpawnHeightOffset: 0

# A random amount to offset the spawn location from the spawn offset height
# Ex. SpawnHeightOffset = 3, SpawnHeightVariance = 3; This object will spawn 3 to 6 blocks above the original spot it would have spawned
SpawnHeightVariance: 0

######################
# Extrusion settings #
######################

# The style of extrusion you wish to use - BottomDown, TopUp, None (Default)
ExtrudeMode: None

# The blocks to extrude your BO3 through
ExtrudeThroughBlocks: AIR

# The height limits for the BO3.
MinHeight: 8

MaxHeight: 40

# Objects can have other objects attacthed to it: branches. Branches can also
# have branches attached to it, which can also have branches, etc. This is the
# maximum branch depth for this objects.
MaxBranchDepth: 10

# When spawned with the UseWorld keyword, this BO3 should NOT spawn in the following biomes.
# If you writer.write the BO3 name directly in the BiomeConfigs, this will be ignored.
ExcludedBiomes: All


#######################################################################
# +-----------------------------------------------------------------+ #
# |                      Source block settings                      | #
# +-----------------------------------------------------------------+ #
#######################################################################

# The block(s) the BO3 should spawn in.
SourceBlocks: AIR

# The maximum percentage of the BO3 that can be outside the SourceBlock.
# The BO3 won't be placed on a location with more blocks outside the SourceBlock than this percentage.
MaxPercentageOutsideSourceBlock: 100

# What to do when a block is about to be placed outside the SourceBlock? (dontPlace, placeAnyway)
OutsideSourceBlock: placeAnyway


#######################################################################
# +-----------------------------------------------------------------+ #
# |                              Blocks                             | #
# +-----------------------------------------------------------------+ #
#######################################################################

# All the blocks used in the BO3 are listed here. Possible blocks:
# Block(x,y,z,id[.data][,nbtfile.nbt)
# RandomBlock(x,y,z,id[:data][,nbtfile.nbt],chance[,id[:data][,nbtfile.nbt],chance[,...]])
# So RandomBlock(0,0,0,CHEST,chest.nbt,50,CHEST,anotherchest.nbt,100) will spawn a chest at
# the BO3 origin, and give it a 50% chance to have the contents of chest.nbt, or, if that
# fails, a 100% percent chance to have the contents of anotherchest.nbt.
Block(-4,-7,-12,SANDSTONE)
Block(-4,-7,-11,SANDSTONE:2)
Block(-4,-7,-10,SANDSTONE:2)
Block(-4,-7,-9,SANDSTONE:1)
Block(-4,-7,-8,SANDSTONE:1)
Block(-4,-7,-7,SANDSTONE)
Block(-4,-7,-6,SANDSTONE)
Block(-4,-7,-5,SANDSTONE)
Block(-4,-7,-4,SANDSTONE:1)
Block(-4,-7,-3,SANDSTONE:1)
Block(-4,-7,-2,SANDSTONE:1)
Block(-4,-7,-1,SANDSTONE:2)
Block(-4,-7,0,SANDSTONE)
Block(-4,-7,1,SANDSTONE:2)
Block(-4,-6,-12,SANDSTONE:1)
Block(-4,-6,-11,SANDSTONE:2)
Block(-4,-6,-10,SANDSTONE)
Block(-4,-6,-9,SANDSTONE)
Block(-4,-6,-8,SANDSTONE:1)
Block(-4,-6,-7,SANDSTONE:2)
Block(-4,-6,-6,SANDSTONE:1)
Block(-4,-6,-5,SANDSTONE:2)
Block(-4,-6,-4,SANDSTONE:2)
Block(-4,-6,-3,SANDSTONE:2)
Block(-4,-6,-2,SANDSTONE)
Block(-4,-6,-1,SANDSTONE)
Block(-4,-6,0,SANDSTONE)
Block(-4,-6,1,SANDSTONE:2)
Block(-4,-5,-12,SANDSTONE:1)
Block(-4,-5,-11,SANDSTONE)
Block(-4,-5,-10,SANDSTONE:1)
Block(-4,-5,-9,SANDSTONE:2)
Block(-4,-5,-8,SANDSTONE:1)
Block(-4,-5,-7,SANDSTONE)
Block(-4,-5,-6,SANDSTONE)
Block(-4,-5,-5,SANDSTONE:2)
Block(-4,-5,-4,SANDSTONE)
Block(-4,-5,-3,SANDSTONE)
Block(-4,-5,-2,SANDSTONE:1)
Block(-4,-5,-1,SANDSTONE:1)
Block(-4,-5,0,SANDSTONE:1)
Block(-4,-5,1,SANDSTONE:2)
Block(-4,-4,-12,SANDSTONE)
Block(-4,-4,-11,SANDSTONE:2)
Block(-4,-4,-10,SANDSTONE)
Block(-4,-4,-9,SANDSTONE:2)
Block(-4,-4,-8,SANDSTONE:2)
Block(-4,-4,-7,SANDSTONE)
Block(-4,-4,-6,SANDSTONE)
Block(-4,-4,-5,SANDSTONE:2)
Block(-4,-4,-4,SANDSTONE:2)
Block(-4,-4,-3,SANDSTONE)
Block(-4,-4,-2,SANDSTONE)
Block(-4,-4,-1,SANDSTONE)
Block(-4,-4,0,SANDSTONE:1)
Block(-4,-4,1,SANDSTONE)
Block(-4,-3,-12,SANDSTONE)
Block(-4,-3,-11,SANDSTONE)
Block(-4,-3,-10,SANDSTONE)
Block(-4,-3,-9,SANDSTONE)
Block(-4,-3,-8,SANDSTONE)
Block(-4,-3,-7,SANDSTONE)
Block(-4,-3,-6,SANDSTONE)
Block(-4,-3,-5,SANDSTONE:2)
Block(-4,-3,-4,SANDSTONE:1)
Block(-4,-3,-3,SANDSTONE:1)
Block(-4,-3,-2,SANDSTONE)
Block(-4,-3,-1,SANDSTONE:1)
Block(-4,-3,0,SANDSTONE)
Block(-4,-3,1,SANDSTONE)
Block(-4,-2,-12,SANDSTONE:1)
Block(-4,-2,-11,SANDSTONE:1)
Block(-4,-2,-10,SANDSTONE)
Block(-4,-2,-9,SANDSTONE)
Block(-4,-2,-8,SANDSTONE:2)
Block(-4,-2,-7,SANDSTONE)
Block(-4,-2,-6,SANDSTONE)
Block(-4,-2,-5,SANDSTONE)
Block(-4,-2,-4,SANDSTONE)
Block(-4,-2,-3,SANDSTONE)
Block(-4,-2,-2,SANDSTONE:2)
Block(-4,-2,-1,SANDSTONE)
Block(-4,-2,0,SANDSTONE:1)
Block(-4,-2,1,SANDSTONE:1)
Block(-4,-1,-12,SANDSTONE)
Block(-4,-1,-11,SANDSTONE:1)
Block(-4,-1,-10,SANDSTONE:2)
Block(-4,-1,-9,SANDSTONE:2)
Block(-4,-1,-8,SANDSTONE:1)
Block(-4,-1,-7,SANDSTONE)
Block(-4,-1,-6,SANDSTONE)
Block(-4,-1,-5,SANDSTONE)
Block(-4,-1,-4,SANDSTONE)
Block(-4,-1,-3,SANDSTONE:2)
Block(-4,-1,-2,SANDSTONE:2)
Block(-4,-1,-1,SANDSTONE:2)
Block(-4,-1,0,SANDSTONE)
Block(-4,-1,1,SANDSTONE:2)
Block(-3,-8,-12,SANDSTONE)
Block(-3,-8,-11,SANDSTONE:2)
Block(-3,-8,-10,SANDSTONE)
Block(-3,-8,-9,SANDSTONE)
Block(-3,-8,-8,SANDSTONE)
Block(-3,-8,-7,SANDSTONE:1)
Block(-3,-8,-6,SANDSTONE:1)
Block(-3,-8,-5,SANDSTONE)
Block(-3,-8,-4,SANDSTONE)
Block(-3,-8,-3,SANDSTONE:2)
Block(-3,-8,-2,SANDSTONE)
Block(-3,-8,-1,SANDSTONE)
Block(-3,-8,0,SANDSTONE)
Block(-3,-7,-13,SANDSTONE:2)
Block(-3,-7,-12,SANDSTONE)
Block(-3,-7,-11,SANDSTONE)
Block(-3,-7,-10,SANDSTONE:1)
Block(-3,-7,-9,SANDSTONE:2)
Block(-3,-7,-8,SANDSTONE)
Block(-3,-7,-7,SANDSTONE)
Block(-3,-7,-6,AIR)
Block(-3,-7,-5,AIR)
Block(-3,-7,-4,AIR)
Block(-3,-7,-3,AIR)
Block(-3,-7,-2,SANDSTONE:1)
Block(-3,-7,-1,SANDSTONE)
Block(-3,-7,0,SANDSTONE:2)
Block(-3,-7,1,SANDSTONE)
Block(-3,-6,-13,SANDSTONE)
Block(-3,-6,-12,SANDSTONE)
Block(-3,-6,-11,AIR)
Block(-3,-6,-10,AIR)
Block(-3,-6,-9,VINE:2)
Block(-3,-6,-8,AIR)
Block(-3,-6,-7,SANDSTONE)
Block(-3,-6,-6,AIR)
Block(-3,-6,-5,AIR)
Block(-3,-6,-4,AIR)
Block(-3,-6,-3,AIR)
Block(-3,-6,-2,AIR)
Block(-3,-6,-1,AIR)
Block(-3,-6,0,AIR)
Block(-3,-6,1,SANDSTONE)
Block(-3,-5,-13,SANDSTONE)
Block(-3,-5,-12,SANDSTONE:1)
Block(-3,-5,-11,AIR)
Block(-3,-5,-10,AIR)
Block(-3,-5,-9,VINE:2)
Block(-3,-5,-8,AIR)
Block(-3,-5,-7,SANDSTONE)
Block(-3,-5,-6,AIR)
Block(-3,-5,-5,AIR)
Block(-3,-5,-4,AIR)
Block(-3,-5,-3,AIR)
Block(-3,-5,-2,AIR)
Block(-3,-5,-1,AIR)
Block(-3,-5,0,AIR)
Block(-3,-5,1,SANDSTONE)
Block(-3,-4,-13,SANDSTONE:1)
Block(-3,-4,-12,SANDSTONE:2)
Block(-3,-4,-11,AIR)
Block(-3,-4,-10,AIR)
Block(-3,-4,-9,VINE:2)
Block(-3,-4,-8,VINE:2)
Block(-3,-4,-7,SANDSTONE)
Block(-3,-4,-6,AIR)
Block(-3,-4,-5,AIR)
Block(-3,-4,-4,AIR)
Block(-3,-4,-3,AIR)
Block(-3,-4,-2,AIR)
Block(-3,-4,-1,AIR)
Block(-3,-4,0,AIR)
Block(-3,-4,1,SANDSTONE)
Block(-3,-3,-13,SANDSTONE:1)
Block(-3,-3,-12,SANDSTONE)
Block(-3,-3,-11,AIR)
Block(-3,-3,-10,AIR)
Block(-3,-3,-9,VINE:2)
Block(-3,-3,-8,VINE:2)
Block(-3,-3,-7,SANDSTONE:2)
Block(-3,-3,-6,AIR)
Block(-3,-3,-5,AIR)
Block(-3,-3,-4,AIR)
Block(-3,-3,-3,AIR)
Block(-3,-3,-2,AIR)
Block(-3,-3,-1,AIR)
Block(-3,-3,0,AIR)
Block(-3,-3,1,SANDSTONE:2)
Block(-3,-2,-13,SANDSTONE:1)
Block(-3,-2,-12,SANDSTONE:2)
Block(-3,-2,-11,AIR)
Block(-3,-2,-10,AIR)
Block(-3,-2,-9,AIR)
Block(-3,-2,-8,AIR)
Block(-3,-2,-7,SANDSTONE)
Block(-3,-2,-6,AIR)
Block(-3,-2,-5,AIR)
Block(-3,-2,-4,AIR)
Block(-3,-2,-3,SANDSTONE:1)
Block(-3,-2,-2,SANDSTONE:2)
Block(-3,-2,-1,AIR)
Block(-3,-2,0,AIR)
Block(-3,-2,1,SANDSTONE:1)
Block(-3,-1,-13,SANDSTONE)
Block(-3,-1,-12,SANDSTONE)
Block(-3,-1,-11,SANDSTONE)
Block(-3,-1,-10,SANDSTONE)
Block(-3,-1,-9,SANDSTONE:2)
Block(-3,-1,-8,SANDSTONE)
Block(-3,-1,-7,SANDSTONE)
Block(-3,-1,-6,SANDSTONE:1)
Block(-3,-1,-5,SANDSTONE)
Block(-3,-1,-4,SANDSTONE:1)
Block(-3,-1,-3,SANDSTONE:2)
Block(-3,-1,-2,SANDSTONE)
Block(-3,-1,-1,AIR)
Block(-3,-1,0,AIR)
Block(-3,-1,1,SANDSTONE:2)
Block(-3,0,-12,SANDSTONE:1)
Block(-3,0,-11,SANDSTONE)
Block(-3,0,-10,SANDSTONE:2)
Block(-3,0,-9,SANDSTONE)
Block(-3,0,-8,SANDSTONE:1)
Block(-3,0,-7,SANDSTONE)
Block(-3,0,-6,SANDSTONE)
Block(-3,0,-5,SANDSTONE)
Block(-3,0,-4,SANDSTONE:2)
Block(-3,0,-3,SANDSTONE)
Block(-3,0,-2,SANDSTONE:2)
Block(-3,0,-1,SANDSTONE)
Block(-3,0,0,SANDSTONE)
Block(-3,1,-4,SANDSTONE)
Block(-3,1,-3,SANDSTONE)
Block(-3,1,-2,SANDSTONE:1)
Block(-3,2,-4,SANDSTONE)
Block(-3,2,-3,SANDSTONE:1)
Block(-3,2,-2,SANDSTONE)
Block(-3,3,-4,SANDSTONE)
Block(-3,3,-3,SANDSTONE)
Block(-3,3,-2,SANDSTONE)
Block(-3,4,-4,SANDSTONE)
Block(-3,4,-3,SANDSTONE:1)
Block(-3,4,-2,SANDSTONE:2)
Block(-3,5,-4,SANDSTONE:1)
Block(-3,5,-3,SANDSTONE:1)
Block(-3,5,-2,SANDSTONE)
Block(-3,6,-4,SANDSTONE:1)
Block(-3,6,-3,SANDSTONE:2)
Block(-3,6,-2,SANDSTONE:2)
Block(-3,7,-4,SANDSTONE)
Block(-3,7,-3,SANDSTONE:2)
Block(-3,7,-2,SANDSTONE:1)
Block(-3,8,-4,SANDSTONE:1)
Block(-3,8,-3,SANDSTONE)
Block(-3,8,-2,SANDSTONE:2)
Block(-3,9,-4,SANDSTONE:2)
Block(-3,9,-3,SANDSTONE)
Block(-3,9,-2,SANDSTONE)
Block(-3,10,-4,SANDSTONE:1)
Block(-3,10,-3,SANDSTONE)
Block(-3,10,-2,SANDSTONE)
Block(-3,11,-4,SANDSTONE:2)
Block(-3,11,-3,SANDSTONE)
Block(-3,11,-2,SANDSTONE)
Block(-3,12,-4,SANDSTONE:1)
Block(-3,12,-3,SANDSTONE:1)
Block(-3,12,-2,SANDSTONE)
Block(-3,13,-4,SANDSTONE)
Block(-3,13,-3,SANDSTONE)
Block(-3,13,-2,SANDSTONE:2)
Block(-3,14,-4,SANDSTONE)
Block(-3,14,-3,SANDSTONE:1)
Block(-3,14,-2,SANDSTONE:1)
Block(-2,-8,-12,SANDSTONE)
Block(-2,-8,-11,SANDSTONE)
Block(-2,-8,-10,SANDSTONE:2)
Block(-2,-8,-9,SANDSTONE)
Block(-2,-8,-8,SANDSTONE:1)
Block(-2,-8,-7,SANDSTONE)
Block(-2,-8,-6,SANDSTONE)
Block(-2,-8,-5,SANDSTONE)
Block(-2,-8,-4,SANDSTONE)
Block(-2,-8,-3,SANDSTONE)
Block(-2,-8,-2,SANDSTONE)
Block(-2,-8,-1,SANDSTONE:1)
Block(-2,-8,0,SANDSTONE:2)
Block(-2,-7,-13,SANDSTONE:1)
Block(-2,-7,-12,SANDSTONE:1)
Block(-2,-7,-11,AIR)
Block(-2,-7,-10,AIR)
Block(-2,-7,-9,AIR)
Block(-2,-7,-8,AIR)
Block(-2,-7,-7,SANDSTONE)
Block(-2,-7,-6,SANDSTONE:2)
Block(-2,-7,-5,AIR)
Block(-2,-7,-4,AIR)
Block(-2,-7,-3,AIR)
Block(-2,-7,-2,SANDSTONE:1)
Block(-2,-7,-1,SANDSTONE)
Block(-2,-7,0,SANDSTONE)
Block(-2,-7,1,SANDSTONE)
Block(-2,-6,-13,SANDSTONE:2)
Block(-2,-6,-12,VINE:4)
Block(-2,-6,-11,AIR)
Block(-2,-6,-10,AIR)
Block(-2,-6,-9,AIR)
Block(-2,-6,-8,AIR)
Block(-2,-6,-7,AIR)
Block(-2,-6,-6,SANDSTONE)
Block(-2,-6,-5,AIR)
Block(-2,-6,-4,AIR)
Block(-2,-6,-3,AIR)
Block(-2,-6,-2,AIR)
Block(-2,-6,-1,AIR)
Block(-2,-6,0,AIR)
Block(-2,-6,1,SANDSTONE)
Block(-2,-5,-13,SANDSTONE)
Block(-2,-5,-12,VINE:4)
Block(-2,-5,-11,AIR)
Block(-2,-5,-10,AIR)
Block(-2,-5,-9,AIR)
Block(-2,-5,-8,AIR)
Block(-2,-5,-7,AIR)
Block(-2,-5,-6,SANDSTONE:2)
Block(-2,-5,-5,AIR)
Block(-2,-5,-4,AIR)
Block(-2,-5,-3,AIR)
Block(-2,-5,-2,AIR)
Block(-2,-5,-1,AIR)
Block(-2,-5,0,AIR)
Block(-2,-5,1,SANDSTONE:1)
Block(-2,-4,-13,SANDSTONE)
Block(-2,-4,-12,AIR)
Block(-2,-4,-11,AIR)
Block(-2,-4,-10,AIR)
Block(-2,-4,-9,AIR)
Block(-2,-4,-8,AIR)
Block(-2,-4,-7,AIR)
Block(-2,-4,-6,SANDSTONE)
Block(-2,-4,-5,AIR)
Block(-2,-4,-4,AIR)
Block(-2,-4,-3,AIR)
Block(-2,-4,-2,AIR)
Block(-2,-4,-1,AIR)
Block(-2,-4,0,AIR)
Block(-2,-4,1,SANDSTONE:2)
Block(-2,-3,-13,SANDSTONE)
Block(-2,-3,-12,AIR)
Block(-2,-3,-11,AIR)
Block(-2,-3,-10,AIR)
Block(-2,-3,-9,AIR)
Block(-2,-3,-8,AIR)
Block(-2,-3,-7,AIR)
Block(-2,-3,-6,SANDSTONE:2)
Block(-2,-3,-5,AIR)
Block(-2,-3,-4,AIR)
Block(-2,-3,-3,AIR)
Block(-2,-3,-2,AIR)
Block(-2,-3,-1,AIR)
Block(-2,-3,0,AIR)
Block(-2,-3,1,SANDSTONE)
Block(-2,-2,-13,SANDSTONE:1)
Block(-2,-2,-12,AIR)
Block(-2,-2,-11,AIR)
Block(-2,-2,-10,AIR)
Block(-2,-2,-9,AIR)
Block(-2,-2,-8,AIR)
Block(-2,-2,-7,AIR)
Block(-2,-2,-6,SANDSTONE)
Block(-2,-2,-5,AIR)
Block(-2,-2,-4,AIR)
Block(-2,-2,-3,SANDSTONE:1)
Block(-2,-2,-2,SANDSTONE)
Block(-2,-2,-1,AIR)
Block(-2,-2,0,AIR)
Block(-2,-2,1,SANDSTONE)
Block(-2,-1,-13,SANDSTONE)
Block(-2,-1,-12,SANDSTONE)
Block(-2,-1,-11,AIR)
Block(-2,-1,-10,AIR)
Block(-2,-1,-9,AIR)
Block(-2,-1,-8,AIR)
Block(-2,-1,-7,SANDSTONE)
Block(-2,-1,-6,SANDSTONE)
Block(-2,-1,-5,SANDSTONE)
Block(-2,-1,-4,SANDSTONE:1)
Block(-2,-1,-2,SANDSTONE)
Block(-2,-1,-1,AIR)
Block(-2,-1,0,AIR)
Block(-2,-1,1,SANDSTONE)
Block(-2,0,-12,SANDSTONE)
Block(-2,0,-11,SANDSTONE)
Block(-2,0,-10,SANDSTONE)
Block(-2,0,-9,SANDSTONE:1)
Block(-2,0,-8,SANDSTONE:2)
Block(-2,0,-7,SANDSTONE:1)
Block(-2,0,-6,SANDSTONE:1)
Block(-2,0,-5,SANDSTONE)
Block(-2,0,-4,SANDSTONE)
Block(-2,0,-3,SANDSTONE)
Block(-2,0,-2,SANDSTONE)
Block(-2,0,-1,SANDSTONE:1)
Block(-2,0,0,SANDSTONE)
Block(-2,1,-5,SANDSTONE)
Block(-2,1,-4,AIR)
Block(-2,1,-3,SANDSTONE:2)
Block(-2,1,-2,AIR)
Block(-2,1,-1,SANDSTONE)
Block(-2,2,-5,SANDSTONE)
Block(-2,2,-4,AIR)
Block(-2,2,-3,AIR)
Block(-2,2,-2,SANDSTONE)
Block(-2,2,-1,SANDSTONE)
Block(-2,3,-5,SANDSTONE)
Block(-2,3,-4,AIR)
Block(-2,3,-3,AIR)
Block(-2,3,-2,AIR)
Block(-2,3,-1,SANDSTONE:2)
Block(-2,4,-5,SANDSTONE)
Block(-2,4,-4,AIR)
Block(-2,4,-3,AIR)
Block(-2,4,-2,AIR)
Block(-2,4,-1,SANDSTONE)
Block(-2,5,-5,SANDSTONE)
Block(-2,5,-4,SANDSTONE:2)
Block(-2,5,-3,AIR)
Block(-2,5,-2,AIR)
Block(-2,5,-1,SANDSTONE:2)
Block(-2,6,-5,SANDSTONE:1)
Block(-2,6,-4,SANDSTONE)
Block(-2,6,-3,SANDSTONE)
Block(-2,6,-2,SANDSTONE)
Block(-2,6,-1,SANDSTONE)
Block(-2,7,-5,SANDSTONE)
Block(-2,7,-4,AIR)
Block(-2,7,-3,SANDSTONE)
Block(-2,7,-2,SANDSTONE:1)
Block(-2,7,-1,SANDSTONE:2)
Block(-2,8,-5,SANDSTONE)
Block(-2,8,-4,SANDSTONE)
Block(-2,8,-3,SANDSTONE)
Block(-2,8,-2,SANDSTONE)
Block(-2,8,-1,SANDSTONE)
Block(-2,9,-5,SANDSTONE)
Block(-2,9,-4,AIR)
Block(-2,9,-3,VINE:2)
Block(-2,9,-2,VINE:2)
Block(-2,9,-1,SANDSTONE)
Block(-2,10,-5,SANDSTONE)
Block(-2,10,-4,AIR)
Block(-2,10,-3,AIR)
Block(-2,10,-2,AIR)
Block(-2,10,-1,SANDSTONE:1)
Block(-2,11,-5,SANDSTONE:2)
Block(-2,11,-4,AIR)
Block(-2,11,-3,AIR)
Block(-2,11,-2,AIR)
Block(-2,11,-1,SANDSTONE)
Block(-2,12,-5,SANDSTONE:2)
Block(-2,12,-4,AIR)
Block(-2,12,-3,AIR)
Block(-2,12,-2,AIR)
Block(-2,12,-1,SANDSTONE)
Block(-2,13,-5,SANDSTONE:2)
Block(-2,13,-4,SANDSTONE)
Block(-2,13,-3,SANDSTONE)
Block(-2,13,-2,SANDSTONE)
Block(-2,13,-1,SANDSTONE)
Block(-2,14,-5,SANDSTONE)
Block(-2,14,-1,SANDSTONE:2)
Block(-1,-8,-12,SANDSTONE)
Block(-1,-8,-11,SANDSTONE)
Block(-1,-8,-10,SANDSTONE:2)
Block(-1,-8,-9,SANDSTONE:1)
Block(-1,-8,-8,SANDSTONE)
Block(-1,-8,-7,SANDSTONE)
Block(-1,-8,-6,SANDSTONE)
Block(-1,-8,-5,SANDSTONE)
Block(-1,-8,-4,SANDSTONE:1)
Block(-1,-8,-3,SANDSTONE)
Block(-1,-8,-2,SANDSTONE:2)
Block(-1,-8,-1,SANDSTONE)
Block(-1,-8,0,SANDSTONE:2)
Block(-1,-7,-13,SANDSTONE)
Block(-1,-7,-12,SANDSTONE:1)
Block(-1,-7,-11,AIR)
Block(-1,-7,-10,AIR)
Block(-1,-7,-9,AIR)
Block(-1,-7,-8,AIR)
Block(-1,-7,-7,SANDSTONE)
Block(-1,-7,-6,SANDSTONE)
Block(-1,-7,-5,AIR)
Block(-1,-7,-4,AIR)
Block(-1,-7,-3,AIR)
Block(-1,-7,-2,SANDSTONE)
Block(-1,-7,-1,SANDSTONE:1)
Block(-1,-7,0,SANDSTONE)
Block(-1,-7,1,SANDSTONE)
Block(-1,-6,-13,SANDSTONE:1)
Block(-1,-6,-12,VINE:4)
Block(-1,-6,-11,AIR)
Block(-1,-6,-10,AIR)
Block(-1,-6,-9,AIR)
Block(-1,-6,-8,AIR)
Block(-1,-6,-7,AIR)
Block(-1,-6,-6,SANDSTONE)
Block(-1,-6,-5,AIR)
Block(-1,-6,-4,AIR)
Block(-1,-6,-3,AIR)
Block(-1,-6,-2,SANDSTONE:1)
Block(-1,-6,-1,SANDSTONE:1)
Block(-1,-6,0,SANDSTONE)
Block(-1,-6,1,SANDSTONE:1)
Block(-1,-5,-13,SANDSTONE)
Block(-1,-5,-12,AIR)
Block(-1,-5,-11,AIR)
Block(-1,-5,-10,AIR)
Block(-1,-5,-9,AIR)
Block(-1,-5,-8,AIR)
Block(-1,-5,-7,AIR)
Block(-1,-5,-6,SANDSTONE)
Block(-1,-5,-5,AIR)
Block(-1,-5,-4,AIR)
Block(-1,-5,-3,AIR)
Block(-1,-5,-2,SANDSTONE:1)
Block(-1,-5,-1,AIR)
Block(-1,-5,0,AIR)
Block(-1,-5,1,SANDSTONE)
Block(-1,-4,-13,SANDSTONE)
Block(-1,-4,-12,AIR)
Block(-1,-4,-11,AIR)
Block(-1,-4,-10,AIR)
Block(-1,-4,-9,AIR)
Block(-1,-4,-8,AIR)
Block(-1,-4,-7,AIR)
Block(-1,-4,-6,SANDSTONE:2)
Block(-1,-4,-5,AIR)
Block(-1,-4,-4,AIR)
Block(-1,-4,-3,AIR)
Block(-1,-4,-2,SANDSTONE:2)
Block(-1,-4,-1,AIR)
Block(-1,-4,0,AIR)
Block(-1,-4,1,SANDSTONE)
Block(-1,-3,-13,SANDSTONE)
Block(-1,-3,-12,AIR)
Block(-1,-3,-11,AIR)
Block(-1,-3,-10,AIR)
Block(-1,-3,-9,AIR)
Block(-1,-3,-8,AIR)
Block(-1,-3,-7,AIR)
Block(-1,-3,-6,SANDSTONE)
Block(-1,-3,-5,AIR)
Block(-1,-3,-4,AIR)
Block(-1,-3,-3,AIR)
Block(-1,-3,-2,SANDSTONE:2)
Block(-1,-3,-1,AIR)
Block(-1,-3,0,AIR)
Block(-1,-3,1,SANDSTONE)
Block(-1,-2,-13,SANDSTONE)
Block(-1,-2,-12,AIR)
Block(-1,-2,-11,AIR)
Block(-1,-2,-10,AIR)
Block(-1,-2,-9,AIR)
Block(-1,-2,-8,AIR)
Block(-1,-2,-7,AIR)
Block(-1,-2,-6,SANDSTONE)
Block(-1,-2,-5,AIR)
Block(-1,-2,-4,AIR)
Block(-1,-2,-3,SANDSTONE)
Block(-1,-2,-2,SANDSTONE)
Block(-1,-2,-1,AIR)
Block(-1,-2,0,AIR)
Block(-1,-2,1,SANDSTONE:2)
Block(-1,-1,-13,SANDSTONE:1)
Block(-1,-1,-12,SANDSTONE)
Block(-1,-1,-11,AIR)
Block(-1,-1,-10,AIR)
Block(-1,-1,-9,AIR)
Block(-1,-1,-8,AIR)
Block(-1,-1,-7,SANDSTONE)
Block(-1,-1,-6,SANDSTONE:2)
Block(-1,-1,-5,SANDSTONE:1)
Block(-1,-1,-4,SANDSTONE:1)
Block(-1,-1,-3,SANDSTONE:2)
Block(-1,-1,-2,SANDSTONE)
Block(-1,-1,-1,AIR)
Block(-1,-1,0,AIR)
Block(-1,-1,1,SANDSTONE:1)
Block(-1,0,-12,SANDSTONE:2)
Block(-1,0,-11,SANDSTONE)
Block(-1,0,-10,SANDSTONE)
Block(-1,0,-9,SANDSTONE)
Block(-1,0,-8,SANDSTONE)
Block(-1,0,-7,SANDSTONE:2)
Block(-1,0,-6,SANDSTONE)
Block(-1,0,-5,SANDSTONE)
Block(-1,0,-4,SANDSTONE:2)
Block(-1,0,-3,SANDSTONE)
Block(-1,0,-2,SANDSTONE)
Block(-1,0,-1,SANDSTONE:2)
Block(-1,0,0,SANDSTONE:1)
Block(-1,1,-6,SANDSTONE)
Block(-1,1,-5,AIR)
Block(-1,1,-4,AIR)
Block(-1,1,-3,SANDSTONE)
Block(-1,1,-2,SANDSTONE)
Block(-1,1,-1,SANDSTONE:2)
Block(-1,1,0,SANDSTONE)
Block(-1,2,-6,SANDSTONE:2)
Block(-1,2,-5,AIR)
Block(-1,2,-4,AIR)
Block(-1,2,-3,AIR)
Block(-1,2,-2,SANDSTONE:1)
Block(-1,2,-1,SANDSTONE)
Block(-1,2,0,SANDSTONE)
Block(-1,3,-6,SANDSTONE:1)
Block(-1,3,-5,AIR)
Block(-1,3,-4,AIR)
Block(-1,3,-3,AIR)
Block(-1,3,-2,AIR)
Block(-1,3,-1,AIR)
Block(-1,3,0,SANDSTONE:1)
Block(-1,4,-6,SANDSTONE)
Block(-1,4,-5,SANDSTONE:2)
Block(-1,4,-4,AIR)
Block(-1,4,-3,AIR)
Block(-1,4,-2,AIR)
Block(-1,4,-1,AIR)
Block(-1,4,0,SANDSTONE)
Block(-1,5,-6,SANDSTONE)
Block(-1,5,-5,AIR)
Block(-1,5,-4,SANDSTONE:1)
Block(-1,5,-3,AIR)
Block(-1,5,-2,AIR)
Block(-1,5,-1,AIR)
Block(-1,5,0,SANDSTONE:2)
Block(-1,6,-6,SANDSTONE:2)
Block(-1,6,-5,SANDSTONE:1)
Block(-1,6,-4,SANDSTONE)
Block(-1,6,-3,SANDSTONE)
Block(-1,6,-2,AIR)
Block(-1,6,-1,AIR)
Block(-1,6,0,SANDSTONE)
Block(-1,7,-6,SANDSTONE:1)
Block(-1,7,-5,AIR)
Block(-1,7,-4,AIR)
Block(-1,7,-3,SANDSTONE:2)
Block(-1,7,-2,AIR)
Block(-1,7,-1,AIR)
Block(-1,7,0,SANDSTONE:1)
Block(-1,8,-6,SANDSTONE)
Block(-1,8,-5,SANDSTONE:2)
Block(-1,8,-4,SANDSTONE)
Block(-1,8,-3,SANDSTONE)
Block(-1,8,-2,SANDSTONE)
Block(-1,8,-1,SANDSTONE)
Block(-1,8,0,SANDSTONE:1)
Block(-1,9,-6,SANDSTONE:1)
Block(-1,9,-5,VINE:4)
Block(-1,9,-4,AIR)
Block(-1,9,-3,AIR)
Block(-1,9,-2,AIR)
Block(-1,9,-1,AIR)
Block(-1,9,0,SANDSTONE)
Block(-1,10,-6,SANDSTONE)
Block(-1,10,-5,VINE:4)
Block(-1,10,-4,AIR)
Block(-1,10,-3,AIR)
Block(-1,10,-2,AIR)
Block(-1,10,-1,AIR)
Block(-1,10,0,SANDSTONE:2)
Block(-1,11,-6,SANDSTONE)
Block(-1,11,-5,AIR)
Block(-1,11,-4,AIR)
Block(-1,11,-3,AIR)
Block(-1,11,-2,AIR)
Block(-1,11,-1,AIR)
Block(-1,11,0,SANDSTONE:2)
Block(-1,12,-6,SANDSTONE)
Block(-1,12,-5,AIR)
Block(-1,12,-4,AIR)
Block(-1,12,-3,AIR)
Block(-1,12,-2,AIR)
Block(-1,12,-1,AIR)
Block(-1,12,0,SANDSTONE:2)
Block(-1,13,-6,SANDSTONE)
Block(-1,13,-5,SANDSTONE)
Block(-1,13,-4,SANDSTONE:1)
Block(-1,13,-3,SANDSTONE)
Block(-1,13,-2,SANDSTONE)
Block(-1,13,-1,SANDSTONE)
Block(-1,13,0,SANDSTONE)
Block(-1,14,-6,SANDSTONE:1)
Block(-1,14,0,SANDSTONE)
Block(0,-8,-12,SANDSTONE:1)
Block(0,-8,-11,SANDSTONE)
Block(0,-8,-10,SANDSTONE:2)
Block(0,-8,-9,MOB_SPAWNER,../../nbt/Spawner/Zombie.nbt)
Block(0,-8,-8,SANDSTONE:1)
Block(0,-8,-7,SANDSTONE)
Block(0,-8,-6,SANDSTONE:1)
Block(0,-8,-5,SANDSTONE)
Block(0,-8,-4,SANDSTONE)
Block(0,-8,-3,SANDSTONE)
Block(0,-8,-2,SANDSTONE)
Block(0,-8,-1,SANDSTONE)
Block(0,-8,0,SANDSTONE)
Block(0,-7,-13,SANDSTONE:2)
Block(0,-7,-12,SANDSTONE)
Block(0,-7,-11,AIR)
Block(0,-7,-10,AIR)
Block(0,-7,-9,AIR)
Block(0,-7,-8,AIR)
Block(0,-7,-7,AIR)
Block(0,-7,-6,AIR)
Block(0,-7,-5,AIR)
Block(0,-7,-4,AIR)
Block(0,-7,-3,AIR)
Block(0,-7,-2,SANDSTONE:2)
Block(0,-7,1,SANDSTONE)
Block(0,-6,-13,SANDSTONE)
Block(0,-6,-12,AIR)
Block(0,-6,-11,AIR)
Block(0,-6,-10,AIR)
Block(0,-6,-9,AIR)
Block(0,-6,-8,AIR)
Block(0,-6,-7,AIR)
Block(0,-6,-6,AIR)
Block(0,-6,-5,AIR)
Block(0,-6,-4,AIR)
Block(0,-6,-3,AIR)
Block(0,-6,-2,SANDSTONE)
Block(0,-6,-1,SANDSTONE:2)
Block(0,-6,1,SANDSTONE:2)
Block(0,-5,-13,SANDSTONE)
Block(0,-5,-12,AIR)
Block(0,-5,-11,AIR)
Block(0,-5,-10,AIR)
Block(0,-5,-9,AIR)
Block(0,-5,-8,AIR)
Block(0,-5,-7,AIR)
Block(0,-5,-6,SANDSTONE)
Block(0,-5,-5,AIR)
Block(0,-5,-4,AIR)
Block(0,-5,-3,AIR)
Block(0,-5,-2,SANDSTONE)
Block(0,-5,-1,SANDSTONE:1)
Block(0,-5,0,SANDSTONE)
Block(0,-5,1,SANDSTONE)
Block(0,-4,-13,SANDSTONE)
Block(0,-4,-12,VINE:4)
Block(0,-4,-11,AIR)
Block(0,-4,-10,AIR)
Block(0,-4,-9,AIR)
Block(0,-4,-8,AIR)
Block(0,-4,-7,AIR)
Block(0,-4,-6,IRON_FENCE)
Block(0,-4,-5,AIR)
Block(0,-4,-4,AIR)
Block(0,-4,-3,AIR)
Block(0,-4,-2,SANDSTONE)
Block(0,-4,-1,AIR)
Block(0,-4,0,AIR)
Block(0,-4,1,SANDSTONE)
Block(0,-3,-13,SANDSTONE)
Block(0,-3,-12,AIR)
Block(0,-3,-11,AIR)
Block(0,-3,-10,AIR)
Block(0,-3,-9,AIR)
Block(0,-3,-8,AIR)
Block(0,-3,-7,AIR)
Block(0,-3,-6,SANDSTONE:2)
Block(0,-3,-5,AIR)
Block(0,-3,-4,AIR)
Block(0,-3,-3,AIR)
Block(0,-3,-2,SANDSTONE)
Block(0,-3,-1,AIR)
Block(0,-3,0,AIR)
Block(0,-3,1,SANDSTONE)
Block(0,-2,-13,SANDSTONE)
Block(0,-2,-12,AIR)
Block(0,-2,-11,AIR)
Block(0,-2,-10,AIR)
Block(0,-2,-9,AIR)
Block(0,-2,-8,AIR)
Block(0,-2,-7,AIR)
Block(0,-2,-6,SANDSTONE)
Block(0,-2,-5,AIR)
Block(0,-2,-4,AIR)
Block(0,-2,-3,SANDSTONE)
Block(0,-2,-2,SANDSTONE:2)
Block(0,-2,-1,AIR)
Block(0,-2,0,AIR)
Block(0,-2,1,SANDSTONE)
Block(0,-1,-13,SANDSTONE)
Block(0,-1,-12,SANDSTONE:1)
Block(0,-1,-11,AIR)
Block(0,-1,-10,AIR)
Block(0,-1,-9,AIR)
Block(0,-1,-8,AIR)
Block(0,-1,-7,SANDSTONE)
Block(0,-1,-6,SANDSTONE:2)
Block(0,-1,-5,SANDSTONE)
Block(0,-1,-4,SANDSTONE:1)
Block(0,-1,-3,SANDSTONE)
Block(0,-1,-2,SANDSTONE)
Block(0,-1,-1,AIR)
Block(0,-1,0,AIR)
Block(0,-1,1,SANDSTONE)
Block(0,0,-12,SANDSTONE:2)
Block(0,0,-11,SANDSTONE)
Block(0,0,-10,SANDSTONE:2)
Block(0,0,-9,SANDSTONE)
Block(0,0,-8,SANDSTONE)
Block(0,0,-7,SANDSTONE)
Block(0,0,-6,SANDSTONE)
Block(0,0,-5,AIR)
Block(0,0,-4,AIR)
Block(0,0,-3,SANDSTONE:1)
Block(0,0,-2,SANDSTONE:2)
Block(0,0,-1,SANDSTONE:1)
Block(0,0,0,SANDSTONE)
Block(0,1,-6,SANDSTONE:2)
Block(0,1,-5,AIR)
Block(0,1,-4,AIR)
Block(0,1,-3,SANDSTONE:2)
Block(0,1,-2,SANDSTONE)
Block(0,1,-1,SANDSTONE)
Block(0,1,0,SANDSTONE)
Block(0,2,-6,SANDSTONE)
Block(0,2,-5,AIR)
Block(0,2,-4,AIR)
Block(0,2,-3,SANDSTONE)
Block(0,2,-2,SANDSTONE)
Block(0,2,-1,SANDSTONE:2)
Block(0,2,0,SANDSTONE:2)
Block(0,3,-6,SANDSTONE:2)
Block(0,3,-5,AIR)
Block(0,3,-4,AIR)
Block(0,3,-3,SANDSTONE)
Block(0,3,-2,SANDSTONE:2)
Block(0,3,-1,SANDSTONE)
Block(0,3,0,SANDSTONE:1)
Block(0,4,-6,SANDSTONE:1)
Block(0,4,-5,SANDSTONE)
Block(0,4,-4,SANDSTONE)
Block(0,4,-3,SANDSTONE:1)
Block(0,4,-2,AIR)
Block(0,4,-1,AIR)
Block(0,4,0,SANDSTONE:2)
Block(0,5,-6,SANDSTONE:2)
Block(0,5,-5,AIR)
Block(0,5,-4,AIR)
Block(0,5,-3,SANDSTONE:1)
Block(0,5,-2,AIR)
Block(0,5,-1,AIR)
Block(0,5,0,SANDSTONE)
Block(0,6,-6,SANDSTONE)
Block(0,6,-5,SANDSTONE)
Block(0,6,-4,SANDSTONE:2)
Block(0,6,-3,SANDSTONE)
Block(0,6,-2,AIR)
Block(0,6,-1,AIR)
Block(0,6,0,SANDSTONE:2)
Block(0,7,-6,SANDSTONE)
Block(0,7,-5,AIR)
Block(0,7,-4,AIR)
Block(0,7,-3,SANDSTONE)
Block(0,7,-2,AIR)
Block(0,7,-1,AIR)
Block(0,7,0,SANDSTONE)
Block(0,8,-6,SANDSTONE:2)
Block(0,8,-5,SANDSTONE)
Block(0,8,-4,SANDSTONE:2)
Block(0,8,-3,SANDSTONE:1)
Block(0,8,-2,SANDSTONE:1)
Block(0,8,-1,SANDSTONE)
Block(0,8,0,SANDSTONE)
Block(0,9,-6,SANDSTONE)
Block(0,9,-5,AIR)
Block(0,9,-4,AIR)
Block(0,9,-3,AIR)
Block(0,9,-2,AIR)
Block(0,9,-1,AIR)
Block(0,9,0,SANDSTONE)
Block(0,10,-6,SANDSTONE)
Block(0,10,-5,VINE:4)
Block(0,10,-4,AIR)
Block(0,10,-3,AIR)
Block(0,10,-2,AIR)
Block(0,10,-1,VINE:1)
Block(0,10,0,SANDSTONE)
Block(0,11,-6,SANDSTONE:1)
Block(0,11,-5,VINE:4)
Block(0,11,-4,AIR)
Block(0,11,-3,AIR)
Block(0,11,-2,AIR)
Block(0,11,-1,AIR)
Block(0,11,0,SANDSTONE:1)
Block(0,12,-6,SANDSTONE)
Block(0,12,-5,AIR)
Block(0,12,-4,AIR)
Block(0,12,-3,AIR)
Block(0,12,-2,AIR)
Block(0,12,-1,AIR)
Block(0,12,0,SANDSTONE)
Block(0,13,-6,SANDSTONE:1)
Block(0,13,-5,SANDSTONE:2)
Block(0,13,-4,SANDSTONE)
Block(0,13,-3,TRAP_DOOR:8)
Block(0,13,-2,SANDSTONE)
Block(0,13,-1,SANDSTONE)
Block(0,13,0,SANDSTONE:2)
Block(0,14,-6,SANDSTONE)
Block(0,14,0,SANDSTONE:1)
Block(1,-8,-12,SANDSTONE:2)
Block(1,-8,-11,SANDSTONE)
Block(1,-8,-10,SANDSTONE)
Block(1,-8,-9,SANDSTONE)
Block(1,-8,-8,SANDSTONE)
Block(1,-8,-7,SANDSTONE:2)
Block(1,-8,-6,SANDSTONE:2)
Block(1,-8,-5,SANDSTONE)
Block(1,-8,-4,SANDSTONE:1)
Block(1,-8,-3,SANDSTONE)
Block(1,-8,-2,SANDSTONE:2)
Block(1,-8,-1,SANDSTONE)
Block(1,-8,0,SANDSTONE:2)
Block(1,-7,-13,SANDSTONE)
Block(1,-7,-12,SANDSTONE)
Block(1,-7,-11,AIR)
Block(1,-7,-10,AIR)
Block(1,-7,-9,AIR)
Block(1,-7,-8,AIR)
Block(1,-7,-7,SANDSTONE)
Block(1,-7,-6,SANDSTONE)
Block(1,-7,-5,AIR)
Block(1,-7,-4,AIR)
Block(1,-7,-3,AIR)
Block(1,-7,-2,SANDSTONE)
Block(1,-7,0,SANDSTONE)
Block(1,-7,1,SANDSTONE:2)
Block(1,-6,-13,SANDSTONE)
Block(1,-6,-12,AIR)
Block(1,-6,-11,AIR)
Block(1,-6,-10,AIR)
Block(1,-6,-9,AIR)
Block(1,-6,-8,AIR)
Block(1,-6,-7,AIR)
Block(1,-6,-6,SANDSTONE)
Block(1,-6,-5,AIR)
Block(1,-6,-4,AIR)
Block(1,-6,-3,AIR)
Block(1,-6,-2,SANDSTONE:2)
Block(1,-6,-1,SANDSTONE)
Block(1,-6,0,SANDSTONE)
Block(1,-6,1,SANDSTONE:2)
Block(1,-5,-13,SANDSTONE)
Block(1,-5,-12,AIR)
Block(1,-5,-11,AIR)
Block(1,-5,-10,AIR)
Block(1,-5,-9,AIR)
Block(1,-5,-8,AIR)
Block(1,-5,-7,AIR)
Block(1,-5,-6,SANDSTONE)
Block(1,-5,-5,AIR)
Block(1,-5,-4,AIR)
Block(1,-5,-3,AIR)
Block(1,-5,-2,TORCH:4)
Block(1,-5,-1,SANDSTONE)
Block(1,-5,0,SANDSTONE)
Block(1,-5,1,SANDSTONE:2)
Block(1,-4,-13,SANDSTONE)
Block(1,-4,-12,AIR)
Block(1,-4,-11,AIR)
Block(1,-4,-10,AIR)
Block(1,-4,-9,AIR)
Block(1,-4,-8,AIR)
Block(1,-4,-7,AIR)
Block(1,-4,-6,SANDSTONE:2)
Block(1,-4,-5,AIR)
Block(1,-4,-4,AIR)
Block(1,-4,-3,AIR)
Block(1,-4,-2,SANDSTONE)
Block(1,-4,-1,SANDSTONE)
Block(1,-4,0,SANDSTONE)
Block(1,-4,1,SANDSTONE:1)
Block(1,-3,-13,SANDSTONE)
Block(1,-3,-12,AIR)
Block(1,-3,-11,AIR)
Block(1,-3,-10,AIR)
Block(1,-3,-9,AIR)
Block(1,-3,-8,AIR)
Block(1,-3,-7,VINE:1)
Block(1,-3,-6,SANDSTONE)
Block(1,-3,-5,AIR)
Block(1,-3,-4,AIR)
Block(1,-3,-3,AIR)
Block(1,-3,-2,SANDSTONE)
Block(1,-3,-1,AIR)
Block(1,-3,0,AIR)
Block(1,-3,1,SANDSTONE:2)
Block(1,-2,-13,SANDSTONE)
Block(1,-2,-12,AIR)
Block(1,-2,-11,AIR)
Block(1,-2,-10,AIR)
Block(1,-2,-9,AIR)
Block(1,-2,-8,AIR)
Block(1,-2,-7,AIR)
Block(1,-2,-6,SANDSTONE)
Block(1,-2,-5,AIR)
Block(1,-2,-4,AIR)
Block(1,-2,-3,SANDSTONE)
Block(1,-2,-2,AIR)
Block(1,-2,-1,AIR)
Block(1,-2,0,AIR)
Block(1,-2,1,SANDSTONE)
Block(1,-1,-13,SANDSTONE)
Block(1,-1,-12,SANDSTONE)
Block(1,-1,-11,AIR)
Block(1,-1,-10,AIR)
Block(1,-1,-9,AIR)
Block(1,-1,-8,AIR)
Block(1,-1,-7,SANDSTONE)
Block(1,-1,-6,SANDSTONE)
Block(1,-1,-5,SANDSTONE:2)
Block(1,-1,-4,SANDSTONE)
Block(1,-1,-3,AIR)
Block(1,-1,-2,AIR)
Block(1,-1,-1,AIR)
Block(1,-1,0,AIR)
Block(1,-1,1,SANDSTONE)
Block(1,0,-12,SANDSTONE:2)
Block(1,0,-11,SANDSTONE)
Block(1,0,-10,SANDSTONE)
Block(1,0,-9,SANDSTONE)
Block(1,0,-8,SANDSTONE)
Block(1,0,-7,SANDSTONE:2)
Block(1,0,-6,SANDSTONE:2)
Block(1,0,-5,AIR)
Block(1,0,-4,AIR)
Block(1,0,-3,AIR)
Block(1,0,-2,AIR)
Block(1,0,-1,AIR)
Block(1,0,0,SANDSTONE)
Block(1,1,-6,SANDSTONE:2)
Block(1,1,-5,AIR)
Block(1,1,-4,AIR)
Block(1,1,-3,AIR)
Block(1,1,-2,AIR)
Block(1,1,-1,SANDSTONE:1)
Block(1,1,0,SANDSTONE)
Block(1,2,-6,SANDSTONE:1)
Block(1,2,-5,AIR)
Block(1,2,-4,AIR)
Block(1,2,-3,AIR)
Block(1,2,-2,SANDSTONE)
Block(1,2,-1,SANDSTONE)
Block(1,2,0,SANDSTONE)
Block(1,3,-6,SANDSTONE)
Block(1,3,-5,AIR)
Block(1,3,-4,AIR)
Block(1,3,-3,SANDSTONE:1)
Block(1,3,-2,SANDSTONE)
Block(1,3,-1,SANDSTONE)
Block(1,3,0,SANDSTONE)
Block(1,4,-6,SANDSTONE)
Block(1,4,-5,SANDSTONE)
Block(1,4,-4,SANDSTONE:2)
Block(1,4,-3,SANDSTONE)
Block(1,4,-2,SANDSTONE:2)
Block(1,4,-1,SANDSTONE)
Block(1,4,0,SANDSTONE:2)
Block(1,5,-6,SANDSTONE:2)
Block(1,5,-5,AIR)
Block(1,5,-4,AIR)
Block(1,5,-3,SANDSTONE)
Block(1,5,-2,AIR)
Block(1,5,-1,AIR)
Block(1,5,0,SANDSTONE)
Block(1,6,-6,SANDSTONE:1)
Block(1,6,-5,SANDSTONE:1)
Block(1,6,-4,SANDSTONE:2)
Block(1,6,-3,SANDSTONE:1)
Block(1,6,-2,AIR)
Block(1,6,-1,AIR)
Block(1,6,0,SANDSTONE:2)
Block(1,7,-6,SANDSTONE)
Block(1,7,-5,AIR)
Block(1,7,-4,AIR)
Block(1,7,-3,SANDSTONE:2)
Block(1,7,-2,AIR)
Block(1,7,-1,AIR)
Block(1,7,0,SANDSTONE)
Block(1,8,-6,SANDSTONE)
Block(1,8,-5,SANDSTONE)
Block(1,8,-4,SANDSTONE:2)
Block(1,8,-3,SANDSTONE:1)
Block(1,8,-2,SANDSTONE)
Block(1,8,-1,SANDSTONE:2)
Block(1,8,0,SANDSTONE:2)
Block(1,9,-6,SANDSTONE:2)
Block(1,9,-5,AIR)
Block(1,9,-4,AIR)
Block(1,9,-3,AIR)
Block(1,9,-2,AIR)
Block(1,9,-1,AIR)
Block(1,9,0,SANDSTONE:1)
Block(1,10,-6,SANDSTONE:1)
Block(1,10,-5,AIR)
Block(1,10,-4,AIR)
Block(1,10,-3,AIR)
Block(1,10,-2,AIR)
Block(1,10,-1,AIR)
Block(1,10,0,SANDSTONE:1)
Block(1,11,-6,SANDSTONE:1)
Block(1,11,-5,AIR)
Block(1,11,-4,AIR)
Block(1,11,-3,AIR)
Block(1,11,-2,AIR)
Block(1,11,-1,AIR)
Block(1,11,0,SANDSTONE)
Block(1,12,-6,SANDSTONE:2)
Block(1,12,-5,AIR)
Block(1,12,-4,AIR)
Block(1,12,-3,AIR)
Block(1,12,-2,AIR)
Block(1,12,-1,AIR)
Block(1,12,0,SANDSTONE)
Block(1,13,-6,SANDSTONE:1)
Block(1,13,-5,SANDSTONE:1)
Block(1,13,-4,SANDSTONE)
Block(1,13,-3,SANDSTONE)
Block(1,13,-2,SANDSTONE)
Block(1,13,-1,SANDSTONE:2)
Block(1,13,0,SANDSTONE)
Block(1,14,-6,SANDSTONE)
Block(1,14,0,SANDSTONE)
Block(2,-8,-12,SANDSTONE)
Block(2,-8,-11,SANDSTONE:2)
Block(2,-8,-10,SANDSTONE)
Block(2,-8,-9,SANDSTONE)
Block(2,-8,-8,SANDSTONE:1)
Block(2,-8,-7,SANDSTONE)
Block(2,-8,-6,SANDSTONE)
Block(2,-8,-5,SANDSTONE)
Block(2,-8,-4,SANDSTONE:2)
Block(2,-8,-3,SANDSTONE)
Block(2,-8,-2,SANDSTONE)
Block(2,-8,-1,SANDSTONE)
Block(2,-8,0,SANDSTONE:2)
Block(2,-7,-13,SANDSTONE:2)
Block(2,-7,-12,SANDSTONE:2)
Block(2,-7,-11,AIR)
Block(2,-7,-10,AIR)
Block(2,-7,-9,AIR)
Block(2,-7,-8,AIR)
Block(2,-7,-7,SANDSTONE)
Block(2,-7,-6,SANDSTONE:1)
Block(2,-7,-5,AIR)
Block(2,-7,-4,AIR)
Block(2,-7,-3,AIR)
Block(2,-7,-2,SANDSTONE)
Block(2,-7,1,SANDSTONE:1)
Block(2,-6,-13,SANDSTONE:2)
Block(2,-6,-12,AIR)
Block(2,-6,-11,AIR)
Block(2,-6,-10,AIR)
Block(2,-6,-9,AIR)
Block(2,-6,-8,AIR)
Block(2,-6,-7,AIR)
Block(2,-6,-6,STEP:5)
Block(2,-6,-5,AIR)
Block(2,-6,-4,AIR)
Block(2,-6,-3,AIR)
Block(2,-6,-2,SANDSTONE:1)
Block(2,-6,-1,SANDSTONE:2)
Block(2,-6,0,SANDSTONE:1)
Block(2,-6,1,SANDSTONE)
Block(2,-5,-13,SANDSTONE:1)
Block(2,-5,-12,AIR)
Block(2,-5,-11,AIR)
Block(2,-5,-10,AIR)
Block(2,-5,-9,AIR)
Block(2,-5,-8,AIR)
Block(2,-5,-7,VINE:9)
Block(2,-5,-6,SANDSTONE:1)
Block(2,-5,-5,AIR)
Block(2,-5,-4,AIR)
Block(2,-5,-3,AIR)
Block(2,-5,-2,SANDSTONE:2)
Block(2,-5,-1,SANDSTONE:1)
Block(2,-5,0,SANDSTONE)
Block(2,-5,1,SANDSTONE:1)
Block(2,-4,-13,SANDSTONE:2)
Block(2,-4,-12,AIR)
Block(2,-4,-11,AIR)
Block(2,-4,-10,AIR)
Block(2,-4,-9,AIR)
Block(2,-4,-8,AIR)
Block(2,-4,-7,VINE:9)
Block(2,-4,-6,SANDSTONE)
Block(2,-4,-5,AIR)
Block(2,-4,-4,AIR)
Block(2,-4,-3,AIR)
Block(2,-4,-2,SANDSTONE)
Block(2,-4,-1,SANDSTONE)
Block(2,-4,0,SANDSTONE:2)
Block(2,-4,1,SANDSTONE:1)
Block(2,-3,-13,SANDSTONE)
Block(2,-3,-12,AIR)
Block(2,-3,-11,AIR)
Block(2,-3,-10,AIR)
Block(2,-3,-9,AIR)
Block(2,-3,-8,AIR)
Block(2,-3,-7,AIR)
Block(2,-3,-6,SANDSTONE)
Block(2,-3,-5,AIR)
Block(2,-3,-4,AIR)
Block(2,-3,-3,AIR)
Block(2,-3,-2,SANDSTONE:1)
Block(2,-3,-1,AIR)
Block(2,-3,0,AIR)
Block(2,-3,1,SANDSTONE)
Block(2,-2,-13,SANDSTONE)
Block(2,-2,-12,AIR)
Block(2,-2,-11,AIR)
Block(2,-2,-10,AIR)
Block(2,-2,-9,AIR)
Block(2,-2,-8,AIR)
Block(2,-2,-7,AIR)
Block(2,-2,-6,SANDSTONE)
Block(2,-2,-5,AIR)
Block(2,-2,-4,AIR)
Block(2,-2,-3,SANDSTONE)
Block(2,-2,-2,AIR)
Block(2,-2,-1,AIR)
Block(2,-2,0,AIR)
Block(2,-2,1,SANDSTONE)
Block(2,-1,-13,SANDSTONE:2)
Block(2,-1,-12,SANDSTONE)
Block(2,-1,-11,AIR)
Block(2,-1,-10,AIR)
Block(2,-1,-9,AIR)
Block(2,-1,-8,AIR)
Block(2,-1,-7,SANDSTONE:1)
Block(2,-1,-6,SANDSTONE:2)
Block(2,-1,-5,SANDSTONE)
Block(2,-1,-4,SANDSTONE:2)
Block(2,-1,-3,AIR)
Block(2,-1,-2,AIR)
Block(2,-1,-1,AIR)
Block(2,-1,0,AIR)
Block(2,-1,1,SANDSTONE:2)
Block(2,0,-12,SANDSTONE)
Block(2,0,-11,SANDSTONE:1)
Block(2,0,-10,SANDSTONE)
Block(2,0,-9,SANDSTONE)
Block(2,0,-8,SANDSTONE:2)
Block(2,0,-7,SANDSTONE)
Block(2,0,-6,SANDSTONE)
Block(2,0,-5,SANDSTONE:2)
Block(2,0,-4,AIR)
Block(2,0,-3,AIR)
Block(2,0,-2,AIR)
Block(2,0,-1,AIR)
Block(2,0,0,SANDSTONE:2)
Block(2,1,-5,SANDSTONE)
Block(2,1,-4,AIR)
Block(2,1,-3,AIR)
Block(2,1,-2,AIR)
Block(2,1,-1,SANDSTONE)
Block(2,2,-5,SANDSTONE)
Block(2,2,-4,AIR)
Block(2,2,-3,AIR)
Block(2,2,-2,SANDSTONE)
Block(2,2,-1,SANDSTONE)
Block(2,3,-5,SANDSTONE)
Block(2,3,-4,SANDSTONE)
Block(2,3,-3,SANDSTONE:2)
Block(2,3,-2,SANDSTONE:1)
Block(2,3,-1,SANDSTONE)
Block(2,4,-5,SANDSTONE:1)
Block(2,4,-4,SANDSTONE)
Block(2,4,-3,SANDSTONE:2)
Block(2,4,-2,SANDSTONE)
Block(2,4,-1,SANDSTONE)
Block(2,5,-5,SANDSTONE:1)
Block(2,5,-4,SANDSTONE)
Block(2,5,-3,SANDSTONE:1)
Block(2,5,-2,SANDSTONE)
Block(2,5,-1,SANDSTONE:1)
Block(2,6,-5,SANDSTONE:2)
Block(2,6,-4,SANDSTONE)
Block(2,6,-3,SANDSTONE:1)
Block(2,6,-2,AIR)
Block(2,6,-1,SANDSTONE:1)
Block(2,7,-5,SANDSTONE)
Block(2,7,-4,SANDSTONE:1)
Block(2,7,-3,AIR)
Block(2,7,-2,AIR)
Block(2,7,-1,SANDSTONE)
Block(2,8,-5,SANDSTONE)
Block(2,8,-4,AIR)
Block(2,8,-3,AIR)
Block(2,8,-2,AIR)
Block(2,8,-1,SANDSTONE:2)
Block(2,9,-5,SANDSTONE)
Block(2,9,-4,AIR)
Block(2,9,-3,AIR)
Block(2,9,-2,AIR)
Block(2,9,-1,SANDSTONE:1)
Block(2,10,-5,SANDSTONE)
Block(2,10,-4,AIR)
Block(2,10,-3,AIR)
Block(2,10,-2,AIR)
Block(2,10,-1,SANDSTONE:1)
Block(2,11,-5,SANDSTONE:2)
Block(2,11,-4,AIR)
Block(2,11,-3,AIR)
Block(2,11,-2,AIR)
Block(2,11,-1,SANDSTONE)
Block(2,12,-5,SANDSTONE:1)
Block(2,12,-4,AIR)
Block(2,12,-3,AIR)
Block(2,12,-2,AIR)
Block(2,12,-1,SANDSTONE)
Block(2,13,-5,SANDSTONE)
Block(2,13,-4,SANDSTONE:2)
Block(2,13,-3,SANDSTONE:1)
Block(2,13,-2,SANDSTONE)
Block(2,13,-1,SANDSTONE)
Block(2,14,-5,SANDSTONE)
Block(2,14,-1,SANDSTONE)
Block(3,-8,-12,SANDSTONE:1)
Block(3,-8,-11,SANDSTONE:2)
Block(3,-8,-10,SANDSTONE)
Block(3,-8,-9,SANDSTONE)
Block(3,-8,-8,SANDSTONE)
Block(3,-8,-7,SANDSTONE)
Block(3,-8,-6,SANDSTONE:2)
Block(3,-8,-5,SANDSTONE:1)
Block(3,-8,-4,SANDSTONE)
Block(3,-8,-3,SANDSTONE)
Block(3,-8,-2,SANDSTONE:2)
Block(3,-8,-1,SANDSTONE)
Block(3,-8,0,SANDSTONE)
Block(3,-7,-13,SANDSTONE)
Block(3,-7,-12,SANDSTONE:2)
Block(3,-7,-11,SANDSTONE)
Block(3,-7,-10,SANDSTONE)
Block(3,-7,-9,SANDSTONE)
Block(3,-7,-8,SANDSTONE)
Block(3,-7,-7,SANDSTONE:1)
Block(3,-7,-6,AIR)
Block(3,-7,-5,AIR)
RandomBlock(3,-7,-4,CHEST:4,../../nbt/Chests/Chest1.nbt,4,CHEST:3,../../nbt/Chests/Chest2.nbt,4,CHEST:3,../../nbt/Chests/Chest3.nbt,4,CHEST:3,../../nbt/Chests/Chest4.nbt,4,CHEST:3,../../nbt/Chests/Chest5.nbt,4,CHEST:3,../../nbt/Chests/Chest6.nbt,4,CHEST:3,../../nbt/Chests/Chest7.nbt,4,CHEST:3,../../nbt/Chests/Chest8.nbt,4,CHEST:3,../../nbt/Chests/Chest9.nbt,4,CHEST:3,../../nbt/Chests/Chest10.nbt,4,CHEST:3,../../nbt/Chests/Chest11.nbt,4,CHEST:3,../../nbt/Chests/Chest12.nbt,4,CHEST:3,../../nbt/Chests/Chest13.nbt,4,CHEST:3,../../nbt/Chests/Chest14.nbt,4,CHEST:3,../../nbt/Chests/Chest15.nbt,4,0,40)
Block(3,-7,-3,AIR)
Block(3,-7,-2,SANDSTONE:1)
Block(3,-7,1,SANDSTONE)
Block(3,-6,-13,SANDSTONE)
Block(3,-6,-12,SANDSTONE:2)
Block(3,-6,-11,VINE:12)
Block(3,-6,-10,VINE:8)
Block(3,-6,-9,AIR)
Block(3,-6,-8,VINE:9)
Block(3,-6,-7,SANDSTONE:2)
Block(3,-6,-6,AIR)
Block(3,-6,-5,AIR)
Block(3,-6,-4,AIR)
Block(3,-6,-3,AIR)
Block(3,-6,-2,SANDSTONE:1)
Block(3,-6,1,SANDSTONE)
Block(3,-5,-13,SANDSTONE)
Block(3,-5,-12,SANDSTONE)
Block(3,-5,-11,AIR)
Block(3,-5,-10,VINE:8)
Block(3,-5,-9,AIR)
Block(3,-5,-8,VINE:9)
Block(3,-5,-7,SANDSTONE)
Block(3,-5,-6,AIR)
Block(3,-5,-5,AIR)
Block(3,-5,-4,AIR)
Block(3,-5,-3,AIR)
Block(3,-5,-2,SANDSTONE)
Block(3,-5,-1,SANDSTONE)
Block(3,-5,0,SANDSTONE)
Block(3,-5,1,SANDSTONE)
Block(3,-4,-13,SANDSTONE:2)
Block(3,-4,-12,SANDSTONE)
Block(3,-4,-11,AIR)
Block(3,-4,-10,AIR)
Block(3,-4,-9,AIR)
Block(3,-4,-8,VINE:9)
Block(3,-4,-7,SANDSTONE:2)
Block(3,-4,-6,AIR)
Block(3,-4,-5,AIR)
Block(3,-4,-4,AIR)
Block(3,-4,-3,AIR)
Block(3,-4,-2,SANDSTONE:1)
Block(3,-4,-1,SANDSTONE)
Block(3,-4,0,SANDSTONE)
Block(3,-4,1,SANDSTONE)
Block(3,-3,-13,SANDSTONE)
Block(3,-3,-12,SANDSTONE)
Block(3,-3,-11,AIR)
Block(3,-3,-10,AIR)
Block(3,-3,-9,AIR)
Block(3,-3,-8,AIR)
Block(3,-3,-7,SANDSTONE)
Block(3,-3,-6,AIR)
Block(3,-3,-5,AIR)
Block(3,-3,-4,AIR)
Block(3,-3,-3,AIR)
Block(3,-3,-2,SANDSTONE)
Block(3,-3,-1,SANDSTONE)
Block(3,-3,0,SANDSTONE)
Block(3,-3,1,SANDSTONE)
Block(3,-2,-13,SANDSTONE:1)
Block(3,-2,-12,SANDSTONE)
Block(3,-2,-11,WEB)
Block(3,-2,-10,AIR)
Block(3,-2,-9,AIR)
Block(3,-2,-8,AIR)
Block(3,-2,-7,SANDSTONE:2)
Block(3,-2,-6,AIR)
Block(3,-2,-5,AIR)
Block(3,-2,-4,AIR)
Block(3,-2,-3,SANDSTONE)
Block(3,-2,-2,SANDSTONE)
Block(3,-2,-1,SANDSTONE:2)
Block(3,-2,0,SANDSTONE:2)
Block(3,-2,1,SANDSTONE:1)
Block(3,-1,-13,SANDSTONE)
Block(3,-1,-12,SANDSTONE:1)
Block(3,-1,-11,SANDSTONE:2)
Block(3,-1,-10,SANDSTONE:2)
Block(3,-1,-9,SANDSTONE)
Block(3,-1,-8,SANDSTONE:1)
Block(3,-1,-7,SANDSTONE:2)
Block(3,-1,-6,SANDSTONE)
Block(3,-1,-5,SANDSTONE)
Block(3,-1,-4,SANDSTONE)
Block(3,-1,-3,SANDSTONE:2)
Block(3,-1,-2,SANDSTONE:2)
Block(3,-1,-1,SANDSTONE)
Block(3,-1,0,SANDSTONE)
Block(3,-1,1,SANDSTONE:1)
Block(3,0,-12,SANDSTONE:1)
Block(3,0,-11,SANDSTONE:2)
Block(3,0,-10,SANDSTONE)
Block(3,0,-9,SANDSTONE)
Block(3,0,-8,SANDSTONE)
Block(3,0,-7,SANDSTONE)
Block(3,0,-6,SANDSTONE:2)
Block(3,0,-5,SANDSTONE)
Block(3,0,-4,SANDSTONE)
Block(3,0,-3,SANDSTONE)
Block(3,0,-2,SANDSTONE)
Block(3,0,-1,SANDSTONE)
Block(3,0,0,SANDSTONE)
Block(3,1,-4,SANDSTONE:1)
Block(3,1,-3,SANDSTONE:2)
Block(3,1,-2,SANDSTONE:2)
Block(3,2,-4,SANDSTONE:2)
Block(3,2,-3,SANDSTONE:1)
Block(3,2,-2,SANDSTONE:2)
Block(3,3,-4,SANDSTONE)
Block(3,3,-3,SANDSTONE)
Block(3,3,-2,SANDSTONE)
Block(3,4,-4,SANDSTONE)
Block(3,4,-3,SANDSTONE:2)
Block(3,4,-2,SANDSTONE)
Block(3,5,-4,SANDSTONE:1)
Block(3,5,-3,SANDSTONE)
Block(3,5,-2,SANDSTONE:2)
Block(3,6,-4,SANDSTONE:2)
Block(3,6,-3,SANDSTONE:2)
Block(3,6,-2,SANDSTONE)
Block(3,7,-4,SANDSTONE)
Block(3,7,-3,SANDSTONE)
Block(3,7,-2,SANDSTONE)
Block(3,8,-4,SANDSTONE:1)
Block(3,8,-3,SANDSTONE:2)
Block(3,8,-2,SANDSTONE:1)
Block(3,9,-4,SANDSTONE:1)
Block(3,9,-3,SANDSTONE:1)
Block(3,9,-2,SANDSTONE)
Block(3,10,-4,SANDSTONE)
Block(3,10,-3,SANDSTONE)
Block(3,10,-2,SANDSTONE)
Block(3,11,-4,SANDSTONE)
Block(3,11,-3,SANDSTONE:1)
Block(3,11,-2,SANDSTONE)
Block(3,12,-4,SANDSTONE:2)
Block(3,12,-3,SANDSTONE:2)
Block(3,12,-2,SANDSTONE)
Block(3,13,-4,SANDSTONE)
Block(3,13,-3,SANDSTONE:1)
Block(3,13,-2,SANDSTONE:1)
Block(3,14,-4,SANDSTONE)
Block(3,14,-3,SANDSTONE)
Block(3,14,-2,SANDSTONE:2)
Block(4,-7,-12,SANDSTONE:1)
Block(4,-7,-11,SANDSTONE:1)
Block(4,-7,-10,SANDSTONE)
Block(4,-7,-9,SANDSTONE:1)
Block(4,-7,-8,SANDSTONE:2)
Block(4,-7,-7,SANDSTONE)
Block(4,-7,-6,SANDSTONE)
Block(4,-7,-5,SANDSTONE)
Block(4,-7,-4,SANDSTONE:2)
Block(4,-7,-3,SANDSTONE)
Block(4,-7,-2,SANDSTONE)
Block(4,-7,-1,SANDSTONE:2)
Block(4,-7,0,SANDSTONE:2)
Block(4,-7,1,SANDSTONE)
Block(4,-6,-12,SANDSTONE:2)
Block(4,-6,-11,SANDSTONE:1)
Block(4,-6,-10,SANDSTONE)
Block(4,-6,-9,SANDSTONE)
Block(4,-6,-8,SANDSTONE)
Block(4,-6,-7,SANDSTONE:2)
Block(4,-6,-6,SANDSTONE)
Block(4,-6,-5,SANDSTONE)
Block(4,-6,-4,SANDSTONE:2)
Block(4,-6,-3,SANDSTONE:1)
Block(4,-6,-2,SANDSTONE)
Block(4,-6,-1,SANDSTONE)
Block(4,-6,0,SANDSTONE)
Block(4,-6,1,SANDSTONE)
Block(4,-5,-12,SANDSTONE:2)
Block(4,-5,-11,SANDSTONE:1)
Block(4,-5,-10,SANDSTONE:1)
Block(4,-5,-9,SANDSTONE)
Block(4,-5,-8,SANDSTONE:1)
Block(4,-5,-7,SANDSTONE:1)
Block(4,-5,-6,SANDSTONE:1)
Block(4,-5,-5,SANDSTONE)
Block(4,-5,-4,SANDSTONE)
Block(4,-5,-3,SANDSTONE:2)
Block(4,-5,-2,SANDSTONE)
Block(4,-5,-1,SANDSTONE)
Block(4,-5,0,SANDSTONE)
Block(4,-5,1,SANDSTONE)
Block(4,-4,-12,SANDSTONE)
Block(4,-4,-11,SANDSTONE:1)
Block(4,-4,-10,SANDSTONE)
Block(4,-4,-9,SANDSTONE:1)
Block(4,-4,-8,SANDSTONE)
Block(4,-4,-7,SANDSTONE:2)
Block(4,-4,-6,SANDSTONE:2)
Block(4,-4,-5,SANDSTONE)
Block(4,-4,-4,SANDSTONE)
Block(4,-4,-3,SANDSTONE:2)
Block(4,-4,-2,SANDSTONE:2)
Block(4,-4,-1,SANDSTONE:1)
Block(4,-4,0,SANDSTONE:1)
Block(4,-4,1,SANDSTONE)
Block(4,-3,-12,SANDSTONE:1)
Block(4,-3,-11,SANDSTONE:1)
Block(4,-3,-10,SANDSTONE:1)
Block(4,-3,-9,SANDSTONE)
Block(4,-3,-8,SANDSTONE)
Block(4,-3,-7,SANDSTONE)
Block(4,-3,-6,SANDSTONE:1)
Block(4,-3,-5,SANDSTONE)
Block(4,-3,-4,SANDSTONE)
Block(4,-3,-3,SANDSTONE:2)
Block(4,-3,-2,SANDSTONE)
Block(4,-3,-1,SANDSTONE)
Block(4,-3,0,SANDSTONE:2)
Block(4,-3,1,SANDSTONE:1)
Block(4,-2,-12,SANDSTONE)
Block(4,-2,-11,SANDSTONE:2)
Block(4,-2,-10,SANDSTONE)
Block(4,-2,-9,SANDSTONE)
Block(4,-2,-8,SANDSTONE)
Block(4,-2,-7,SANDSTONE:2)
Block(4,-2,-6,SANDSTONE)
Block(4,-2,-5,SANDSTONE)
Block(4,-2,-4,SANDSTONE:1)
Block(4,-2,-3,SANDSTONE)
Block(4,-2,-2,SANDSTONE)
Block(4,-2,-1,SANDSTONE)
Block(4,-2,0,SANDSTONE)
Block(4,-2,1,SANDSTONE)
Block(4,-1,-12,SANDSTONE:2)
Block(4,-1,-11,SANDSTONE:1)
Block(4,-1,-10,SANDSTONE)
Block(4,-1,-9,SANDSTONE)
Block(4,-1,-8,SANDSTONE:1)
Block(4,-1,-7,SANDSTONE)
Block(4,-1,-6,SANDSTONE)
Block(4,-1,-5,SANDSTONE)
Block(4,-1,-4,SANDSTONE:1)
Block(4,-1,-3,SANDSTONE)
Block(4,-1,-2,SANDSTONE)
Block(4,-1,-1,SANDSTONE)
Block(4,-1,0,SANDSTONE:1)
Block(4,-1,1,SANDSTONE)

#######################################################################
# +-----------------------------------------------------------------+ #
# |                            BO3 checks                           | #
# +-----------------------------------------------------------------+ #
#######################################################################

# Require a condition at a certain location in order for the BO3 to be spawned.
# BlockCheck(x,y,z,BlockName[,BlockName[,...]]) - one of the blocks must be at the location
# BlockCheckNot(x,y,z,BlockName[,BlockName[,...]]) - all the blocks must not be at the location
# LightCheck(x,y,z,minLightLevel,maxLightLevel) - light must be between min and max (inclusive)

# You can use "Solid" as a BlockName for matching all solid blocks or "All" to match all blocks that aren't air.

# Examples:
#   BlockCheck(0,-1,0,GRASS,DIRT)  Require grass or dirt just below the object
#   BlockCheck(0,-1,0,Solid)       Require any solid block just below the object
#   BlockCheck(0,-1,0,WOOL)        Require any type of wool just below the object
#   BlockCheck(0,-1,0,WOOL:0)      Require white wool just below the object
#   BlockCheckNot(0,-1,0,WOOL:0)   Require that there is no white wool below the object
#   LightCheck(0,0,0,0,1)          Require almost complete darkness just below the object

#######################################################################
# +-----------------------------------------------------------------+ #
# |                             Branches                            | #
# +-----------------------------------------------------------------+ #
#######################################################################

# Branches are objects that will spawn when this object spawns when it is used in
# the CustomStructure resource. Branches can also have branches, making complex
# structures possible. See the wiki for more details.

# Regular Branches spawn each branch with an independent chance of spawning.
# Branch(x,y,z,branchName,rotation,chance[,anotherBranchName,rotation,chance[,...]][IndividualChance])
# branchName - name of the object to spawn.
# rotation - NORTH, SOUTH, EAST or WEST.
# IndividualChance - The chance each branch has to spawn, assumed to be 100 when left blank

# Weighted Branches spawn branches with a dependent chance of spawning.
# WeightedBranch(x,y,z,branchName,rotation,chance[,anotherBranchName,rotation,chance[,...]][MaxChanceOutOf])
# MaxChanceOutOf - The chance all branches have to spawn out of, assumed to be 100 when left blank
