
#######################################################################
# +-----------------------------------------------------------------+ #
# |                            BO3 object                           | #
# +-----------------------------------------------------------------+ #
#######################################################################

# This is the config file of a custom object.
# If you add this object correctly to your BiomeConfigs, it will spawn in the world.

# This is the creator of this BO3 object
Author: LordSmellyPants

# A short description of this BO3 object
Description: No description given

# The BO3 version, don't change this! It can be used by external applications to do a version check.
Version: 3

# The settings mode, WriteAll, WriteWithoutComments or WriteDisable. See WorldConfig.
SettingsMode: WriteDisable


#######################################################################
# +-----------------------------------------------------------------+ #
# |                          Main settings                          | #
# +-----------------------------------------------------------------+ #
#######################################################################

# This needs to be set to true to spawn the object in the Tree and Sapling resources.
Tree: true

# The frequency of the BO3 from 1 to 200. Tries this many times to spawn this BO3 when using the CustomObject(...) resource.
# Ignored by Tree(..), Sapling(..) and CustomStructure(..)
Frequency: 1

# The rarity of the BO3 from 0 to 100. Each spawn attempt has rarity% chance to succeed when using the CustomObject(...) resource.
# Ignored by Tree(..), Sapling(..) and CustomStructure(..)
Rarity: 100.0

# If you set this to true, the BO3 will be placed with a random rotation.
RotateRandomly: false

# The spawn height of the BO3 - randomY, highestBlock or highestSolidBlock.
SpawnHeight: highestSolidBlock

# The height limits for the BO3.
MinHeight: 0

MaxHeight: 256

# Objects can have other objects attacthed to it: branches. Branches can also
# have branches attached to it, which can also have branches, etc. This is the
# maximum branch depth for this objects.
MaxBranchDepth: 10

# When spawned with the UseWorld keyword, this BO3 should NOT spawn in the following biomes.
# If you writer.write the BO3 name directly in the BiomeConfigs, this will be ignored.
ExcludedBiomes: All


#######################################################################
# +-----------------------------------------------------------------+ #
# |                      Source block settings                      | #
# +-----------------------------------------------------------------+ #
#######################################################################

# The block(s) the BO3 should spawn in.
SourceBlocks: AIR

# The maximum percentage of the BO3 that can be outside the SourceBlock.
# The BO3 won't be placed on a location with more blocks outside the SourceBlock than this percentage.
MaxPercentageOutsideSourceBlock: 100

# What to do when a block is about to be placed outside the SourceBlock? (dontPlace, placeAnyway)
OutsideSourceBlock: placeAnyway


#######################################################################
# +-----------------------------------------------------------------+ #
# |                              Blocks                             | #
# +-----------------------------------------------------------------+ #
#######################################################################

# All the blocks used in the BO3 are listed here. Possible blocks:
# Block(x,y,z,id[.data][,nbtfile.nbt)
# RandomBlock(x,y,z,id[:data][,nbtfile.nbt],chance[,id[:data][,nbtfile.nbt],chance[,...]])
# So RandomBlock(0,0,0,CHEST,chest.nbt,50,CHEST,anotherchest.nbt,100) will spawn a chest at
# the BO3 origin, and give it a 50% chance to have the contents of chest.nbt, or, if that
# fails, a 100% percent chance to have the contents of anotherchest.nbt.
Block(-3,-10,-8,COBBLESTONE)
Block(-3,-10,-7,COBBLESTONE)
Block(-3,-10,-6,COBBLESTONE)
Block(-3,-10,-5,COBBLESTONE)
Block(-3,-10,-4,COBBLESTONE)
Block(-3,-10,-3,COBBLESTONE)
Block(-3,-10,-2,COBBLESTONE)
Block(-3,-10,-1,SMOOTH_BRICK)
Block(-3,-10,0,SMOOTH_BRICK)
Block(-3,-10,1,COBBLESTONE)
Block(-3,-10,2,COBBLESTONE)
Block(-3,-10,3,SMOOTH_BRICK)
Block(-3,-9,-8,COBBLESTONE)
Block(-3,-9,-7,COBBLESTONE)
Block(-3,-9,-6,COBBLESTONE)
Block(-3,-9,-5,COBBLESTONE)
Block(-3,-9,-4,COBBLESTONE)
Block(-3,-9,-3,COBBLESTONE)
Block(-3,-9,-2,COBBLESTONE)
Block(-3,-9,-1,SMOOTH_BRICK)
Block(-3,-9,0,SMOOTH_BRICK)
Block(-3,-9,1,COBBLESTONE)
Block(-3,-9,2,COBBLESTONE)
Block(-3,-9,3,SMOOTH_BRICK)
Block(-3,-8,-8,COBBLESTONE)
Block(-3,-8,-7,COBBLESTONE)
Block(-3,-8,-6,COBBLESTONE)
Block(-3,-8,-5,COBBLESTONE)
Block(-3,-8,-4,COBBLESTONE)
Block(-3,-8,-3,COBBLESTONE)
Block(-3,-8,-2,COBBLESTONE)
Block(-3,-8,-1,SMOOTH_BRICK)
Block(-3,-8,0,SMOOTH_BRICK)
Block(-3,-8,1,COBBLESTONE)
Block(-3,-8,2,COBBLESTONE)
Block(-3,-8,3,SMOOTH_BRICK)
Block(-3,-7,-8,COBBLESTONE)
Block(-3,-7,-7,COBBLESTONE)
Block(-3,-7,-6,COBBLESTONE)
Block(-3,-7,-5,COBBLESTONE)
Block(-3,-7,-4,COBBLESTONE)
Block(-3,-7,-3,COBBLESTONE)
Block(-3,-7,-2,COBBLESTONE)
Block(-3,-7,-1,SMOOTH_BRICK)
Block(-3,-7,0,SMOOTH_BRICK)
Block(-3,-7,1,AIR)
Block(-3,-7,2,COBBLESTONE)
Block(-3,-7,3,SMOOTH_BRICK)
Block(-3,-6,-8,COBBLESTONE)
Block(-3,-6,-7,COBBLESTONE)
Block(-3,-6,-6,COBBLESTONE)
Block(-3,-6,-5,COBBLESTONE)
Block(-3,-6,-4,COBBLESTONE)
Block(-3,-6,-3,COBBLESTONE)
Block(-3,-6,-2,COBBLESTONE)
Block(-3,-6,-1,SMOOTH_BRICK)
Block(-3,-6,0,SMOOTH_BRICK)
Block(-3,-6,1,COBBLESTONE)
Block(-3,-6,2,COBBLESTONE)
Block(-3,-6,3,SMOOTH_BRICK)
Block(-3,-5,-8,COBBLESTONE)
Block(-3,-5,-7,COBBLESTONE)
Block(-3,-5,-6,COBBLESTONE)
Block(-3,-5,-5,COBBLESTONE)
Block(-3,-5,-4,COBBLESTONE)
Block(-3,-5,-3,COBBLESTONE)
Block(-3,-5,-2,COBBLESTONE)
Block(-3,-5,-1,SMOOTH_BRICK)
Block(-3,-5,0,SMOOTH_BRICK)
Block(-3,-5,1,COBBLESTONE)
Block(-3,-5,2,COBBLESTONE)
Block(-3,-5,3,SMOOTH_BRICK)
Block(-3,-4,-8,COBBLESTONE)
Block(-3,-4,-7,COBBLESTONE)
Block(-3,-4,-6,COBBLESTONE)
Block(-3,-4,-5,COBBLESTONE)
Block(-3,-4,-4,COBBLESTONE)
Block(-3,-4,-3,COBBLESTONE)
Block(-3,-4,-2,COBBLESTONE)
Block(-3,-4,-1,SMOOTH_BRICK)
Block(-3,-4,0,SMOOTH_BRICK)
Block(-3,-4,1,COBBLESTONE)
Block(-3,-4,2,COBBLESTONE)
Block(-3,-4,3,SMOOTH_BRICK)
Block(-3,-3,-8,COBBLESTONE)
Block(-3,-3,-7,COBBLESTONE)
Block(-3,-3,-6,COBBLESTONE)
Block(-3,-3,-5,COBBLESTONE)
Block(-3,-3,-4,COBBLESTONE)
Block(-3,-3,-3,COBBLESTONE)
Block(-3,-3,-2,COBBLESTONE)
Block(-3,-3,-1,SMOOTH_BRICK)
Block(-3,-3,0,SMOOTH_BRICK)
Block(-3,-3,1,COBBLESTONE)
Block(-3,-3,2,COBBLESTONE)
Block(-3,-3,3,SMOOTH_BRICK)
Block(-3,-2,-8,COBBLESTONE)
Block(-3,-2,-7,COBBLESTONE)
Block(-3,-2,-6,COBBLESTONE)
Block(-3,-2,-5,COBBLESTONE)
Block(-3,-2,-4,COBBLESTONE)
Block(-3,-2,-3,COBBLESTONE)
Block(-3,-2,-2,COBBLESTONE)
Block(-3,-2,-1,SMOOTH_BRICK)
Block(-3,-2,0,SMOOTH_BRICK)
Block(-3,-2,1,COBBLESTONE)
Block(-3,-2,2,COBBLESTONE)
Block(-3,-2,3,SMOOTH_BRICK)
Block(-3,-1,-7,SMOOTH_BRICK)
Block(-3,-1,-6,SMOOTH_BRICK)
Block(-3,-1,-5,SMOOTH_BRICK)
Block(-3,-1,-4,SMOOTH_BRICK)
Block(-3,-1,-3,SMOOTH_BRICK)
Block(-3,-1,-2,SMOOTH_BRICK)
Block(-3,-1,-1,SMOOTH_BRICK)
Block(-3,-1,0,SMOOTH_BRICK)
Block(-3,-1,1,SMOOTH_BRICK)
Block(-3,-1,2,SMOOTH_BRICK)
Block(-3,-1,3,SMOOTH_BRICK)
Block(-3,0,-1,STEP)
Block(-3,0,0,LEAVES:1)
Block(-3,0,1,STEP)
Block(-3,0,2,STEP)
Block(-3,0,3,STEP)
Block(-3,1,-1,LEAVES:1)
Block(-3,1,1,LEAVES:1)
Block(-3,1,3,LEAVES:1)
Block(-3,2,1,LEAVES:1)
Block(-3,2,2,LEAVES:1)
Block(-3,3,-1,LEAVES:1)
Block(-3,3,0,LEAVES:1)
Block(-3,4,-6,WOOD_STAIRS:2)
Block(-3,4,-5,WOOD)
Block(-3,4,-2,LEAVES:1)
Block(-3,4,-1,LEAVES:1)
Block(-3,4,1,WOOD)
Block(-3,4,2,WOOD_STAIRS:3)
Block(-3,5,-5,WOOD)
Block(-3,5,-2,LEAVES:1)
Block(-3,5,1,WOOD)
Block(-3,6,-5,WOOD_STAIRS:2)
Block(-3,6,-4,WOOD_STAIRS:7)
Block(-3,6,-3,LEAVES:1)
Block(-3,6,0,WOOD_STAIRS:6)
Block(-3,6,1,WOOD_STAIRS:3)
Block(-3,7,-4,WOOD)
Block(-3,7,-3,WOOD_STAIRS:7)
Block(-3,7,-1,WOOD_STAIRS:6)
Block(-3,7,0,WOOD)
Block(-3,8,-4,WOOD_STAIRS:2)
Block(-3,8,-3,WOOD)
Block(-3,8,-1,WOOD)
Block(-3,8,0,WOOD_STAIRS:3)
Block(-3,9,-3,WOOD)
Block(-3,9,-1,WOOD)
Block(-3,10,-3,WOOD_STAIRS:2)
Block(-3,10,-2,WOOD)
Block(-3,10,-1,WOOD_STAIRS:3)
Block(-2,-10,-8,COBBLESTONE)
Block(-2,-10,-7,COBBLESTONE)
Block(-2,-10,-6,COBBLESTONE)
Block(-2,-10,-5,COBBLESTONE)
Block(-2,-10,-4,COBBLESTONE)
Block(-2,-10,-3,COBBLESTONE)
Block(-2,-10,-2,COBBLESTONE)
Block(-2,-10,-1,COBBLESTONE)
Block(-2,-10,0,COBBLESTONE)
Block(-2,-10,1,COBBLESTONE)
Block(-2,-10,2,COBBLESTONE)
Block(-2,-10,3,COBBLESTONE)
Block(-2,-9,-8,COBBLESTONE)
Block(-2,-9,-7,COBBLESTONE)
Block(-2,-9,-6,COBBLESTONE)
Block(-2,-9,-5,COBBLESTONE)
Block(-2,-9,-4,COBBLESTONE)
Block(-2,-9,-3,COBBLESTONE)
Block(-2,-9,-2,COBBLESTONE)
Block(-2,-9,-1,COBBLESTONE)
Block(-2,-9,0,COBBLESTONE)
Block(-2,-9,1,COBBLESTONE)
Block(-2,-9,2,COBBLESTONE)
Block(-2,-9,3,COBBLESTONE)
Block(-2,-8,-8,COBBLESTONE)
Block(-2,-8,-7,COBBLESTONE)
Block(-2,-8,-6,COBBLESTONE)
Block(-2,-8,-5,COBBLESTONE)
Block(-2,-8,-4,COBBLESTONE)
Block(-2,-8,-3,COBBLESTONE)
Block(-2,-8,-2,COBBLESTONE)
Block(-2,-8,-1,COBBLESTONE)
Block(-2,-8,0,COBBLESTONE)
Block(-2,-8,1,COBBLESTONE)
Block(-2,-8,2,COBBLESTONE)
Block(-2,-8,3,COBBLESTONE)
Block(-2,-7,-8,COBBLESTONE)
Block(-2,-7,-7,COBBLESTONE)
Block(-2,-7,-6,COBBLESTONE)
Block(-2,-7,-5,COBBLESTONE)
Block(-2,-7,-4,COBBLESTONE)
Block(-2,-7,-3,COBBLESTONE)
Block(-2,-7,-2,COBBLESTONE)
Block(-2,-7,-1,COBBLESTONE)
Block(-2,-7,0,COBBLESTONE)
RandomBlock(-2,-7,1,GRAVEL,50,0,50)
Block(-2,-7,2,COBBLESTONE)
Block(-2,-7,3,COBBLESTONE)
Block(-2,-6,-8,COBBLESTONE)
Block(-2,-6,-7,COBBLESTONE)
Block(-2,-6,-6,COBBLESTONE)
Block(-2,-6,-5,COBBLESTONE)
Block(-2,-6,-4,COBBLESTONE)
Block(-2,-6,-3,COBBLESTONE)
Block(-2,-6,-2,COBBLESTONE)
Block(-2,-6,-1,COBBLESTONE)
Block(-2,-6,0,COBBLESTONE)
Block(-2,-6,1,COBBLESTONE)
Block(-2,-6,2,COBBLESTONE)
Block(-2,-6,3,COBBLESTONE)
Block(-2,-5,-8,COBBLESTONE)
Block(-2,-5,-7,COBBLESTONE)
Block(-2,-5,-6,COBBLESTONE)
Block(-2,-5,-5,COBBLESTONE)
Block(-2,-5,-4,COBBLESTONE)
Block(-2,-5,-3,COBBLESTONE)
Block(-2,-5,-2,COBBLESTONE)
Block(-2,-5,-1,IRON_FENCE)
Block(-2,-5,0,COBBLESTONE)
Block(-2,-5,1,COBBLESTONE)
Block(-2,-5,2,COBBLESTONE)
Block(-2,-5,3,COBBLESTONE)
Block(-2,-4,-8,COBBLESTONE)
Block(-2,-4,-7,COBBLESTONE)
Block(-2,-4,-6,COBBLESTONE)
Block(-2,-4,-5,COBBLESTONE)
Block(-2,-4,-4,COBBLESTONE)
Block(-2,-4,-3,COBBLESTONE)
Block(-2,-4,-2,COBBLESTONE)
Block(-2,-4,-1,COBBLESTONE)
Block(-2,-4,0,COBBLESTONE)
Block(-2,-4,1,COBBLESTONE)
Block(-2,-4,2,COBBLESTONE)
Block(-2,-4,3,COBBLESTONE)
Block(-2,-3,-8,COBBLESTONE)
Block(-2,-3,-7,COBBLESTONE)
Block(-2,-3,-6,COBBLESTONE)
Block(-2,-3,-5,COBBLESTONE)
Block(-2,-3,-4,COBBLESTONE)
Block(-2,-3,-3,COBBLESTONE)
Block(-2,-3,-2,COBBLESTONE)
Block(-2,-3,-1,COBBLESTONE)
Block(-2,-3,0,COBBLESTONE)
Block(-2,-3,1,COBBLESTONE)
Block(-2,-3,2,COBBLESTONE)
Block(-2,-3,3,COBBLESTONE)
Block(-2,-2,-8,COBBLESTONE)
Block(-2,-2,-7,COBBLESTONE)
Block(-2,-2,-6,COBBLESTONE)
Block(-2,-2,-5,LOG)
Block(-2,-2,-4,COBBLESTONE)
Block(-2,-2,-3,LOG)
Block(-2,-2,-2,COBBLESTONE)
Block(-2,-2,-1,COBBLESTONE)
Block(-2,-2,0,COBBLESTONE)
Block(-2,-2,1,COBBLESTONE)
Block(-2,-2,2,COBBLESTONE)
Block(-2,-2,3,COBBLESTONE)
Block(-2,-1,-7,SMOOTH_BRICK)
Block(-2,-1,-6,SMOOTH_BRICK)
Block(-2,-1,-5,LOG)
Block(-2,-1,-4,SMOOTH_BRICK)
Block(-2,-1,-3,LOG)
Block(-2,-1,-2,SMOOTH_BRICK)
Block(-2,-1,-1,STONE)
Block(-2,-1,0,STONE)
Block(-2,-1,1,STONE:6)
Block(-2,-1,2,STONE:6)
Block(-2,-1,3,SMOOTH_BRICK)
Block(-2,0,-5,LOG)
Block(-2,0,-3,LOG)
Block(-2,0,-1,LOG)
Block(-2,0,0,WOOD)
Block(-2,0,1,WOOD)
Block(-2,0,2,LOG)
Block(-2,0,3,STEP)
Block(-2,1,-5,LOG)
Block(-2,1,-3,LOG)
Block(-2,1,-1,LOG)
Block(-2,1,0,BRICK)
Block(-2,1,1,BRICK)
Block(-2,1,2,LOG)
Block(-2,1,3,LEAVES:1)
Block(-2,2,-5,LOG)
Block(-2,2,-3,LOG)
Block(-2,2,-1,LOG)
Block(-2,2,0,BRICK)
Block(-2,2,1,BRICK)
Block(-2,2,2,LOG)
Block(-2,3,-5,LOG)
Block(-2,3,-4,LOG)
Block(-2,3,-3,LOG)
Block(-2,3,-2,LOG)
Block(-2,3,-1,LOG)
Block(-2,3,0,LOG)
Block(-2,3,1,LOG)
Block(-2,3,2,LOG)
Block(-2,3,3,WOOD_STAIRS:3)
Block(-2,4,-6,WOOD_STAIRS:2)
Block(-2,4,-5,WOOD)
Block(-2,4,-4,BRICK)
Block(-2,4,-3,LOG)
Block(-2,4,-2,BRICK)
Block(-2,4,-1,LOG)
Block(-2,4,0,BRICK)
Block(-2,4,1,WOOD)
Block(-2,4,2,WOOD_STAIRS:3)
Block(-2,5,-5,WOOD)
Block(-2,5,-4,BRICK)
Block(-2,5,-3,LOG)
Block(-2,5,-2,BRICK)
Block(-2,5,-1,LOG)
Block(-2,5,0,BRICK)
Block(-2,5,1,WOOD)
Block(-2,6,-5,WOOD_STAIRS:2)
Block(-2,6,-4,BRICK)
Block(-2,6,-3,LOG)
Block(-2,6,-2,BRICK)
Block(-2,6,-1,LOG)
Block(-2,6,0,BRICK)
Block(-2,6,1,WOOD_STAIRS:3)
Block(-2,7,-4,WOOD)
Block(-2,7,-3,LOG)
Block(-2,7,-2,BRICK)
Block(-2,7,-1,LOG)
Block(-2,7,0,WOOD)
Block(-2,8,-4,WOOD_STAIRS:2)
Block(-2,8,-3,LOG)
Block(-2,8,-2,BRICK)
Block(-2,8,-1,LOG)
Block(-2,8,0,WOOD_STAIRS:3)
Block(-2,9,-3,WOOD)
Block(-2,9,-2,WOOD)
Block(-2,9,-1,WOOD)
Block(-2,10,-3,WOOD_STAIRS:2)
Block(-2,10,-2,WOOD)
Block(-2,10,-1,WOOD_STAIRS:3)
Block(-1,-10,-8,COBBLESTONE)
Block(-1,-10,-7,COBBLESTONE)
Block(-1,-10,-6,MOSSY_COBBLESTONE)
Block(-1,-10,-5,MOSSY_COBBLESTONE)
Block(-1,-10,-4,DIRT)
Block(-1,-10,-3,MOSSY_COBBLESTONE)
Block(-1,-10,-2,MOSSY_COBBLESTONE)
Block(-1,-10,-1,MOSSY_COBBLESTONE)
RandomBlock(-1,-10,0,GRAVEL,50,0,50)
Block(-1,-10,1,MOSSY_COBBLESTONE)
Block(-1,-10,2,COBBLESTONE)
Block(-1,-10,3,COBBLESTONE)
Block(-1,-9,-8,COBBLESTONE)
Block(-1,-9,-7,COBBLESTONE)
Block(-1,-9,-6,AIR)
Block(-1,-9,-5,AIR)
Block(-1,-9,-4,AIR)
Block(-1,-9,-3,AIR)
Block(-1,-9,-2,COBBLESTONE)
Block(-1,-9,-1,AIR)
Block(-1,-9,0,AIR)
Block(-1,-9,1,AIR)
Block(-1,-9,2,COBBLESTONE)
Block(-1,-9,3,COBBLESTONE)
Block(-1,-8,-8,COBBLESTONE)
Block(-1,-8,-7,COBBLESTONE)
Block(-1,-8,-6,AIR)
Block(-1,-8,-5,AIR)
Block(-1,-8,-4,AIR)
Block(-1,-8,-3,AIR)
Block(-1,-8,-2,COBBLESTONE)
Block(-1,-8,-1,AIR)
Block(-1,-8,0,AIR)
Block(-1,-8,1,AIR)
Block(-1,-8,2,COBBLESTONE)
Block(-1,-8,3,COBBLESTONE)
Block(-1,-7,-8,COBBLESTONE)
Block(-1,-7,-7,COBBLESTONE)
Block(-1,-7,-6,AIR)
Block(-1,-7,-5,AIR)
Block(-1,-7,-4,AIR)
Block(-1,-7,-3,AIR)
Block(-1,-7,-2,COBBLESTONE)
Block(-1,-7,-1,AIR)
Block(-1,-7,0,AIR)
Block(-1,-7,1,AIR)
Block(-1,-7,2,COBBLESTONE)
Block(-1,-7,3,COBBLESTONE)
Block(-1,-6,-8,COBBLESTONE)
Block(-1,-6,-7,COBBLESTONE)
Block(-1,-6,-6,COBBLESTONE)
Block(-1,-6,-5,COBBLESTONE)
Block(-1,-6,-4,COBBLESTONE)
Block(-1,-6,-3,COBBLESTONE)
Block(-1,-6,-2,COBBLESTONE)
Block(-1,-6,-1,AIR)
Block(-1,-6,0,AIR)
Block(-1,-6,1,AIR)
Block(-1,-6,2,COBBLESTONE)
Block(-1,-6,3,COBBLESTONE)
Block(-1,-5,-8,COBBLESTONE)
Block(-1,-5,-7,COBBLESTONE)
Block(-1,-5,-6,COBBLESTONE)
Block(-1,-5,-5,COBBLESTONE)
Block(-1,-5,-4,COBBLESTONE)
Block(-1,-5,-3,COBBLESTONE)
Block(-1,-5,-2,COBBLESTONE)
Block(-1,-5,-1,AIR)
Block(-1,-5,0,AIR)
Block(-1,-5,1,WEB)
Block(-1,-5,2,COBBLESTONE)
Block(-1,-5,3,COBBLESTONE)
Block(-1,-4,-8,COBBLESTONE)
Block(-1,-4,-7,COBBLESTONE)
Block(-1,-4,-6,COBBLESTONE)
Block(-1,-4,-5,COBBLESTONE)
Block(-1,-4,-4,COBBLESTONE)
Block(-1,-4,-3,COBBLESTONE)
Block(-1,-4,-2,COBBLESTONE)
Block(-1,-4,-1,AIR)
Block(-1,-4,0,AIR)
Block(-1,-4,1,AIR)
Block(-1,-4,2,COBBLESTONE)
Block(-1,-4,3,COBBLESTONE)
Block(-1,-3,-8,COBBLESTONE)
Block(-1,-3,-7,COBBLESTONE)
Block(-1,-3,-6,COBBLESTONE)
Block(-1,-3,-5,COBBLESTONE)
Block(-1,-3,-4,COBBLESTONE)
Block(-1,-3,-3,COBBLESTONE)
Block(-1,-3,-2,COBBLESTONE)
Block(-1,-3,-1,WEB)
Block(-1,-3,0,AIR)
Block(-1,-3,1,AIR)
Block(-1,-3,2,COBBLESTONE)
Block(-1,-3,3,COBBLESTONE)
Block(-1,-2,-8,COBBLESTONE)
Block(-1,-2,-7,COBBLESTONE)
Block(-1,-2,-6,COBBLESTONE)
Block(-1,-2,-5,COBBLESTONE)
Block(-1,-2,-4,COBBLESTONE)
Block(-1,-2,-3,COBBLESTONE)
Block(-1,-2,-2,COBBLESTONE)
Block(-1,-2,-1,COBBLESTONE)
Block(-1,-2,0,COBBLESTONE)
Block(-1,-2,1,COBBLESTONE)
Block(-1,-2,2,COBBLESTONE)
Block(-1,-2,3,COBBLESTONE)
Block(-1,-1,-7,SMOOTH_BRICK)
Block(-1,-1,-6,SMOOTH_BRICK)
Block(-1,-1,-5,SMOOTH_BRICK)
Block(-1,-1,-4,SMOOTH_BRICK)
Block(-1,-1,-3,SMOOTH_BRICK)
Block(-1,-1,-2,SMOOTH_BRICK)
Block(-1,-1,-1,WOOD)
Block(-1,-1,0,WOOD)
Block(-1,-1,1,WOOD)
Block(-1,-1,2,STONE:6)
Block(-1,-1,3,SMOOTH_BRICK)
Block(-1,0,-1,WOOD)
Block(-1,0,2,WOOD)
Block(-1,0,3,LEAVES:1)
Block(-1,1,-1,BRICK)
Block(-1,1,2,BRICK)
Block(-1,2,-1,BRICK)
Block(-1,2,2,BRICK)
Block(-1,3,-5,LOG)
Block(-1,3,-4,WOOD)
Block(-1,3,-3,WOOD)
Block(-1,3,-2,WOOD)
Block(-1,3,-1,BRICK)
Block(-1,3,2,BRICK)
Block(-1,3,3,WOOD_STAIRS:3)
Block(-1,4,-6,WOOD_STAIRS:2)
Block(-1,4,-5,WOOD)
Block(-1,4,-4,WOOD)
Block(-1,4,-3,WOOD)
Block(-1,4,-2,WOOD)
Block(-1,4,-1,WOOD)
Block(-1,4,0,WOOD)
Block(-1,4,1,WOOD)
Block(-1,4,2,WOOD_STAIRS:3)
Block(-1,5,-5,WOOD)
RandomBlock(-1,5,-1,MOB_SPAWNER,../../nbt/Spawner/Skeleton.nbt,45,MOB_SPAWNER,../../nbt/Spawner/Zombie.nbt,45,MOB_SPAWNER,../../nbt/Spawner/Spider.nbt,10)
Block(-1,5,1,WOOD)
Block(-1,6,-5,WOOD_STAIRS:2)
Block(-1,6,1,WOOD_STAIRS:3)
Block(-1,7,-4,WOOD)
Block(-1,7,0,WOOD)
Block(-1,8,-4,WOOD_STAIRS:2)
Block(-1,8,0,WOOD_STAIRS:3)
Block(-1,9,-3,WOOD)
Block(-1,9,-2,WEB)
Block(-1,9,-1,WOOD)
Block(-1,10,-3,WOOD_STAIRS:2)
Block(-1,10,-2,WOOD)
Block(-1,10,-1,WOOD_STAIRS:3)
Block(0,-10,-8,COBBLESTONE)
Block(0,-10,-7,COBBLESTONE)
RandomBlock(0,-10,-6,CHEST:3,../../nbt/Chests/Chest1.nbt,3,CHEST:3,../../nbt/Chests/Chest2.nbt,6,CHEST:3,../../nbt/Chests/Chest3.nbt,6,CHEST:3,../../nbt/Chests/Chest4.nbt,6,CHEST:3,../../nbt/Chests/Chest5.nbt,6,CHEST:3,../../nbt/Chests/Chest6.nbt,6,CHEST:3,../../nbt/Chests/Chest7.nbt,6,CHEST:3,../../nbt/Chests/Chest8.nbt,6,CHEST:3,../../nbt/Chests/Chest9.nbt,6,CHEST:3,../../nbt/Chests/Chest10.nbt,6,CHEST:3,../../nbt/Chests/Chest11.nbt,3,CHEST:3,../../nbt/Chests/Chest12.nbt,6,CHEST:3,../../nbt/Chests/Chest13.nbt,3,CHEST:3,../../nbt/Chests/Chest14.nbt,6,CHEST:3,../../nbt/Chests/Chest15.nbt,6,0,19)
Block(0,-10,-5,DIRT)
Block(0,-10,-4,MOSSY_COBBLESTONE)
Block(0,-10,-3,MOSSY_COBBLESTONE)
Block(0,-10,-2,MOSSY_COBBLESTONE)
Block(0,-10,-1,MOSSY_COBBLESTONE)
Block(0,-10,0,MOSSY_COBBLESTONE)
Block(0,-10,1,DIRT)
Block(0,-10,2,COBBLESTONE)
Block(0,-10,3,SMOOTH_BRICK)
Block(0,-9,-8,COBBLESTONE)
Block(0,-9,-7,COBBLESTONE)
RandomBlock(0,-9,-6,MOB_SPAWNER,../../nbt/Spawner/Skeleton.nbt,45,MOB_SPAWNER,../../nbt/Spawner/Zombie.nbt,45,MOB_SPAWNER,../../nbt/Spawner/Spider.nbt,10)
Block(0,-9,-5,AIR)
Block(0,-9,-4,AIR)
Block(0,-9,-3,AIR)
Block(0,-9,-2,IRON_DOOR_BLOCK:3)
Block(0,-9,-1,AIR)
Block(0,-9,0,AIR)
Block(0,-9,1,AIR)
Block(0,-9,2,COBBLESTONE)
Block(0,-9,3,SMOOTH_BRICK)
Block(0,-8,-8,COBBLESTONE)
Block(0,-8,-7,COBBLESTONE)
Block(0,-8,-6,AIR)
Block(0,-8,-5,AIR)
Block(0,-8,-4,AIR)
Block(0,-8,-3,AIR)
Block(0,-8,-2,IRON_DOOR_BLOCK:8)
Block(0,-8,-1,AIR)
Block(0,-8,0,AIR)
Block(0,-8,1,AIR)
Block(0,-8,2,COBBLESTONE)
Block(0,-8,3,SMOOTH_BRICK)
Block(0,-7,-8,COBBLESTONE)
Block(0,-7,-7,COBBLESTONE)
Block(0,-7,-6,AIR)
Block(0,-7,-5,AIR)
Block(0,-7,-4,AIR)
Block(0,-7,-3,AIR)
Block(0,-7,-2,IRON_FENCE)
Block(0,-7,-1,AIR)
Block(0,-7,0,AIR)
Block(0,-7,1,AIR)
Block(0,-7,2,COBBLESTONE)
Block(0,-7,3,SMOOTH_BRICK)
Block(0,-6,-8,COBBLESTONE)
Block(0,-6,-7,COBBLESTONE)
Block(0,-6,-6,COBBLESTONE)
Block(0,-6,-5,COBBLESTONE)
Block(0,-6,-4,COBBLESTONE)
Block(0,-6,-3,COBBLESTONE)
Block(0,-6,-2,COBBLESTONE)
Block(0,-6,-1,AIR)
Block(0,-6,0,AIR)
Block(0,-6,1,AIR)
Block(0,-6,2,COBBLESTONE)
Block(0,-6,3,SMOOTH_BRICK)
Block(0,-5,-8,COBBLESTONE)
Block(0,-5,-7,COBBLESTONE)
Block(0,-5,-6,COBBLESTONE)
Block(0,-5,-5,COBBLESTONE)
Block(0,-5,-4,COBBLESTONE)
Block(0,-5,-3,COBBLESTONE)
Block(0,-5,-2,COBBLESTONE)
Block(0,-5,-1,AIR)
Block(0,-5,0,AIR)
Block(0,-5,1,AIR)
Block(0,-5,2,COBBLESTONE)
Block(0,-5,3,SMOOTH_BRICK)
Block(0,-4,-8,COBBLESTONE)
Block(0,-4,-7,COBBLESTONE)
Block(0,-4,-6,COBBLESTONE)
Block(0,-4,-5,COBBLESTONE)
Block(0,-4,-4,COBBLESTONE)
Block(0,-4,-3,COBBLESTONE)
Block(0,-4,-2,COBBLESTONE)
Block(0,-4,-1,AIR)
Block(0,-4,0,AIR)
Block(0,-4,1,AIR)
Block(0,-4,2,COBBLESTONE)
Block(0,-4,3,SMOOTH_BRICK)
Block(0,-3,-8,COBBLESTONE)
Block(0,-3,-7,COBBLESTONE)
Block(0,-3,-6,COBBLESTONE)
Block(0,-3,-5,COBBLESTONE)
Block(0,-3,-4,COBBLESTONE)
Block(0,-3,-3,COBBLESTONE)
Block(0,-3,-2,COBBLESTONE)
Block(0,-3,-1,AIR)
Block(0,-3,0,AIR)
Block(0,-3,1,AIR)
Block(0,-3,2,COBBLESTONE)
Block(0,-3,3,SMOOTH_BRICK)
Block(0,-2,-8,COBBLESTONE)
Block(0,-2,-7,COBBLESTONE)
Block(0,-2,-6,COBBLESTONE)
Block(0,-2,-5,COBBLESTONE)
Block(0,-2,-4,COBBLESTONE)
Block(0,-2,-3,COBBLESTONE)
Block(0,-2,-2,COBBLESTONE)
Block(0,-2,-1,COBBLESTONE)
Block(0,-2,0,COBBLESTONE)
Block(0,-2,1,COBBLESTONE)
Block(0,-2,2,COBBLESTONE)
Block(0,-2,3,SMOOTH_BRICK)
Block(0,-1,-7,SMOOTH_BRICK)
Block(0,-1,-6,SMOOTH_BRICK)
Block(0,-1,-5,SMOOTH_BRICK)
Block(0,-1,-4,SMOOTH_BRICK)
Block(0,-1,-3,SMOOTH_BRICK)
Block(0,-1,-2,SMOOTH_BRICK)
Block(0,-1,-1,WOOD)
Block(0,-1,0,WOOD)
Block(0,-1,1,WOOD)
Block(0,-1,2,STONE)
Block(0,-1,3,SMOOTH_BRICK)
Block(0,0,-1,WOODEN_DOOR:1)
Block(0,0,2,LOG)
Block(0,0,3,SMOOTH_STAIRS:3)
Block(0,1,-1,WOODEN_DOOR:8)
Block(0,1,2,LOG)
Block(0,2,-1,BRICK)
Block(0,2,2,LOG)
Block(0,3,-5,LOG)
Block(0,3,-4,WOOD)
Block(0,3,-3,WOOD)
Block(0,3,-2,WOOD)
Block(0,3,-1,BRICK)
Block(0,3,2,LOG)
Block(0,3,3,WOOD_STAIRS:3)
Block(0,4,-6,WOOD_STAIRS:2)
Block(0,4,-5,WOOD)
Block(0,4,-4,WOOD)
Block(0,4,-3,WOOD)
Block(0,4,-2,WOOD)
Block(0,4,-1,WOOD)
Block(0,4,0,WOOD)
Block(0,4,1,WOOD)
Block(0,4,2,WOOD_STAIRS:3)
Block(0,5,-5,WOOD)
Block(0,5,-3,BOOKSHELF)
Block(0,5,-1,BOOKSHELF)
Block(0,5,1,WOOD)
Block(0,6,-5,WOOD_STAIRS:2)
Block(0,6,-3,BOOKSHELF)
Block(0,6,-1,BOOKSHELF)
Block(0,6,1,WOOD_STAIRS:3)
Block(0,7,-4,WOOD)
Block(0,7,-3,BOOKSHELF)
Block(0,7,-1,BOOKSHELF)
Block(0,7,0,WOOD)
Block(0,8,-4,WOOD_STAIRS:2)
RandomBlock(0,8,-1,CHEST:3,../../nbt/Chests/Chest1.nbt,3,CHEST:3,../../nbt/Chests/Chest2.nbt,6,CHEST:3,../../nbt/Chests/Chest3.nbt,6,CHEST:3,../../nbt/Chests/Chest4.nbt,6,CHEST:3,../../nbt/Chests/Chest5.nbt,6,CHEST:3,../../nbt/Chests/Chest6.nbt,6,CHEST:3,../../nbt/Chests/Chest7.nbt,6,CHEST:3,../../nbt/Chests/Chest8.nbt,6,CHEST:3,../../nbt/Chests/Chest9.nbt,6,CHEST:3,../../nbt/Chests/Chest10.nbt,6,CHEST:3,../../nbt/Chests/Chest11.nbt,3,CHEST:3,../../nbt/Chests/Chest12.nbt,6,CHEST:3,../../nbt/Chests/Chest13.nbt,3,CHEST:3,../../nbt/Chests/Chest14.nbt,6,CHEST:3,../../nbt/Chests/Chest15.nbt,6,0,19)
Block(0,8,0,WOOD_STAIRS:3)
Block(0,9,-3,WOOD)
Block(0,9,-1,WOOD)
Block(0,10,-3,WOOD_STAIRS:2)
Block(0,10,-2,WOOD)
Block(0,10,-1,WOOD_STAIRS:3)
Block(1,-10,-8,COBBLESTONE)
Block(1,-10,-7,COBBLESTONE)
Block(1,-10,-6,MOSSY_COBBLESTONE)
Block(1,-10,-5,MOSSY_COBBLESTONE)
Block(1,-10,-4,MOSSY_COBBLESTONE)
Block(1,-10,-3,DIRT)
Block(1,-10,-2,MOSSY_COBBLESTONE)
Block(1,-10,-1,MOSSY_COBBLESTONE)
Block(1,-10,0,MOSSY_COBBLESTONE)
Block(1,-10,1,MOSSY_COBBLESTONE)
Block(1,-10,2,COBBLESTONE)
Block(1,-10,3,COBBLESTONE)
Block(1,-9,-8,COBBLESTONE)
Block(1,-9,-7,COBBLESTONE)
Block(1,-9,-6,COBBLESTONE)
Block(1,-9,-5,COBBLESTONE)
Block(1,-9,-4,IRON_FENCE)
Block(1,-9,-3,IRON_FENCE)
Block(1,-9,-2,COBBLESTONE)
Block(1,-9,-1,AIR)
Block(1,-9,0,AIR)
RandomBlock(1,-9,1,SKULL:1,../../nbt/Misc/Skull.nbt,10,CHEST:4,../../nbt/Chests/Chest1.nbt,6,CHEST:3,../../nbt/Chests/Chest2.nbt,6,CHEST:3,../../nbt/Chests/Chest3.nbt,6,CHEST:3,../../nbt/Chests/Chest4.nbt,6,CHEST:3,../../nbt/Chests/Chest5.nbt,6,CHEST:3,../../nbt/Chests/Chest6.nbt,6,CHEST:3,../../nbt/Chests/Chest7.nbt,6,CHEST:3,../../nbt/Chests/Chest8.nbt,6,CHEST:3,../../nbt/Chests/Chest9.nbt,6,CHEST:3,../../nbt/Chests/Chest10.nbt,6,CHEST:3,../../nbt/Chests/Chest11.nbt,6,CHEST:3,../../nbt/Chests/Chest12.nbt,6,CHEST:3,../../nbt/Chests/Chest13.nbt,6,CHEST:3,../../nbt/Chests/Chest14.nbt,6,CHEST:3,../../nbt/Chests/Chest15.nbt,6)
Block(1,-9,2,COBBLESTONE)
Block(1,-9,3,COBBLESTONE)
Block(1,-8,-8,COBBLESTONE)
Block(1,-8,-7,COBBLESTONE)
Block(1,-8,-6,COBBLESTONE)
Block(1,-8,-5,COBBLESTONE)
Block(1,-8,-4,IRON_FENCE)
Block(1,-8,-3,IRON_FENCE)
Block(1,-8,-2,COBBLESTONE)
Block(1,-8,-1,STONE_BUTTON:3)
Block(1,-8,0,AIR)
Block(1,-8,1,AIR)
Block(1,-8,2,COBBLESTONE)
Block(1,-8,3,COBBLESTONE)
Block(1,-7,-8,COBBLESTONE)
Block(1,-7,-7,COBBLESTONE)
Block(1,-7,-6,COBBLESTONE)
Block(1,-7,-5,COBBLESTONE)
Block(1,-7,-4,IRON_FENCE)
Block(1,-7,-3,IRON_FENCE)
Block(1,-7,-2,COBBLESTONE)
Block(1,-7,-1,AIR)
Block(1,-7,0,AIR)
Block(1,-7,1,AIR)
Block(1,-7,2,IRON_FENCE)
Block(1,-7,3,AIR)
Block(1,-6,-8,COBBLESTONE)
Block(1,-6,-7,COBBLESTONE)
Block(1,-6,-6,COBBLESTONE)
Block(1,-6,-5,COBBLESTONE)
Block(1,-6,-4,COBBLESTONE)
Block(1,-6,-3,COBBLESTONE)
Block(1,-6,-2,COBBLESTONE)
Block(1,-6,-1,AIR)
Block(1,-6,0,AIR)
Block(1,-6,1,AIR)
Block(1,-6,2,IRON_FENCE)
Block(1,-6,3,AIR)
Block(1,-5,-8,COBBLESTONE)
Block(1,-5,-7,COBBLESTONE)
Block(1,-5,-6,COBBLESTONE)
Block(1,-5,-5,COBBLESTONE)
Block(1,-5,-4,COBBLESTONE)
Block(1,-5,-3,COBBLESTONE)
Block(1,-5,-2,COBBLESTONE)
Block(1,-5,-1,AIR)
Block(1,-5,0,AIR)
Block(1,-5,1,AIR)
Block(1,-5,2,COBBLESTONE)
Block(1,-5,3,COBBLESTONE)
Block(1,-4,-8,COBBLESTONE)
Block(1,-4,-7,COBBLESTONE)
Block(1,-4,-6,COBBLESTONE)
Block(1,-4,-5,COBBLESTONE)
Block(1,-4,-4,COBBLESTONE)
Block(1,-4,-3,COBBLESTONE)
Block(1,-4,-2,COBBLESTONE)
Block(1,-4,-1,AIR)
Block(1,-4,0,AIR)
Block(1,-4,1,AIR)
Block(1,-4,2,COBBLESTONE)
Block(1,-4,3,COBBLESTONE)
Block(1,-3,-8,COBBLESTONE)
Block(1,-3,-7,COBBLESTONE)
Block(1,-3,-6,COBBLESTONE)
Block(1,-3,-5,COBBLESTONE)
Block(1,-3,-4,COBBLESTONE)
Block(1,-3,-3,COBBLESTONE)
Block(1,-3,-2,COBBLESTONE)
Block(1,-3,-1,AIR)
Block(1,-3,0,AIR)
Block(1,-3,1,AIR)
Block(1,-3,2,COBBLESTONE)
Block(1,-3,3,COBBLESTONE)
Block(1,-2,-8,COBBLESTONE)
Block(1,-2,-7,COBBLESTONE)
Block(1,-2,-6,COBBLESTONE)
Block(1,-2,-5,COBBLESTONE)
Block(1,-2,-4,COBBLESTONE)
Block(1,-2,-3,COBBLESTONE)
Block(1,-2,-2,COBBLESTONE)
Block(1,-2,-1,COBBLESTONE)
Block(1,-2,0,COBBLESTONE)
Block(1,-2,1,COBBLESTONE)
Block(1,-2,2,COBBLESTONE)
Block(1,-2,3,COBBLESTONE)
Block(1,-1,-7,SMOOTH_BRICK)
Block(1,-1,-6,SMOOTH_BRICK)
Block(1,-1,-5,SMOOTH_BRICK)
Block(1,-1,-4,SMOOTH_BRICK)
Block(1,-1,-3,SMOOTH_BRICK)
Block(1,-1,-2,SMOOTH_BRICK)
Block(1,-1,-1,WOOD)
Block(1,-1,0,WOOD)
Block(1,-1,1,WOOD)
Block(1,-1,2,STONE:6)
Block(1,-1,3,SMOOTH_BRICK)
Block(1,0,-7,STEP)
Block(1,0,-6,STEP)
Block(1,0,-5,STEP)
Block(1,0,-4,STEP)
Block(1,0,-3,STEP)
Block(1,0,-2,STEP)
Block(1,0,-1,WOOD)
Block(1,0,2,WOOD)
Block(1,0,3,STEP)
Block(1,1,-1,BRICK)
Block(1,1,2,BRICK)
Block(1,2,-1,BRICK)
Block(1,2,2,BRICK)
Block(1,3,-5,LOG)
Block(1,3,-4,WOOD)
Block(1,3,-3,WOOD)
Block(1,3,-2,WOOD)
Block(1,3,-1,BRICK)
Block(1,3,2,BRICK)
Block(1,3,3,WOOD_STAIRS:3)
Block(1,4,-9,WOOD_STAIRS:2)
Block(1,4,-8,WOOD_STAIRS)
Block(1,4,-7,WOOD_STAIRS)
Block(1,4,-6,WOOD_STAIRS:2)
Block(1,4,-5,WOOD)
Block(1,4,-4,WOOD)
Block(1,4,-3,WOOD)
Block(1,4,-2,WOOD)
Block(1,4,-1,WOOD)
Block(1,4,0,WOOD)
Block(1,4,1,WOOD)
Block(1,4,2,WOOD_STAIRS:3)
Block(1,5,-5,WOOD)
Block(1,5,1,WOOD)
Block(1,6,-5,WOOD_STAIRS:2)
Block(1,6,1,WOOD_STAIRS:3)
Block(1,7,-4,WOOD)
Block(1,7,0,WOOD)
Block(1,8,-4,WOOD_STAIRS:2)
Block(1,8,0,WOOD_STAIRS:3)
Block(1,9,-3,WOOD)
Block(1,9,-1,WOOD)
Block(1,10,-3,WOOD_STAIRS:2)
Block(1,10,-2,WOOD)
Block(1,10,-1,WOOD_STAIRS:3)
Block(2,-10,-8,SMOOTH_BRICK)
Block(2,-10,-7,COBBLESTONE)
Block(2,-10,-6,MOSSY_COBBLESTONE)
Block(2,-10,-5,MOSSY_COBBLESTONE)
Block(2,-10,-4,MOSSY_COBBLESTONE)
Block(2,-10,-3,MOSSY_COBBLESTONE)
Block(2,-10,-2,MOSSY_COBBLESTONE)
Block(2,-10,-1,MOSSY_COBBLESTONE)
RandomBlock(2,-10,0,MOB_SPAWNER,../../nbt/Spawner/Skeleton.nbt,45,MOB_SPAWNER,../../nbt/Spawner/Zombie.nbt,45,MOB_SPAWNER,../../nbt/Spawner/Spider.nbt,10)
Block(2,-10,1,MOSSY_COBBLESTONE)
Block(2,-10,2,COBBLESTONE)
Block(2,-10,3,COBBLESTONE)
Block(2,-9,-8,SMOOTH_BRICK)
Block(2,-9,-7,COBBLESTONE)
Block(2,-9,-6,COBBLESTONE)
RandomBlock(2,-9,-5,GRAVEL,50,0,50)
Block(2,-9,-4,AIR)
Block(2,-9,-3,AIR)
RandomBlock(2,-9,-2,SKULL:1,../../nbt/Misc/Skull.nbt,10,CHEST:4,../../nbt/Chests/Chest1.nbt,6,CHEST:3,../../nbt/Chests/Chest2.nbt,6,CHEST:3,../../nbt/Chests/Chest3.nbt,6,CHEST:3,../../nbt/Chests/Chest4.nbt,6,CHEST:3,../../nbt/Chests/Chest5.nbt,6,CHEST:3,../../nbt/Chests/Chest6.nbt,6,CHEST:3,../../nbt/Chests/Chest7.nbt,6,CHEST:3,../../nbt/Chests/Chest8.nbt,6,CHEST:3,../../nbt/Chests/Chest9.nbt,6,CHEST:3,../../nbt/Chests/Chest10.nbt,6,CHEST:3,../../nbt/Chests/Chest11.nbt,6,CHEST:3,../../nbt/Chests/Chest12.nbt,6,CHEST:3,../../nbt/Chests/Chest13.nbt,6,CHEST:3,../../nbt/Chests/Chest14.nbt,6,CHEST:3,../../nbt/Chests/Chest15.nbt,6)
Block(2,-9,-1,AIR)
Block(2,-9,0,AIR)
RandomBlock(2,-9,1,GRAVEL,50,0,50)
Block(2,-9,2,COBBLESTONE)
Block(2,-9,3,COBBLESTONE)
Block(2,-8,-8,SMOOTH_BRICK)
Block(2,-8,-7,COBBLESTONE)
Block(2,-8,-6,COBBLESTONE)
Block(2,-8,-5,AIR)
Block(2,-8,-4,AIR)
Block(2,-8,-3,AIR)
Block(2,-8,-2,AIR)
Block(2,-8,-1,AIR)
Block(2,-8,0,AIR)
Block(2,-8,1,AIR)
Block(2,-8,2,COBBLESTONE)
Block(2,-8,3,COBBLESTONE)
Block(2,-7,-8,SMOOTH_BRICK)
Block(2,-7,-7,COBBLESTONE)
Block(2,-7,-6,COBBLESTONE)
Block(2,-7,-5,AIR)
Block(2,-7,-4,AIR)
Block(2,-7,-3,AIR)
Block(2,-7,-2,AIR)
Block(2,-7,-1,AIR)
Block(2,-7,0,AIR)
Block(2,-7,1,AIR)
Block(2,-7,2,COBBLESTONE)
Block(2,-7,3,COBBLESTONE)
Block(2,-6,-8,SMOOTH_BRICK)
Block(2,-6,-7,COBBLESTONE)
Block(2,-6,-6,COBBLESTONE)
Block(2,-6,-5,WEB)
Block(2,-6,-4,AIR)
Block(2,-6,-3,AIR)
Block(2,-6,-2,AIR)
Block(2,-6,-1,AIR)
Block(2,-6,0,AIR)
Block(2,-6,1,AIR)
Block(2,-6,2,COBBLESTONE)
Block(2,-6,3,COBBLESTONE)
Block(2,-5,-8,SMOOTH_BRICK)
Block(2,-5,-7,COBBLESTONE)
Block(2,-5,-6,COBBLESTONE)
Block(2,-5,-5,AIR)
Block(2,-5,-4,AIR)
Block(2,-5,-3,AIR)
Block(2,-5,-2,AIR)
Block(2,-5,-1,AIR)
Block(2,-5,0,AIR)
Block(2,-5,1,AIR)
Block(2,-5,2,COBBLESTONE)
Block(2,-5,3,COBBLESTONE)
Block(2,-4,-8,SMOOTH_BRICK)
Block(2,-4,-7,COBBLESTONE)
RandomBlock(2,-4,-6,GRAVEL,50,0,50)
Block(2,-4,-5,AIR)
Block(2,-4,-4,AIR)
Block(2,-4,-3,AIR)
Block(2,-4,-2,AIR)
Block(2,-4,-1,AIR)
Block(2,-4,0,AIR)
Block(2,-4,1,AIR)
Block(2,-4,2,COBBLESTONE)
Block(2,-4,3,COBBLESTONE)
Block(2,-3,-9,SMOOTH_BRICK)
Block(2,-3,-8,SMOOTH_BRICK)
Block(2,-3,-7,COBBLESTONE)
Block(2,-3,-6,COBBLESTONE)
Block(2,-3,-5,AIR)
Block(2,-3,-4,AIR)
Block(2,-3,-3,AIR)
Block(2,-3,-2,AIR)
Block(2,-3,-1,AIR)
Block(2,-3,0,AIR)
Block(2,-3,1,AIR)
Block(2,-3,2,COBBLESTONE)
Block(2,-3,3,COBBLESTONE)
Block(2,-2,-9,SMOOTH_BRICK)
Block(2,-2,-8,SMOOTH_BRICK)
Block(2,-2,-7,COBBLESTONE)
Block(2,-2,-6,COBBLESTONE)
Block(2,-2,-5,COBBLESTONE)
Block(2,-2,-4,COBBLESTONE)
Block(2,-2,-3,COBBLESTONE)
Block(2,-2,-2,COBBLESTONE)
Block(2,-2,-1,COBBLESTONE)
Block(2,-2,0,COBBLESTONE)
Block(2,-2,1,COBBLESTONE)
Block(2,-2,2,COBBLESTONE)
Block(2,-2,3,COBBLESTONE)
Block(2,-1,-9,SMOOTH_BRICK)
Block(2,-1,-8,SMOOTH_BRICK)
Block(2,-1,-7,STONE)
Block(2,-1,-6,STONE:6)
Block(2,-1,-5,LOG)
Block(2,-1,-4,STONE)
Block(2,-1,-3,STONE)
Block(2,-1,-2,WOOD)
Block(2,-1,-1,WOOD)
Block(2,-1,0,WOOD)
Block(2,-1,1,WOOD)
Block(2,-1,2,STONE:6)
Block(2,-1,3,SMOOTH_BRICK)
Block(2,0,-9,STEP)
Block(2,0,-8,LOG)
Block(2,0,-7,WOOD)
Block(2,0,-6,WOOD)
Block(2,0,-5,LOG)
Block(2,0,-4,WOOD)
Block(2,0,-3,WOOD)
Block(2,0,-2,WOOD)
Block(2,0,-1,LOG)
Block(2,0,2,WOOD)
Block(2,0,3,STEP)
Block(2,1,-8,LOG)
Block(2,1,-7,BRICK)
Block(2,1,-6,BRICK)
Block(2,1,-5,LOG)
Block(2,1,-4,BRICK)
Block(2,1,-3,BRICK)
Block(2,1,-2,BRICK)
Block(2,1,-1,LOG)
Block(2,1,2,BRICK)
Block(2,1,3,LEAVES:1)
Block(2,2,-8,LOG)
Block(2,2,-7,BRICK)
Block(2,2,-6,BRICK)
Block(2,2,-5,LOG)
Block(2,2,-1,LOG)
Block(2,2,2,BRICK)
Block(2,3,-8,LOG)
Block(2,3,-7,BRICK)
Block(2,3,-6,BRICK)
Block(2,3,-5,LOG)
Block(2,3,-4,BRICK)
Block(2,3,-3,BRICK)
Block(2,3,-2,BRICK)
Block(2,3,-1,LOG)
Block(2,3,2,BRICK)
Block(2,3,3,WOOD_STAIRS:3)
Block(2,4,-9,WOOD_STAIRS:2)
Block(2,4,-8,WOOD)
Block(2,4,-7,WOOD)
Block(2,4,-6,WOOD)
Block(2,4,-5,WOOD)
Block(2,4,-4,WOOD)
Block(2,4,-3,WOOD)
Block(2,4,-2,WOOD)
Block(2,4,-1,WOOD)
Block(2,4,0,WOOD)
Block(2,4,1,WOOD)
Block(2,4,2,WOOD_STAIRS:3)
Block(2,5,-8,WOOD)
Block(2,5,-7,WOOD)
Block(2,5,-6,WOOD)
Block(2,5,-5,WOOD)
Block(2,5,-3,BOOKSHELF)
Block(2,5,-2,VINE:1)
Block(2,5,-1,BOOKSHELF)
Block(2,5,1,WOOD)
Block(2,6,-8,WOOD_STAIRS)
Block(2,6,-7,WOOD_STAIRS)
Block(2,6,-6,WOOD_STAIRS)
Block(2,6,-5,WOOD_STAIRS:2)
Block(2,6,-3,BOOKSHELF)
Block(2,6,-2,VINE:1)
Block(2,6,-1,BOOKSHELF)
Block(2,6,1,WOOD_STAIRS)
Block(2,6,2,WOOD_STAIRS:3)
Block(2,7,-4,WOOD)
Block(2,7,-3,BOOKSHELF)
Block(2,7,-2,VINE:1)
Block(2,7,-1,BOOKSHELF)
Block(2,7,0,WOOD)
Block(2,8,-4,WOOD_STAIRS:2)
Block(2,8,-2,VINE:5)
Block(2,8,0,WOOD_STAIRS:3)
Block(2,9,-3,WOOD)
Block(2,9,-2,VINE:5)
Block(2,9,-1,WOOD)
Block(2,10,-3,WOOD_STAIRS:2)
Block(2,10,-2,WOOD)
Block(2,10,-1,WOOD_STAIRS:3)
Block(3,-10,-8,COBBLESTONE)
Block(3,-10,-7,COBBLESTONE)
Block(3,-10,-6,COBBLESTONE)
Block(3,-10,-5,MOSSY_COBBLESTONE)
Block(3,-10,-4,DIRT)
RandomBlock(3,-10,-3,GRAVEL,50,0,50)
Block(3,-10,-2,MOSSY_COBBLESTONE)
Block(3,-10,-1,MOSSY_COBBLESTONE)
Block(3,-10,0,MOSSY_COBBLESTONE)
Block(3,-10,1,MOSSY_COBBLESTONE)
Block(3,-10,2,COBBLESTONE)
Block(3,-10,3,SMOOTH_BRICK)
Block(3,-9,-8,COBBLESTONE)
Block(3,-9,-7,COBBLESTONE)
Block(3,-9,-6,COBBLESTONE)
Block(3,-9,-5,GRAVEL)
RandomBlock(3,-9,-4,GRAVEL,50,0,50)
Block(3,-9,-3,AIR)
Block(3,-9,-2,AIR)
Block(3,-9,-1,AIR)
Block(3,-9,0,GRAVEL)
Block(3,-9,1,GRAVEL)
Block(3,-9,2,COBBLESTONE)
Block(3,-9,3,SMOOTH_BRICK)
Block(3,-8,-8,COBBLESTONE)
Block(3,-8,-7,COBBLESTONE)
Block(3,-8,-6,COBBLESTONE)
RandomBlock(3,-8,-5,GRAVEL,50,0,50)
Block(3,-8,-4,AIR)
Block(3,-8,-3,AIR)
Block(3,-8,-2,AIR)
Block(3,-8,-1,AIR)
Block(3,-8,0,AIR)
RandomBlock(3,-8,1,GRAVEL,50,0,50)
Block(3,-8,2,COBBLESTONE)
Block(3,-8,3,SMOOTH_BRICK)
Block(3,-7,-8,COBBLESTONE)
Block(3,-7,-7,COBBLESTONE)
Block(3,-7,-6,COBBLESTONE)
Block(3,-7,-5,AIR)
Block(3,-7,-4,AIR)
Block(3,-7,-3,AIR)
Block(3,-7,-2,AIR)
Block(3,-7,-1,AIR)
Block(3,-7,0,AIR)
Block(3,-7,1,AIR)
Block(3,-7,2,COBBLESTONE)
Block(3,-7,3,SMOOTH_BRICK)
Block(3,-6,-8,COBBLESTONE)
Block(3,-6,-7,COBBLESTONE)
Block(3,-6,-6,COBBLESTONE)
Block(3,-6,-5,AIR)
Block(3,-6,-4,AIR)
Block(3,-6,-3,AIR)
Block(3,-6,-2,AIR)
Block(3,-6,-1,AIR)
Block(3,-6,0,AIR)
Block(3,-6,1,AIR)
Block(3,-6,2,COBBLESTONE)
Block(3,-6,3,SMOOTH_BRICK)
Block(3,-5,-8,COBBLESTONE)
Block(3,-5,-7,COBBLESTONE)
Block(3,-5,-6,COBBLESTONE)
Block(3,-5,-5,AIR)
Block(3,-5,-4,AIR)
Block(3,-5,-3,AIR)
Block(3,-5,-2,AIR)
Block(3,-5,-1,AIR)
Block(3,-5,0,AIR)
Block(3,-5,1,AIR)
Block(3,-5,2,COBBLESTONE)
Block(3,-5,3,SMOOTH_BRICK)
Block(3,-4,-8,COBBLESTONE)
Block(3,-4,-7,COBBLESTONE)
Block(3,-4,-6,COBBLESTONE)
Block(3,-4,-5,AIR)
Block(3,-4,-4,AIR)
Block(3,-4,-3,AIR)
Block(3,-4,-2,AIR)
Block(3,-4,-1,AIR)
Block(3,-4,0,AIR)
Block(3,-4,1,AIR)
Block(3,-4,2,COBBLESTONE)
Block(3,-4,3,SMOOTH_BRICK)
Block(3,-3,-9,SMOOTH_BRICK)
Block(3,-3,-8,COBBLESTONE)
Block(3,-3,-7,COBBLESTONE)
Block(3,-3,-6,COBBLESTONE)
Block(3,-3,-5,AIR)
Block(3,-3,-4,AIR)
Block(3,-3,-3,AIR)
Block(3,-3,-2,AIR)
Block(3,-3,-1,AIR)
Block(3,-3,0,AIR)
Block(3,-3,1,WEB)
Block(3,-3,2,COBBLESTONE)
Block(3,-3,3,SMOOTH_BRICK)
Block(3,-2,-9,SMOOTH_BRICK)
Block(3,-2,-8,COBBLESTONE)
Block(3,-2,-7,COBBLESTONE)
Block(3,-2,-6,COBBLESTONE)
Block(3,-2,-5,COBBLESTONE)
Block(3,-2,-4,COBBLESTONE)
Block(3,-2,-3,COBBLESTONE)
Block(3,-2,-2,COBBLESTONE)
Block(3,-2,-1,COBBLESTONE)
Block(3,-2,0,COBBLESTONE)
Block(3,-2,1,COBBLESTONE)
Block(3,-2,2,COBBLESTONE)
Block(3,-2,3,SMOOTH_BRICK)
Block(3,-1,-9,SMOOTH_BRICK)
Block(3,-1,-8,STONE)
Block(3,-1,-7,WOOD)
Block(3,-1,-6,WOOD)
Block(3,-1,-5,WOOD)
Block(3,-1,-4,WOOD)
Block(3,-1,-3,WOOD)
Block(3,-1,-2,WOOD)
Block(3,-1,-1,WOOD)
Block(3,-1,0,WOOD)
Block(3,-1,1,WOOD)
Block(3,-1,2,STONE)
Block(3,-1,3,SMOOTH_BRICK)
Block(3,0,-9,STEP)
Block(3,0,-8,WOOD)
Block(3,0,2,LOG)
Block(3,0,3,SMOOTH_STAIRS:3)
Block(3,1,-8,BRICK)
Block(3,1,2,LOG)
Block(3,2,2,LOG)
Block(3,2,3,LEAVES:1)
Block(3,3,-8,BRICK)
Block(3,3,2,LOG)
Block(3,3,3,WOOD_STAIRS:3)
Block(3,4,-9,WOOD_STAIRS:2)
Block(3,4,-8,WOOD)
Block(3,4,-7,WOOD)
Block(3,4,-6,WOOD)
Block(3,4,-5,WOOD)
Block(3,4,-4,WOOD)
Block(3,4,-3,WOOD)
Block(3,4,-2,WOOD)
Block(3,4,-1,WOOD)
Block(3,4,0,WOOD)
Block(3,4,1,WOOD)
Block(3,4,2,WOOD_STAIRS:3)
Block(3,5,-8,WOOD)
Block(3,5,-7,WOOD)
Block(3,5,-6,WOOD)
Block(3,5,-5,WOOD)
Block(3,5,-4,WEB)
Block(3,5,-3,VINE:2)
Block(3,5,-1,VINE:2)
Block(3,5,1,WOOD)
Block(3,6,-8,WOOD_STAIRS:2)
Block(3,6,-7,WOOD)
Block(3,6,-6,WOOD)
Block(3,6,-5,WOOD)
Block(3,6,-3,VINE:2)
Block(3,6,1,LOG)
Block(3,6,2,WOOD_STAIRS:3)
Block(3,7,-6,WOOD_STAIRS:2)
Block(3,7,-5,WOOD)
Block(3,7,-4,WOOD)
Block(3,7,-3,VINE:2)
Block(3,7,0,WOOD)
Block(3,7,1,LOG)
Block(3,8,-4,WOOD_STAIRS:2)
Block(3,8,-2,VINE:1)
Block(3,8,0,WOOD)
Block(3,8,1,LOG)
Block(3,9,-3,WOOD)
Block(3,9,-2,VINE:5)
Block(3,9,-1,WOOD)
Block(3,9,0,WOOD_STAIRS:4)
Block(3,9,1,LOG)
Block(3,10,-3,WOOD_STAIRS:2)
Block(3,10,-2,WOOD)
Block(3,10,-1,WOOD_STAIRS:3)
Block(3,10,0,WOOD_STEP)
Block(3,10,1,WOOD_STEP)
Block(3,10,2,WOOD_STEP)
Block(4,-10,-8,COBBLESTONE)
Block(4,-10,-7,COBBLESTONE)
Block(4,-10,-6,COBBLESTONE)
Block(4,-10,-5,DIRT)
Block(4,-10,-4,MOSSY_COBBLESTONE)
Block(4,-10,-3,MOSSY_COBBLESTONE)
Block(4,-10,-2,MOSSY_COBBLESTONE)
Block(4,-10,-1,MOSSY_COBBLESTONE)
Block(4,-10,0,DIRT)
Block(4,-10,1,MOSSY_COBBLESTONE)
Block(4,-10,2,COBBLESTONE)
Block(4,-10,3,COBBLESTONE)
Block(4,-9,-8,COBBLESTONE)
Block(4,-9,-7,COBBLESTONE)
Block(4,-9,-6,COBBLESTONE)
Block(4,-9,-5,AIR)
Block(4,-9,-4,AIR)


#######################################################################
# +-----------------------------------------------------------------+ #
# |                            BO3 checks                           | #
# +-----------------------------------------------------------------+ #
#######################################################################

# Require a condition at a certain location in order for the BO3 to be spawned.
# BlockCheck(x,y,z,BlockName[,BlockName[,...]]) - one of the blocks must be at the location
# BlockCheckNot(x,y,z,BlockName[,BlockName[,...]]) - all the blocks must not be at the location
# LightCheck(x,y,z,minLightLevel,maxLightLevel) - light must be between min and max (inclusive)

# You can use "Solid" as a BlockName for matching all solid blocks or "All" to match all blocks that aren't air.

# Examples:
#   BlockCheck(0,-1,0,GRASS,DIRT)  Require grass or dirt just below the object
#   BlockCheck(0,-1,0,Solid)       Require any solid block just below the object
#   BlockCheck(0,-1,0,WOOL)        Require any type of wool just below the object
#   BlockCheck(0,-1,0,WOOL:0)      Require white wool just below the object
#   BlockCheckNot(0,-1,0,WOOL:0)   Require that there is no white wool below the object
#   LightCheck(0,0,0,0,1)          Require almost complete darkness just below the object

#######################################################################
# +-----------------------------------------------------------------+ #
# |                             Branches                            | #
# +-----------------------------------------------------------------+ #
#######################################################################

# Branches are objects that will spawn when this object spawns when it is used in
# the CustomStructure resource. Branches can also have branches, making complex
# structures possible. See the wiki for more details.

# Regular Branches spawn each branch with an independent chance of spawning.
# Branch(x,y,z,branchName,rotation,chance[,anotherBranchName,rotation,chance[,...]][IndividualChance])
# branchName - name of the object to spawn.
# rotation - NORTH, SOUTH, EAST or WEST.
# IndividualChance - The chance each branch has to spawn, assumed to be 100 when left blank

# Weighted Branches spawn branches with a dependent chance of spawning.
# WeightedBranch(x,y,z,branchName,rotation,chance[,anotherBranchName,rotation,chance[,...]][MaxChanceOutOf])
# MaxChanceOutOf - The chance all branches have to spawn out of, assumed to be 100 when left blank
WeightedBranch(-12,0,0,WitchHutWell,NORTH,25,WitchHutFarm,NORTH,25,WitchHutCauldronOutdoor,NORTH,25,WitchHutFlowerPot,NORTH,25,125)
WeightedBranch(-8,0,-8,WitchHutPath1,NORTH,25,WitchHutFenceTorch,NORTH,25,WitchHutCauldronOutdoor,NORTH,25,WitchHutJackNGravel,NORTH,25,100)
WeightedBranch(0,0,-8,WitchHutCauldronOutdoor,NORTH,25,WitchHutFlowerPot,NORTH,25,WitchHutMossyTorchS,NORTH,25,100)
WeightedBranch(12,0,0,WitchHutPath1,NORTH,25,WitchHutFenceTorch,NORTH,25,WitchHutPathCorner,NORTH,25,100)
WeightedBranch(0,0,12,WitchHutPath2,NORTH,25,WitchHutPathGate,NORTH,25,100)
WeightedBranch(8,0,8,WitchHutPath1,NORTH,25,WitchHutCauldronOutdoor,NORTH,25,WitchHutFenceTorch,NORTH,25,100)
WeightedBranch(-8,0,12,WitchHutFarm,NORTH,25,WitchHutWell,NORTH,25,WitchHutMossyTorchS,NORTH,25,WitchHutMossyTorchL,NORTH,25,100)
WeightedBranch(8,0,-8,WitchHutFlowerPot,NORTH,25,WitchHutCauldronOutdoor,NORTH,25,WitchHutMossyTorchL,NORTH,25,100)