[META]
version=2.0
spawnOnBlockType=2
spawnSunlight=True
spawnDarkness=True
spawnWater=False
spawnLava=False
underFill=False
randomRotation=True
dig=True
tree=True
branch=False
needsFoundation=True
rarity=30
collisionPercentage=20
spawnElevationMin=65
spawnElevationMax=200
spawnInBiome=Custom
[DATA]
1,-3,0:161.1
0,-1,0:162.1
0,-1,-2:162.1
0,-1,-1:162.1
-1,-3,1:161.1
1,-3,1:161.1
-1,-1,1:161.1
0,-1,1:162.1
-1,-3,2:161.1
0,-3,2:161.1
1,-3,2:161.1
-1,-2,2:161.1
-1,-1,2:161.1
0,-1,2:162.1
1,-1,2:161.1
0,0,2:161.1
-1,-3,3:161.1
0,-3,3:161.1
1,-3,3:161.1
-1,-2,3:161.1
0,-2,3:162.1
1,-2,3:161.1
-1,-1,3:161.1
0,-1,3:162.1
1,-1,3:161.1
1,0,3:162.1
0,-3,4:161.1
-1,-2,4:161.1
0,-2,4:162.1
1,-2,4:161.1
-1,-1,4:162.1
1,0,4:162.1
-1,-1,5:162.1
1,0,5:162.1
-1,-1,6:162.1
2,-1,6:161.1
1,0,6:162.1
0,1,6:161.1
1,2,6:161.1
-1,-1,7:162.1
1,-1,7:161.1
2,-1,7:161.1
0,0,7:161.1
1,0,7:162.1
3,0,7:161.1
0,1,7:161.1
1,2,7:161.1
-1,-1,8:162.1
1,-1,8:161.1
2,-1,8:161.1
0,0,8:161.1
1,0,8:162.1
2,0,8:162.5
3,0,8:161.1
0,1,8:161.1
1,1,8:162.9
2,1,8:161.1
1,2,8:161.1
-1,-1,9:162.1
2,0,9:162.1
3,0,9:161.1
2,1,9:161.1
-1,0,10:162.1
-1,0,11:162.1
1,0,11:161.1
-1,2,11:161.1
-2,-2,12:161.1
-3,0,12:161.1
-1,0,12:162.1
1,0,12:161.1
0,1,12:161.1
-1,2,12:161.1
-1,-3,13:161.1
-2,-2,13:161.1
-2,-1,13:161.1
0,-1,13:161.1
-3,0,13:161.1
-1,0,13:162.1
1,0,13:161.1
-2,1,13:161.1
0,1,13:161.1
-1,2,13:161.1
-1,-3,14:161.1
-2,-2,14:161.1
0,-2,14:161.1
-2,-1,14:161.1
0,-1,14:161.1
1,-1,14:161.1
-3,0,14:161.1
-1,0,14:162.1
0,0,14:162.5
1,0,14:161.1
-2,1,14:161.1
-1,1,14:162.9
0,1,14:161.1
-1,2,14:161.1
-1,-3,15:161.1
-2,-2,15:161.1
-1,-2,15:162.9
0,-2,15:161.1
-2,-1,15:161.1
-1,-1,15:161.1
0,-1,15:161.1
1,-1,15:161.1
-3,0,15:161.1
-2,0,15:162.5
-1,0,15:161.1
0,0,15:161.1
-2,1,15:161.1
-1,1,15:161.1
