[META]
version=2.0
spawnOnBlockType=2
spawnSunlight=True
spawnDarkness=True
spawnWater=False
spawnLava=False
underFill=False
randomRotation=True
dig=True
tree=True
branch=False
needsFoundation=True
rarity=30
collisionPercentage=20
spawnElevationMin=65
spawnElevationMax=200
spawnInBiome=Custom
[DATA]
-1,0,0:162.1
-1,0,-1:162.1
-1,0,1:162.1
-1,0,2:162.1
0,-1,3:162.1
-1,0,3:162.1
0,-1,4:162.1
0,-1,5:162.1
1,1,5:161.1
1,-1,6:161.1
0,0,6:162.1
1,1,6:161.1
-1,-1,7:161.1
1,-1,7:161.1
0,0,7:162.1
1,0,7:161.1
-1,1,7:161.1
1,1,7:161.1
-1,-1,8:161.1
0,-1,8:161.1
1,-1,8:161.1
-1,0,8:161.1
0,0,8:161.1
1,0,8:161.1
-1,1,8:161.1
0,1,8:161.1
1,1,8:161.1
0,-1,9:161.1
-1,0,9:161.1
0,0,9:161.1
1,0,9:161.1
0,1,9:161.1
