[META]
version=2.0
spawnOnBlockType=2
spawnSunlight=True
spawnDarkness=True
spawnWater=False
spawnLava=False
underFill=False
randomRotation=True
dig=True
tree=True
branch=False
needsFoundation=True
rarity=30
collisionPercentage=20
spawnElevationMin=65
spawnElevationMax=200
spawnInBiome=Custom
[DATA]
1,-2,0:162.1
1,-2,-2:162.1
1,-2,-1:162.1
1,-2,1:162.1
1,-2,2:162.1
1,-2,3:162.1
0,-1,3:162.1
2,-2,4:161.1
0,-1,4:162.1
-2,0,4:161.1
0,-3,5:161.1
2,-2,5:161.1
0,-1,5:162.1
-2,0,5:161.1
2,0,5:161.1
-1,1,5:161.1
0,-3,6:161.1
-1,-2,6:161.1
0,-2,6:162.9
1,-2,6:161.1
2,-2,6:161.1
-2,-1,6:161.1
-1,-1,6:162.5
0,-1,6:162.1
1,-1,6:162.5
3,-1,6:161.1
-2,0,6:161.1
-1,0,6:161.1
2,0,6:161.1
-1,1,6:161.1
1,1,6:161.1
0,-2,7:161.1
2,-2,7:161.1
-1,-1,7:161.1
0,-1,7:162.1
1,-1,7:161.1
2,-1,7:162.5
3,-1,7:161.1
-1,0,7:161.1
0,0,7:162.9
1,0,7:161.1
2,0,7:161.1
-1,1,7:161.1
0,1,7:161.1
1,1,7:161.1
