[META]
version=2.0
spawnOnBlockType=2
spawnSunlight=True
spawnDarkness=True
spawnWater=False
spawnLava=False
underFill=False
randomRotation=True
dig=True
tree=True
branch=False
needsFoundation=True
rarity=30
collisionPercentage=20
spawnElevationMin=65
spawnElevationMax=200
spawnInBiome=Custom
[DATA]
0,-2,0:162.1
0,-2,-3:162.1
0,-2,-2:162.1
0,-2,-1:162.1
0,-2,1:162.1
0,-2,2:162.1
0,-2,3:162.1
0,-1,4:162.1
0,-1,5:162.1
-1,-2,6:161.1
0,-2,6:161.1
-1,-1,6:161.1
0,-1,6:162.1
1,-1,6:161.1
0,-3,7:161.1
-1,-2,7:161.1
0,-2,7:161.1
1,-2,7:161.1
0,-1,7:162.1
-1,0,7:161.1
0,0,7:161.1
1,0,7:161.1
0,-2,8:161.1
-1,-1,8:161.1
0,-1,8:162.1
1,-1,8:161.1
0,0,9:162.1
0,0,10:162.1
0,0,11:162.1
-1,-1,12:161.1
1,-1,12:161.1
-2,0,12:161.1
0,0,12:162.1
2,0,12:161.1
-3,1,12:161.1
2,2,12:161.1
-3,3,12:161.1
1,3,12:161.1
-1,-1,13:161.1
0,-1,13:161.1
1,-1,13:161.1
-2,0,13:161.1
-1,0,13:161.1
0,0,13:162.1
1,0,13:161.1
2,0,13:161.1
-3,1,13:161.1
-2,1,13:161.1
-1,1,13:162.5
0,1,13:162.9
1,1,13:162.5
2,1,13:161.1
-3,2,13:161.1
-2,2,13:162.5
-1,2,13:162.9
0,2,13:161.1
1,2,13:161.1
2,2,13:161.1
-3,3,13:161.1
-2,3,13:161.1
-1,3,13:161.1
0,3,13:161.1
1,3,13:161.1
0,0,14:161.1
-1,1,14:161.1
0,1,14:161.1
1,1,14:161.1
-2,2,14:161.1
-1,2,14:162.1
0,2,14:161.1
-1,3,14:161.1
-1,1,15:161.1
-2,2,15:161.1
-1,2,15:161.1
0,2,15:161.1
-1,3,15:161.1
