[META]
version=2.0
spawnOnBlockType=2
spawnSunlight=True
spawnDarkness=True
spawnWater=False
spawnLava=False
underFill=False
randomRotation=True
dig=True
tree=True
branch=False
needsFoundation=True
rarity=30
collisionPercentage=20
spawnElevationMin=65
spawnElevationMax=200
spawnInBiome=Custom
[DATA]
3,-4,0:162.1
3,-4,-3:162.1
3,-4,-2:162.1
3,-4,-1:162.5
3,-4,1:162.1
4,-4,1:162.1
5,-3,1:162.1
7,-2,1:161.1
3,-4,2:162.1
7,-4,2:161.1
5,-3,2:162.1
5,-2,2:161.1
7,-2,2:161.1
3,-4,3:162.1
5,-4,3:161.1
7,-4,3:161.1
4,-3,3:161.1
5,-3,3:162.1
5,-2,3:161.1
7,-2,3:161.1
3,-4,4:162.1
5,-4,4:161.1
6,-4,4:161.1
7,-4,4:161.1
4,-3,4:161.1
5,-3,4:161.1
6,-3,4:162.1
7,-3,4:161.1
5,-2,4:161.1
6,-2,4:161.1
7,-2,4:161.1
5,-4,5:161.1
7,-4,5:161.1
3,-3,5:162.1
6,-3,5:161.1
5,-2,5:161.1
7,-2,5:161.1
3,-3,6:162.1
0,-4,7:161.1
2,-3,7:162.1
2,-2,7:161.1
0,-4,8:161.1
3,-4,8:161.1
-2,-3,8:161.1
2,-3,8:162.1
0,-2,8:161.1
2,-2,8:161.1
3,-2,8:161.1
-1,-4,9:161.1
0,-4,9:161.1
1,-4,9:161.1
2,-4,9:161.1
3,-4,9:161.1
-2,-3,9:161.1
1,-3,9:162.1
2,-3,9:161.1
3,-3,9:161.1
-1,-2,9:161.1
0,-2,9:161.1
1,-2,9:161.1
2,-2,9:161.1
3,-2,9:161.1
-1,-4,10:161.1
1,-4,10:161.1
-2,-3,10:161.1
0,-3,10:161.1
1,-3,10:161.1
2,-3,10:161.1
3,-3,10:161.1
-1,-2,10:161.1
1,-2,10:161.1
-1,-4,11:161.1
-2,-3,11:161.1
-1,-3,11:161.1
0,-3,11:161.1
1,-3,11:161.1
2,-3,11:161.1
-1,-2,11:161.1
