[META]
version=2.0
spawnOnBlockType=2
spawnSunlight=True
spawnDarkness=True
spawnWater=False
spawnLava=False
underFill=False
randomRotation=True
dig=True
tree=True
branch=False
needsFoundation=True
rarity=30
collisionPercentage=20
spawnElevationMin=65
spawnElevationMax=200
spawnInBiome=Custom
[DATA]
-1,-1,0:162.1
-1,-1,-2:162.1
-1,-1,-1:162.1
-1,-1,1:162.1
-1,-1,2:162.1
-1,-1,3:162.1
-1,-1,4:162.1
-1,-1,5:162.1
-1,-1,6:162.1
-1,-1,7:162.1
-2,0,7:162.1
-2,0,8:162.1
-3,1,8:161.1
-3,-1,9:161.1
-2,-1,9:161.1
-1,-1,9:161.1
-2,0,9:162.1
-3,1,9:161.1
-2,-1,10:161.1
-3,0,10:161.1
-2,0,10:162.1
-1,0,10:161.1
-2,1,10:161.1
-1,1,11:162.1
-1,1,12:162.1
-1,1,13:162.1
-2,0,14:161.1
0,0,14:161.1
-1,1,14:162.1
-2,2,14:161.1
0,2,14:161.1
-2,0,15:161.1
-1,0,15:161.1
0,0,15:161.1
-2,1,15:161.1
-1,1,15:162.1
0,1,15:161.1
-2,2,15:161.1
-1,2,15:161.1
0,2,15:161.1
3,-1,16:161.1
0,0,16:162.1
-1,1,16:161.1
3,-1,17:161.1
0,0,17:162.1
1,2,17:161.1
3,2,17:161.1
-2,-3,18:161.1
1,-1,18:161.1
3,-1,18:161.1
-2,0,18:161.1
0,0,18:162.1
3,1,18:161.1
1,2,18:161.1
3,2,18:161.1
-2,-3,19:161.1
0,-3,19:161.1
-2,-2,19:161.1
-1,-2,19:161.1
-1,-1,19:161.1
0,-1,19:161.1
1,-1,19:161.1
2,-1,19:161.1
3,-1,19:161.1
-2,0,19:161.1
0,0,19:162.1
1,0,19:162.5
2,0,19:162.5
3,0,19:161.1
-2,1,19:161.1
-1,1,19:162.5
0,1,19:162.9
1,1,19:161.1
2,1,19:162.9
3,1,19:161.1
-2,2,19:161.1
-1,2,19:162.9
0,2,19:161.1
1,2,19:161.1
2,2,19:161.1
3,2,19:161.1
-2,-3,20:161.1
-1,-3,20:161.1
0,-3,20:161.1
-2,-2,20:161.1
-1,-2,20:161.1
0,-2,20:161.1
-2,-1,20:161.1
-1,-1,20:161.1
0,-1,20:161.1
1,-1,20:161.1
-2,0,20:161.1
-1,0,20:161.1
0,0,20:161.1
1,0,20:161.1
2,0,20:161.1
-1,1,20:161.1
0,1,20:161.1
2,1,20:161.1
-1,2,20:161.1
