[META]
version=2.0
spawnOnBlockType=12
spawnSunlight=True
spawnDarkness=True
spawnWater=True
spawnLava=False
underFill=False
randomRotation=True
dig=True
tree=True
branch=False
needsFoundation=True
rarity=100
collisionPercentage=50
spawnElevationMin=48
spawnElevationMax=60
spawnInBiome=Custom
[DATA]
-2,-2,-5:17.3
-1,-2,-5:17.3
-3,-1,-5:17.3
0,-1,-5:17.3
-4,0,-5:17.3
1,0,-5:17.3
-4,1,-5:17.3
1,1,-5:17.3
-3,2,-5:17.3
0,2,-5:17.3
-2,3,-5:17.3
-1,3,-5:17.3
-2,-2,-4:17.3
-1,-2,-4:17.3
-3,-1,-4:17.3
-2,-1,-4:17.3
-1,-1,-4:17.3
0,-1,-4:17.3
-4,0,-4:17.3
-3,0,-4:17.3
0,0,-4:17.3
1,0,-4:17.3
-4,1,-4:17.3
-3,1,-4:17.3
0,1,-4:17.3
1,1,-4:17.3
-3,2,-4:17.3
-2,2,-4:17.3
-1,2,-4:17.3
0,2,-4:17.3
-2,3,-4:17.3
-1,3,-4:17.3
-2,-2,-3:17.3
-1,-2,-3:17.3
-3,-1,-3:17.3
-2,-1,-3:17.3
-1,-1,-3:17.3
0,-1,-3:17.3
-4,0,-3:17.3
-3,0,-3:17.3
-2,0,-3:17.3
-1,0,-3:17.3
0,0,-3:17.3
1,0,-3:17.3
-4,1,-3:17.3
-3,1,-3:17.3
-2,1,-3:17.3
-1,1,-3:17.3
0,1,-3:17.3
1,1,-3:17.3
-3,2,-3:17.3
-2,2,-3:17.3
-1,2,-3:17.3
0,2,-3:17.3
-2,3,-3:17.3
-1,3,-3:17.3
-2,-2,-2:17.3
-1,-2,-2:17.3
-3,-1,-2:17.3
-2,-1,-2:17.3
-1,-1,-2:17.3
0,-1,-2:17.3
-4,0,-2:17.3
-3,0,-2:17.3
-2,0,-2:17.3
-1,0,-2:17.3
0,0,-2:17.3
1,0,-2:17.3
-4,1,-2:17.3
-3,1,-2:17.3
-2,1,-2:17.3
-1,1,-2:17.3
0,1,-2:17.3
1,1,-2:17.3
-3,2,-2:17.3
-2,2,-2:17.3
-1,2,-2:17.3
0,2,-2:17.3
-2,3,-2:17.3
-1,3,-2:17.3
-2,-2,-1:17.3
-1,-2,-1:17.3
-3,-1,-1:17.3
-2,-1,-1:17.3
-1,-1,-1:17.3
0,-1,-1:17.3
-4,0,-1:17.3
-3,0,-1:17.3
-2,0,-1:17.3
-1,0,-1:17.3
0,0,-1:17.3
1,0,-1:17.3
-4,1,-1:17.3
-3,1,-1:17.3
-2,1,-1:17.3
-1,1,-1:17.3
0,1,-1:17.3
1,1,-1:17.3
-3,2,-1:17.3
-2,2,-1:17.3
-1,2,-1:17.3
0,2,-1:17.3
-2,3,-1:17.3
-1,3,-1:17.3
-2,-2,0:17.3
-1,-2,0:17.3
-3,-1,0:17.3
-2,-1,0:17.3
-1,-1,0:17.3
0,-1,0:17.3
-4,0,0:17.3
-3,0,0:17.3
-2,0,0:17.3
-1,0,0:17.3
0,0,0:17.3
1,0,0:17.3
-4,1,0:17.3
-3,1,0:17.3
-2,1,0:17.3
-1,1,0:17.3
0,1,0:17.3
1,1,0:17.3
-3,2,0:17.3
-2,2,0:17.3
-1,2,0:17.3
0,2,0:17.3
-2,3,0:17.3
-1,3,0:17.3
-2,-2,1:17.3
-2,-1,1:17.3
-1,-1,1:17.3
0,-1,1:17.3
-3,0,1:17.3
-2,0,1:17.3
-1,0,1:17.3
0,0,1:17.3
-4,1,1:17.3
-3,1,1:17.3
-2,1,1:17.3
-1,1,1:17.3
0,1,1:17.3
1,1,1:17.3
-3,2,1:17.3
-2,2,1:17.3
-1,2,1:17.3
0,2,1:17.3
-1,3,1:17.3
-2,-1,2:17.3
-1,-1,2:17.3
-3,0,2:17.3
-2,0,2:17.3
-1,0,2:17.3
0,0,2:17.3
-3,1,2:17.3
-2,1,2:17.3
-1,1,2:17.3
0,1,2:17.3
-2,2,2:17.3
-1,2,2:17.3
-2,0,3:17.3
-1,1,3:17.3
-2,-1,4:17.3
-3,1,4:17.3
-1,1,4:17.3
0,2,4:17.3
-2,-3,5:18.12
-3,-2,5:18.12
-1,-2,5:18.4
-2,-1,5:17.3
-1,-1,5:18.4
-4,0,5:18.4
-3,0,5:18.12
0,0,5:17.3
-3,1,5:17.3
-4,2,5:18.12
-3,2,5:18.12
0,2,5:17.3
-3,3,5:18.4
-1,3,5:18.12
1,3,5:18.12
0,4,5:18.12
-2,-2,6:18.4
-2,-1,6:18.4
0,0,6:17.3
1,0,6:18.4
-4,1,6:18.4
-3,1,6:18.4
-2,1,6:18.4
1,1,6:18.4
2,1,6:18.4
-1,2,6:18.12
0,2,6:18.12
1,2,6:18.12
0,3,6:18.4
0,-1,7:18.4
-1,0,7:18.4
0,0,7:18.4
-3,1,7:18.4
0,1,7:18.4
0,0,8:18.4
