[META]
version=2.0
spawnOnBlockType=2
spawnSunlight=True
spawnDarkness=True
spawnWater=False
spawnLava=False
underFill=False
randomRotation=True
dig=True
tree=True
branch=False
needsFoundation=True
rarity=200
collisionPercentage=20
spawnElevationMin=0
spawnElevationMax=200
spawnInBiome=Custom
[DATA]
0,0,0:17.0
0,0,1:17.0
0,0,2:17.0
0,-1,3:18.0
-1,0,3:18.0
0,0,3:17.0	
1,0,3:18.0
0,1,3:18.0
0,-2,4:18.0
-1,-1,4:18.0
0,-1,4:17.0
1,-1,4:18.0
-2,0,4:18.0
-1,0,4:17.0
0,0,4:17.0
1,0,4:17.0
2,0,4:18.0
-1,1,4:18.0
0,1,4:17.0
1,1,4:18.0
0,2,4:18.0
0,-3,5:18.0
-1,-2,5:18.0
0,-2,5:17.0
1,-2,5:18.0
-2,-1,5:18.0
-1,-1,5:18.0
0,-1,5:18.0
1,-1,5:18.0
2,-1,5:18.0
-3,0,5:18.0
-2,0,5:17.0
-1,0,5:18.0
0,0,5:17.0
1,0,5:18.0
2,0,5:17.0
3,0,5:18.0
-2,1,5:18.0
-1,1,5:18.0
0,1,5:18.0
1,1,5:18.0
2,1,5:18.0
-1,2,5:18.0
0,2,5:17.0
1,2,5:18.0
0,3,5:18.0
0,-3,6:18.0
-1,-2,6:18.0
0,-2,6:17.0
1,-2,6:18.0
-2,-1,6:18.0
-1,-1,6:18.0
0,-1,6:18.0
1,-1,6:18.0
2,-1,6:18.0
-3,0,6:18.0
-2,0,6:17.0
-1,0,6:18.0
0,0,6:17.0
1,0,6:18.0
2,0,6:17.0
3,0,6:18.0
-2,1,6:18.0
-1,1,6:18.0
0,1,6:18.0
1,1,6:18.0
2,1,6:18.0
-1,2,6:18.0
0,2,6:17.0
1,2,6:17.4
2,2,6:18.0
0,3,6:18.0
1,3,6:18.0
-1,-3,7:18.0
0,-3,7:18.0
-2,-2,7:18.0
-1,-2,7:17.4
0,-2,7:17.0
1,-2,7:18.0
2,-2,7:18.0
-2,-1,7:18.0
-1,-1,7:18.0
0,-1,7:18.0
1,-1,7:18.0
2,-1,7:17.8
3,-1,7:18.0
-3,0,7:18.0
-2,0,7:17.0
-1,0,7:18.0
0,0,7:17.0
1,0,7:18.0
2,0,7:17.0
3,0,7:18.0
-3,1,7:18.0
-2,1,7:17.8
-1,1,7:18.0
0,1,7:18.0
1,1,7:18.0
2,1,7:18.0
-2,2,7:18.0
-1,2,7:18.0
0,2,7:17.0
1,2,7:18.0
0,3,7:18.0
0,-3,8:18.0
-1,-2,8:18.0
0,-2,8:17.0
1,-2,8:18.0
-2,-1,8:18.0
-1,-1,8:18.0
0,-1,8:18.0
1,-1,8:18.0
2,-1,8:18.0
-3,0,8:18.0
-2,0,8:17.0
-1,0,8:18.0
0,0,8:17.0
1,0,8:18.0
2,0,8:17.0
3,0,8:18.0
-2,1,8:18.0
-1,1,8:18.0
0,1,8:18.0
1,1,8:18.0
2,1,8:18.0
-1,2,8:18.0
0,2,8:17.0
1,2,8:18.0
0,3,8:18.0
0,-3,9:18.0
1,-3,9:18.0
-2,-2,9:18.0
-1,-2,9:18.0
0,-2,9:17.0
1,-2,9:17.4
2,-2,9:18.0
-3,-1,9:18.0
-2,-1,9:17.8
-1,-1,9:18.0
0,-1,9:18.0
1,-1,9:18.0
2,-1,9:18.0
-3,0,9:18.0
-2,0,9:17.0
-1,0,9:18.0
0,0,9:17.0
1,0,9:18.0
2,0,9:17.0
3,0,9:18.0
-2,1,9:18.0
-1,1,9:18.0
0,1,9:18.0
1,1,9:18.0
2,1,9:17.8
3,1,9:18.0
-2,2,9:18.0
-1,2,9:17.4
0,2,9:17.0
1,2,9:18.0
2,2,9:18.0
-1,3,9:18.0
0,3,9:18.0
0,-3,10:18.0
-1,-2,10:18.0
0,-2,10:17.0
1,-2,10:18.0
-2,-1,10:18.0
-1,-1,10:18.0
0,-1,10:18.0
1,-1,10:18.0
2,-1,10:18.0
-3,0,10:18.0
-2,0,10:17.0
-1,0,10:18.0
0,0,10:17.0
1,0,10:18.0
2,0,10:17.0
3,0,10:18.0
-3,1,10:18.0
-2,1,10:18.0
-1,1,10:18.0
0,1,10:18.0
1,1,10:18.0
2,1,10:18.0
-1,2,10:18.0
0,2,10:17.0
1,2,10:18.0
0,3,10:18.0
1,3,10:18.0
-1,-3,11:18.0
0,-3,11:18.0
-1,-2,11:18.0
0,-2,11:17.0
1,-2,11:18.0
-2,-1,11:18.0
-1,-1,11:18.0
0,-1,11:18.0
1,-1,11:18.0
2,-1,11:18.0
3,-1,11:18.0
-3,0,11:18.0
-2,0,11:17.0
-1,0,11:18.0
0,0,11:17.0
1,0,11:18.0
2,0,11:17.0
3,0,11:18.0
-2,1,11:18.0
-1,1,11:18.0
0,1,11:18.0
1,1,11:18.0
2,1,11:18.0
-1,2,11:18.0
0,2,11:17.0
1,2,11:18.0
-1,3,11:18.0
0,3,11:18.0
0,-3,12:18.0
-2,-2,12:18.0
-1,-2,12:18.0
0,-2,12:17.0
1,-2,12:18.0
2,-2,12:18.0
-2,-1,12:18.0
-1,-1,12:18.0
0,-1,12:18.0
1,-1,12:18.0
2,-1,12:18.0
-3,0,12:18.0
-2,0,12:17.0
-1,0,12:18.0
0,0,12:17.0
1,0,12:18.0
2,0,12:17.0
3,0,12:18.0
-2,1,12:18.0
-1,1,12:18.0
0,1,12:18.0
1,1,12:18.0
2,1,12:18.0
-2,2,12:18.0
-1,2,12:18.0
0,2,12:17.0
1,2,12:18.0
2,2,12:18.0
0,3,12:18.0
0,-3,13:18.0
-1,-2,13:18.0
0,-2,13:17.0
1,-2,13:18.0
-2,-1,13:18.0
-1,-1,13:18.0
0,-1,13:18.0
1,-1,13:18.0
2,-1,13:18.0
-3,0,13:18.0
-2,0,13:17.0
-1,0,13:18.0
0,0,13:17.0
1,0,13:18.0
2,0,13:17.0
3,0,13:18.0
-2,1,13:18.0
-1,1,13:18.0
0,1,13:18.0
1,1,13:18.0
2,1,13:18.0
-1,2,13:18.0
0,2,13:17.0
1,2,13:18.0
0,3,13:18.0
0,-2,14:18.0
-1,-1,14:18.0
0,-1,14:18.0
1,-1,14:18.0
-2,0,14:18.0
-1,0,14:18.0
0,0,14:17.0
1,0,14:18.0
2,0,14:18.0
-1,1,14:18.0
0,1,14:18.0
1,1,14:18.0
0,2,14:18.0
0,-2,15:18.0
-1,-1,15:18.0
0,-1,15:18.0
1,-1,15:18.0
-2,0,15:18.0
-1,0,15:18.0
0,0,15:17.0
1,0,15:18.0
2,0,15:18.0
-1,1,15:18.0
0,1,15:18.0
1,1,15:18.0
0,2,15:18.0
0,-1,16:18.0
-1,0,16:18.0
0,0,16:17.0
1,0,16:18.0
0,1,16:18.0
0,-1,17:18.0
-1,0,17:18.0
0,0,17:18.0
1,0,17:18.0
0,1,17:18.0
0,0,18:18.0
