[META]
version=2.0
spawnOnBlockType=2
spawnSunlight=True
spawnDarkness=True
spawnWater=False
spawnLava=False
underFill=False
randomRotation=True
dig=True
tree=True
branch=False
needsFoundation=True
rarity=200
collisionPercentage=2
spawnElevationMin=0
spawnElevationMax=256
spawnInBiome=Custom
[DATA]
0,0,0:17
0,-1,1:18
-1,0,1:18
0,0,1:18
1,0,1:18
0,1,1:18
0,-1,2:18
1,-1,2:18
-1,0,2:18
0,0,2:18
1,0,2:18
0,1,2:18
-1,-1,3:18
0,-1,3:18
1,-1,3:18
-1,0,3:18
0,0,3:18
1,0,3:18
-1,1,3:18
0,1,3:18
1,1,3:18
-1,-1,4:18
0,-1,4:18
1,-1,4:18
-1,0,4:18
0,0,4:18
1,0,4:18
-1,1,4:18
0,1,4:18
1,1,4:18
0,-1,5:18
-1,0,5:18
0,0,5:18
1,0,5:18
-1,1,5:18
0,1,5:18
0,-1,6:18
-1,0,6:18
0,0,6:18
1,0,6:18
0,1,6:18
0,-1,7:18
-1,0,7:18
0,0,7:18
1,0,7:18
0,1,7:18
0,-1,8:18
-1,0,8:18
0,0,8:18
1,0,8:18
0,1,8:18
0,-1,9:18
0,0,9:18
0,1,9:18
0,0,10:18
0,0,11:18
