[META]
version=2.0
spawnOnBlockType=2
spawnSunlight=True
spawnDarkness=True
spawnWater=False
spawnLava=False
underFill=False
randomRotation=True
dig=True
tree=True
branch=False
needsFoundation=True
rarity=10
collisionPercentage=20
spawnElevationMin=0
spawnElevationMax=200
spawnInBiome=Custom
[DATA]
-2,3,0:17.0
-2,3,1:17.0
-2,3,2:17.0
-2,3,3:17.0
-3,0,4:18.0
-4,1,4:18.0
-3,1,4:18.0
-5,2,4:18.0
-4,2,4:18.0
-3,2,4:18.0
-6,3,4:18.0
-5,3,4:18.0
-4,3,4:18.0
-3,3,4:17.0
-2,3,4:17.0
-5,4,4:18.0
-4,4,4:18.0
-3,4,4:18.0
-4,5,4:18.0
-3,5,4:18.0
-3,6,4:18.0
-3,-2,5:18.0
-2,-2,5:18.0
-3,-1,5:18.0
-2,-1,5:18.0
-1,-1,5:18.0
-3,0,5:18.0
-2,0,5:18.0
-1,0,5:18.0
-3,1,5:18.0
-2,1,5:18.0
-1,1,5:18.0
-4,2,5:18.0
-3,2,5:18.0
-2,2,5:17.0
-1,2,5:18.0
0,2,5:18.0
-5,3,5:18.0
-4,3,5:18.0
-3,3,5:18.0
-2,3,5:17.0
-1,3,5:17.4
0,3,5:18.0
1,3,5:18.0
-6,4,5:18.0
-5,4,5:18.0
-4,4,5:17.0
-3,4,5:18.0
-2,4,5:18.0
-1,4,5:18.0
0,4,5:18.0
1,4,5:18.0
-5,5,5:18.0
-4,5,5:18.0
-3,5,5:18.0
-2,5,5:18.0
-1,5,5:18.0
0,5,5:18.0
1,5,5:18.0
-2,-4,6:18.0
-4,-3,6:18.0
-3,-3,6:18.0
-2,-3,6:18.0
-1,-3,6:18.0
-5,-2,6:18.0
-4,-2,6:18.0
-3,-2,6:18.0
-2,-2,6:17.8
-1,-2,6:18.0
-5,-1,6:18.0
-4,-1,6:18.0
-3,-1,6:17.4
-2,-1,6:17.8
-1,-1,6:18.0
0,-1,6:18.0
-5,0,6:18.0
-4,0,6:18.0
-3,0,6:18.0
-2,0,6:17.8
-1,0,6:18.0
0,0,6:18.0
1,0,6:18.0
-3,1,6:18.0
-2,1,6:17.8
-1,1,6:17.4
0,1,6:18.0
1,1,6:18.0
-3,2,6:18.0
-2,2,6:18.0
-1,2,6:18.0
0,2,6:18.0
1,2,6:18.0
-6,3,6:18.0
-5,3,6:18.0
-4,3,6:18.0
-3,3,6:18.0
-2,3,6:17.0
-1,3,6:18.0
0,3,6:18.0
1,3,6:18.0
2,3,6:18.0
-7,4,6:18.0
-6,4,6:18.0
-5,4,6:18.0
-4,4,6:18.0
-3,4,6:18.0
-2,4,6:18.0
-1,4,6:18.0
0,4,6:17.0
1,4,6:18.0
2,4,6:18.0
-7,5,6:18.0
-6,5,6:18.0
-5,5,6:17.0
-4,5,6:18.0
-3,5,6:18.0
-2,5,6:18.0
-1,5,6:18.0
0,5,6:18.0
1,5,6:18.0
2,5,6:18.0
-7,6,6:18.0
-6,6,6:18.0
-5,6,6:18.0
-4,6,6:18.0
-3,6,6:18.0
0,6,6:18.0
1,6,6:18.0
-6,7,6:18.0
-5,7,6:18.0
-4,7,6:18.0
-3,-6,7:18.0
-2,-6,7:18.0
-1,-6,7:18.0
-4,-5,7:18.0
-3,-5,7:18.0
-2,-5,7:18.0
-1,-5,7:18.0
0,-5,7:18.0
-4,-4,7:18.0
-3,-4,7:18.0
-2,-4,7:18.0
-1,-4,7:18.0
0,-4,7:18.0
-5,-3,7:18.0
-4,-3,7:18.0
-3,-3,7:18.0
-2,-3,7:17.0
-1,-3,7:18.0
0,-3,7:18.0
-6,-2,7:18.0
-5,-2,7:18.0
-4,-2,7:17.0
-3,-2,7:18.0
-2,-2,7:18.0
-1,-2,7:18.0
0,-2,7:18.0
1,-2,7:18.0
-6,-1,7:18.0
-5,-1,7:18.0
-4,-1,7:18.0
-3,-1,7:18.0
-2,-1,7:18.0
-1,-1,7:18.0
0,-1,7:18.0
1,-1,7:18.0
2,-1,7:18.0
-5,0,7:18.0
-4,0,7:18.0
-3,0,7:18.0
-2,0,7:18.0
-1,0,7:18.0
0,0,7:17.0
1,0,7:18.0
2,0,7:18.0
-2,1,7:18.0
-1,1,7:18.0
0,1,7:18.0
1,1,7:18.0
2,1,7:18.0
-3,2,7:18.0
-2,2,7:18.0
-1,2,7:18.0
0,2,7:18.0
1,2,7:18.0
2,2,7:18.0
-3,3,7:18.0
-2,3,7:17.0
-1,3,7:18.0
0,3,7:18.0
1,3,7:17.0
2,3,7:18.0
3,3,7:18.0
-6,4,7:18.0
-5,4,7:18.0
-4,4,7:18.0
-3,4,7:18.0
-2,4,7:17.8
-1,4,7:18.0
0,4,7:18.0
1,4,7:18.0
2,4,7:18.0
3,4,7:18.0
-6,5,7:18.0
-5,5,7:18.0
-4,5,7:18.0
-3,5,7:18.0
-2,5,7:18.0
0,5,7:18.0
1,5,7:17.0
2,5,7:18.0
3,5,7:18.0
-6,6,7:18.0
-5,6,7:18.0
-4,6,7:18.0
0,6,7:18.0
1,6,7:18.0
2,6,7:18.0
3,6,7:18.0
1,7,7:18.0
2,7,7:18.0
-3,-5,8:18.0
-2,-5,8:18.0
-1,-5,8:18.0
-3,-4,8:18.0
-2,-4,8:17.0
-1,-4,8:18.0
-4,-3,8:18.0
-3,-3,8:18.0
-2,-3,8:18.0
-1,-3,8:18.0
0,-3,8:18.0
1,-3,8:18.0
2,-3,8:18.0
-5,-2,8:18.0
-4,-2,8:18.0
-3,-2,8:18.0
-2,-2,8:18.0
-1,-2,8:18.0
0,-2,8:18.0
1,-2,8:18.0
2,-2,8:18.0
-5,-1,8:18.0
-4,-1,8:18.0
-3,-1,8:18.0
-2,-1,8:18.0
-1,-1,8:18.0
0,-1,8:18.0
1,-1,8:17.0
2,-1,8:18.0
3,-1,8:18.0
-4,0,8:18.0
-3,0,8:18.0
-2,0,8:18.0
-1,0,8:18.0
0,0,8:18.0
1,0,8:18.0
2,0,8:18.0
3,0,8:18.0
-3,1,8:18.0
-2,1,8:18.0
-1,1,8:18.0
0,1,8:18.0
1,1,8:18.0
2,1,8:18.0
3,1,8:18.0
-3,2,8:18.0
-2,2,8:18.0
-1,2,8:18.0
0,2,8:18.0
1,2,8:18.0
2,2,8:18.0
3,2,8:18.0
4,2,8:18.0
-4,3,8:18.0
-3,3,8:18.0
-2,3,8:17.0
-1,3,8:18.0
0,3,8:18.0
1,3,8:18.0
2,3,8:17.0
3,3,8:18.0
4,3,8:18.0
-5,4,8:18.0
-4,4,8:18.0
-3,4,8:18.0
-2,4,8:18.0
-1,4,8:18.0
0,4,8:18.0
1,4,8:18.0
2,4,8:18.0
3,4,8:18.0
4,4,8:18.0
-5,5,8:18.0
-4,5,8:18.0
-3,5,8:17.0
-2,5,8:18.0
-1,5,8:18.0
0,5,8:18.0
1,5,8:18.0
2,5,8:18.0
3,5,8:18.0
4,5,8:18.0
-5,6,8:18.0
-4,6,8:18.0
-3,6,8:18.0
-2,6,8:18.0
-1,6,8:18.0
0,6,8:18.0
1,6,8:17.0
2,6,8:18.0
3,6,8:18.0
-4,7,8:18.0
-3,7,8:18.0
0,7,8:18.0
1,7,8:18.0
-2,-4,9:18.0
-3,-3,9:18.0
-2,-3,9:18.0
-1,-3,9:18.0
-3,-2,9:18.0
-2,-2,9:18.0
-1,-2,9:18.0
0,-2,9:18.0
1,-2,9:18.0
-4,-1,9:18.0
-3,-1,9:18.0
-2,-1,9:18.0
-1,-1,9:18.0
0,-1,9:18.0
1,-1,9:18.0
2,-1,9:18.0
-3,0,9:18.0
-2,0,9:18.0
-1,0,9:18.0
0,0,9:18.0
1,0,9:18.0
2,0,9:18.0
-3,1,9:18.0
-2,1,9:17.8
-1,1,9:18.0
0,1,9:18.0
1,1,9:18.0
2,1,9:18.0
-4,2,9:18.0
-3,2,9:18.0
-2,2,9:17.8
-1,2,9:18.0
0,2,9:18.0
1,2,9:18.0
2,2,9:18.0
3,2,9:18.0
-5,3,9:18.0
-4,3,9:18.0
-3,3,9:17.0
-2,3,9:17.0
-1,3,9:18.0
0,3,9:18.0
1,3,9:18.0
2,3,9:18.0
3,3,9:18.0
-6,4,9:18.0
-5,4,9:18.0
-4,4,9:18.0
-3,4,9:18.0
-2,4,9:18.0
-1,4,9:18.0
0,4,9:18.0
1,4,9:18.0
2,4,9:18.0
3,4,9:18.0
-7,5,9:18.0
-6,5,9:18.0
-5,5,9:18.0
-4,5,9:18.0
-3,5,9:18.0
-2,5,9:18.0
-1,5,9:18.0
0,5,9:18.0
1,5,9:18.0
2,5,9:18.0
3,5,9:18.0
-7,6,9:18.0
-6,6,9:18.0
-5,6,9:18.0
-4,6,9:17.0
-3,6,9:18.0
-2,6,9:18.0
0,6,9:18.0
1,6,9:18.0
2,6,9:18.0
-7,7,9:18.0
-6,7,9:18.0
-5,7,9:18.0
-4,7,9:18.0
-3,7,9:18.0
-2,7,9:18.0
-6,8,9:18.0
-5,8,9:18.0
-4,8,9:18.0
-3,8,9:18.0
-3,-2,10:18.0
-2,-2,10:18.0
-1,-2,10:18.0
-3,-1,10:18.0
-2,-1,10:18.0
-1,-1,10:18.0
0,-1,10:18.0
-5,0,10:18.0
-3,0,10:18.0
-2,0,10:17.0
-1,0,10:18.0
0,0,10:18.0
-6,1,10:18.0
-5,1,10:18.0
-4,1,10:18.0
-3,1,10:18.0
-2,1,10:18.0
-1,1,10:18.0
-7,2,10:18.0
-6,2,10:18.0
-5,2,10:18.0
-4,2,10:17.0
-3,2,10:18.0
-2,2,10:18.0
-1,2,10:18.0
-6,3,10:18.0
-5,3,10:18.0
-4,3,10:18.0
-3,3,10:18.0
-2,3,10:17.0
-1,3,10:18.0
0,3,10:18.0
1,3,10:18.0
-5,4,10:18.0
-4,4,10:18.0
-3,4,10:18.0
-2,4,10:17.8
-1,4,10:18.0
0,4,10:18.0
1,4,10:18.0
2,4,10:18.0
-2,5,10:18.0
-1,5,10:18.0
0,5,10:18.0
1,5,10:18.0
-5,6,10:18.0
-4,6,10:18.0
-2,6,10:18.0
-1,6,10:18.0
0,6,10:18.0
-5,7,10:18.0
-4,7,10:18.0
-1,7,10:18.0
0,7,10:18.0
-3,-3,11:18.0
-2,-3,11:18.0
-1,-3,11:18.0
-4,-2,11:18.0
-3,-2,11:18.0
-2,-2,11:18.0
-1,-2,11:18.0
0,-2,11:18.0
-4,-1,11:18.0
-3,-1,11:18.0
-2,-1,11:17.0
-1,-1,11:18.0
0,-1,11:18.0
-5,0,11:18.0
-4,0,11:18.0
-3,0,11:18.0
-2,0,11:18.0
-1,0,11:18.0
0,0,11:18.0
-6,1,11:18.0
-5,1,11:18.0
-4,1,11:18.0
-3,1,11:18.0
-2,1,11:18.0
-1,1,11:18.0
-7,2,11:18.0
-6,2,11:18.0
-5,2,11:17.0
-4,2,11:18.0
-3,2,11:18.0
-1,2,11:18.0
-6,3,11:18.0
-5,3,11:18.0
-4,3,11:18.0
-3,3,11:18.0
-2,3,11:17.0
-1,3,11:18.0
-4,4,11:18.0
-3,4,11:18.0
-2,4,11:18.0
-1,4,11:18.0
0,4,11:18.0
-3,5,11:18.0
-2,5,11:18.0
-1,5,11:17.0
0,5,11:18.0
1,5,11:18.0
-2,6,11:18.0
-1,6,11:18.0
0,6,11:18.0
-1,7,11:18.0
-3,-2,12:18.0
-2,-2,12:18.0
-1,-2,12:18.0
-3,-1,12:18.0
-2,-1,12:18.0
-1,-1,12:18.0
-3,0,12:18.0
-2,0,12:18.0
-1,0,12:18.0
0,0,12:18.0
-5,1,12:18.0
-4,1,12:18.0
-3,1,12:18.0
-2,1,12:18.0
-1,1,12:18.0
0,1,12:18.0
1,1,12:18.0
-6,2,12:18.0
-5,2,12:18.0
-4,2,12:18.0
-3,2,12:18.0
-2,2,12:17.8
-1,2,12:18.0
0,2,12:18.0
1,2,12:18.0
-5,3,12:18.0
-4,3,12:18.0
-3,3,12:18.0
-2,3,12:17.0
-1,3,12:18.0
0,3,12:18.0
-4,4,12:18.0
-3,4,12:17.0
-2,4,12:18.0
-1,4,12:18.0
-3,5,12:18.0
-1,5,12:18.0
-2,0,13:18.0
-1,0,13:18.0
-2,1,13:18.0
-1,1,13:17.0
0,1,13:18.0
-3,2,13:18.0
-2,2,13:18.0
-1,2,13:18.0
-3,3,13:18.0
-2,3,13:17.0
-1,3,13:18.0
-3,4,13:18.0
-2,4,13:18.0
-1,1,14:18.0
-2,3,14:18.0
