[META]
version=2.0
spawnOnBlockType=2
spawnSunlight=True
spawnDarkness=False
spawnWater=False
spawnLava=False
underFill=True
randomRotation=True
dig=True
tree=True
branch=False
needsFoundation=True
rarity=20
collisionPercentage=2
spawnElevationMin=0
spawnElevationMax=128
spawnInBiome=Custom
[DATA]
0,0,0:17.0
0,0,-1:17.0
0,0,1:17.0
0,-1,2:18.0
-1,0,2:18.0
0,0,2:17.0
1,0,2:18.0
0,1,2:18.0
1,-2,3:18.0
-1,-1,3:18.0
0,-1,3:18.0
1,-1,3:17.0
2,-1,3:18.0
-2,0,3:18.0
-1,0,3:17.0
0,0,3:17.0
1,0,3:17.0
-2,1,3:18.0
-1,1,3:18.0
0,1,3:18.0
1,1,3:18.0
-1,2,3:18.0
1,-2,4:18.0
2,-2,4:18.0
-2,-1,4:18.0
0,-1,4:18.0
1,-1,4:17.0
2,-1,4:18.0
3,-1,4:18.0
-3,0,4:18.0
-2,0,4:18.0
-1,0,4:18.0
0,0,4:18.0
1,0,4:18.0
2,0,4:18.0
-3,1,4:18.0
-2,1,4:17.0
-1,1,4:17.0
0,1,4:18.0
-2,2,4:18.0
-1,2,4:18.0
0,2,4:18.0
0,-2,5:18.0
1,-2,5:18.0
2,-2,5:18.0
-1,-1,5:18.0
0,-1,5:18.0
1,-1,5:17.0
2,-1,5:18.0
3,-1,5:18.0
-2,0,5:18.0
-1,0,5:18.0
0,0,5:18.0
1,0,5:18.0
2,0,5:18.0
-3,1,5:18.0
-2,1,5:18.0
-1,1,5:18.0
0,1,5:18.0
1,1,5:18.0
-2,2,5:18.0
-1,2,5:18.0
1,-2,6:18.0
0,-1,6:18.0
1,-1,6:18.0
2,-1,6:18.0
-1,0,6:18.0
0,0,6:18.0
1,0,6:18.0
0,1,6:18.0
