
#######################################################################
# +-----------------------------------------------------------------+ #
# |                            BO3 object                           | #
# +-----------------------------------------------------------------+ #
#######################################################################

# This is the config file of a custom object.
# If you add this object correctly to your BiomeConfigs, it will spawn in the world.

# This is the creator of this BO3 object
Author: LordSmellyPants

# A short description of this BO3 object
Description: No description given

# The BO3 version, don't change this! It can be used by external applications to do a version check.
Version: 3

# The settings mode, WriteAll, WriteWithoutComments or WriteDisable. See WorldConfig.
SettingsMode: WriteDisable


#######################################################################
# +-----------------------------------------------------------------+ #
# |                          Main settings                          | #
# +-----------------------------------------------------------------+ #
#######################################################################

# This needs to be set to true to spawn the object in the Tree and Sapling resources.
Tree: true

# The frequency of the BO3 from 1 to 200. Tries this many times to spawn this BO3 when using the CustomObject(...) resource.
# Ignored by Tree(..), Sapling(..) and CustomStructure(..)
Frequency: 1

# The rarity of the BO3 from 0 to 100. Each spawn attempt has rarity% chance to succeed when using the CustomObject(...) resource.
# Ignored by Tree(..), Sapling(..) and CustomStructure(..)
Rarity: 10.0

# If you set this to true, the BO3 will be placed with a random rotation.
RotateRandomly: true

# The spawn height of the BO3 - randomY, highestBlock or highestSolidBlock.
SpawnHeight: highestSolidBlock

# The height limits for the BO3.
MinHeight: 50

MaxHeight: 100

# Objects can have other objects attacthed to it: branches. Branches can also
# have branches attached to it, which can also have branches, etc. This is the
# maximum branch depth for this objects.
MaxBranchDepth: 10

# When spawned with the UseWorld keyword, this BO3 should NOT spawn in the following biomes.
# If you writer.write the BO3 name directly in the BiomeConfigs, this will be ignored.
ExcludedBiomes: All


#######################################################################
# +-----------------------------------------------------------------+ #
# |                      Source block settings                      | #
# +-----------------------------------------------------------------+ #
#######################################################################

# The block(s) the BO3 should spawn in.
SourceBlocks: AIR

# The maximum percentage of the BO3 that can be outside the SourceBlock.
# The BO3 won't be placed on a location with more blocks outside the SourceBlock than this percentage.
MaxPercentageOutsideSourceBlock: 10

# What to do when a block is about to be placed outside the SourceBlock? (dontPlace, placeAnyway)
OutsideSourceBlock: placeAnyway


#######################################################################
# +-----------------------------------------------------------------+ #
# |                              Blocks                             | #
# +-----------------------------------------------------------------+ #
#######################################################################

# All the blocks used in the BO3 are listed here. Possible blocks:
# Block(x,y,z,id[.data][,nbtfile.nbt)
# RandomBlock(x,y,z,id[:data][,nbtfile.nbt],chance[,id[:data][,nbtfile.nbt],chance[,...]])
# So RandomBlock(0,0,0,CHEST,chest.nbt,50,CHEST,anotherchest.nbt,100) will spawn a chest at
# the BO3 origin, and give it a 50% chance to have the contents of chest.nbt, or, if that
# fails, a 100% percent chance to have the contents of anotherchest.nbt.
Block(-20,11,0,LEAVES)
Block(-20,11,2,LEAVES)
Block(-20,12,0,LEAVES)
Block(-20,12,3,LEAVES)
Block(-20,13,-1,LEAVES)
Block(-20,14,5,LEAVES)
Block(-20,14,7,LEAVES)
Block(-20,15,5,LEAVES)
Block(-20,15,6,LEAVES)
Block(-20,15,7,LEAVES)
Block(-20,16,5,LEAVES)
Block(-20,16,6,LEAVES)
Block(-20,17,4,LEAVES)
Block(-20,17,7,LEAVES)
Block(-20,17,8,LEAVES)
Block(-20,18,6,LEAVES)
Block(-20,18,8,LEAVES)
Block(-20,19,9,LEAVES)
Block(-19,5,0,LEAVES)
Block(-19,6,-2,LEAVES)
Block(-19,6,-1,LEAVES)
Block(-19,7,-3,LEAVES)
Block(-19,8,-3,LEAVES)
Block(-19,8,-2,LEAVES)
Block(-19,9,-4,LEAVES)
Block(-19,9,-3,LEAVES)
Block(-19,9,-1,LEAVES)
Block(-19,10,-5,LEAVES)
Block(-19,10,-3,LEAVES)
Block(-19,10,1,LEAVES)
Block(-19,10,2,LEAVES)
Block(-19,11,-4,LEAVES)
Block(-19,11,-2,LEAVES)
Block(-19,11,-1,LEAVES)
Block(-19,11,0,LEAVES)
Block(-19,11,1,LEAVES)
Block(-19,11,2,LEAVES)
Block(-19,11,3,LEAVES)
Block(-19,12,-3,LEAVES)
Block(-19,12,-1,LEAVES)
Block(-19,12,0,LEAVES)
Block(-19,12,1,LEAVES)
Block(-19,12,2,LEAVES)
Block(-19,12,3,LEAVES)
Block(-19,12,4,LEAVES)
Block(-19,13,-2,LEAVES)
Block(-19,13,-1,LEAVES)
Block(-19,13,0,LEAVES)
Block(-19,13,2,LEAVES)
Block(-19,13,5,LEAVES)
Block(-19,13,8,LEAVES)
Block(-19,14,1,LEAVES)
Block(-19,14,4,LEAVES)
Block(-19,14,5,LEAVES)
Block(-19,15,2,LEAVES)
Block(-19,15,3,LEAVES)
Block(-19,15,6,LEAVES)
Block(-19,16,3,LEAVES)
Block(-19,16,5,LEAVES)
Block(-19,16,6,LEAVES)
Block(-19,16,7,LEAVES)
Block(-19,16,8,LEAVES)
Block(-19,17,3,LEAVES)
Block(-19,17,4,LEAVES)
Block(-19,17,5,LEAVES)
Block(-19,17,6,LEAVES)
Block(-19,17,7,LEAVES)
Block(-19,17,8,LEAVES)
Block(-19,17,9,LEAVES)
Block(-19,18,5,LEAVES)
Block(-19,18,6,LEAVES)
Block(-19,18,7,LEAVES)
Block(-19,18,8,LEAVES)
Block(-19,18,9,LEAVES)
Block(-19,18,11,LEAVES)
Block(-19,19,7,LEAVES)
Block(-19,19,9,LEAVES)
Block(-19,19,10,LEAVES)
Block(-18,4,0,LEAVES)
Block(-18,5,-1,LEAVES)
Block(-18,5,0,LEAVES)
Block(-18,5,1,LEAVES)
Block(-18,6,-1,LEAVES)
Block(-18,6,0,LEAVES)
Block(-18,7,-4,LEAVES)
Block(-18,7,-3,LEAVES)
Block(-18,7,-2,LEAVES)
Block(-18,7,0,LEAVES)
Block(-18,8,-4,LEAVES)
Block(-18,8,-3,LEAVES)
Block(-18,8,-2,LEAVES)
Block(-18,8,-1,LEAVES)
Block(-18,9,-4,LEAVES)
Block(-18,9,-3,LEAVES)
Block(-18,9,-2,LEAVES)
Block(-18,10,-5,LEAVES)
Block(-18,10,-4,LEAVES)
Block(-18,10,-3,LEAVES)
Block(-18,10,-1,LEAVES)
Block(-18,11,-4,LEAVES)
Block(-18,11,-3,LEAVES)
Block(-18,11,-2,LEAVES)
Block(-18,11,-1,LEAVES)
Block(-18,11,0,LEAVES)
Block(-18,11,1,LEAVES)
Block(-18,11,2,LEAVES)
Block(-18,12,-3,LEAVES)
Block(-18,12,-2,LEAVES)
Block(-18,12,0,LEAVES)
Block(-18,12,1,LEAVES)
Block(-18,12,2,LEAVES)
Block(-18,12,3,LEAVES)
Block(-18,12,4,LEAVES)
Block(-18,12,5,LEAVES)
Block(-18,13,-2,LEAVES)
Block(-18,13,-1,LEAVES)
Block(-18,13,0,LEAVES)
Block(-18,13,1,LEAVES)
Block(-18,13,2,LEAVES)
Block(-18,13,4,LEAVES)
Block(-18,13,5,LEAVES)
Block(-18,13,6,LEAVES)
Block(-18,14,-1,LEAVES)
Block(-18,14,0,LEAVES)
Block(-18,14,1,LEAVES)
Block(-18,14,2,LEAVES)
Block(-18,14,3,LEAVES)
Block(-18,14,4,LEAVES)
Block(-18,14,5,LEAVES)
Block(-18,14,7,LEAVES)
Block(-18,15,1,LEAVES)
Block(-18,15,2,LEAVES)
Block(-18,15,3,LEAVES)
Block(-18,15,5,LEAVES)
Block(-18,15,6,LEAVES)
Block(-18,15,8,LEAVES)
Block(-18,16,2,LEAVES)
Block(-18,16,3,LEAVES)
Block(-18,16,4,LEAVES)
Block(-18,16,5,LEAVES)
Block(-18,16,6,LEAVES)
Block(-18,16,8,LEAVES)
Block(-18,16,9,LEAVES)
Block(-18,17,3,LEAVES)
Block(-18,17,4,LEAVES)
Block(-18,17,5,LEAVES)
Block(-18,17,6,LEAVES)
Block(-18,17,7,LEAVES)
Block(-18,17,8,LEAVES)
Block(-18,17,9,LEAVES)
Block(-18,17,10,LEAVES)
Block(-18,18,5,LEAVES)
Block(-18,18,6,LEAVES)
Block(-18,18,7,LEAVES)
Block(-18,18,8,LEAVES)
Block(-18,18,9,LEAVES)
Block(-18,18,10,LEAVES)
Block(-18,18,11,LEAVES)
Block(-18,18,12,LEAVES)
Block(-18,19,6,LEAVES)
Block(-18,19,7,LEAVES)
Block(-18,19,9,LEAVES)
Block(-18,19,10,LEAVES)
Block(-18,19,11,LEAVES)
Block(-18,20,10,LEAVES)
Block(-18,20,11,LEAVES)
Block(-17,4,0,LEAVES)
Block(-17,4,1,LEAVES)
Block(-17,4,2,LEAVES)
Block(-17,5,-2,LEAVES)
Block(-17,5,-1,LEAVES)
Block(-17,5,0,LEAVES)
Block(-17,5,1,LEAVES)
Block(-17,5,2,LEAVES)
Block(-17,5,3,LEAVES)
Block(-17,6,-2,LEAVES)
Block(-17,6,0,LEAVES)
Block(-17,6,1,LEAVES)
Block(-17,6,2,LEAVES)
Block(-17,6,3,LEAVES)
Block(-17,7,-4,LEAVES)
Block(-17,7,-3,LEAVES)
Block(-17,7,-2,LEAVES)
Block(-17,8,-4,LEAVES)
Block(-17,8,-3,LEAVES)
Block(-17,9,-4,LEAVES)
Block(-17,9,-1,LEAVES)
Block(-17,9,1,LEAVES)
Block(-17,9,2,LEAVES)
Block(-17,10,-5,LEAVES)
Block(-17,10,-4,LEAVES)
Block(-17,10,-3,LEAVES)
Block(-17,10,-1,LEAVES)
Block(-17,10,2,LEAVES)
Block(-17,11,-6,LEAVES)
Block(-17,11,-4,LEAVES)
Block(-17,11,-2,LEAVES)
Block(-17,11,-1,LEAVES)
Block(-17,11,1,LEAVES)
Block(-17,11,2,LEAVES)
Block(-17,12,-3,LEAVES)
Block(-17,12,-2,LEAVES)
Block(-17,12,-1,LEAVES)
Block(-17,12,0,LEAVES)
Block(-17,12,1,LEAVES)
Block(-17,12,2,LEAVES)
Block(-17,12,3,LEAVES)
Block(-17,12,5,LEAVES)
Block(-17,12,6,LEAVES)
Block(-17,12,7,LEAVES)
Block(-17,13,-2,LEAVES)
Block(-17,13,-1,LEAVES)
Block(-17,13,0,LEAVES)
Block(-17,13,2,LEAVES)
Block(-17,13,3,LEAVES)
Block(-17,13,5,LEAVES)
Block(-17,13,7,LEAVES)
Block(-17,13,8,LEAVES)
Block(-17,14,-4,LEAVES)
Block(-17,14,0,LEAVES)
Block(-17,14,2,LEAVES)
Block(-17,14,4,LEAVES)
Block(-17,14,5,LEAVES)
Block(-17,14,6,LEAVES)
Block(-17,14,7,LEAVES)
Block(-17,15,1,LEAVES)
Block(-17,15,2,LEAVES)
Block(-17,15,4,LEAVES)
Block(-17,15,5,LEAVES)
Block(-17,15,6,LEAVES)
Block(-17,15,8,LEAVES)
Block(-17,15,9,LEAVES)
Block(-17,16,-6,LEAVES)
Block(-17,16,3,LEAVES)
Block(-17,16,4,LEAVES)
Block(-17,16,5,LEAVES)
Block(-17,16,6,LEAVES)
Block(-17,16,8,LEAVES)
Block(-17,17,4,LEAVES)
Block(-17,17,5,LEAVES)
Block(-17,17,6,LOG)
Block(-17,17,7,LOG)
Block(-17,17,8,LEAVES)
Block(-17,18,-4,LEAVES)
Block(-17,18,-2,LEAVES)
Block(-17,18,6,LEAVES)
Block(-17,18,7,LEAVES)
Block(-17,18,8,LEAVES)
Block(-17,18,9,LEAVES)
Block(-17,18,10,LEAVES)
Block(-17,18,11,LEAVES)
Block(-17,19,-4,LEAVES)
Block(-17,19,6,LEAVES)
Block(-17,19,7,LEAVES)
Block(-17,19,8,LEAVES)
Block(-17,19,9,LEAVES)
Block(-17,19,10,LEAVES)
Block(-17,19,11,LEAVES)
Block(-17,19,12,LEAVES)
Block(-17,19,13,LEAVES)
Block(-17,20,7,LEAVES)
Block(-17,20,9,LEAVES)
Block(-17,20,11,LEAVES)
Block(-17,20,12,LEAVES)
Block(-17,21,11,LEAVES)
Block(-16,4,3,LEAVES)
Block(-16,5,-2,LEAVES)
Block(-16,5,-1,LEAVES)
Block(-16,5,0,LEAVES)
Block(-16,5,1,LEAVES)
Block(-16,5,2,LEAVES)
Block(-16,5,3,LEAVES)
Block(-16,6,-4,LEAVES)
Block(-16,6,-3,LEAVES)
Block(-16,6,-2,LEAVES)
Block(-16,6,0,LEAVES)
Block(-16,6,1,LEAVES)
Block(-16,6,2,LEAVES)
Block(-16,7,-5,LEAVES)
Block(-16,7,-4,LEAVES)
Block(-16,7,-3,LEAVES)
Block(-16,7,-2,LEAVES)
Block(-16,7,-1,LEAVES)
Block(-16,7,0,LEAVES)
Block(-16,7,1,LEAVES)
Block(-16,8,-4,LEAVES)
Block(-16,8,-3,LEAVES)
Block(-16,8,-1,LEAVES)
Block(-16,9,-5,LEAVES)
Block(-16,9,-4,LEAVES)
Block(-16,9,-3,LEAVES)
Block(-16,9,-2,LEAVES)
Block(-16,9,-1,LEAVES)
Block(-16,9,0,LEAVES)
Block(-16,10,-6,LEAVES)
Block(-16,10,-5,LEAVES)
Block(-16,10,-4,LEAVES)
Block(-16,10,-3,LEAVES)
Block(-16,10,0,LEAVES)
Block(-16,10,1,LEAVES)
Block(-16,10,2,LEAVES)
Block(-16,11,-7,LEAVES)
Block(-16,11,-6,LEAVES)
Block(-16,11,-5,LEAVES)
Block(-16,11,-4,LEAVES)
Block(-16,11,-3,LEAVES)
Block(-16,11,-2,LEAVES)
Block(-16,11,-1,LEAVES)
Block(-16,12,-4,LEAVES)
Block(-16,12,-3,LEAVES)
Block(-16,12,-1,LEAVES)
Block(-16,12,0,LEAVES)
Block(-16,12,1,LEAVES)
Block(-16,12,2,LEAVES)
Block(-16,12,3,LEAVES)
Block(-16,13,-7,LEAVES)
Block(-16,13,-2,LEAVES)
Block(-16,13,-1,LEAVES)
Block(-16,13,1,LEAVES)
Block(-16,13,2,LEAVES)
Block(-16,13,4,LEAVES)
Block(-16,13,5,LEAVES)
Block(-16,13,6,LEAVES)
Block(-16,13,7,LEAVES)
Block(-16,14,-7,LEAVES)
Block(-16,14,-5,LEAVES)
Block(-16,14,-4,LEAVES)
Block(-16,14,4,LEAVES)
Block(-16,14,6,LEAVES)
Block(-16,14,7,LEAVES)
Block(-16,15,-6,LEAVES)
Block(-16,15,-4,LEAVES)
Block(-16,15,1,LEAVES)
Block(-16,15,3,LEAVES)
Block(-16,15,5,LEAVES)
Block(-16,15,7,LEAVES)
Block(-16,16,-6,LEAVES)
Block(-16,16,-3,LEAVES)
Block(-16,16,-2,LEAVES)
Block(-16,16,3,LEAVES)
Block(-16,16,4,LEAVES)
Block(-16,16,5,LEAVES)
Block(-16,16,6,LEAVES)
Block(-16,16,7,LOG)
Block(-16,16,8,LOG)
Block(-16,17,-5,LEAVES)
Block(-16,17,-3,LEAVES)
Block(-16,17,7,LOG)
Block(-16,17,8,LEAVES)
Block(-16,17,10,LEAVES)
Block(-16,17,11,LEAVES)
Block(-16,18,-6,LEAVES)
Block(-16,18,4,LEAVES)
Block(-16,18,7,LEAVES)
Block(-16,18,8,LEAVES)
Block(-16,18,9,LEAVES)
Block(-16,18,10,LEAVES)
Block(-16,18,11,LEAVES)
Block(-16,19,-5,LEAVES)
Block(-16,19,7,LEAVES)
Block(-16,19,9,LEAVES)
Block(-16,19,10,LEAVES)
Block(-16,19,11,LEAVES)
Block(-16,19,12,LEAVES)
Block(-16,19,13,LEAVES)
Block(-16,20,-3,LEAVES)
Block(-16,20,8,LEAVES)
Block(-16,20,9,LEAVES)
Block(-16,20,10,LEAVES)
Block(-16,20,12,LEAVES)
Block(-16,20,13,LEAVES)
Block(-16,21,11,LEAVES)
Block(-16,21,12,LEAVES)
Block(-16,22,11,LEAVES)
Block(-15,3,0,LEAVES)
Block(-15,3,1,LEAVES)
Block(-15,4,-2,LEAVES)
Block(-15,4,0,LEAVES)
Block(-15,4,1,LEAVES)
Block(-15,4,2,LEAVES)
Block(-15,5,-4,LEAVES)
Block(-15,5,-2,LEAVES)
Block(-15,5,-1,LEAVES)
Block(-15,5,0,LEAVES)
Block(-15,5,1,LOG)
Block(-15,5,2,LOG)
Block(-15,5,3,LEAVES)
Block(-15,6,-5,LEAVES)
Block(-15,6,-4,LEAVES)
Block(-15,6,-3,LEAVES)
Block(-15,6,-2,LEAVES)
Block(-15,6,-1,LEAVES)
Block(-15,6,0,LEAVES)
Block(-15,6,1,LEAVES)
Block(-15,6,2,LOG)
Block(-15,7,-5,LEAVES)
Block(-15,7,-4,LEAVES)
Block(-15,7,-3,LEAVES)
Block(-15,7,-2,LEAVES)
Block(-15,7,-1,LEAVES)
Block(-15,7,0,LEAVES)
Block(-15,8,-4,LEAVES)
Block(-15,8,-1,LEAVES)
Block(-15,8,0,LEAVES)
Block(-15,9,-4,LEAVES)
Block(-15,9,-3,LEAVES)
Block(-15,9,-2,LEAVES)
Block(-15,10,-3,LEAVES)
Block(-15,10,-2,LEAVES)
Block(-15,10,2,LEAVES)
Block(-15,11,-7,LEAVES)
Block(-15,11,-6,LEAVES)
Block(-15,11,-5,LOG)
Block(-15,11,-4,LOG)
Block(-15,11,-3,LEAVES)
Block(-15,11,-2,LEAVES)
Block(-15,11,-1,LEAVES)
Block(-15,11,2,LEAVES)
Block(-15,12,-8,LEAVES)
Block(-15,12,-7,LEAVES)
Block(-15,12,-6,LEAVES)
Block(-15,12,3,LEAVES)
Block(-15,13,-5,LEAVES)
Block(-15,13,-2,LEAVES)
Block(-15,13,2,LEAVES)
Block(-15,13,4,LEAVES)
Block(-15,14,-6,LEAVES)
Block(-15,14,-5,LEAVES)
Block(-15,14,-4,LEAVES)
Block(-15,14,-2,LEAVES)
Block(-15,14,2,LEAVES)
Block(-15,14,3,LEAVES)
Block(-15,14,4,LEAVES)
Block(-15,15,-7,LEAVES)
Block(-15,15,-6,LEAVES)
Block(-15,15,-5,LEAVES)
Block(-15,15,-2,LEAVES)
Block(-15,15,4,LEAVES)
Block(-15,15,5,LEAVES)
Block(-15,15,8,LOG)
Block(-15,15,9,LOG)
Block(-15,16,-6,LEAVES)
Block(-15,16,-4,LEAVES)
Block(-15,16,-2,LEAVES)
Block(-15,16,4,LEAVES)
Block(-15,16,8,LOG)
Block(-15,17,-7,LEAVES)
Block(-15,17,-4,LEAVES)
Block(-15,17,-3,LEAVES)
Block(-15,17,-2,LEAVES)
Block(-15,17,3,LEAVES)
Block(-15,17,5,LEAVES)
Block(-15,18,-7,LEAVES)
Block(-15,18,-6,LEAVES)
Block(-15,18,-4,LEAVES)
Block(-15,18,-3,LEAVES)
Block(-15,18,4,LEAVES)
Block(-15,18,9,LEAVES)
Block(-15,18,10,LEAVES)
Block(-15,18,12,LEAVES)
Block(-15,19,-6,LEAVES)
Block(-15,19,-5,LEAVES)
Block(-15,19,-4,LEAVES)
Block(-15,19,-3,LEAVES)
Block(-15,19,-2,LEAVES)
Block(-15,19,4,LEAVES)
Block(-15,19,8,LEAVES)
Block(-15,19,9,LEAVES)
Block(-15,19,10,LEAVES)
Block(-15,19,11,LEAVES)
Block(-15,19,13,LEAVES)
Block(-15,19,14,LEAVES)
Block(-15,20,-4,LEAVES)
Block(-15,20,-2,LEAVES)
Block(-15,20,8,LEAVES)
Block(-15,20,9,LEAVES)
Block(-15,20,10,LEAVES)
Block(-15,20,12,LEAVES)
Block(-15,20,13,LEAVES)
Block(-15,20,14,LEAVES)
Block(-15,21,-4,LEAVES)
Block(-15,21,-3,LEAVES)
Block(-15,21,10,LEAVES)
Block(-15,21,11,LEAVES)
Block(-15,21,12,LEAVES)
Block(-15,21,13,LEAVES)
Block(-14,2,0,LEAVES)
Block(-14,3,-1,LEAVES)
Block(-14,3,0,LEAVES)
Block(-14,3,1,LEAVES)
Block(-14,3,2,LEAVES)
Block(-14,4,-2,LEAVES)
Block(-14,4,-1,LEAVES)
Block(-14,4,0,LEAVES)
Block(-14,4,1,LEAVES)
Block(-14,4,2,LEAVES)
Block(-14,4,3,LEAVES)
Block(-14,5,-4,LEAVES)
Block(-14,5,0,LOG)
Block(-14,5,1,LEAVES)
Block(-14,5,2,LEAVES)
Block(-14,5,3,LEAVES)
Block(-14,6,-4,LEAVES)
Block(-14,6,-2,LEAVES)
Block(-14,6,-1,LEAVES)
Block(-14,6,0,LEAVES)
Block(-14,6,1,LEAVES)
Block(-14,6,3,LOG)
Block(-14,7,-3,LEAVES)
Block(-14,7,-2,LEAVES)
Block(-14,7,-1,LEAVES)
Block(-14,7,3,LOG)
Block(-14,7,4,LOG)
Block(-14,8,-4,LEAVES)
Block(-14,8,-3,LEAVES)
Block(-14,8,-1,LEAVES)
Block(-14,9,-2,LEAVES)
Block(-14,11,-5,LEAVES)
Block(-14,11,-4,LOG)
Block(-14,11,-3,LOG)
Block(-14,11,-1,LEAVES)
Block(-14,11,2,LEAVES)
Block(-14,12,-7,LEAVES)
Block(-14,12,-6,LEAVES)
Block(-14,12,-3,LOG)
Block(-14,12,2,LEAVES)
Block(-14,12,3,LEAVES)
Block(-14,13,-7,LEAVES)
Block(-14,13,-6,LEAVES)
Block(-14,13,-5,LEAVES)
Block(-14,13,-4,LEAVES)
Block(-14,13,2,LEAVES)
Block(-14,13,3,LEAVES)
Block(-14,13,4,LEAVES)
Block(-14,13,9,LOG)
Block(-14,14,-8,LEAVES)
Block(-14,14,-7,LEAVES)
Block(-14,14,-3,LEAVES)
Block(-14,14,-2,LEAVES)
Block(-14,14,1,LEAVES)
Block(-14,14,4,LEAVES)
Block(-14,14,5,LEAVES)
Block(-14,14,9,LOG)
Block(-14,15,-4,LEAVES)
Block(-14,15,1,LEAVES)
Block(-14,15,2,LEAVES)
Block(-14,15,3,LEAVES)
Block(-14,15,9,LOG)
Block(-14,16,-8,LEAVES)
Block(-14,16,-6,LEAVES)
Block(-14,16,-4,LEAVES)
Block(-14,16,-2,LEAVES)
Block(-14,16,2,LEAVES)
Block(-14,16,3,LEAVES)
Block(-14,16,12,LEAVES)
Block(-14,16,14,LEAVES)
Block(-14,17,-8,LEAVES)
Block(-14,17,-7,LEAVES)
Block(-14,17,-6,LEAVES)
Block(-14,17,-5,LEAVES)
Block(-14,17,4,LEAVES)
Block(-14,17,14,LEAVES)
Block(-14,18,-7,LEAVES)
Block(-14,18,-6,LEAVES)
Block(-14,18,-5,LEAVES)
Block(-14,18,-4,LEAVES)
Block(-14,18,-3,LOG)
Block(-14,18,-2,LOG)
Block(-14,18,-1,LEAVES)
Block(-14,18,3,LEAVES)
Block(-14,18,4,LEAVES)
Block(-14,18,5,LEAVES)
Block(-14,18,10,LEAVES)
Block(-14,18,12,LEAVES)
Block(-14,18,13,LEAVES)
Block(-14,18,14,LEAVES)
Block(-14,19,-7,LEAVES)
Block(-14,19,-4,LOG)
Block(-14,19,-3,LOG)
Block(-14,19,-2,LEAVES)
Block(-14,19,-1,LEAVES)
Block(-14,19,4,LEAVES)
Block(-14,19,5,LEAVES)
Block(-14,19,9,LEAVES)
Block(-14,19,10,LEAVES)
Block(-14,19,11,LEAVES)
Block(-14,19,12,LEAVES)
Block(-14,19,13,LEAVES)
Block(-14,19,14,LEAVES)
Block(-14,19,15,LEAVES)
Block(-14,20,-4,LEAVES)
Block(-14,20,-3,LEAVES)
Block(-14,20,-2,LEAVES)
Block(-14,20,4,LEAVES)
Block(-14,20,9,LEAVES)
Block(-14,20,10,LEAVES)
Block(-14,20,12,LEAVES)
Block(-14,20,13,LEAVES)
Block(-14,20,14,LEAVES)
Block(-14,20,15,LEAVES)
Block(-14,21,-4,LEAVES)
Block(-14,21,-3,LEAVES)
Block(-14,21,-2,LEAVES)
Block(-14,21,9,LEAVES)
Block(-14,21,10,LEAVES)
Block(-14,21,11,LEAVES)
Block(-14,21,12,LEAVES)
Block(-14,21,13,LEAVES)
Block(-14,22,-4,LEAVES)
Block(-14,22,10,LEAVES)
Block(-14,22,12,LEAVES)
Block(-13,3,0,LEAVES)
Block(-13,4,-1,LEAVES)
Block(-13,4,0,LEAVES)
Block(-13,4,1,LEAVES)
Block(-13,4,2,LEAVES)
Block(-13,5,-7,LEAVES)
Block(-13,5,0,LEAVES)
Block(-13,5,1,LEAVES)
Block(-13,5,2,LEAVES)
Block(-13,6,-9,LEAVES)
Block(-13,6,-8,LEAVES)
Block(-13,6,0,LEAVES)
Block(-13,7,-8,LEAVES)
Block(-13,7,-3,LEAVES)
Block(-13,7,-1,LEAVES)
Block(-13,7,4,LOG)
Block(-13,8,-1,LEAVES)
Block(-13,8,4,LOG)
Block(-13,11,-6,LEAVES)
Block(-13,12,-7,LEAVES)
Block(-13,12,-6,LEAVES)
Block(-13,12,-5,LEAVES)
Block(-13,12,-4,LEAVES)
Block(-13,12,-3,LOG)
Block(-13,12,-2,LOG)
Block(-13,12,7,LOG)
Block(-13,12,8,LOG)
Block(-13,13,-10,LEAVES)
Block(-13,13,-8,LEAVES)
Block(-13,13,-7,LEAVES)
Block(-13,13,-5,LEAVES)
Block(-13,13,5,LEAVES)
Block(-13,13,8,LOG)
Block(-13,13,9,LOG)
Block(-13,14,-9,LEAVES)
Block(-13,14,-8,LEAVES)
Block(-13,14,-5,LEAVES)
Block(-13,15,-11,LEAVES)
Block(-13,15,-7,LEAVES)
Block(-13,15,-6,LEAVES)
Block(-13,15,-5,LEAVES)
Block(-13,15,0,LEAVES)
Block(-13,15,4,LEAVES)
Block(-13,15,5,LEAVES)
Block(-13,15,12,LEAVES)
Block(-13,15,14,LEAVES)
Block(-13,16,-12,LEAVES)
Block(-13,16,-11,LEAVES)
Block(-13,16,-6,LEAVES)
Block(-13,16,-5,LEAVES)
Block(-13,16,-4,LEAVES)
Block(-13,16,-1,LOG)
Block(-13,16,5,LEAVES)
Block(-13,16,12,LEAVES)
Block(-13,16,13,LEAVES)
Block(-13,16,14,LEAVES)
Block(-13,17,-11,LEAVES)
Block(-13,17,-8,LEAVES)
Block(-13,17,-7,LEAVES)
Block(-13,17,-6,LEAVES)
Block(-13,17,-2,LOG)
Block(-13,17,-1,LOG)
Block(-13,17,3,LEAVES)
Block(-13,17,12,LEAVES)
Block(-13,17,14,LEAVES)
Block(-13,18,-7,LEAVES)
Block(-13,18,-6,LEAVES)
Block(-13,18,-5,LEAVES)
Block(-13,18,-4,LEAVES)
Block(-13,18,-3,LEAVES)
Block(-13,18,-2,LOG)
Block(-13,18,-1,LEAVES)
Block(-13,18,3,LEAVES)
Block(-13,18,6,LEAVES)
Block(-13,18,10,LEAVES)
Block(-13,18,12,LEAVES)
Block(-13,19,-6,LEAVES)
Block(-13,19,-5,LEAVES)
Block(-13,19,-4,LEAVES)
Block(-13,19,-3,LEAVES)
Block(-13,19,-2,LEAVES)
Block(-13,19,-1,LEAVES)
Block(-13,19,0,LEAVES)
Block(-13,19,6,LEAVES)
Block(-13,19,7,LEAVES)
Block(-13,19,8,LEAVES)
Block(-13,19,9,LEAVES)
Block(-13,19,10,LEAVES)
Block(-13,19,11,LEAVES)
Block(-13,19,12,LEAVES)
Block(-13,19,14,LEAVES)
Block(-13,20,-4,LEAVES)
Block(-13,20,-3,LEAVES)
Block(-13,20,-2,LEAVES)
Block(-13,20,-1,LEAVES)
Block(-13,20,3,LEAVES)
Block(-13,20,5,LEAVES)
Block(-13,20,7,LEAVES)
Block(-13,20,8,LEAVES)
Block(-13,20,9,LEAVES)
Block(-13,20,10,LEAVES)
Block(-13,20,11,LEAVES)
Block(-13,20,12,LEAVES)
Block(-13,20,13,LEAVES)
Block(-13,20,14,LEAVES)
Block(-13,20,15,LEAVES)
Block(-13,21,-5,LEAVES)
Block(-13,21,-4,LEAVES)
Block(-13,21,-3,LEAVES)
Block(-13,21,9,LEAVES)
Block(-13,21,10,LEAVES)
Block(-13,21,11,LEAVES)
Block(-13,21,13,LEAVES)
Block(-13,21,14,LEAVES)
Block(-13,22,-3,LEAVES)
Block(-13,22,3,LEAVES)
Block(-13,22,9,LEAVES)
Block(-13,22,13,LEAVES)
Block(-12,4,-7,LEAVES)
Block(-12,5,-8,LEAVES)
Block(-12,5,-7,LEAVES)
Block(-12,5,-6,LEAVES)
Block(-12,5,1,LEAVES)
Block(-12,6,-10,LEAVES)
Block(-12,6,-9,LEAVES)
Block(-12,6,-8,LEAVES)
Block(-12,6,-7,LEAVES)
Block(-12,7,-10,LEAVES)
Block(-12,7,-8,LEAVES)
Block(-12,8,4,LOG)
Block(-12,9,4,LOG)
Block(-12,9,5,LOG)
Block(-12,10,6,LOG)
Block(-12,11,-11,LEAVES)
Block(-12,11,-5,LEAVES)
Block(-12,11,6,LOG)
Block(-12,11,7,LOG)
Block(-12,12,-12,LEAVES)
Block(-12,12,-4,LEAVES)
Block(-12,12,-2,LOG)
Block(-12,12,7,LOG)
Block(-12,13,-13,LEAVES)
Block(-12,13,-7,LEAVES)
Block(-12,13,-5,LEAVES)
Block(-12,13,-2,LOG)
Block(-12,14,-11,LEAVES)
Block(-12,14,-9,LEAVES)
Block(-12,14,-4,LEAVES)
Block(-12,14,-3,LEAVES)
Block(-12,14,-2,LOG)
Block(-12,14,-1,LOG)
Block(-12,15,-7,LEAVES)
Block(-12,15,-6,LEAVES)
Block(-12,15,-5,LEAVES)
Block(-12,15,-4,LEAVES)
Block(-12,15,-1,LOG)
Block(-12,15,0,LEAVES)
Block(-12,15,1,LEAVES)
Block(-12,15,5,LEAVES)
Block(-12,15,11,LEAVES)
Block(-12,15,12,LEAVES)
Block(-12,15,13,LEAVES)
Block(-12,15,15,LEAVES)
Block(-12,15,16,LEAVES)
Block(-12,16,-13,LEAVES)
Block(-12,16,-12,LEAVES)
Block(-12,16,-11,LEAVES)
Block(-12,16,-6,LEAVES)
Block(-12,16,-5,LEAVES)
Block(-12,16,-3,LEAVES)
Block(-12,16,-2,LEAVES)
Block(-12,16,-1,LOG)
Block(-12,16,3,LEAVES)
Block(-12,16,4,LEAVES)
Block(-12,16,5,LEAVES)
Block(-12,16,11,LEAVES)
Block(-12,16,12,LEAVES)
Block(-12,16,13,LEAVES)
Block(-12,16,14,LEAVES)
Block(-12,16,15,LEAVES)
Block(-12,16,16,LEAVES)
Block(-12,17,-12,LEAVES)
Block(-12,17,-10,LEAVES)
Block(-12,17,-7,LEAVES)
Block(-12,17,-6,LEAVES)
Block(-12,17,-2,LEAVES)
Block(-12,17,3,LEAVES)
Block(-12,17,4,LEAVES)
Block(-12,17,6,LEAVES)
Block(-12,17,7,LEAVES)
Block(-12,17,11,LEAVES)
Block(-12,17,13,LEAVES)
Block(-12,17,14,LEAVES)
Block(-12,17,16,LEAVES)
Block(-12,18,-6,LEAVES)
Block(-12,18,-4,LEAVES)
Block(-12,18,-2,LEAVES)
Block(-12,18,4,LEAVES)
Block(-12,18,5,LEAVES)
Block(-12,18,6,LEAVES)
Block(-12,18,10,LEAVES)
Block(-12,18,11,LEAVES)
Block(-12,18,12,LEAVES)
Block(-12,18,14,LEAVES)
Block(-12,18,16,LEAVES)
Block(-12,19,-5,LEAVES)
Block(-12,19,-3,LEAVES)
Block(-12,19,-2,LEAVES)
Block(-12,19,0,LEAVES)
Block(-12,19,3,LEAVES)
Block(-12,19,5,LEAVES)
Block(-12,19,7,LEAVES)
Block(-12,19,10,LEAVES)
Block(-12,19,11,LEAVES)
Block(-12,20,-5,LEAVES)
Block(-12,20,-4,LEAVES)
Block(-12,20,-2,LEAVES)
Block(-12,20,-1,LEAVES)
Block(-12,20,2,LEAVES)
Block(-12,20,3,LEAVES)
Block(-12,20,4,LEAVES)
Block(-12,20,6,LEAVES)
Block(-12,20,9,LEAVES)
Block(-12,20,10,LEAVES)
Block(-12,20,11,LEAVES)
Block(-12,20,13,LEAVES)
Block(-12,20,14,LEAVES)
Block(-12,21,-4,LEAVES)
Block(-12,21,-1,LEAVES)
Block(-12,21,3,LEAVES)
Block(-12,21,4,LEAVES)
Block(-12,21,10,LEAVES)
Block(-12,21,11,LEAVES)
Block(-12,21,12,LEAVES)
Block(-12,21,13,LEAVES)
Block(-12,22,2,LEAVES)
Block(-12,22,3,LEAVES)
Block(-12,22,4,LEAVES)
Block(-12,22,5,LEAVES)
Block(-12,22,10,LEAVES)
Block(-12,22,11,LEAVES)
Block(-12,23,3,LEAVES)
Block(-11,4,-8,LEAVES)
Block(-11,4,-7,LEAVES)
Block(-11,4,-6,LEAVES)
Block(-11,5,-9,LEAVES)
Block(-11,5,-8,LEAVES)
Block(-11,5,-7,LOG)
Block(-11,5,-6,LEAVES)
Block(-11,5,-5,LEAVES)
Block(-11,6,-10,LEAVES)
Block(-11,6,-9,LEAVES)
Block(-11,6,-7,LEAVES)
Block(-11,6,-6,LEAVES)
Block(-11,7,-10,LEAVES)
Block(-11,7,-7,LEAVES)
Block(-11,7,-6,LEAVES)
Block(-11,7,-5,LEAVES)
Block(-11,7,-4,LEAVES)
Block(-11,8,-8,LEAVES)
Block(-11,8,-6,LEAVES)
Block(-11,8,-5,LEAVES)
Block(-11,8,7,LOG)
Block(-11,9,4,LOG)
Block(-11,9,5,LOG)
Block(-11,9,7,LOG)
Block(-11,10,5,LOG)
Block(-11,10,6,LOG)
Block(-11,11,-11,LEAVES)
Block(-11,11,-10,LEAVES)
Block(-11,12,-13,LEAVES)
Block(-11,12,-12,LEAVES)
Block(-11,12,-11,LEAVES)
Block(-11,13,-14,LEAVES)
Block(-11,13,-13,LEAVES)
Block(-11,13,-12,LEAVES)
Block(-11,13,-11,LEAVES)
Block(-11,13,-4,LEAVES)
Block(-11,13,-3,LOG)
Block(-11,13,-2,LOG)
Block(-11,14,-12,LEAVES)
Block(-11,14,-11,LEAVES)
Block(-11,14,-9,LEAVES)
Block(-11,14,-4,LEAVES)
Block(-11,14,-3,LEAVES)
Block(-11,14,-1,LEAVES)
Block(-11,15,-13,LEAVES)
Block(-11,15,-12,LEAVES)
Block(-11,15,-11,LEAVES)
Block(-11,15,-10,LEAVES)
Block(-11,15,-9,LEAVES)
Block(-11,15,-8,LEAVES)
Block(-11,15,-5,LEAVES)
Block(-11,15,-4,LEAVES)
Block(-11,15,-3,LEAVES)
Block(-11,15,-2,LEAVES)
Block(-11,15,-1,LEAVES)
Block(-11,15,4,LEAVES)
Block(-11,15,5,LEAVES)
Block(-11,15,13,LEAVES)
Block(-11,15,14,LEAVES)
Block(-11,15,15,LEAVES)
Block(-11,15,16,LEAVES)
Block(-11,16,-13,LEAVES)
Block(-11,16,-12,LEAVES)
Block(-11,16,-11,LEAVES)
Block(-11,16,-10,LEAVES)
Block(-11,16,-8,LEAVES)
Block(-11,16,-7,LEAVES)
Block(-11,16,-6,LEAVES)
Block(-11,16,-5,LEAVES)
Block(-11,16,-4,LEAVES)
Block(-11,16,-3,LEAVES)
Block(-11,16,-2,LEAVES)
Block(-11,16,-1,LOG)
Block(-11,16,0,LOG)
Block(-11,16,1,LEAVES)
Block(-11,16,2,LEAVES)
Block(-11,16,16,LEAVES)
Block(-11,17,-12,LEAVES)
Block(-11,17,-11,LEAVES)
Block(-11,17,-10,LEAVES)
Block(-11,17,-9,LEAVES)
Block(-11,17,-8,LEAVES)
Block(-11,17,-6,LEAVES)
Block(-11,17,0,LEAVES)
Block(-11,17,2,LEAVES)
Block(-11,17,6,LEAVES)
Block(-11,17,8,LEAVES)
Block(-11,17,11,LEAVES)
Block(-11,17,12,LEAVES)
Block(-11,17,13,LEAVES)
Block(-11,17,14,LEAVES)
Block(-11,18,-11,LEAVES)
Block(-11,18,-4,LEAVES)
Block(-11,18,-3,LEAVES)
Block(-11,18,-2,LEAVES)
Block(-11,18,6,LEAVES)
Block(-11,18,7,LEAVES)
Block(-11,18,8,LEAVES)
Block(-11,18,9,LEAVES)
Block(-11,18,10,LEAVES)
Block(-11,18,11,LEAVES)
Block(-11,18,13,LEAVES)
Block(-11,18,14,LEAVES)
Block(-11,18,16,LEAVES)
Block(-11,18,17,LEAVES)
Block(-11,19,-5,LEAVES)
Block(-11,19,-4,LEAVES)
Block(-11,19,-3,LEAVES)
Block(-11,19,-2,LEAVES)
Block(-11,19,0,LEAVES)
Block(-11,19,3,LEAVES)
Block(-11,19,5,LEAVES)
Block(-11,19,6,LEAVES)
Block(-11,19,8,LEAVES)
Block(-11,19,10,LEAVES)
Block(-11,19,12,LEAVES)
Block(-11,19,15,LEAVES)
Block(-11,20,-3,LEAVES)
Block(-11,20,-1,LEAVES)
Block(-11,20,0,LEAVES)
Block(-11,20,1,LEAVES)
Block(-11,20,10,LEAVES)
Block(-11,20,12,LEAVES)
Block(-11,20,14,LEAVES)
Block(-11,21,2,LEAVES)
Block(-11,21,3,LEAVES)
Block(-11,21,5,LEAVES)
Block(-11,21,6,LEAVES)
Block(-11,21,10,LEAVES)
Block(-11,21,11,LEAVES)
Block(-11,21,12,LEAVES)
Block(-11,22,2,LEAVES)
Block(-11,22,3,LEAVES)
Block(-11,22,4,LEAVES)
Block(-11,22,5,LEAVES)
Block(-11,22,6,LEAVES)
Block(-11,22,11,LEAVES)
Block(-11,23,3,LEAVES)
Block(-11,23,4,LEAVES)
Block(-11,23,5,LEAVES)
Block(-10,4,-9,LEAVES)
Block(-10,4,-7,LEAVES)
Block(-10,4,-5,LEAVES)
Block(-10,5,-10,LEAVES)
Block(-10,5,-9,LEAVES)
Block(-10,5,-8,LEAVES)
Block(-10,5,-7,LEAVES)
Block(-10,5,-6,LEAVES)
Block(-10,5,-5,LEAVES)
Block(-10,6,-10,LEAVES)
Block(-10,6,-9,LEAVES)
Block(-10,6,-8,LEAVES)
Block(-10,6,-7,LEAVES)
Block(-10,6,-6,LOG)
Block(-10,7,-10,LEAVES)
Block(-10,7,-9,LEAVES)
Block(-10,7,-7,LEAVES)
Block(-10,7,-6,LOG)
Block(-10,7,-5,LEAVES)
Block(-10,8,-6,LEAVES)
Block(-10,9,5,LOG)
Block(-10,9,6,LOG)
Block(-10,9,7,LOG)
Block(-10,10,5,LOG)
Block(-10,11,-12,LEAVES)
Block(-10,11,-11,LEAVES)
Block(-10,11,-10,LEAVES)
Block(-10,12,-13,LEAVES)
Block(-10,12,-4,LOG)
Block(-10,12,-3,LOG)
Block(-10,12,14,LEAVES)
Block(-10,12,15,LEAVES)
Block(-10,12,16,LEAVES)
Block(-10,13,-13,LEAVES)
Block(-10,13,-4,LOG)
Block(-10,13,-3,LOG)
Block(-10,13,13,LEAVES)
Block(-10,14,-13,LEAVES)
Block(-10,14,-12,LEAVES)
Block(-10,14,-10,LEAVES)
Block(-10,14,-3,LEAVES)
Block(-10,14,0,LEAVES)
Block(-10,14,14,LEAVES)
Block(-10,14,15,LEAVES)
Block(-10,15,-13,LEAVES)
Block(-10,15,-12,LEAVES)
Block(-10,15,-11,LEAVES)
Block(-10,15,-8,LEAVES)
Block(-10,15,1,LEAVES)
Block(-10,15,13,LEAVES)
Block(-10,15,14,LEAVES)
Block(-10,15,16,LEAVES)
Block(-10,15,17,LEAVES)
Block(-10,16,-11,LEAVES)
Block(-10,16,-10,LEAVES)
Block(-10,16,-9,LEAVES)
Block(-10,16,-8,LEAVES)
Block(-10,16,-7,LEAVES)
Block(-10,16,-6,LEAVES)
Block(-10,16,-4,LEAVES)
Block(-10,16,3,LEAVES)
Block(-10,16,6,LEAVES)
Block(-10,16,12,LEAVES)
Block(-10,16,13,LEAVES)
Block(-10,16,15,LEAVES)
Block(-10,16,16,LEAVES)
Block(-10,16,17,LEAVES)
Block(-10,17,-12,LEAVES)
Block(-10,17,-10,LEAVES)
Block(-10,17,-9,LEAVES)
Block(-10,17,-8,LEAVES)
Block(-10,17,-5,LEAVES)
Block(-10,17,-4,LEAVES)
Block(-10,17,-2,LEAVES)
Block(-10,17,-1,LEAVES)
Block(-10,17,0,LOG)
Block(-10,17,1,LEAVES)
Block(-10,17,8,LEAVES)
Block(-10,17,13,LEAVES)
Block(-10,17,17,LEAVES)
Block(-10,18,-12,LEAVES)
Block(-10,18,-10,LEAVES)
Block(-10,18,-8,LEAVES)
Block(-10,18,-2,LEAVES)
Block(-10,18,-1,LEAVES)
Block(-10,18,1,LEAVES)
Block(-10,18,3,LEAVES)
Block(-10,18,4,LEAVES)
Block(-10,18,6,LEAVES)
Block(-10,18,7,LEAVES)
Block(-10,18,8,LEAVES)
Block(-10,18,10,LEAVES)
Block(-10,18,14,LEAVES)
Block(-10,18,16,LEAVES)
Block(-10,18,17,LEAVES)
Block(-10,19,-4,LEAVES)
Block(-10,19,-3,LEAVES)
Block(-10,19,-1,LEAVES)
Block(-10,19,0,LEAVES)
Block(-10,19,1,LEAVES)
Block(-10,19,2,LEAVES)
Block(-10,19,7,LEAVES)
Block(-10,19,8,LEAVES)
Block(-10,19,9,LEAVES)
Block(-10,19,15,LEAVES)
Block(-10,19,16,LEAVES)
Block(-10,19,17,LEAVES)
Block(-10,20,0,LEAVES)
Block(-10,20,1,LEAVES)
Block(-10,20,2,LEAVES)
Block(-10,20,7,LEAVES)
Block(-10,20,9,LEAVES)
Block(-10,21,1,LEAVES)
Block(-10,21,3,LEAVES)
Block(-10,21,4,LEAVES)
Block(-10,21,5,LEAVES)
Block(-10,21,8,LEAVES)
Block(-10,21,9,LEAVES)
Block(-10,21,10,LEAVES)
Block(-10,21,11,LEAVES)
Block(-10,22,2,LEAVES)
Block(-10,22,3,LEAVES)
Block(-10,22,4,LEAVES)
Block(-10,22,5,LEAVES)
Block(-10,22,6,LEAVES)
Block(-10,22,8,LEAVES)
Block(-10,22,10,LEAVES)
Block(-10,23,6,LEAVES)
Block(-10,23,7,LEAVES)
Block(-9,4,-10,LEAVES)
Block(-9,4,-7,LEAVES)
Block(-9,5,-10,LEAVES)
Block(-9,5,-9,LEAVES)
Block(-9,5,-8,LEAVES)
Block(-9,5,-7,LEAVES)
Block(-9,5,-6,LEAVES)
Block(-9,5,-5,LEAVES)
Block(-9,6,-10,LEAVES)
Block(-9,6,-9,LEAVES)
Block(-9,6,-8,LEAVES)
Block(-9,6,-6,LEAVES)
Block(-9,7,-9,LEAVES)
Block(-9,7,-8,LEAVES)
Block(-9,7,-7,LEAVES)
Block(-9,7,-6,LOG)
Block(-9,7,-5,LEAVES)
Block(-9,8,-8,LEAVES)
Block(-9,8,5,LOG)
Block(-9,9,5,LOG)
Block(-9,9,6,LOG)
Block(-9,10,6,LOG)
Block(-9,11,-10,LEAVES)
Block(-9,11,-4,LOG)
Block(-9,11,14,LEAVES)
Block(-9,11,15,LEAVES)
Block(-9,12,-11,LEAVES)
Block(-9,12,-9,LEAVES)
Block(-9,12,-6,LOG)
Block(-9,12,-5,LOG)
Block(-9,12,-4,LOG)
Block(-9,12,14,LEAVES)
Block(-9,12,15,LEAVES)
Block(-9,12,16,LEAVES)
Block(-9,13,-14,LEAVES)
Block(-9,13,-13,LEAVES)
Block(-9,13,-10,LOG)
Block(-9,13,-9,LOG)
Block(-9,13,-8,LEAVES)
Block(-9,13,13,LEAVES)
Block(-9,13,14,LEAVES)
Block(-9,13,15,LEAVES)
Block(-9,13,16,LEAVES)
Block(-9,13,17,LEAVES)
Block(-9,14,-9,LEAVES)
Block(-9,14,-8,LOG)
Block(-9,14,13,LEAVES)
Block(-9,14,14,LEAVES)
Block(-9,14,16,LEAVES)
Block(-9,15,-11,LEAVES)
Block(-9,15,-8,LEAVES)
Block(-9,15,0,LEAVES)
Block(-9,15,12,LEAVES)
Block(-9,15,13,LOG)
Block(-9,15,14,LEAVES)
Block(-9,15,16,LEAVES)
Block(-9,15,17,LEAVES)
Block(-9,16,-9,LEAVES)
Block(-9,16,-8,LEAVES)
Block(-9,16,-2,LEAVES)
Block(-9,16,-1,LEAVES)
Block(-9,16,0,LEAVES)
Block(-9,16,1,LEAVES)
Block(-9,16,2,LEAVES)
Block(-9,16,3,LEAVES)
Block(-9,16,6,LEAVES)
Block(-9,16,13,LOG)
Block(-9,17,-11,LEAVES)
Block(-9,17,-10,LEAVES)
Block(-9,17,-9,LEAVES)
Block(-9,17,-8,LEAVES)
Block(-9,17,-7,LEAVES)
Block(-9,17,-3,LEAVES)
Block(-9,17,-2,LEAVES)
Block(-9,17,-1,LEAVES)
Block(-9,17,0,LEAVES)
Block(-9,17,2,LEAVES)
Block(-9,17,4,LEAVES)
Block(-9,17,7,LEAVES)
Block(-9,17,13,LOG)
Block(-9,17,14,LOG)
Block(-9,17,15,LEAVES)
Block(-9,17,16,LEAVES)
Block(-9,18,-12,LEAVES)
Block(-9,18,-11,LEAVES)
Block(-9,18,-10,LEAVES)
Block(-9,18,-2,LEAVES)
Block(-9,18,-1,LEAVES)
Block(-9,18,0,LEAVES)
Block(-9,18,2,LEAVES)
Block(-9,18,6,LEAVES)
Block(-9,18,8,LEAVES)
Block(-9,18,13,LEAVES)
Block(-9,18,14,LOG)
Block(-9,18,15,LOG)
Block(-9,18,16,LEAVES)
Block(-9,18,17,LEAVES)
Block(-9,19,-1,LEAVES)
Block(-9,19,0,LEAVES)
Block(-9,19,1,LEAVES)
Block(-9,19,3,LEAVES)
Block(-9,19,4,LEAVES)
Block(-9,19,7,LEAVES)
Block(-9,19,15,LEAVES)
Block(-9,19,16,LEAVES)
Block(-9,19,17,LEAVES)
Block(-9,20,-1,LEAVES)
Block(-9,20,0,LEAVES)
Block(-9,20,4,LEAVES)
Block(-9,20,8,LEAVES)
Block(-9,20,13,LEAVES)
Block(-9,20,14,LEAVES)
Block(-9,20,15,LEAVES)
Block(-9,20,16,LEAVES)
Block(-9,20,17,LEAVES)
Block(-9,21,1,LEAVES)
Block(-9,21,2,LEAVES)
Block(-9,21,3,LEAVES)
Block(-9,21,4,LEAVES)
Block(-9,21,5,LEAVES)
Block(-9,21,7,LEAVES)
Block(-9,21,10,LEAVES)
Block(-9,21,15,LEAVES)
Block(-9,22,1,LEAVES)
Block(-9,22,2,LEAVES)
Block(-9,22,3,LEAVES)
Block(-9,22,4,LEAVES)
Block(-9,22,5,LEAVES)
Block(-9,22,6,LEAVES)
Block(-9,22,7,LEAVES)
Block(-9,22,8,LEAVES)
Block(-9,22,9,LEAVES)
Block(-9,23,3,LEAVES)
Block(-9,23,4,LEAVES)
Block(-9,23,8,LEAVES)
Block(-8,-6,1,LOG)
Block(-8,-5,1,LOG)
Block(-8,4,-11,LEAVES)
Block(-8,4,-7,LEAVES)
Block(-8,5,-11,LEAVES)
Block(-8,5,-10,LEAVES)
Block(-8,5,-7,LEAVES)
Block(-8,5,-6,LEAVES)
Block(-8,6,-11,LEAVES)
Block(-8,6,-10,LEAVES)
Block(-8,6,-7,LEAVES)
Block(-8,7,-10,LEAVES)
Block(-8,7,-9,LEAVES)
Block(-8,7,-8,LOG)
Block(-8,7,-7,LOG)
Block(-8,7,-6,LOG)
Block(-8,8,-9,LEAVES)
Block(-8,8,-7,LOG)
Block(-8,8,-6,LOG)
Block(-8,8,-5,LOG)
Block(-8,8,6,LOG)
Block(-8,9,-5,LOG)
Block(-8,9,-4,LOG)
Block(-8,9,5,LOG)
Block(-8,9,6,LOG)
Block(-8,9,7,LOG)
Block(-8,10,-4,LOG)
Block(-8,10,-3,LOG)
Block(-8,10,6,LOG)
Block(-8,10,12,LEAVES)
Block(-8,11,-4,LOG)
Block(-8,11,13,LEAVES)
Block(-8,12,-11,LEAVES)
Block(-8,12,-10,LEAVES)
Block(-8,12,-6,LOG)
Block(-8,12,14,LEAVES)
Block(-8,12,15,LEAVES)
Block(-8,12,17,LEAVES)
Block(-8,13,-14,LEAVES)
Block(-8,13,-12,LEAVES)
Block(-8,13,-11,LOG)
Block(-8,13,-9,LEAVES)
Block(-8,13,-8,LEAVES)
Block(-8,13,-7,LOG)
Block(-8,13,-6,LOG)
Block(-8,13,12,LOG)
Block(-8,13,13,LEAVES)
Block(-8,13,14,LEAVES)
Block(-8,13,15,LEAVES)
Block(-8,13,16,LEAVES)
Block(-8,13,17,LEAVES)
Block(-8,14,-13,LEAVES)
Block(-8,14,-12,LEAVES)
Block(-8,14,-11,LEAVES)
Block(-8,14,-9,LEAVES)
Block(-8,14,-8,LOG)
Block(-8,14,-7,LOG)
Block(-8,14,12,LOG)
Block(-8,14,14,LEAVES)
Block(-8,14,15,LEAVES)
Block(-8,14,16,LEAVES)
Block(-8,14,17,LEAVES)
Block(-8,15,-12,LEAVES)
Block(-8,15,-11,LEAVES)
Block(-8,15,-8,LEAVES)
Block(-8,15,-7,LEAVES)
Block(-8,15,-1,LEAVES)
Block(-8,15,0,LEAVES)
Block(-8,15,12,LOG)
Block(-8,15,16,LEAVES)
Block(-8,16,-12,LEAVES)
Block(-8,16,-11,LEAVES)
Block(-8,16,-9,LEAVES)
Block(-8,16,-8,LEAVES)
Block(-8,16,-1,LEAVES)
Block(-8,16,13,LEAVES)
Block(-8,16,15,LEAVES)
Block(-8,16,16,LEAVES)
Block(-8,17,-11,LEAVES)
Block(-8,17,-10,LEAVES)
Block(-8,17,0,LEAVES)
Block(-8,17,1,LEAVES)
Block(-8,17,2,LEAVES)
Block(-8,17,3,LEAVES)
Block(-8,17,7,LEAVES)
Block(-8,17,8,LEAVES)
Block(-8,17,9,LEAVES)
Block(-8,17,15,LEAVES)
Block(-8,17,16,LEAVES)
Block(-8,17,17,LEAVES)
Block(-8,18,-13,LEAVES)
Block(-8,18,-12,LEAVES)
Block(-8,18,-11,LEAVES)
Block(-8,18,-1,LEAVES)
Block(-8,18,1,LEAVES)
Block(-8,18,7,LEAVES)
Block(-8,18,16,LEAVES)
Block(-8,18,17,LEAVES)
Block(-8,19,-11,LEAVES)
Block(-8,19,0,LEAVES)
Block(-8,19,2,LEAVES)
Block(-8,19,8,LEAVES)
Block(-8,19,10,LEAVES)
Block(-8,19,14,LEAVES)
Block(-8,19,15,LEAVES)
Block(-8,19,16,LEAVES)
Block(-8,20,2,LEAVES)
Block(-8,20,4,LEAVES)
Block(-8,20,10,LEAVES)
Block(-8,21,2,LEAVES)
Block(-8,21,3,LEAVES)
Block(-8,21,4,LEAVES)
Block(-8,21,5,LEAVES)
Block(-8,21,6,LEAVES)
Block(-8,21,7,LEAVES)
Block(-8,21,8,LEAVES)
Block(-8,21,9,LEAVES)
Block(-8,21,10,LEAVES)
Block(-8,21,11,LEAVES)
Block(-8,21,16,LEAVES)
Block(-8,22,2,LEAVES)
Block(-8,22,3,LEAVES)
Block(-8,22,4,LEAVES)
Block(-8,22,5,LEAVES)
Block(-8,22,6,LEAVES)
Block(-8,22,7,LEAVES)
Block(-8,22,10,LEAVES)
Block(-8,23,4,LEAVES)
Block(-8,23,6,LEAVES)
Block(-8,23,8,LEAVES)
Block(-8,23,9,LEAVES)
Block(-7,-6,8,LOG)
Block(-7,-5,1,LOG)
Block(-7,-5,2,LOG)
Block(-7,-5,3,LOG)
Block(-7,-5,8,LOG)
Block(-7,-4,1,LOG)
Block(-7,-4,2,LOG)
Block(-7,-4,3,LOG)
Block(-7,5,-10,LEAVES)
Block(-7,6,-12,LEAVES)
Block(-7,6,-11,LEAVES)
Block(-7,6,-10,LOG)
Block(-7,6,-8,LEAVES)
Block(-7,6,-7,LEAVES)
Block(-7,7,-11,LEAVES)
Block(-7,7,-10,LOG)
Block(-7,7,-9,LOG)
Block(-7,7,-8,LOG)
Block(-7,8,-10,LEAVES)
Block(-7,9,-11,LEAVES)
Block(-7,9,-10,LEAVES)
Block(-7,9,-9,LEAVES)
Block(-7,9,-3,LOG)
Block(-7,9,6,LOG)
Block(-7,9,7,LOG)
Block(-7,9,12,LEAVES)
Block(-7,9,14,LEAVES)
Block(-7,10,-4,LOG)
Block(-7,10,-3,LOG)
Block(-7,10,-2,LOG)
Block(-7,10,6,LOG)
Block(-7,10,7,LOG)
Block(-7,10,11,LEAVES)
Block(-7,10,12,LEAVES)
Block(-7,10,13,LEAVES)
Block(-7,10,15,LEAVES)
Block(-7,11,-3,LOG)
Block(-7,11,12,LEAVES)
Block(-7,11,13,LEAVES)
Block(-7,11,16,LEAVES)
Block(-7,12,-10,LEAVES)
Block(-7,12,-8,LEAVES)
Block(-7,12,14,LEAVES)
Block(-7,12,15,LEAVES)
Block(-7,12,17,LEAVES)
Block(-7,13,-12,LEAVES)
Block(-7,13,-11,LEAVES)
Block(-7,13,-10,LEAVES)
Block(-7,13,-9,LEAVES)
Block(-7,13,-8,LEAVES)
Block(-7,13,-7,LEAVES)
Block(-7,13,11,LOG)
Block(-7,13,12,LOG)
Block(-7,13,14,LEAVES)
Block(-7,13,16,LEAVES)
Block(-7,13,17,LEAVES)
Block(-7,14,-11,LEAVES)
Block(-7,14,-9,LEAVES)
Block(-7,14,-8,LEAVES)
Block(-7,14,13,LEAVES)
Block(-7,14,14,LEAVES)
Block(-7,14,15,LEAVES)
Block(-7,14,17,LEAVES)
Block(-7,15,-11,LEAVES)
Block(-7,15,-10,LEAVES)
Block(-7,15,-8,LEAVES)
Block(-7,15,1,LEAVES)
Block(-7,15,14,LEAVES)
Block(-7,15,16,LEAVES)
Block(-7,15,17,LEAVES)
Block(-7,16,-12,LEAVES)
Block(-7,16,-11,LEAVES)
Block(-7,16,-10,LEAVES)
Block(-7,16,-9,LEAVES)
Block(-7,16,0,LEAVES)
Block(-7,16,12,LEAVES)
Block(-7,16,15,LEAVES)
Block(-7,16,17,LEAVES)
Block(-7,17,-12,LEAVES)
Block(-7,17,-10,LEAVES)
Block(-7,17,-9,LEAVES)
Block(-7,17,0,LEAVES)
Block(-7,17,8,LEAVES)
Block(-7,17,9,LEAVES)
Block(-7,17,13,LEAVES)
Block(-7,17,16,LEAVES)
Block(-7,17,17,LEAVES)
Block(-7,18,-12,LEAVES)
Block(-7,18,-11,LEAVES)
Block(-7,18,-10,LEAVES)
Block(-7,18,-1,LEAVES)
Block(-7,18,0,LEAVES)
Block(-7,18,1,LEAVES)
Block(-7,18,2,LEAVES)
Block(-7,18,10,LEAVES)
Block(-7,19,-12,LEAVES)
Block(-7,19,-1,LEAVES)
Block(-7,19,0,LEAVES)
Block(-7,19,1,LEAVES)
Block(-7,19,3,LEAVES)
Block(-7,19,6,LEAVES)
Block(-7,19,7,LEAVES)
Block(-7,19,8,LOG)
Block(-7,19,10,LEAVES)
Block(-7,19,11,LEAVES)
Block(-7,19,12,LEAVES)
Block(-7,19,16,LEAVES)
Block(-7,20,-1,LEAVES)
Block(-7,20,0,LEAVES)
Block(-7,20,2,LEAVES)
Block(-7,20,4,LEAVES)
Block(-7,20,6,LEAVES)
Block(-7,20,8,LOG)
Block(-7,20,9,LEAVES)
Block(-7,20,10,LEAVES)
Block(-7,20,11,LEAVES)
Block(-7,20,12,LEAVES)
Block(-7,21,1,LEAVES)
Block(-7,21,2,LEAVES)
Block(-7,21,3,LEAVES)
Block(-7,21,4,LEAVES)
Block(-7,21,5,LEAVES)
Block(-7,21,6,LEAVES)
Block(-7,21,7,LEAVES)
Block(-7,21,8,LEAVES)
Block(-7,21,9,LEAVES)
Block(-7,21,10,LEAVES)
Block(-7,21,11,LEAVES)
Block(-7,22,1,LEAVES)
Block(-7,22,2,LEAVES)
Block(-7,22,4,LEAVES)
Block(-7,22,5,LEAVES)
Block(-7,22,6,LEAVES)
Block(-7,22,7,LEAVES)
Block(-7,22,8,LEAVES)
Block(-7,22,11,LEAVES)
Block(-7,22,12,LEAVES)
Block(-7,23,2,LEAVES)
Block(-7,23,5,LEAVES)
Block(-7,23,7,LEAVES)
Block(-7,23,8,LEAVES)
Block(-6,-6,-1,LOG)
Block(-6,-6,0,LOG)
Block(-6,-5,6,LOG)
Block(-6,-5,7,LOG)
Block(-6,-5,8,LOG)
Block(-6,-4,3,LOG)
Block(-6,-4,5,LOG)
Block(-6,-4,6,LOG)
Block(-6,-3,3,LOG)
Block(-6,-3,5,LOG)
Block(-6,-3,6,LOG)
Block(-6,-2,3,LOG)
Block(-6,3,-10,LEAVES)
Block(-6,4,-11,LEAVES)
Block(-6,4,-10,LEAVES)
Block(-6,4,-9,LEAVES)
Block(-6,5,-12,LEAVES)
Block(-6,5,-11,LEAVES)
Block(-6,5,-8,LEAVES)
Block(-6,6,-11,LEAVES)
Block(-6,6,-8,LEAVES)
Block(-6,6,-7,LEAVES)
Block(-6,7,-7,LEAVES)
Block(-6,8,-12,LEAVES)
Block(-6,8,-11,LEAVES)
Block(-6,8,-10,LEAVES)
Block(-6,8,-8,LEAVES)
Block(-6,8,-1,LOG)
Block(-6,8,15,LEAVES)
Block(-6,9,-11,LEAVES)
Block(-6,9,-3,LOG)
Block(-6,9,-2,LOG)
Block(-6,9,-1,LOG)
Block(-6,9,7,LOG)
Block(-6,9,12,LEAVES)
Block(-6,9,13,LEAVES)
Block(-6,9,14,LEAVES)
Block(-6,10,-3,LOG)
Block(-6,10,-2,LOG)
Block(-6,10,6,LOG)
Block(-6,10,7,LOG)
Block(-6,10,11,LEAVES)
Block(-6,10,12,LEAVES)
Block(-6,10,13,LEAVES)
Block(-6,10,14,LEAVES)
Block(-6,10,15,LEAVES)
Block(-6,10,16,LEAVES)
Block(-6,11,12,LOG)
Block(-6,11,13,LEAVES)
Block(-6,11,14,LEAVES)
Block(-6,11,15,LEAVES)
Block(-6,12,10,LOG)
Block(-6,12,11,LOG)
Block(-6,12,13,LEAVES)
Block(-6,12,14,LEAVES)
Block(-6,12,15,LEAVES)
Block(-6,12,16,LEAVES)
Block(-6,13,-12,LEAVES)
Block(-6,13,-11,LEAVES)
Block(-6,13,-10,LEAVES)
Block(-6,13,-8,LEAVES)
Block(-6,13,11,LOG)
Block(-6,13,15,LEAVES)
Block(-6,13,16,LEAVES)
Block(-6,13,17,LEAVES)
Block(-6,14,-13,LEAVES)
Block(-6,14,-11,LEAVES)
Block(-6,14,16,LEAVES)
Block(-6,14,17,LEAVES)
Block(-6,15,-12,LEAVES)
Block(-6,15,-11,LEAVES)
Block(-6,15,-8,LEAVES)
Block(-6,15,15,LEAVES)
Block(-6,15,16,LEAVES)
Block(-6,15,17,LEAVES)
Block(-6,16,-11,LEAVES)
Block(-6,16,-9,LEAVES)
Block(-6,16,-8,LEAVES)
Block(-6,16,16,LEAVES)
Block(-6,17,-13,LEAVES)
Block(-6,17,-11,LEAVES)
Block(-6,17,-9,LEAVES)
Block(-6,17,1,LEAVES)
Block(-6,18,-13,LEAVES)
Block(-6,18,-12,LEAVES)
Block(-6,18,-11,LEAVES)
Block(-6,18,1,LEAVES)
Block(-6,18,7,LOG)
Block(-6,18,15,LEAVES)
Block(-6,19,-12,LEAVES)
Block(-6,19,-11,LEAVES)
Block(-6,19,-1,LEAVES)
Block(-6,19,2,LEAVES)
Block(-6,19,7,LOG)
Block(-6,19,8,LOG)
Block(-6,19,9,LEAVES)
Block(-6,19,10,LEAVES)
Block(-6,19,11,LEAVES)
Block(-6,20,2,LEAVES)
Block(-6,20,5,LEAVES)
Block(-6,20,6,LEAVES)
Block(-6,20,9,LEAVES)
Block(-6,20,11,LEAVES)
Block(-6,21,2,LEAVES)
Block(-6,21,3,LEAVES)
Block(-6,21,4,LEAVES)
Block(-6,21,5,LEAVES)
Block(-6,21,6,LEAVES)
Block(-6,21,7,LEAVES)
Block(-6,21,8,LEAVES)
Block(-6,21,9,LEAVES)
Block(-6,21,10,LEAVES)
Block(-6,21,11,LEAVES)
Block(-6,21,12,LEAVES)
Block(-6,22,2,LEAVES)
Block(-6,22,3,LEAVES)
Block(-6,22,4,LEAVES)
Block(-6,22,5,LEAVES)
Block(-6,22,7,LEAVES)
Block(-6,22,8,LEAVES)
Block(-6,22,10,LEAVES)
Block(-6,23,2,LEAVES)
Block(-5,-6,-1,LOG)
Block(-5,-6,0,LOG)
Block(-5,-6,8,LOG)
Block(-5,-5,0,LOG)
Block(-5,-5,7,LOG)
Block(-5,-5,8,LOG)
Block(-5,-4,6,LOG)
Block(-5,-4,7,LOG)
Block(-5,-3,3,LOG)
Block(-5,-3,4,LOG)
Block(-5,-3,5,LOG)
Block(-5,-3,6,LOG)
Block(-5,-2,3,LOG)
Block(-5,-2,4,LOG)
Block(-5,4,-12,LEAVES)
Block(-5,4,-11,LEAVES)
Block(-5,4,-10,LEAVES)
Block(-5,4,-9,LEAVES)
Block(-5,5,-12,LEAVES)
Block(-5,5,-11,LEAVES)
Block(-5,6,-11,LEAVES)
Block(-5,6,-10,LEAVES)
Block(-5,6,-8,LEAVES)
Block(-5,6,0,LOG)
Block(-5,6,1,LOG)
Block(-5,7,-12,LEAVES)
Block(-5,7,-11,LEAVES)
Block(-5,7,-10,LEAVES)
Block(-5,7,-9,LEAVES)
Block(-5,7,-8,LEAVES)
Block(-5,7,-7,LEAVES)
Block(-5,7,-1,LOG)
Block(-5,7,0,LOG)
Block(-5,7,1,LOG)
Block(-5,7,13,LEAVES)
Block(-5,7,15,LEAVES)
Block(-5,8,-12,LEAVES)
Block(-5,8,-11,LEAVES)
Block(-5,8,-10,LEAVES)
Block(-5,8,-9,LEAVES)
Block(-5,8,-8,LEAVES)
Block(-5,8,-2,LOG)
Block(-5,8,-1,LOG)
Block(-5,8,0,LOG)
Block(-5,8,13,LEAVES)
Block(-5,8,14,LEAVES)
Block(-5,8,15,LEAVES)
Block(-5,8,16,LEAVES)
Block(-5,9,-3,LOG)
Block(-5,9,-2,LOG)
Block(-5,9,-1,LOG)
Block(-5,9,12,LEAVES)
Block(-5,9,13,LOG)
Block(-5,9,14,LEAVES)
Block(-5,9,15,LEAVES)
Block(-5,9,16,LEAVES)
Block(-5,10,-4,LOG)
Block(-5,10,-3,LOG)
Block(-5,10,7,LOG)
Block(-5,10,8,LOG)
Block(-5,10,12,LOG)
Block(-5,10,15,LEAVES)
Block(-5,11,6,LOG)
Block(-5,11,7,LOG)
Block(-5,11,8,LOG)
Block(-5,11,9,LOG)
Block(-5,12,9,LOG)
Block(-5,12,10,LOG)
Block(-5,12,14,LEAVES)
Block(-5,12,15,LEAVES)
Block(-5,13,14,LEAVES)
Block(-5,13,15,LEAVES)
Block(-5,13,16,LEAVES)
Block(-5,13,17,LEAVES)
Block(-5,14,16,LEAVES)
Block(-5,14,17,LEAVES)
Block(-5,15,-13,LEAVES)
Block(-5,15,15,LEAVES)
Block(-5,15,16,LEAVES)
Block(-5,16,-13,LEAVES)
Block(-5,16,-11,LEAVES)
Block(-5,16,-10,LEAVES)
Block(-5,16,-9,LEAVES)
Block(-5,17,-13,LEAVES)
Block(-5,17,-12,LEAVES)
Block(-5,17,-11,LEAVES)
Block(-5,17,-10,LEAVES)
Block(-5,17,-8,LEAVES)
Block(-5,17,14,LEAVES)
Block(-5,17,15,LEAVES)
Block(-5,18,-14,LEAVES)
Block(-5,18,-11,LEAVES)
Block(-5,18,-10,LEAVES)
Block(-5,18,2,LEAVES)
Block(-5,18,6,LOG)
Block(-5,18,7,LOG)
Block(-5,18,10,LEAVES)
Block(-5,19,-12,LEAVES)
Block(-5,19,-11,LEAVES)
Block(-5,19,-10,LEAVES)
Block(-5,19,8,LEAVES)
Block(-5,19,10,LEAVES)
Block(-5,20,-10,LEAVES)
Block(-5,20,2,LEAVES)
Block(-5,20,3,LEAVES)
Block(-5,20,4,LEAVES)
Block(-5,20,5,LEAVES)
Block(-5,21,2,LEAVES)
Block(-5,21,3,LEAVES)
Block(-5,21,4,LEAVES)
Block(-5,21,5,LEAVES)
Block(-5,21,6,LEAVES)
Block(-5,21,7,LEAVES)
Block(-5,21,8,LEAVES)
Block(-5,21,9,LEAVES)
Block(-5,21,11,LEAVES)
Block(-5,22,1,LEAVES)
Block(-5,22,2,LEAVES)
Block(-5,22,4,LEAVES)
Block(-5,22,7,LEAVES)
Block(-5,22,8,LEAVES)
Block(-4,-6,0,LOG)
Block(-4,-5,0,LOG)
Block(-4,-3,-5,LOG)
Block(-4,-3,4,LOG)
Block(-4,-3,5,LOG)
Block(-4,-2,-5,LOG)
Block(-4,-2,-4,LOG)
Block(-4,-2,-3,LOG)
Block(-4,-2,3,LOG)
Block(-4,-2,4,LOG)
Block(-4,-1,-4,LOG)
Block(-4,-1,-3,LOG)
Block(-4,-1,-2,LOG)
Block(-4,-1,4,LOG)
Block(-4,3,1,LOG)
Block(-4,4,-12,LEAVES)
Block(-4,4,-11,LEAVES)
Block(-4,4,-10,LEAVES)
Block(-4,4,-9,LEAVES)
Block(-4,4,1,LOG)
Block(-4,4,2,LOG)
Block(-4,5,-13,LEAVES)
Block(-4,5,-12,LEAVES)
Block(-4,5,-11,LEAVES)
Block(-4,5,-10,LEAVES)
Block(-4,5,-9,LEAVES)
Block(-4,5,1,LOG)
Block(-4,5,2,LOG)
Block(-4,5,3,LOG)
Block(-4,6,-13,LEAVES)
Block(-4,6,-12,LEAVES)
Block(-4,6,-11,LEAVES)
Block(-4,6,-10,LEAVES)
Block(-4,6,-9,LEAVES)
Block(-4,6,-1,LOG)
Block(-4,6,0,LOG)
Block(-4,6,1,LOG)
Block(-4,6,2,LOG)
Block(-4,6,3,LOG)
Block(-4,7,-12,LEAVES)
Block(-4,7,-11,LEAVES)
Block(-4,7,-10,LEAVES)
Block(-4,7,-9,LEAVES)
Block(-4,7,-8,LEAVES)
Block(-4,7,-1,LOG)
Block(-4,7,0,LOG)
Block(-4,7,3,LOG)
Block(-4,8,-11,LEAVES)
Block(-4,8,-9,LEAVES)
Block(-4,8,-1,LOG)
Block(-4,8,12,LEAVES)
Block(-4,8,13,LEAVES)
Block(-4,8,14,LEAVES)
Block(-4,8,15,LEAVES)
Block(-4,9,-11,LEAVES)
Block(-4,9,-10,LEAVES)
Block(-4,9,11,LEAVES)
Block(-4,9,12,LEAVES)
Block(-4,9,13,LEAVES)
Block(-4,9,14,LEAVES)
Block(-4,9,15,LEAVES)
Block(-4,9,16,LEAVES)
Block(-4,10,-4,LOG)
Block(-4,10,7,LOG)
Block(-4,10,8,LOG)
Block(-4,10,15,LEAVES)
Block(-4,11,-5,LOG)
Block(-4,11,-4,LOG)
Block(-4,11,7,LOG)
Block(-4,11,8,LOG)
Block(-4,11,13,LEAVES)
Block(-4,12,7,LOG)
Block(-4,12,15,LEAVES)
Block(-4,12,16,LEAVES)
Block(-4,13,-11,LEAVES)
Block(-4,13,15,LEAVES)
Block(-4,14,-11,LEAVES)
Block(-4,14,-10,LEAVES)
Block(-4,14,15,LEAVES)
Block(-4,14,16,LEAVES)
Block(-4,15,-11,LEAVES)
Block(-4,15,-10,LEAVES)
Block(-4,16,-13,LEAVES)
Block(-4,16,-12,LEAVES)
Block(-4,16,-11,LEAVES)
Block(-4,16,-10,LEAVES)
Block(-4,17,-13,LEAVES)
Block(-4,17,-12,LEAVES)
Block(-4,17,-11,LEAVES)
Block(-4,17,-10,LEAVES)
Block(-4,17,-9,LEAVES)
Block(-4,17,-8,LEAVES)
Block(-4,17,-7,LEAVES)
Block(-4,18,-14,LEAVES)
Block(-4,18,-13,LEAVES)
Block(-4,18,-11,LEAVES)
Block(-4,18,-9,LEAVES)
Block(-4,18,-8,LEAVES)
Block(-4,18,5,LOG)
Block(-4,18,6,LOG)
Block(-4,19,-13,LEAVES)
Block(-4,19,-12,LEAVES)
Block(-4,19,-11,LEAVES)
Block(-4,19,-10,LEAVES)
Block(-4,19,-9,LEAVES)
Block(-4,19,3,LEAVES)
Block(-4,19,4,LOG)
Block(-4,19,5,LOG)
Block(-4,19,6,LEAVES)
Block(-4,19,7,LEAVES)
Block(-4,20,-11,LEAVES)
Block(-4,20,-10,LEAVES)
Block(-4,20,2,LEAVES)
Block(-4,20,3,LEAVES)
Block(-4,20,4,LEAVES)
Block(-4,20,5,LEAVES)
Block(-4,21,5,LEAVES)
Block(-4,21,6,LEAVES)
Block(-4,21,7,LEAVES)
Block(-4,21,8,LEAVES)
Block(-4,22,2,LEAVES)
Block(-4,22,4,LEAVES)
Block(-4,22,5,LEAVES)
Block(-3,-6,-5,LOG)
Block(-3,-5,-5,LOG)
Block(-3,-5,0,LOG)
Block(-3,-5,1,LOG)
Block(-3,-4,-6,LOG)
Block(-3,-4,-5,LOG)
Block(-3,-4,-1,LOG)
Block(-3,-4,0,LOG)
Block(-3,-3,-5,LOG)
Block(-3,-3,-2,LOG)
Block(-3,-3,-1,LOG)
Block(-3,-2,-5,LOG)
Block(-3,-2,-4,LOG)
Block(-3,-2,-3,LOG)
Block(-3,-2,-2,LOG)
Block(-3,-2,-1,LOG)
Block(-3,-2,3,LOG)
Block(-3,-2,4,LOG)
Block(-3,-1,-3,LOG)
Block(-3,-1,-2,LOG)
Block(-3,-1,-1,LOG)
Block(-3,-1,3,LOG)
Block(-3,0,-2,LOG)
Block(-3,0,-1,LOG)
Block(-3,2,-1,LOG)
Block(-3,2,0,LOG)
Block(-3,2,1,LOG)
Block(-3,3,-11,LEAVES)
Block(-3,3,-1,LOG)
Block(-3,3,0,LOG)
Block(-3,3,1,LOG)
Block(-3,3,2,LOG)
Block(-3,4,-11,LEAVES)
Block(-3,4,-10,LEAVES)
Block(-3,4,0,LOG)
Block(-3,4,1,LOG)
Block(-3,4,2,LOG)
Block(-3,4,3,LOG)
Block(-3,5,-14,LEAVES)
Block(-3,5,-13,LEAVES)
Block(-3,5,-12,LEAVES)
Block(-3,5,-11,LEAVES)
Block(-3,5,-10,LEAVES)
Block(-3,5,-9,LEAVES)
Block(-3,5,0,LOG)
Block(-3,5,1,LOG)
Block(-3,5,2,LOG)
Block(-3,5,3,LOG)
Block(-3,5,4,LOG)
Block(-3,6,-14,LEAVES)
Block(-3,6,-13,LEAVES)
Block(-3,6,-12,LEAVES)
Block(-3,6,-11,LOG)
Block(-3,6,-10,LEAVES)
Block(-3,6,-9,LEAVES)
Block(-3,6,2,LOG)
Block(-3,6,3,LOG)
Block(-3,6,4,LOG)
Block(-3,7,-13,LEAVES)
Block(-3,7,-12,LEAVES)
Block(-3,7,-11,LEAVES)
Block(-3,7,-10,LOG)
Block(-3,7,2,LOG)
Block(-3,7,3,LOG)
Block(-3,7,4,LOG)
Block(-3,8,-10,LOG)
Block(-3,8,4,LOG)
Block(-3,8,15,LEAVES)
Block(-3,9,-10,LEAVES)
Block(-3,9,12,LEAVES)
Block(-3,9,13,LEAVES)
Block(-3,9,14,LEAVES)
Block(-3,9,15,LEAVES)
Block(-3,9,16,LEAVES)
Block(-3,10,14,LEAVES)
Block(-3,10,15,LEAVES)
Block(-3,10,16,LEAVES)
Block(-3,11,-6,LOG)
Block(-3,11,-5,LOG)
Block(-3,11,6,LOG)
Block(-3,11,7,LOG)
Block(-3,11,8,LOG)
Block(-3,11,12,LEAVES)
Block(-3,11,13,LEAVES)
Block(-3,11,14,LEAVES)
Block(-3,11,15,LEAVES)
Block(-3,12,-6,LOG)
Block(-3,12,-5,LOG)
Block(-3,12,7,LOG)
Block(-3,12,13,LEAVES)
Block(-3,12,15,LEAVES)
Block(-3,13,-6,LEAVES)
Block(-3,13,15,LEAVES)
Block(-3,15,-13,LEAVES)
Block(-3,15,-11,LEAVES)
Block(-3,15,-10,LEAVES)
Block(-3,16,-13,LEAVES)
Block(-3,16,-12,LEAVES)
Block(-3,16,-11,LEAVES)
Block(-3,17,-13,LEAVES)
Block(-3,17,-11,LEAVES)
Block(-3,17,-8,LEAVES)
Block(-3,18,-11,LEAVES)
Block(-3,18,-10,LEAVES)
Block(-3,18,-9,LEAVES)
Block(-3,18,-8,LEAVES)
Block(-3,18,6,LOG)
Block(-3,18,7,LOG)
Block(-3,19,-13,LEAVES)
Block(-3,19,-12,LEAVES)
Block(-3,19,-11,LEAVES)
Block(-3,19,-10,LEAVES)
Block(-3,19,-9,LEAVES)
Block(-3,19,2,LEAVES)
Block(-3,19,3,LEAVES)
Block(-3,19,4,LEAVES)
Block(-3,19,6,LEAVES)
Block(-3,19,7,LEAVES)
Block(-3,19,8,LEAVES)
Block(-3,20,-13,LEAVES)
Block(-3,20,-12,LEAVES)
Block(-3,20,-11,LEAVES)
Block(-3,20,2,LEAVES)
Block(-3,20,3,LOG)
Block(-3,20,4,LEAVES)
Block(-3,20,5,LEAVES)
Block(-3,20,6,LEAVES)
Block(-3,20,7,LEAVES)
Block(-3,21,-12,LEAVES)
Block(-3,21,-11,LEAVES)
Block(-3,21,1,LEAVES)
Block(-3,21,2,LEAVES)
Block(-3,21,3,LEAVES)
Block(-3,21,5,LEAVES)
Block(-3,21,6,LEAVES)
Block(-3,21,7,LEAVES)
Block(-3,22,4,LEAVES)
Block(-3,22,5,LEAVES)
Block(-3,22,6,LEAVES)
Block(-3,23,3,LEAVES)
Block(-2,-5,-6,LOG)
Block(-2,-5,-5,LOG)
Block(-2,-4,-6,LOG)
Block(-2,-4,-1,LOG)
Block(-2,-3,-1,LOG)
Block(-2,-2,-2,LOG)
Block(-2,-2,-1,LOG)
Block(-2,-2,2,LOG)
Block(-2,-1,-2,LOG)
Block(-2,-1,-1,LOG)
Block(-2,-1,0,LOG)
Block(-2,-1,1,LOG)
Block(-2,-1,2,LOG)
Block(-2,-1,3,LOG)
Block(-2,0,-1,LOG)
Block(-2,0,0,LOG)
Block(-2,0,1,LOG)
Block(-2,0,2,LOG)
Block(-2,1,-1,LOG)
Block(-2,1,0,LOG)
Block(-2,1,1,LOG)
Block(-2,1,2,LOG)
Block(-2,2,-1,LOG)
Block(-2,2,0,LOG)
Block(-2,2,1,LOG)
Block(-2,2,2,LOG)
Block(-2,3,-1,LOG)
Block(-2,3,0,LOG)
Block(-2,3,1,LOG)
Block(-2,3,2,LOG)
Block(-2,4,-11,LEAVES)
Block(-2,4,-10,LEAVES)
Block(-2,4,-9,LEAVES)
Block(-2,4,1,LOG)
Block(-2,4,2,LOG)
Block(-2,4,3,LOG)
Block(-2,5,-13,LEAVES)
Block(-2,5,-12,LEAVES)
Block(-2,5,-11,LEAVES)
Block(-2,5,-10,LEAVES)
Block(-2,5,1,LOG)
Block(-2,5,2,LOG)
Block(-2,5,3,LOG)
Block(-2,6,-13,LEAVES)
Block(-2,6,-12,LEAVES)
Block(-2,6,-11,LEAVES)
Block(-2,6,-10,LEAVES)
Block(-2,6,2,LOG)
Block(-2,6,3,LOG)
Block(-2,6,4,LOG)
Block(-2,7,-12,LEAVES)
Block(-2,7,-11,LEAVES)
Block(-2,7,-10,LEAVES)
Block(-2,7,3,LOG)
Block(-2,7,4,LOG)
Block(-2,7,5,LOG)
Block(-2,8,-10,LEAVES)
Block(-2,8,3,LOG)
Block(-2,8,4,LOG)
Block(-2,8,5,LOG)
Block(-2,9,-9,LOG)
Block(-2,9,4,LOG)
Block(-2,9,5,LOG)
Block(-2,9,13,LEAVES)
Block(-2,9,14,LEAVES)
Block(-2,10,-10,LEAVES)
Block(-2,10,-9,LEAVES)
Block(-2,10,5,LOG)
Block(-2,10,6,LOG)
Block(-2,10,11,LEAVES)
Block(-2,10,12,LEAVES)
Block(-2,10,13,LEAVES)
Block(-2,10,14,LEAVES)
Block(-2,10,15,LEAVES)
Block(-2,10,16,LEAVES)
Block(-2,11,-8,LOG)
Block(-2,11,-7,LOG)
Block(-2,11,6,LOG)
Block(-2,11,7,LOG)
Block(-2,11,11,LEAVES)
Block(-2,11,12,LEAVES)
Block(-2,11,13,LEAVES)
Block(-2,11,14,LEAVES)
Block(-2,11,15,LEAVES)
Block(-2,12,-7,LOG)
Block(-2,12,-6,LOG)
Block(-2,12,6,LOG)
Block(-2,12,10,LEAVES)
Block(-2,12,12,LEAVES)
Block(-2,12,13,LEAVES)
Block(-2,12,14,LEAVES)
Block(-2,12,15,LEAVES)
Block(-2,13,-7,LEAVES)
Block(-2,13,-6,LEAVES)
Block(-2,14,-9,LEAVES)
Block(-2,14,-6,LEAVES)
Block(-2,14,-5,LEAVES)
Block(-2,14,-4,LEAVES)
Block(-2,15,-11,LEAVES)
Block(-2,15,-8,LEAVES)
Block(-2,15,-6,LEAVES)
Block(-2,15,-5,LEAVES)
Block(-2,15,-2,LEAVES)
Block(-2,16,-12,LEAVES)
Block(-2,16,-11,LEAVES)
Block(-2,16,2,LEAVES)
Block(-2,16,3,LEAVES)
Block(-2,17,-11,LEAVES)
Block(-2,17,-9,LEAVES)
Block(-2,17,-8,LEAVES)
Block(-2,17,-7,LEAVES)
Block(-2,17,7,LOG)
Block(-2,18,-12,LEAVES)
Block(-2,18,-11,LEAVES)
Block(-2,18,-10,LEAVES)
Block(-2,18,-7,LEAVES)
Block(-2,18,3,LEAVES)
Block(-2,18,4,LEAVES)
Block(-2,18,7,LOG)
Block(-2,18,8,LEAVES)
Block(-2,19,-13,LEAVES)
Block(-2,19,-12,LEAVES)
Block(-2,19,-11,LEAVES)
Block(-2,19,-10,LEAVES)
Block(-2,19,-8,LEAVES)
Block(-2,19,4,LEAVES)
Block(-2,19,7,LEAVES)
Block(-2,19,8,LEAVES)
Block(-2,20,-12,LEAVES)
Block(-2,20,-11,LEAVES)
Block(-2,20,-10,LEAVES)
Block(-2,20,1,LEAVES)
Block(-2,20,2,LEAVES)
Block(-2,20,3,LEAVES)
Block(-2,20,5,LEAVES)
Block(-2,20,6,LEAVES)
Block(-2,20,7,LEAVES)
Block(-2,21,2,LEAVES)
Block(-2,21,3,LEAVES)
Block(-2,21,4,LEAVES)
Block(-2,21,6,LEAVES)
Block(-2,22,3,LEAVES)
Block(-2,22,4,LEAVES)
Block(-2,22,5,LEAVES)
Block(-2,22,6,LEAVES)
Block(-2,23,3,LEAVES)
Block(-1,-6,-6,LOG)
Block(-1,-5,-6,LOG)
Block(-1,-3,3,LOG)
Block(-1,-3,4,LOG)
Block(-1,-2,0,LOG)
Block(-1,-2,2,LOG)
Block(-1,-2,3,LOG)
Block(-1,-1,-2,LOG)
Block(-1,-1,-1,LOG)
Block(-1,-1,0,LOG)
Block(-1,-1,1,LOG)
Block(-1,-1,2,LOG)
Block(-1,-1,3,LOG)
Block(-1,0,-2,LOG)
Block(-1,0,-1,LOG)
Block(-1,0,0,LOG)
Block(-1,0,1,LOG)
Block(-1,0,2,LOG)
Block(-1,1,-2,LOG)
Block(-1,1,-1,LOG)
Block(-1,1,0,LOG)
Block(-1,1,1,LOG)
Block(-1,2,-1,LOG)
Block(-1,2,0,LOG)
Block(-1,2,1,LOG)
Block(-1,2,2,LOG)
Block(-1,3,0,LOG)
Block(-1,3,1,LOG)
Block(-1,3,2,LOG)
Block(-1,4,-10,LEAVES)
Block(-1,4,1,LOG)
Block(-1,4,2,LOG)
Block(-1,5,-12,LEAVES)
Block(-1,5,-11,LEAVES)
Block(-1,5,-10,LEAVES)
Block(-1,6,-12,LEAVES)
Block(-1,6,-11,LEAVES)
Block(-1,6,-10,LEAVES)
Block(-1,7,-10,LEAVES)
Block(-1,7,3,LOG)
Block(-1,8,3,LOG)
Block(-1,8,4,LOG)
Block(-1,8,5,LOG)
Block(-1,9,-10,LEAVES)
Block(-1,9,-9,LOG)
Block(-1,9,4,LOG)
Block(-1,9,5,LOG)
Block(-1,9,6,LOG)
Block(-1,9,12,LEAVES)
Block(-1,9,14,LEAVES)
Block(-1,9,15,LEAVES)
Block(-1,10,-11,LEAVES)
Block(-1,10,-10,LEAVES)
Block(-1,10,-9,LOG)
Block(-1,10,-8,LOG)
Block(-1,10,4,LOG)
Block(-1,10,5,LOG)
Block(-1,10,6,LOG)
Block(-1,10,11,LEAVES)
Block(-1,10,12,LEAVES)
Block(-1,10,13,LEAVES)
Block(-1,10,14,LEAVES)
Block(-1,10,15,LEAVES)
Block(-1,11,-10,LEAVES)
Block(-1,11,-9,LEAVES)
Block(-1,11,-8,LOG)
Block(-1,11,5,LOG)
Block(-1,11,6,LOG)
Block(-1,11,7,LOG)
Block(-1,11,10,LEAVES)
Block(-1,11,11,LEAVES)
Block(-1,11,12,LEAVES)
Block(-1,11,13,LEAVES)
Block(-1,11,14,LEAVES)
Block(-1,11,15,LEAVES)
Block(-1,12,6,LOG)
Block(-1,12,11,LEAVES)
Block(-1,12,12,LEAVES)
Block(-1,12,14,LEAVES)
Block(-1,13,-7,LEAVES)
Block(-1,13,-6,LOG)
Block(-1,13,-4,LEAVES)
Block(-1,13,12,LEAVES)
Block(-1,13,13,LEAVES)
Block(-1,14,-11,LEAVES)
Block(-1,14,-7,LEAVES)
Block(-1,14,-6,LEAVES)
Block(-1,14,-5,LEAVES)
Block(-1,14,-4,LEAVES)
Block(-1,14,-3,LEAVES)
Block(-1,15,-11,LEAVES)
Block(-1,15,-7,LEAVES)
Block(-1,15,-6,LEAVES)
Block(-1,15,-5,LEAVES)
Block(-1,15,-4,LEAVES)
Block(-1,15,-3,LEAVES)
Block(-1,15,-2,LEAVES)
Block(-1,15,-1,LEAVES)
Block(-1,15,3,LEAVES)
Block(-1,16,-11,LEAVES)
Block(-1,16,-10,LEAVES)
Block(-1,16,-9,LEAVES)
Block(-1,16,-8,LEAVES)
Block(-1,16,-6,LEAVES)
Block(-1,16,-5,LEAVES)
Block(-1,16,-3,LEAVES)
Block(-1,16,2,LEAVES)
Block(-1,16,3,LEAVES)
Block(-1,16,7,LOG)
Block(-1,17,-12,LEAVES)
Block(-1,17,-11,LEAVES)
Block(-1,17,-8,LEAVES)
Block(-1,17,-7,LEAVES)
Block(-1,17,-6,LEAVES)
Block(-1,17,3,LEAVES)
Block(-1,17,7,LOG)
Block(-1,18,-11,LEAVES)
Block(-1,18,-10,LEAVES)
Block(-1,18,-8,LEAVES)
Block(-1,18,2,LEAVES)
Block(-1,18,4,LEAVES)
Block(-1,19,-12,LEAVES)
Block(-1,19,-10,LEAVES)
Block(-1,19,2,LEAVES)
Block(-1,20,-11,LEAVES)
Block(-1,20,-10,LEAVES)
Block(-1,20,1,LEAVES)
Block(-1,20,2,LEAVES)
Block(-1,20,3,LEAVES)
Block(-1,20,7,LEAVES)
Block(-1,21,-11,LEAVES)
Block(-1,21,2,LEAVES)
Block(-1,21,6,LEAVES)
Block(-1,22,3,LEAVES)
Block(-1,22,5,LEAVES)
Block(0,-6,-6,LOG)
Block(0,-6,-5,LOG)
Block(0,-6,4,LOG)
Block(0,-5,4,LOG)
Block(0,-5,5,LOG)
Block(0,-4,4,LOG)
Block(0,-4,5,LOG)
Block(0,-3,3,LOG)
Block(0,-3,4,LOG)
Block(0,-1,-2,LOG)
Block(0,-1,-1,LOG)
Block(0,0,-3,LOG)
Block(0,0,-2,LOG)
Block(0,0,-1,LOG)
Block(0,0,0,LOG)
Block(0,1,-1,LOG)
Block(0,1,0,LOG)
Block(0,1,1,LOG)
Block(0,2,1,LOG)
Block(0,5,-11,LEAVES)
Block(0,6,-10,LEAVES)
Block(0,7,12,LEAVES)
Block(0,8,12,LEAVES)
Block(0,8,13,LEAVES)
Block(0,8,14,LEAVES)
Block(0,9,-10,LEAVES)
Block(0,9,4,LOG)
Block(0,9,5,LOG)
Block(0,9,10,LEAVES)
Block(0,9,11,LEAVES)
Block(0,9,12,LEAVES)
Block(0,9,13,LEAVES)
Block(0,9,14,LEAVES)
Block(0,10,-11,LEAVES)
Block(0,10,-10,LEAVES)
Block(0,10,-9,LOG)
Block(0,10,-8,LOG)
Block(0,10,4,LOG)
Block(0,10,5,LOG)
Block(0,10,6,LOG)
Block(0,10,11,LEAVES)
Block(0,10,12,LOG)
Block(0,10,13,LEAVES)
Block(0,10,14,LEAVES)
Block(0,11,-9,LEAVES)
Block(0,11,-8,LEAVES)
Block(0,11,5,LOG)
Block(0,11,6,LOG)
Block(0,11,11,LEAVES)
Block(0,11,12,LEAVES)
Block(0,11,14,LEAVES)
Block(0,11,15,LEAVES)
Block(0,12,-10,LEAVES)
Block(0,12,-9,LEAVES)
Block(0,12,6,LOG)
Block(0,12,12,LEAVES)
Block(0,12,13,LEAVES)
Block(0,12,14,LEAVES)
Block(0,13,-6,LOG)
Block(0,13,12,LEAVES)
Block(0,13,13,LEAVES)
Block(0,14,-11,LEAVES)
Block(0,14,-10,LEAVES)
Block(0,14,-9,LEAVES)
Block(0,14,-8,LEAVES)
Block(0,14,-5,LEAVES)
Block(0,14,-4,LEAVES)
Block(0,14,1,LEAVES)
Block(0,14,3,LEAVES)
Block(0,15,-10,LEAVES)
Block(0,15,-8,LEAVES)
Block(0,15,-7,LEAVES)
Block(0,15,-6,LEAVES)
Block(0,15,-5,LEAVES)
Block(0,15,-4,LEAVES)
Block(0,15,-3,LEAVES)
Block(0,15,-2,LEAVES)
Block(0,15,-1,LEAVES)
Block(0,15,0,LEAVES)
Block(0,15,2,LEAVES)
Block(0,15,3,LEAVES)
Block(0,16,-11,LEAVES)
Block(0,16,-9,LEAVES)
Block(0,16,-7,LEAVES)
Block(0,16,-6,LEAVES)
Block(0,16,-4,LEAVES)
Block(0,16,-3,LEAVES)
Block(0,16,-1,LEAVES)
Block(0,16,1,LEAVES)
Block(0,16,2,LEAVES)
Block(0,16,3,LEAVES)
Block(0,16,4,LEAVES)
Block(0,16,5,LEAVES)
Block(0,16,7,LOG)
Block(0,17,-8,LEAVES)
Block(0,17,-6,LEAVES)
Block(0,17,-5,LEAVES)
Block(0,17,-4,LEAVES)
Block(0,17,-2,LEAVES)
Block(0,17,2,LEAVES)
Block(0,17,3,LEAVES)
Block(0,17,4,LEAVES)
Block(0,18,-10,LEAVES)
Block(0,18,-9,LEAVES)
Block(0,18,-7,LEAVES)
Block(0,18,-1,LEAVES)
Block(0,18,1,LEAVES)
Block(0,18,3,LEAVES)
Block(0,18,4,LEAVES)
Block(0,18,5,LEAVES)
Block(0,19,3,LEAVES)
Block(0,19,4,LEAVES)
Block(0,20,-10,LEAVES)
Block(0,20,2,LEAVES)
Block(0,20,3,LEAVES)
Block(1,-6,-5,LOG)
Block(1,-6,-4,LOG)
Block(1,-1,-3,LOG)
Block(1,-1,-2,LOG)
Block(1,0,-2,LOG)
Block(1,0,-1,LOG)
Block(1,7,10,LEAVES)
Block(1,8,-10,LEAVES)
Block(1,8,10,LEAVES)
Block(1,8,11,LEAVES)
Block(1,8,13,LEAVES)
Block(1,9,9,LEAVES)
Block(1,9,10,LEAVES)
Block(1,9,11,LOG)
Block(1,9,12,LOG)
Block(1,9,13,LEAVES)
Block(1,9,14,LEAVES)
Block(1,10,-12,LEAVES)
Block(1,10,-11,LEAVES)
Block(1,10,-10,LEAVES)
Block(1,10,-9,LOG)
Block(1,10,7,LOG)
Block(1,10,12,LEAVES)
Block(1,10,14,LEAVES)
Block(1,10,15,LEAVES)
Block(1,11,-11,LEAVES)
Block(1,11,-10,LEAVES)
Block(1,11,5,LOG)
Block(1,11,6,LOG)
Block(1,11,7,LOG)
Block(1,11,11,LEAVES)
Block(1,11,12,LEAVES)
Block(1,11,15,LEAVES)
Block(1,12,-10,LEAVES)
Block(1,12,-9,LEAVES)
Block(1,12,-8,LEAVES)
Block(1,12,2,LEAVES)
Block(1,12,5,LOG)
Block(1,12,6,LOG)
Block(1,12,7,LOG)
Block(1,12,12,LEAVES)
Block(1,12,13,LEAVES)
Block(1,12,14,LEAVES)
Block(1,12,15,LEAVES)
Block(1,13,-11,LEAVES)
Block(1,13,-10,LEAVES)
Block(1,13,-9,LEAVES)
Block(1,13,-8,LEAVES)
Block(1,13,-6,LEAVES)
Block(1,13,-5,LEAVES)
Block(1,13,-2,LEAVES)
Block(1,13,3,LEAVES)
Block(1,14,-8,LEAVES)
Block(1,14,-6,LEAVES)
Block(1,14,-5,LOG)
Block(1,14,-3,LEAVES)
Block(1,14,0,LEAVES)
Block(1,14,1,LEAVES)
Block(1,14,2,LEAVES)
Block(1,14,3,LEAVES)
Block(1,14,4,LEAVES)
Block(1,14,6,LOG)
Block(1,15,-9,LEAVES)
Block(1,15,-7,LEAVES)
Block(1,15,-3,LEAVES)
Block(1,15,-2,LEAVES)
Block(1,15,0,LEAVES)
Block(1,15,1,LEAVES)
Block(1,15,2,LEAVES)
Block(1,15,4,LEAVES)
Block(1,15,7,LOG)
Block(1,16,-11,LEAVES)
Block(1,16,-5,LEAVES)
Block(1,16,-4,LEAVES)
Block(1,16,-3,LEAVES)
Block(1,16,-2,LEAVES)
Block(1,16,-1,LEAVES)
Block(1,16,0,LEAVES)
Block(1,16,2,LEAVES)
Block(1,16,3,LOG)
Block(1,16,6,LOG)
Block(1,16,7,LOG)
Block(1,17,-8,LEAVES)
Block(1,17,-6,LEAVES)
Block(1,17,-5,LEAVES)
Block(1,17,-3,LEAVES)
Block(1,17,-2,LEAVES)
Block(1,17,-1,LEAVES)
Block(1,17,0,LEAVES)
Block(1,17,1,LEAVES)
Block(1,17,2,LEAVES)
Block(1,17,3,LOG)
Block(1,17,4,LOG)
Block(1,17,5,LOG)
Block(1,17,6,LOG)
Block(1,18,-3,LEAVES)
Block(1,18,-2,LEAVES)
Block(1,18,-1,LEAVES)
Block(1,18,0,LEAVES)
Block(1,18,1,LEAVES)
Block(1,18,2,LEAVES)
Block(1,18,3,LEAVES)
Block(1,18,4,LEAVES)
Block(1,18,5,LEAVES)
Block(1,18,6,LEAVES)
Block(1,19,-2,LEAVES)
Block(1,19,1,LEAVES)
Block(1,19,2,LEAVES)
Block(1,20,2,LEAVES)
Block(2,-6,-5,LOG)
Block(2,-3,-1,LOG)
Block(2,-2,-2,LOG)
Block(2,-2,-1,LOG)
Block(2,-1,-3,LOG)
Block(2,-1,-2,LOG)
Block(2,6,-11,LEAVES)
Block(2,7,-12,LEAVES)
Block(2,7,-11,LEAVES)
Block(2,7,-10,LEAVES)
Block(2,7,-9,LEAVES)
Block(2,7,-8,LEAVES)
Block(2,8,-12,LEAVES)
Block(2,8,-10,LEAVES)
Block(2,8,9,LOG)
Block(2,8,10,LOG)
Block(2,8,11,LOG)
Block(2,8,12,LEAVES)
Block(2,9,-7,LEAVES)
Block(2,9,8,LOG)
Block(2,9,9,LOG)
Block(2,9,10,LEAVES)
Block(2,9,11,LOG)
Block(2,9,12,LEAVES)
Block(2,10,-12,LEAVES)
Block(2,10,-11,LEAVES)
Block(2,10,-10,LEAVES)
Block(2,10,-9,LOG)
Block(2,10,-8,LEAVES)
Block(2,10,-6,LEAVES)
Block(2,10,7,LOG)
Block(2,10,8,LOG)
Block(2,10,10,LEAVES)
Block(2,10,11,LEAVES)
Block(2,10,12,LEAVES)
Block(2,10,13,LEAVES)
Block(2,10,14,LEAVES)
Block(2,11,-12,LEAVES)
Block(2,11,-11,LEAVES)
Block(2,11,-10,LEAVES)
Block(2,11,-9,LEAVES)
Block(2,11,2,LEAVES)
Block(2,11,7,LOG)
Block(2,11,9,LEAVES)
Block(2,11,10,LEAVES)
Block(2,11,11,LEAVES)
Block(2,11,12,LEAVES)
Block(2,11,13,LEAVES)
Block(2,11,14,LEAVES)
Block(2,12,-9,LEAVES)
Block(2,12,-7,LEAVES)
Block(2,12,1,LEAVES)
Block(2,12,2,LEAVES)
Block(2,12,3,LEAVES)
Block(2,12,5,LOG)
Block(2,12,6,LOG)
Block(2,12,11,LEAVES)
Block(2,12,12,LEAVES)
Block(2,12,14,LEAVES)
Block(2,12,15,LEAVES)
Block(2,13,-11,LEAVES)
Block(2,13,-10,LEAVES)
Block(2,13,-9,LEAVES)
Block(2,13,-8,LEAVES)
Block(2,13,-7,LEAVES)
Block(2,13,1,LEAVES)
Block(2,13,2,LEAVES)
Block(2,13,6,LOG)
Block(2,13,13,LEAVES)
Block(2,14,-10,LEAVES)
Block(2,14,-9,LEAVES)
Block(2,14,-4,LEAVES)
Block(2,14,-3,LEAVES)
Block(2,14,-2,LEAVES)
Block(2,14,2,LEAVES)
Block(2,14,3,LEAVES)
Block(2,14,6,LOG)
Block(2,14,7,LOG)
Block(2,15,-10,LEAVES)
Block(2,15,-8,LEAVES)
Block(2,15,-7,LEAVES)
Block(2,15,-6,LEAVES)
Block(2,15,-5,LEAVES)
Block(2,15,-3,LEAVES)
Block(2,15,-2,LEAVES)
Block(2,15,-1,LEAVES)
Block(2,15,0,LEAVES)
Block(2,15,2,LOG)
Block(2,15,3,LEAVES)
Block(2,15,7,LOG)
Block(2,15,8,LOG)
Block(2,16,-9,LEAVES)
Block(2,16,-7,LEAVES)
Block(2,16,-3,LEAVES)
Block(2,16,-2,LEAVES)
Block(2,16,2,LOG)
Block(2,16,3,LOG)
Block(2,16,4,LEAVES)
Block(2,16,6,LEAVES)
Block(2,16,7,LEAVES)
Block(2,16,8,LOG)
Block(2,16,9,LOG)
Block(2,17,-4,LEAVES)
Block(2,17,-2,LEAVES)
Block(2,17,1,LEAVES)
Block(2,17,3,LEAVES)
Block(2,17,4,LEAVES)
Block(2,17,6,LEAVES)
Block(2,17,7,LEAVES)
Block(2,17,9,LOG)
Block(2,18,-4,LEAVES)
Block(2,18,-3,LEAVES)
Block(2,18,-2,LEAVES)
Block(2,18,-1,LEAVES)
Block(2,18,0,LEAVES)
Block(2,18,2,LEAVES)
Block(2,18,3,LEAVES)
Block(2,18,4,LEAVES)
Block(2,18,5,LEAVES)
Block(2,18,9,LEAVES)
Block(2,18,10,LEAVES)
Block(2,19,-3,LEAVES)
Block(2,19,-2,LEAVES)
Block(2,19,-1,LEAVES)
Block(2,19,5,LEAVES)
Block(2,19,9,LEAVES)
Block(2,20,3,LEAVES)
Block(3,-3,-2,LOG)
Block(3,-3,-1,LOG)
Block(3,-2,-2,LOG)
Block(3,-2,-1,LOG)
Block(3,6,-12,LEAVES)
Block(3,6,-11,LEAVES)
Block(3,6,-10,LEAVES)
Block(3,6,-8,LEAVES)
Block(3,6,-7,LEAVES)
Block(3,7,-12,LEAVES)
Block(3,7,-9,LEAVES)
Block(3,7,-8,LEAVES)
Block(3,7,-7,LEAVES)
Block(3,8,-13,LEAVES)
Block(3,8,-12,LEAVES)
Block(3,8,-11,LEAVES)
Block(3,8,-10,LEAVES)
Block(3,8,-9,LEAVES)
Block(3,8,-8,LEAVES)
Block(3,8,10,LEAVES)
Block(3,8,11,LEAVES)
Block(3,9,-13,LEAVES)
Block(3,9,-9,LOG)
Block(3,9,-7,LEAVES)
Block(3,9,9,LEAVES)
Block(3,9,10,LEAVES)
Block(3,9,11,LEAVES)
Block(3,9,12,LEAVES)
Block(3,9,14,LEAVES)
Block(3,10,-11,LEAVES)
Block(3,10,-7,LEAVES)
Block(3,10,-6,LEAVES)
Block(3,10,10,LEAVES)
Block(3,10,11,LEAVES)
Block(3,10,12,LEAVES)
Block(3,10,13,LEAVES)
Block(3,10,14,LEAVES)
Block(3,10,15,LEAVES)
Block(3,11,-11,LEAVES)
Block(3,11,-9,LEAVES)
Block(3,11,-8,LEAVES)
Block(3,11,-7,LEAVES)
Block(3,11,2,LEAVES)
Block(3,11,3,LEAVES)
Block(3,11,10,LEAVES)
Block(3,11,11,LEAVES)
Block(3,11,12,LEAVES)
Block(3,11,13,LEAVES)
Block(3,11,14,LEAVES)
Block(3,11,15,LEAVES)
Block(3,12,-11,LEAVES)
Block(3,12,-10,LEAVES)
Block(3,12,-9,LEAVES)
Block(3,12,-8,LEAVES)
Block(3,12,1,LEAVES)
Block(3,12,2,LEAVES)
Block(3,12,3,LEAVES)
Block(3,12,4,LEAVES)
Block(3,12,11,LEAVES)
Block(3,12,12,LEAVES)
Block(3,12,13,LEAVES)
Block(3,12,14,LEAVES)
Block(3,13,-10,LEAVES)
Block(3,13,-9,LEAVES)
Block(3,13,-5,LEAVES)
Block(3,13,-1,LEAVES)
Block(3,13,1,LEAVES)
Block(3,13,2,LEAVES)
Block(3,13,3,LEAVES)
Block(3,13,6,LOG)
Block(3,14,-11,LEAVES)
Block(3,14,-10,LEAVES)
Block(3,14,-6,LEAVES)
Block(3,14,-5,LEAVES)
Block(3,14,-4,LEAVES)
Block(3,14,1,LOG)
Block(3,14,6,LOG)
Block(3,15,-10,LEAVES)
Block(3,15,-5,LEAVES)
Block(3,15,-4,LEAVES)
Block(3,15,-3,LEAVES)
Block(3,15,0,LEAVES)
Block(3,15,1,LOG)
Block(3,15,2,LOG)
Block(3,16,-5,LEAVES)
Block(3,16,0,LOG)
Block(3,16,2,LEAVES)
Block(3,16,3,LEAVES)
Block(3,16,6,LEAVES)
Block(3,16,7,LEAVES)
Block(3,17,-5,LEAVES)
Block(3,17,-3,LEAVES)
Block(3,17,-2,LEAVES)
Block(3,17,-1,LEAVES)
Block(3,17,0,LEAVES)
Block(3,17,1,LEAVES)
Block(3,17,3,LEAVES)
Block(3,17,4,LEAVES)
Block(3,17,5,LEAVES)
Block(3,17,6,LEAVES)
Block(3,17,7,LEAVES)
Block(3,17,9,LOG)
Block(3,18,-3,LEAVES)
Block(3,18,-2,LEAVES)
Block(3,18,-1,LEAVES)
Block(3,18,0,LEAVES)
Block(3,18,2,LEAVES)
Block(3,18,3,LEAVES)
Block(3,18,4,LEAVES)
Block(3,18,5,LEAVES)
Block(3,18,6,LEAVES)
Block(3,18,9,LOG)
Block(3,18,10,LOG)
Block(3,18,11,LEAVES)
Block(3,19,-3,LEAVES)
Block(3,19,-2,LEAVES)
Block(3,19,-1,LEAVES)
Block(3,19,1,LEAVES)
Block(3,19,2,LEAVES)
Block(3,19,3,LEAVES)
Block(3,19,4,LEAVES)
Block(3,19,9,LEAVES)
Block(3,20,-3,LEAVES)
Block(3,20,-2,LEAVES)
Block(3,20,2,LEAVES)
Block(3,20,3,LEAVES)
Block(3,20,4,LEAVES)
Block(3,20,8,LEAVES)
Block(3,20,9,LEAVES)
Block(3,20,10,LEAVES)
Block(3,21,9,LEAVES)
Block(4,-5,0,LOG)
Block(4,-4,0,LOG)
Block(4,-3,-1,LOG)
Block(4,-3,0,LOG)
Block(4,-2,-1,LOG)
Block(4,4,-9,LEAVES)
Block(4,5,-10,LEAVES)
Block(4,5,-9,LEAVES)
Block(4,5,-8,LEAVES)
Block(4,5,-7,LEAVES)
Block(4,6,-11,LEAVES)
Block(4,6,-10,LEAVES)
Block(4,6,-9,LEAVES)
Block(4,6,-8,LEAVES)
Block(4,6,-7,LEAVES)
Block(4,6,-6,LEAVES)
Block(4,7,-13,LEAVES)
Block(4,7,-12,LEAVES)
Block(4,7,-11,LEAVES)
Block(4,7,-10,LEAVES)
Block(4,7,-9,LEAVES)
Block(4,7,-7,LEAVES)
Block(4,8,-13,LEAVES)
Block(4,8,-12,LEAVES)
Block(4,8,-10,LOG)
Block(4,8,-9,LEAVES)
Block(4,8,-8,LEAVES)
Block(4,8,11,LEAVES)
Block(4,9,-13,LEAVES)
Block(4,9,-12,LEAVES)
Block(4,9,-11,LEAVES)
Block(4,9,-10,LEAVES)
Block(4,9,-8,LEAVES)
Block(4,9,-7,LEAVES)
Block(4,9,9,LEAVES)
Block(4,9,12,LEAVES)
Block(4,10,-11,LEAVES)
Block(4,10,-10,LEAVES)
Block(4,10,-9,LEAVES)
Block(4,10,-8,LEAVES)
Block(4,10,-7,LEAVES)
Block(4,10,-6,LEAVES)
Block(4,10,9,LEAVES)
Block(4,10,11,LEAVES)
Block(4,11,-12,LEAVES)
Block(4,11,-11,LEAVES)
Block(4,11,-8,LEAVES)
Block(4,11,3,LEAVES)
Block(4,11,4,LEAVES)
Block(4,11,12,LEAVES)
Block(4,11,14,LEAVES)
Block(4,12,-11,LEAVES)
Block(4,12,-10,LEAVES)
Block(4,12,-9,LEAVES)
Block(4,12,-8,LEAVES)
Block(4,12,-7,LEAVES)
Block(4,12,-1,LEAVES)
Block(4,12,2,LEAVES)
Block(4,12,3,LEAVES)
Block(4,12,4,LEAVES)
Block(4,12,13,LEAVES)
Block(4,13,-10,LEAVES)
Block(4,13,-9,LEAVES)
Block(4,13,-3,LEAVES)
Block(4,13,-2,LEAVES)
Block(4,13,-1,LEAVES)
Block(4,13,0,LEAVES)
Block(4,13,1,LOG)
Block(4,13,3,LEAVES)
Block(4,13,4,LEAVES)
Block(4,14,-10,LEAVES)
Block(4,14,-9,LEAVES)
Block(4,14,-5,LEAVES)
Block(4,14,-3,LEAVES)
Block(4,14,0,LEAVES)
Block(4,14,2,LEAVES)
Block(4,15,-4,LEAVES)
Block(4,15,-1,LEAVES)
Block(4,15,0,LEAVES)
Block(4,15,2,LEAVES)
Block(4,15,7,LEAVES)
Block(4,16,-2,LEAVES)
Block(4,16,0,LOG)
Block(4,16,5,LEAVES)
Block(4,16,7,LEAVES)
Block(4,17,-3,LEAVES)
Block(4,17,-2,LEAVES)
Block(4,17,-1,LOG)
Block(4,17,2,LEAVES)
Block(4,17,3,LEAVES)
Block(4,17,4,LEAVES)
Block(4,17,5,LEAVES)
Block(4,17,6,LEAVES)
Block(4,17,7,LEAVES)
Block(4,17,8,LEAVES)
Block(4,17,9,LEAVES)
Block(4,17,10,LEAVES)
Block(4,18,-4,LEAVES)
Block(4,18,-3,LEAVES)
Block(4,18,-2,LEAVES)
Block(4,18,-1,LEAVES)
Block(4,18,3,LEAVES)
Block(4,18,4,LEAVES)
Block(4,18,5,LEAVES)
Block(4,18,7,LEAVES)
Block(4,18,8,LEAVES)
Block(4,18,10,LOG)
Block(4,19,-4,LEAVES)
Block(4,19,-3,LEAVES)
Block(4,19,-2,LEAVES)
Block(4,19,-1,LEAVES)
Block(4,19,1,LEAVES)
Block(4,19,2,LEAVES)
Block(4,19,4,LEAVES)
Block(4,19,5,LEAVES)
Block(4,19,6,LEAVES)
Block(4,19,8,LEAVES)
Block(4,19,9,LEAVES)
Block(4,19,10,LOG)
Block(4,19,11,LEAVES)
Block(4,20,-2,LEAVES)
Block(4,20,3,LEAVES)
Block(4,20,4,LEAVES)
Block(4,20,7,LEAVES)
Block(4,20,8,LEAVES)
Block(4,20,9,LEAVES)
Block(4,20,10,LEAVES)
Block(4,21,4,LEAVES)
Block(4,21,8,LEAVES)
Block(4,21,9,LEAVES)
Block(5,-6,0,LOG)
Block(5,-5,0,LOG)
Block(5,-4,0,LOG)
Block(5,-4,1,LOG)
Block(5,4,-10,LEAVES)
Block(5,5,-11,LEAVES)
Block(5,5,-10,LEAVES)
Block(5,5,-9,LEAVES)
Block(5,5,-8,LEAVES)
Block(5,5,-7,LEAVES)
Block(5,6,-11,LEAVES)
Block(5,6,-10,LEAVES)
Block(5,6,-9,LEAVES)
Block(5,6,-8,LEAVES)
Block(5,6,-7,LEAVES)
Block(5,7,-12,LEAVES)
Block(5,7,-11,LEAVES)
Block(5,7,-10,LOG)
Block(5,7,-9,LOG)
Block(5,7,-8,LEAVES)
Block(5,7,-7,LEAVES)
Block(5,7,-6,LEAVES)
Block(5,8,-13,LEAVES)
Block(5,8,-12,LEAVES)
Block(5,8,-11,LEAVES)
Block(5,8,-10,LEAVES)
Block(5,8,-9,LEAVES)
Block(5,8,-6,LEAVES)
Block(5,9,-13,LEAVES)
Block(5,9,-10,LEAVES)
Block(5,9,-8,LEAVES)
Block(5,9,-7,LEAVES)
Block(5,10,-11,LEAVES)
Block(5,10,-10,LEAVES)
Block(5,10,-9,LEAVES)
Block(5,10,-7,LEAVES)
Block(5,11,-11,LEAVES)
Block(5,11,-10,LEAVES)
Block(5,11,-9,LEAVES)
Block(5,11,-8,LEAVES)
Block(5,11,-7,LEAVES)
Block(5,11,-1,LEAVES)
Block(5,11,0,LEAVES)
Block(5,11,2,LEAVES)
Block(5,11,3,LEAVES)
Block(5,12,-10,LEAVES)
Block(5,12,-8,LEAVES)
Block(5,12,-2,LEAVES)
Block(5,12,2,LEAVES)
Block(5,12,3,LEAVES)
Block(5,12,5,LEAVES)
Block(5,13,-9,LEAVES)
Block(5,13,-2,LEAVES)
Block(5,13,-1,LEAVES)
Block(5,13,0,LEAVES)
Block(5,13,1,LOG)
Block(5,13,3,LEAVES)
Block(5,14,2,LEAVES)
Block(5,15,-3,LEAVES)
Block(5,15,-2,LEAVES)
Block(5,15,-1,LEAVES)
Block(5,15,2,LEAVES)
Block(5,15,3,LEAVES)
Block(5,15,7,LEAVES)
Block(5,16,-4,LEAVES)
Block(5,16,-3,LEAVES)
Block(5,16,0,LEAVES)
Block(5,16,1,LEAVES)
Block(5,16,4,LEAVES)
Block(5,16,7,LEAVES)
Block(5,16,8,LEAVES)
Block(5,16,9,LEAVES)
Block(5,17,-4,LEAVES)
Block(5,17,-3,LEAVES)
Block(5,17,-2,LOG)
Block(5,17,-1,LEAVES)
Block(5,17,2,LEAVES)
Block(5,17,3,LEAVES)
Block(5,17,5,LEAVES)
Block(5,17,7,LEAVES)
Block(5,17,8,LEAVES)
Block(5,17,9,LEAVES)
Block(5,18,-3,LEAVES)
Block(5,18,-2,LEAVES)
Block(5,18,0,LEAVES)
Block(5,18,1,LEAVES)
Block(5,18,2,LEAVES)
Block(5,18,3,LEAVES)
Block(5,18,4,LEAVES)
Block(5,18,5,LEAVES)
Block(5,18,6,LEAVES)
Block(5,18,11,LEAVES)
Block(5,19,-3,LEAVES)
Block(5,19,-2,LEAVES)
Block(5,19,3,LEAVES)
Block(5,19,5,LEAVES)
Block(5,19,6,LEAVES)
Block(5,19,7,LEAVES)
Block(5,19,8,LEAVES)
Block(5,19,9,LOG)
Block(5,19,10,LOG)
Block(5,19,11,LEAVES)
Block(5,20,2,LEAVES)
Block(5,20,3,LEAVES)
Block(5,20,6,LEAVES)
Block(5,20,7,LEAVES)
Block(5,20,8,LEAVES)
Block(5,20,9,LEAVES)
Block(5,20,10,LEAVES)
Block(5,20,11,LEAVES)
Block(5,21,3,LEAVES)
Block(5,21,7,LEAVES)
Block(5,21,8,LEAVES)
Block(5,21,10,LEAVES)
Block(5,21,11,LEAVES)
Block(5,22,9,LEAVES)
Block(6,4,-8,LEAVES)
Block(6,5,-10,LEAVES)
Block(6,5,-8,LEAVES)
Block(6,5,-7,LEAVES)
Block(6,6,-11,LEAVES)
Block(6,6,-10,LEAVES)
Block(6,6,-9,LEAVES)
Block(6,6,-8,LEAVES)
Block(6,6,-6,LEAVES)
Block(6,7,-13,LEAVES)
Block(6,7,-12,LEAVES)
Block(6,7,-11,LEAVES)
Block(6,7,-10,LEAVES)
Block(6,7,-9,LOG)
Block(6,7,-8,LOG)
Block(6,7,-7,LEAVES)
Block(6,7,-6,LEAVES)
Block(6,8,-10,LEAVES)
Block(6,8,-9,LEAVES)
Block(6,8,-8,LEAVES)
Block(6,8,-7,LEAVES)
Block(6,9,-9,LEAVES)
Block(6,9,-8,LEAVES)
Block(6,10,-10,LEAVES)
Block(6,10,-9,LEAVES)
Block(6,10,-8,LEAVES)
Block(6,10,-7,LEAVES)
Block(6,10,-6,LEAVES)
Block(6,10,-1,LEAVES)
Block(6,10,1,LEAVES)
Block(6,10,2,LEAVES)
Block(6,11,-11,LEAVES)
Block(6,11,-8,LEAVES)
Block(6,11,-1,LEAVES)
Block(6,11,0,LEAVES)
Block(6,11,1,LEAVES)
Block(6,11,2,LEAVES)
Block(6,11,3,LEAVES)
Block(6,12,-3,LEAVES)
Block(6,12,-2,LEAVES)
Block(6,12,-1,LEAVES)
Block(6,12,0,LEAVES)
Block(6,12,1,LEAVES)
Block(6,12,2,LOG)
Block(6,12,3,LEAVES)
Block(6,12,4,LEAVES)
Block(6,13,-1,LEAVES)
Block(6,13,2,LEAVES)
Block(6,13,4,LEAVES)
Block(6,14,1,LEAVES)
Block(6,14,2,LEAVES)
Block(6,14,3,LEAVES)
Block(6,15,-3,LEAVES)
Block(6,15,0,LEAVES)
Block(6,15,2,LEAVES)
Block(6,15,8,LEAVES)
Block(6,16,-3,LEAVES)
Block(6,16,-2,LEAVES)
Block(6,16,2,LEAVES)
Block(6,16,4,LEAVES)
Block(6,16,6,LEAVES)
Block(6,16,7,LEAVES)
Block(6,16,8,LEAVES)
Block(6,16,9,LEAVES)
Block(6,17,-3,LEAVES)
Block(6,17,-2,LEAVES)
Block(6,17,4,LEAVES)
Block(6,17,6,LEAVES)
Block(6,17,7,LEAVES)
Block(6,17,8,LEAVES)
Block(6,17,9,LEAVES)
Block(6,17,10,LEAVES)
Block(6,18,-4,LEAVES)
Block(6,18,-3,LEAVES)
Block(6,18,0,LEAVES)
Block(6,18,1,LEAVES)
Block(6,18,3,LEAVES)
Block(6,18,6,LEAVES)
Block(6,18,7,LEAVES)
Block(6,18,8,LEAVES)
Block(6,18,9,LEAVES)
Block(6,19,-2,LEAVES)
Block(6,19,-1,LEAVES)
Block(6,19,3,LEAVES)
Block(6,19,5,LEAVES)
Block(6,19,7,LEAVES)
Block(6,19,9,LOG)
Block(6,19,10,LEAVES)
Block(6,19,11,LEAVES)
Block(6,19,12,LEAVES)
Block(6,20,-1,LEAVES)
Block(6,20,2,LEAVES)
Block(6,20,3,LEAVES)
Block(6,20,8,LEAVES)
Block(6,20,9,LEAVES)
Block(6,20,10,LEAVES)
Block(6,20,11,LEAVES)
Block(6,20,12,LEAVES)
Block(6,21,7,LEAVES)
Block(6,21,8,LEAVES)
Block(6,21,9,LEAVES)
Block(6,21,10,LEAVES)
Block(7,5,-9,LEAVES)
Block(7,5,-8,LEAVES)
Block(7,6,-9,LEAVES)
Block(7,6,-8,LEAVES)
Block(7,7,-12,LEAVES)
Block(7,7,-11,LEAVES)
Block(7,7,-10,LEAVES)
Block(7,7,-9,LEAVES)
Block(7,7,-8,LEAVES)
Block(7,7,-7,LEAVES)
Block(7,7,-6,LEAVES)
Block(7,8,-11,LEAVES)
Block(7,8,-10,LEAVES)
Block(7,8,-9,LEAVES)
Block(7,8,-8,LEAVES)
Block(7,8,-7,LEAVES)
Block(7,9,-11,LEAVES)
Block(7,9,-10,LEAVES)
Block(7,9,-8,LEAVES)
Block(7,10,-9,LEAVES)
Block(7,10,-7,LEAVES)
Block(7,11,3,LEAVES)
Block(7,12,-2,LEAVES)
Block(7,12,-1,LEAVES)
Block(7,12,1,LEAVES)
Block(7,12,2,LEAVES)
Block(7,12,3,LEAVES)
Block(7,13,-3,LEAVES)
Block(7,13,-2,LEAVES)
Block(7,13,-1,LEAVES)
Block(7,13,0,LEAVES)
Block(7,13,1,LEAVES)
Block(7,13,2,LEAVES)
Block(7,13,3,LEAVES)
Block(7,13,4,LEAVES)
Block(7,14,-2,LEAVES)
Block(7,14,-1,LEAVES)
Block(7,14,0,LEAVES)
Block(7,14,1,LEAVES)
Block(7,14,2,LEAVES)
Block(7,14,4,LEAVES)
Block(7,15,-1,LEAVES)
Block(7,15,2,LEAVES)
Block(7,15,7,LEAVES)
Block(7,16,1,LEAVES)
Block(7,16,2,LEAVES)
Block(7,16,5,LEAVES)
Block(7,16,7,LEAVES)
Block(7,17,-1,LEAVES)
Block(7,17,1,LEAVES)
Block(7,17,5,LEAVES)
Block(7,17,7,LEAVES)
Block(7,17,8,LEAVES)
Block(7,18,-2,LEAVES)
Block(7,18,-1,LEAVES)
Block(7,18,0,LEAVES)
Block(7,18,1,LEAVES)
Block(7,18,3,LEAVES)
Block(7,18,4,LEAVES)
Block(7,18,5,LEAVES)
Block(7,18,6,LEAVES)
Block(7,18,7,LEAVES)
Block(7,18,8,LEAVES)
Block(7,18,9,LEAVES)
Block(7,19,1,LEAVES)
Block(7,19,4,LEAVES)
Block(7,19,5,LEAVES)
Block(7,19,6,LEAVES)
Block(7,19,7,LEAVES)
Block(7,19,8,LEAVES)
Block(7,19,9,LEAVES)
Block(7,20,3,LEAVES)
Block(7,20,4,LEAVES)
Block(7,20,9,LEAVES)
Block(7,20,10,LEAVES)
Block(7,20,11,LEAVES)
Block(7,21,7,LEAVES)
Block(7,21,9,LEAVES)
Block(7,21,10,LEAVES)
Block(7,22,8,LEAVES)
Block(7,22,10,LEAVES)
Block(8,6,-11,LEAVES)
Block(8,6,-9,LEAVES)
Block(8,7,-11,LEAVES)
Block(8,7,-9,LEAVES)
Block(8,7,-8,LEAVES)
Block(8,7,-7,LEAVES)
Block(8,8,-9,LEAVES)
Block(8,8,-8,LEAVES)
Block(8,9,-11,LEAVES)
Block(8,12,-2,LEAVES)
Block(8,12,0,LEAVES)
Block(8,12,1,LEAVES)
Block(8,12,2,LEAVES)
Block(8,12,3,LEAVES)
Block(8,13,-2,LEAVES)
Block(8,13,-1,LEAVES)
Block(8,13,1,LEAVES)
Block(8,13,2,LEAVES)
Block(8,13,3,LEAVES)
Block(8,13,4,LEAVES)
Block(8,14,-1,LEAVES)
Block(8,14,0,LEAVES)
Block(8,14,1,LEAVES)
Block(8,14,2,LEAVES)
Block(8,15,-1,LEAVES)
Block(8,15,0,LEAVES)
Block(8,15,1,LEAVES)
Block(8,16,-1,LEAVES)
Block(8,16,0,LEAVES)
Block(8,17,-1,LEAVES)
Block(8,17,1,LEAVES)
Block(8,17,2,LEAVES)
Block(8,17,7,LEAVES)
Block(8,17,8,LEAVES)
Block(8,18,-1,LEAVES)
Block(8,18,0,LEAVES)
Block(8,18,2,LEAVES)
Block(8,18,3,LEAVES)
Block(8,18,4,LEAVES)
Block(8,18,5,LEAVES)
Block(8,18,6,LEAVES)
Block(8,18,7,LEAVES)
Block(8,18,8,LEAVES)
Block(8,18,10,LEAVES)
Block(8,19,0,LEAVES)
Block(8,19,2,LEAVES)
Block(8,19,3,LEAVES)
Block(8,19,5,LEAVES)
Block(8,19,9,LEAVES)
Block(8,19,10,LEAVES)
Block(8,19,11,LEAVES)
Block(8,20,7,LEAVES)
Block(8,20,8,LEAVES)
Block(8,20,9,LEAVES)
Block(8,20,10,LEAVES)
Block(8,21,8,LEAVES)
Block(8,21,10,LEAVES)
Block(9,12,1,LEAVES)
Block(9,12,3,LEAVES)
Block(9,13,2,LEAVES)
Block(9,13,4,LEAVES)
Block(9,14,1,LEAVES)
Block(9,14,2,LEAVES)
Block(9,15,-1,LEAVES)
Block(9,15,0,LEAVES)
Block(9,15,1,LEAVES)
Block(9,16,-1,LEAVES)
Block(9,16,1,LEAVES)
Block(9,18,9,LEAVES)
Block(9,19,10,LEAVES)
Block(9,20,8,LEAVES)
Block(9,20,10,LEAVES)

#######################################################################
# +-----------------------------------------------------------------+ #
# |                            BO3 checks                           | #
# +-----------------------------------------------------------------+ #
#######################################################################

# Require a condition at a certain location in order for the BO3 to be spawned.
# BlockCheck(x,y,z,BlockName[,BlockName[,...]]) - one of the blocks must be at the location
# BlockCheckNot(x,y,z,BlockName[,BlockName[,...]]) - all the blocks must not be at the location
# LightCheck(x,y,z,minLightLevel,maxLightLevel) - light must be between min and max (inclusive)

# You can use "Solid" as a BlockName for matching all solid blocks or "All" to match all blocks that aren't air.

# Examples:
#   BlockCheck(0,-1,0,GRASS,DIRT)  Require grass or dirt just below the object
#   BlockCheck(0,-1,0,Solid)       Require any solid block just below the object
#   BlockCheck(0,-1,0,WOOL)        Require any type of wool just below the object
#   BlockCheck(0,-1,0,WOOL:0)      Require white wool just below the object
#   BlockCheckNot(0,-1,0,WOOL:0)   Require that there is no white wool below the object
#   LightCheck(0,0,0,0,1)          Require almost complete darkness just below the object
BlockCheck(0,-1,0,GRASS)

#######################################################################
# +-----------------------------------------------------------------+ #
# |                             Branches                            | #
# +-----------------------------------------------------------------+ #
#######################################################################

# Branches are objects that will spawn when this object spawns when it is used in
# the CustomStructure resource. Branches can also have branches, making complex
# structures possible. See the wiki for more details.

# Regular Branches spawn each branch with an independent chance of spawning.
# Branch(x,y,z,branchName,rotation,chance[,anotherBranchName,rotation,chance[,...]][IndividualChance])
# branchName - name of the object to spawn.
# rotation - NORTH, SOUTH, EAST or WEST.
# IndividualChance - The chance each branch has to spawn, assumed to be 100 when left blank

# Weighted Branches spawn branches with a dependent chance of spawning.
# WeightedBranch(x,y,z,branchName,rotation,chance[,anotherBranchName,rotation,chance[,...]][MaxChanceOutOf])
# MaxChanceOutOf - The chance all branches have to spawn out of, assumed to be 100 when left blank
