[META]
version=2.0
spawnOnBlockType=2
spawnSunlight=True
spawnDarkness=True
spawnWater=False
spawnLava=False
underFill=False
randomRotation=True
dig=True
tree=True
branch=False
needsFoundation=True
rarity=10
collisionPercentage=20
spawnElevationMin=0
spawnElevationMax=200
spawnInBiome=Custom
[DATA]
0,1,0:17.0
0,1,1:17.0
0,1,2:17.0
0,1,3:17.0
0,-1,4:17.8
1,-1,4:18.0
0,0,4:17.8
0,1,4:17.0
0,-3,5:18.0
1,-3,5:18.0
-1,-2,5:18.0
0,-2,5:17.0
1,-2,5:18.0
-1,-1,5:18.0
0,-1,5:18.0
1,-1,5:18.0
-1,0,5:18.0
0,0,5:18.0
-1,1,5:17.4
0,1,5:17.0
1,-6,6:18.0
2,-6,6:18.0
3,-6,6:18.0
1,-5,6:18.0
2,-5,6:18.0
3,-5,6:18.0
0,-4,6:18.0
1,-4,6:18.0
2,-4,6:18.0
3,-4,6:18.0
-1,-3,6:18.0
0,-3,6:18.0
1,-3,6:17.0
2,-3,6:18.0
-1,-2,6:18.0
0,-2,6:18.0
1,-2,6:18.0
2,-2,6:18.0
-2,-1,6:18.0
-1,-1,6:18.0
0,-1,6:18.0
1,-1,6:18.0
-2,0,6:18.0
-1,0,6:18.0
0,0,6:17.0
1,0,6:18.0
2,0,6:18.0
3,0,6:18.0
-2,1,6:17.0
0,1,6:17.0
1,1,6:17.4
2,1,6:17.4
3,1,6:18.0
4,1,6:18.0
1,2,6:18.0
2,2,6:18.0
3,2,6:18.0
1,-7,7:18.0
2,-7,7:18.0
3,-7,7:18.0
0,-6,7:18.0
1,-6,7:18.0
2,-6,7:18.0
3,-6,7:18.0
4,-6,7:18.0
0,-5,7:18.0
1,-5,7:18.0
2,-5,7:17.0
3,-5,7:18.0
4,-5,7:18.0
0,-4,7:18.0
1,-4,7:18.0
2,-4,7:17.0
3,-4,7:18.0
4,-4,7:18.0
-2,-3,7:18.0
-1,-3,7:18.0
0,-3,7:18.0
1,-3,7:18.0
2,-3,7:18.0
3,-3,7:18.0
-3,-2,7:18.0
-2,-2,7:18.0
-1,-2,7:18.0
0,-2,7:18.0
1,-2,7:18.0
-3,-1,7:18.0
-2,-1,7:18.0
-1,-1,7:17.0
0,-1,7:18.0
1,-1,7:18.0
2,-1,7:18.0
3,-1,7:18.0
4,-1,7:18.0
5,-1,7:18.0
-4,0,7:18.0
-3,0,7:18.0
-2,0,7:18.0
-1,0,7:18.0
0,0,7:18.0
1,0,7:18.0
2,0,7:18.0
3,0,7:18.0
4,0,7:18.0
5,0,7:18.0
6,0,7:18.0
-4,1,7:18.0
-3,1,7:17.0
-2,1,7:18.0
-1,1,7:18.0
0,1,7:17.0
1,1,7:18.0
2,1,7:18.0
3,1,7:17.0
4,1,7:18.0
5,1,7:18.0
6,1,7:18.0
-4,2,7:18.0
-3,2,7:18.0
-2,2,7:18.0
-1,2,7:18.0
0,2,7:18.0
1,2,7:18.0
2,2,7:18.0
3,2,7:18.0
4,2,7:18.0
5,2,7:18.0
6,2,7:18.0
1,3,7:18.0
2,3,7:18.0
3,3,7:18.0
4,3,7:18.0
5,3,7:18.0
1,-6,8:18.0
2,-6,8:18.0
3,-6,8:18.0
1,-5,8:18.0
2,-5,8:18.0
3,-5,8:18.0
-2,-4,8:18.0
1,-4,8:18.0
2,-4,8:18.0
3,-4,8:18.0
-3,-3,8:18.0
-2,-3,8:18.0
-1,-3,8:18.0
2,-3,8:18.0
-4,-2,8:18.0
-3,-2,8:18.0
-2,-2,8:17.0
-1,-2,8:18.0
-5,-1,8:18.0
-4,-1,8:18.0
-3,-1,8:18.0
-2,-1,8:18.0
-1,-1,8:18.0
-5,0,8:18.0
-4,0,8:18.0
-3,0,8:18.0
-2,0,8:18.0
-1,0,8:18.0
0,0,8:18.0
2,0,8:18.0
4,0,8:18.0
5,0,8:18.0
-5,1,8:18.0
-4,1,8:18.0
-3,1,8:18.0
-2,1,8:18.0
-1,1,8:18.0
0,1,8:17.0
1,1,8:18.0
2,1,8:18.0
3,1,8:18.0
4,1,8:17.0
5,1,8:18.0
6,1,8:18.0
7,1,8:18.0
-5,2,8:18.0
-4,2,8:17.0
-3,2,8:18.0
-2,2,8:18.0
-1,2,8:18.0
0,2,8:17.8
1,2,8:18.0
2,2,8:18.0
3,2,8:18.0
4,2,8:18.0
5,2,8:18.0
6,2,8:18.0
-5,3,8:18.0
-4,3,8:18.0
-3,3,8:18.0
-1,3,8:18.0
0,3,8:18.0
1,3,8:18.0
2,3,8:18.0
3,3,8:18.0
4,3,8:18.0
5,3,8:18.0
-1,4,8:18.0
0,4,8:18.0
0,5,8:18.0
2,-5,9:18.0
-3,-4,9:18.0
-2,-4,9:18.0
-1,-4,9:18.0
2,-4,9:18.0
-4,-3,9:18.0
-3,-3,9:18.0
-2,-3,9:17.0
-1,-3,9:18.0
0,-3,9:18.0
-5,-2,9:18.0
-4,-2,9:18.0
-3,-2,9:17.0
-2,-2,9:18.0
-1,-2,9:18.0
0,-2,9:18.0
-5,-1,9:18.0
-4,-1,9:18.0
-3,-1,9:18.0
-2,-1,9:18.0
4,-1,9:18.0
5,-1,9:18.0
6,-1,9:18.0
-6,0,9:18.0
-5,0,9:18.0
-4,0,9:18.0
-3,0,9:18.0
-2,0,9:18.0
-1,0,9:18.0
0,0,9:18.0
1,0,9:18.0
2,0,9:18.0
3,0,9:18.0
4,0,9:18.0
5,0,9:18.0
6,0,9:18.0
7,0,9:18.0
-7,1,9:18.0
-6,1,9:18.0
-5,1,9:18.0
-4,1,9:18.0
-3,1,9:18.0
-2,1,9:18.0
-1,1,9:18.0
0,1,9:17.0
1,1,9:18.0
2,1,9:18.0
3,1,9:18.0
4,1,9:18.0
5,1,9:17.0
6,1,9:18.0
7,1,9:18.0
-7,2,9:18.0
-6,2,9:18.0
-5,2,9:17.0
-4,2,9:18.0
-3,2,9:18.0
-2,2,9:18.0
-1,2,9:18.0
0,2,9:18.0
1,2,9:18.0
2,2,9:18.0
3,2,9:18.0
4,2,9:18.0
5,2,9:18.0
6,2,9:18.0
7,2,9:18.0
-7,3,9:18.0
-6,3,9:18.0
-5,3,9:18.0
-4,3,9:18.0
-3,3,9:18.0
-1,3,9:18.0
0,3,9:17.0
1,3,9:18.0
4,3,9:18.0
5,3,9:18.0
6,3,9:18.0
-6,4,9:18.0
-5,4,9:18.0
-4,4,9:18.0
-1,4,9:18.0
0,4,9:18.0
1,4,9:18.0
-2,5,9:18.0
-1,5,9:18.0
0,5,9:18.0
1,5,9:18.0
-1,6,9:18.0
0,6,9:18.0
-3,-4,10:18.0
-2,-4,10:18.0
-1,-4,10:18.0
-4,-3,10:18.0
-3,-3,10:18.0
-2,-3,10:18.0
-1,-3,10:18.0
0,-3,10:18.0
-4,-2,10:18.0
-3,-2,10:18.0
-2,-2,10:18.0
-1,-2,10:18.0
2,-2,10:18.0
-4,-1,10:18.0
-3,-1,10:18.0
-2,-1,10:18.0
1,-1,10:18.0
2,-1,10:18.0
3,-1,10:18.0
0,0,10:18.0
1,0,10:17.0
2,0,10:18.0
3,0,10:18.0
4,0,10:18.0
5,0,10:18.0
6,0,10:18.0
-6,1,10:18.0
-5,1,10:18.0
-4,1,10:18.0
-1,1,10:18.0
0,1,10:17.0
1,1,10:18.0
2,1,10:18.0
3,1,10:18.0
4,1,10:18.0
5,1,10:18.0
6,1,10:18.0
-6,2,10:18.0
-5,2,10:18.0
-4,2,10:18.0
-3,2,10:18.0
0,2,10:18.0
1,2,10:18.0
4,2,10:18.0
5,2,10:18.0
6,2,10:18.0
-6,3,10:18.0
-5,3,10:18.0
-4,3,10:18.0
-1,3,10:18.0
0,3,10:18.0
1,3,10:18.0
-2,4,10:18.0
-1,4,10:18.0
0,4,10:17.0
1,4,10:18.0
2,4,10:18.0
-2,5,10:18.0
-1,5,10:18.0
0,5,10:17.0
1,5,10:18.0
2,5,10:18.0
-2,6,10:18.0
-1,6,10:18.0
0,6,10:18.0
1,6,10:18.0
-1,7,10:18.0
0,7,10:18.0
-2,-3,11:18.0
-3,-2,11:18.0
1,-2,11:18.0
2,-2,11:18.0
0,-1,11:18.0
1,-1,11:18.0
2,-1,11:17.0
3,-1,11:18.0
-1,0,11:18.0
0,0,11:18.0
1,0,11:18.0
2,0,11:18.0
-2,1,11:18.0
-1,1,11:18.0
0,1,11:17.0
1,1,11:18.0
4,1,11:18.0
5,1,11:18.0
-5,2,11:18.0
-4,2,11:18.0
0,2,11:18.0
0,3,11:18.0
-1,4,11:18.0
0,4,11:18.0
1,4,11:18.0
-1,5,11:18.0
0,5,11:18.0
1,5,11:18.0
-1,6,11:18.0
0,6,11:18.0
1,6,11:18.0
-1,-1,12:18.0
0,-1,12:18.0
1,-1,12:18.0
2,-1,12:18.0
-2,0,12:18.0
-1,0,12:18.0
0,0,12:18.0
1,0,12:18.0
2,0,12:18.0
-3,1,12:18.0
-2,1,12:18.0
-1,1,12:17.0
0,1,12:17.0
1,1,12:18.0
-2,2,12:18.0
-1,2,12:18.0
0,2,12:18.0
-1,3,12:18.0
0,4,12:18.0
0,5,12:18.0
0,-1,13:18.0
1,-1,13:18.0
-3,0,13:18.0
-2,0,13:18.0
-1,0,13:18.0
0,0,13:18.0
1,0,13:18.0
-4,1,13:18.0
-3,1,13:18.0
-2,1,13:17.0
-1,1,13:18.0
0,1,13:17.0
1,1,13:18.0
-3,2,13:18.0
-2,2,13:18.0
-1,2,13:18.0
0,2,13:18.0
1,2,13:18.0
-1,3,13:18.0
-3,0,14:18.0
-2,0,14:18.0
0,0,14:18.0
-3,1,14:18.0
-2,1,14:18.0
-1,1,14:18.0
0,1,14:17.0
1,1,14:18.0
2,1,14:18.0
-2,2,14:18.0
-1,2,14:18.0
0,2,14:18.0
1,2,14:17.0
2,2,14:18.0
-1,3,14:18.0
0,3,14:18.0
1,3,14:18.0
2,3,14:18.0
-1,-1,15:18.0
0,-1,15:18.0
1,-1,15:18.0
-2,0,15:18.0
-1,0,15:18.0
0,0,15:18.0
1,0,15:18.0
2,0,15:18.0
-2,1,15:18.0
-1,1,15:18.0
0,1,15:17.0
1,1,15:18.0
2,1,15:18.0
-2,2,15:18.0
-1,2,15:18.0
0,2,15:18.0
1,2,15:18.0
2,2,15:18.0
0,3,15:18.0
1,3,15:18.0
0,0,16:18.0
1,0,16:18.0
-1,1,16:18.0
0,1,16:18.0
1,1,16:18.0
-1,2,16:18.0
0,2,16:18.0
0,1,17:18.0
