[META]
version=2.0
spawnOnBlockType=8,9,2
spawnSunlight=True
spawnDarkness=True
spawnWater=True
spawnLava=False
underFill=False
randomRotation=True
dig=True
tree=True
branch=False
needsFoundation=False
rarity=100
collisionPercentage=50
spawnElevationMin=49
spawnElevationMax=54
spawnInBiome=Custom
[DATA]
0,-2,0:17.0
-3,-1,0:17.0
1,-1,0:17.0
-4,0,0:17.0
1,1,0:17.0
-2,2,0:17.0
-1,3,0:17.0
0,-1,1:17.0
-3,0,1:17.0
0,1,1:17.0
-1,2,1:17.0
0,-1,2:17.0
-2,0,2:17.0
0,1,2:17.0
-1,2,2:17.0
-1,-1,3:17.0
-2,0,3:17.0
-1,1,3:17.0
-1,-1,4:17.0
-2,0,4:17.0
-1,0,4:17.0
-1,1,4:17.0
-1,0,5:17.0
-1,0,6:17.0
-1,0,7:17.0
-1,0,8:17.0
0,-4,9:18.0
-1,-3,9:18.0
0,-3,9:18.0
-1,-2,9:18.0
0,-2,9:18.0
1,-2,9:18.0
-2,-1,9:18.0
-1,-1,9:18.0
0,-1,9:18.0
1,-1,9:18.0
2,-1,9:18.0
-2,0,9:18.0
-1,0,9:17.0
0,0,9:18.0
1,0,9:18.0
2,0,9:18.0
3,0,9:18.0
-3,1,9:18.0
-2,1,9:18.0
-1,1,9:18.0
0,1,9:18.0
1,1,9:18.0
2,1,9:18.0
3,1,9:18.0
4,1,9:18.0
-3,2,9:18.0
-2,2,9:18.0
-1,-6,10:18.0
0,-6,10:18.0
-2,-5,10:18.0
-1,-5,10:18.0
0,-5,10:18.0
1,-5,10:18.0
-3,-4,10:18.0
-2,-4,10:18.0
-1,-4,10:18.0
0,-4,10:18.0
1,-4,10:18.0
2,-4,10:18.0
-4,-3,10:18.0
-3,-3,10:18.0
-2,-3,10:18.0
-1,-3,10:17.0
0,-3,10:17.0
1,-3,10:18.0
2,-3,10:18.0
3,-3,10:18.0
-4,-2,10:18.0
-3,-2,10:18.0
-2,-2,10:18.0
-1,-2,10:17.0
0,-2,10:18.0
1,-2,10:18.0
2,-2,10:18.0
3,-2,10:18.0
-4,-1,10:18.0
-3,-1,10:18.0
-2,-1,10:18.0
-1,-1,10:17.0
0,-1,10:18.0
1,-1,10:18.0
2,-1,10:18.0
3,-1,10:18.0
4,-1,10:18.0
-5,0,10:18.0
-4,0,10:18.0
-3,0,10:18.0
-2,0,10:17.0
-1,0,10:17.0
0,0,10:17.0
1,0,10:17.0
2,0,10:17.0
3,0,10:17.0
4,0,10:18.0
5,0,10:18.0
6,0,10:18.0
-6,1,10:18.0
-5,1,10:18.0
-4,1,10:18.0
-3,1,10:17.0
-2,1,10:17.0
-1,1,10:18.0
0,1,10:18.0
1,1,10:18.0
2,1,10:18.0
3,1,10:17.0
4,1,10:17.0
5,1,10:18.0
6,1,10:18.0
7,1,10:18.0
-6,2,10:18.0
-5,2,10:18.0
-4,2,10:18.0
-3,2,10:17.0
-2,2,10:18.0
-1,2,10:18.0
0,2,10:18.0
1,2,10:18.0
2,2,10:18.0
3,2,10:18.0
4,2,10:18.0
5,2,10:18.0
-5,3,10:18.0
-4,3,10:18.0
-3,3,10:18.0
-2,3,10:18.0
2,3,10:18.0
3,3,10:18.0
4,3,10:18.0
-3,4,10:18.0
3,4,10:18.0
-3,5,10:18.0
-1,-3,11:18.0
0,-3,11:18.0
-2,-2,11:18.0
-1,-2,11:18.0
0,-2,11:18.0
1,-2,11:18.0
-2,-1,11:18.0
-1,-1,11:18.0
0,-1,11:18.0
1,-1,11:18.0
2,-1,11:18.0
-3,0,11:18.0
-2,0,11:18.0
-1,0,11:18.0
0,0,11:18.0
1,0,11:18.0
2,0,11:18.0
3,0,11:18.0
-3,1,11:18.0
-2,1,11:18.0
2,1,11:18.0
3,1,11:18.0
4,1,11:18.0
-3,2,11:18.0
