[META]
version=2.0
spawnOnBlockType=8,9,2
spawnSunlight=True
spawnDarkness=True
spawnWater=True
spawnLava=False
underFill=False
randomRotation=True
dig=True
tree=True
branch=False
needsFoundation=False
rarity=100
collisionPercentage=50
spawnElevationMin=49
spawnElevationMax=54
spawnInBiome=Custom
[DATA]
-2,-2,-5:17.0
2,-2,-5:17.0
-3,-1,-5:17.0
-2,-1,-5:17.0
2,-1,-5:17.0
3,-1,-5:17.0
-5,1,-5:17.0
-4,1,-5:17.0
-1,1,-5:17.0
-4,2,-5:17.0
-2,3,-5:17.0
-1,3,-5:17.0
1,3,-5:17.0
2,3,-5:17.0
-1,4,-5:17.0
1,4,-5:17.0
-2,-2,-4:17.0
2,-2,-4:17.0
-3,-1,-4:17.0
-2,-1,-4:17.0
2,-1,-4:17.0
3,-1,-4:17.0
-5,1,-4:17.0
-4,1,-4:17.0
-1,1,-4:17.0
-4,2,-4:17.0
-2,3,-4:17.0
-1,3,-4:17.0
1,3,-4:17.0
2,3,-4:17.0
-1,4,-4:17.0
1,4,-4:17.0
-2,-2,-3:17.0
2,-2,-3:17.0
-3,-1,-3:17.0
-2,-1,-3:17.0
2,-1,-3:17.0
3,-1,-3:17.0
-5,1,-3:17.0
-4,1,-3:17.0
-1,1,-3:17.0
-4,2,-3:17.0
-2,3,-3:17.0
-1,3,-3:17.0
1,3,-3:17.0
2,3,-3:17.0
-1,4,-3:17.0
1,4,-3:17.0
-2,-2,-2:17.0
2,-2,-2:17.0
-3,-1,-2:17.0
-2,-1,-2:17.0
2,-1,-2:17.0
3,-1,-2:17.0
-5,1,-2:17.0
-4,1,-2:17.0
-1,1,-2:17.0
-4,2,-2:17.0
-2,3,-2:17.0
-1,3,-2:17.0
1,3,-2:17.0
2,3,-2:17.0
-1,4,-2:17.0
1,4,-2:17.0
-2,-1,-1:17.0
2,-1,-1:17.0
-4,1,-1:17.0
-1,1,-1:17.0
-1,3,-1:17.0
1,3,-1:17.0
-2,-1,0:17.0
1,-1,0:17.0
2,-1,0:17.0
-4,1,0:17.0
-1,1,0:17.0
-1,3,0:17.0
1,3,0:17.0
-2,-1,1:17.0
0,-1,1:17.0
1,-1,1:17.0
-2,0,1:17.0
-4,1,1:17.0
-3,1,1:17.0
-1,1,1:17.0
-1,2,1:17.0
1,2,1:17.0
-1,3,1:17.0
1,3,1:17.0
0,-1,2:17.0
-2,0,2:17.0
0,0,2:17.0
-3,1,2:17.0
-2,1,2:17.0
-1,1,2:17.0
-1,2,2:17.0
0,2,2:17.0
1,2,2:17.0
-2,0,3:17.0
-1,0,3:17.0
0,0,3:17.0
-2,1,3:17.0
-1,1,3:17.0
-1,2,3:17.0
0,2,3:17.0
-1,0,4:17.0
-2,1,4:17.0
-1,1,4:17.0
-1,2,4:17.0
-1,1,5:17.0
-1,1,6:17.0
-1,1,7:17.0
-1,1,8:17.0
-1,1,9:17.0
-3,-3,10:18.0
-2,-3,10:18.0
-2,-2,10:18.0
-1,-2,10:18.0
-2,-1,10:18.0
-1,-1,10:18.0
0,-1,10:18.0
-5,0,10:18.0
-4,0,10:18.0
-3,0,10:18.0
-2,0,10:18.0
-1,0,10:18.0
0,0,10:18.0
1,0,10:18.0
-4,1,10:18.0
-3,1,10:18.0
-2,1,10:18.0
-1,1,10:17.0
0,1,10:18.0
1,1,10:18.0
2,1,10:18.0
-3,2,10:18.0
-2,2,10:18.0
-1,2,10:18.0
0,2,10:18.0
1,2,10:18.0
2,2,10:18.0
3,2,10:18.0
-3,3,10:18.0
-2,3,10:18.0
-1,3,10:18.0
0,3,10:18.0
1,3,10:18.0
-4,4,10:18.0
-3,4,10:18.0
-1,4,10:18.0
0,4,10:18.0
1,4,10:18.0
0,5,10:18.0
-3,-5,11:18.0
-2,-5,11:18.0
-4,-4,11:18.0
-3,-4,11:18.0
-2,-4,11:18.0
-1,-4,11:18.0
-4,-3,11:18.0
-3,-3,11:18.0
-2,-3,11:17.0
-1,-3,11:18.0
0,-3,11:18.0
3,-3,11:18.0
-6,-2,11:18.0
-5,-2,11:18.0
-4,-2,11:18.0
-3,-2,11:18.0
-2,-2,11:17.0
-1,-2,11:17.0
0,-2,11:18.0
1,-2,11:18.0
2,-2,11:18.0
3,-2,11:18.0
4,-2,11:18.0
-5,-1,11:18.0
-4,-1,11:18.0
-3,-1,11:18.0
-2,-1,11:18.0
-1,-1,11:17.0
0,-1,11:18.0
1,-1,11:18.0
2,-1,11:18.0
3,-1,11:18.0
4,-1,11:18.0
-6,0,11:18.0
-5,0,11:18.0
-4,0,11:17.0
-3,0,11:17.0
-2,0,11:18.0
-1,0,11:17.0
0,0,11:18.0
1,0,11:17.0
2,0,11:17.0
3,0,11:18.0
-6,1,11:18.0
-5,1,11:18.0
-4,1,11:18.0
-3,1,11:17.0
-2,1,11:17.0
-1,1,11:17.0
0,1,11:17.0
1,1,11:17.0
2,1,11:18.0
3,1,11:18.0
4,1,11:18.0
-4,2,11:18.0
-3,2,11:18.0
-2,2,11:18.0
-1,2,11:17.0
0,2,11:18.0
1,2,11:18.0
2,2,11:18.0
3,2,11:18.0
4,2,11:18.0
-5,3,11:18.0
-4,3,11:18.0
-3,3,11:17.0
-2,3,11:17.0
-1,3,11:17.0
0,3,11:17.0
1,3,11:18.0
2,3,11:18.0
3,3,11:18.0
4,3,11:18.0
-5,4,11:18.0
-4,4,11:18.0
-3,4,11:17.0
-2,4,11:18.0
-1,4,11:18.0
0,4,11:17.0
1,4,11:17.0
2,4,11:18.0
3,4,11:18.0
-6,5,11:18.0
-5,5,11:18.0
-4,5,11:18.0
-3,5,11:18.0
-2,5,11:18.0
-1,5,11:18.0
0,5,11:18.0
1,5,11:18.0
2,5,11:18.0
-3,6,11:18.0
0,6,11:18.0
1,6,11:18.0
-2,-3,12:18.0
-4,-2,12:18.0
-3,-2,12:18.0
-2,-2,12:18.0
-1,-2,12:18.0
0,-2,12:18.0
-4,-1,12:18.0
-3,-1,12:18.0
-2,-1,12:18.0
-1,-1,12:18.0
0,-1,12:18.0
1,-1,12:18.0
2,-1,12:18.0
3,-1,12:18.0
-4,0,12:18.0
-3,0,12:18.0
-2,0,12:18.0
-1,0,12:18.0
0,0,12:18.0
1,0,12:18.0
2,0,12:18.0
-3,1,12:18.0
-2,1,12:18.0
-1,1,12:18.0
0,1,12:18.0
1,1,12:18.0
2,1,12:18.0
-3,2,12:18.0
-2,2,12:18.0
-1,2,12:18.0
0,2,12:18.0
1,2,12:18.0
2,2,12:18.0
3,2,12:18.0
-4,3,12:18.0
-3,3,12:18.0
-2,3,12:18.0
-1,3,12:18.0
0,3,12:18.0
1,3,12:18.0
2,3,12:18.0
-3,4,12:18.0
-2,4,12:18.0
-1,4,12:18.0
1,4,12:18.0
-3,-1,13:18.0
-3,0,13:18.0
-2,0,13:18.0
0,0,13:18.0
1,0,13:18.0
-2,1,13:18.0
-1,1,13:18.0
0,1,13:18.0
-2,2,13:18.0
-1,2,13:18.0
0,2,13:18.0
1,2,13:18.0
-2,3,13:18.0
-1,3,13:18.0
1,3,13:18.0

