[META]
version=2.0
spawnOnBlockType=8,9,2
spawnSunlight=True
spawnDarkness=True
spawnWater=True
spawnLava=False
underFill=False
randomRotation=True
dig=True
tree=True
branch=False
needsFoundation=False
rarity=100
collisionPercentage=50
spawnElevationMin=49
spawnElevationMax=54
spawnInBiome=Custom
[DATA]
0,-2,-5:17.0
-3,-1,-5:17.0
0,-1,-5:17.0
1,-1,-5:17.0
-4,0,-5:17.0
-3,0,-5:17.0
-5,2,-5:17.0
-4,2,-5:17.0
1,2,-5:17.0
2,2,-5:17.0
-4,3,-5:17.0
1,3,-5:17.0
-2,4,-5:17.0
-1,4,-5:17.0
-1,5,-5:17.0
0,-2,-4:17.0
-3,-1,-4:17.0
0,-1,-4:17.0
1,-1,-4:17.0
-4,0,-4:17.0
-3,0,-4:17.0
-5,2,-4:17.0
-4,2,-4:17.0
1,2,-4:17.0
2,2,-4:17.0
-4,3,-4:17.0
1,3,-4:17.0
-2,4,-4:17.0
-1,4,-4:17.0
-1,5,-4:17.0
0,-2,-3:17.0
-3,-1,-3:17.0
0,-1,-3:17.0
1,-1,-3:17.0
-4,0,-3:17.0
-3,0,-3:17.0
-5,2,-3:17.0
-4,2,-3:17.0
1,2,-3:17.0
2,2,-3:17.0
-4,3,-3:17.0
1,3,-3:17.0
-2,4,-3:17.0
-1,4,-3:17.0
-1,5,-3:17.0
0,-1,-2:17.0
-3,0,-2:17.0
0,0,-2:17.0
-4,2,-2:17.0
1,2,-2:17.0
-1,4,-2:17.0
0,-1,-1:17.0
-3,0,-1:17.0
0,0,-1:17.0
-4,2,-1:17.0
1,2,-1:17.0
-1,4,-1:17.0
-3,0,0:17.0
-2,0,0:17.0
0,0,0:17.0
-3,2,0:17.0
0,2,0:17.0
1,2,0:17.0
-1,4,0:17.0
-2,0,1:17.0
0,0,1:17.0
-2,1,1:17.0
-3,2,1:17.0
0,2,1:17.0
-1,3,1:17.0
-1,4,1:17.0
0,0,2:17.0
-2,1,2:17.0
0,1,2:17.0
-3,2,2:17.0
-2,2,2:17.0
0,2,2:17.0
-1,3,2:17.0
0,1,3:17.0
-2,2,3:17.0
-1,2,3:17.0
0,2,3:17.0
-1,3,3:17.0
-1,2,4:17.0
-1,3,4:17.0
-1,2,5:17.0
-1,2,6:17.0
-1,2,7:17.0
-1,2,8:17.0
-1,2,9:17.0
-1,2,10:17.0
1,-3,11:18.0
0,-2,11:18.0
1,-2,11:18.0
-1,-1,11:18.0
0,-1,11:18.0
1,-1,11:18.0
-5,0,11:18.0
-4,0,11:18.0
-3,0,11:18.0
-2,0,11:18.0
-1,0,11:18.0
-4,1,11:18.0
-3,1,11:18.0
-2,1,11:18.0
-1,1,11:18.0
0,1,11:18.0
-3,2,11:18.0
-2,2,11:18.0
-1,2,11:17.0
0,2,11:18.0
-2,3,11:18.0
-1,3,11:18.0
0,3,11:18.0
-2,4,11:18.0
-1,4,11:18.0
0,4,11:18.0
-1,5,11:18.0
0,5,11:18.0
0,6,11:18.0
1,6,11:18.0
0,7,11:18.0
1,7,11:18.0
1,-6,12:18.0
0,-5,12:18.0
1,-5,12:18.0
2,-5,12:18.0
-1,-4,12:18.0
0,-4,12:18.0
1,-4,12:18.0
2,-4,12:18.0
-2,-3,12:18.0
-1,-3,12:18.0
0,-3,12:18.0
1,-3,12:17.0
2,-3,12:18.0
-4,-2,12:18.0
-3,-2,12:18.0
-2,-2,12:18.0
-1,-2,12:18.0
0,-2,12:18.0
1,-2,12:17.0
2,-2,12:18.0
3,-2,12:18.0
-6,-1,12:18.0
-5,-1,12:18.0
-4,-1,12:18.0
-3,-1,12:18.0
-2,-1,12:18.0
-1,-1,12:17.0
0,-1,12:17.0
1,-1,12:17.0
2,-1,12:18.0
3,-1,12:18.0
4,-1,12:18.0
-8,0,12:18.0
-7,0,12:18.0
-6,0,12:18.0
-5,0,12:17.0
-4,0,12:17.0
-3,0,12:18.0
-2,0,12:18.0
-1,0,12:17.0
0,0,12:18.0
1,0,12:18.0
2,0,12:18.0
3,0,12:18.0
-6,1,12:18.0
-5,1,12:18.0
-4,1,12:17.0
-3,1,12:17.0
-2,1,12:18.0
-1,1,12:17.0
0,1,12:18.0
1,1,12:18.0
-5,2,12:18.0
-4,2,12:18.0
-3,2,12:17.0
-2,2,12:17.0
-1,2,12:17.0
0,2,12:18.0
1,2,12:18.0
-4,3,12:18.0
-3,3,12:18.0
-2,3,12:18.0
-1,3,12:17.0
0,3,12:18.0
1,3,12:18.0
2,3,12:18.0
-2,4,12:18.0
-1,4,12:17.0
0,4,12:17.0
1,4,12:18.0
2,4,12:18.0
3,4,12:18.0
-2,5,12:18.0
-1,5,12:18.0
0,5,12:17.0
1,5,12:18.0
2,5,12:18.0
3,5,12:18.0
-1,6,12:18.0
0,6,12:17.0
1,6,12:17.0
2,6,12:18.0
3,6,12:18.0
4,6,12:18.0
-1,7,12:18.0
0,7,12:18.0
1,7,12:17.0
2,7,12:18.0
3,7,12:18.0
0,8,12:18.0
1,8,12:18.0
2,8,12:18.0
0,9,12:18.0
1,9,12:18.0
1,10,12:18.0
1,-4,13:18.0
0,-3,13:18.0
1,-3,13:18.0
-1,-2,13:18.0
0,-2,13:18.0
1,-2,13:18.0
-1,-1,13:18.0
0,-1,13:18.0
1,-1,13:18.0
2,-1,13:18.0
-5,0,13:18.0
-4,0,13:18.0
-2,0,13:18.0
-1,0,13:18.0
0,0,13:18.0
1,0,13:18.0
-4,1,13:18.0
-3,1,13:18.0
-2,1,13:18.0
-1,1,13:18.0
-3,2,13:18.0
-2,2,13:18.0
-1,2,13:18.0
-1,3,13:18.0
0,3,13:18.0
-1,4,13:18.0
0,4,13:18.0
-1,5,13:18.0
0,5,13:18.0
1,5,13:18.0
0,6,13:18.0
1,6,13:18.0
1,7,13:18.0

