[META]
version=2.0
spawnOnBlockType=8,9,2
spawnSunlight=True
spawnDarkness=True
spawnWater=True
spawnLava=False
underFill=False
randomRotation=True
dig=True
tree=True
branch=False
needsFoundation=False
rarity=100
collisionPercentage=50
spawnElevationMin=49
spawnElevationMax=54
spawnInBiome=Custom
[DATA]
0,-2,0:17.0
-2,0,0:17.0
0,0,0:17.0
2,0,0:17.0
0,2,0:17.0
0,-1,1:17.0
-1,0,1:17.0
0,0,1:17.0
1,0,1:17.0
0,1,1:17.0
0,0,2:17.0
-1,-1,3:18.0
0,-1,3:18.0
1,-1,3:18.0
-1,0,3:18.0
0,0,3:17.0
1,0,3:18.0
-1,1,3:18.0
0,1,3:18.0
1,1,3:18.0
0,-3,4:18.0
-1,-2,4:18.0
0,-2,4:18.0
1,-2,4:18.0
-2,-1,4:18.0
-1,-1,4:18.0
0,-1,4:17.0
1,-1,4:18.0
2,-1,4:18.0
-3,0,4:18.0
-2,0,4:18.0
-1,0,4:17.0
0,0,4:17.0
1,0,4:17.0
2,0,4:18.0
3,0,4:18.0
-2,1,4:18.0
-1,1,4:18.0
0,1,4:17.0
1,1,4:18.0
2,1,4:18.0
-1,2,4:18.0
0,2,4:18.0
1,2,4:18.0
0,3,4:18.0
-1,-1,5:18.0
0,-1,5:18.0
1,-1,5:18.0
-1,0,5:18.0
0,0,5:18.0
1,0,5:18.0
-1,1,5:18.0
0,1,5:18.0
1,1,5:18.0
