[META]
version=2.0
spawnOnBlockType=8,9,2
spawnSunlight=True
spawnDarkness=True
spawnWater=True
spawnLava=False
underFill=False
randomRotation=True
dig=True
tree=True
branch=False
needsFoundation=False
rarity=100
collisionPercentage=50
spawnElevationMin=49
spawnElevationMax=54
spawnInBiome=Custom
[DATA]
-1,-3,-5:17.0
-2,-2,-5:17.0
1,-1,-5:17.0
-4,0,-5:17.0
0,0,-5:17.0
-3,1,-5:17.0
-1,-3,-4:17.0
-2,-2,-4:17.0
1,-1,-4:17.0
-4,0,-4:17.0
0,0,-4:17.0
-3,1,-4:17.0
-1,-3,-3:17.0
-2,-2,-3:17.0
1,-1,-3:17.0
-4,0,-3:17.0
0,0,-3:17.0
-3,1,-3:17.0
-1,-2,-2:17.0
0,-1,-2:17.0
-3,0,-2:17.0
-1,-2,-1:17.0
0,-1,-1:17.0
-3,0,-1:17.0
-1,-2,0:17.0
0,-1,0:17.0
-3,0,0:17.0
-1,-2,1:17.0
-1,-1,1:17.0
0,-1,1:17.0
-3,0,1:17.0
-1,-2,2:17.0
-3,-1,2:17.0
-1,-1,2:17.0
0,-1,2:17.0
-3,-1,3:17.0
-2,-1,3:17.0
-1,-1,3:17.0
-2,-1,4:17.0
-1,-1,4:17.0
-2,-1,5:17.0
-1,-1,5:17.0
-1,-1,6:17.0
-2,-2,7:18.0
-1,-2,7:18.0
0,-2,7:18.0
1,-2,7:18.0
-3,-1,7:18.0
-2,-1,7:18.0
-1,-1,7:17.0
0,-1,7:18.0
1,-1,7:18.0
-2,0,7:18.0
-1,0,7:18.0
0,0,7:18.0
-2,1,7:18.0
-1,1,7:18.0
0,1,7:18.0
-1,2,7:18.0
0,2,7:18.0
-2,-5,8:18.0
1,-5,8:18.0
-3,-4,8:18.0
-2,-4,8:18.0
-1,-4,8:18.0
0,-4,8:18.0
1,-4,8:18.0
2,-4,8:18.0
-4,-3,8:18.0
-3,-3,8:18.0
-2,-3,8:18.0
-1,-3,8:18.0
0,-3,8:18.0
1,-3,8:18.0
2,-3,8:18.0
3,-3,8:18.0
-5,-2,8:18.0
-4,-2,8:18.0
-3,-2,8:18.0
-2,-2,8:17.0
-1,-2,8:18.0
0,-2,8:18.0
1,-2,8:17.0
2,-2,8:18.0
3,-2,8:18.0
4,-2,8:18.0
-5,-1,8:18.0
-4,-1,8:18.0
-3,-1,8:18.0
-2,-1,8:17.0
-1,-1,8:17.0
0,-1,8:17.0
1,-1,8:17.0
2,-1,8:18.0
3,-1,8:18.0
4,-1,8:18.0
-4,0,8:18.0
-3,0,8:18.0
-2,0,8:18.0
-1,0,8:17.0
0,0,8:18.0
1,0,8:18.0
2,0,8:18.0
-4,1,8:18.0
-3,1,8:18.0
-2,1,8:18.0
-1,1,8:17.0
0,1,8:18.0
1,1,8:18.0
2,1,8:18.0
-4,2,8:18.0
-3,2,8:18.0
-2,2,8:18.0
-1,2,8:17.0
0,2,8:17.0
1,2,8:18.0
2,2,8:18.0
3,2,8:18.0
-3,3,8:18.0
-2,3,8:18.0
-1,3,8:18.0
0,3,8:18.0
1,3,8:18.0
2,3,8:18.0
-2,4,8:18.0
-1,4,8:18.0
0,4,8:18.0
1,4,8:18.0
-1,5,8:18.0
0,5,8:18.0
-3,-2,9:18.0
-2,-2,9:18.0
-1,-2,9:18.0
0,-2,9:18.0
1,-2,9:18.0
2,-2,9:18.0
-2,-1,9:18.0
-1,-1,9:18.0
0,-1,9:18.0
1,-1,9:18.0
-2,0,9:18.0
-1,0,9:18.0
0,0,9:18.0
1,0,9:18.0
-1,1,9:18.0
0,1,9:18.0
-1,2,9:18.0
0,2,9:18.0

