[META]
version=2.0
spawnOnBlockType=2
spawnSunlight=True
spawnDarkness=True
spawnWater=False
spawnLava=False
underFill=False
randomRotation=True
dig=True
tree=True
branch=False
needsFoundation=True
rarity=60
collisionPercentage=20
spawnElevationMin=0
spawnElevationMax=200
spawnInBiome=Custom
[DATA]
2,-2,0:17.0
2,-2,1:17.0
2,-2,2:17.0
2,-2,3:17.0
2,-2,4:17.0
2,-2,5:17.0
2,-2,6:17.0
2,-2,7:17.0
2,-2,8:17.0
1,-1,8:17.4
0,0,8:17.4
-1,1,8:17.4
2,-2,9:17.0
-4,0,9:18.0
-4,1,9:18.0
-2,1,9:17.8
-6,2,9:18.0
-5,2,9:18.0
-4,2,9:18.0
-3,2,9:18.0
-2,2,9:17.8
-7,3,9:18.0
-6,3,9:18.0
-5,3,9:18.0
-4,3,9:18.0
-3,3,9:18.0
-2,3,9:18.0
-6,4,9:18.0
-5,4,9:18.0
-4,4,9:18.0
-3,4,9:18.0
-2,4,9:18.0
-6,5,9:18.0
-4,5,9:18.0
-2,5,9:18.0
2,-2,10:17.0
-5,0,10:18.0
-4,0,10:18.0
-3,0,10:18.0
-6,1,10:18.0
-5,1,10:18.0
-4,1,10:18.0
-3,1,10:18.0
-2,1,10:18.0
-7,2,10:18.0
-6,2,10:18.0
-5,2,10:18.0
-4,2,10:18.0
-3,2,10:18.0
-2,2,10:18.0
-1,2,10:18.0
-7,3,10:18.0
-6,3,10:18.0
-5,3,10:18.0
-4,3,10:17.0
-3,3,10:17.0
-2,3,10:18.0
-1,3,10:18.0
-7,4,10:18.0
-6,4,10:18.0
-5,4,10:18.0
-4,4,10:18.0
-3,4,10:18.0
-2,4,10:18.0
-1,4,10:18.0
-6,5,10:18.0
-5,5,10:18.0
-4,5,10:18.0
-3,5,10:18.0
-2,5,10:18.0
-5,6,10:18.0
-4,6,10:18.0
-3,6,10:18.0
2,-2,11:17.0
-4,0,11:18.0
-6,1,11:18.0
-5,1,11:18.0
-4,1,11:18.0
-3,1,11:18.0
-2,1,11:18.0
-6,2,11:18.0
-5,2,11:18.0
-4,2,11:18.0
-3,2,11:18.0
-2,2,11:18.0
-7,3,11:18.0
-6,3,11:18.0
-5,3,11:18.0
-4,3,11:18.0
-3,3,11:18.0
-2,3,11:18.0
-1,3,11:18.0
-6,4,11:18.0
-5,4,11:18.0
-4,4,11:18.0
-3,4,11:18.0
-2,4,11:18.0
-6,5,11:18.0
-5,5,11:18.0
-4,5,11:18.0
-3,5,11:18.0
-2,5,11:18.0
-4,6,11:18.0
5,-8,12:18.0
4,-7,12:18.0
5,-7,12:18.0
6,-7,12:18.0
3,-6,12:18.0
4,-6,12:18.0
5,-6,12:18.0
6,-6,12:18.0
7,-6,12:18.0
4,-5,12:17.4
5,-5,12:18.0
6,-5,12:18.0
3,-4,12:17.8
5,-4,12:18.0
3,-3,12:17.8
2,-2,12:17.0
-5,1,12:18.0
-4,1,12:18.0
-3,1,12:18.0
-6,2,12:18.0
-5,2,12:18.0
-4,2,12:18.0
-3,2,12:18.0
-2,2,12:18.0
-6,3,12:18.0
-5,3,12:18.0
-4,3,12:18.0
-3,3,12:18.0
-2,3,12:18.0
-6,4,12:18.0
-5,4,12:18.0
-4,4,12:18.0
-3,4,12:18.0
-2,4,12:18.0
-5,5,12:18.0
-4,5,12:18.0
-3,5,12:18.0
4,-8,13:18.0
5,-8,13:18.0
6,-8,13:18.0
3,-7,13:18.0
4,-7,13:18.0
5,-7,13:18.0
6,-7,13:18.0
7,-7,13:18.0
3,-6,13:18.0
4,-6,13:18.0
5,-6,13:17.0
6,-6,13:18.0
7,-6,13:18.0
3,-5,13:18.0
4,-5,13:18.0
5,-5,13:18.0
6,-5,13:18.0
7,-5,13:18.0
4,-4,13:18.0
5,-4,13:18.0
6,-4,13:18.0
2,-2,13:17.0
6,-2,13:18.0
5,-1,13:18.0
6,-1,13:18.0
7,-1,13:18.0
4,0,13:18.0
5,0,13:18.0
6,0,13:18.0
7,0,13:18.0
8,0,13:18.0
5,1,13:18.0
6,1,13:18.0
7,1,13:18.0
-4,2,13:18.0
6,2,13:18.0
-5,3,13:18.0
-4,3,13:18.0
-3,3,13:18.0
-4,4,13:18.0
5,-8,14:18.0
4,-7,14:18.0
5,-7,14:18.0
6,-7,14:18.0
1,-6,14:18.0
3,-6,14:18.0
4,-6,14:18.0
5,-6,14:18.0
6,-6,14:18.0
7,-6,14:18.0
0,-5,14:18.0
1,-5,14:18.0
2,-5,14:18.0
4,-5,14:18.0
5,-5,14:18.0
6,-5,14:18.0
1,-4,14:18.0
5,-4,14:18.0
2,-2,14:17.0
5,-2,14:18.0
6,-2,14:18.0
7,-2,14:18.0
3,-1,14:17.4
4,-1,14:17.4
5,-1,14:18.0
6,-1,14:18.0
7,-1,14:18.0
8,-1,14:18.0
4,0,14:18.0
5,0,14:17.0
6,0,14:17.0
7,0,14:18.0
8,0,14:18.0
4,1,14:18.0
5,1,14:18.0
6,1,14:18.0
7,1,14:18.0
8,1,14:18.0
5,2,14:18.0
6,2,14:18.0
7,2,14:18.0
5,-7,15:18.0
0,-6,15:18.0
1,-6,15:18.0
2,-6,15:18.0
4,-6,15:18.0
5,-6,15:18.0
6,-6,15:18.0
0,-5,15:18.0
1,-5,15:17.0
2,-5,15:18.0
5,-5,15:18.0
0,-4,15:18.0
1,-4,15:18.0
2,-4,15:17.8
2,-3,15:17.8
2,-2,15:17.0
6,-2,15:18.0
1,-1,15:18.0
5,-1,15:18.0
6,-1,15:18.0
7,-1,15:18.0
0,0,15:18.0
1,0,15:18.0
2,0,15:18.0
4,0,15:18.0
5,0,15:18.0
6,0,15:18.0
7,0,15:18.0
8,0,15:18.0
1,1,15:18.0
5,1,15:18.0
6,1,15:18.0
7,1,15:18.0
6,2,15:18.0
1,-6,16:18.0
0,-5,16:18.0
1,-5,16:18.0
2,-5,16:18.0
1,-4,16:18.0
4,-4,16:18.0
3,-3,16:18.0
4,-3,16:18.0
2,-2,16:17.0
0,-1,16:18.0
1,-1,16:18.0
2,-1,16:17.8
6,-1,16:18.0
0,0,16:18.0
1,0,16:17.0
2,0,16:18.0
5,0,16:18.0
6,0,16:18.0
7,0,16:18.0
0,1,16:18.0
1,1,16:18.0
2,1,16:18.0
6,1,16:18.0
3,-4,17:18.0
4,-4,17:18.0
5,-4,17:18.0
1,-3,17:18.0
3,-3,17:18.0
4,-3,17:17.0
5,-3,17:18.0
0,-2,17:18.0
1,-2,17:18.0
2,-2,17:17.0
3,-2,17:17.4
4,-2,17:18.0
5,-2,17:18.0
1,-1,17:18.0
0,0,17:18.0
1,0,17:18.0
2,0,17:18.0
1,1,17:18.0
4,-4,18:18.0
0,-3,18:18.0
1,-3,18:18.0
2,-3,18:18.0
3,-3,18:18.0
4,-3,18:18.0
5,-3,18:18.0
0,-2,18:18.0
1,-2,18:17.0
2,-2,18:17.0
4,-2,18:18.0
0,-1,18:18.0
1,-1,18:18.0
2,-1,18:18.0
1,-4,19:18.0
2,-4,19:18.0
4,-4,19:18.0
1,-3,19:18.0
2,-3,19:18.0
3,-3,19:18.0
4,-3,19:18.0
-1,-2,19:18.0
0,-2,19:18.0
1,-2,19:18.0
2,-2,19:17.0
3,-2,19:18.0
4,-2,19:18.0
0,-1,19:18.0
1,-1,19:18.0
3,-1,19:18.0
1,0,19:18.0
2,0,19:18.0
3,0,19:18.0
2,1,19:18.0
1,-5,20:18.0
2,-5,20:18.0
3,-5,20:18.0
0,-4,20:18.0
1,-4,20:18.0
2,-4,20:18.0
3,-4,20:18.0
4,-4,20:18.0
-1,-3,20:18.0
0,-3,20:18.0
1,-3,20:18.0
2,-3,20:18.0
3,-3,20:18.0
4,-3,20:18.0
5,-3,20:18.0
-1,-2,20:18.0
0,-2,20:18.0
1,-2,20:18.0
2,-2,20:17.0
3,-2,20:18.0
4,-2,20:18.0
5,-2,20:18.0
-1,-1,20:18.0
0,-1,20:18.0
1,-1,20:18.0
2,-1,20:18.0
3,-1,20:18.0
4,-1,20:18.0
5,-1,20:18.0
0,0,20:18.0
1,0,20:18.0
2,0,20:18.0
3,0,20:18.0
4,0,20:18.0
1,1,20:18.0
2,1,20:18.0
3,1,20:18.0
2,-5,21:18.0
0,-4,21:18.0
1,-4,21:18.0
2,-4,21:18.0
3,-4,21:18.0
4,-4,21:18.0
0,-3,21:18.0
1,-3,21:18.0
2,-3,21:18.0
3,-3,21:18.0
4,-3,21:18.0
-1,-2,21:18.0
0,-2,21:18.0
1,-2,21:18.0
2,-2,21:18.0
3,-2,21:18.0
4,-2,21:18.0
5,-2,21:18.0
0,-1,21:18.0
1,-1,21:18.0
2,-1,21:18.0
3,-1,21:18.0
4,-1,21:18.0
0,0,21:18.0
1,0,21:18.0
2,0,21:18.0
3,0,21:18.0
4,0,21:18.0
2,1,21:18.0
1,-4,22:18.0
2,-4,22:18.0
3,-4,22:18.0
0,-3,22:18.0
1,-3,22:18.0
2,-3,22:18.0
3,-3,22:18.0
4,-3,22:18.0
0,-2,22:18.0
1,-2,22:18.0
2,-2,22:18.0
3,-2,22:18.0
4,-2,22:18.0
0,-1,22:18.0
1,-1,22:18.0
2,-1,22:18.0
3,-1,22:18.0
4,-1,22:18.0
1,0,22:18.0
2,0,22:18.0
3,0,22:18.0
2,-3,23:18.0
1,-2,23:18.0
2,-2,23:18.0
3,-2,23:18.0
2,-1,23:18.0
