[META]
version=2.0
spawnOnBlockType=2
spawnSunlight=True
spawnDarkness=True
spawnWater=False
spawnLava=False
underFill=False
randomRotation=True
dig=True
tree=True
branch=False
needsFoundation=True
rarity=50
collisionPercentage=20
spawnElevationMin=0
spawnElevationMax=200
spawnInBiome=Custom
[DATA]
0,1,0:17.0
-3,2,0:17.0
-2,2,0:17.0
-1,2,0:17.0
0,2,0:17.0
-2,3,0:17.0
-1,3,0:17.0
0,3,0:17.0
1,3,0:17.0
-2,4,0:17.0
-1,4,0:17.0
0,4,0:17.0
-2,5,0:17.0
-2,2,1:17.4
-1,2,1:17.0
0,2,1:17.0
-2,3,1:17.0
-1,3,1:17.0
0,3,1:17.0
-2,4,1:17.0
-1,4,1:17.0
0,4,1:17.0
2,-4,2:18.0
-1,2,2:17.0
-2,3,2:17.0
-1,3,2:17.0
0,3,2:17.0
-4,4,2:18.0
-1,4,2:17.0
2,-5,3:18.0
1,-4,3:18.0
2,-4,3:18.0
3,-4,3:18.0
-3,2,3:18.0
-1,2,3:17.0
-4,3,3:18.0
-2,3,3:17.0
-1,3,3:17.0
0,3,3:17.0
-5,4,3:18.0
-4,4,3:18.0
-1,4,3:17.0
-4,5,3:18.0
2,8,3:18.0
2,-6,4:18.0
1,-5,4:18.0
2,-5,4:18.0
3,-5,4:18.0
1,-4,4:18.0
2,-4,4:18.0
3,-4,4:18.0
2,-2,4:18.0
-1,-1,4:18.0
-4,0,4:18.0
-1,0,4:18.0
-1,1,4:18.0
3,1,4:18.0
-3,2,4:18.0
-1,2,4:17.0
-6,3,4:18.0
-4,3,4:18.0
-2,3,4:17.0
-1,3,4:17.0
0,3,4:17.0
-7,4,4:18.0
-5,4,4:18.0
-4,4,4:18.0
-1,4,4:17.0
-6,5,4:18.0
-4,5,4:18.0
3,5,4:18.0
-2,6,4:18.0
2,7,4:18.0
2,8,4:18.0
3,8,4:18.0
2,9,4:18.0
2,-6,5:18.0
1,-5,5:18.0
2,-5,5:18.0
3,-5,5:18.0
1,-4,5:18.0
2,-4,5:18.0
3,-4,5:18.0
-1,-3,5:18.0
1,-3,5:18.0
2,-3,5:18.0
3,-3,5:18.0
-5,-2,5:18.0
-1,-2,5:18.0
0,-2,5:18.0
1,-2,5:18.0
2,-2,5:18.0
-4,-1,5:18.0
-2,-1,5:18.0
-1,-1,5:17.0
0,-1,5:18.0
-5,0,5:18.0
-4,0,5:18.0
-2,0,5:18.0
-1,0,5:17.0
3,0,5:18.0
-2,1,5:18.0
-1,1,5:17.0
2,1,5:18.0
3,1,5:18.0
4,1,5:18.0
-3,2,5:18.0
-2,2,5:18.0
-1,2,5:17.0
3,2,5:18.0
-7,3,5:18.0
-6,3,5:18.0
-4,3,5:18.0
-3,3,5:18.0
-2,3,5:17.0
-1,3,5:17.0
0,3,5:17.0
-8,4,5:18.0
-7,4,5:18.0
-5,4,5:18.0
-4,4,5:18.0
-2,4,5:18.0
-1,4,5:17.0
3,4,5:18.0
-7,5,5:18.0
-6,5,5:18.0
-4,5,5:18.0
-1,5,5:18.0
0,5,5:18.0
3,5,5:18.0
4,5,5:18.0
-3,6,5:18.0
-2,6,5:18.0
-1,6,5:18.0
1,6,5:18.0
3,6,5:18.0
-4,7,5:18.0
-2,7,5:18.0
2,7,5:18.0
-3,8,5:18.0
2,8,5:18.0
3,8,5:18.0
2,9,5:18.0
2,-6,6:18.0
1,-5,6:18.0
2,-5,6:18.0
3,-5,6:18.0
-1,-4,6:18.0
1,-4,6:18.0
2,-4,6:17.0
3,-4,6:18.0
-5,-3,6:18.0
-2,-3,6:18.0
-1,-3,6:18.0
0,-3,6:18.0
1,-3,6:17.0
2,-3,6:18.0
3,-3,6:18.0
4,-3,6:18.0
-6,-2,6:18.0
-5,-2,6:18.0
-4,-2,6:18.0
-2,-2,6:18.0
-1,-2,6:18.0
0,-2,6:17.0
1,-2,6:18.0
2,-2,6:18.0
3,-2,6:18.0
-5,-1,6:18.0
-4,-1,6:18.0
-3,-1,6:18.0
-2,-1,6:18.0
-1,-1,6:17.0
0,-1,6:17.4
1,-1,6:18.0
-5,0,6:18.0
-4,0,6:18.0
3,0,6:18.0
4,0,6:18.0
-6,1,6:18.0
-3,1,6:18.0
2,1,6:18.0
3,1,6:18.0
4,1,6:18.0
-3,2,6:18.0
-1,2,6:17.0
0,2,6:18.0
1,2,6:18.0
3,2,6:18.0
4,2,6:18.0
-7,3,6:18.0
-6,3,6:18.0
-4,3,6:18.0
-3,3,6:17.4
-2,3,6:17.0
-1,3,6:17.0
0,3,6:17.0
1,3,6:18.0
-8,4,6:18.0
-7,4,6:18.0
-5,4,6:18.0
-4,4,6:17.4
-3,4,6:18.0
-2,4,6:18.0
-1,4,6:17.0
0,4,6:17.0
1,4,6:18.0
3,4,6:18.0
4,4,6:18.0
-7,5,6:18.0
-6,5,6:18.0
-4,5,6:18.0
-3,5,6:18.0
-2,5,6:18.0
-1,5,6:18.0
0,5,6:17.0
1,5,6:18.0
3,5,6:18.0
4,5,6:18.0
5,5,6:18.0
-3,6,6:18.0
-2,6,6:18.0
-1,6,6:18.0
0,6,6:18.0
1,6,6:17.0
2,6,6:18.0
3,6,6:18.0
-4,7,6:18.0
-2,7,6:18.0
0,7,6:18.0
1,7,6:18.0
2,7,6:18.0
-4,8,6:18.0
-3,8,6:18.0
-2,8,6:18.0
2,8,6:18.0
3,8,6:18.0
-3,9,6:18.0
2,9,6:18.0
2,-7,7:18.0
1,-6,7:18.0
2,-6,7:18.0
3,-6,7:18.0
-1,-5,7:18.0
1,-5,7:18.0
2,-5,7:17.0
3,-5,7:18.0
-2,-4,7:18.0
-1,-4,7:18.0
0,-4,7:18.0
1,-4,7:18.0
2,-4,7:18.0
3,-4,7:18.0
-5,-3,7:18.0
-2,-3,7:18.0
-1,-3,7:18.0
0,-3,7:18.0
1,-3,7:18.0
2,-3,7:18.0
3,-3,7:18.0
4,-3,7:18.0
5,-3,7:18.0
-6,-2,7:18.0
-5,-2,7:18.0
-4,-2,7:18.0
-3,-2,7:18.0
-2,-2,7:18.0
-1,-2,7:17.0
0,-2,7:18.0
1,-2,7:18.0
2,-2,7:18.0
3,-2,7:18.0
-5,-1,7:18.0
-4,-1,7:18.0
-3,-1,7:18.0
-1,-1,7:18.0
0,-1,7:18.0
1,-1,7:17.0
2,-1,7:18.0
-7,0,7:18.0
-5,0,7:18.0
-4,0,7:18.0
3,0,7:18.0
4,0,7:18.0
-6,1,7:18.0
-4,1,7:18.0
-3,1,7:17.0
2,1,7:18.0
3,1,7:18.0
4,1,7:18.0
5,1,7:18.0
-3,2,7:18.0
-2,2,7:17.0
-1,2,7:17.0
0,2,7:17.4
1,2,7:17.4
2,2,7:18.0
3,2,7:18.0
4,2,7:18.0
-7,3,7:18.0
-6,3,7:18.0
-5,3,7:18.0
-3,3,7:18.0
-2,3,7:17.0
-1,3,7:17.0
0,3,7:17.0
1,3,7:18.0
-8,4,7:18.0
-7,4,7:18.0
-6,4,7:17.4
-5,4,7:17.4
-4,4,7:18.0
-3,4,7:18.0
-2,4,7:17.0
-1,4,7:17.0
0,4,7:18.0
1,4,7:18.0
3,4,7:18.0
4,4,7:18.0
-7,5,7:18.0
-6,5,7:18.0
-5,5,7:18.0
-4,5,7:18.0
-3,5,7:18.0
-2,5,7:18.0
0,5,7:18.0
2,5,7:18.0
3,5,7:18.0
4,5,7:18.0
5,5,7:18.0
-6,6,7:18.0
-4,6,7:18.0
-3,6,7:18.0
-2,6,7:18.0
-1,6,7:18.0
1,6,7:18.0
2,6,7:18.0
3,6,7:18.0
4,6,7:18.0
-4,7,7:18.0
-2,7,7:18.0
-1,7,7:18.0
0,7,7:18.0
1,7,7:17.0
2,7,7:18.0
-4,8,7:18.0
-3,8,7:18.0
-2,8,7:18.0
0,8,7:18.0
1,8,7:18.0
2,8,7:17.0
3,8,7:18.0
-3,9,7:18.0
2,9,7:18.0
-1,-5,8:18.0
1,-5,8:18.0
2,-5,8:18.0
3,-5,8:18.0
-2,-4,8:18.0
-1,-4,8:18.0
0,-4,8:18.0
1,-4,8:18.0
2,-4,8:18.0
3,-4,8:18.0
4,-4,8:18.0
-5,-3,8:18.0
-3,-3,8:18.0
-2,-3,8:18.0
-1,-3,8:17.0
0,-3,8:18.0
1,-3,8:18.0
2,-3,8:18.0
3,-3,8:18.0
4,-3,8:18.0
5,-3,8:18.0
-6,-2,8:18.0
-5,-2,8:18.0
-4,-2,8:18.0
-3,-2,8:18.0
-1,-2,8:18.0
0,-2,8:18.0
1,-2,8:18.0
2,-2,8:17.0
3,-2,8:18.0
4,-2,8:18.0
-7,-1,8:18.0
-5,-1,8:18.0
-4,-1,8:18.0
-3,-1,8:18.0
1,-1,8:18.0
2,-1,8:18.0
3,-1,8:18.0
-8,0,8:18.0
-7,0,8:18.0
-6,0,8:18.0
-5,0,8:18.0
-4,0,8:17.0
3,0,8:18.0
4,0,8:18.0
-7,1,8:18.0
-6,1,8:18.0
-5,1,8:18.0
-4,1,8:18.0
2,1,8:18.0
3,1,8:17.4
4,1,8:18.0
5,1,8:18.0
-6,2,8:18.0
-5,2,8:18.0
-4,2,8:18.0
-3,2,8:18.0
-1,2,8:17.0
1,2,8:18.0
2,2,8:17.4
3,2,8:18.0
4,2,8:18.0
-7,3,8:18.0
-6,3,8:18.0
-5,3,8:18.0
-3,3,8:18.0
-2,3,8:17.0
-1,3,8:17.0
0,3,8:17.0
1,3,8:18.0
2,3,8:18.0
3,3,8:18.0
-8,4,8:18.0
-7,4,8:17.0
-6,4,8:18.0
-5,4,8:18.0
-4,4,8:18.0
-3,4,8:18.0
-2,4,8:17.0
-1,4,8:17.0
0,4,8:17.4
1,4,8:17.4
2,4,8:18.0
3,4,8:18.0
4,4,8:18.0
-7,5,8:18.0
-6,5,8:18.0
-5,5,8:18.0
-4,5,8:18.0
-3,5,8:18.0
-2,5,8:17.0
2,5,8:17.4
3,5,8:17.4
4,5,8:18.0
5,5,8:18.0
-6,6,8:18.0
-4,6,8:18.0
-3,6,8:18.0
-2,6,8:17.0
-1,6,8:18.0
2,6,8:18.0
3,6,8:18.0
4,6,8:18.0
-4,7,8:18.0
-3,7,8:17.0
-2,7,8:18.0
-1,7,8:18.0
0,7,8:18.0
1,7,8:18.0
2,7,8:18.0
-4,8,8:18.0
-3,8,8:18.0
-2,8,8:18.0
0,8,8:18.0
1,8,8:18.0
2,8,8:18.0
3,8,8:18.0
-3,9,8:18.0
1,9,8:18.0
2,9,8:18.0
-1,-5,9:18.0
2,-5,9:18.0
-2,-4,9:18.0
-1,-4,9:18.0
0,-4,9:18.0
1,-4,9:18.0
2,-4,9:18.0
3,-4,9:18.0
4,-4,9:18.0
-5,-3,9:18.0
-3,-3,9:18.0
-2,-3,9:18.0
-1,-3,9:17.0
0,-3,9:18.0
1,-3,9:18.0
2,-3,9:18.0
3,-3,9:17.0
4,-3,9:18.0
5,-3,9:18.0
-6,-2,9:18.0
-5,-2,9:17.0
-4,-2,9:18.0
-3,-2,9:18.0
-2,-2,9:18.0
-1,-2,9:18.0
0,-2,9:18.0
1,-2,9:18.0
2,-2,9:18.0
3,-2,9:18.0
4,-2,9:18.0
-7,-1,9:18.0
-5,-1,9:18.0
-4,-1,9:17.0
-3,-1,9:18.0
-2,-1,9:18.0
-1,-1,9:18.0
0,-1,9:18.0
1,-1,9:18.0
2,-1,9:18.0
3,-1,9:18.0
-8,0,9:18.0
-7,0,9:18.0
-6,0,9:18.0
-4,0,9:17.0
-3,0,9:18.0
-2,0,9:18.0
-1,0,9:18.0
2,0,9:18.0
3,0,9:18.0
4,0,9:18.0
-7,1,9:18.0
-6,1,9:18.0
-5,1,9:18.0
-4,1,9:18.0
-3,1,9:18.0
-2,1,9:18.0
-1,1,9:17.0
0,1,9:18.0
1,1,9:18.0
2,1,9:18.0
3,1,9:18.0
4,1,9:17.0
5,1,9:18.0
-6,2,9:18.0
-5,2,9:18.0
-4,2,9:18.0
-3,2,9:17.4
-2,2,9:17.4
-1,2,9:17.0
0,2,9:18.0
1,2,9:18.0
2,2,9:18.0
3,2,9:18.0
4,2,9:18.0
-7,3,9:18.0
-6,3,9:18.0
-4,3,9:18.0
-3,3,9:18.0
-2,3,9:17.0
-1,3,9:17.0
0,3,9:17.0
1,3,9:18.0
2,3,9:18.0
3,3,9:18.0
-8,4,9:18.0
-7,4,9:17.0
-6,4,9:18.0
-5,4,9:18.0
-4,4,9:18.0
-3,4,9:18.0
-2,4,9:18.0
-1,4,9:17.0
0,4,9:18.0
1,4,9:18.0
2,4,9:18.0
3,4,9:18.0
4,4,9:18.0
-7,5,9:18.0
-6,5,9:18.0
-4,5,9:18.0
-3,5,9:18.0
-2,5,9:18.0
-1,5,9:18.0
2,5,9:18.0
3,5,9:18.0
4,5,9:17.4
5,5,9:18.0
-3,6,9:18.0
-2,6,9:18.0
-1,6,9:18.0
0,6,9:18.0
2,6,9:18.0
3,6,9:18.0
4,6,9:18.0
-3,7,9:18.0
-1,7,9:18.0
0,7,9:18.0
2,7,9:18.0
-4,8,9:18.0
-3,8,9:17.0
-2,8,9:18.0
0,8,9:18.0
1,8,9:18.0
2,8,9:18.0
-3,9,9:18.0
1,9,9:18.0
-1,-5,10:18.0
2,-5,10:18.0
-2,-4,10:18.0
-1,-4,10:17.0
0,-4,10:18.0
1,-4,10:18.0
2,-4,10:17.0
3,-4,10:18.0
4,-4,10:18.0
-2,-3,10:18.0
-1,-3,10:18.0
0,-3,10:18.0
1,-3,10:18.0
2,-3,10:18.0
3,-3,10:18.0
4,-3,10:17.0
5,-3,10:18.0
-5,-2,10:18.0
-1,-2,10:18.0
0,-2,10:18.0
1,-2,10:18.0
2,-2,10:18.0
3,-2,10:18.0
4,-2,10:18.0
-7,-1,10:18.0
-4,-1,10:18.0
-1,-1,10:18.0
0,-1,10:18.0
1,-1,10:18.0
-8,0,10:18.0
-7,0,10:18.0
-6,0,10:18.0
-4,0,10:18.0
-1,0,10:18.0
0,0,10:17.0
1,0,10:18.0
2,0,10:18.0
3,0,10:18.0
4,0,10:18.0
-7,1,10:18.0
-6,1,10:17.4
-5,1,10:18.0
-4,1,10:18.0
-3,1,10:18.0
-1,1,10:18.0
0,1,10:18.0
1,1,10:18.0
2,1,10:18.0
3,1,10:18.0
4,1,10:17.0
5,1,10:18.0
-6,2,10:18.0
-5,2,10:17.4
-4,2,10:17.4
-3,2,10:18.0
-2,2,10:18.0
-1,2,10:17.0
0,2,10:18.0
1,2,10:18.0
2,2,10:18.0
3,2,10:18.0
4,2,10:18.0
-5,3,10:18.0
-4,3,10:18.0
-3,3,10:18.0
-2,3,10:17.0
-1,3,10:17.0
0,3,10:17.0
1,3,10:18.0
2,3,10:18.0
-7,4,10:18.0
-6,4,10:18.0
-4,4,10:18.0
-3,4,10:18.0
-2,4,10:18.0
-1,4,10:17.0
0,4,10:18.0
1,4,10:18.0
2,4,10:18.0
3,4,10:18.0
-3,5,10:18.0
-2,5,10:18.0
-1,5,10:17.0
0,5,10:18.0
1,5,10:18.0
2,5,10:18.0
3,5,10:18.0
4,5,10:18.0
-2,6,10:18.0
-1,6,10:18.0
0,6,10:17.0
1,6,10:18.0
2,6,10:18.0
-1,7,10:18.0
0,7,10:17.0
1,7,10:18.0
-3,8,10:18.0
0,8,10:18.0
1,8,10:18.0
2,8,10:18.0
1,9,10:18.0
-1,-4,11:18.0
0,-4,11:18.0
2,-4,11:18.0
4,-4,11:18.0
-1,-3,11:18.0
2,-3,11:18.0
3,-3,11:18.0
4,-3,11:17.0
5,-3,11:18.0
3,-2,11:18.0
4,-2,11:18.0
-7,-1,11:18.0
-6,-1,11:18.0
-8,0,11:18.0
-7,0,11:17.4
-6,0,11:18.0
-5,0,11:18.0
-3,0,11:18.0
0,0,11:18.0
3,0,11:18.0
-7,1,11:18.0
-6,1,11:18.0
-5,1,11:18.0
-4,1,11:18.0
-3,1,11:18.0
-2,1,11:18.0
-1,1,11:18.0
0,1,11:18.0
1,1,11:18.0
2,1,11:18.0
3,1,11:18.0
4,1,11:18.0
-6,2,11:18.0
-5,2,11:18.0
-4,2,11:18.0
-1,2,11:18.0
0,2,11:18.0
3,2,11:18.0
-4,3,11:18.0
-3,3,11:18.0
-2,3,11:17.0
-1,3,11:17.0
0,3,11:17.0
1,3,11:18.0
-3,4,11:18.0
-2,4,11:18.0
-1,4,11:17.0
0,4,11:18.0
2,4,11:18.0
-1,5,11:18.0
0,5,11:18.0
1,5,11:18.0
-3,6,11:18.0
0,6,11:18.0
0,7,11:18.0
1,7,11:18.0
0,8,11:18.0
1,8,11:17.0
2,8,11:18.0
1,9,11:18.0
3,-3,12:18.0
4,-3,12:18.0
-7,0,12:18.0
-6,0,12:18.0
-3,0,12:18.0
2,0,12:18.0
-6,1,12:18.0
-4,1,12:18.0
-3,1,12:18.0
-2,1,12:18.0
1,1,12:18.0
2,1,12:18.0
-4,2,12:18.0
-3,2,12:17.0
-2,2,12:18.0
-1,2,12:18.0
0,2,12:18.0
1,2,12:17.0
2,2,12:18.0
-3,3,12:18.0
-2,3,12:18.0
-1,3,12:18.0
0,3,12:18.0
1,3,12:18.0
-2,4,12:18.0
-1,4,12:18.0
1,4,12:17.0
2,4,12:18.0
-3,5,12:18.0
-2,5,12:17.0
-1,5,12:18.0
1,5,12:18.0
2,5,12:18.0
-4,6,12:18.0
-3,6,12:18.0
-2,6,12:18.0
3,6,12:18.0
-3,7,12:18.0
1,8,12:18.0
-3,0,13:18.0
2,0,13:18.0
-4,1,13:18.0
-3,1,13:18.0
-2,1,13:18.0
1,1,13:18.0
2,1,13:18.0
3,1,13:18.0
-4,2,13:18.0
-3,2,13:17.0
-2,2,13:18.0
0,2,13:18.0
1,2,13:17.0
2,2,13:18.0
-3,3,13:18.0
0,3,13:18.0
1,3,13:18.0
-2,4,13:18.0
1,4,13:18.0
2,4,13:18.0
-3,5,13:18.0
-2,5,13:17.0
-1,5,13:18.0
1,5,13:18.0
2,5,13:17.0
3,5,13:18.0
-4,6,13:18.0
-3,6,13:18.0
-2,6,13:18.0
2,6,13:18.0
3,6,13:18.0
4,6,13:18.0
-3,7,13:18.0
3,7,13:18.0
-3,0,14:18.0
2,0,14:18.0
-4,1,14:18.0
-3,1,14:17.0
-2,1,14:18.0
1,1,14:18.0
2,1,14:17.0
3,1,14:18.0
-3,2,14:18.0
1,2,14:18.0
2,2,14:18.0
2,4,14:18.0
-3,5,14:18.0
-2,5,14:18.0
1,5,14:18.0
2,5,14:17.0
3,5,14:18.0
-4,6,14:18.0
-3,6,14:17.0
-2,6,14:18.0
2,6,14:18.0
3,6,14:18.0
4,6,14:18.0
-3,7,14:18.0
3,7,14:18.0
-3,1,15:18.0
2,1,15:18.0
2,5,15:18.0
3,5,15:18.0
-3,6,15:18.0
2,6,15:18.0
3,6,15:17.0
4,6,15:18.0
3,7,15:18.0
3,6,16:18.0
-6,3,11:106.4
-7,2,11:106.8
-6,3,10:106.4
-7,2,10:106.8
-1,8,9:106.4
3,7,9:106.4
4,3,9:106.2
-7,2,9:106.8
4,-1,9:106.2
-4,-3,9:106.1
1,-5,9:106.1
0,-5,9:106.1
-1,8,8:106.4
3,7,8:106.4
-5,6,8:106.4
4,3,8:106.2
-7,2,8:106.8
4,-1,8:106.2
-6,-1,8:106.8
0,-5,8:106.1
-1,8,7:106.4
3,7,7:106.4
2,3,7:106.2
-6,-1,7:106.8
4,-4,7:106.2
0,-5,7:106.1
1,8,6:106.4
3,7,6:106.4
-1,7,6:106.4
-4,6,6:106.8
-5,5,6:106.4
2,3,6:106.2
2,-1,6:106.2
-6,-1,6:106.8
-3,-2,6:106.1
4,-4,6:106.2
0,-4,6:106.1
3,7,5:106.4
0,-3,5:106.1
4,-4,5:106.2
