[META]
version=2.0
spawnOnBlockType=2
spawnSunlight=True
spawnDarkness=True
spawnWater=False
spawnLava=False
underFill=False
randomRotation=True
dig=True
tree=True
branch=False
needsFoundation=True
rarity=60
collisionPercentage=20
spawnElevationMin=0
spawnElevationMax=200
spawnInBiome=Custom
[DATA]
0,0,0:17.0
0,0,1:17.0
0,0,2:17.0
0,0,3:17.0
0,0,4:17.0
0,0,5:17.0
0,0,6:17.0
0,0,7:17.0
0,0,8:17.0
0,0,9:17.0
0,0,10:17.0
0,0,11:17.0
-2,1,11:17.4
-1,1,11:17.4
-2,2,11:17.4
-3,3,11:17.4
0,0,12:17.0
-7,3,12:18.0
-4,3,12:17.4
-8,4,12:18.0
-7,4,12:18.0
-6,4,12:17.4
-5,4,12:17.4
-7,5,12:18.0
0,0,13:17.0
-8,3,13:18.0
-7,3,13:18.0
-6,3,13:18.0
-8,4,13:18.0
-7,4,13:17.0
-6,4,13:18.0
-5,4,13:18.0
-4,4,13:18.0
-8,5,13:18.0
-7,5,13:18.0
-6,5,13:17.4
-5,5,13:17.4
-9,6,13:18.0
-8,6,13:18.0
-7,6,13:18.0
-6,6,13:18.0
-5,6,13:18.0
-4,6,13:18.0
-3,6,13:18.0
-8,7,13:18.0
-7,7,13:18.0
-6,7,13:18.0
-5,7,13:18.0
-4,7,13:18.0
-8,8,13:18.0
-7,8,13:18.0
-6,8,13:18.0
-4,8,13:18.0
-6,9,13:18.0
0,0,14:17.0
-7,3,14:18.0
-6,3,14:18.0
-5,3,14:18.0
-8,4,14:18.0
-7,4,14:18.0
-6,4,14:18.0
-5,4,14:18.0
-4,4,14:18.0
-9,5,14:18.0
-8,5,14:18.0
-7,5,14:18.0
-6,5,14:18.0
-5,5,14:18.0
-4,5,14:18.0
-3,5,14:18.0
-9,6,14:18.0
-8,6,14:18.0
-7,6,14:18.0
-6,6,14:17.0
-5,6,14:18.0
-4,6,14:18.0
-3,6,14:18.0
-9,7,14:18.0
-8,7,14:18.0
-7,7,14:18.0
-6,7,14:18.0
-5,7,14:18.0
-4,7,14:18.0
-3,7,14:18.0
-8,8,14:18.0
-7,8,14:18.0
-6,8,14:18.0
-5,8,14:18.0
-4,8,14:18.0
-7,9,14:18.0
-6,9,14:18.0
-5,9,14:18.0
4,-8,15:18.0
3,-7,15:18.0
4,-7,15:18.0
6,-7,15:18.0
2,-6,15:18.0
4,-6,15:18.0
5,-6,15:18.0
6,-6,15:18.0
1,-5,15:18.0
3,-5,15:18.0
4,-5,15:18.0
5,-5,15:18.0
6,-5,15:18.0
7,-5,15:18.0
3,-4,15:18.0
4,-4,15:18.0
6,-4,15:18.0
2,-3,15:17.4
3,-3,15:17.4
4,-3,15:18.0
5,-3,15:18.0
6,-3,15:18.0
1,-2,15:17.8
4,-2,15:18.0
1,-1,15:17.8
0,0,15:17.0
-6,3,15:18.0
-8,4,15:18.0
-7,4,15:18.0
-6,4,15:18.0
-5,4,15:18.0
-4,4,15:18.0
-8,5,15:18.0
-7,5,15:18.0
-6,5,15:18.0
-5,5,15:18.0
-4,5,15:18.0
-9,6,15:18.0
-8,6,15:18.0
-7,6,15:18.0
-6,6,15:18.0
-5,6,15:18.0
-4,6,15:18.0
-3,6,15:18.0
-8,7,15:18.0
-7,7,15:18.0
-6,7,15:18.0
-5,7,15:18.0
-4,7,15:18.0
-8,8,15:18.0
-7,8,15:18.0
-6,8,15:18.0
-5,8,15:18.0
-4,8,15:18.0
-6,9,15:18.0
3,-8,16:18.0
4,-8,16:18.0
5,-8,16:18.0
2,-7,16:18.0
3,-7,16:18.0
4,-7,16:18.0
5,-7,16:18.0
6,-7,16:18.0
1,-6,16:18.0
2,-6,16:18.0
3,-6,16:18.0
4,-6,16:18.0
5,-6,16:18.0
6,-6,16:18.0
7,-6,16:18.0
1,-5,16:18.0
2,-5,16:18.0
3,-5,16:18.0
4,-5,16:17.0
5,-5,16:18.0
6,-5,16:18.0
7,-5,16:18.0
1,-4,16:18.0
2,-4,16:18.0
3,-4,16:17.0
4,-4,16:18.0
5,-4,16:18.0
6,-4,16:18.0
7,-4,16:18.0
2,-3,16:18.0
3,-3,16:18.0
4,-3,16:18.0
5,-3,16:18.0
6,-3,16:18.0
3,-2,16:18.0
4,-2,16:18.0
5,-2,16:18.0
0,0,16:17.0
-7,4,16:18.0
-6,4,16:18.0
-5,4,16:18.0
-8,5,16:18.0
-7,5,16:18.0
-6,5,16:18.0
-5,5,16:18.0
-4,5,16:18.0
-8,6,16:18.0
-7,6,16:18.0
-6,6,16:18.0
-5,6,16:18.0
-4,6,16:18.0
-8,7,16:18.0
-7,7,16:18.0
-6,7,16:18.0
-5,7,16:18.0
-4,7,16:18.0
-7,8,16:18.0
-6,8,16:18.0
-5,8,16:18.0
4,-8,17:18.0
2,-7,17:18.0
3,-7,17:18.0
4,-7,17:18.0
5,-7,17:18.0
6,-7,17:18.0
2,-6,17:18.0
3,-6,17:18.0
4,-6,17:18.0
5,-6,17:18.0
6,-6,17:18.0
-2,-5,17:18.0
-1,-5,17:18.0
1,-5,17:18.0
2,-5,17:18.0
3,-5,17:18.0
4,-5,17:18.0
5,-5,17:18.0
6,-5,17:18.0
7,-5,17:18.0
-3,-4,17:18.0
-2,-4,17:18.0
-1,-4,17:18.0
0,-4,17:18.0
1,-4,17:18.0
2,-4,17:18.0
3,-4,17:18.0
4,-4,17:18.0
5,-4,17:18.0
6,-4,17:18.0
-1,-3,17:18.0
0,-3,17:18.0
2,-3,17:18.0
3,-3,17:18.0
4,-3,17:18.0
5,-3,17:18.0
6,-3,17:18.0
-1,-2,17:18.0
4,-2,17:18.0
0,0,17:17.0
1,1,17:17.4
2,1,17:17.4
4,1,17:18.0
3,2,17:17.4
4,2,17:17.4
5,2,17:18.0
2,3,17:18.0
3,3,17:18.0
4,3,17:18.0
5,3,17:18.0
6,3,17:18.0
4,4,17:18.0
5,4,17:18.0
-6,5,17:18.0
4,5,17:18.0
-7,6,17:18.0
-6,6,17:18.0
-5,6,17:18.0
-6,7,17:18.0
3,-7,18:18.0
4,-7,18:18.0
5,-7,18:18.0
-2,-6,18:18.0
-1,-6,18:18.0
0,-6,18:18.0
2,-6,18:18.0
3,-6,18:18.0
4,-6,18:18.0
5,-6,18:18.0
6,-6,18:18.0
-3,-5,18:18.0
-2,-5,18:18.0
-1,-5,18:18.0
0,-5,18:18.0
1,-5,18:18.0
2,-5,18:18.0
3,-5,18:18.0
4,-5,18:18.0
5,-5,18:18.0
6,-5,18:18.0
-3,-4,18:18.0
-2,-4,18:18.0
-1,-4,18:17.0
0,-4,18:18.0
1,-4,18:18.0
2,-4,18:18.0
3,-4,18:18.0
4,-4,18:18.0
5,-4,18:18.0
6,-4,18:18.0
-3,-3,18:18.0
-2,-3,18:18.0
-1,-3,18:18.0
0,-3,18:17.8
1,-3,18:18.0
3,-3,18:18.0
4,-3,18:18.0
5,-3,18:18.0
-2,-2,18:18.0
-1,-2,18:18.0
0,-2,18:17.8
0,-1,18:17.8
0,0,18:17.0
3,1,18:18.0
4,1,18:18.0
5,1,18:18.0
-1,2,18:18.0
2,2,18:18.0
3,2,18:18.0
4,2,18:18.0
5,2,18:18.0
6,2,18:18.0
-2,3,18:18.0
-1,3,18:18.0
0,3,18:18.0
2,3,18:18.0
3,3,18:18.0
4,3,18:17.0
5,3,18:18.0
6,3,18:18.0
-1,4,18:18.0
2,4,18:18.0
3,4,18:18.0
4,4,18:18.0
5,4,18:18.0
6,4,18:18.0
3,5,18:18.0
4,5,18:18.0
5,5,18:18.0
-1,-6,19:18.0
4,-6,19:18.0
-2,-5,19:18.0
-1,-5,19:18.0
0,-5,19:18.0
3,-5,19:18.0
4,-5,19:18.0
5,-5,19:18.0
-3,-4,19:18.0
-2,-4,19:18.0
-1,-4,19:18.0
0,-4,19:18.0
1,-4,19:18.0
4,-4,19:18.0
-2,-3,19:18.0
-1,-3,19:18.0
0,-3,19:18.0
-1,-2,19:18.0
3,-2,19:18.0
2,-1,19:18.0
3,-1,19:18.0
4,-1,19:18.0
0,0,19:17.0
3,0,19:18.0
0,1,19:17.8
4,1,19:18.0
-2,2,19:18.0
-1,2,19:17.8
0,2,19:18.0
3,2,19:18.0
4,2,19:18.0
5,2,19:18.0
-2,3,19:18.0
-1,3,19:17.8
0,3,19:18.0
2,3,19:18.0
3,3,19:18.0
4,3,19:18.0
5,3,19:18.0
6,3,19:18.0
-2,4,19:18.0
-1,4,19:18.0
0,4,19:18.0
3,4,19:18.0
4,4,19:18.0
5,4,19:18.0
4,5,19:18.0
-1,-5,20:18.0
-2,-4,20:18.0
-1,-4,20:18.0
0,-4,20:18.0
-1,-3,20:18.0
-2,-2,20:18.0
2,-2,20:18.0
3,-2,20:18.0
4,-2,20:18.0
-3,-1,20:18.0
-2,-1,20:18.0
-1,-1,20:18.0
2,-1,20:18.0
3,-1,20:17.0
4,-1,20:18.0
-2,0,20:18.0
0,0,20:17.0
1,0,20:17.4
2,0,20:17.4
3,0,20:18.0
4,0,20:18.0
-1,2,20:18.0
4,2,20:18.0
-2,3,20:18.0
-1,3,20:18.0
0,3,20:18.0
3,3,20:18.0
4,3,20:18.0
5,3,20:18.0
-1,4,20:18.0
4,4,20:18.0
-3,-2,21:18.0
-2,-2,21:18.0
-1,-2,21:18.0
3,-2,21:18.0
-3,-1,21:18.0
-2,-1,21:17.0
-1,-1,21:18.0
2,-1,21:18.0
3,-1,21:18.0
4,-1,21:18.0
-3,0,21:18.0
-2,0,21:18.0
-1,0,21:17.0
0,0,21:17.0
3,0,21:18.0
-1,1,21:18.0
0,1,21:18.0
1,1,21:18.0
0,2,21:18.0
-2,-2,22:18.0
-3,-1,22:18.0
-2,-1,22:18.0
-1,-1,22:18.0
-2,0,22:18.0
-1,0,22:18.0
0,0,22:17.0
1,0,22:18.0
-1,1,22:18.0
0,1,22:17.0
1,1,22:18.0
-1,2,22:18.0
0,2,22:18.0
1,2,22:18.0
0,-3,23:18.0
-2,-2,23:18.0
-1,-2,23:18.0
0,-2,23:18.0
1,-2,23:18.0
0,-1,23:18.0
1,-1,23:18.0
-3,0,23:18.0
-2,0,23:18.0
-1,0,23:18.0
0,0,23:17.0
1,0,23:18.0
3,0,23:18.0
-2,1,23:18.0
-1,1,23:18.0
0,1,23:18.0
1,1,23:18.0
2,1,23:18.0
-1,2,23:18.0
0,2,23:18.0
2,2,23:18.0
0,3,23:18.0
-1,-3,24:18.0
0,-3,24:18.0
1,-3,24:18.0
-2,-2,24:18.0
-1,-2,24:18.0
0,-2,24:18.0
1,-2,24:18.0
2,-2,24:18.0
-3,-1,24:18.0
-2,-1,24:18.0
-1,-1,24:18.0
0,-1,24:18.0
1,-1,24:18.0
2,-1,24:18.0
3,-1,24:18.0
-3,0,24:18.0
-2,0,24:18.0
-1,0,24:18.0
0,0,24:17.0
1,0,24:18.0
2,0,24:18.0
3,0,24:18.0
-3,1,24:18.0
-2,1,24:18.0
-1,1,24:18.0
0,1,24:18.0
1,1,24:18.0
2,1,24:18.0
3,1,24:18.0
-2,2,24:18.0
-1,2,24:18.0
0,2,24:18.0
1,2,24:18.0
2,2,24:18.0
-1,3,24:18.0
0,3,24:18.0
1,3,24:18.0
0,-3,25:18.0
-2,-2,25:18.0
-1,-2,25:18.0
0,-2,25:18.0
1,-2,25:18.0
2,-2,25:18.0
-2,-1,25:18.0
-1,-1,25:18.0
0,-1,25:18.0
1,-1,25:18.0
2,-1,25:18.0
-3,0,25:18.0
-2,0,25:18.0
-1,0,25:18.0
0,0,25:18.0
1,0,25:18.0
2,0,25:18.0
3,0,25:18.0
-2,1,25:18.0
-1,1,25:18.0
0,1,25:18.0
1,1,25:18.0
2,1,25:18.0
-2,2,25:18.0
-1,2,25:18.0
0,2,25:18.0
1,2,25:18.0
2,2,25:18.0
0,3,25:18.0
-1,-2,26:18.0
0,-2,26:18.0
1,-2,26:18.0
-2,-1,26:18.0
-1,-1,26:18.0
0,-1,26:18.0
1,-1,26:18.0
2,-1,26:18.0
-2,0,26:18.0
-1,0,26:18.0
0,0,26:18.0
1,0,26:18.0
2,0,26:18.0
-2,1,26:18.0
-1,1,26:18.0
0,1,26:18.0
1,1,26:18.0
2,1,26:18.0
-1,2,26:18.0
0,2,26:18.0
1,2,26:18.0
0,-1,27:18.0
-1,0,27:18.0
0,0,27:18.0
1,0,27:18.0
0,1,27:18.0
