[META]
version=2.0
spawnOnBlockType=2
spawnSunlight=True
spawnDarkness=True
spawnWater=False
spawnLava=False
underFill=False
randomRotation=True
dig=True
tree=True
branch=False
needsFoundation=True
rarity=60
collisionPercentage=20
spawnElevationMin=0
spawnElevationMax=200
spawnInBiome=Custom
[DATA]
0,0,0:17.0
0,0,1:17.0
0,0,2:17.0
0,0,3:17.0
0,0,4:17.0
0,0,5:17.0
-4,0,6:18.0
-1,0,6:17.4
0,0,6:17.0
1,0,6:17.4
-5,1,6:18.0
-4,1,6:18.0
-3,1,6:17.4
-2,1,6:17.4
2,1,6:17.4
3,1,6:17.4
-5,2,6:18.0
-4,2,6:17.8
-3,2,6:18.0
-5,3,6:18.0
-3,3,6:18.0
-4,4,6:18.0
-3,-5,7:18.0
-4,-4,7:18.0
-3,-4,7:17.8
-2,-4,7:18.0
-3,-3,7:18.0
-2,-3,7:17.8
-2,-2,7:17.8
-1,-1,7:17.8
-3,0,7:18.0
0,0,7:17.0
4,0,7:18.0
-4,1,7:18.0
-3,1,7:18.0
0,1,7:17.8
4,1,7:17.4
5,1,7:18.0
-4,2,7:18.0
-3,2,7:18.0
0,2,7:17.8
4,2,7:18.0
-4,3,7:18.0
0,3,7:17.8
0,4,7:18.0
1,4,7:18.0
-4,-5,8:18.0
-3,-5,8:18.0
-2,-5,8:18.0
-4,-4,8:18.0
-3,-4,8:18.0
-2,-4,8:18.0
1,-4,8:18.0
2,-4,8:18.0
3,-4,8:18.0
-4,-3,8:18.0
-3,-3,8:18.0
-2,-3,8:18.0
1,-3,8:18.0
2,-3,8:17.8
3,-3,8:18.0
2,-2,8:17.8
1,-1,8:17.8
0,0,8:17.0
4,0,8:18.0
5,0,8:18.0
3,1,8:18.0
4,1,8:18.0
5,1,8:18.0
4,2,8:18.0
5,2,8:18.0
1,3,8:18.0
0,4,8:18.0
1,4,8:17.0
2,4,8:18.0
0,5,8:18.0
1,5,8:18.0
2,5,8:18.0
-3,-5,9:18.0
-4,-4,9:18.0
-3,-4,9:18.0
-2,-4,9:18.0
2,-4,9:18.0
-3,-3,9:18.0
0,-3,9:18.0
1,-3,9:18.0
2,-3,9:18.0
3,-3,9:18.0
4,-3,9:18.0
1,-2,9:18.0
2,-2,9:18.0
3,-2,9:18.0
0,0,9:17.0
-1,1,9:17.8
4,1,9:18.0
-2,2,9:17.8
-3,3,9:18.0
-2,3,9:17.8
-1,3,9:18.0
1,3,9:18.0
-3,4,9:18.0
-2,4,9:18.0
0,4,9:18.0
1,4,9:18.0
2,4,9:18.0
1,5,9:18.0
2,-3,10:18.0
-1,-2,10:18.0
2,-2,10:18.0
-2,-1,10:18.0
-1,-1,10:17.8
0,-1,10:18.0
-1,0,10:18.0
0,0,10:17.0
1,1,10:18.0
-2,2,10:18.0
-3,3,10:18.0
-2,3,10:18.0
-1,3,10:18.0
-2,4,10:18.0
-1,-1,11:18.0
0,0,11:18.0
1,0,11:18.0
2,0,11:18.0
0,1,11:18.0
1,1,11:17.8
2,1,11:18.0
0,2,11:18.0
1,2,11:18.0
2,2,11:18.0
1,0,12:18.0
0,1,12:18.0
1,1,12:18.0
2,1,12:18.0
1,2,12:18.0
