[META]
version=2.0
spawnOnBlockType=2
spawnSunlight=True
spawnDarkness=True
spawnWater=False
spawnLava=False
underFill=False
randomRotation=True
dig=True
tree=True
branch=False
needsFoundation=True
rarity=60
collisionPercentage=20
spawnElevationMin=0
spawnElevationMax=200
spawnInBiome=Custom
[DATA]
2,0,0:17.0
2,0,1:17.0
2,0,2:17.0
2,0,3:17.0
2,0,4:17.0
2,0,5:17.0
2,0,6:17.0
2,0,7:17.0
4,-3,8:17.4
5,-3,8:17.4
3,-2,8:17.8
3,-1,8:17.8
2,0,8:17.0
6,-5,9:17.8
5,-4,9:17.8
-3,0,9:17.4
-2,0,9:17.4
-1,0,9:17.4
0,0,9:17.4
1,0,9:17.4
2,0,9:17.0
8,-10,10:18.0
6,-9,10:18.0
7,-9,10:18.0
8,-9,10:18.0
6,-8,10:18.0
7,-8,10:18.0
8,-8,10:18.0
9,-8,10:18.0
10,-8,10:18.0
6,-7,10:18.0
7,-7,10:17.4
8,-7,10:17.4
9,-7,10:18.0
10,-7,10:18.0
6,-6,10:17.4
7,-6,10:17.4
8,-6,10:18.0
9,-6,10:18.0
10,-6,10:18.0
7,-5,10:18.0
8,-5,10:18.0
9,-5,10:18.0
10,-5,10:18.0
-6,-3,10:18.0
-6,-2,10:18.0
-5,-2,10:18.0
-7,-1,10:18.0
-6,-1,10:18.0
-5,-1,10:17.4
-4,-1,10:18.0
-7,0,10:18.0
-6,0,10:17.4
-5,0,10:17.4
-4,0,10:17.4
2,0,10:17.0
-7,1,10:18.0
-6,1,10:18.0
-5,1,10:17.4
3,1,10:17.4
4,1,10:17.4
-6,2,10:18.0
5,2,10:17.4
6,2,10:17.4
7,-10,11:18.0
8,-10,11:18.0
9,-10,11:18.0
6,-9,11:18.0
7,-9,11:18.0
8,-9,11:18.0
9,-9,11:18.0
10,-9,11:18.0
5,-8,11:18.0
6,-8,11:18.0
7,-8,11:18.0
8,-8,11:18.0
9,-8,11:18.0
10,-8,11:18.0
11,-8,11:18.0
5,-7,11:18.0
6,-7,11:18.0
7,-7,11:17.0
8,-7,11:17.0
9,-7,11:18.0
10,-7,11:18.0
11,-7,11:18.0
5,-6,11:18.0
6,-6,11:18.0
7,-6,11:18.0
8,-6,11:18.0
9,-6,11:18.0
10,-6,11:18.0
11,-6,11:18.0
6,-5,11:18.0
7,-5,11:18.0
8,-5,11:18.0
9,-5,11:18.0
10,-5,11:18.0
1,-4,11:17.8
7,-4,11:18.0
8,-4,11:18.0
9,-4,11:18.0
-7,-3,11:18.0
-6,-3,11:18.0
-5,-3,11:18.0
1,-3,11:17.8
-8,-2,11:18.0
-7,-2,11:18.0
-6,-2,11:18.0
-5,-2,11:18.0
-4,-2,11:18.0
2,-2,11:17.8
-9,-1,11:18.0
-8,-1,11:18.0
-7,-1,11:18.0
-6,-1,11:17.0
-5,-1,11:18.0
-4,-1,11:18.0
2,-1,11:17.8
-9,0,11:18.0
-8,0,11:18.0
-7,0,11:18.0
-6,0,11:18.0
-5,0,11:17.0
-4,0,11:18.0
2,0,11:17.0
-9,1,11:18.0
-8,1,11:18.0
-7,1,11:18.0
-6,1,11:17.0
-5,1,11:17.0
-4,1,11:18.0
-7,2,11:18.0
-6,2,11:18.0
-5,2,11:18.0
-9,3,11:18.0
-7,3,11:18.0
-5,3,11:18.0
6,3,11:17.4
7,3,11:17.4
-7,4,11:18.0
0,-11,12:18.0
-2,-10,12:18.0
-1,-10,12:18.0
0,-10,12:18.0
2,-10,12:18.0
8,-10,12:18.0
-2,-9,12:18.0
-1,-9,12:18.0
0,-9,12:18.0
1,-9,12:18.0
6,-9,12:18.0
7,-9,12:18.0
8,-9,12:18.0
9,-9,12:18.0
10,-9,12:18.0
-3,-8,12:18.0
-2,-8,12:18.0
-1,-8,12:18.0
0,-8,12:18.0
1,-8,12:18.0
2,-8,12:18.0
3,-8,12:18.0
6,-8,12:18.0
7,-8,12:18.0
8,-8,12:18.0
9,-8,12:18.0
10,-8,12:18.0
-2,-7,12:18.0
-1,-7,12:17.8
0,-7,12:17.8
1,-7,12:17.8
2,-7,12:18.0
5,-7,12:18.0
6,-7,12:18.0
7,-7,12:18.0
8,-7,12:17.0
9,-7,12:18.0
10,-7,12:18.0
11,-7,12:18.0
-2,-6,12:18.0
-1,-6,12:18.0
0,-6,12:18.0
1,-6,12:17.8
2,-6,12:18.0
6,-6,12:18.0
7,-6,12:18.0
8,-6,12:18.0
9,-6,12:18.0
10,-6,12:18.0
0,-5,12:18.0
1,-5,12:17.8
6,-5,12:18.0
7,-5,12:18.0
8,-5,12:18.0
9,-5,12:18.0
10,-5,12:18.0
8,-4,12:18.0
-6,-3,12:18.0
-8,-2,12:18.0
-7,-2,12:18.0
-6,-2,12:18.0
-5,-2,12:18.0
-9,-1,12:18.0
-8,-1,12:18.0
-7,-1,12:18.0
-6,-1,12:18.0
-5,-1,12:18.0
-4,-1,12:18.0
-10,0,12:18.0
-9,0,12:18.0
-8,0,12:18.0
-7,0,12:18.0
-6,0,12:18.0
-5,0,12:18.0
-4,0,12:18.0
2,0,12:17.0
-10,1,12:18.0
-9,1,12:18.0
-8,1,12:18.0
-7,1,12:17.0
-6,1,12:18.0
-5,1,12:18.0
-4,1,12:18.0
2,1,12:17.8
-10,2,12:18.0
-9,2,12:18.0
-8,2,12:18.0
-7,2,12:18.0
-6,2,12:18.0
-5,2,12:18.0
-4,2,12:18.0
1,2,12:17.8
-9,3,12:18.0
-8,3,12:18.0
-7,3,12:18.0
-6,3,12:18.0
-5,3,12:18.0
1,3,12:17.8
8,3,12:18.0
9,3,12:18.0
10,3,12:18.0
11,3,12:18.0
-8,4,12:18.0
-7,4,12:18.0
-6,4,12:18.0
0,4,12:17.8
7,4,12:18.0
8,4,12:17.4
9,4,12:17.4
10,4,12:17.4
11,4,12:18.0
0,5,12:17.8
6,5,12:18.0
7,5,12:18.0
8,5,12:18.0
9,5,12:18.0
10,5,12:18.0
11,5,12:18.0
12,5,12:18.0
0,6,12:18.0
8,6,12:18.0
9,6,12:18.0
10,6,12:18.0
11,6,12:18.0
0,7,12:18.0
7,7,12:18.0
8,7,12:18.0
9,7,12:18.0
10,7,12:18.0
9,8,12:18.0
-1,-11,13:18.0
0,-11,13:18.0
1,-11,13:18.0
-2,-10,13:18.0
-1,-10,13:18.0
0,-10,13:18.0
1,-10,13:18.0
2,-10,13:18.0
-3,-9,13:18.0
-2,-9,13:18.0
-1,-9,13:18.0
0,-9,13:18.0
1,-9,13:18.0
2,-9,13:18.0
3,-9,13:18.0
7,-9,13:18.0
8,-9,13:18.0
9,-9,13:18.0
-3,-8,13:18.0
-2,-8,13:18.0
-1,-8,13:18.0
0,-8,13:17.0
1,-8,13:18.0
2,-8,13:18.0
3,-8,13:18.0
6,-8,13:18.0
7,-8,13:18.0
8,-8,13:18.0
9,-8,13:18.0
10,-8,13:18.0
-3,-7,13:18.0
-2,-7,13:18.0
-1,-7,13:18.0
0,-7,13:18.0
1,-7,13:17.0
2,-7,13:18.0
3,-7,13:18.0
6,-7,13:18.0
7,-7,13:18.0
8,-7,13:18.0
9,-7,13:18.0
10,-7,13:18.0
-2,-6,13:18.0
-1,-6,13:18.0
0,-6,13:18.0
1,-6,13:18.0
2,-6,13:18.0
6,-6,13:18.0
7,-6,13:18.0
8,-6,13:18.0
9,-6,13:18.0
10,-6,13:18.0
-1,-5,13:18.0
0,-5,13:18.0
1,-5,13:18.0
7,-5,13:18.0
8,-5,13:18.0
9,-5,13:18.0
-7,-2,13:18.0
-6,-2,13:18.0
-9,-1,13:18.0
-8,-1,13:18.0
-7,-1,13:18.0
-6,-1,13:18.0
-5,-1,13:18.0
4,-1,13:17.4
5,-1,13:17.4
6,-1,13:17.4
-9,0,13:18.0
-8,0,13:18.0
-7,0,13:18.0
-6,0,13:18.0
-5,0,13:18.0
2,0,13:17.0
3,0,13:17.4
-10,1,13:18.0
-9,1,13:18.0
-8,1,13:18.0
-7,1,13:18.0
-6,1,13:18.0
-5,1,13:18.0
-4,1,13:18.0
-9,2,13:18.0
-8,2,13:18.0
-7,2,13:18.0
-6,2,13:18.0
-5,2,13:18.0
8,2,13:18.0
9,2,13:18.0
10,2,13:18.0
-9,3,13:18.0
-8,3,13:18.0
-7,3,13:18.0
-6,3,13:18.0
-5,3,13:18.0
-1,3,13:18.0
7,3,13:18.0
8,3,13:18.0
9,3,13:18.0
10,3,13:18.0
11,3,13:18.0
-7,4,13:18.0
-1,4,13:18.0
0,4,13:18.0
1,4,13:18.0
6,4,13:18.0
7,4,13:18.0
8,4,13:18.0
9,4,13:18.0
10,4,13:18.0
11,4,13:18.0
12,4,13:18.0
-3,5,13:18.0
-2,5,13:18.0
-1,5,13:17.8
0,5,13:17.8
1,5,13:18.0
6,5,13:18.0
7,5,13:18.0
8,5,13:18.0
9,5,13:17.0
10,5,13:18.0
11,5,13:18.0
12,5,13:18.0
-4,6,13:18.0
-3,6,13:18.0
-2,6,13:18.0
-1,6,13:18.0
0,6,13:17.0
1,6,13:18.0
2,6,13:18.0
6,6,13:18.0
7,6,13:18.0
8,6,13:18.0
9,6,13:18.0
10,6,13:18.0
11,6,13:18.0
12,6,13:18.0
-2,7,13:18.0
-1,7,13:18.0
0,7,13:18.0
1,7,13:18.0
7,7,13:18.0
8,7,13:18.0
9,7,13:18.0
10,7,13:18.0
11,7,13:18.0
-1,8,13:18.0
0,8,13:18.0
1,8,13:18.0
8,8,13:18.0
9,8,13:18.0
10,8,13:18.0
-1,9,13:18.0
0,-11,14:18.0
-2,-10,14:18.0
-1,-10,14:18.0
0,-10,14:18.0
1,-10,14:18.0
2,-10,14:18.0
-2,-9,14:18.0
-1,-9,14:18.0
0,-9,14:18.0
1,-9,14:18.0
2,-9,14:18.0
-3,-8,14:18.0
-2,-8,14:18.0
-1,-8,14:18.0
0,-8,14:18.0
1,-8,14:18.0
2,-8,14:18.0
3,-8,14:18.0
8,-8,14:18.0
-2,-7,14:18.0
-1,-7,14:18.0
0,-7,14:18.0
1,-7,14:18.0
2,-7,14:18.0
7,-7,14:18.0
8,-7,14:18.0
9,-7,14:18.0
-2,-6,14:18.0
-1,-6,14:18.0
0,-6,14:18.0
1,-6,14:18.0
2,-6,14:18.0
8,-6,14:18.0
-4,-5,14:18.0
0,-5,14:18.0
9,-5,14:18.0
-6,-4,14:18.0
-4,-4,14:18.0
-3,-4,14:18.0
7,-4,14:18.0
8,-4,14:18.0
9,-4,14:18.0
10,-4,14:18.0
11,-4,14:18.0
-6,-3,14:18.0
-5,-3,14:18.0
-4,-3,14:18.0
-3,-3,14:18.0
-2,-3,14:18.0
7,-3,14:18.0
8,-3,14:18.0
9,-3,14:18.0
10,-3,14:18.0
11,-3,14:18.0
-7,-2,14:18.0
-6,-2,14:18.0
-5,-2,14:18.0
-4,-2,14:18.0
-3,-2,14:18.0
-2,-2,14:18.0
-1,-2,14:18.0
6,-2,14:18.0
7,-2,14:18.0
8,-2,14:17.4
9,-2,14:17.4
10,-2,14:18.0
11,-2,14:18.0
12,-2,14:18.0
-8,-1,14:18.0
-7,-1,14:18.0
-6,-1,14:18.0
-5,-1,14:18.0
-4,-1,14:18.0
-3,-1,14:18.0
-2,-1,14:17.4
-1,-1,14:17.4
0,-1,14:17.4
7,-1,14:17.4
8,-1,14:18.0
9,-1,14:18.0
10,-1,14:18.0
-9,0,14:18.0
-8,0,14:18.0
-7,0,14:18.0
-6,0,14:18.0
-5,0,14:18.0
-4,0,14:18.0
-3,0,14:18.0
1,0,14:17.4
2,0,14:17.0
7,0,14:18.0
8,0,14:18.0
9,0,14:18.0
10,0,14:18.0
11,0,14:18.0
-9,1,14:18.0
-8,1,14:18.0
-7,1,14:18.0
-6,1,14:18.0
-5,1,14:18.0
-4,1,14:18.0
-9,2,14:18.0
-8,2,14:18.0
-7,2,14:18.0
-6,2,14:18.0
-5,2,14:18.0
9,2,14:18.0
-8,3,14:18.0
-7,3,14:18.0
-6,3,14:18.0
-2,3,14:18.0
-1,3,14:18.0
0,3,14:18.0
7,3,14:18.0
8,3,14:18.0
9,3,14:18.0
10,3,14:18.0
11,3,14:18.0
-3,4,14:18.0
-2,4,14:18.0
-1,4,14:18.0
0,4,14:18.0
1,4,14:18.0
7,4,14:18.0
8,4,14:18.0
9,4,14:18.0
10,4,14:18.0
11,4,14:18.0
-4,5,14:18.0
-3,5,14:18.0
-2,5,14:18.0
-1,5,14:18.0
0,5,14:18.0
1,5,14:18.0
2,5,14:18.0
6,5,14:18.0
7,5,14:18.0
8,5,14:18.0
9,5,14:18.0
10,5,14:18.0
11,5,14:18.0
12,5,14:18.0
-4,6,14:18.0
-3,6,14:18.0
-2,6,14:18.0
-1,6,14:17.0
0,6,14:18.0
1,6,14:18.0
2,6,14:18.0
7,6,14:18.0
8,6,14:18.0
9,6,14:18.0
10,6,14:18.0
11,6,14:18.0
-4,7,14:18.0
-3,7,14:18.0
-2,7,14:18.0
-1,7,14:18.0
0,7,14:18.0
1,7,14:18.0
2,7,14:18.0
7,7,14:18.0
8,7,14:18.0
9,7,14:18.0
10,7,14:18.0
11,7,14:18.0
-3,8,14:18.0
-2,8,14:18.0
-1,8,14:18.0
0,8,14:18.0
1,8,14:18.0
9,8,14:18.0
-2,9,14:18.0
-1,9,14:18.0
0,9,14:18.0
-1,-10,15:18.0
0,-10,15:18.0
1,-10,15:18.0
-2,-9,15:18.0
-1,-9,15:18.0
0,-9,15:18.0
1,-9,15:18.0
2,-9,15:18.0
-2,-8,15:18.0
-1,-8,15:18.0
0,-8,15:18.0
1,-8,15:18.0
2,-8,15:18.0
-2,-7,15:18.0
-1,-7,15:18.0
0,-7,15:18.0
1,-7,15:18.0
2,-7,15:18.0
-1,-6,15:18.0
0,-6,15:18.0
1,-6,15:18.0
3,-6,15:18.0
-5,-5,15:18.0
-4,-5,15:18.0
-3,-5,15:18.0
2,-5,15:18.0
3,-5,15:18.0
4,-5,15:18.0
8,-5,15:18.0
9,-5,15:18.0
10,-5,15:18.0
-6,-4,15:18.0
-5,-4,15:18.0
-4,-4,15:18.0
-3,-4,15:18.0
-2,-4,15:18.0
1,-4,15:18.0
2,-4,15:18.0
3,-4,15:18.0
4,-4,15:18.0
5,-4,15:18.0
7,-4,15:18.0
8,-4,15:18.0
9,-4,15:18.0
10,-4,15:18.0
11,-4,15:18.0
-7,-3,15:18.0
-6,-3,15:18.0
-5,-3,15:18.0
-4,-3,15:18.0
-3,-3,15:18.0
-2,-3,15:18.0
-1,-3,15:18.0
2,-3,15:18.0
3,-3,15:18.0
4,-3,15:18.0
6,-3,15:18.0
7,-3,15:18.0
8,-3,15:18.0
9,-3,15:18.0
10,-3,15:18.0
11,-3,15:18.0
12,-3,15:18.0
-7,-2,15:18.0
-6,-2,15:18.0
-5,-2,15:18.0
-4,-2,15:17.0
-3,-2,15:17.0
-2,-2,15:18.0
-1,-2,15:18.0
3,-2,15:18.0
6,-2,15:18.0
7,-2,15:18.0
8,-2,15:18.0
9,-2,15:17.0
10,-2,15:18.0
11,-2,15:18.0
12,-2,15:18.0
-7,-1,15:18.0
-6,-1,15:18.0
-5,-1,15:18.0
-4,-1,15:18.0
-3,-1,15:18.0
-2,-1,15:18.0
-1,-1,15:18.0
6,-1,15:18.0
7,-1,15:18.0
8,-1,15:18.0
9,-1,15:18.0
10,-1,15:18.0
11,-1,15:18.0
12,-1,15:18.0
-7,0,15:18.0
-6,0,15:18.0
-5,0,15:18.0
-4,0,15:18.0
-3,0,15:18.0
-2,0,15:18.0
2,0,15:17.0
7,0,15:18.0
8,0,15:18.0
9,0,15:18.0
10,0,15:18.0
11,0,15:18.0
-8,1,15:18.0
-7,1,15:18.0
-6,1,15:18.0
-5,1,15:18.0
-4,1,15:18.0
-3,1,15:18.0
2,1,15:17.8
8,1,15:18.0
9,1,15:18.0
10,1,15:18.0
-7,2,15:18.0
3,2,15:17.8
-1,3,15:18.0
3,3,15:17.8
4,3,15:18.0
8,3,15:18.0
9,3,15:18.0
10,3,15:18.0
-3,4,15:18.0
-2,4,15:18.0
-1,4,15:18.0
0,4,15:18.0
1,4,15:18.0
3,4,15:18.0
4,4,15:17.8
5,4,15:18.0
7,4,15:18.0
8,4,15:18.0
9,4,15:18.0
10,4,15:18.0
11,4,15:18.0
-3,5,15:18.0
-2,5,15:18.0
-1,5,15:18.0
0,5,15:18.0
1,5,15:18.0
2,5,15:18.0
3,5,15:18.0
4,5,15:18.0
5,5,15:18.0
6,5,15:18.0
7,5,15:18.0
8,5,15:18.0
9,5,15:18.0
10,5,15:18.0
11,5,15:18.0
-4,6,15:18.0
-3,6,15:18.0
-2,6,15:18.0
-1,6,15:18.0
0,6,15:18.0
1,6,15:18.0
2,6,15:18.0
3,6,15:18.0
4,6,15:18.0
5,6,15:18.0
7,6,15:18.0
8,6,15:18.0
9,6,15:18.0
10,6,15:18.0
11,6,15:18.0
-3,7,15:18.0
-2,7,15:18.0
-1,7,15:18.0
0,7,15:18.0
1,7,15:18.0
4,7,15:18.0
8,7,15:18.0
9,7,15:18.0
10,7,15:18.0
-3,8,15:18.0
-2,8,15:18.0
-1,8,15:18.0
0,8,15:18.0
1,8,15:18.0
-1,9,15:18.0
0,-9,16:18.0
-1,-8,16:18.0
0,-8,16:18.0
1,-8,16:18.0
0,-7,16:18.0
2,-6,16:18.0
3,-6,16:18.0
4,-6,16:18.0
-4,-5,16:18.0
1,-5,16:18.0
2,-5,16:18.0
3,-5,16:18.0
4,-5,16:18.0
5,-5,16:18.0
9,-5,16:18.0
-6,-4,16:18.0
-5,-4,16:18.0
-4,-4,16:18.0
-3,-4,16:18.0
-2,-4,16:18.0
1,-4,16:18.0
2,-4,16:18.0
3,-4,16:17.0
4,-4,16:17.0
5,-4,16:18.0
7,-4,16:18.0
8,-4,16:18.0
9,-4,16:18.0
10,-4,16:18.0
11,-4,16:18.0
-6,-3,16:18.0
-5,-3,16:18.0
-4,-3,16:18.0
-3,-3,16:18.0
-2,-3,16:18.0
1,-3,16:18.0
2,-3,16:18.0
3,-3,16:17.0
4,-3,16:18.0
5,-3,16:18.0
7,-3,16:18.0
8,-3,16:18.0
9,-3,16:18.0
10,-3,16:18.0
11,-3,16:18.0
-7,-2,16:18.0
-6,-2,16:18.0
-5,-2,16:18.0
-4,-2,16:18.0
-3,-2,16:18.0
-2,-2,16:18.0
-1,-2,16:18.0
2,-2,16:17.0
3,-2,16:18.0
4,-2,16:18.0
6,-2,16:18.0
7,-2,16:18.0
8,-2,16:18.0
9,-2,16:18.0
10,-2,16:18.0
11,-2,16:18.0
12,-2,16:18.0
-6,-1,16:18.0
-5,-1,16:18.0
-4,-1,16:18.0
-3,-1,16:18.0
-2,-1,16:18.0
2,-1,16:17.0
7,-1,16:18.0
8,-1,16:18.0
9,-1,16:18.0
10,-1,16:18.0
11,-1,16:18.0
-6,0,16:18.0
-5,0,16:18.0
-4,0,16:18.0
-3,0,16:18.0
-2,0,16:18.0
-1,0,16:18.0
2,0,16:17.0
7,0,16:18.0
8,0,16:18.0
9,0,16:18.0
10,0,16:18.0
11,0,16:18.0
-4,1,16:18.0
-3,1,16:18.0
-2,1,16:18.0
-1,1,16:18.0
0,1,16:18.0
9,1,16:18.0
-4,2,16:18.0
-3,2,16:18.0
-2,2,16:18.0
-1,2,16:18.0
0,2,16:18.0
-3,3,16:18.0
-2,3,16:18.0
-1,3,16:18.0
3,3,16:18.0
4,3,16:18.0
5,3,16:18.0
-2,4,16:18.0
-1,4,16:18.0
0,4,16:18.0
2,4,16:18.0
3,4,16:18.0
4,4,16:18.0
5,4,16:18.0
6,4,16:18.0
9,4,16:18.0
-3,5,16:18.0
-2,5,16:18.0
-1,5,16:18.0
0,5,16:18.0
1,5,16:18.0
2,5,16:18.0
3,5,16:18.0
4,5,16:17.0
5,5,16:18.0
6,5,16:18.0
8,5,16:18.0
9,5,16:18.0
10,5,16:18.0
-3,6,16:18.0
-2,6,16:18.0
-1,6,16:18.0
0,6,16:18.0
1,6,16:18.0
2,6,16:18.0
3,6,16:18.0
4,6,16:18.0
5,6,16:18.0
6,6,16:18.0
9,6,16:18.0
-3,7,16:18.0
-2,7,16:18.0
-1,7,16:18.0
0,7,16:18.0
1,7,16:18.0
3,7,16:18.0
4,7,16:18.0
5,7,16:18.0
-2,8,16:18.0
-1,8,16:18.0
0,8,16:18.0
3,-6,17:18.0
2,-5,17:18.0
3,-5,17:18.0
4,-5,17:18.0
-5,-4,17:18.0
-4,-4,17:18.0
-3,-4,17:18.0
1,-4,17:18.0
2,-4,17:18.0
3,-4,17:18.0
4,-4,17:18.0
5,-4,17:18.0
8,-4,17:18.0
9,-4,17:18.0
10,-4,17:18.0
-6,-3,17:18.0
-5,-3,17:18.0
-4,-3,17:18.0
-3,-3,17:18.0
-2,-3,17:18.0
2,-3,17:18.0
3,-3,17:18.0
4,-3,17:18.0
7,-3,17:18.0
8,-3,17:18.0
9,-3,17:18.0
10,-3,17:18.0
11,-3,17:18.0
-6,-2,17:18.0
-5,-2,17:18.0
-4,-2,17:18.0
-3,-2,17:18.0
-2,-2,17:18.0
3,-2,17:18.0
7,-2,17:18.0
8,-2,17:18.0
9,-2,17:18.0
10,-2,17:18.0
11,-2,17:18.0
-6,-1,17:18.0
-5,-1,17:18.0
-4,-1,17:18.0
-3,-1,17:18.0
-2,-1,17:18.0
5,-1,17:18.0
7,-1,17:18.0
8,-1,17:18.0
9,-1,17:18.0
10,-1,17:18.0
11,-1,17:18.0
-5,0,17:18.0
-4,0,17:18.0
-3,0,17:18.0
-2,0,17:18.0
-1,0,17:18.0
0,0,17:18.0
1,0,17:17.4
2,0,17:17.0
4,0,17:18.0
5,0,17:18.0
8,0,17:18.0
9,0,17:18.0
10,0,17:18.0
-4,1,17:18.0
-3,1,17:18.0
-2,1,17:18.0
-1,1,17:17.4
0,1,17:17.4
5,1,17:18.0
-4,2,17:18.0
-3,2,17:18.0
-2,2,17:17.0
-1,2,17:18.0
0,2,17:18.0
-4,3,17:18.0
-3,3,17:18.0
-2,3,17:18.0
-1,3,17:18.0
0,3,17:18.0
4,3,17:18.0
-3,4,17:18.0
-2,4,17:18.0
-1,4,17:18.0
3,4,17:18.0
4,4,17:18.0
5,4,17:18.0
-1,5,17:18.0
2,5,17:18.0
3,5,17:18.0
4,5,17:18.0
5,5,17:18.0
6,5,17:18.0
-2,6,17:18.0
-1,6,17:18.0
0,6,17:18.0
3,6,17:18.0
4,6,17:18.0
5,6,17:18.0
-1,7,17:18.0
4,7,17:18.0
3,-5,18:18.0
2,-4,18:18.0
3,-4,18:18.0
4,-4,18:18.0
-4,-3,18:18.0
1,-3,18:18.0
3,-3,18:18.0
9,-3,18:18.0
-5,-2,18:18.0
-4,-2,18:18.0
-3,-2,18:18.0
0,-2,18:18.0
1,-2,18:18.0
2,-2,18:18.0
8,-2,18:18.0
9,-2,18:18.0
10,-2,18:18.0
-4,-1,18:18.0
1,-1,18:18.0
4,-1,18:18.0
5,-1,18:18.0
6,-1,18:18.0
9,-1,18:18.0
-2,0,18:18.0
-1,0,18:18.0
2,0,18:17.0
3,0,18:17.4
4,0,18:17.4
5,0,18:17.4
6,0,18:18.0
-3,1,18:18.0
-2,1,18:18.0
-1,1,18:18.0
0,1,18:18.0
4,1,18:18.0
5,1,18:18.0
6,1,18:18.0
-4,2,18:18.0
-3,2,18:18.0
-2,2,18:18.0
-1,2,18:18.0
0,2,18:18.0
-3,3,18:18.0
-2,3,18:18.0
-1,3,18:18.0
-2,4,18:18.0
4,4,18:18.0
3,5,18:18.0
4,5,18:18.0
5,5,18:18.0
4,6,18:18.0
0,-3,19:18.0
1,-3,19:18.0
2,-3,19:18.0
0,-2,19:18.0
1,-2,19:17.8
2,-2,19:18.0
0,-1,19:18.0
1,-1,19:17.8
2,-1,19:18.0
5,-1,19:18.0
2,0,19:17.0
4,0,19:18.0
5,0,19:18.0
6,0,19:18.0
-2,1,19:18.0
2,1,19:18.0
5,1,19:18.0
-3,2,19:18.0
-2,2,19:18.0
-1,2,19:18.0
2,2,19:18.0
3,2,19:18.0
-2,3,19:18.0
2,3,19:18.0
1,-3,20:18.0
0,-2,20:18.0
1,-2,20:18.0
2,-2,20:18.0
3,-2,20:18.0
1,-1,20:18.0
2,-1,20:18.0
3,-1,20:18.0
4,-1,20:18.0
2,0,20:17.0
3,0,20:18.0
1,1,20:18.0
2,1,20:17.0
3,1,20:18.0
1,2,20:18.0
2,2,20:17.0
3,2,20:18.0
1,3,20:18.0
2,3,20:18.0
3,3,20:18.0
2,-2,21:18.0
3,-2,21:18.0
4,-2,21:18.0
2,-1,21:18.0
3,-1,21:17.0
4,-1,21:18.0
2,0,21:17.0
3,0,21:18.0
4,0,21:18.0
2,1,21:18.0
1,2,21:18.0
2,2,21:18.0
3,2,21:18.0
2,3,21:18.0
2,-3,22:18.0
0,-2,22:18.0
1,-2,22:18.0
2,-2,22:18.0
3,-2,22:18.0
4,-2,22:18.0
0,-1,22:18.0
1,-1,22:18.0
2,-1,22:18.0
3,-1,22:18.0
4,-1,22:18.0
-1,0,22:18.0
0,0,22:18.0
1,0,22:18.0
2,0,22:17.0
3,0,22:18.0
4,0,22:18.0
5,0,22:18.0
0,1,22:18.0
1,1,22:18.0
2,1,22:18.0
4,1,22:18.0
0,2,22:18.0
1,2,22:18.0
2,2,22:18.0
3,2,22:18.0
4,2,22:18.0
2,3,22:18.0
1,-3,23:18.0
2,-3,23:18.0
3,-3,23:18.0
0,-2,23:18.0
1,-2,23:18.0
2,-2,23:18.0
3,-2,23:18.0
4,-2,23:18.0
-1,-1,23:18.0
0,-1,23:18.0
1,-1,23:18.0
2,-1,23:18.0
3,-1,23:18.0
4,-1,23:18.0
5,-1,23:18.0
-1,0,23:18.0
0,0,23:18.0
1,0,23:18.0
2,0,23:17.0
3,0,23:18.0
4,0,23:18.0
5,0,23:18.0
-1,1,23:18.0
0,1,23:18.0
1,1,23:18.0
2,1,23:18.0
3,1,23:18.0
4,1,23:18.0
5,1,23:18.0
0,2,23:18.0
1,2,23:18.0
2,2,23:18.0
3,2,23:18.0
4,2,23:18.0
1,3,23:18.0
2,3,23:18.0
3,3,23:18.0
2,-3,24:18.0
0,-2,24:18.0
1,-2,24:18.0
2,-2,24:18.0
3,-2,24:18.0
4,-2,24:18.0
0,-1,24:18.0
1,-1,24:18.0
2,-1,24:18.0
3,-1,24:18.0
4,-1,24:18.0
-1,0,24:18.0
0,0,24:18.0
1,0,24:18.0
2,0,24:18.0
3,0,24:18.0
4,0,24:18.0
5,0,24:18.0
0,1,24:18.0
1,1,24:18.0
2,1,24:18.0
3,1,24:18.0
4,1,24:18.0
0,2,24:18.0
1,2,24:18.0
2,2,24:18.0
3,2,24:18.0
4,2,24:18.0
2,3,24:18.0
1,-2,25:18.0
2,-2,25:18.0
3,-2,25:18.0
0,-1,25:18.0
1,-1,25:18.0
2,-1,25:18.0
3,-1,25:18.0
4,-1,25:18.0
0,0,25:18.0
1,0,25:18.0
2,0,25:18.0
3,0,25:18.0
4,0,25:18.0
0,1,25:18.0
1,1,25:18.0
2,1,25:18.0
3,1,25:18.0
4,1,25:18.0
1,2,25:18.0
2,2,25:18.0
3,2,25:18.0
2,-1,26:18.0
1,0,26:18.0
2,0,26:18.0
3,0,26:18.0
2,1,26:18.0
