[META]
version=2.0
spawnOnBlockType=2
spawnSunlight=True
spawnDarkness=True
spawnWater=False
spawnLava=False
underFill=False
randomRotation=True
dig=True
tree=True
branch=False
needsFoundation=True
rarity=60
collisionPercentage=20
spawnElevationMin=0
spawnElevationMax=200
spawnInBiome=Custom
[DATA]
0,0,0:17.0
0,0,1:17.0
0,0,2:17.0
0,0,3:17.0
0,0,4:17.0
0,0,5:17.0
0,0,6:17.0
0,0,7:17.0
1,0,7:17.0
0,-1,8:17.0
-1,0,8:17.0
0,0,8:17.0
1,0,8:17.0
0,1,8:17.0
0,-1,9:17.0
-1,0,9:17.0
0,0,9:17.0
2,0,9:17.4
0,1,9:17.0
-1,-1,10:17.4
2,-1,10:17.0
-2,0,10:17.4
0,2,10:17.8
-2,-4,11:18.0
3,-3,11:18.0
-2,-2,11:18.0
-1,-2,11:18.0
3,-2,11:18.0
4,-2,11:18.0
-3,-1,11:18.0
-2,-1,11:18.0
-1,-1,11:17.0
2,-1,11:17.0
3,-1,11:18.0
-4,0,11:18.0
-3,0,11:18.0
-2,0,11:18.0
0,0,11:18.0
-3,1,11:18.0
-1,1,11:18.0
0,1,11:17.0
1,1,11:18.0
0,2,11:18.0
-2,-5,12:18.0
-2,-4,12:18.0
-1,-4,12:18.0
2,-4,12:18.0
-2,-3,12:18.0
-1,-3,12:18.0
0,-3,12:18.0
1,-3,12:18.0
2,-3,12:18.0
3,-3,12:18.0
4,-3,12:18.0
-4,-2,12:18.0
-3,-2,12:18.0
-2,-2,12:18.0
-1,-2,12:18.0
1,-2,12:18.0
2,-2,12:18.0
3,-2,12:18.0
4,-2,12:18.0
-5,-1,12:18.0
-4,-1,12:18.0
-3,-1,12:17.0
-2,-1,12:17.0
-1,-1,12:18.0
0,-1,12:18.0
2,-1,12:18.0
3,-1,12:17.0
4,-1,12:18.0
5,-1,12:18.0
-4,0,12:18.0
-3,0,12:18.0
-2,0,12:18.0
-1,0,12:18.0
0,0,12:18.0
1,0,12:18.0
2,0,12:18.0
3,0,12:18.0
4,0,12:18.0
-4,1,12:18.0
-3,1,12:18.0
-2,1,12:18.0
-1,1,12:18.0
0,1,12:18.0
1,1,12:18.0
2,1,12:18.0
3,1,12:18.0
-2,2,12:18.0
-1,2,12:18.0
0,2,12:17.0
1,2,12:18.0
2,2,12:18.0
3,2,12:18.0
-1,3,12:18.0
0,3,12:18.0
1,3,12:18.0
2,3,12:18.0
0,4,12:18.0
-1,-5,13:18.0
-2,-4,13:18.0
-1,-4,13:18.0
0,-4,13:18.0
1,-4,13:18.0
2,-4,13:18.0
3,-4,13:18.0
-3,-3,13:18.0
-2,-3,13:18.0
-1,-3,13:18.0
0,-3,13:18.0
1,-3,13:18.0
2,-3,13:18.0
3,-3,13:18.0
4,-3,13:18.0
-5,-2,13:18.0
-4,-2,13:18.0
-3,-2,13:18.0
-2,-2,13:17.0
-1,-2,13:18.0
0,-2,13:18.0
1,-2,13:18.0
2,-2,13:18.0
3,-2,13:18.0
4,-2,13:18.0
5,-2,13:18.0
-5,-1,13:18.0
-4,-1,13:17.0
-3,-1,13:18.0
-2,-1,13:18.0
-1,-1,13:18.0
0,-1,13:18.0
1,-1,13:17.0
2,-1,13:18.0
3,-1,13:18.0
4,-1,13:17.0
5,-1,13:18.0
-5,0,13:18.0
-4,0,13:18.0
-3,0,13:18.0
-2,0,13:17.0
-1,0,13:18.0
0,0,13:18.0
1,0,13:18.0
2,0,13:18.0
3,0,13:18.0
4,0,13:18.0
5,0,13:18.0
-3,1,13:18.0
-2,1,13:18.0
-1,1,13:18.0
0,1,13:18.0
1,1,13:18.0
2,1,13:18.0
3,1,13:18.0
4,1,13:18.0
-3,2,13:18.0
-2,2,13:18.0
-1,2,13:18.0
0,2,13:17.0
1,2,13:18.0
2,2,13:18.0
3,2,13:18.0
-1,3,13:18.0
0,3,13:18.0
1,3,13:18.0
2,3,13:18.0
3,3,13:18.0
-1,4,13:18.0
0,4,13:18.0
1,4,13:18.0
-3,-4,14:18.0
-2,-4,14:18.0
-1,-4,14:18.0
2,-4,14:18.0
-3,-3,14:18.0
-2,-3,14:17.0
-1,-3,14:18.0
0,-3,14:18.0
1,-3,14:18.0
2,-3,14:18.0
3,-3,14:18.0
-4,-2,14:18.0
-3,-2,14:18.0
-2,-2,14:18.0
-1,-2,14:18.0
0,-2,14:18.0
1,-2,14:17.0
2,-2,14:18.0
3,-2,14:18.0
4,-2,14:18.0
-5,-1,14:18.0
-4,-1,14:17.0
-3,-1,14:18.0
-2,-1,14:18.0
-1,-1,14:18.0
0,-1,14:18.0
1,-1,14:18.0
2,-1,14:18.0
3,-1,14:18.0
4,-1,14:17.0
5,-1,14:18.0
-4,0,14:18.0
-3,0,14:18.0
-2,0,14:17.0
-1,0,14:18.0
0,0,14:18.0
1,0,14:17.0
2,0,14:18.0
3,0,14:18.0
4,0,14:18.0
-3,1,14:18.0
-2,1,14:18.0
-1,1,14:18.0
0,1,14:18.0
1,1,14:18.0
2,1,14:18.0
3,1,14:18.0
-2,2,14:18.0
-1,2,14:17.0
0,2,14:18.0
1,2,14:18.0
2,2,14:18.0
3,2,14:18.0
-2,3,14:18.0
-1,3,14:18.0
0,3,14:18.0
1,3,14:18.0
2,3,14:18.0
0,4,14:18.0
-2,-4,15:18.0
-3,-3,15:18.0
-2,-3,15:18.0
-1,-3,15:18.0
0,-3,15:18.0
1,-3,15:18.0
-3,-2,15:18.0
-2,-2,15:18.0
-1,-2,15:18.0
0,-2,15:18.0
1,-2,15:18.0
2,-2,15:18.0
3,-2,15:18.0
-4,-1,15:18.0
-3,-1,15:18.0
-2,-1,15:18.0
-1,-1,15:18.0
0,-1,15:18.0
1,-1,15:18.0
2,-1,15:18.0
3,-1,15:18.0
4,-1,15:18.0
-3,0,15:18.0
-2,0,15:18.0
-1,0,15:18.0
0,0,15:18.0
1,0,15:18.0
2,0,15:18.0
3,0,15:18.0
-2,1,15:18.0
-1,1,15:18.0
0,1,15:18.0
1,1,15:18.0
-2,2,15:18.0
-1,2,15:18.0
0,2,15:18.0
-1,3,15:18.0
0,-3,16:18.0
-1,-2,16:18.0
0,-2,16:18.0
1,-2,16:18.0
-2,-1,16:18.0
-1,-1,16:18.0
0,-1,16:18.0
-1,0,16:18.0
-2,1,16:18.0
-1,1,16:18.0
0,1,16:18.0
-1,2,16:18.0
