[META]
version=2.0
spawnOnBlockType=2
spawnSunlight=True
spawnDarkness=True
spawnWater=False
spawnLava=False
underFill=False
randomRotation=True
dig=True
tree=True
branch=False
needsFoundation=True
rarity=60
collisionPercentage=20
spawnElevationMin=0
spawnElevationMax=200
spawnInBiome=Custom
[DATA]
-1,0,0:17.0
-1,0,1:17.0
-1,0,2:17.0
-1,0,3:17.0
-1,0,4:17.0
-1,0,5:17.0
-1,0,6:17.0
-1,0,7:17.0
-1,0,8:17.0
-1,0,9:17.0
-1,0,10:17.0
-3,-6,11:18.0
-4,-5,11:18.0
-3,-5,11:17.8
-2,-5,11:18.0
-3,-4,11:17.8
-2,-3,11:17.8
-2,-2,11:17.8
4,-2,11:18.0
-2,-1,11:17.8
2,-1,11:17.4
3,-1,11:17.4
4,-1,11:17.4
5,-1,11:18.0
-1,0,11:17.0
0,0,11:17.4
1,0,11:17.4
4,0,11:18.0
-4,-6,12:18.0
-3,-6,12:18.0
-2,-6,12:18.0
-5,-5,12:18.0
-4,-5,12:18.0
-3,-5,12:18.0
-2,-5,12:18.0
-1,-5,12:18.0
-4,-4,12:18.0
-3,-4,12:18.0
-2,-4,12:18.0
3,-3,12:18.0
3,-2,12:18.0
4,-2,12:18.0
5,-2,12:18.0
3,-1,12:18.0
4,-1,12:18.0
5,-1,12:18.0
-1,0,12:17.0
3,0,12:18.0
4,0,12:18.0
5,0,12:18.0
-1,1,12:17.8
-1,2,12:17.8
-2,3,12:17.8
-3,4,12:17.8
-4,5,12:18.0
-3,5,12:17.8
-2,5,12:18.0
-3,6,12:18.0
-3,-6,13:18.0
-4,-5,13:18.0
-3,-5,13:18.0
-2,-5,13:18.0
-3,-4,13:18.0
4,-2,13:18.0
0,-1,13:17.8
3,-1,13:18.0
4,-1,13:18.0
5,-1,13:18.0
-3,0,13:17.4
-2,0,13:17.4
-1,0,13:17.0
4,0,13:18.0
-4,1,13:17.4
0,1,13:17.4
1,2,13:17.4
2,2,13:17.4
4,2,13:18.0
-3,3,13:18.0
3,3,13:17.4
4,3,13:17.4
5,3,13:18.0
-4,4,13:18.0
-3,4,13:18.0
-2,4,13:18.0
4,4,13:18.0
-4,5,13:18.0
-3,5,13:18.0
-2,5,13:18.0
-4,6,13:18.0
-2,6,13:18.0
-3,7,13:18.0
1,-5,14:18.0
0,-4,14:18.0
1,-4,14:17.8
2,-4,14:18.0
1,-3,14:17.8
0,-2,14:17.8
-6,0,14:18.0
-1,0,14:17.0
-7,1,14:18.0
-6,1,14:17.4
-5,1,14:17.4
-4,1,14:17.4
4,1,14:18.0
-6,2,14:18.0
3,2,14:18.0
4,2,14:18.0
5,2,14:18.0
3,3,14:18.0
4,3,14:18.0
5,3,14:18.0
-3,4,14:18.0
3,4,14:18.0
4,4,14:18.0
5,4,14:18.0
-3,5,14:18.0
-2,5,14:18.0
3,5,14:18.0
-3,6,14:18.0
0,-5,15:18.0
1,-5,15:18.0
2,-5,15:18.0
0,-4,15:18.0
1,-4,15:18.0
2,-4,15:18.0
0,-3,15:18.0
1,-3,15:18.0
2,-3,15:18.0
1,-2,15:18.0
2,-2,15:18.0
-6,-1,15:18.0
-7,0,15:18.0
-6,0,15:18.0
-5,0,15:18.0
-4,0,15:18.0
-1,0,15:17.0
-7,1,15:18.0
-6,1,15:18.0
-5,1,15:18.0
-7,2,15:18.0
-6,2,15:18.0
-5,2,15:18.0
4,2,15:18.0
3,3,15:18.0
4,3,15:18.0
5,3,15:18.0
4,4,15:18.0
1,-5,16:18.0
0,-4,16:18.0
1,-4,16:18.0
2,-4,16:18.0
1,-3,16:18.0
-6,0,16:18.0
-1,0,16:17.0
-7,1,16:18.0
-6,1,16:18.0
-5,1,16:18.0
-2,1,16:17.8
0,1,16:17.4
-6,2,16:18.0
-2,-2,17:18.0
-3,-1,17:18.0
-2,-1,17:17.8
-1,-1,17:18.0
-2,0,17:18.0
1,1,17:18.0
-2,2,17:17.8
0,2,17:18.0
1,2,17:17.4
2,2,17:18.0
1,3,17:18.0
-3,-2,18:18.0
-2,-2,18:18.0
-1,-2,18:18.0
-3,-1,18:18.0
-2,-1,18:18.0
-1,-1,18:18.0
-3,0,18:18.0
-2,0,18:18.0
-1,0,18:18.0
2,0,18:18.0
-2,1,18:18.0
0,1,18:18.0
1,1,18:18.0
2,1,18:18.0
-2,2,18:18.0
-1,2,18:18.0
0,2,18:18.0
1,2,18:18.0
2,2,18:18.0
-3,3,18:18.0
-2,3,18:17.8
-1,3,18:18.0
0,3,18:18.0
1,3,18:18.0
2,3,18:18.0
-3,4,18:18.0
-2,4,18:17.8
-1,4,18:18.0
-2,5,18:18.0
-2,-2,19:18.0
-3,-1,19:18.0
-2,-1,19:18.0
-1,-1,19:18.0
-2,0,19:18.0
-3,1,19:18.0
-2,1,19:18.0
-1,1,19:18.0
1,1,19:18.0
-3,2,19:18.0
-2,2,19:18.0
-1,2,19:18.0
0,2,19:18.0
1,2,19:18.0
2,2,19:18.0
-3,3,19:18.0
-2,3,19:18.0
-1,3,19:18.0
1,3,19:18.0
-2,4,19:18.0
-2,1,20:18.0
-3,2,20:18.0
-2,2,20:18.0
-1,2,20:18.0
-2,3,20:18.0
