[META]
version=2.0
spawnOnBlockType=2
spawnSunlight=True
spawnDarkness=True
spawnWater=False
spawnLava=False
underFill=False
randomRotation=True
dig=True
tree=False
branch=False
needsFoundation=True
rarity=10
collisionPercentage=20
spawnElevationMin=0
spawnElevationMax=200
spawnInBiome=Custom
[DATA]
1,-4,0:17
2,-4,0:17
1,-3,0:17
0,-2,0:17
1,-2,0:17
2,-2,0:17
1,-1,0:17
2,-1,0:17
3,-1,0:17
1,0,0:17
2,0,0:17
2,1,0:17
1,-2,1:17
1,-1,1:17
2,-1,1:17
1,-2,2:17
1,-1,2:17
1,-1,3:17
1,-1,4:17
4,1,4:18
4,2,4:18
1,-2,5:17
2,-2,5:17
0,-1,5:17
1,-1,5:17
1,0,5:17
2,0,5:17
3,0,5:18
4,0,5:17
5,0,5:17
2,1,5:17
3,1,5:17
4,1,5:17
4,2,5:18
3,-5,6:17
2,-4,6:17
3,-4,6:17
2,-3,6:17
1,-2,6:18
2,-2,6:17
3,-2,6:18
-2,-1,6:17
-1,-1,6:17
0,-1,6:17
1,-1,6:18
2,-1,6:18
-2,0,6:17
4,0,6:18
-2,1,6:18
3,1,6:17
3,2,6:17
2,-3,7:17
1,-2,7:18
2,-2,7:18
3,-2,7:18
-3,-1,7:18
-2,-1,7:18
-1,-1,7:18
-4,0,7:17
-3,0,7:17
-2,0,7:17
-2,1,7:17
-2,0,8:18
-1,0,8:18
-2,1,8:18
