[META]
version=2.0
spawnOnBlockType=2
spawnSunlight=True
spawnDarkness=True
spawnWater=False
spawnLava=False
underFill=False
randomRotation=True
dig=True
tree=False
branch=False
needsFoundation=True
rarity=10
collisionPercentage=20
spawnElevationMin=0
spawnElevationMax=200
spawnInBiome=Custom
[DATA]
0,-2,0:17
0,-1,0:17
-3,0,0:17
-1,0,0:17
0,0,0:17
1,0,0:17
-3,1,0:17
-2,1,0:17
-1,1,0:17
0,1,0:17
1,1,0:17
2,1,0:17
-2,2,0:17
-1,2,0:17
0,2,0:17
2,2,0:17
0,3,0:17
0,4,0:17
0,0,1:17
-2,1,1:17
-1,1,1:17
0,1,1:17
-1,2,1:17
-1,1,2:17
0,1,2:17
-1,1,3:17
-1,0,4:17
0,0,4:17
-1,1,4:17
0,0,5:17
3,-1,6:18
0,0,6:17
1,0,6:17
3,0,6:18
0,-5,7:18
1,-4,7:18
3,-2,7:17
4,-2,7:17
1,-1,7:17
2,-1,7:17
3,-1,7:17
1,0,7:17
1,1,7:17
2,1,7:17
3,1,7:17
-4,2,7:18
-2,2,7:18
-1,2,7:18
0,2,7:17
1,2,7:17
3,2,7:17
4,2,7:17
-2,3,7:18
0,4,7:18
1,4,7:18
2,4,7:18
1,5,7:18
-1,-5,8:18
0,-5,8:18
-1,-4,8:17
0,-4,8:17
1,-4,8:18
0,-3,8:17
0,-2,8:17
1,-2,8:17
1,-1,8:17
2,-1,8:18
-4,0,8:17
-3,0,8:18
3,0,8:18
-5,1,8:18
-4,1,8:17
-3,1,8:17
-2,1,8:17
-4,2,8:18
-2,2,8:17
-1,2,8:17
0,2,8:17
4,2,8:17
-1,3,8:17
0,3,8:18
1,3,8:18
-1,4,8:17
0,4,8:17
1,4,8:17
1,5,8:17
2,5,8:18
-4,1,9:18
-3,2,9:18
2,4,9:18
