[META]
version=2.0
spawnOnBlockType=2
spawnSunlight=True
spawnDarkness=True
spawnWater=False
spawnLava=False
underFill=False
randomRotation=True
dig=True
tree=False
branch=False
needsFoundation=True
rarity=10
collisionPercentage=20
spawnElevationMin=0
spawnElevationMax=200
spawnInBiome=Custom
[DATA]
-1,-2,0:17
-1,-1,0:17
0,-1,0:17
-2,0,0:17
-1,0,0:17
0,0,0:17
1,0,0:17
2,0,0:17
-1,1,0:17
0,1,0:17
1,1,0:17
-1,2,0:17
-1,0,1:17
0,0,1:17
-1,1,1:17
-1,0,2:17
-1,-1,3:17
-1,0,3:17
-1,-1,4:17
-2,-4,5:17
-2,-3,5:17
-1,-3,5:17
0,-3,5:17
2,-3,5:18
-1,-2,5:17
-4,-1,5:18
-3,-1,5:18
-2,-1,5:17
-1,-1,5:17
0,-1,5:17
0,0,5:18
1,2,5:17
2,2,5:18
3,2,5:18
1,-4,6:17
2,-4,6:18
0,-3,6:17
1,-3,6:17
2,-3,6:18
-3,-2,6:18
0,-2,6:18
1,-2,6:18
-4,-1,6:17
-3,-1,6:17
-2,-1,6:17
-1,-1,6:18
0,-1,6:17
1,-1,6:18
-3,0,6:17
0,0,6:17
1,0,6:17
2,0,6:17
2,1,6:17
3,1,6:17
1,2,6:17
2,2,6:17
3,2,6:18
1,3,6:18
1,-4,7:18
0,-2,7:18
-1,-1,7:18
0,-1,7:18
1,0,7:17
