[META]
version=2.0
spawnOnBlockType=2
spawnSunlight=True
spawnDarkness=True
spawnWater=False
spawnLava=False
underFill=False
randomRotation=True
dig=True
tree=True
branch=False
needsFoundation=True
rarity=10
collisionPercentage=20
spawnElevationMin=0
spawnElevationMax=200
spawnInBiome=Custom
[DATA]
1,-4,0:17.3
1,-4,1:17.3
0,-3,1:17.3
2,-4,2:17.3
0,-3,2:17.3
3,-5,3:18.3
4,-5,3:18.3
-1,-4,3:18.3
2,-4,3:18.3
3,-4,3:17.3
4,-4,3:17.3
-2,-3,3:18.3
-1,-3,3:17.3
0,-3,3:18.3
3,-3,3:18.3
4,-3,3:18.3
-1,-2,3:18.3
0,-2,3:17.3
1,-2,3:18.3
-2,-5,4:18.3
5,-5,4:18.3
-3,-4,4:18.3
-2,-4,4:17.3
-1,-4,4:18.3
3,-4,4:18.3
4,-4,4:18.3
5,-4,4:17.3
6,-4,4:18.3
-2,-3,4:18.3
-1,-3,4:18.3
5,-3,4:18.3
0,-2,4:18.3
-1,-1,4:18.3
0,-1,4:17.3
1,-1,4:18.3
0,0,4:18.3
5,-5,5:18.3
-2,-4,5:18.3
4,-4,5:18.3
5,-4,5:17.3
6,-4,5:18.3
-1,-3,5:18.3
5,-3,5:18.3
0,-2,5:18.3
-1,-1,5:18.3
0,-1,5:17.3
1,-1,5:18.3
0,0,5:18.3
-2,-4,6:18.3
5,-4,6:18.3
0,-1,6:18.3
5,-4,7:18.3
0,-1,7:18.3
5,-2,4:106.4
6,-3,4:106.2
4,-3,4:106.8
1,-1,3:106.4
0,-1,3:106.4
-1,-1,3:106.4
5,-2,3:106.4
6,-3,3:106.2
0,-4,3:106.1
1,-1,2:106.4
0,-1,2:106.4
-1,-1,2:106.4
6,-3,2:106.2
0,-4,2:106.1
-1,-3,1:106.8
0,-4,1:106.1
-1,-3,0:106.8
0,-4,0:106.1
