[META]
version=2.0
spawnOnBlockType=2
spawnSunlight=True
spawnDarkness=True
spawnWater=False
spawnLava=False
underFill=False
randomRotation=True
dig=True
tree=True
branch=False
needsFoundation=True
rarity=10
collisionPercentage=20
spawnElevationMin=0
spawnElevationMax=200
spawnInBiome=Custom
[DATA]
-2,1,0:17.3
-2,1,1:17.3
-2,0,2:17.3
-2,1,2:17.3
-2,2,2:17.3
-3,3,2:18.3
-2,3,2:17.3
-1,3,2:18.3
-2,-3,3:18.3
-3,-2,3:18.3
-2,-2,3:17.3
-1,-2,3:18.3
-3,-1,3:18.3
-2,-1,3:17.3
-1,-1,3:18.3
-3,0,3:18.3
-4,1,3:18.3
-3,1,3:17.3
-2,1,3:17.3
-3,2,3:18.3
-2,3,3:18.3
-3,4,3:18.3
-2,4,3:17.3
-1,4,3:18.3
-2,5,3:18.3
-2,-2,4:18.3
-2,-1,4:18.3
-3,0,4:18.3
-4,1,4:18.3
-3,1,4:17.3
-1,1,4:17.3
0,1,4:18.3
-3,2,4:18.3
-1,2,4:18.3
-2,4,4:18.3
-2,-2,5:18.3
-1,-1,5:18.3
-3,0,5:18.3
-2,0,5:18.3
-1,0,5:17.3
0,0,5:18.3
-4,1,5:18.3
-3,1,5:17.3
-1,1,5:18.3
-3,2,5:18.3
-2,4,5:18.3
0,-2,6:18.3
-1,-1,6:18.3
0,-1,6:17.3
1,-1,6:18.3
-1,0,6:18.3
0,0,6:18.3
-3,1,6:18.3
0,-1,7:18.3
-3,1,7:18.3
0,-1,8:18.3
-2,1,4:106.10
-3,2,2:106.8
