[META]
version=2.0
spawnOnBlockType=2
spawnSunlight=True
spawnDarkness=True
spawnWater=False
spawnLava=False
underFill=False
randomRotation=True
dig=True
tree=True
branch=False
needsFoundation=True
rarity=10
collisionPercentage=20
spawnElevationMin=0
spawnElevationMax=200
spawnInBiome=Custom
[DATA]
0,0,0:17.3
0,0,1:17.3
0,-1,2:17.3
-1,0,2:17.3
0,0,2:17.3
1,0,2:17.3
0,1,2:17.3
0,-2,3:17.3
0,-1,3:17.3
-2,0,3:17.3
-1,0,3:17.3
1,0,3:17.3
2,0,3:17.3
0,1,3:17.3
0,2,3:17.3
0,-3,4:18.3
-1,-2,4:18.3
0,-2,4:17.3
1,-2,4:18.3
-2,-1,4:18.3
0,-1,4:18.3
2,-1,4:18.3
-3,0,4:18.3
-2,0,4:17.3
-1,0,4:18.3
1,0,4:18.3
2,0,4:17.3
3,0,4:18.3
-2,1,4:18.3
0,1,4:18.3
2,1,4:18.3
-1,2,4:18.3
0,2,4:17.3
1,2,4:18.3
0,3,4:18.3
0,-4,5:18.3
-1,-3,5:18.3
0,-3,5:17.3
1,-3,5:18.3
0,-2,5:18.3
-3,-1,5:18.3
3,-1,5:18.3
-4,0,5:18.3
-3,0,5:17.3
-2,0,5:18.3
2,0,5:18.3
3,0,5:17.3
4,0,5:18.3
-3,1,5:18.3
3,1,5:18.3
0,2,5:18.3
-1,3,5:18.3
0,3,5:17.3
1,3,5:18.3
0,4,5:18.3
0,-3,6:18.3
0,-2,6:18.3
-3,0,6:18.3
-2,0,6:18.3
2,0,6:18.3
3,0,6:18.3
0,2,6:18.3
0,3,6:18.3
0,-3,7:18.3
-3,0,7:18.3
3,0,7:18.3
0,3,7:18.3
